Workbook

Sheet REKAPITULASI
A1: BAGIAN PEREKONOMIAN DAN SUMBER DAYA ALAM
A2: LAPORAN HARGA BAHAN POKOK DI KOTA SURABAYA
A3: PERIODE PEBRUARI 2024
B4: NAMA BAHAN POKOK DAN PENTING LAINNYA | C4: SAT | AG4: HET/HAPK (Harga Eceran Tertinggi) | AH4: FLUKTUASI
D5: 1 | E5: 2 | F5: 3 | G5: 4 | H5: 5 | I5: 6 | J5: 7 | K5: 8 | L5: 9 | M5: 10 | N5: 11 | O5: 12 | P5: 13 | Q5: 14 | R5: 15 | S5: 16 | T5: 17 | U5: 18 | V5: 19 | W5: 20 | X5: 21 | Y5: 22 | Z5: 23 | AA5: 24 | AB5: 25 | AC5: 26 | AD5: 27 | AE5: 28 | AF5: 29
A7: 1 | B7: BERAS
B8: - Beras Premium | C8: Kg | D8: ='1'!K8 -> 14000 | E8: ='2'!K8 -> 14285.714 | F8: ='3'!K8 -> 14314.286 | G8: ='4'!K8 -> 14300 | H8: ='5'!K8 -> 15071.429 | I8: ='6'!K8 -> 15285.714 | J8: ='7'!K8 -> 15357.143 | K8: ='8'!K8 -> 15428.571 | L8: ='9'!K8 -> 15142.857 | M8: ='10'!K8 -> 15500 | N8: ='11'!K8 -> 15500 | O8: ='12'!K8 -> 16071.429 | P8: ='13'!K8 -> 16071.429 | Q8: ='14'!K8 -> 16071.429 | R8: ='15'!K8 -> 16071.429 | S8: ='16'!K8 -> 16071.429 | T8: ='17'!K8 -> 16071.429 | U8: ='18'!K8 -> 16071.429 | V8: ='19'!K8 -> 16071.429 | W8: ='20'!K8 -> 16142.857 | X8: ='21'!K8 -> 16142.857 | Y8: ='22'!K8 -> 16142.857 | Z8: ='23'!K8 -> 16142.857 | AA8: ='24'!K8 -> 16142.857 | AB8: ='25'!K8 -> 16142.857 | AC8: ='26'!K8 -> 16142.857 | AD8: ='27'!K8 -> 16157.143 | AE8: ='28'!K8 -> 16171.429 | AF8: ='29'!K8 -> 16171.429 | AG8: 13900 | AH8: =AF8-D8 -> 2171.4286 | AI8: =AVERAGE(D8:AF8) -> 15664.039
B9: - Beras Medium Bulog | C9: Kg | D9: ='1'!K9 -> 10900 | E9: ='2'!K9 -> 11083.333 | F9: ='3'!K9 -> 11083.333 | G9: ='4'!K9 -> 11083.333 | H9: ='5'!K9 -> 11083.333 | I9: ='6'!K9 -> 11083.333 | J9: ='7'!K9 -> 11083.333 | K9: ='8'!K9 -> 11083.333 | L9: ='9'!K9 -> 11083.333 | M9: ='10'!K9 -> 11083.333 | N9: ='11'!K9 -> 11083.333 | O9: ='12'!K9 -> 11083.333 | P9: ='13'!K9 -> 11083.333 | Q9: ='14'!K9 -> 11083.333 | R9: ='15'!K9 -> 11083.333 | S9: ='16'!K9 -> 11600 | T9: ='17'!K9 -> 11600 | U9: ='18'!K9 -> 11600 | V9: ='19'!K9 -> 11600 | W9: ='20'!K9 -> 11766.667 | X9: ='21'!K9 -> 11766.667 | Y9: ='22'!K9 -> 11933.333 | Z9: ='23'!K9 -> 10900 | AA9: ='24'!K9 -> 10900 | AB9: ='25'!K9 -> 10900 | AC9: ='26'!K9 -> 10900 | AD9: ='27'!K9 -> 10900 | AE9: ='28'!K9 -> 10900 | AF9: ='29'!K9 -> 10900 | AH9: =AF9-D9 -> 0 | AI9: =AVERAGE(D9:AF9) -> 11180.46
B10: - Beras Medium | C10: Kg | D10: ='1'!K10 -> 0 | E10: ='2'!K10 -> 0 | F10: ='3'!K10 -> 0 | G10: ='4'!K10 -> 0 | H10: ='5'!K10 -> 0 | I10: ='6'!K10 -> 0 | J10: ='7'!K10 -> 0 | K10: ='8'!K10 -> 0 | L10: ='9'!K10 -> 0 | M10: ='10'!K10 -> 0 | N10: ='11'!K10 -> 0 | O10: ='12'!K10 -> 0 | P10: ='13'!K10 -> 0 | Q10: ='14'!K10 -> 0 | R10: ='15'!K10 -> 0 | S10: ='16'!K10 -> 0 | T10: ='17'!K10 -> 0 | U10: ='18'!K10 -> 0 | V10: ='19'!K10 -> 0 | W10: ='20'!K10 -> 0 | X10: ='21'!K10 -> 0 | Y10: ='22'!K10 -> 0 | Z10: ='23'!K10 -> 14000 | AA10: ='24'!K10 -> 13000 | AB10: ='25'!K10 -> 13000 | AC10: ='26'!K10 -> 13000 | AD10: ='27'!K10 -> 13000 | AE10: ='28'!K10 -> 13000 | AF10: ='29'!K10 -> 13000 | AG10: 10900 | AH10: =AF10-D10 -> 13000 | AI10: =AVERAGE(D10:AF10) -> 3172.4138
B11: - Beras Jagung | C11: Kg | D11: ='1'!K11 -> 10666.667 | E11: ='2'!K11 -> 10666.667 | F11: ='3'!K11 -> 10666.667 | G11: ='4'!K11 -> 10666.667 | H11: ='5'!K11 -> 10666.667 | I11: ='6'!K11 -> 10666.667 | J11: ='7'!K11 -> 10666.667 | K11: ='8'!K11 -> 10666.667 | L11: ='9'!K11 -> 10666.667 | M11: ='10'!K11 -> 10666.667 | N11: ='11'!K11 -> 10666.667 | O11: ='12'!K11 -> 10666.667 | P11: ='13'!K11 -> 10666.667 | Q11: ='14'!K11 -> 10666.667 | R11: ='15'!K11 -> 10666.667 | S11: ='16'!K11 -> 10666.667 | T11: ='17'!K11 -> 10666.667 | U11: ='18'!K11 -> 10666.667 | V11: ='19'!K11 -> 10666.667 | W11: ='20'!K11 -> 10666.667 | X11: ='21'!K11 -> 10666.667 | Y11: ='22'!K11 -> 10666.667 | Z11: ='23'!K11 -> 10666.667 | AA11: ='24'!K11 -> 10666.667 | AB11: ='25'!K11 -> 10666.667 | AC11: ='26'!K11 -> 10666.667 | AD11: ='27'!K11 -> 10666.667 | AE11: ='28'!K11 -> 10666.667 | AF11: ='29'!K11 -> 10666.667 | AH11: =AF11-D11 -> 0 | AI11: =AVERAGE(D11:AF11) -> 10666.667
B12: - Beras Ketan (Jenis Siyem) | C12: Kg | D12: ='1'!K12 -> 19000 | E12: ='2'!K12 -> 19000 | F12: ='3'!K12 -> 19000 | G12: ='4'!K12 -> 19000 | H12: ='5'!K12 -> 19000 | I12: ='6'!K12 -> 19000 | J12: ='7'!K12 -> 19000 | K12: ='8'!K12 -> 19000 | L12: ='9'!K12 -> 19000 | M12: ='10'!K12 -> 19000 | N12: ='11'!K12 -> 19000 | O12: ='12'!K12 -> 19000 | P12: ='13'!K12 -> 19000 | Q12: ='14'!K12 -> 19000 | R12: ='15'!K12 -> 19000 | S12: ='16'!K12 -> 19000 | T12: ='17'!K12 -> 19000 | U12: ='18'!K12 -> 19000 | V12: ='19'!K12 -> 19000 | W12: ='20'!K12 -> 19000 | X12: ='21'!K12 -> 19000 | Y12: ='22'!K12 -> 19000 | Z12: ='23'!K12 -> 19000 | AA12: ='24'!K12 -> 19000 | AB12: ='25'!K12 -> 19000 | AC12: ='26'!K12 -> 19000 | AD12: ='27'!K12 -> 19000 | AE12: ='28'!K12 -> 19000 | AF12: ='29'!K12 -> 19000 | AH12: =AF12-D12 -> 0 | AI12: =AVERAGE(D12:AF12) -> 19000
A13: 2 | B13: GULA | D13: ='1'!K13 -> 0 | E13: ='2'!K13 -> 0 | F13: ='3'!K13 -> 0 | G13: ='4'!K13 -> 0 | H13: ='5'!K13 -> 0 | I13: ='6'!K13 -> 0 | J13: ='7'!K13 -> 0 | K13: ='8'!K13 -> 0 | L13: ='9'!K13 -> 0 | M13: ='10'!K13 -> 0 | N13: ='11'!K13 -> 0 | O13: ='12'!K13 -> 0 | P13: ='13'!K13 -> 0 | Q13: ='14'!K13 -> 0 | R13: ='15'!K13 -> 0 | S13: ='16'!K13 -> 0 | T13: ='17'!K13 -> 0 | U13: ='18'!K13 -> 0 | V13: ='19'!K13 -> 0 | W13: ='20'!K13 -> 0 | X13: ='21'!K13 -> 0 | Y13: ='22'!K13 -> 0 | Z13: ='23'!K13 -> 0 | AA13: ='24'!K13 -> 0 | AB13: ='25'!K13 -> 0 | AC13: ='26'!K13 -> 0 | AD13: ='27'!K13 -> 0 | AE13: ='28'!K13 -> 0 | AF13: ='29'!K13 -> 0 | AH13: =AF13-D13 -> 0 | AI13: =AVERAGE(D13:AF13) -> 0
B14: - Gula pasir lokal curah | C14: Kg | D14: ='1'!K14 -> 16285.714 | E14: ='2'!K14 -> 16285.714 | F14: ='3'!K14 -> 16214.286 | G14: ='4'!K14 -> 16214.286 | H14: ='5'!K14 -> 16214.286 | I14: ='6'!K14 -> 16214.286 | J14: ='7'!K14 -> 16214.286 | K14: ='8'!K14 -> 16214.286 | L14: ='9'!K14 -> 16214.286 | M14: ='10'!K14 -> 16214.286 | N14: ='11'!K14 -> 16214.286 | O14: ='12'!K14 -> 16285.714 | P14: ='13'!K14 -> 16285.714 | Q14: ='14'!K14 -> 16285.714 | R14: ='15'!K14 -> 16285.714 | S14: ='16'!K14 -> 16285.714 | T14: ='17'!K14 -> 16285.714 | U14: ='18'!K14 -> 16285.714 | V14: ='19'!K14 -> 16285.714 | W14: ='20'!K14 -> 16428.571 | X14: ='21'!K14 -> 16428.571 | Y14: ='22'!K14 -> 16428.571 | Z14: ='23'!K14 -> 16500 | AA14: ='24'!K14 -> 16500 | AB14: ='25'!K14 -> 16500 | AC14: ='26'!K14 -> 16500 | AD14: ='27'!K14 -> 16642.857 | AE14: ='28'!K14 -> 16642.857 | AF14: ='29'!K14 -> 16642.857 | AG14: 16000 | AH14: =AF14-D14 -> 357.14286 | AI14: =AVERAGE(D14:AF14) -> 16344.828
B15: - Gula Jawa/Merah (Bahan Kelapa) | C15: Kg | D15: ='1'!K15 -> 16571.429 | E15: ='2'!K15 -> 16571.429 | F15: ='3'!K15 -> 16571.429 | G15: ='4'!K15 -> 16571.429 | H15: ='5'!K15 -> 16571.429 | I15: ='6'!K15 -> 16571.429 | J15: ='7'!K15 -> 16571.429 | K15: ='8'!K15 -> 16571.429 | L15: ='9'!K15 -> 16571.429 | M15: ='10'!K15 -> 16571.429 | N15: ='11'!K15 -> 16571.429 | O15: ='12'!K15 -> 16571.429 | P15: ='13'!K15 -> 16571.429 | Q15: ='14'!K15 -> 16571.429 | R15: ='15'!K15 -> 16571.429 | S15: ='16'!K15 -> 16571.429 | T15: ='17'!K15 -> 16714.286 | U15: ='18'!K15 -> 16714.286 | V15: ='19'!K15 -> 16714.286 | W15: ='20'!K15 -> 16857.143 | X15: ='21'!K15 -> 16857.143 | Y15: ='22'!K15 -> 16857.143 | Z15: ='23'!K15 -> 16857.143 | AA15: ='24'!K15 -> 16857.143 | AB15: ='25'!K15 -> 16857.143 | AC15: ='26'!K15 -> 16857.143 | AD15: ='27'!K15 -> 16857.143 | AE15: ='28'!K15 -> 16857.143 | AF15: ='29'!K15 -> 16857.143 | AH15: =AF15-D15 -> 285.71429 | AI15: =AVERAGE(D15:AF15) -> 16684.729
A16: 3 | B16: MINYAK GORENG | D16: ='1'!K16 -> 0 | E16: ='2'!K16 -> 0 | F16: ='3'!K16 -> 0 | G16: ='4'!K16 -> 0 | H16: ='5'!K16 -> 0 | I16: ='6'!K16 -> 0 | J16: ='7'!K16 -> 0 | K16: ='8'!K16 -> 0 | L16: ='9'!K16 -> 0 | M16: ='10'!K16 -> 0 | N16: ='11'!K16 -> 0 | O16: ='12'!K16 -> 0 | P16: ='13'!K16 -> 0 | Q16: ='14'!K16 -> 0 | R16: ='15'!K16 -> 0 | S16: ='16'!K16 -> 0 | T16: ='17'!K16 -> 0 | U16: ='18'!K16 -> 0 | V16: ='19'!K16 -> 0 | W16: ='20'!K16 -> 0 | X16: ='21'!K16 -> 0 | Y16: ='22'!K16 -> 0 | Z16: ='23'!K16 -> 0 | AA16: ='24'!K16 -> 0 | AB16: ='25'!K16 -> 0 | AC16: ='26'!K16 -> 0 | AD16: ='27'!K16 -> 0 | AE16: ='28'!K16 -> 0 | AF16: ='29'!K16 -> 0 | AH16: =AF16-D16 -> 0 | AI16: =AVERAGE(D16:AF16) -> 0
B17: - Minyak Goreng Curah (Bening) | C17: Kg | D17: ='1'!K17 -> 15142.857 | E17: ='2'!K17 -> 15285.714 | F17: ='3'!K17 -> 15285.714 | G17: ='4'!K17 -> 15285.714 | H17: ='5'!K17 -> 15285.714 | I17: ='6'!K17 -> 15285.714 | J17: ='7'!K17 -> 15285.714 | K17: ='8'!K17 -> 15285.714 | L17: ='9'!K17 -> 15285.714 | M17: ='10'!K17 -> 15285.714 | N17: ='11'!K17 -> 15285.714 | O17: ='12'!K17 -> 15285.714 | P17: ='13'!K17 -> 15285.714 | Q17: ='14'!K17 -> 15285.714 | R17: ='15'!K17 -> 15285.714 | S17: ='16'!K17 -> 15357.143 | T17: ='17'!K17 -> 15357.143 | U17: ='18'!K17 -> 15357.143 | V17: ='19'!K17 -> 15285.714 | W17: ='20'!K17 -> 15571.429 | X17: ='21'!K17 -> 15571.429 | Y17: ='22'!K17 -> 15571.429 | Z17: ='23'!K17 -> 15642.857 | AA17: ='24'!K17 -> 15642.857 | AB17: ='25'!K17 -> 15642.857 | AC17: ='26'!K17 -> 15642.857 | AD17: ='27'!K17 -> 15642.857 | AE17: ='28'!K17 -> 15642.857 | AF17: ='29'!K17 -> 15642.857 | AG17: 15500 | AH17: =AF17-D17 -> 500 | AI17: =AVERAGE(D17:AF17) -> 15403.941
B18: - Minyak Kita | C18: Liter | D18: ='1'!K18 -> 14000 | E18: ='2'!K18 -> 14000 | F18: ='3'!K18 -> 14000 | G18: ='4'!K18 -> 14000 | H18: ='5'!K18 -> 14000 | I18: ='6'!K18 -> 14000 | J18: ='7'!K18 -> 14000 | K18: ='8'!K18 -> 14000 | L18: ='9'!K18 -> 14000 | M18: ='10'!K18 -> 14000 | N18: ='11'!K18 -> 14000 | O18: ='12'!K18 -> 14000 | P18: ='13'!K18 -> 14000 | Q18: ='14'!K18 -> 14000 | R18: ='15'!K18 -> 14000 | S18: ='16'!K18 -> 14000 | T18: ='17'!K18 -> 14000 | U18: ='18'!K18 -> 14000 | V18: ='19'!K18 -> 14000 | W18: ='20'!K18 -> 14000 | X18: ='21'!K18 -> 14000 | Y18: ='22'!K18 -> 14000 | Z18: ='23'!K18 -> 14000 | AA18: ='24'!K18 -> 14000 | AB18: ='25'!K18 -> 14000 | AC18: ='26'!K18 -> 14000 | AD18: ='27'!K18 -> 14000 | AE18: ='28'!K18 -> 14000 | AF18: ='29'!K18 -> 14000 | AG18: 14000 | AH18: =AF18-D18 -> 0 | AI18: =AVERAGE(D18:AF18) -> 14000
A19: 4 | B19: MENTEGA | D19: ='1'!K19 -> 0 | E19: ='2'!K19 -> 0 | F19: ='3'!K19 -> 0 | G19: ='4'!K19 -> 0 | H19: ='5'!K19 -> 0 | I19: ='6'!K19 -> 0 | J19: ='7'!K19 -> 0 | K19: ='8'!K19 -> 0 | L19: ='9'!K19 -> 0 | M19: ='10'!K19 -> 0 | N19: ='11'!K19 -> 0 | O19: ='12'!K19 -> 0 | P19: ='13'!K19 -> 0 | Q19: ='14'!K19 -> 0 | R19: ='15'!K19 -> 0 | S19: ='16'!K19 -> 0 | T19: ='17'!K19 -> 0 | U19: ='18'!K19 -> 0 | V19: ='19'!K19 -> 0 | W19: ='20'!K19 -> 0 | X19: ='21'!K19 -> 0 | Y19: ='22'!K19 -> 0 | Z19: ='23'!K19 -> 0 | AA19: ='24'!K19 -> 0 | AB19: ='25'!K19 -> 0 | AC19: ='26'!K19 -> 0 | AD19: ='27'!K19 -> 0 | AE19: ='28'!K19 -> 0 | AF19: ='29'!K19 -> 0 | AH19: =AF19-D19 -> 0 | AI19: =AVERAGE(D19:AF19) -> 0
B20: - Mentega Curah (Amanda) | C20: Kg | D20: ='1'!K20 -> 22500 | E20: ='2'!K20 -> 22500 | F20: ='3'!K20 -> 22500 | G20: ='4'!K20 -> 22500 | H20: ='5'!K20 -> 22500 | I20: ='6'!K20 -> 22500 | J20: ='7'!K20 -> 22500 | K20: ='8'!K20 -> 22500 | L20: ='9'!K20 -> 22500 | M20: ='10'!K20 -> 22500 | N20: ='11'!K20 -> 22500 | O20: ='12'!K20 -> 22500 | P20: ='13'!K20 -> 22500 | Q20: ='14'!K20 -> 22500 | R20: ='15'!K20 -> 22500 | S20: ='16'!K20 -> 22500 | T20: ='17'!K20 -> 22500 | U20: ='18'!K20 -> 22500 | V20: ='19'!K20 -> 22500 | W20: ='20'!K20 -> 22500 | X20: ='21'!K20 -> 22500 | Y20: ='22'!K20 -> 22500 | Z20: ='23'!K20 -> 22500 | AA20: ='24'!K20 -> 22500 | AB20: ='25'!K20 -> 22500 | AC20: ='26'!K20 -> 22500 | AD20: ='27'!K20 -> 22500 | AE20: ='28'!K20 -> 22500 | AF20: ='29'!K20 -> 22500 | AH20: =AF20-D20 -> 0 | AI20: =AVERAGE(D20:AF20) -> 22500
A21: 5 | B21: DAGING | D21: ='1'!K21 -> 0 | E21: ='2'!K21 -> 0 | F21: ='3'!K21 -> 0 | G21: ='4'!K21 -> 0 | H21: ='5'!K21 -> 0 | I21: ='6'!K21 -> 0 | J21: ='7'!K21 -> 0 | K21: ='8'!K21 -> 0 | L21: ='9'!K21 -> 0 | M21: ='10'!K21 -> 0 | N21: ='11'!K21 -> 0 | O21: ='12'!K21 -> 0 | P21: ='13'!K21 -> 0 | Q21: ='14'!K21 -> 0 | R21: ='15'!K21 -> 0 | S21: ='16'!K21 -> 0 | T21: ='17'!K21 -> 0 | U21: ='18'!K21 -> 0 | V21: ='19'!K21 -> 0 | W21: ='20'!K21 -> 0 | X21: ='21'!K21 -> 0 | Y21: ='22'!K21 -> 0 | Z21: ='23'!K21 -> 0 | AA21: ='24'!K21 -> 0 | AB21: ='25'!K21 -> 0 | AC21: ='26'!K21 -> 0 | AD21: ='27'!K21 -> 0 | AE21: ='28'!K21 -> 0 | AF21: ='29'!K21 -> 0 | AH21: =AF21-D21 -> 0 | AI21: =AVERAGE(D21:AF21) -> 0
B22: - Daging Sapi Grade Atas | C22: Kg | D22: ='1'!K22 -> 120000 | E22: ='2'!K22 -> 120000 | F22: ='3'!K22 -> 120000 | G22: ='4'!K22 -> 120000 | H22: ='5'!K22 -> 120000 | I22: ='6'!K22 -> 120000 | J22: ='7'!K22 -> 120000 | K22: ='8'!K22 -> 120000 | L22: ='9'!K22 -> 120000 | M22: ='10'!K22 -> 120000 | N22: ='11'!K22 -> 120000 | O22: ='12'!K22 -> 120000 | P22: ='13'!K22 -> 120000 | Q22: ='14'!K22 -> 120000 | R22: ='15'!K22 -> 120000 | S22: ='16'!K22 -> 120000 | T22: ='17'!K22 -> 120000 | U22: ='18'!K22 -> 120000 | V22: ='19'!K22 -> 120000 | W22: ='20'!K22 -> 120000 | X22: ='21'!K22 -> 120000 | Y22: ='22'!K22 -> 120000 | Z22: ='23'!K22 -> 120000 | AA22: ='24'!K22 -> 120000 | AB22: ='25'!K22 -> 120000 | AC22: ='26'!K22 -> 120000 | AD22: ='27'!K22 -> 120000 | AE22: ='28'!K22 -> 120000 | AF22: ='29'!K22 -> 120000 | AG22: 140000 | AH22: =AF22-D22 -> 0 | AI22: =AVERAGE(D22:AF22) -> 120000
B23: - Daging Sapi Grade Sedang | C23: Kg | D23: ='1'!K23 -> 110714.29 | E23: ='2'!K23 -> 110714.29 | F23: ='3'!K23 -> 110714.29 | G23: ='4'!K23 -> 110714.29 | H23: ='5'!K23 -> 110714.29 | I23: ='6'!K23 -> 110714.29 | J23: ='7'!K23 -> 110714.29 | K23: ='8'!K23 -> 110714.29 | L23: ='9'!K23 -> 110714.29 | M23: ='10'!K23 -> 110714.29 | N23: ='11'!K23 -> 110714.29 | O23: ='12'!K23 -> 110714.29 | P23: ='13'!K23 -> 110714.29 | Q23: ='14'!K23 -> 110714.29 | R23: ='15'!K23 -> 110714.29 | S23: ='16'!K23 -> 110714.29 | T23: ='17'!K23 -> 110714.29 | U23: ='18'!K23 -> 110714.29 | V23: ='19'!K23 -> 110714.29 | W23: ='20'!K23 -> 110714.29 | X23: ='21'!K23 -> 110714.29 | Y23: ='22'!K23 -> 110714.29 | Z23: ='23'!K23 -> 110714.29 | AA23: ='24'!K23 -> 110714.29 | AB23: ='25'!K23 -> 110714.29 | AC23: ='26'!K23 -> 110714.29 | AD23: ='27'!K23 -> 110714.29 | AE23: ='28'!K23 -> 110714.29 | AF23: ='29'!K23 -> 110714.29 | AH23: =AF23-D23 -> 0 | AI23: =AVERAGE(D23:AF23) -> 110714.29
B24: - Daging Sapi Grade Bawah | C24: Kg | D24: ='1'!K24 -> 100000 | E24: ='2'!K24 -> 100000 | F24: ='3'!K24 -> 100000 | G24: ='4'!K24 -> 100000 | H24: ='5'!K24 -> 100000 | I24: ='6'!K24 -> 100000 | J24: ='7'!K24 -> 100000 | K24: ='8'!K24 -> 100000 | L24: ='9'!K24 -> 100000 | M24: ='10'!K24 -> 100000 | N24: ='11'!K24 -> 100000 | O24: ='12'!K24 -> 100000 | P24: ='13'!K24 -> 100000 | Q24: ='14'!K24 -> 100000 | R24: ='15'!K24 -> 100000 | S24: ='16'!K24 -> 100000 | T24: ='17'!K24 -> 100000 | U24: ='18'!K24 -> 100000 | V24: ='19'!K24 -> 100000 | W24: ='20'!K24 -> 100000 | X24: ='21'!K24 -> 100000 | Y24: ='22'!K24 -> 100000 | Z24: ='23'!K24 -> 100000 | AA24: ='24'!K24 -> 100000 | AB24: ='25'!K24 -> 100000 | AC24: ='26'!K24 -> 101428.57 | AD24: ='27'!K24 -> 101428.57 | AE24: ='28'!K24 -> 100000 | AF24: ='29'!K24 -> 100000 | AH24: =AF24-D24 -> 0 | AI24: =AVERAGE(D24:AF24) -> 100098.52
B25: - Daging Ayam Broiler | C25: Kg | D25: ='1'!K25 -> 31714.286 | E25: ='2'!K25 -> 31714.286 | F25: ='3'!K25 -> 31571.429 | G25: ='4'!K25 -> 31714.286 | H25: ='5'!K25 -> 31714.286 | I25: ='6'!K25 -> 31857.143 | J25: ='7'!K25 -> 32428.571 | K25: ='8'!K25 -> 32142.857 | L25: ='9'!K25 -> 32285.714 | M25: ='10'!K25 -> 32714.286 | N25: ='11'!K25 -> 32714.286 | O25: ='12'!K25 -> 33142.857 | P25: ='13'!K25 -> 33142.857 | Q25: ='14'!K25 -> 33000 | R25: ='15'!K25 -> 33571.429 | S25: ='16'!K25 -> 33571.429 | T25: ='17'!K25 -> 33000 | U25: ='18'!K25 -> 32714.286 | V25: ='19'!K25 -> 32857.143 | W25: ='20'!K25 -> 33285.714 | X25: ='21'!K25 -> 33285.714 | Y25: ='22'!K25 -> 32857.143 | Z25: ='23'!K25 -> 33000 | AA25: ='24'!K25 -> 33000 | AB25: ='25'!K25 -> 33000 | AC25: ='26'!K25 -> 33428.571 | AD25: ='27'!K25 -> 33571.429 | AE25: ='28'!K25 -> 33428.571 | AF25: ='29'!K25 -> 33571.429 | AG25: 36750 | AH25: =AF25-D25 -> 1857.1429 | AI25: =AVERAGE(D25:AF25) -> 32758.621
A26: 6 | B26: I K A N | D26: ='1'!K26 -> 0 | E26: ='2'!K26 -> 0 | F26: ='3'!K26 -> 0 | G26: ='4'!K26 -> 0 | H26: ='5'!K26 -> 0 | I26: ='6'!K26 -> 0 | J26: ='7'!K26 -> 0 | K26: ='8'!K26 -> 0 | L26: ='9'!K26 -> 0 | M26: ='10'!K26 -> 0 | N26: ='11'!K26 -> 0 | O26: ='12'!K26 -> 0 | P26: ='13'!K26 -> 0 | Q26: ='14'!K26 -> 0 | R26: ='15'!K26 -> 0 | S26: ='16'!K26 -> 0 | T26: ='17'!K26 -> 0 | U26: ='18'!K26 -> 0 | V26: ='19'!K26 -> 0 | W26: ='20'!K26 -> 0 | X26: ='21'!K26 -> 0 | Y26: ='22'!K26 -> 0 | Z26: ='23'!K26 -> 0 | AA26: ='24'!K26 -> 0 | AB26: ='25'!K26 -> 0 | AC26: ='26'!K26 -> 0 | AD26: ='27'!K26 -> 0 | AE26: ='28'!K26 -> 0 | AF26: ='29'!K26 -> 0 | AH26: =AF26-D26 -> 0 | AI26: =AVERAGE(D26:AF26) -> 0
B27: - Ikan Tongkol Segar (Uk. Sedang) | C27: Kg | D27: ='1'!K27 -> 34000 | E27: ='2'!K27 -> 34000 | F27: ='3'!K27 -> 34000 | G27: ='4'!K27 -> 33600 | H27: ='5'!K27 -> 33600 | I27: ='6'!K27 -> 33600 | J27: ='7'!K27 -> 33400 | K27: ='8'!K27 -> 33800 | L27: ='9'!K27 -> 33800 | M27: ='10'!K27 -> 33800 | N27: ='11'!K27 -> 33800 | O27: ='12'!K27 -> 33800 | P27: ='13'!K27 -> 33800 | Q27: ='14'!K27 -> 33800 | R27: ='15'!K27 -> 33800 | S27: ='16'!K27 -> 33800 | T27: ='17'!K27 -> 33800 | U27: ='18'!K27 -> 33800 | V27: ='19'!K27 -> 33800 | W27: ='20'!K27 -> 33400 | X27: ='21'!K27 -> 33400 | Y27: ='22'!K27 -> 33400 | Z27: ='23'!K27 -> 33400 | AA27: ='24'!K27 -> 33000 | AB27: ='25'!K27 -> 33000 | AC27: ='26'!K27 -> 33000 | AD27: ='27'!K27 -> 33000 | AE27: ='28'!K27 -> 33000 | AF27: ='29'!K27 -> 33000 | AH27: =AF27-D27 -> -1000 | AI27: =AVERAGE(D27:AF27) -> 33565.517
B28: - Ikan Mujair Segar (Uk. Sedang) | C28: Kg | D28: ='1'!K28 -> 30285.714 | E28: ='2'!K28 -> 30285.714 | F28: ='3'!K28 -> 30285.714 | G28: ='4'!K28 -> 30285.714 | H28: ='5'!K28 -> 30285.714 | I28: ='6'!K28 -> 30000 | J28: ='7'!K28 -> 30142.857 | K28: ='8'!K28 -> 30142.857 | L28: ='9'!K28 -> 30142.857 | M28: ='10'!K28 -> 30428.571 | N28: ='11'!K28 -> 30428.571 | O28: ='12'!K28 -> 30142.857 | P28: ='13'!K28 -> 30142.857 | Q28: ='14'!K28 -> 30142.857 | R28: ='15'!K28 -> 30142.857 | S28: ='16'!K28 -> 30142.857 | T28: ='17'!K28 -> 30142.857 | U28: ='18'!K28 -> 30142.857 | V28: ='19'!K28 -> 30142.857 | W28: ='20'!K28 -> 29285.714 | X28: ='21'!K28 -> 29285.714 | Y28: ='22'!K28 -> 29285.714 | Z28: ='23'!K28 -> 28714.286 | AA28: ='24'!K28 -> 28714.286 | AB28: ='25'!K28 -> 28714.286 | AC28: ='26'!K28 -> 28714.286 | AD28: ='27'!K28 -> 28714.286 | AE28: ='28'!K28 -> 30000 | AF28: ='29'!K28 -> 28714.286 | AH28: =AF28-D28 -> -1571.4286 | AI28: =AVERAGE(D28:AF28) -> 29793.103
B29: - Udang Segar (Uk. Sedang) | C29: Kg | D29: ='1'!K29 -> 62571.429 | E29: ='2'!K29 -> 62571.429 | F29: ='3'!K29 -> 61857.143 | G29: ='4'!K29 -> 61857.143 | H29: ='5'!K29 -> 61857.143 | I29: ='6'!K29 -> 61857.143 | J29: ='7'!K29 -> 61857.143 | K29: ='8'!K29 -> 61857.143 | L29: ='9'!K29 -> 61714.286 | M29: ='10'!K29 -> 61857.143 | N29: ='11'!K29 -> 61857.143 | O29: ='12'!K29 -> 61857.143 | P29: ='13'!K29 -> 61857.143 | Q29: ='14'!K29 -> 61857.143 | R29: ='15'!K29 -> 61857.143 | S29: ='16'!K29 -> 62142.857 | T29: ='17'!K29 -> 62142.857 | U29: ='18'!K29 -> 62142.857 | V29: ='19'!K29 -> 62142.857 | W29: ='20'!K29 -> 62142.857 | X29: ='21'!K29 -> 62142.857 | Y29: ='22'!K29 -> 62142.857 | Z29: ='23'!K29 -> 62142.857 | AA29: ='24'!K29 -> 62142.857 | AB29: ='25'!K29 -> 62142.857 | AC29: ='26'!K29 -> 62142.857 | AD29: ='27'!K29 -> 62142.857 | AE29: ='28'!K29 -> 62142.857 | AF29: ='29'!K29 -> 62142.857 | AH29: =AF29-D29 -> -428.57143 | AI29: =AVERAGE(D29:AF29) -> 62039.409
B30: - Ikan Lele Segar (Ukuran Sedang) | C30: Kg | D30: ='1'!K30 -> 24750 | E30: ='2'!K30 -> 24750 | F30: ='3'!K30 -> 24750 | G30: ='4'!K30 -> 24750 | H30: ='5'!K30 -> 24750 | I30: ='6'!K30 -> 24750 | J30: ='7'!K30 -> 24750 | K30: ='8'!K30 -> 24750 | L30: ='9'!K30 -> 24750 | M30: ='10'!K30 -> 24750 | N30: ='11'!K30 -> 24750 | O30: ='12'!K30 -> 24750 | P30: ='13'!K30 -> 24750 | Q30: ='14'!K30 -> 24750 | R30: ='15'!K30 -> 24750 | S30: ='16'!K30 -> 24750 | T30: ='17'!K30 -> 24750 | U30: ='18'!K30 -> 24750 | V30: ='19'!K30 -> 24750 | W30: ='20'!K30 -> 24750 | X30: ='21'!K30 -> 24750 | Y30: ='22'!K30 -> 24750 | Z30: ='23'!K30 -> 24750 | AA30: ='24'!K30 -> 24750 | AB30: ='25'!K30 -> 24750 | AC30: ='26'!K30 -> 24750 | AD30: ='27'!K30 -> 24750 | AE30: ='28'!K30 -> 24750 | AF30: ='29'!K30 -> 24750 | AH30: =AF30-D30 -> 0 | AI30: =AVERAGE(D30:AF30) -> 24750
B31: - Ikan Bandeng Segar (Uk. Sedang) | C31: Kg | D31: ='1'!K31 -> 36571.429 | E31: ='2'!K31 -> 36571.429 | F31: ='3'!K31 -> 36285.714 | G31: ='4'!K31 -> 36285.714 | H31: ='5'!K31 -> 36285.714 | I31: ='6'!K31 -> 36285.714 | J31: ='7'!K31 -> 36285.714 | K31: ='8'!K31 -> 36285.714 | L31: ='9'!K31 -> 35571.429 | M31: ='10'!K31 -> 35000 | N31: ='11'!K31 -> 35000 | O31: ='12'!K31 -> 35714.286 | P31: ='13'!K31 -> 35714.286 | Q31: ='14'!K31 -> 35714.286 | R31: ='15'!K31 -> 35714.286 | S31: ='16'!K31 -> 35571.429 | T31: ='17'!K31 -> 36142.857 | U31: ='18'!K31 -> 36142.857 | V31: ='19'!K31 -> 36142.857 | W31: ='20'!K31 -> 36142.857 | X31: ='21'!K31 -> 36142.857 | Y31: ='22'!K31 -> 36142.857 | Z31: ='23'!K31 -> 36142.857 | AA31: ='24'!K31 -> 36142.857 | AB31: ='25'!K31 -> 35857.143 | AC31: ='26'!K31 -> 35857.143 | AD31: ='27'!K31 -> 34428.571 | AE31: ='28'!K31 -> 35571.429 | AF31: ='29'!K31 -> 34428.571 | AH31: =AF31-D31 -> -2142.8571 | AI31: =AVERAGE(D31:AF31) -> 35866.995
B32: - Ikan Teri Asin (Bukan Teri Medan) | C32: Kg | D32: ='1'!K32 -> 87500 | E32: ='2'!K32 -> 87500 | F32: ='3'!K32 -> 87500 | G32: ='4'!K32 -> 87500 | H32: ='5'!K32 -> 87500 | I32: ='6'!K32 -> 87500 | J32: ='7'!K32 -> 87500 | K32: ='8'!K32 -> 87500 | L32: ='9'!K32 -> 87500 | M32: ='10'!K32 -> 87500 | N32: ='11'!K32 -> 87500 | O32: ='12'!K32 -> 87500 | P32: ='13'!K32 -> 87500 | Q32: ='14'!K32 -> 87500 | R32: ='15'!K32 -> 87500 | S32: ='16'!K32 -> 90000 | T32: ='17'!K32 -> 90000 | U32: ='18'!K32 -> 90000 | V32: ='19'!K32 -> 90000 | W32: ='20'!K32 -> 90000 | X32: ='21'!K32 -> 90000 | Y32: ='22'!K32 -> 90000 | Z32: ='23'!K32 -> 90000 | AA32: ='24'!K32 -> 90000 | AB32: ='25'!K32 -> 90000 | AC32: ='26'!K32 -> 90000 | AD32: ='27'!K32 -> 90000 | AE32: ='28'!K32 -> 90000 | AF32: ='29'!K32 -> 90000 | AH32: =AF32-D32 -> 2500 | AI32: =AVERAGE(D32:AF32) -> 88706.897
A33: 7 | B33: TELUR | D33: ='1'!K33 -> 0 | E33: ='2'!K33 -> 0 | F33: ='3'!K33 -> 0 | G33: ='4'!K33 -> 0 | H33: ='5'!K33 -> 0 | I33: ='6'!K33 -> 0 | J33: ='7'!K33 -> 0 | K33: ='8'!K33 -> 0 | L33: ='9'!K33 -> 0 | M33: ='10'!K33 -> 0 | N33: ='11'!K33 -> 0 | O33: ='12'!K33 -> 0 | P33: ='13'!K33 -> 0 | Q33: ='14'!K33 -> 0 | R33: ='15'!K33 -> 0 | S33: ='16'!K33 -> 0 | T33: ='17'!K33 -> 0 | U33: ='18'!K33 -> 0 | V33: ='19'!K33 -> 0 | W33: ='20'!K33 -> 0 | X33: ='21'!K33 -> 0 | Y33: ='22'!K33 -> 0 | Z33: ='23'!K33 -> 0 | AA33: ='24'!K33 -> 0 | AB33: ='25'!K33 -> 0 | AC33: ='26'!K33 -> 0 | AD33: ='27'!K33 -> 0 | AE33: ='28'!K33 -> 0 | AF33: ='29'!K33 -> 0 | AH33: =AF33-D33 -> 0 | AI33: =AVERAGE(D33:AF33) -> 0
B34: - Telur Ayam Broiler | C34: Kg | D34: ='1'!K34 -> 26000 | E34: ='2'!K34 -> 26142.857 | F34: ='3'!K34 -> 26000 | G34: ='4'!K34 -> 26000 | H34: ='5'!K34 -> 26142.857 | I34: ='6'!K34 -> 26142.857 | J34: ='7'!K34 -> 26285.714 | K34: ='8'!K34 -> 26285.714 | L34: ='9'!K34 -> 26357.143 | M34: ='10'!K34 -> 26571.429 | N34: ='11'!K34 -> 26428.571 | O34: ='12'!K34 -> 26714.286 | P34: ='13'!K34 -> 26571.429 | Q34: ='14'!K34 -> 26571.429 | R34: ='15'!K34 -> 26928.571 | S34: ='16'!K34 -> 26928.571 | T34: ='17'!K34 -> 27357.143 | U34: ='18'!K34 -> 27214.286 | V34: ='19'!K34 -> 27142.857 | W34: ='20'!K34 -> 28000 | X34: ='21'!K34 -> 28000 | Y34: ='22'!K34 -> 27714.286 | Z34: ='23'!K34 -> 27500 | AA34: ='24'!K34 -> 27928.571 | AB34: ='25'!K34 -> 27928.571 | AC34: ='26'!K34 -> 28571.429 | AD34: ='27'!K34 -> 29571.429 | AE34: ='28'!K34 -> 30000 | AF34: ='29'!K34 -> 30000 | AG34: 27000 | AH34: =AF34-D34 -> 4000 | AI34: =AVERAGE(D34:AF34) -> 27206.897
B35: - Telur Ayam Kampung | C35: Butir | D35: ='1'!K35 -> 2742.8571 | E35: ='2'!K35 -> 2757.1429 | F35: ='3'!K35 -> 2757.1429 | G35: ='4'!K35 -> 2757.1429 | H35: ='5'!K35 -> 2757.1429 | I35: ='6'!K35 -> 2757.1429 | J35: ='7'!K35 -> 2757.1429 | K35: ='8'!K35 -> 2757.1429 | L35: ='9'!K35 -> 2757.1429 | M35: ='10'!K35 -> 2757.1429 | N35: ='11'!K35 -> 2757.1429 | O35: ='12'!K35 -> 2757.1429 | P35: ='13'!K35 -> 2757.1429 | Q35: ='14'!K35 -> 2757.1429 | R35: ='15'!K35 -> 2757.1429 | S35: ='16'!K35 -> 2757.1429 | T35: ='17'!K35 -> 2771.4286 | U35: ='18'!K35 -> 2771.4286 | V35: ='19'!K35 -> 2771.4286 | W35: ='20'!K35 -> 2771.4286 | X35: ='21'!K35 -> 2771.4286 | Y35: ='22'!K35 -> 2771.4286 | Z35: ='23'!K35 -> 2771.4286 | AA35: ='24'!K35 -> 2800 | AB35: ='25'!K35 -> 2800 | AC35: ='26'!K35 -> 2800 | AD35: ='27'!K35 -> 2800 | AE35: ='28'!K35 -> 2800 | AF35: ='29'!K35 -> 2800 | AH35: =AF35-D35 -> 57.142857 | AI35: =AVERAGE(D35:AF35) -> 2768.9655
A36: 8 | B36: TAHU | D36: ='1'!K36 -> 0 | E36: ='2'!K36 -> 0 | F36: ='3'!K36 -> 0 | G36: ='4'!K36 -> 0 | H36: ='5'!K36 -> 0 | I36: ='6'!K36 -> 0 | J36: ='7'!K36 -> 0 | K36: ='8'!K36 -> 0 | L36: ='9'!K36 -> 0 | M36: ='10'!K36 -> 0 | N36: ='11'!K36 -> 0 | O36: ='12'!K36 -> 0 | P36: ='13'!K36 -> 0 | Q36: ='14'!K36 -> 0 | R36: ='15'!K36 -> 0 | S36: ='16'!K36 -> 0 | T36: ='17'!K36 -> 0 | U36: ='18'!K36 -> 0 | V36: ='19'!K36 -> 0 | W36: ='20'!K36 -> 0 | X36: ='21'!K36 -> 0 | Y36: ='22'!K36 -> 0 | Z36: ='23'!K36 -> 0 | AA36: ='24'!K36 -> 0 | AB36: ='25'!K36 -> 0 | AC36: ='26'!K36 -> 0 | AD36: ='27'!K36 -> 0 | AE36: ='28'!K36 -> 0 | AF36: ='29'!K36 -> 0 | AH36: =AF36-D36 -> 0 | AI36: =AVERAGE(D36:AF36) -> 0
B37: - Tahu biasa | C37: Kg | D37: ='1'!K37 -> 8178.5714 | E37: ='2'!K37 -> 8178.5714 | F37: ='3'!K37 -> 8178.5714 | G37: ='4'!K37 -> 8178.5714 | H37: ='5'!K37 -> 8178.5714 | I37: ='6'!K37 -> 8178.5714 | J37: ='7'!K37 -> 8178.5714 | K37: ='8'!K37 -> 8178.5714 | L37: ='9'!K37 -> 8178.5714 | M37: ='10'!K37 -> 8178.5714 | N37: ='11'!K37 -> 8178.5714 | O37: ='12'!K37 -> 8178.5714 | P37: ='13'!K37 -> 8178.5714 | Q37: ='14'!K37 -> 8178.5714 | R37: ='15'!K37 -> 8178.5714 | S37: ='16'!K37 -> 8178.5714 | T37: ='17'!K37 -> 8178.5714 | U37: ='18'!K37 -> 8178.5714 | V37: ='19'!K37 -> 8178.5714 | W37: ='20'!K37 -> 8178.5714 | X37: ='21'!K37 -> 8178.5714 | Y37: ='22'!K37 -> 8178.5714 | Z37: ='23'!K37 -> 8178.5714 | AA37: ='24'!K37 -> 8178.5714 | AB37: ='25'!K37 -> 8178.5714 | AC37: ='26'!K37 -> 8178.5714 | AD37: ='27'!K37 -> 8178.5714 | AE37: ='28'!K37 -> 8178.5714 | AF37: ='29'!K37 -> 8178.5714 | AH37: =AF37-D37 -> 0 | AI37: =AVERAGE(D37:AF37) -> 8178.5714
B38: - Tahu susu | C38: Kg | D38: ='1'!K38 -> 12000 | E38: ='2'!K38 -> 12000 | F38: ='3'!K38 -> 12000 | G38: ='4'!K38 -> 12000 | H38: ='5'!K38 -> 12000 | I38: ='6'!K38 -> 12000 | J38: ='7'!K38 -> 12000 | K38: ='8'!K38 -> 12000 | L38: ='9'!K38 -> 12000 | M38: ='10'!K38 -> 12000 | N38: ='11'!K38 -> 12000 | O38: ='12'!K38 -> 12000 | P38: ='13'!K38 -> 12000 | Q38: ='14'!K38 -> 12000 | R38: ='15'!K38 -> 12000 | S38: ='16'!K38 -> 12000 | T38: ='17'!K38 -> 12000 | U38: ='18'!K38 -> 12000 | V38: ='19'!K38 -> 12000 | W38: ='20'!K38 -> 12000 | X38: ='21'!K38 -> 12000 | Y38: ='22'!K38 -> 12000 | Z38: ='23'!K38 -> 12000 | AA38: ='24'!K38 -> 12000 | AB38: ='25'!K38 -> 12000 | AC38: ='26'!K38 -> 12000 | AD38: ='27'!K38 -> 12000 | AE38: ='28'!K38 -> 12000 | AF38: ='29'!K38 -> 12000 | AH38: =AF38-D38 -> 0 | AI38: =AVERAGE(D38:AF38) -> 12000
A39: 9 | B39: TEMPE | D39: ='1'!K39 -> 0 | E39: ='2'!K39 -> 0 | F39: ='3'!K39 -> 0 | G39: ='4'!K39 -> 0 | H39: ='5'!K39 -> 0 | I39: ='6'!K39 -> 0 | J39: ='7'!K39 -> 0 | K39: ='8'!K39 -> 0 | L39: ='9'!K39 -> 0 | M39: ='10'!K39 -> 0 | N39: ='11'!K39 -> 0 | O39: ='12'!K39 -> 0 | P39: ='13'!K39 -> 0 | Q39: ='14'!K39 -> 0 | R39: ='15'!K39 -> 0 | S39: ='16'!K39 -> 0 | T39: ='17'!K39 -> 0 | U39: ='18'!K39 -> 0 | V39: ='19'!K39 -> 0 | W39: ='20'!K39 -> 0 | X39: ='21'!K39 -> 0 | Y39: ='22'!K39 -> 0 | Z39: ='23'!K39 -> 0 | AA39: ='24'!K39 -> 0 | AB39: ='25'!K39 -> 0 | AC39: ='26'!K39 -> 0 | AD39: ='27'!K39 -> 0 | AE39: ='28'!K39 -> 0 | AF39: ='29'!K39 -> 0 | AH39: =AF39-D39 -> 0 | AI39: =AVERAGE(D39:AF39) -> 0
B40: - Tempe Kw I (campuran kedelai) | C40: Kg | D40: ='1'!K40 -> 15000 | E40: ='2'!K40 -> 15000 | F40: ='3'!K40 -> 15000 | G40: ='4'!K40 -> 15000 | H40: ='5'!K40 -> 15000 | I40: ='6'!K40 -> 15000 | J40: ='7'!K40 -> 15000 | K40: ='8'!K40 -> 15000 | L40: ='9'!K40 -> 15000 | M40: ='10'!K40 -> 15000 | N40: ='11'!K40 -> 15000 | O40: ='12'!K40 -> 15000 | P40: ='13'!K40 -> 15000 | Q40: ='14'!K40 -> 15000 | R40: ='15'!K40 -> 15000 | S40: ='16'!K40 -> 15000 | T40: ='17'!K40 -> 15000 | U40: ='18'!K40 -> 15000 | V40: ='19'!K40 -> 15000 | W40: ='20'!K40 -> 15000 | X40: ='21'!K40 -> 15000 | Y40: ='22'!K40 -> 15000 | Z40: ='23'!K40 -> 15000 | AA40: ='24'!K40 -> 15000 | AB40: ='25'!K40 -> 15000 | AC40: ='26'!K40 -> 15000 | AD40: ='27'!K40 -> 15000 | AE40: ='28'!K40 -> 15000 | AF40: ='29'!K40 -> 15000 | AH40: =AF40-D40 -> 0 | AI40: =AVERAGE(D40:AF40) -> 15000
B41: - Tempe Kw II (campuran jagung) | C41: Kg | D41: ='1'!K41 -> 6000 | E41: ='2'!K41 -> 6000 | F41: ='3'!K41 -> 6000 | G41: ='4'!K41 -> 6000 | H41: ='5'!K41 -> 6000 | I41: ='6'!K41 -> 6000 | J41: ='7'!K41 -> 6000 | K41: ='8'!K41 -> 6000 | L41: ='9'!K41 -> 6000 | M41: ='10'!K41 -> 6000 | N41: ='11'!K41 -> 6000 | O41: ='12'!K41 -> 6000 | P41: ='13'!K41 -> 6000 | Q41: ='14'!K41 -> 6000 | R41: ='15'!K41 -> 6000 | S41: ='16'!K41 -> 6000 | T41: ='17'!K41 -> 6000 | U41: ='18'!K41 -> 6000 | V41: ='19'!K41 -> 6000 | W41: ='20'!K41 -> 6000 | X41: ='21'!K41 -> 6000 | Y41: ='22'!K41 -> 6000 | Z41: ='23'!K41 -> 6000 | AA41: ='24'!K41 -> 6000 | AB41: ='25'!K41 -> 6000 | AC41: ='26'!K41 -> 6000 | AD41: ='27'!K41 -> 6000 | AE41: ='28'!K41 -> 6000 | AF41: ='29'!K41 -> 6000 | AH41: =AF41-D41 -> 0 | AI41: =AVERAGE(D41:AF41) -> 6000
...

Sheet GRAFIK
C2: 1 | D2: 2 | E2: 3 | F2: 4 | G2: 5 | H2: 6 | I2: 7 | J2: 8 | K2: 9 | L2: 10 | M2: 11 | N2: 12 | O2: 13 | P2: 14 | Q2: 15 | R2: 16 | S2: 17 | T2: 18 | U2: 19 | V2: 20 | W2: 21 | X2: 22 | Y2: 23 | Z2: 24 | AA2: 25 | AB2: 26 | AC2: 27 | AD2: 28 | AE2: 29 | AF2: 30 | AG2: 31
A3: - Beras IR.64 Kwalitas I | B3: Kg | C3: ='1'!K8 -> 14000 | D3: ='2'!K8 -> 14285.714 | E3: ='3'!K8 -> 14314.286 | F3: ='4'!K8 -> 14300 | G3: ='5'!K8 -> 15071.429 | H3: ='6'!K8 -> 15285.714 | I3: ='7'!K8 -> 15357.143 | J3: ='8'!K8 -> 15428.571 | K3: ='9'!K8 -> 15142.857 | L3: ='10'!K8 -> 15500 | M3: ='11'!K8 -> 15500 | N3: ='12'!K8 -> 16071.429 | O3: ='13'!K8 -> 16071.429 | P3: ='14'!K8 -> 16071.429 | Q3: ='15'!K8 -> 16071.429 | R3: ='16'!K8 -> 16071.429 | S3: ='17'!K8 -> 16071.429 | T3: ='18'!K8 -> 16071.429 | U3: ='19'!K8 -> 16071.429 | V3: ='20'!K8 -> 16142.857 | W3: ='21'!K8 -> 16142.857 | X3: ='22'!K8 -> 16142.857 | Y3: ='23'!K8 -> 16142.857 | Z3: ='24'!K8 -> 16142.857 | AA3: ='25'!K8 -> 16142.857 | AB3: ='26'!K8 -> 16142.857 | AC3: ='27'!K8 -> 16157.143 | AD3: ='28'!K8 -> 16171.429 | AE3: =#REF! -> #REF! | AF3: =#REF! -> #REF! | AG3: =#REF! -> #REF!
A4: - Beras IR.64 Kwalitas II | B4: Kg | C4: ='1'!K9 -> 10900 | D4: ='2'!K9 -> 11083.333 | E4: ='3'!K9 -> 11083.333 | F4: ='4'!K9 -> 11083.333 | G4: ='5'!K9 -> 11083.333 | H4: ='6'!K9 -> 11083.333 | I4: ='7'!K9 -> 11083.333 | J4: ='8'!K9 -> 11083.333 | K4: ='9'!K9 -> 11083.333 | L4: ='10'!K9 -> 11083.333 | M4: ='11'!K9 -> 11083.333 | N4: ='12'!K9 -> 11083.333 | O4: ='13'!K9 -> 11083.333 | P4: ='14'!K9 -> 11083.333 | Q4: ='15'!K9 -> 11083.333 | R4: ='16'!K9 -> 11600 | S4: ='17'!K9 -> 11600 | T4: ='18'!K9 -> 11600 | U4: ='19'!K9 -> 11600 | V4: ='20'!K9 -> 11766.667 | W4: ='21'!K9 -> 11766.667 | X4: ='22'!K9 -> 11933.333 | Y4: ='23'!K9 -> 10900 | Z4: ='24'!K9 -> 10900 | AA4: ='25'!K9 -> 10900 | AB4: ='26'!K9 -> 10900 | AC4: ='27'!K9 -> 10900 | AD4: ='28'!K9 -> 10900 | AE4: =#REF! -> #REF! | AF4: =#REF! -> #REF! | AG4: =#REF! -> #REF!
A5: - Beras IR.64 Kwalitas III | B5: Kg | C5: ='1'!K10 -> 0 | D5: ='2'!K10 -> 0 | E5: ='3'!K10 -> 0 | F5: ='4'!K10 -> 0 | G5: ='5'!K10 -> 0 | H5: ='6'!K10 -> 0 | I5: ='7'!K10 -> 0 | J5: ='8'!K10 -> 0 | K5: ='9'!K10 -> 0 | L5: ='10'!K10 -> 0 | M5: ='11'!K10 -> 0 | N5: ='12'!K10 -> 0 | O5: ='13'!K10 -> 0 | P5: ='14'!K10 -> 0 | Q5: ='15'!K10 -> 0 | R5: ='16'!K10 -> 0 | S5: ='17'!K10 -> 0 | T5: ='18'!K10 -> 0 | U5: ='19'!K10 -> 0 | V5: ='20'!K10 -> 0 | W5: ='21'!K10 -> 0 | X5: ='22'!K10 -> 0 | Y5: ='23'!K10 -> 14000 | Z5: ='24'!K10 -> 13000 | AA5: ='25'!K10 -> 13000 | AB5: ='26'!K10 -> 13000 | AC5: ='27'!K10 -> 13000 | AD5: ='28'!K10 -> 13000 | AE5: =#REF! -> #REF! | AF5: =#REF! -> #REF! | AG5: =#REF! -> #REF!
C24: 1 | D24: 2 | E24: 3 | F24: 4 | G24: 5 | H24: 6 | I24: 7 | J24: 8 | K24: 9 | L24: 10 | M24: 11 | N24: 12 | O24: 13 | P24: 14 | Q24: 15 | R24: 16 | S24: 17 | T24: 18 | U24: 19 | V24: 20 | W24: 21 | X24: 22 | Y24: 23 | Z24: 24 | AA24: 25 | AB24: 26 | AC24: 27 | AD24: 28 | AE24: 29 | AF24: 30 | AG24: 31
A25: Gula Pasir Lokal Curah | B25: Kg | C25: ='1'!K14 -> 16285.714 | D25: ='2'!K14 -> 16285.714 | E25: ='3'!K14 -> 16214.286 | F25: ='4'!K14 -> 16214.286 | G25: ='5'!K14 -> 16214.286 | H25: ='6'!K14 -> 16214.286 | I25: ='7'!K14 -> 16214.286 | J25: ='8'!K14 -> 16214.286 | K25: ='9'!K14 -> 16214.286 | L25: ='10'!K14 -> 16214.286 | M25: ='11'!K14 -> 16214.286 | N25: ='12'!K14 -> 16285.714 | O25: ='13'!K14 -> 16285.714 | P25: ='14'!K14 -> 16285.714 | Q25: ='15'!K14 -> 16285.714 | R25: ='16'!K14 -> 16285.714 | S25: ='17'!K14 -> 16285.714 | T25: ='18'!K14 -> 16285.714 | U25: ='19'!K14 -> 16285.714 | V25: ='20'!K14 -> 16428.571 | W25: ='21'!K14 -> 16428.571 | X25: ='22'!K14 -> 16428.571 | Y25: ='23'!K14 -> 16500 | Z25: ='24'!K14 -> 16500 | AA25: ='25'!K14 -> 16500 | AB25: ='26'!K14 -> 16500 | AC25: ='27'!K14 -> 16642.857 | AD25: ='28'!K14 -> 16642.857 | AE25: =#REF! -> #REF! | AF25: =#REF! -> #REF! | AG25: =#REF! -> #REF!
C46: 1 | D46: 2 | E46: 3 | F46: 4 | G46: 5 | H46: 6 | I46: 7 | J46: 8 | K46: 9 | L46: 10 | M46: 11 | N46: 12 | O46: 13 | P46: 14 | Q46: 15 | R46: 16 | S46: 17 | T46: 18 | U46: 19 | V46: 20 | W46: 21 | X46: 22 | Y46: 23 | Z46: 24 | AA46: 25 | AB46: 26 | AC46: 27 | AD46: 28 | AE46: 29 | AF46: 30 | AG46: 31
A47: - Minyak Goreng Curah (Bening) | B47: Kg | C47: ='1'!K17 -> 15142.857 | D47: ='2'!K17 -> 15285.714 | E47: ='3'!K17 -> 15285.714 | F47: ='4'!K17 -> 15285.714 | G47: ='5'!K17 -> 15285.714 | H47: ='6'!K17 -> 15285.714 | I47: ='7'!K17 -> 15285.714 | J47: ='8'!K17 -> 15285.714 | K47: ='9'!K17 -> 15285.714 | L47: ='10'!K17 -> 15285.714 | M47: ='11'!K17 -> 15285.714 | N47: ='12'!K17 -> 15285.714 | O47: ='13'!K17 -> 15285.714 | P47: ='14'!K17 -> 15285.714 | Q47: ='15'!K17 -> 15285.714 | R47: ='16'!K17 -> 15357.143 | S47: ='17'!K17 -> 15357.143 | T47: ='18'!K17 -> 15357.143 | U47: ='19'!K17 -> 15285.714 | V47: ='20'!K17 -> 15571.429 | W47: ='21'!K17 -> 15571.429 | X47: ='22'!K17 -> 15571.429 | Y47: ='23'!K17 -> 15642.857 | Z47: ='24'!K17 -> 15642.857 | AA47: ='25'!K17 -> 15642.857 | AB47: ='26'!K17 -> 15642.857 | AC47: ='27'!K17 -> 15642.857 | AD47: ='28'!K17 -> 15642.857 | AE47: =#REF! -> #REF! | AF47: =#REF! -> #REF! | AG47: =#REF! -> #REF!
C75: 1 | D75: 2 | E75: 3 | F75: 4 | G75: 5 | H75: 6 | I75: 7 | J75: 8 | K75: 9 | L75: 10 | M75: 11 | N75: 12 | O75: 13 | P75: 14 | Q75: 15 | R75: 16 | S75: 17 | T75: 18 | U75: 19 | V75: 20 | W75: 21 | X75: 22 | Y75: 23 | Z75: 24 | AA75: 25 | AB75: 26 | AC75: 27 | AD75: 28 | AE75: 29 | AF75: 30 | AG75: 31
A76: - Daging Ayam Broiler | B76: Kg | C76: ='1'!K24 -> 100000 | D76: ='2'!K24 -> 100000 | E76: ='3'!K24 -> 100000 | F76: ='4'!K24 -> 100000 | G76: ='5'!K24 -> 100000 | H76: ='6'!K24 -> 100000 | I76: ='7'!K24 -> 100000 | J76: ='8'!K24 -> 100000 | K76: ='9'!K24 -> 100000 | L76: ='10'!K24 -> 100000 | M76: ='11'!K24 -> 100000 | N76: ='12'!K24 -> 100000 | O76: ='13'!K24 -> 100000 | P76: ='14'!K24 -> 100000 | Q76: ='15'!K24 -> 100000 | R76: ='16'!K24 -> 100000 | S76: ='17'!K24 -> 100000 | T76: ='18'!K24 -> 100000 | U76: ='19'!K24 -> 100000 | V76: ='20'!K24 -> 100000 | W76: ='21'!K24 -> 100000 | X76: ='22'!K24 -> 100000 | Y76: ='23'!K24 -> 100000 | Z76: ='24'!K24 -> 100000 | AA76: ='25'!K24 -> 100000 | AB76: ='26'!K24 -> 101428.57 | AC76: ='27'!K24 -> 101428.57 | AD76: ='28'!K24 -> 100000 | AE76: =#REF! -> #REF! | AF76: =#REF! -> #REF! | AG76: =#REF! -> #REF!
C96: 1 | D96: 2 | E96: 3 | F96: 4 | G96: 5 | H96: 6 | I96: 7 | J96: 8 | K96: 9 | L96: 10 | M96: 11 | N96: 12 | O96: 13 | P96: 14 | Q96: 15 | R96: 16 | S96: 17 | T96: 18 | U96: 19 | V96: 20 | W96: 21 | X96: 22 | Y96: 23 | Z96: 24 | AA96: 25 | AB96: 26 | AC96: 27 | AD96: 28 | AE96: 29 | AF96: 30 | AG96: 31
A97: - Telur Ayam Horn | B97: Kg | C97: ='1'!K33 -> 0 | D97: ='2'!K33 -> 0 | E97: ='3'!K33 -> 0 | F97: ='4'!K33 -> 0 | G97: ='5'!K33 -> 0 | H97: ='6'!K33 -> 0 | I97: ='7'!K33 -> 0 | J97: ='8'!K33 -> 0 | K97: ='9'!K33 -> 0 | L97: ='10'!K33 -> 0 | M97: ='11'!K33 -> 0 | N97: ='12'!K33 -> 0 | O97: ='13'!K33 -> 0 | P97: ='14'!K33 -> 0 | Q97: ='15'!K33 -> 0 | R97: ='16'!K33 -> 0 | S97: ='17'!K33 -> 0 | T97: ='18'!K33 -> 0 | U97: ='19'!K33 -> 0 | V97: ='20'!K33 -> 0 | W97: ='21'!K33 -> 0 | X97: ='22'!K33 -> 0 | Y97: ='23'!K33 -> 0 | Z97: ='24'!K33 -> 0 | AA97: ='25'!K33 -> 0 | AB97: ='26'!K33 -> 0 | AC97: ='27'!K33 -> 0 | AD97: ='28'!K33 -> 0 | AE97: =#REF! -> #REF! | AF97: =#REF! -> #REF! | AG97: =#REF! -> #REF!
C116: 1 | D116: 2 | E116: 3 | F116: 4 | G116: 5 | H116: 6 | I116: 7 | J116: 8 | K116: 9 | L116: 10 | M116: 11 | N116: 12 | O116: 13 | P116: 14 | Q116: 15 | R116: 16 | S116: 17 | T116: 18 | U116: 19 | V116: 20 | W116: 21 | X116: 22 | Y116: 23 | Z116: 24 | AA116: 25 | AB116: 26 | AC116: 27 | AD116: 28 | AE116: 29 | AF116: 30 | AG116: 31
A117: - Garam Halus (Cap Kapal) | B117: 250 Gr/Bngks | C117: ='1'!K45 -> 12500 | D117: ='2'!K45 -> 12500 | E117: ='3'!K45 -> 12500 | F117: ='4'!K45 -> 12500 | G117: ='5'!K45 -> 12500 | H117: ='6'!K45 -> 12500 | I117: ='7'!K45 -> 12500 | J117: ='8'!K45 -> 12500 | K117: ='9'!K45 -> 12500 | L117: ='10'!K45 -> 12500 | M117: ='11'!K45 -> 12500 | N117: ='12'!K45 -> 12500 | O117: ='13'!K45 -> 12500 | P117: ='14'!K45 -> 12500 | Q117: ='15'!K45 -> 12500 | R117: ='16'!K45 -> 12500 | S117: ='17'!K45 -> 12500 | T117: ='18'!K45 -> 12500 | U117: ='19'!K45 -> 12500 | V117: ='20'!K45 -> 12500 | W117: ='21'!K45 -> 12500 | X117: ='22'!K45 -> 12500 | Y117: ='23'!K45 -> 12500 | Z117: ='24'!K45 -> 12500 | AA117: ='25'!K45 -> 12500 | AB117: ='26'!K45 -> 12500 | AC117: ='27'!K45 -> 12500 | AD117: ='28'!K45 -> 12500 | AE117: =#REF! -> #REF! | AF117: =#REF! -> #REF! | AG117: =#REF! -> #REF!
C149: 1 | D149: 2 | E149: 3 | F149: 4 | G149: 5 | H149: 6 | I149: 7 | J149: 8 | K149: 9 | L149: 10 | M149: 11 | N149: 12 | O149: 13 | P149: 14 | Q149: 15 | R149: 16 | S149: 17 | T149: 18 | U149: 19 | V149: 20 | W149: 21 | X149: 22 | Y149: 23 | Z149: 24 | AA149: 25 | AB149: 26 | AC149: 27 | AD149: 28 | AE149: 29 | AF149: 30 | AG149: 31
A150: - Kacang Kedelai (Kualitas Import) | B150: Kg | C150: ='1'!K49 -> 0 | D150: ='2'!K49 -> 0 | E150: ='3'!K49 -> 0 | F150: ='4'!K49 -> 0 | G150: ='5'!K49 -> 0 | H150: ='6'!K49 -> 0 | I150: ='7'!K49 -> 0 | J150: ='8'!K49 -> 0 | K150: ='9'!K49 -> 0 | L150: ='10'!K49 -> 0 | M150: ='11'!K49 -> 0 | N150: ='12'!K49 -> 0 | O150: ='13'!K49 -> 0 | P150: ='14'!K49 -> 0 | Q150: ='15'!K49 -> 0 | R150: ='16'!K49 -> 0 | S150: ='17'!K49 -> 0 | T150: ='18'!K49 -> 0 | U150: ='19'!K49 -> 0 | V150: ='20'!K49 -> 0 | W150: ='21'!K49 -> 0 | X150: ='22'!K49 -> 0 | Y150: ='23'!K49 -> 0 | Z150: ='24'!K49 -> 0 | AA150: ='25'!K49 -> 0 | AB150: ='26'!K49 -> 0 | AC150: ='27'!K49 -> 0 | AD150: ='28'!K49 -> 0 | AE150: =#REF! -> #REF! | AF150: =#REF! -> #REF! | AG150: =#REF! -> #REF!
C169: 1 | D169: 2 | E169: 3 | F169: 4 | G169: 5 | H169: 6 | I169: 7 | J169: 8 | K169: 9 | L169: 10 | M169: 11 | N169: 12 | O169: 13 | P169: 14 | Q169: 15 | R169: 16 | S169: 17 | T169: 18 | U169: 19 | V169: 20 | W169: 21 | X169: 22 | Y169: 23 | Z169: 24 | AA169: 25 | AB169: 26 | AC169: 27 | AD169: 28 | AE169: 29 | AF169: 30 | AG169: 31
A170: - Cabe Merah Besar | B170: Kg | C170: ='1'!K56 -> 0 | D170: ='2'!K56 -> 0 | E170: ='3'!K56 -> 0 | F170: ='4'!K56 -> 0 | G170: ='5'!K56 -> 0 | H170: ='6'!K56 -> 0 | I170: ='7'!K56 -> 0 | J170: ='8'!K56 -> 0 | K170: ='9'!K56 -> 0 | L170: ='10'!K56 -> 0 | M170: ='11'!K56 -> 0 | N170: ='12'!K56 -> 0 | O170: ='13'!K56 -> 0 | P170: ='14'!K56 -> 0 | Q170: ='15'!K56 -> 0 | R170: ='16'!K56 -> 0 | S170: ='17'!K56 -> 0 | T170: ='18'!K56 -> 0 | U170: ='19'!K56 -> 0 | V170: ='20'!K56 -> 0 | W170: ='21'!K56 -> 0 | X170: ='22'!K56 -> 0 | Y170: ='23'!K56 -> 0 | Z170: ='24'!K56 -> 0 | AA170: ='25'!K56 -> 0 | AB170: ='26'!K56 -> 0 | AC170: ='27'!K56 -> 0 | AD170: ='28'!K56 -> 0 | AE170: =#REF! -> #REF! | AF170: =#REF! -> #REF! | AG170: =#REF! -> #REF!
A171: - Cabe Merah Kriting | B171: Kg | C171: ='1'!K57 -> 13916.667 | D171: ='2'!K57 -> 13916.667 | E171: ='3'!K57 -> 14250 | F171: ='4'!K57 -> 14250 | G171: ='5'!K57 -> 14250 | H171: ='6'!K57 -> 14250 | I171: ='7'!K57 -> 14250 | J171: ='8'!K57 -> 14250 | K171: ='9'!K57 -> 14250 | L171: ='10'!K57 -> 14250 | M171: ='11'!K57 -> 14250 | N171: ='12'!K57 -> 14250 | O171: ='13'!K57 -> 14250 | P171: ='14'!K57 -> 14250 | Q171: ='15'!K57 -> 14250 | R171: ='16'!K57 -> 14250 | S171: ='17'!K57 -> 14250 | T171: ='18'!K57 -> 14250 | U171: ='19'!K57 -> 14250 | V171: ='20'!K57 -> 14250 | W171: ='21'!K57 -> 14250 | X171: ='22'!K57 -> 14250 | Y171: ='23'!K57 -> 14250 | Z171: ='24'!K57 -> 14250 | AA171: ='25'!K57 -> 14250 | AB171: ='26'!K57 -> 14250 | AC171: ='27'!K57 -> 14250 | AD171: ='28'!K57 -> 14250 | AE171: =#REF! -> #REF! | AF171: =#REF! -> #REF! | AG171: =#REF! -> #REF!
A172: - Cabe Merah Kecil-Rawit | B172: Kg | C172: ='1'!K58 -> 14000 | D172: ='2'!K58 -> 14000 | E172: ='3'!K58 -> 14250 | F172: ='4'!K58 -> 14250 | G172: ='5'!K58 -> 14250 | H172: ='6'!K58 -> 14250 | I172: ='7'!K58 -> 14250 | J172: ='8'!K58 -> 14250 | K172: ='9'!K58 -> 14250 | L172: ='10'!K58 -> 14250 | M172: ='11'!K58 -> 14250 | N172: ='12'!K58 -> 14250 | O172: ='13'!K58 -> 14250 | P172: ='14'!K58 -> 14250 | Q172: ='15'!K58 -> 14250 | R172: ='16'!K58 -> 14250 | S172: ='17'!K58 -> 14250 | T172: ='18'!K58 -> 14250 | U172: ='19'!K58 -> 14250 | V172: ='20'!K58 -> 14250 | W172: ='21'!K58 -> 14250 | X172: ='22'!K58 -> 14250 | Y172: ='23'!K58 -> 14250 | Z172: ='24'!K58 -> 14250 | AA172: ='25'!K58 -> 14250 | AB172: ='26'!K58 -> 14250 | AC172: ='27'!K58 -> 14250 | AD172: ='28'!K58 -> 14250 | AE172: =#REF! -> #REF! | AF172: =#REF! -> #REF! | AG172: =#REF! -> #REF!
C193: 1 | D193: 2 | E193: 3 | F193: 4 | G193: 5 | H193: 6 | I193: 7 | J193: 8 | K193: 9 | L193: 10 | M193: 11 | N193: 12 | O193: 13 | P193: 14 | Q193: 15 | R193: 16 | S193: 17 | T193: 18 | U193: 19 | V193: 20 | W193: 21 | X193: 22 | Y193: 23 | Z193: 24 | AA193: 25 | AB193: 26 | AC193: 27 | AD193: 28 | AE193: 29 | AF193: 30 | AG193: 31
A194: - Bawang Putih (Jenis Kating) | B194: Kg | C194: ='1'!K62 -> 3116.6667 | D194: ='2'!K62 -> 3116.6667 | E194: ='3'!K62 -> 3116.6667 | F194: ='4'!K62 -> 3116.6667 | G194: ='5'!K62 -> 3116.6667 | H194: ='6'!K62 -> 3116.6667 | I194: ='7'!K62 -> 3116.6667 | J194: ='8'!K62 -> 3116.6667 | K194: ='9'!K62 -> 3116.6667 | L194: ='10'!K62 -> 3116.6667 | M194: ='11'!K62 -> 3116.6667 | N194: ='12'!K62 -> 3116.6667 | O194: ='13'!K62 -> 3116.6667 | P194: ='14'!K62 -> 3116.6667 | Q194: ='15'!K62 -> 3116.6667 | R194: ='16'!K62 -> 3116.6667 | S194: ='17'!K62 -> 3116.6667 | T194: ='18'!K62 -> 3116.6667 | U194: ='19'!K62 -> 3116.6667 | V194: ='20'!K62 -> 3116.6667 | W194: ='21'!K62 -> 3116.6667 | X194: ='22'!K62 -> 3116.6667 | Y194: ='23'!K62 -> 3116.6667 | Z194: ='24'!K62 -> 3116.6667 | AA194: ='25'!K62 -> 3116.6667 | AB194: ='26'!K62 -> 3116.6667 | AC194: ='27'!K62 -> 3116.6667 | AD194: ='28'!K62 -> 3116.6667 | AE194: =#REF! -> #REF! | AF194: =#REF! -> #REF! | AG194: =#REF! -> #REF!
A195: - Bawang Putih (Jenis Sinco) | B195: Kg | C195: ='1'!K63 -> 0 | D195: ='2'!K63 -> 0 | E195: ='3'!K63 -> 0 | F195: ='4'!K63 -> 0 | G195: ='5'!K63 -> 0 | H195: ='6'!K63 -> 0 | I195: ='7'!K63 -> 0 | J195: ='8'!K63 -> 0 | K195: ='9'!K63 -> 0 | L195: ='10'!K63 -> 0 | M195: ='11'!K63 -> 0 | N195: ='12'!K63 -> 0 | O195: ='13'!K63 -> 0 | P195: ='14'!K63 -> 0 | Q195: ='15'!K63 -> 0 | R195: ='16'!K63 -> 0 | S195: ='17'!K63 -> 0 | T195: ='18'!K63 -> 0 | U195: ='19'!K63 -> 0 | V195: ='20'!K63 -> 0 | W195: ='21'!K63 -> 0 | X195: ='22'!K63 -> 0 | Y195: ='23'!K63 -> 0 | Z195: ='24'!K63 -> 0 | AA195: ='25'!K63 -> 0 | AB195: ='26'!K63 -> 0 | AC195: ='27'!K63 -> 0 | AD195: ='28'!K63 -> 0 | AE195: =#REF! -> #REF! | AF195: =#REF! -> #REF! | AG195: =#REF! -> #REF!
A196: - Bawang Merah (Kualitas Lokal) | B196: Kg | C196: ='1'!K64 -> 63285.714 | D196: ='2'!K64 -> 62571.429 | E196: ='3'!K64 -> 65571.429 | F196: ='4'!K64 -> 66571.429 | G196: ='5'!K64 -> 68714.286 | H196: ='6'!K64 -> 65000 | I196: ='7'!K64 -> 65285.714 | J196: ='8'!K64 -> 64571.429 | K196: ='9'!K64 -> 62857.143 | L196: ='10'!K64 -> 67000 | M196: ='11'!K64 -> 66428.571 | N196: ='12'!K64 -> 65000 | O196: ='13'!K64 -> 65000 | P196: ='14'!K64 -> 65000 | Q196: ='15'!K64 -> 72000 | R196: ='16'!K64 -> 71000 | S196: ='17'!K64 -> 71714.286 | T196: ='18'!K64 -> 71714.286 | U196: ='19'!K64 -> 75000 | V196: ='20'!K64 -> 75714.286 | W196: ='21'!K64 -> 77142.857 | X196: ='22'!K64 -> 82142.857 | Y196: ='23'!K64 -> 81714.286 | Z196: ='24'!K64 -> 80285.714 | AA196: ='25'!K64 -> 81000 | AB196: ='26'!K64 -> 81000 | AC196: ='27'!K64 -> 78857.143 | AD196: ='28'!K64 -> 79714.286 | AE196: =#REF! -> #REF! | AF196: =#REF! -> #REF! | AG196: =#REF! -> #REF!
A197: - Bawang Bombay | B197: Kg | C197: ='1'!K65 -> 50428.571 | D197: ='2'!K65 -> 47857.143 | E197: ='3'!K65 -> 51000 | F197: ='4'!K65 -> 52857.143 | G197: ='5'!K65 -> 52857.143 | H197: ='6'!K65 -> 54000 | I197: ='7'!K65 -> 56142.857 | J197: ='8'!K65 -> 56000 | K197: ='9'!K65 -> 55714.286 | L197: ='10'!K65 -> 55285.714 | M197: ='11'!K65 -> 56714.286 | N197: ='12'!K65 -> 56857.143 | O197: ='13'!K65 -> 58571.429 | P197: ='14'!K65 -> 57857.143 | Q197: ='15'!K65 -> 62142.857 | R197: ='16'!K65 -> 66714.286 | S197: ='17'!K65 -> 67428.571 | T197: ='18'!K65 -> 66714.286 | U197: ='19'!K65 -> 64857.143 | V197: ='20'!K65 -> 67857.143 | W197: ='21'!K65 -> 70000 | X197: ='22'!K65 -> 73571.429 | Y197: ='23'!K65 -> 78142.857 | Z197: ='24'!K65 -> 76714.286 | AA197: ='25'!K65 -> 78142.857 | AB197: ='26'!K65 -> 72428.571 | AC197: ='27'!K65 -> 69571.429 | AD197: ='28'!K65 -> 65285.714 | AE197: =#REF! -> #REF! | AF197: =#REF! -> #REF! | AG197: =#REF! -> #REF!

Sheet 1
A1: HARGA BAHAN-BAHAN POKOK
A2: DI PASAR TRADISIONAL KOTA SURABAYA
A3: HARI / TANGGAL : Kamis / 01 Februari 2024
B4: NAMA BAHAN POKOK DAN PENTING LAINNYA | C4: SATUAN | D4: Pasar Tambahrejo | E4: Pasar Pucang Anom | F4: Pasar Wonokromo | G4: Pasar Genteng Baru | H4: Pasar Pabean | I4: Pasar Kembang | J4: Pasar Balongsari | K4: Rata-Rata
A7: 1 | B7: BERAS
B8: - Beras Premium | C8: Kg | D8: 14000 | E8: 14000 | F8: 14000 | G8: 14000 | H8: 14000 | I8: 14000 | J8: 14000 | K8: =AVERAGE(D8:J8) -> 14000
B9: - Beras Medium Bulog | C9: Kg | D9: 10900 | E9: 10900 | F9: 10900 | G9: 10900 | H9: 10900 | I9: 10900 | J9: - | K9: =AVERAGE(D9:J9) -> 10900
B10: - Beras Medium | C10: Kg | D10: - | E10: - | F10: - | G10: - | H10: - | I10: - | J10: - | K10: 0
B11: - Beras Jagung | C11: Kg | D11: - | E11: 10000 | F11: 12000 | G11: 10000 | H11: 10000 | I11: 12000 | J11: 10000 | K11: =AVERAGE(D11:J11) -> 10666.667
B12: - Beras Ketan (Jenis Siyem) | C12: Kg | D12: - | E12: 21000 | F12: 16000 | G12: 18000 | H12: 25000 | I12: 17000 | J12: 17000 | K12: =AVERAGE(D12:J12) -> 19000
A13: 2 | B13: GULA
B14: - Gula pasir lokal curah | C14: Kg | D14: 16000 | E14: 16000 | F14: 16000 | G14: 16000 | H14: 16500 | I14: 17000 | J14: 16500 | K14: =AVERAGE(D14:J14) -> 16285.714
B15: - Gula Jawa/Merah (Bahan Kelapa) | C15: Kg | D15: 17000 | E15: 16000 | F15: 16000 | G15: 16000 | H15: 17000 | I15: 16000 | J15: 18000 | K15: =AVERAGE(D15:J15) -> 16571.429
A16: 3 | B16: MINYAK GORENG
B17: - Minyak Goreng Curah (Bening) | C17: Kg | D17: 15000 | E17: 15000 | F17: 14000 | G17: 15000 | H17: 15000 | I17: 16000 | J17: 16000 | K17: =AVERAGE(D17:J17) -> 15142.857
B18: - Minyak Kita | C18: Liter | D18: 14000 | E18: 14000 | F18: 14000 | G18: 14000 | H18: - | I18: 14000 | J18: 14000 | K18: =AVERAGE(D18:J18) -> 14000
A19: 4 | B19: MENTEGA
B20: - Mentega Curah (Amanda) | C20: Kg | D20: 20000 | E20: 20000 | F20: 20000 | G20: 22000 | H20: 33000 | I20: 20000 | J20: - | K20: =AVERAGE(D20:J20) -> 22500
A21: 5 | B21: DAGING
B22: - Daging Sapi Grade Atas | C22: Kg | D22: 120000 | E22: 120000 | F22: 120000 | G22: 120000 | H22: 120000 | I22: 120000 | J22: - | K22: =AVERAGE(D22:J22) -> 120000
B23: - Daging Sapi Grade Sedang | C23: Kg | D23: 110000 | E23: 110000 | F23: 110000 | G23: 110000 | H23: 115000 | I23: 110000 | J23: 110000 | K23: =AVERAGE(D23:J23) -> 110714.29
B24: - Daging Sapi Grade Bawah | C24: Kg | D24: 90000 | E24: 90000 | F24: 100000 | G24: 105000 | H24: 110000 | I24: 100000 | J24: 105000 | K24: =AVERAGE(D24:J24) -> 100000
B25: - Daging Ayam Broiler | C25: Kg | D25: 31000 | E25: 31000 | F25: 31000 | G25: 31000 | H25: 32000 | I25: 33000 | J25: 33000 | K25: =AVERAGE(D25:J25) -> 31714.286
A26: 6 | B26: I K A N
B27: - Ikan Tongkol Segar (Uk. Sedang) | C27: Kg | D27: 35000 | E27: 35000 | F27: - | G27: 40000 | H27: 30000 | I27: - | J27: 30000 | K27: =AVERAGE(D27:J27) -> 34000
B28: - Ikan Mujair Segar (Uk. Sedang) | C28: Kg | D28: 35000 | E28: 28000 | F28: 35000 | G28: 30000 | H28: 20000 | I28: 32000 | J28: 32000 | K28: =AVERAGE(D28:J28) -> 30285.714
B29: - Udang Segar (Uk. Sedang) | C29: Kg | D29: 60000 | E29: 60000 | F29: 60000 | G29: 70000 | H29: 63000 | I29: 65000 | J29: 60000 | K29: =AVERAGE(D29:J29) -> 62571.429
B30: - Ikan Lele Segar (Ukuran Sedang) | C30: Kg | D30: 25000 | E30: - | F30: - | G30: 25000 | H30: 23000 | I30: - | J30: 26000 | K30: =AVERAGE(D30:J30) -> 24750
B31: - Ikan Bandeng Segar (Uk. Sedang) | C31: Kg | D31: 35000 | E31: 36000 | F31: 40000 | G31: 40000 | H31: 28000 | I31: 42000 | J31: 35000 | K31: =AVERAGE(D31:J31) -> 36571.429
B32: - Ikan Teri Asin (Bukan Teri Medan) | C32: Kg | D32: - | E32: 100000 | F32: 100000 | G32: - | H32: 80000 | I32: - | J32: 70000 | K32: =AVERAGE(D32:J32) -> 87500
A33: 7 | B33: TELUR
B34: - Telur Ayam Broiler | C34: Kg | D34: 26000 | E34: 26000 | F34: 26000 | G34: 26000 | H34: 25000 | I34: 27000 | J34: 26000 | K34: =AVERAGE(D34:J34) -> 26000
B35: - Telur Ayam Kampung | C35: Butir | D35: 3000 | E35: 2500 | F35: 2500 | G35: 2800 | H35: 2400 | I35: 3000 | J35: 3000 | K35: =AVERAGE(D35:J35) -> 2742.8571
A36: 8 | B36: TAHU
B37: - Tahu biasa | C37: Kg | D37: 10000 | E37: 1250 | F37: 9000 | G37: 9000 | H37: 16000 | I37: 9000 | J37: 3000 | K37: =AVERAGE(D37:J37) -> 8178.5714
B38: - Tahu susu | C38: Kg | D38: - | E38: 10000 | F38: 12000 | G38: 14000 | H38: - | I38: 12000 | J38: 12000 | K38: =AVERAGE(D38:J38) -> 12000
A39: 9 | B39: TEMPE
B40: - Tempe Kw I (campuran kedelai) | C40: Kg | D40: - | E40: - | F40: - | G40: 16000 | H40: 14000 | I40: - | J40: 15000 | K40: =AVERAGE(D40:J40) -> 15000
B41: - Tempe Kw II (campuran jagung) | C41: Kg | D41: - | E41: - | F41: 6000 | G41: - | H41: - | I41: 6000 | J41: - | K41: =AVERAGE(D41:J41) -> 6000
B42: - Tempe Kw III (campuran kulit) | C42: Kg | D42: - | E42: 2500 | F42: - | G42: - | H42: - | I42: - | J42: - | K42: =AVERAGE(D42:J42) -> 2500
...

Sheet 2
A1: HARGA BAHAN-BAHAN POKOK
A2: DI PASAR TRADISIONAL KOTA SURABAYA
A3: HARI / TANGGAL : Jumat / 02 Februari 2024
B4: NAMA BAHAN POKOK DAN PENTING LAINNYA | C4: SATUAN | D4: Pasar Tambahrejo | E4: Pasar Pucang Anom | F4: Pasar Wonokromo | G4: Pasar Genteng Baru | H4: Pasar Pabean | I4: Pasar Kembang | J4: Pasar Balongsari | K4: Rata-Rata
A7: 1 | B7: BERAS
B8: - Beras Premium | C8: Kg | D8: 14000 | E8: 14000 | F8: 14000 | G8: 14000 | H8: 16000 | I8: 14000 | J8: 14000 | K8: =AVERAGE(D8:J8) -> 14285.714
B9: - Beras Medium Bulog | C9: Kg | D9: 10900 | E9: 10900 | F9: 10900 | G9: 10900 | H9: 12000 | I9: 10900 | J9: - | K9: =AVERAGE(D9:J9) -> 11083.333
B10: - Beras Medium | C10: Kg | D10: - | E10: - | F10: - | G10: - | H10: - | I10: - | J10: - | K10: 0
B11: - Beras Jagung | C11: Kg | D11: - | E11: 10000 | F11: 12000 | G11: 10000 | H11: 10000 | I11: 12000 | J11: 10000 | K11: =AVERAGE(D11:J11) -> 10666.667
B12: - Beras Ketan (Jenis Siyem) | C12: Kg | D12: - | E12: 21000 | F12: 16000 | G12: 18000 | H12: 25000 | I12: 17000 | J12: 17000 | K12: =AVERAGE(D12:J12) -> 19000
A13: 2 | B13: GULA
B14: - Gula pasir lokal curah | C14: Kg | D14: 16000 | E14: 16000 | F14: 16000 | G14: 16000 | H14: 16500 | I14: 17000 | J14: 16500 | K14: =AVERAGE(D14:J14) -> 16285.714
B15: - Gula Jawa/Merah (Bahan Kelapa) | C15: Kg | D15: 17000 | E15: 16000 | F15: 16000 | G15: 16000 | H15: 17000 | I15: 16000 | J15: 18000 | K15: =AVERAGE(D15:J15) -> 16571.429
A16: 3 | B16: MINYAK GORENG
B17: - Minyak Goreng Curah (Bening) | C17: Kg | D17: 15000 | E17: 15000 | F17: 14000 | G17: 15000 | H17: 16000 | I17: 16000 | J17: 16000 | K17: =AVERAGE(D17:J17) -> 15285.714
B18: - Minyak Kita | C18: Liter | D18: 14000 | E18: 14000 | F18: 14000 | G18: 14000 | H18: - | I18: 14000 | J18: 14000 | K18: =AVERAGE(D18:J18) -> 14000
A19: 4 | B19: MENTEGA
B20: - Mentega Curah (Amanda) | C20: Kg | D20: 20000 | E20: 20000 | F20: 20000 | G20: 22000 | H20: 33000 | I20: 20000 | J20: - | K20: =AVERAGE(D20:J20) -> 22500
A21: 5 | B21: DAGING
B22: - Daging Sapi Grade Atas | C22: Kg | D22: 120000 | E22: 120000 | F22: 120000 | G22: 120000 | H22: 120000 | I22: 120000 | J22: - | K22: =AVERAGE(D22:J22) -> 120000
B23: - Daging Sapi Grade Sedang | C23: Kg | D23: 110000 | E23: 110000 | F23: 110000 | G23: 110000 | H23: 115000 | I23: 110000 | J23: 110000 | K23: =AVERAGE(D23:J23) -> 110714.29
B24: - Daging Sapi Grade Bawah | C24: Kg | D24: 90000 | E24: 90000 | F24: 100000 | G24: 105000 | H24: 110000 | I24: 100000 | J24: 105000 | K24: =AVERAGE(D24:J24) -> 100000
B25: - Daging Ayam Broiler | C25: Kg | D25: 32000 | E25: 31000 | F25: 30000 | G25: 31000 | H25: 32000 | I25: 33000 | J25: 33000 | K25: =AVERAGE(D25:J25) -> 31714.286
A26: 6 | B26: I K A N
B27: - Ikan Tongkol Segar (Uk. Sedang) | C27: Kg | D27: 35000 | E27: 35000 | F27: - | G27: 40000 | H27: 30000 | I27: - | J27: 30000 | K27: =AVERAGE(D27:J27) -> 34000
B28: - Ikan Mujair Segar (Uk. Sedang) | C28: Kg | D28: 35000 | E28: 28000 | F28: 35000 | G28: 30000 | H28: 20000 | I28: 32000 | J28: 32000 | K28: =AVERAGE(D28:J28) -> 30285.714
B29: - Udang Segar (Uk. Sedang) | C29: Kg | D29: 60000 | E29: 60000 | F29: 60000 | G29: 70000 | H29: 63000 | I29: 65000 | J29: 60000 | K29: =AVERAGE(D29:J29) -> 62571.429
B30: - Ikan Lele Segar (Ukuran Sedang) | C30: Kg | D30: 25000 | E30: - | F30: - | G30: 25000 | H30: 23000 | I30: - | J30: 26000 | K30: =AVERAGE(D30:J30) -> 24750
B31: - Ikan Bandeng Segar (Uk. Sedang) | C31: Kg | D31: 35000 | E31: 36000 | F31: 40000 | G31: 40000 | H31: 28000 | I31: 42000 | J31: 35000 | K31: =AVERAGE(D31:J31) -> 36571.429
B32: - Ikan Teri Asin (Bukan Teri Medan) | C32: Kg | D32: - | E32: 100000 | F32: 100000 | G32: - | H32: 80000 | I32: - | J32: 70000 | K32: =AVERAGE(D32:J32) -> 87500
A33: 7 | B33: TELUR
B34: - Telur Ayam Broiler | C34: Kg | D34: 26000 | E34: 26000 | F34: 26000 | G34: 26000 | H34: 26000 | I34: 27000 | J34: 26000 | K34: =AVERAGE(D34:J34) -> 26142.857
B35: - Telur Ayam Kampung | C35: Butir | D35: 3000 | E35: 2500 | F35: 2500 | G35: 2800 | H35: 2500 | I35: 3000 | J35: 3000 | K35: =AVERAGE(D35:J35) -> 2757.1429
A36: 8 | B36: TAHU
B37: - Tahu biasa | C37: Kg | D37: 10000 | E37: 1250 | F37: 9000 | G37: 9000 | H37: 16000 | I37: 9000 | J37: 3000 | K37: =AVERAGE(D37:J37) -> 8178.5714
B38: - Tahu susu | C38: Kg | D38: - | E38: 10000 | F38: 12000 | G38: 14000 | H38: - | I38: 12000 | J38: 12000 | K38: =AVERAGE(D38:J38) -> 12000
A39: 9 | B39: TEMPE
B40: - Tempe Kw I (campuran kedelai) | C40: Kg | D40: - | E40: - | F40: - | G40: 16000 | H40: 14000 | I40: - | J40: 15000 | K40: =AVERAGE(D40:J40) -> 15000
B41: - Tempe Kw II (campuran jagung) | C41: Kg | D41: - | E41: - | F41: 6000 | G41: - | H41: - | I41: 6000 | J41: - | K41: =AVERAGE(D41:J41) -> 6000
B42: - Tempe Kw III (campuran kulit) | C42: Kg | D42: - | E42: 2500 | F42: - | G42: - | H42: - | I42: - | J42: - | K42: =AVERAGE(D42:J42) -> 2500
...

Sheet 3
A1: HARGA BAHAN-BAHAN POKOK
A2: DI PASAR TRADISIONAL KOTA SURABAYA
A3: HARI / TANGGAL : Sabtu / 03 Februari 2024
B4: NAMA BAHAN POKOK DAN PENTING LAINNYA | C4: SATUAN | D4: Pasar Tambahrejo | E4: Pasar Pucang Anom | F4: Pasar Wonokromo | G4: Pasar Genteng Baru | H4: Pasar Pabean | I4: Pasar Kembang | J4: Pasar Balongsari | K4: Rata-Rata
A7: 1 | B7: BERAS
B8: - Beras Premium | C8: Kg | D8: 14000 | E8: 14000 | F8: 14200 | G8: 14000 | H8: 16000 | I8: 14000 | J8: 14000 | K8: =AVERAGE(D8:J8) -> 14314.286
B9: - Beras Medium Bulog | C9: Kg | D9: 10900 | E9: 10900 | F9: 10900 | G9: 10900 | H9: 12000 | I9: 10900 | J9: - | K9: =AVERAGE(D9:J9) -> 11083.333
B10: - Beras Medium | C10: Kg | D10: - | E10: - | F10: - | G10: - | H10: - | I10: - | J10: - | K10: 0
B11: - Beras Jagung | C11: Kg | D11: - | E11: 10000 | F11: 12000 | G11: 10000 | H11: 10000 | I11: 12000 | J11: 10000 | K11: =AVERAGE(D11:J11) -> 10666.667
B12: - Beras Ketan (Jenis Siyem) | C12: Kg | D12: - | E12: 21000 | F12: 16000 | G12: 18000 | H12: 25000 | I12: 17000 | J12: 17000 | K12: =AVERAGE(D12:J12) -> 19000
A13: 2 | B13: GULA
B14: - Gula pasir lokal curah | C14: Kg | D14: 16000 | E14: 16000 | F14: 16000 | G14: 16000 | H14: 16500 | I14: 16500 | J14: 16500 | K14: =AVERAGE(D14:J14) -> 16214.286
B15: - Gula Jawa/Merah (Bahan Kelapa) | C15: Kg | D15: 17000 | E15: 16000 | F15: 16000 | G15: 16000 | H15: 17000 | I15: 16000 | J15: 18000 | K15: =AVERAGE(D15:J15) -> 16571.429
A16: 3 | B16: MINYAK GORENG
B17: - Minyak Goreng Curah (Bening) | C17: Kg | D17: 15000 | E17: 15000 | F17: 14000 | G17: 15000 | H17: 16000 | I17: 16000 | J17: 16000 | K17: =AVERAGE(D17:J17) -> 15285.714
B18: - Minyak Kita | C18: Liter | D18: 14000 | E18: 14000 | F18: 14000 | G18: 14000 | H18: - | I18: 14000 | J18: 14000 | K18: =AVERAGE(D18:J18) -> 14000
A19: 4 | B19: MENTEGA
B20: - Mentega Curah (Amanda) | C20: Kg | D20: 20000 | E20: 20000 | F20: 20000 | G20: 22000 | H20: 33000 | I20: 20000 | J20: - | K20: =AVERAGE(D20:J20) -> 22500
A21: 5 | B21: DAGING
B22: - Daging Sapi Grade Atas | C22: Kg | D22: 120000 | E22: 120000 | F22: 120000 | G22: 120000 | H22: 120000 | I22: 120000 | J22: - | K22: =AVERAGE(D22:J22) -> 120000
B23: - Daging Sapi Grade Sedang | C23: Kg | D23: 110000 | E23: 110000 | F23: 110000 | G23: 110000 | H23: 115000 | I23: 110000 | J23: 110000 | K23: =AVERAGE(D23:J23) -> 110714.29
B24: - Daging Sapi Grade Bawah | C24: Kg | D24: 90000 | E24: 90000 | F24: 100000 | G24: 105000 | H24: 110000 | I24: 100000 | J24: 105000 | K24: =AVERAGE(D24:J24) -> 100000
B25: - Daging Ayam Broiler | C25: Kg | D25: 32000 | E25: 31000 | F25: 30000 | G25: 31000 | H25: 32000 | I25: 32000 | J25: 33000 | K25: =AVERAGE(D25:J25) -> 31571.429
A26: 6 | B26: I K A N
B27: - Ikan Tongkol Segar (Uk. Sedang) | C27: Kg | D27: 35000 | E27: 35000 | F27: - | G27: 40000 | H27: 30000 | I27: - | J27: 30000 | K27: =AVERAGE(D27:J27) -> 34000
B28: - Ikan Mujair Segar (Uk. Sedang) | C28: Kg | D28: 35000 | E28: 28000 | F28: 35000 | G28: 30000 | H28: 20000 | I28: 32000 | J28: 32000 | K28: =AVERAGE(D28:J28) -> 30285.714
B29: - Udang Segar (Uk. Sedang) | C29: Kg | D29: 60000 | E29: 60000 | F29: 60000 | G29: 70000 | H29: 63000 | I29: 60000 | J29: 60000 | K29: =AVERAGE(D29:J29) -> 61857.143
B30: - Ikan Lele Segar (Ukuran Sedang) | C30: Kg | D30: 25000 | E30: - | F30: - | G30: 25000 | H30: 23000 | I30: - | J30: 26000 | K30: =AVERAGE(D30:J30) -> 24750
B31: - Ikan Bandeng Segar (Uk. Sedang) | C31: Kg | D31: 35000 | E31: 36000 | F31: 40000 | G31: 40000 | H31: 28000 | I31: 40000 | J31: 35000 | K31: =AVERAGE(D31:J31) -> 36285.714
B32: - Ikan Teri Asin (Bukan Teri Medan) | C32: Kg | D32: - | E32: 100000 | F32: 100000 | G32: - | H32: 80000 | I32: - | J32: 70000 | K32: =AVERAGE(D32:J32) -> 87500
A33: 7 | B33: TELUR
