Workbook

Sheet REKAPITULASI
A1: BAGIAN PEREKONOMIAN DAN SUMBER DAYA ALAM
A2: LAPORAN HARGA BAHAN POKOK DI KOTA SURABAYA
A3: PERIODE PEBRUARI 2023
B4: NAMA BAHAN POKOK DAN PENTING LAINNYA | C4: SAT | AF4: HET/HAPK (Harga Eceran Tertinggi) | AG4: FLUKTUASI
D5: 1 | E5: 2 | F5: 3 | G5: 4 | H5: 5 | I5: 6 | J5: 7 | K5: 8 | L5: 9 | M5: 10 | N5: 11 | O5: 12 | P5: 13 | Q5: 14 | R5: 15 | S5: 16 | T5: 17 | U5: 18 | V5: 19 | W5: 20 | X5: 21 | Y5: 22 | Z5: 23 | AA5: 24 | AB5: 25 | AC5: 26 | AD5: 27 | AE5: 28
A7: 1 | B7: BERAS
B8: - Beras IR.64 Kwalitas I | C8: Kg | D8: ='1'!K8 -> 12542.857 | E8: ='2'!K8 -> 12542.857 | F8: ='3'!K8 -> 12685.714 | G8: ='4'!K8 -> 12685.714 | H8: ='5'!K8 -> 12685.714 | I8: ='6'!K8 -> 12900 | J8: ='7'!K8 -> 12900 | K8: ='8'!K8 -> 12900 | L8: ='9'!K8 -> 12900 | M8: ='10'!K8 -> 12971.429 | N8: ='11'!K8 -> 12971.429 | O8: ='12'!K8 -> 12828.571 | P8: ='13'!K8 -> 13114.286 | Q8: ='14'!K8 -> 13257.143 | R8: ='15'!K8 -> 13257.143 | S8: ='16'!K8 -> 13328.571 | T8: ='17'!K8 -> 13328.571 | U8: ='18'!K8 -> 13400 | V8: ='19'!K8 -> 13400 | W8: ='20'!K8 -> 13328.571 | X8: ='21'!K8 -> 13328.571 | Y8: ='22'!K8 -> 13328.571 | Z8: ='23'!K8 -> 13328.571 | AA8: ='24'!K8 -> 13328.571 | AB8: ='25'!K8 -> 13328.571 | AC8: ='26'!K8 -> 13328.571 | AD8: ='27'!K8 -> 13328.571 | AE8: ='28'!K8 -> 13328.571 | AF8: 12800 | AG8: =AE8-D8 -> 785.71429 | AH8: =AVERAGE(D8:AE8) -> 13091.327
B9: - Beras IR.64 Kwalitas II | C9: Kg | D9: ='1'!K9 -> 11428.571 | E9: ='2'!K9 -> 11428.571 | F9: ='3'!K9 -> 11500 | G9: ='4'!K9 -> 11357.143 | H9: ='5'!K9 -> 11357.143 | I9: ='6'!K9 -> 11714.286 | J9: ='7'!K9 -> 11714.286 | K9: ='8'!K9 -> 11928.571 | L9: ='9'!K9 -> 11928.571 | M9: ='10'!K9 -> 12000 | N9: ='11'!K9 -> 11714.286 | O9: ='12'!K9 -> 9035.7143 | P9: ='13'!K9 -> 8971.4286 | Q9: ='14'!K9 -> 8971.4286 | R9: ='15'!K9 -> 8971.4286 | S9: ='16'!K9 -> 9028.5714 | T9: ='17'!K9 -> 8971.4286 | U9: ='18'!K9 -> 8971.4286 | V9: ='19'!K9 -> 8971.4286 | W9: ='20'!K9 -> 8971.4286 | X9: ='21'!K9 -> 8971.4286 | Y9: ='22'!K9 -> 8971.4286 | Z9: ='23'!K9 -> 8971.4286 | AA9: ='24'!K9 -> 8971.4286 | AB9: ='25'!K9 -> 8971.4286 | AC9: ='26'!K9 -> 8971.4286 | AD9: ='27'!K9 -> 8971.4286 | AE9: ='28'!K9 -> 8971.4286 | AG9: =AE9-D9 -> -2457.1429 | AH9: =AVERAGE(D9:AE9) -> 10025.255
B10: - Beras IR.64 Kwalitas III | C10: Kg | D10: ='1'!K10 -> 10575 | E10: ='2'!K10 -> 10575 | F10: ='3'!K10 -> 10741.667 | G10: ='4'!K10 -> 6908.3333 | H10: ='5'!K10 -> 8741.6667 | I10: ='6'!K10 -> 7158.3333 | J10: ='7'!K10 -> 7158.3333 | K10: ='8'!K10 -> 7158.3333 | L10: ='9'!K10 -> 7158.3333 | M10: ='10'!K10 -> 7757.1429 | N10: ='11'!K10 -> 7757.1429 | O10: ='12'!K10 -> 9500 | P10: ='13'!K10 -> 9500 | Q10: ='14'!K10 -> 9500 | R10: ='15'!K10 -> 9500 | S10: ='16'!K10 -> 9500 | T10: ='17'!K10 -> 9500 | U10: ='18'!K10 -> 9500 | V10: ='19'!K10 -> 9500 | W10: ='20'!K10 -> 9500 | X10: ='21'!K10 -> 9500 | Y10: ='22'!K10 -> 9500 | Z10: ='23'!K10 -> 9500 | AA10: ='24'!K10 -> 9500 | AB10: ='25'!K10 -> 9500 | AC10: ='26'!K10 -> 9500 | AD10: ='27'!K10 -> 9500 | AE10: ='28'!K10 -> 9500 | AF10: 9450 | AG10: =AE10-D10 -> -1075 | AH10: =AVERAGE(D10:AE10) -> 9042.4745
B11: - Beras Jagung | C11: Kg | D11: ='1'!K11 -> 10000 | E11: ='2'!K11 -> 10000 | F11: ='3'!K11 -> 10000 | G11: ='4'!K11 -> 10000 | H11: ='5'!K11 -> 10000 | I11: ='6'!K11 -> 10000 | J11: ='7'!K11 -> 10000 | K11: ='8'!K11 -> 10000 | L11: ='9'!K11 -> 10000 | M11: ='10'!K11 -> 10333.333 | N11: ='11'!K11 -> 10333.333 | O11: ='12'!K11 -> 20000 | P11: ='13'!K11 -> 20000 | Q11: ='14'!K11 -> 20000 | R11: ='15'!K11 -> 20000 | S11: ='16'!K11 -> 20000 | T11: ='17'!K11 -> 20000 | U11: ='18'!K11 -> 20000 | V11: ='19'!K11 -> 20000 | W11: ='20'!K11 -> 20000 | X11: ='21'!K11 -> 20000 | Y11: ='22'!K11 -> 20000 | Z11: ='23'!K11 -> 20000 | AA11: ='24'!K11 -> 20000 | AB11: ='25'!K11 -> 20000 | AC11: ='26'!K11 -> 20000 | AD11: ='27'!K11 -> 20000 | AE11: ='28'!K11 -> 20000 | AG11: =AE11-D11 -> 10000 | AH11: =AVERAGE(D11:AE11) -> 16095.238
B12: - Beras Ketan (Jenis Siyem) | C12: Kg | D12: ='1'!K12 -> 19250 | E12: ='2'!K12 -> 19250 | F12: ='3'!K12 -> 19250 | G12: ='4'!K12 -> 19250 | H12: ='5'!K12 -> 19250 | I12: ='6'!K12 -> 19250 | J12: ='7'!K12 -> 19250 | K12: ='8'!K12 -> 19750 | L12: ='9'!K12 -> 19750 | M12: ='10'!K12 -> 19750 | N12: ='11'!K12 -> 19750 | O12: ='12'!K12 -> 0 | P12: ='13'!K12 -> 0 | Q12: ='14'!K12 -> 0 | R12: ='15'!K12 -> 0 | S12: ='16'!K12 -> 0 | T12: ='17'!K12 -> 0 | U12: ='18'!K12 -> 0 | V12: ='19'!K12 -> 0 | W12: ='20'!K12 -> 0 | X12: ='21'!K12 -> 0 | Y12: ='22'!K12 -> 0 | Z12: ='23'!K12 -> 0 | AA12: ='24'!K12 -> 0 | AB12: ='25'!K12 -> 0 | AC12: ='26'!K12 -> 0 | AD12: ='27'!K12 -> 0 | AE12: ='28'!K12 -> 0 | AG12: =AE12-D12 -> -19250 | AH12: =AVERAGE(D12:AE12) -> 7633.9286
A13: 2 | B13: GULA | D13: ='1'!K13 -> 0 | E13: ='2'!K13 -> 0 | F13: ='3'!K13 -> 0 | G13: ='4'!K13 -> 0 | H13: ='5'!K13 -> 0 | I13: ='6'!K13 -> 0 | J13: ='7'!K13 -> 0 | K13: ='8'!K13 -> 0 | L13: ='9'!K13 -> 0 | M13: ='10'!K13 -> 0 | N13: ='11'!K13 -> 0 | O13: ='12'!K13 -> 13071.429 | P13: ='13'!K13 -> 13071.429 | Q13: ='14'!K13 -> 13071.429 | R13: ='15'!K13 -> 13000 | S13: ='16'!K13 -> 13000 | T13: ='17'!K13 -> 13000 | U13: ='18'!K13 -> 13000 | V13: ='19'!K13 -> 13000 | W13: ='20'!K13 -> 13000 | X13: ='21'!K13 -> 13071.429 | Y13: ='22'!K13 -> 13000 | Z13: ='23'!K13 -> 13000 | AA13: ='24'!K13 -> 13000 | AB13: ='25'!K13 -> 13000 | AC13: ='26'!K13 -> 13000 | AD13: ='27'!K13 -> 13000 | AE13: ='28'!K13 -> 13000 | AG13: =AE13-D13 -> 13000 | AH13: =AVERAGE(D13:AE13) -> 7903.0612
B14: Gula Pasir Lokal Curah | C14: Kg | D14: ='1'!K14 -> 13142.857 | E14: ='2'!K14 -> 13142.857 | F14: ='3'!K14 -> 13142.857 | G14: ='4'!K14 -> 13142.857 | H14: ='5'!K14 -> 13142.857 | I14: ='6'!K14 -> 13142.857 | J14: ='7'!K14 -> 13142.857 | K14: ='8'!K14 -> 13142.857 | L14: ='9'!K14 -> 13142.857 | M14: ='10'!K14 -> 13071.429 | N14: ='11'!K14 -> 13071.429 | O14: ='12'!K14 -> 16142.857 | P14: ='13'!K14 -> 16142.857 | Q14: ='14'!K14 -> 16142.857 | R14: ='15'!K14 -> 16142.857 | S14: ='16'!K14 -> 16142.857 | T14: ='17'!K14 -> 16142.857 | U14: ='18'!K14 -> 16142.857 | V14: ='19'!K14 -> 16142.857 | W14: ='20'!K14 -> 16142.857 | X14: ='21'!K14 -> 16142.857 | Y14: ='22'!K14 -> 16142.857 | Z14: ='23'!K14 -> 16142.857 | AA14: ='24'!K14 -> 16142.857 | AB14: ='25'!K14 -> 16142.857 | AC14: ='26'!K14 -> 16142.857 | AD14: ='27'!K14 -> 16142.857 | AE14: ='28'!K14 -> 16142.857 | AF14: 13500 | AG14: =AE14-D14 -> 3000 | AH14: =AVERAGE(D14:AE14) -> 14959.184
B15: - Gula Jawa/Merah (Bahan Kelapa) | C15: Kg | D15: ='1'!K15 -> 16285.714 | E15: ='2'!K15 -> 16285.714 | F15: ='3'!K15 -> 16142.857 | G15: ='4'!K15 -> 16142.857 | H15: ='5'!K15 -> 16142.857 | I15: ='6'!K15 -> 16142.857 | J15: ='7'!K15 -> 16142.857 | K15: ='8'!K15 -> 16142.857 | L15: ='9'!K15 -> 16142.857 | M15: ='10'!K15 -> 16142.857 | N15: ='11'!K15 -> 16142.857 | O15: ='12'!K15 -> 0 | P15: ='13'!K15 -> 0 | Q15: ='14'!K15 -> 0 | R15: ='15'!K15 -> 0 | S15: ='16'!K15 -> 0 | T15: ='17'!K15 -> 0 | U15: ='18'!K15 -> 0 | V15: ='19'!K15 -> 0 | W15: ='20'!K15 -> 0 | X15: ='21'!K15 -> 0 | Y15: ='22'!K15 -> 0 | Z15: ='23'!K15 -> 0 | AA15: ='24'!K15 -> 0 | AB15: ='25'!K15 -> 0 | AC15: ='26'!K15 -> 0 | AD15: ='27'!K15 -> 0 | AE15: ='28'!K15 -> 0 | AG15: =AE15-D15 -> -16285.714 | AH15: =AVERAGE(D15:AE15) -> 6352.0408
B16: MINYAK GORENG | D16: ='1'!K16 -> 0 | E16: ='2'!K16 -> 0 | F16: ='3'!K16 -> 0 | G16: ='4'!K16 -> 0 | H16: ='5'!K16 -> 0 | I16: ='6'!K16 -> 0 | J16: ='7'!K16 -> 0 | K16: ='8'!K16 -> 0 | L16: ='9'!K16 -> 0 | M16: ='10'!K16 -> 0 | N16: ='11'!K16 -> 0 | O16: ='12'!K16 -> 16000 | P16: ='13'!K16 -> 15357.143 | Q16: ='14'!K16 -> 15357.143 | R16: ='15'!K16 -> 15071.429 | S16: ='16'!K16 -> 15071.429 | T16: ='17'!K16 -> 15071.429 | U16: ='18'!K16 -> 15071.429 | V16: ='19'!K16 -> 15071.429 | W16: ='20'!K16 -> 15071.429 | X16: ='21'!K16 -> 15071.429 | Y16: ='22'!K16 -> 15142.857 | Z16: ='23'!K16 -> 15142.857 | AA16: ='24'!K16 -> 15142.857 | AB16: ='25'!K16 -> 15142.857 | AC16: ='26'!K16 -> 15142.857 | AD16: ='27'!K16 -> 15357.143 | AE16: ='28'!K16 -> 15428.571 | AG16: =AE16-D16 -> 15428.571 | AH16: =AVERAGE(D16:AE16) -> 9239.7959
B17: - Minyak Goreng Curah (Bening) | C17: Kg | D17: ='1'!K17 -> 16214.286 | E17: ='2'!K17 -> 16214.286 | F17: ='3'!K17 -> 16214.286 | G17: ='4'!K17 -> 16214.286 | H17: ='5'!K17 -> 16214.286 | I17: ='6'!K17 -> 16071.429 | J17: ='7'!K17 -> 16071.429 | K17: ='8'!K17 -> 16000 | L17: ='9'!K17 -> 16000 | M17: ='10'!K17 -> 16000 | N17: ='11'!K17 -> 16000 | O17: ='12'!K17 -> 14000 | P17: ='13'!K17 -> 14000 | Q17: ='14'!K17 -> 14000 | R17: ='15'!K17 -> 14000 | S17: ='16'!K17 -> 14000 | T17: ='17'!K17 -> 14000 | U17: ='18'!K17 -> 14000 | V17: ='19'!K17 -> 14000 | W17: ='20'!K17 -> 14000 | X17: ='21'!K17 -> 14000 | Y17: ='22'!K17 -> 14000 | Z17: ='23'!K17 -> 14000 | AA17: ='24'!K17 -> 14000 | AB17: ='25'!K17 -> 14000 | AC17: ='26'!K17 -> 14000 | AD17: ='27'!K17 -> 14000 | AE17: ='28'!K17 -> 14000 | AF17: 15500 | AG17: =AE17-D17 -> -2214.2857 | AH17: =AVERAGE(D17:AE17) -> 14829.082
A18: 4 | B18: MENTEGA | D18: ='1'!K18 -> 0 | E18: ='2'!K18 -> 0 | F18: ='3'!K18 -> 0 | G18: ='4'!K18 -> 0 | H18: ='5'!K18 -> 0 | I18: ='6'!K18 -> 0 | J18: ='7'!K18 -> 0 | K18: ='8'!K18 -> 0 | L18: ='9'!K18 -> 0 | M18: ='10'!K18 -> 0 | N18: ='11'!K18 -> 0 | O18: ='12'!K18 -> 0 | P18: ='13'!K18 -> 0 | Q18: ='14'!K18 -> 0 | R18: ='15'!K18 -> 0 | S18: ='16'!K18 -> 0 | T18: ='17'!K18 -> 0 | U18: ='18'!K18 -> 0 | V18: ='19'!K18 -> 0 | W18: ='20'!K18 -> 0 | X18: ='21'!K18 -> 0 | Y18: ='22'!K18 -> 0 | Z18: ='23'!K18 -> 0 | AA18: ='24'!K18 -> 0 | AB18: ='25'!K18 -> 0 | AC18: ='26'!K18 -> 0 | AD18: ='27'!K18 -> 0 | AE18: ='28'!K18 -> 0 | AG18: =AE18-D18 -> 0 | AH18: =AVERAGE(D18:AE18) -> 0
B19: - Mentega Curah (Amanda) | C19: Kg | D19: ='1'!K19 -> 19000 | E19: ='2'!K19 -> 19000 | F19: ='3'!K19 -> 19000 | G19: ='4'!K19 -> 19000 | H19: ='5'!K19 -> 19000 | I19: ='6'!K19 -> 19000 | J19: ='7'!K19 -> 19000 | K19: ='8'!K19 -> 19000 | L19: ='9'!K19 -> 19000 | M19: ='10'!K19 -> 19000 | N19: ='11'!K19 -> 19000 | O19: ='12'!K19 -> 19000 | P19: ='13'!K19 -> 19000 | Q19: ='14'!K19 -> 19000 | R19: ='15'!K19 -> 19000 | S19: ='16'!K19 -> 19000 | T19: ='17'!K19 -> 19000 | U19: ='18'!K19 -> 19000 | V19: ='19'!K19 -> 19000 | W19: ='20'!K19 -> 19000 | X19: ='21'!K19 -> 19000 | Y19: ='22'!K19 -> 19000 | Z19: ='23'!K19 -> 19000 | AA19: ='24'!K19 -> 19000 | AB19: ='25'!K19 -> 19000 | AC19: ='26'!K19 -> 19000 | AD19: ='27'!K19 -> 19000 | AE19: ='28'!K19 -> 19000 | AG19: =AE19-D19 -> 0 | AH19: =AVERAGE(D19:AE19) -> 19000
A20: 5 | B20: DAGING | D20: ='1'!K20 -> 0 | E20: ='2'!K20 -> 0 | F20: ='3'!K20 -> 0 | G20: ='4'!K20 -> 0 | H20: ='5'!K20 -> 0 | I20: ='6'!K20 -> 0 | J20: ='7'!K20 -> 0 | K20: ='8'!K20 -> 0 | L20: ='9'!K20 -> 0 | M20: ='10'!K20 -> 0 | N20: ='11'!K20 -> 0 | O20: ='12'!K20 -> 0 | P20: ='13'!K20 -> 0 | Q20: ='14'!K20 -> 0 | R20: ='15'!K20 -> 0 | S20: ='16'!K20 -> 0 | T20: ='17'!K20 -> 0 | U20: ='18'!K20 -> 0 | V20: ='19'!K20 -> 0 | W20: ='20'!K20 -> 0 | X20: ='21'!K20 -> 0 | Y20: ='22'!K20 -> 0 | Z20: ='23'!K20 -> 0 | AA20: ='24'!K20 -> 0 | AB20: ='25'!K20 -> 0 | AC20: ='26'!K20 -> 0 | AD20: ='27'!K20 -> 0 | AE20: ='28'!K20 -> 0 | AG20: =AE20-D20 -> 0 | AH20: =AVERAGE(D20:AE20) -> 0
B21: - Daging Sapi Grade Atas | C21: Kg | D21: ='1'!K21 -> 118142.86 | E21: ='2'!K21 -> 118142.86 | F21: ='3'!K21 -> 118142.86 | G21: ='4'!K21 -> 118142.86 | H21: ='5'!K21 -> 118142.86 | I21: ='6'!K21 -> 118142.86 | J21: ='7'!K21 -> 118142.86 | K21: ='8'!K21 -> 118142.86 | L21: ='9'!K21 -> 118142.86 | M21: ='10'!K21 -> 118142.86 | N21: ='11'!K21 -> 118142.86 | O21: ='12'!K21 -> 118142.86 | P21: ='13'!K21 -> 118142.86 | Q21: ='14'!K21 -> 118142.86 | R21: ='15'!K21 -> 118142.86 | S21: ='16'!K21 -> 118142.86 | T21: ='17'!K21 -> 118142.86 | U21: ='18'!K21 -> 118142.86 | V21: ='19'!K21 -> 118142.86 | W21: ='20'!K21 -> 118142.86 | X21: ='21'!K21 -> 118142.86 | Y21: ='22'!K21 -> 118142.86 | Z21: ='23'!K21 -> 118142.86 | AA21: ='24'!K21 -> 118142.86 | AB21: ='25'!K21 -> 118142.86 | AC21: ='26'!K21 -> 118142.86 | AD21: ='27'!K21 -> 118142.86 | AE21: ='28'!K21 -> 118142.86 | AF21: 105000 | AG21: =AE21-D21 -> 0 | AH21: =AVERAGE(D21:AE21) -> 118142.86
B22: - Daging Sapi Grade Sedang | C22: Kg | D22: ='1'!K22 -> 109142.86 | E22: ='2'!K22 -> 114857.14 | F22: ='3'!K22 -> 114857.14 | G22: ='4'!K22 -> 109857.14 | H22: ='5'!K22 -> 109857.14 | I22: ='6'!K22 -> 109857.14 | J22: ='7'!K22 -> 109857.14 | K22: ='8'!K22 -> 109857.14 | L22: ='9'!K22 -> 109857.14 | M22: ='10'!K22 -> 109857.14 | N22: ='11'!K22 -> 109857.14 | O22: ='12'!K22 -> 109857.14 | P22: ='13'!K22 -> 109857.14 | Q22: ='14'!K22 -> 109857.14 | R22: ='15'!K22 -> 109857.14 | S22: ='16'!K22 -> 109857.14 | T22: ='17'!K22 -> 109857.14 | U22: ='18'!K22 -> 109857.14 | V22: ='19'!K22 -> 109857.14 | W22: ='20'!K22 -> 109857.14 | X22: ='21'!K22 -> 109857.14 | Y22: ='22'!K22 -> 109857.14 | Z22: ='23'!K22 -> 109857.14 | AA22: ='24'!K22 -> 109857.14 | AB22: ='25'!K22 -> 109857.14 | AC22: ='26'!K22 -> 109857.14 | AD22: ='27'!K22 -> 109857.14 | AE22: ='28'!K22 -> 109857.14 | AF22: 80000 | AG22: =AE22-D22 -> 714.28571 | AH22: =AVERAGE(D22:AE22) -> 110188.78
B23: - Daging Sapi Grade Bawah | C23: Kg | D23: ='1'!K23 -> 99166.667 | E23: ='2'!K23 -> 100000 | F23: ='3'!K23 -> 100000 | G23: ='4'!K23 -> 100000 | H23: ='5'!K23 -> 100000 | I23: ='6'!K23 -> 100000 | J23: ='7'!K23 -> 100000 | K23: ='8'!K23 -> 100000 | L23: ='9'!K23 -> 100000 | M23: ='10'!K23 -> 100000 | N23: ='11'!K23 -> 100000 | O23: ='12'!K23 -> 100000 | P23: ='13'!K23 -> 100000 | Q23: ='14'!K23 -> 100000 | R23: ='15'!K23 -> 100000 | S23: ='16'!K23 -> 100000 | T23: ='17'!K23 -> 100000 | U23: ='18'!K23 -> 100000 | V23: ='19'!K23 -> 100000 | W23: ='20'!K23 -> 100000 | X23: ='21'!K23 -> 100000 | Y23: ='22'!K23 -> 100000 | Z23: ='23'!K23 -> 100000 | AA23: ='24'!K23 -> 100000 | AB23: ='25'!K23 -> 100000 | AC23: ='26'!K23 -> 100000 | AD23: ='27'!K23 -> 100000 | AE23: ='28'!K23 -> 100000 | AF23: 80000 | AG23: =AE23-D23 -> 833.33333 | AH23: =AVERAGE(D23:AE23) -> 99970.238
B24: - Daging Ayam Broiler | C24: Kg | D24: ='1'!K24 -> 29714.286 | E24: ='2'!K24 -> 30285.714 | F24: ='3'!K24 -> 30714.286 | G24: ='4'!K24 -> 30714.286 | H24: ='5'!K24 -> 30428.571 | I24: ='6'!K24 -> 30714.286 | J24: ='7'!K24 -> 30714.286 | K24: ='8'!K24 -> 30857.143 | L24: ='9'!K24 -> 31142.857 | M24: ='10'!K24 -> 31142.857 | N24: ='11'!K24 -> 31142.857 | O24: ='12'!K24 -> 30857.143 | P24: ='13'!K24 -> 30857.143 | Q24: ='14'!K24 -> 30857.143 | R24: ='15'!K24 -> 31142.857 | S24: ='16'!K24 -> 31000 | T24: ='17'!K24 -> 30571.429 | U24: ='18'!K24 -> 30571.429 | V24: ='19'!K24 -> 30285.714 | W24: ='20'!K24 -> 30000 | X24: ='21'!K24 -> 30285.714 | Y24: ='22'!K24 -> 30285.714 | Z24: ='23'!K24 -> 30428.571 | AA24: ='24'!K24 -> 31000 | AB24: ='25'!K24 -> 30714.286 | AC24: ='26'!K24 -> 30857.143 | AD24: ='27'!K24 -> 30857.143 | AE24: ='28'!K24 -> 30857.143 | AF24: 36750 | AG24: =AE24-D24 -> 1142.8571 | AH24: =AVERAGE(D24:AE24) -> 30678.571
A25: 6 | B25: I K A N | D25: ='1'!K25 -> 0 | E25: ='2'!K25 -> 0 | F25: ='3'!K25 -> 0 | G25: ='4'!K25 -> 0 | H25: ='5'!K25 -> 0 | I25: ='6'!K25 -> 0 | J25: ='7'!K25 -> 0 | K25: ='8'!K25 -> 0 | L25: ='9'!K25 -> 0 | M25: ='10'!K25 -> 0 | N25: ='11'!K25 -> 0 | O25: ='12'!K25 -> 0 | P25: ='13'!K25 -> 0 | Q25: ='14'!K25 -> 0 | R25: ='15'!K25 -> 0 | S25: ='16'!K25 -> 0 | T25: ='17'!K25 -> 0 | U25: ='18'!K25 -> 0 | V25: ='19'!K25 -> 0 | W25: ='20'!K25 -> 0 | X25: ='21'!K25 -> 0 | Y25: ='22'!K25 -> 0 | Z25: ='23'!K25 -> 0 | AA25: ='24'!K25 -> 0 | AB25: ='25'!K25 -> 0 | AC25: ='26'!K25 -> 0 | AD25: ='27'!K25 -> 0 | AE25: ='28'!K25 -> 0 | AG25: =AE25-D25 -> 0 | AH25: =AVERAGE(D25:AE25) -> 0
B26: - Ikan Tongkol Segar (Uk. Sedang) | C26: Kg | D26: ='1'!K26 -> 37714.286 | E26: ='2'!K26 -> 37714.286 | F26: ='3'!K26 -> 38571.429 | G26: ='4'!K26 -> 38571.429 | H26: ='5'!K26 -> 39571.429 | I26: ='6'!K26 -> 39571.429 | J26: ='7'!K26 -> 38857.143 | K26: ='8'!K26 -> 39571.429 | L26: ='9'!K26 -> 39285.714 | M26: ='10'!K26 -> 38857.143 | N26: ='11'!K26 -> 37714.286 | O26: ='12'!K26 -> 37714.286 | P26: ='13'!K26 -> 37714.286 | Q26: ='14'!K26 -> 37500 | R26: ='15'!K26 -> 37428.571 | S26: ='16'!K26 -> 37428.571 | T26: ='17'!K26 -> 37428.571 | U26: ='18'!K26 -> 36857.143 | V26: ='19'!K26 -> 36857.143 | W26: ='20'!K26 -> 37142.857 | X26: ='21'!K26 -> 37142.857 | Y26: ='22'!K26 -> 37166.667 | Z26: ='23'!K26 -> 38000 | AA26: ='24'!K26 -> 38000 | AB26: ='25'!K26 -> 38666.667 | AC26: ='26'!K26 -> 38666.667 | AD26: ='27'!K26 -> 38666.667 | AE26: ='28'!K26 -> 37000 | AG26: =AE26-D26 -> -714.28571 | AH26: =AVERAGE(D26:AE26) -> 38049.32
B27: - Ikan Mujair Segar (Uk. Sedang) | C27: Kg | D27: ='1'!K27 -> 28500 | E27: ='2'!K27 -> 28500 | F27: ='3'!K27 -> 28500 | G27: ='4'!K27 -> 28500 | H27: ='5'!K27 -> 28500 | I27: ='6'!K27 -> 28166.667 | J27: ='7'!K27 -> 28166.667 | K27: ='8'!K27 -> 28166.667 | L27: ='9'!K27 -> 28166.667 | M27: ='10'!K27 -> 28500 | N27: ='11'!K27 -> 28500 | O27: ='12'!K27 -> 28500 | P27: ='13'!K27 -> 28500 | Q27: ='14'!K27 -> 28500 | R27: ='15'!K27 -> 28500 | S27: ='16'!K27 -> 28166.667 | T27: ='17'!K27 -> 28500 | U27: ='18'!K27 -> 28500 | V27: ='19'!K27 -> 28500 | W27: ='20'!K27 -> 28500 | X27: ='21'!K27 -> 28500 | Y27: ='22'!K27 -> 28500 | Z27: ='23'!K27 -> 28500 | AA27: ='24'!K27 -> 28500 | AB27: ='25'!K27 -> 28500 | AC27: ='26'!K27 -> 28500 | AD27: ='27'!K27 -> 28500 | AE27: ='28'!K27 -> 28500 | AG27: =AE27-D27 -> 0 | AH27: =AVERAGE(D27:AE27) -> 28440.476
B28: - Udang Segar (Uk. Sedang) | C28: Kg | D28: ='1'!K28 -> 64333.333 | E28: ='2'!K28 -> 63833.333 | F28: ='3'!K28 -> 63833.333 | G28: ='4'!K28 -> 63833.333 | H28: ='5'!K28 -> 65500 | I28: ='6'!K28 -> 63833.333 | J28: ='7'!K28 -> 64666.667 | K28: ='8'!K28 -> 66333.333 | L28: ='9'!K28 -> 66333.333 | M28: ='10'!K28 -> 66333.333 | N28: ='11'!K28 -> 66333.333 | O28: ='12'!K28 -> 65500 | P28: ='13'!K28 -> 65500 | Q28: ='14'!K28 -> 65500 | R28: ='15'!K28 -> 65500 | S28: ='16'!K28 -> 65500 | T28: ='17'!K28 -> 67166.667 | U28: ='18'!K28 -> 67166.667 | V28: ='19'!K28 -> 67166.667 | W28: ='20'!K28 -> 67166.667 | X28: ='21'!K28 -> 68000 | Y28: ='22'!K28 -> 66333.333 | Z28: ='23'!K28 -> 66333.333 | AA28: ='24'!K28 -> 66333.333 | AB28: ='25'!K28 -> 67166.667 | AC28: ='26'!K28 -> 67166.667 | AD28: ='27'!K28 -> 67166.667 | AE28: ='28'!K28 -> 67166.667 | AG28: =AE28-D28 -> 2833.3333 | AH28: =AVERAGE(D28:AE28) -> 65964.286
B29: - Ikan Lele Segar (Ukuran Sedang) | C29: Kg | D29: ='1'!K29 -> 24500 | E29: ='2'!K29 -> 24500 | F29: ='3'!K29 -> 24500 | G29: ='4'!K29 -> 24500 | H29: ='5'!K29 -> 24500 | I29: ='6'!K29 -> 24500 | J29: ='7'!K29 -> 24500 | K29: ='8'!K29 -> 24500 | L29: ='9'!K29 -> 24500 | M29: ='10'!K29 -> 24500 | N29: ='11'!K29 -> 24500 | O29: ='12'!K29 -> 24333.333 | P29: ='13'!K29 -> 24333.333 | Q29: ='14'!K29 -> 24333.333 | R29: ='15'!K29 -> 24333.333 | S29: ='16'!K29 -> 24333.333 | T29: ='17'!K29 -> 24333.333 | U29: ='18'!K29 -> 24333.333 | V29: ='19'!K29 -> 24333.333 | W29: ='20'!K29 -> 24333.333 | X29: ='21'!K29 -> 24333.333 | Y29: ='22'!K29 -> 24333.333 | Z29: ='23'!K29 -> 24333.333 | AA29: ='24'!K29 -> 24333.333 | AB29: ='25'!K29 -> 24333.333 | AC29: ='26'!K29 -> 24333.333 | AD29: ='27'!K29 -> 24333.333 | AE29: ='28'!K29 -> 24333.333 | AG29: =AE29-D29 -> -166.66667 | AH29: =AVERAGE(D29:AE29) -> 24398.81
B30: - Ikan Bandeng Segar (Uk. Sedang) | C30: Kg | D30: ='1'!K30 -> 37142.857 | E30: ='2'!K30 -> 37428.571 | F30: ='3'!K30 -> 36000 | G30: ='4'!K30 -> 36000 | H30: ='5'!K30 -> 36000 | I30: ='6'!K30 -> 36285.714 | J30: ='7'!K30 -> 36571.429 | K30: ='8'!K30 -> 36571.429 | L30: ='9'!K30 -> 36571.429 | M30: ='10'!K30 -> 36571.429 | N30: ='11'!K30 -> 36571.429 | O30: ='12'!K30 -> 36571.429 | P30: ='13'!K30 -> 36571.429 | Q30: ='14'!K30 -> 36571.429 | R30: ='15'!K30 -> 38000 | S30: ='16'!K30 -> 37714.286 | T30: ='17'!K30 -> 38571.429 | U30: ='18'!K30 -> 38571.429 | V30: ='19'!K30 -> 38571.429 | W30: ='20'!K30 -> 38285.714 | X30: ='21'!K30 -> 38285.714 | Y30: ='22'!K30 -> 37714.286 | Z30: ='23'!K30 -> 37000 | AA30: ='24'!K30 -> 36714.286 | AB30: ='25'!K30 -> 36428.571 | AC30: ='26'!K30 -> 36428.571 | AD30: ='27'!K30 -> 36428.571 | AE30: ='28'!K30 -> 37142.857 | AG30: =AE30-D30 -> 0 | AH30: =AVERAGE(D30:AE30) -> 37045.918
B31: - Ikan Teri Asin (Bukan Teri Medan) | C31: Kg | D31: ='1'!K31 -> 84000 | E31: ='2'!K31 -> 84000 | F31: ='3'!K31 -> 84000 | G31: ='4'!K31 -> 80000 | H31: ='5'!K31 -> 82000 | I31: ='6'!K31 -> 80000 | J31: ='7'!K31 -> 80000 | K31: ='8'!K31 -> 80000 | L31: ='9'!K31 -> 80000 | M31: ='10'!K31 -> 80000 | N31: ='11'!K31 -> 80000 | O31: ='12'!K31 -> 87500 | P31: ='13'!K31 -> 87500 | Q31: ='14'!K31 -> 85000 | R31: ='15'!K31 -> 85000 | S31: ='16'!K31 -> 85000 | T31: ='17'!K31 -> 85000 | U31: ='18'!K31 -> 85000 | V31: ='19'!K31 -> 85000 | W31: ='20'!K31 -> 85000 | X31: ='21'!K31 -> 87500 | Y31: ='22'!K31 -> 85000 | Z31: ='23'!K31 -> 85000 | AA31: ='24'!K31 -> 85000 | AB31: ='25'!K31 -> 85000 | AC31: ='26'!K31 -> 85000 | AD31: ='27'!K31 -> 85000 | AE31: ='28'!K31 -> 85000 | AG31: =AE31-D31 -> 1000 | AH31: =AVERAGE(D31:AE31) -> 83803.571
A32: 7 | B32: TELUR | D32: ='1'!K32 -> 0 | E32: ='2'!K32 -> 0 | F32: ='3'!K32 -> 0 | G32: ='4'!K32 -> 0 | H32: ='5'!K32 -> 0 | I32: ='6'!K32 -> 0 | J32: ='7'!K32 -> 0 | K32: ='8'!K32 -> 0 | L32: ='9'!K32 -> 0 | M32: ='10'!K32 -> 0 | N32: ='11'!K32 -> 0 | O32: ='12'!K32 -> 0 | P32: ='13'!K32 -> 0 | Q32: ='14'!K32 -> 0 | R32: ='15'!K32 -> 0 | S32: ='16'!K32 -> 0 | T32: ='17'!K32 -> 0 | U32: ='18'!K32 -> 0 | V32: ='19'!K32 -> 0 | W32: ='20'!K32 -> 0 | X32: ='21'!K32 -> 0 | Y32: ='22'!K32 -> 0 | Z32: ='23'!K32 -> 0 | AA32: ='24'!K32 -> 0 | AB32: ='25'!K32 -> 0 | AC32: ='26'!K32 -> 0 | AD32: ='27'!K32 -> 0 | AE32: ='28'!K32 -> 0 | AG32: =AE32-D32 -> 0 | AH32: =AVERAGE(D32:AE32) -> 0
B33: - Telur Ayam Horn | C33: Kg | D33: ='1'!K33 -> 26500 | E33: ='2'!K33 -> 26500 | F33: ='3'!K33 -> 26214.286 | G33: ='4'!K33 -> 26071.429 | H33: ='5'!K33 -> 26071.429 | I33: ='6'!K33 -> 26142.857 | J33: ='7'!K33 -> 26285.714 | K33: ='8'!K33 -> 26571.429 | L33: ='9'!K33 -> 26571.429 | M33: ='10'!K33 -> 26714.286 | N33: ='11'!K33 -> 26857.143 | O33: ='12'!K33 -> 27000 | P33: ='13'!K33 -> 26642.857 | Q33: ='14'!K33 -> 26642.857 | R33: ='15'!K33 -> 26642.857 | S33: ='16'!K33 -> 26642.857 | T33: ='17'!K33 -> 26500 | U33: ='18'!K33 -> 26500 | V33: ='19'!K33 -> 26357.143 | W33: ='20'!K33 -> 26142.857 | X33: ='21'!K33 -> 26142.857 | Y33: ='22'!K33 -> 26142.857 | Z33: ='23'!K33 -> 26142.857 | AA33: ='24'!K33 -> 26142.857 | AB33: ='25'!K33 -> 25928.571 | AC33: ='26'!K33 -> 25928.571 | AD33: ='27'!K33 -> 25714.286 | AE33: ='28'!K33 -> 25714.286 | AF33: 27000 | AG33: =AE33-D33 -> -785.71429 | AH33: =AVERAGE(D33:AE33) -> 26336.735
B34: - Telur Ayam Kampung | C34: Butir | D34: ='1'!K34 -> 2371.4286 | E34: ='2'!K34 -> 2414.2857 | F34: ='3'!K34 -> 2342.8571 | G34: ='4'!K34 -> 2342.8571 | H34: ='5'!K34 -> 2342.8571 | I34: ='6'!K34 -> 2342.8571 | J34: ='7'!K34 -> 2342.8571 | K34: ='8'!K34 -> 2357.1429 | L34: ='9'!K34 -> 2357.1429 | M34: ='10'!K34 -> 2357.1429 | N34: ='11'!K34 -> 2357.1429 | O34: ='12'!K34 -> 2357.1429 | P34: ='13'!K34 -> 2357.1429 | Q34: ='14'!K34 -> 2357.1429 | R34: ='15'!K34 -> 2357.1429 | S34: ='16'!K34 -> 2357.1429 | T34: ='17'!K34 -> 2357.1429 | U34: ='18'!K34 -> 2357.1429 | V34: ='19'!K34 -> 2357.1429 | W34: ='20'!K34 -> 2357.1429 | X34: ='21'!K34 -> 2357.1429 | Y34: ='22'!K34 -> 2357.1429 | Z34: ='23'!K34 -> 2357.1429 | AA34: ='24'!K34 -> 2357.1429 | AB34: ='25'!K34 -> 2357.1429 | AC34: ='26'!K34 -> 2357.1429 | AD34: ='27'!K34 -> 2357.1429 | AE34: ='28'!K34 -> 2357.1429 | AG34: =AE34-D34 -> -14.285714 | AH34: =AVERAGE(D34:AE34) -> 2357.1429
B35: TAHU TEMPE | Y35: ='22'!K35 -> 0 | Z35: ='23'!K35 -> 0 | AA35: ='24'!K35 -> 0 | AB35: ='25'!K35 -> 0 | AC35: ='26'!K35 -> 0 | AD35: ='27'!K35 -> 0 | AE35: ='28'!K35 -> 0 | AH35: =AVERAGE(D35:AE35) -> 0
B36: Tahu | Y36: ='22'!K36 -> 2857.1429 | Z36: ='23'!K36 -> 2428.5714 | AA36: ='24'!K36 -> 2428.5714 | AB36: ='25'!K36 -> 2428.5714 | AC36: ='26'!K36 -> 2314.2857 | AD36: ='27'!K36 -> 2314.2857 | AE36: ='28'!K36 -> 2314.2857 | AH36: =AVERAGE(D36:AE36) -> 2440.8163
B37: Tempe | Y37: ='22'!K37 -> 3000 | Z37: ='23'!K37 -> 3571.4286 | AA37: ='24'!K37 -> 3428.5714 | AB37: ='25'!K37 -> 3428.5714 | AC37: ='26'!K37 -> 3428.5714 | AD37: ='27'!K37 -> 3428.5714 | AE37: ='28'!K37 -> 3428.5714 | AH37: =AVERAGE(D37:AE37) -> 3387.7551
A38: 8 | B38: S U S U | D38: ='1'!K35 -> 0 | E38: ='2'!K35 -> 0 | F38: ='3'!K35 -> 0 | G38: ='4'!K35 -> 0 | H38: ='5'!K35 -> 0 | I38: ='6'!K35 -> 0 | J38: ='7'!K35 -> 0 | K38: ='8'!K35 -> 0 | L38: ='9'!K35 -> 0 | M38: ='10'!K35 -> 0 | N38: ='11'!K35 -> 0 | O38: ='12'!K35 -> 0 | P38: ='13'!K35 -> 0 | Q38: ='14'!K35 -> 0 | R38: ='15'!K35 -> 0 | S38: ='16'!K35 -> 0 | T38: ='17'!K35 -> 0 | U38: ='18'!K35 -> 0 | V38: ='19'!K35 -> 0 | W38: ='20'!K35 -> 0 | X38: ='21'!K35 -> 0 | Y38: ='22'!K38 -> 0 | Z38: ='23'!K38 -> 0 | AA38: ='24'!K38 -> 0 | AB38: ='25'!K38 -> 0 | AC38: ='26'!K38 -> 0 | AD38: ='27'!K38 -> 0 | AE38: ='28'!K38 -> 0 | AG38: =AE38-D38 -> 0 | AH38: =AVERAGE(D38:AE38) -> 0
B39: - Susu Kental Manis "INDOMILK" Putih | C39: 390 Gr/kaleng | D39: ='1'!K36 -> 11500 | E39: ='2'!K36 -> 11500 | F39: ='3'!K36 -> 11500 | G39: ='4'!K36 -> 11500 | H39: ='5'!K36 -> 11500 | I39: ='6'!K36 -> 11500 | J39: ='7'!K36 -> 11500 | K39: ='8'!K36 -> 11500 | L39: ='9'!K36 -> 11500 | M39: ='10'!K36 -> 11500 | N39: ='11'!K36 -> 11500 | O39: ='12'!K36 -> 11500 | P39: ='13'!K36 -> 11500 | Q39: ='14'!K36 -> 11500 | R39: ='15'!K36 -> 11500 | S39: ='16'!K36 -> 11416.667 | T39: ='17'!K36 -> 11416.667 | U39: ='18'!K36 -> 11416.667 | V39: ='19'!K36 -> 11416.667 | W39: ='20'!K36 -> 11416.667 | X39: ='21'!K36 -> 11416.667 | Y39: ='22'!K39 -> 11416.667 | Z39: ='23'!K39 -> 11416.667 | AA39: ='24'!K39 -> 11416.667 | AB39: ='25'!K39 -> 11416.667 | AC39: ='26'!K39 -> 11416.667 | AD39: ='27'!K39 -> 11416.667 | AE39: ='28'!K39 -> 11416.667 | AG39: =AE39-D39 -> -83.333333 | AH39: =AVERAGE(D39:AE39) -> 11461.31
B40: - Susu Bubuk "DANCOW" Full Cream | C40: 400 Gr/Dos | D40: ='1'!K37 -> 40200 | E40: ='2'!K37 -> 40200 | F40: ='3'!K37 -> 40200 | G40: ='4'!K37 -> 40200 | H40: ='5'!K37 -> 40200 | I40: ='6'!K37 -> 40200 | J40: ='7'!K37 -> 40200 | K40: ='8'!K37 -> 40200 | L40: ='9'!K37 -> 40200 | M40: ='10'!K37 -> 40200 | N40: ='11'!K37 -> 40200 | O40: ='12'!K37 -> 40200 | P40: ='13'!K37 -> 40200 | Q40: ='14'!K37 -> 40200 | R40: ='15'!K37 -> 40200 | S40: ='16'!K37 -> 40200 | T40: ='17'!K37 -> 40200 | U40: ='18'!K37 -> 40200 | V40: ='19'!K37 -> 40200 | W40: ='20'!K37 -> 40200 | X40: ='21'!K37 -> 40200 | Y40: ='22'!K40 -> 40200 | Z40: ='23'!K40 -> 40200 | AA40: ='24'!K40 -> 40200 | AB40: ='25'!K40 -> 40200 | AC40: ='26'!K40 -> 40200 | AD40: ='27'!K40 -> 40200 | AE40: ='28'!K40 -> 40200 | AG40: =AE40-D40 -> 0 | AH40: =AVERAGE(D40:AE40) -> 40200
A41: 9 | B41: SABUN CUCI | D41: ='1'!K38 -> 0 | E41: ='2'!K38 -> 0 | F41: ='3'!K38 -> 0 | G41: ='4'!K38 -> 0 | H41: ='5'!K38 -> 0 | I41: ='6'!K38 -> 0 | J41: ='7'!K38 -> 0 | K41: ='8'!K38 -> 0 | L41: ='9'!K38 -> 0 | M41: ='10'!K38 -> 0 | N41: ='11'!K38 -> 0 | O41: ='12'!K38 -> 0 | P41: ='13'!K38 -> 0 | Q41: ='14'!K38 -> 0 | R41: ='15'!K38 -> 0 | S41: ='16'!K38 -> 0 | T41: ='17'!K38 -> 0 | U41: ='18'!K38 -> 0 | V41: ='19'!K38 -> 0 | W41: ='20'!K38 -> 0 | X41: ='21'!K38 -> 0 | Y41: ='22'!K41 -> 0 | Z41: ='23'!K41 -> 0 | AA41: ='24'!K41 -> 0 | AB41: ='25'!K41 -> 0 | AC41: ='26'!K41 -> 0 | AD41: ='27'!K41 -> 0 | AE41: ='28'!K41 -> 0 | AG41: =AE41-D41 -> 0 | AH41: =AVERAGE(D41:AE41) -> 0
...

Sheet GRAFIK
C2: 1 | D2: 2 | E2: 3 | F2: 4 | G2: 5 | H2: 6 | I2: 7 | J2: 8 | K2: 9 | L2: 10 | M2: 11 | N2: 12 | O2: 13 | P2: 14 | Q2: 15 | R2: 16 | S2: 17 | T2: 18 | U2: 19 | V2: 20 | W2: 21 | X2: 22 | Y2: 23 | Z2: 24 | AA2: 25 | AB2: 26 | AC2: 27 | AD2: 28 | AE2: 29 | AF2: 30 | AG2: 31
A3: - Beras IR.64 Kwalitas I | B3: Kg | C3: ='1'!K8 -> 12542.857 | D3: ='2'!K8 -> 12542.857 | E3: ='3'!K8 -> 12685.714 | F3: ='4'!K8 -> 12685.714 | G3: ='5'!K8 -> 12685.714 | H3: ='6'!K8 -> 12900 | I3: ='7'!K8 -> 12900 | J3: ='8'!K8 -> 12900 | K3: ='9'!K8 -> 12900 | L3: ='10'!K8 -> 12971.429 | M3: ='11'!K8 -> 12971.429 | N3: ='12'!K8 -> 12828.571 | O3: ='13'!K8 -> 13114.286 | P3: ='14'!K8 -> 13257.143 | Q3: ='15'!K8 -> 13257.143 | R3: ='16'!K8 -> 13328.571 | S3: ='17'!K8 -> 13328.571 | T3: ='18'!K8 -> 13400 | U3: ='19'!K8 -> 13400 | V3: ='20'!K8 -> 13328.571 | W3: ='21'!K8 -> 13328.571 | X3: ='22'!K8 -> 13328.571 | Y3: ='23'!K8 -> 13328.571 | Z3: ='24'!K8 -> 13328.571 | AA3: ='25'!K8 -> 13328.571 | AB3: ='26'!K8 -> 13328.571 | AC3: ='27'!K8 -> 13328.571 | AD3: ='28'!K8 -> 13328.571 | AE3: =#REF! -> #REF! | AF3: =#REF! -> #REF! | AG3: =#REF! -> #REF!
A4: - Beras IR.64 Kwalitas II | B4: Kg | C4: ='1'!K9 -> 11428.571 | D4: ='2'!K9 -> 11428.571 | E4: ='3'!K9 -> 11500 | F4: ='4'!K9 -> 11357.143 | G4: ='5'!K9 -> 11357.143 | H4: ='6'!K9 -> 11714.286 | I4: ='7'!K9 -> 11714.286 | J4: ='8'!K9 -> 11928.571 | K4: ='9'!K9 -> 11928.571 | L4: ='10'!K9 -> 12000 | M4: ='11'!K9 -> 11714.286 | N4: ='12'!K9 -> 9035.7143 | O4: ='13'!K9 -> 8971.4286 | P4: ='14'!K9 -> 8971.4286 | Q4: ='15'!K9 -> 8971.4286 | R4: ='16'!K9 -> 9028.5714 | S4: ='17'!K9 -> 8971.4286 | T4: ='18'!K9 -> 8971.4286 | U4: ='19'!K9 -> 8971.4286 | V4: ='20'!K9 -> 8971.4286 | W4: ='21'!K9 -> 8971.4286 | X4: ='22'!K9 -> 8971.4286 | Y4: ='23'!K9 -> 8971.4286 | Z4: ='24'!K9 -> 8971.4286 | AA4: ='25'!K9 -> 8971.4286 | AB4: ='26'!K9 -> 8971.4286 | AC4: ='27'!K9 -> 8971.4286 | AD4: ='28'!K9 -> 8971.4286 | AE4: =#REF! -> #REF! | AF4: =#REF! -> #REF! | AG4: =#REF! -> #REF!
A5: - Beras IR.64 Kwalitas III | B5: Kg | C5: ='1'!K10 -> 10575 | D5: ='2'!K10 -> 10575 | E5: ='3'!K10 -> 10741.667 | F5: ='4'!K10 -> 6908.3333 | G5: ='5'!K10 -> 8741.6667 | H5: ='6'!K10 -> 7158.3333 | I5: ='7'!K10 -> 7158.3333 | J5: ='8'!K10 -> 7158.3333 | K5: ='9'!K10 -> 7158.3333 | L5: ='10'!K10 -> 7757.1429 | M5: ='11'!K10 -> 7757.1429 | N5: ='12'!K10 -> 9500 | O5: ='13'!K10 -> 9500 | P5: ='14'!K10 -> 9500 | Q5: ='15'!K10 -> 9500 | R5: ='16'!K10 -> 9500 | S5: ='17'!K10 -> 9500 | T5: ='18'!K10 -> 9500 | U5: ='19'!K10 -> 9500 | V5: ='20'!K10 -> 9500 | W5: ='21'!K10 -> 9500 | X5: ='22'!K10 -> 9500 | Y5: ='23'!K10 -> 9500 | Z5: ='24'!K10 -> 9500 | AA5: ='25'!K10 -> 9500 | AB5: ='26'!K10 -> 9500 | AC5: ='27'!K10 -> 9500 | AD5: ='28'!K10 -> 9500 | AE5: =#REF! -> #REF! | AF5: =#REF! -> #REF! | AG5: =#REF! -> #REF!
C24: 1 | D24: 2 | E24: 3 | F24: 4 | G24: 5 | H24: 6 | I24: 7 | J24: 8 | K24: 9 | L24: 10 | M24: 11 | N24: 12 | O24: 13 | P24: 14 | Q24: 15 | R24: 16 | S24: 17 | T24: 18 | U24: 19 | V24: 20 | W24: 21 | X24: 22 | Y24: 23 | Z24: 24 | AA24: 25 | AB24: 26 | AC24: 27 | AD24: 28 | AE24: 29 | AF24: 30 | AG24: 31
A25: Gula Pasir Lokal Curah | B25: Kg | C25: ='1'!K14 -> 13142.857 | D25: ='2'!K14 -> 13142.857 | E25: ='3'!K14 -> 13142.857 | F25: ='4'!K14 -> 13142.857 | G25: ='5'!K14 -> 13142.857 | H25: ='6'!K14 -> 13142.857 | I25: ='7'!K14 -> 13142.857 | J25: ='8'!K14 -> 13142.857 | K25: ='9'!K14 -> 13142.857 | L25: ='10'!K14 -> 13071.429 | M25: ='11'!K14 -> 13071.429 | N25: ='12'!K14 -> 16142.857 | O25: ='13'!K14 -> 16142.857 | P25: ='14'!K14 -> 16142.857 | Q25: ='15'!K14 -> 16142.857 | R25: ='16'!K14 -> 16142.857 | S25: ='17'!K14 -> 16142.857 | T25: ='18'!K14 -> 16142.857 | U25: ='19'!K14 -> 16142.857 | V25: ='20'!K14 -> 16142.857 | W25: ='21'!K14 -> 16142.857 | X25: ='22'!K14 -> 16142.857 | Y25: ='23'!K14 -> 16142.857 | Z25: ='24'!K14 -> 16142.857 | AA25: ='25'!K14 -> 16142.857 | AB25: ='26'!K14 -> 16142.857 | AC25: ='27'!K14 -> 16142.857 | AD25: ='28'!K14 -> 16142.857 | AE25: =#REF! -> #REF! | AF25: =#REF! -> #REF! | AG25: =#REF! -> #REF!
C46: 1 | D46: 2 | E46: 3 | F46: 4 | G46: 5 | H46: 6 | I46: 7 | J46: 8 | K46: 9 | L46: 10 | M46: 11 | N46: 12 | O46: 13 | P46: 14 | Q46: 15 | R46: 16 | S46: 17 | T46: 18 | U46: 19 | V46: 20 | W46: 21 | X46: 22 | Y46: 23 | Z46: 24 | AA46: 25 | AB46: 26 | AC46: 27 | AD46: 28 | AE46: 29 | AF46: 30 | AG46: 31
A47: - Minyak Goreng Curah (Bening) | B47: Kg | C47: ='1'!K17 -> 16214.286 | D47: ='2'!K17 -> 16214.286 | E47: ='3'!K17 -> 16214.286 | F47: ='4'!K17 -> 16214.286 | G47: ='5'!K17 -> 16214.286 | H47: ='6'!K17 -> 16071.429 | I47: ='7'!K17 -> 16071.429 | J47: ='8'!K17 -> 16000 | K47: ='9'!K17 -> 16000 | L47: ='10'!K17 -> 16000 | M47: ='11'!K17 -> 16000 | N47: ='12'!K17 -> 14000 | O47: ='13'!K17 -> 14000 | P47: ='14'!K17 -> 14000 | Q47: ='15'!K17 -> 14000 | R47: ='16'!K17 -> 14000 | S47: ='17'!K17 -> 14000 | T47: ='18'!K17 -> 14000 | U47: ='19'!K17 -> 14000 | V47: ='20'!K17 -> 14000 | W47: ='21'!K17 -> 14000 | X47: ='22'!K17 -> 14000 | Y47: ='23'!K17 -> 14000 | Z47: ='24'!K17 -> 14000 | AA47: ='25'!K17 -> 14000 | AB47: ='26'!K17 -> 14000 | AC47: ='27'!K17 -> 14000 | AD47: ='28'!K17 -> 14000 | AE47: =#REF! -> #REF! | AF47: =#REF! -> #REF! | AG47: =#REF! -> #REF!
C75: 1 | D75: 2 | E75: 3 | F75: 4 | G75: 5 | H75: 6 | I75: 7 | J75: 8 | K75: 9 | L75: 10 | M75: 11 | N75: 12 | O75: 13 | P75: 14 | Q75: 15 | R75: 16 | S75: 17 | T75: 18 | U75: 19 | V75: 20 | W75: 21 | X75: 22 | Y75: 23 | Z75: 24 | AA75: 25 | AB75: 26 | AC75: 27 | AD75: 28 | AE75: 29 | AF75: 30 | AG75: 31
A76: - Daging Ayam Broiler | B76: Kg | C76: ='1'!K24 -> 29714.286 | D76: ='2'!K24 -> 30285.714 | E76: ='3'!K24 -> 30714.286 | F76: ='4'!K24 -> 30714.286 | G76: ='5'!K24 -> 30428.571 | H76: ='6'!K24 -> 30714.286 | I76: ='7'!K24 -> 30714.286 | J76: ='8'!K24 -> 30857.143 | K76: ='9'!K24 -> 31142.857 | L76: ='10'!K24 -> 31142.857 | M76: ='11'!K24 -> 31142.857 | N76: ='12'!K24 -> 30857.143 | O76: ='13'!K24 -> 30857.143 | P76: ='14'!K24 -> 30857.143 | Q76: ='15'!K24 -> 31142.857 | R76: ='16'!K24 -> 31000 | S76: ='17'!K24 -> 30571.429 | T76: ='18'!K24 -> 30571.429 | U76: ='19'!K24 -> 30285.714 | V76: ='20'!K24 -> 30000 | W76: ='21'!K24 -> 30285.714 | X76: ='22'!K24 -> 30285.714 | Y76: ='23'!K24 -> 30428.571 | Z76: ='24'!K24 -> 31000 | AA76: ='25'!K24 -> 30714.286 | AB76: ='26'!K24 -> 30857.143 | AC76: ='27'!K24 -> 30857.143 | AD76: ='28'!K24 -> 30857.143 | AE76: =#REF! -> #REF! | AF76: =#REF! -> #REF! | AG76: =#REF! -> #REF!
C96: 1 | D96: 2 | E96: 3 | F96: 4 | G96: 5 | H96: 6 | I96: 7 | J96: 8 | K96: 9 | L96: 10 | M96: 11 | N96: 12 | O96: 13 | P96: 14 | Q96: 15 | R96: 16 | S96: 17 | T96: 18 | U96: 19 | V96: 20 | W96: 21 | X96: 22 | Y96: 23 | Z96: 24 | AA96: 25 | AB96: 26 | AC96: 27 | AD96: 28 | AE96: 29 | AF96: 30 | AG96: 31
A97: - Telur Ayam Horn | B97: Kg | C97: ='1'!K33 -> 26500 | D97: ='2'!K33 -> 26500 | E97: ='3'!K33 -> 26214.286 | F97: ='4'!K33 -> 26071.429 | G97: ='5'!K33 -> 26071.429 | H97: ='6'!K33 -> 26142.857 | I97: ='7'!K33 -> 26285.714 | J97: ='8'!K33 -> 26571.429 | K97: ='9'!K33 -> 26571.429 | L97: ='10'!K33 -> 26714.286 | M97: ='11'!K33 -> 26857.143 | N97: ='12'!K33 -> 27000 | O97: ='13'!K33 -> 26642.857 | P97: ='14'!K33 -> 26642.857 | Q97: ='15'!K33 -> 26642.857 | R97: ='16'!K33 -> 26642.857 | S97: ='17'!K33 -> 26500 | T97: ='18'!K33 -> 26500 | U97: ='19'!K33 -> 26357.143 | V97: ='20'!K33 -> 26142.857 | W97: ='21'!K33 -> 26142.857 | X97: ='22'!K33 -> 26142.857 | Y97: ='23'!K33 -> 26142.857 | Z97: ='24'!K33 -> 26142.857 | AA97: ='25'!K33 -> 25928.571 | AB97: ='26'!K33 -> 25928.571 | AC97: ='27'!K33 -> 25714.286 | AD97: ='28'!K33 -> 25714.286 | AE97: =#REF! -> #REF! | AF97: =#REF! -> #REF! | AG97: =#REF! -> #REF!
C116: 1 | D116: 2 | E116: 3 | F116: 4 | G116: 5 | H116: 6 | I116: 7 | J116: 8 | K116: 9 | L116: 10 | M116: 11 | N116: 12 | O116: 13 | P116: 14 | Q116: 15 | R116: 16 | S116: 17 | T116: 18 | U116: 19 | V116: 20 | W116: 21 | X116: 22 | Y116: 23 | Z116: 24 | AA116: 25 | AB116: 26 | AC116: 27 | AD116: 28 | AE116: 29 | AF116: 30 | AG116: 31
A117: - Garam Halus (Cap Kapal) | B117: 250 Gr/Bngks | C117: ='1'!K45 -> 4000 | D117: ='2'!K45 -> 4000 | E117: ='3'!K45 -> 4000 | F117: ='4'!K45 -> 3916.6667 | G117: ='5'!K45 -> 3916.6667 | H117: ='6'!K45 -> 3916.6667 | I117: ='7'!K45 -> 3916.6667 | J117: ='8'!K45 -> 3916.6667 | K117: ='9'!K45 -> 3916.6667 | L117: ='10'!K45 -> 3916.6667 | M117: ='11'!K45 -> 3916.6667 | N117: ='12'!K45 -> 4000 | O117: ='13'!K45 -> 4000 | P117: ='14'!K45 -> 3916.6667 | Q117: ='15'!K45 -> 3916.6667 | R117: ='16'!K45 -> 3916.6667 | S117: ='17'!K45 -> 3916.6667 | T117: ='18'!K45 -> 3916.6667 | U117: ='19'!K45 -> 3916.6667 | V117: ='20'!K45 -> 3916.6667 | W117: ='21'!K45 -> 3916.6667 | X117: ='22'!K45 -> 9166.6667 | Y117: ='23'!K45 -> 9166.6667 | Z117: ='24'!K45 -> 9166.6667 | AA117: ='25'!K45 -> 9166.6667 | AB117: ='26'!K45 -> 9166.6667 | AC117: ='27'!K45 -> 9166.6667 | AD117: ='28'!K45 -> 9166.6667 | AE117: =#REF! -> #REF! | AF117: =#REF! -> #REF! | AG117: =#REF! -> #REF!
C149: 1 | D149: 2 | E149: 3 | F149: 4 | G149: 5 | H149: 6 | I149: 7 | J149: 8 | K149: 9 | L149: 10 | M149: 11 | N149: 12 | O149: 13 | P149: 14 | Q149: 15 | R149: 16 | S149: 17 | T149: 18 | U149: 19 | V149: 20 | W149: 21 | X149: 22 | Y149: 23 | Z149: 24 | AA149: 25 | AB149: 26 | AC149: 27 | AD149: 28 | AE149: 29 | AF149: 30 | AG149: 31
A150: - Kacang Kedelai (Kualitas Import) | B150: Kg | C150: ='1'!K49 -> 15583.333 | D150: ='2'!K49 -> 15583.333 | E150: ='3'!K49 -> 15750 | F150: ='4'!K49 -> 15750 | G150: ='5'!K49 -> 15750 | H150: ='6'!K49 -> 15750 | I150: ='7'!K49 -> 15750 | J150: ='8'!K49 -> 16166.667 | K150: ='9'!K49 -> 16166.667 | L150: ='10'!K49 -> 16166.667 | M150: ='11'!K49 -> 16166.667 | N150: ='12'!K49 -> 16166.667 | O150: ='13'!K49 -> 16166.667 | P150: ='14'!K49 -> 16166.667 | Q150: ='15'!K49 -> 15833.333 | R150: ='16'!K49 -> 15833.333 | S150: ='17'!K49 -> 15833.333 | T150: ='18'!K49 -> 15833.333 | U150: ='19'!K49 -> 15833.333 | V150: ='20'!K49 -> 15833.333 | W150: ='21'!K49 -> 15833.333 | X150: ='22'!K49 -> 0 | Y150: ='23'!K49 -> 0 | Z150: ='24'!K49 -> 0 | AA150: ='25'!K49 -> 0 | AB150: ='26'!K49 -> 0 | AC150: ='27'!K49 -> 0 | AD150: ='28'!K49 -> 0 | AE150: =#REF! -> #REF! | AF150: =#REF! -> #REF! | AG150: =#REF! -> #REF!
C169: 1 | D169: 2 | E169: 3 | F169: 4 | G169: 5 | H169: 6 | I169: 7 | J169: 8 | K169: 9 | L169: 10 | M169: 11 | N169: 12 | O169: 13 | P169: 14 | Q169: 15 | R169: 16 | S169: 17 | T169: 18 | U169: 19 | V169: 20 | W169: 21 | X169: 22 | Y169: 23 | Z169: 24 | AA169: 25 | AB169: 26 | AC169: 27 | AD169: 28 | AE169: 29 | AF169: 30 | AG169: 31
A170: - Cabe Merah Besar | B170: Kg | C170: ='1'!K56 -> 27714.286 | D170: ='2'!K56 -> 28000 | E170: ='3'!K56 -> 28000 | F170: ='4'!K56 -> 28142.857 | G170: ='5'!K56 -> 28857.143 | H170: ='6'!K56 -> 29142.857 | I170: ='7'!K56 -> 31428.571 | J170: ='8'!K56 -> 32142.857 | K170: ='9'!K56 -> 32571.429 | L170: ='10'!K56 -> 31428.571 | M170: ='11'!K56 -> 31428.571 | N170: ='12'!K56 -> 31428.571 | O170: ='13'!K56 -> 32142.857 | P170: ='14'!K56 -> 32428.571 | Q170: ='15'!K56 -> 33428.571 | R170: ='16'!K56 -> 35285.714 | S170: ='17'!K56 -> 36714.286 | T170: ='18'!K56 -> 37142.857 | U170: ='19'!K56 -> 37142.857 | V170: ='20'!K56 -> 37428.571 | W170: ='21'!K56 -> 37714.286 | X170: ='22'!K56 -> 0 | Y170: ='23'!K56 -> 0 | Z170: ='24'!K56 -> 0 | AA170: ='25'!K56 -> 0 | AB170: ='26'!K56 -> 0 | AC170: ='27'!K56 -> 0 | AD170: ='28'!K56 -> 0 | AE170: =#REF! -> #REF! | AF170: =#REF! -> #REF! | AG170: =#REF! -> #REF!
A171: - Cabe Merah Kriting | B171: Kg | C171: ='1'!K57 -> 38750 | D171: ='2'!K57 -> 37500 | E171: ='3'!K57 -> 38750 | F171: ='4'!K57 -> 38750 | G171: ='5'!K57 -> 38750 | H171: ='6'!K57 -> 36750 | I171: ='7'!K57 -> 40000 | J171: ='8'!K57 -> 41250 | K171: ='9'!K57 -> 40000 | L171: ='10'!K57 -> 40000 | M171: ='11'!K57 -> 40000 | N171: ='12'!K57 -> 40000 | O171: ='13'!K57 -> 41250 | P171: ='14'!K57 -> 46250 | Q171: ='15'!K57 -> 47500 | R171: ='16'!K57 -> 51250 | S171: ='17'!K57 -> 51250 | T171: ='18'!K57 -> 51250 | U171: ='19'!K57 -> 52500 | V171: ='20'!K57 -> 50000 | W171: ='21'!K57 -> 50000 | X171: ='22'!K57 -> 3200 | Y171: ='23'!K57 -> 3200 | Z171: ='24'!K57 -> 3200 | AA171: ='25'!K57 -> 3200 | AB171: ='26'!K57 -> 3200 | AC171: ='27'!K57 -> 3200 | AD171: ='28'!K57 -> 3200 | AE171: =#REF! -> #REF! | AF171: =#REF! -> #REF! | AG171: =#REF! -> #REF!
A172: - Cabe Merah Kecil-Rawit | B172: Kg | C172: ='1'!K58 -> 51428.571 | D172: ='2'!K58 -> 50000 | E172: ='3'!K58 -> 48428.571 | F172: ='4'!K58 -> 49142.857 | G172: ='5'!K58 -> 49857.143 | H172: ='6'!K58 -> 48428.571 | I172: ='7'!K58 -> 56142.857 | J172: ='8'!K58 -> 57142.857 | K172: ='9'!K58 -> 56428.571 | L172: ='10'!K58 -> 57857.143 | M172: ='11'!K58 -> 55714.286 | N172: ='12'!K58 -> 56428.571 | O172: ='13'!K58 -> 57857.143 | P172: ='14'!K58 -> 57142.857 | Q172: ='15'!K58 -> 56428.571 | R172: ='16'!K58 -> 60714.286 | S172: ='17'!K58 -> 62142.857 | T172: ='18'!K58 -> 61428.571 | U172: ='19'!K58 -> 61428.571 | V172: ='20'!K58 -> 60714.286 | W172: ='21'!K58 -> 59285.714 | X172: ='22'!K58 -> 0 | Y172: ='23'!K58 -> 0 | Z172: ='24'!K58 -> 0 | AA172: ='25'!K58 -> 0 | AB172: ='26'!K58 -> 0 | AC172: ='27'!K58 -> 0 | AD172: ='28'!K58 -> 0 | AE172: =#REF! -> #REF! | AF172: =#REF! -> #REF! | AG172: =#REF! -> #REF!
C193: 1 | D193: 2 | E193: 3 | F193: 4 | G193: 5 | H193: 6 | I193: 7 | J193: 8 | K193: 9 | L193: 10 | M193: 11 | N193: 12 | O193: 13 | P193: 14 | Q193: 15 | R193: 16 | S193: 17 | T193: 18 | U193: 19 | V193: 20 | W193: 21 | X193: 22 | Y193: 23 | Z193: 24 | AA193: 25 | AB193: 26 | AC193: 27 | AD193: 28 | AE193: 29 | AF193: 30 | AG193: 31
A194: - Bawang Putih (Jenis Kating) | B194: Kg | C194: ='1'!K62 -> 29714.286 | D194: ='2'!K62 -> 31428.571 | E194: ='3'!K62 -> 31285.714 | F194: ='4'!K62 -> 31142.857 | G194: ='5'!K62 -> 30857.143 | H194: ='6'!K62 -> 31285.714 | I194: ='7'!K62 -> 30714.286 | J194: ='8'!K62 -> 30571.429 | K194: ='9'!K62 -> 30714.286 | L194: ='10'!K62 -> 30571.429 | M194: ='11'!K62 -> 30285.714 | N194: ='12'!K62 -> 30285.714 | O194: ='13'!K62 -> 30285.714 | P194: ='14'!K62 -> 30142.857 | Q194: ='15'!K62 -> 30428.571 | R194: ='16'!K62 -> 30714.286 | S194: ='17'!K62 -> 30285.714 | T194: ='18'!K62 -> 30285.714 | U194: ='19'!K62 -> 30285.714 | V194: ='20'!K62 -> 30285.714 | W194: ='21'!K62 -> 29714.286 | X194: ='22'!K62 -> 0 | Y194: ='23'!K62 -> 0 | Z194: ='24'!K62 -> 0 | AA194: ='25'!K62 -> 0 | AB194: ='26'!K62 -> 0 | AC194: ='27'!K62 -> 0 | AD194: ='28'!K62 -> 0 | AE194: =#REF! -> #REF! | AF194: =#REF! -> #REF! | AG194: =#REF! -> #REF!
A195: - Bawang Putih (Jenis Sinco) | B195: Kg | C195: ='1'!K63 -> 26000 | D195: ='2'!K63 -> 26285.714 | E195: ='3'!K63 -> 26285.714 | F195: ='4'!K63 -> 26000 | G195: ='5'!K63 -> 25714.286 | H195: ='6'!K63 -> 26142.857 | I195: ='7'!K63 -> 26142.857 | J195: ='8'!K63 -> 26000 | K195: ='9'!K63 -> 26142.857 | L195: ='10'!K63 -> 26000 | M195: ='11'!K63 -> 25714.286 | N195: ='12'!K63 -> 25428.571 | O195: ='13'!K63 -> 25714.286 | P195: ='14'!K63 -> 24857.143 | Q195: ='15'!K63 -> 25285.714 | R195: ='16'!K63 -> 25428.571 | S195: ='17'!K63 -> 25428.571 | T195: ='18'!K63 -> 25714.286 | U195: ='19'!K63 -> 25714.286 | V195: ='20'!K63 -> 25714.286 | W195: ='21'!K63 -> 26000 | X195: ='22'!K63 -> 18166.667 | Y195: ='23'!K63 -> 18166.667 | Z195: ='24'!K63 -> 18166.667 | AA195: ='25'!K63 -> 18166.667 | AB195: ='26'!K63 -> 18166.667 | AC195: ='27'!K63 -> 18166.667 | AD195: ='28'!K63 -> 18166.667 | AE195: =#REF! -> #REF! | AF195: =#REF! -> #REF! | AG195: =#REF! -> #REF!
A196: - Bawang Merah (Kualitas Lokal) | B196: Kg | C196: ='1'!K64 -> 37000 | D196: ='2'!K64 -> 39142.857 | E196: ='3'!K64 -> 39714.286 | F196: ='4'!K64 -> 39000 | G196: ='5'!K64 -> 39000 | H196: ='6'!K64 -> 38571.429 | I196: ='7'!K64 -> 37428.571 | J196: ='8'!K64 -> 36857.143 | K196: ='9'!K64 -> 36571.429 | L196: ='10'!K64 -> 35428.571 | M196: ='11'!K64 -> 35000 | N196: ='12'!K64 -> 35857.143 | O196: ='13'!K64 -> 35571.429 | P196: ='14'!K64 -> 36000 | Q196: ='15'!K64 -> 35285.714 | R196: ='16'!K64 -> 34000 | S196: ='17'!K64 -> 33285.714 | T196: ='18'!K64 -> 32714.286 | U196: ='19'!K64 -> 33000 | V196: ='20'!K64 -> 33142.857 | W196: ='21'!K64 -> 30285.714 | X196: ='22'!K64 -> 0 | Y196: ='23'!K64 -> 0 | Z196: ='24'!K64 -> 0 | AA196: ='25'!K64 -> 0 | AB196: ='26'!K64 -> 0 | AC196: ='27'!K64 -> 0 | AD196: ='28'!K64 -> 0 | AE196: =#REF! -> #REF! | AF196: =#REF! -> #REF! | AG196: =#REF! -> #REF!
A197: - Bawang Bombay | B197: Kg | C197: ='1'!K65 -> 21714.286 | D197: ='2'!K65 -> 21714.286 | E197: ='3'!K65 -> 21714.286 | F197: ='4'!K65 -> 21714.286 | G197: ='5'!K65 -> 22000 | H197: ='6'!K65 -> 21428.571 | I197: ='7'!K65 -> 21000 | J197: ='8'!K65 -> 21000 | K197: ='9'!K65 -> 21000 | L197: ='10'!K65 -> 21000 | M197: ='11'!K65 -> 21428.571 | N197: ='12'!K65 -> 21428.571 | O197: ='13'!K65 -> 21714.286 | P197: ='14'!K65 -> 21714.286 | Q197: ='15'!K65 -> 21428.571 | R197: ='16'!K65 -> 21428.571 | S197: ='17'!K65 -> 21428.571 | T197: ='18'!K65 -> 21428.571 | U197: ='19'!K65 -> 21428.571 | V197: ='20'!K65 -> 21428.571 | W197: ='21'!K65 -> 21428.571 | X197: ='22'!K65 -> 30285.714 | Y197: ='23'!K65 -> 30571.429 | Z197: ='24'!K65 -> 29857.143 | AA197: ='25'!K65 -> 30285.714 | AB197: ='26'!K65 -> 30285.714 | AC197: ='27'!K65 -> 31571.429 | AD197: ='28'!K65 -> 32000 | AE197: =#REF! -> #REF! | AF197: =#REF! -> #REF! | AG197: =#REF! -> #REF!

Sheet 1
A1: HARGA BAHAN-BAHAN POKOK
A2: DI PASAR TRADISIONAL KOTA SURABAYA
A3: HARI / TANGGAL : Rabu / 01 Februari 2023
B4: NAMA BAHAN POKOK DAN PENTING LAINNYA | C4: SATUAN | D4: Pasar Tambahrejo | E4: Pasar Pucang Anom | F4: Pasar Wonokromo | G4: Pasar Genteng Baru | H4: Pasar Pabean | I4: Pasar Kembang | J4: Pasar Balongsari | K4: Rata-Rata
A7: 1 | B7: BERAS
B8: - Beras IR.64 Kwalitas I | C8: Kg | D8: 12500 | E8: 12500 | F8: 12000 | G8: 12800 | H8: 12500 | I8: 13000 | J8: 12500 | K8: =AVERAGE(D8:J8) -> 12542.857
B9: - Beras IR.64 Kwalitas II | C9: Kg | D9: 11000 | E9: 12500 | F9: 11500 | G9: 12000 | H9: 10500 | I9: 11500 | J9: 11000 | K9: =AVERAGE(D9:J9) -> 11428.571
B10: - Beras IR.64 Kwalitas III | C10: Kg | D10: 12000 | E10: 11500 | F10: 10500 | G10: 9450 | H10: 9500 | I10: 10500 | J10: - | K10: =AVERAGE(D10:J10) -> 10575
B11: - Beras Jagung | C11: Kg | D11: - | E11: - | F11: - | G11: 11000 | H11: - | I11: 11000 | J11: 8000 | K11: =AVERAGE(D11:J11) -> 10000
B12: - Beras Ketan (Jenis Siyem) | C12: Kg | D12: - | E12: 23000 | F12: - | G12: 18000 | H12: - | I12: 18000 | J12: 18000 | K12: =AVERAGE(D12:J12) -> 19250
A13: 2 | B13: GULA
B14: Gula Pasir Lokal Curah | C14: Kg | D14: 13000 | E14: 13000 | F14: 13500 | G14: 13000 | H14: 13000 | I14: 13500 | J14: 13000 | K14: =AVERAGE(D14:J14) -> 13142.857
B15: - Gula Jawa/Merah (Bahan Kelapa) | C15: Kg | D15: 15000 | E15: 16000 | F15: 17000 | G15: 19000 | H15: 15000 | I15: 16000 | J15: 16000 | K15: =AVERAGE(D15:J15) -> 16285.714
B16: MINYAK GORENG
B17: - Minyak Goreng Curah (Bening) | C17: Kg | D17: 16000 | E17: 16000 | F17: 17000 | G17: 16000 | H17: 16000 | I17: 16500 | J17: 16000 | K17: =AVERAGE(D17:J17) -> 16214.286
A18: 4 | B18: MENTEGA
B19: - Mentega Curah (Amanda) | C19: Kg | D19: - | E19: - | F19: - | G19: 14000 | H19: - | I19: 24000 | J19: - | K19: =AVERAGE(D19:J19) -> 19000
A20: 5 | B20: DAGING
B21: - Daging Sapi Grade Atas | C21: Kg | D21: 120000 | E21: 120000 | F21: 120000 | G21: 120000 | H21: 117000 | I21: 120000 | J21: 110000 | K21: =AVERAGE(D21:J21) -> 118142.86
B22: - Daging Sapi Grade Sedang | C22: Kg | D22: 110000 | E22: 110000 | F22: 110000 | G22: 110000 | H22: 114000 | I22: 110000 | J22: 100000 | K22: =AVERAGE(D22:J22) -> 109142.86
B23: - Daging Sapi Grade Bawah | C23: Kg | D23: 100000 | E23: 95000 | F23: 100000 | G23: 100000 | H23: 100000 | I23: 100000 | J23: - | K23: =AVERAGE(D23:J23) -> 99166.667
B24: - Daging Ayam Broiler | C24: Kg | D24: 30000 | E24: 28000 | F24: 30000 | G24: 30000 | H24: 31000 | I24: 29000 | J24: 30000 | K24: =AVERAGE(D24:J24) -> 29714.286
A25: 6 | B25: I K A N
B26: - Ikan Tongkol Segar (Uk. Sedang) | C26: Kg | D26: 42000 | E26: 44000 | F26: 35000 | G26: 40000 | H26: 30000 | I26: 38000 | J26: 35000 | K26: =AVERAGE(D26:J26) -> 37714.286
B27: - Ikan Mujair Segar (Uk. Sedang) | C27: Kg | D27: - | E27: 30000 | F27: 30000 | G27: 30000 | H27: 23000 | I27: 30000 | J27: 28000 | K27: =AVERAGE(D27:J27) -> 28500
B28: - Udang Segar (Uk. Sedang) | C28: Kg | D28: - | E28: 60000 | F28: 60000 | G28: 85000 | H28: 58000 | I28: 68000 | J28: 55000 | K28: =AVERAGE(D28:J28) -> 64333.333
B29: - Ikan Lele Segar (Ukuran Sedang) | C29: Kg | D29: - | E29: - | F29: - | G29: 25000 | H29: 23000 | I29: 24000 | J29: 26000 | K29: =AVERAGE(D29:J29) -> 24500
B30: - Ikan Bandeng Segar (Uk. Sedang) | C30: Kg | D30: 40000 | E30: 36000 | F30: 38000 | G30: 40000 | H30: 28000 | I30: 38000 | J30: 40000 | K30: =AVERAGE(D30:J30) -> 37142.857
B31: - Ikan Teri Asin (Bukan Teri Medan) | C31: Kg | D31: 80000 | E31: 100000 | F31: 100000 | G31: 60000 | H31: 80000 | I31: - | J31: - | K31: =AVERAGE(D31:J31) -> 84000
A32: 7 | B32: TELUR
B33: - Telur Ayam Broiler | C33: Kg | D33: 26000 | E33: 26000 | F33: 27000 | G33: 27000 | H33: 26000 | I33: 27000 | J33: 26500 | K33: =AVERAGE(D33:J33) -> 26500
B34: - Telur Ayam Kampung | C34: Butir | D34: 2500 | E34: 2000 | F34: 2200 | G34: 2400 | H34: 2000 | I34: 2500 | J34: 3000 | K34: =AVERAGE(D34:J34) -> 2371.4286
A35: 8 | B35: S U S U
B36: - Susu Kental Manis "INDOMILK" Putih | C36: 390 Gr/kaleng | D36: 12500 | E36: 12000 | F36: 10000 | G36: 12500 | H36: - | I36: 12000 | J36: 10000 | K36: =AVERAGE(D36:J36) -> 11500
B37: - Susu Bubuk "DANCOW" Full Cream | C37: 400 Gr/Dos | D37: - | E37: 37900 | F37: - | G37: 42500 | H37: - | I37: - | J37: - | K37: =AVERAGE(D37:J37) -> 40200
A38: 9 | B38: SABUN CUCI
B39: - Sabun Detergen Rinso (Anti Noda) | C39: 900 Gram | D39: 22000 | E39: - | F39: - | G39: 20500 | H39: 17500 | I39: 21000 | J39: 17500 | K39: =AVERAGE(D39:J39) -> 19700
B40: - Sabun Colek "Wing's Biru" | C40: 350 Gram | D40: 2000 | E40: - | F40: - | G40: 2000 | H40: 2000 | I40: 2000 | J40: 2000 | K40: =AVERAGE(D40:J40) -> 2000
A41: 10 | B41: JAGUNG
B42: - Jagung Pipilan Kering (Jenis Kecil) | C42: Kg | D42: 11000 | E42: 8000 | F42: 8000 | G42: 11000 | H42: 9000 | I42: 10000 | J42: 8000 | K42: =AVERAGE(D42:J42) -> 9285.7143
...

Sheet 2
A1: HARGA BAHAN-BAHAN POKOK
A2: DI PASAR TRADISIONAL KOTA SURABAYA
A3: HARI / TANGGAL : Kamis / 02 Februari 2023
B4: NAMA BAHAN POKOK DAN PENTING LAINNYA | C4: SATUAN | D4: Pasar Tambahrejo | E4: Pasar Pucang Anom | F4: Pasar Wonokromo | G4: Pasar Genteng Baru | H4: Pasar Pabean | I4: Pasar Kembang | J4: Pasar Balongsari | K4: Rata-Rata
A7: 1 | B7: BERAS
B8: - Beras IR.64 Kwalitas I | C8: Kg | D8: 12500 | E8: 12500 | F8: 12000 | G8: 12800 | H8: 12500 | I8: 13000 | J8: 12500 | K8: =AVERAGE(D8:J8) -> 12542.857
B9: - Beras IR.64 Kwalitas II | C9: Kg | D9: 11000 | E9: 12500 | F9: 11500 | G9: 12000 | H9: 10500 | I9: 11500 | J9: 11000 | K9: =AVERAGE(D9:J9) -> 11428.571
B10: - Beras IR.64 Kwalitas III | C10: Kg | D10: 12000 | E10: 11500 | F10: 10500 | G10: 9450 | H10: 9500 | I10: 10500 | J10: - | K10: =AVERAGE(D10:J10) -> 10575
B11: - Beras Jagung | C11: Kg | D11: - | E11: - | F11: - | G11: 11000 | H11: - | I11: 11000 | J11: 8000 | K11: =AVERAGE(D11:J11) -> 10000
B12: - Beras Ketan (Jenis Siyem) | C12: Kg | D12: - | E12: 23000 | F12: - | G12: 18000 | H12: - | I12: 18000 | J12: 18000 | K12: =AVERAGE(D12:J12) -> 19250
A13: 2 | B13: GULA
B14: Gula Pasir Lokal Curah | C14: Kg | D14: 13000 | E14: 13000 | F14: 13500 | G14: 13000 | H14: 13000 | I14: 13500 | J14: 13000 | K14: =AVERAGE(D14:J14) -> 13142.857
B15: - Gula Jawa/Merah (Bahan Kelapa) | C15: Kg | D15: 15000 | E15: 16000 | F15: 17000 | G15: 19000 | H15: 15000 | I15: 16000 | J15: 16000 | K15: =AVERAGE(D15:J15) -> 16285.714
B16: MINYAK GORENG
B17: - Minyak Goreng Curah (Bening) | C17: Kg | D17: 16000 | E17: 16000 | F17: 17000 | G17: 16000 | H17: 16000 | I17: 16500 | J17: 16000 | K17: =AVERAGE(D17:J17) -> 16214.286
A18: 4 | B18: MENTEGA
B19: - Mentega Curah (Amanda) | C19: Kg | D19: - | E19: - | F19: - | G19: 14000 | H19: - | I19: 24000 | J19: - | K19: =AVERAGE(D19:J19) -> 19000
A20: 5 | B20: DAGING
B21: - Daging Sapi Grade Atas | C21: Kg | D21: 120000 | E21: 120000 | F21: 120000 | G21: 120000 | H21: 117000 | I21: 120000 | J21: 110000 | K21: =AVERAGE(D21:J21) -> 118142.86
B22: - Daging Sapi Grade Sedang | C22: Kg | D22: 110000 | E22: 110000 | F22: 150000 | G22: 110000 | H22: 114000 | I22: 110000 | J22: 100000 | K22: =AVERAGE(D22:J22) -> 114857.14
B23: - Daging Sapi Grade Bawah | C23: Kg | D23: 100000 | E23: 95000 | F23: 105000 | G23: 100000 | H23: 100000 | I23: 100000 | J23: - | K23: =AVERAGE(D23:J23) -> 100000
B24: - Daging Ayam Broiler | C24: Kg | D24: 30000 | E24: 29000 | F24: 31000 | G24: 30000 | H24: 32000 | I24: 30000 | J24: 30000 | K24: =AVERAGE(D24:J24) -> 30285.714
A25: 6 | B25: I K A N
B26: - Ikan Tongkol Segar (Uk. Sedang) | C26: Kg | D26: 42000 | E26: 44000 | F26: 35000 | G26: 40000 | H26: 30000 | I26: 38000 | J26: 35000 | K26: =AVERAGE(D26:J26) -> 37714.286
B27: - Ikan Mujair Segar (Uk. Sedang) | C27: Kg | D27: - | E27: 30000 | F27: 30000 | G27: 30000 | H27: 23000 | I27: 30000 | J27: 28000 | K27: =AVERAGE(D27:J27) -> 28500
B28: - Udang Segar (Uk. Sedang) | C28: Kg | D28: - | E28: 60000 | F28: 60000 | G28: 85000 | H28: 58000 | I28: 65000 | J28: 55000 | K28: =AVERAGE(D28:J28) -> 63833.333
B29: - Ikan Lele Segar (Ukuran Sedang) | C29: Kg | D29: - | E29: - | F29: - | G29: 25000 | H29: 23000 | I29: 24000 | J29: 26000 | K29: =AVERAGE(D29:J29) -> 24500
B30: - Ikan Bandeng Segar (Uk. Sedang) | C30: Kg | D30: 40000 | E30: 36000 | F30: 40000 | G30: 40000 | H30: 28000 | I30: 38000 | J30: 40000 | K30: =AVERAGE(D30:J30) -> 37428.571
B31: - Ikan Teri Asin (Bukan Teri Medan) | C31: Kg | D31: 80000 | E31: 100000 | F31: 100000 | G31: 60000 | H31: 80000 | I31: - | J31: - | K31: =AVERAGE(D31:J31) -> 84000
A32: 7 | B32: TELUR
B33: - Telur Ayam Broiler | C33: Kg | D33: 26000 | E33: 27000 | F33: 27000 | G33: 27000 | H33: 25000 | I33: 27000 | J33: 26500 | K33: =AVERAGE(D33:J33) -> 26500
B34: - Telur Ayam Kampung | C34: Butir | D34: 2500 | E34: 2000 | F34: 2500 | G34: 2400 | H34: 2000 | I34: 2500 | J34: 3000 | K34: =AVERAGE(D34:J34) -> 2414.2857
A35: 8 | B35: S U S U
B36: - Susu Kental Manis "INDOMILK" Putih | C36: 390 Gr/kaleng | D36: 12500 | E36: 12000 | F36: 10000 | G36: 12500 | H36: - | I36: 12000 | J36: 10000 | K36: =AVERAGE(D36:J36) -> 11500
B37: - Susu Bubuk "DANCOW" Full Cream | C37: 400 Gr/Dos | D37: - | E37: 37900 | F37: - | G37: 42500 | H37: - | I37: - | J37: - | K37: =AVERAGE(D37:J37) -> 40200
A38: 9 | B38: SABUN CUCI
B39: - Sabun Detergen Rinso (Anti Noda) | C39: 900 Gram | D39: 22000 | E39: - | F39: - | G39: 20500 | H39: 17500 | I39: 21000 | J39: 17500 | K39: =AVERAGE(D39:J39) -> 19700
B40: - Sabun Colek "Wing's Biru" | C40: 350 Gram | D40: 2000 | E40: - | F40: - | G40: 2000 | H40: 2000 | I40: 2000 | J40: 2000 | K40: =AVERAGE(D40:J40) -> 2000
A41: 10 | B41: JAGUNG
B42: - Jagung Pipilan Kering (Jenis Kecil) | C42: Kg | D42: 11000 | E42: 8000 | F42: 8000 | G42: 11000 | H42: 9000 | I42: 10000 | J42: 8000 | K42: =AVERAGE(D42:J42) -> 9285.7143
...

Sheet 3
A1: HARGA BAHAN-BAHAN POKOK
A2: DI PASAR TRADISIONAL KOTA SURABAYA
A3: HARI / TANGGAL : Jumat / 03 Februari 2023
B4: NAMA BAHAN POKOK DAN PENTING LAINNYA | C4: SATUAN | D4: Pasar Tambahrejo | E4: Pasar Pucang Anom | F4: Pasar Wonokromo | G4: Pasar Genteng Baru | H4: Pasar Pabean | I4: Pasar Kembang | J4: Pasar Balongsari | K4: Rata-Rata
A7: 1 | B7: BERAS
B8: - Beras IR.64 Kwalitas I | C8: Kg | D8: 12000 | E8: 12500 | F8: 13500 | G8: 12800 | H8: 12500 | I8: 13000 | J8: 12500 | K8: =AVERAGE(D8:J8) -> 12685.714
B9: - Beras IR.64 Kwalitas II | C9: Kg | D9: 11000 | E9: 12500 | F9: 12000 | G9: 12000 | H9: 10500 | I9: 11500 | J9: 11000 | K9: =AVERAGE(D9:J9) -> 11500
B10: - Beras IR.64 Kwalitas III | C10: Kg | D10: 11000 | E10: 12000 | F10: 12000 | G10: 9450 | H10: 9500 | I10: 10500 | J10: - | K10: =AVERAGE(D10:J10) -> 10741.667
B11: - Beras Jagung | C11: Kg | D11: - | E11: - | F11: - | G11: 11000 | H11: - | I11: 11000 | J11: 8000 | K11: =AVERAGE(D11:J11) -> 10000
B12: - Beras Ketan (Jenis Siyem) | C12: Kg | D12: - | E12: 23000 | F12: - | G12: 18000 | H12: - | I12: 18000 | J12: 18000 | K12: =AVERAGE(D12:J12) -> 19250
A13: 2 | B13: GULA
B14: Gula Pasir Lokal Curah | C14: Kg | D14: 13000 | E14: 13000 | F14: 13500 | G14: 13000 | H14: 13000 | I14: 13500 | J14: 13000 | K14: =AVERAGE(D14:J14) -> 13142.857
B15: - Gula Jawa/Merah (Bahan Kelapa) | C15: Kg | D15: 15000 | E15: 16000 | F15: 16000 | G15: 19000 | H15: 15000 | I15: 16000 | J15: 16000 | K15: =AVERAGE(D15:J15) -> 16142.857
B16: MINYAK GORENG
B17: - Minyak Goreng Curah (Bening) | C17: Kg | D17: 16000 | E17: 16000 | F17: 17000 | G17: 16000 | H17: 16000 | I17: 16500 | J17: 16000 | K17: =AVERAGE(D17:J17) -> 16214.286
A18: 4 | B18: MENTEGA
B19: - Mentega Curah (Amanda) | C19: Kg | D19: - | E19: - | F19: - | G19: 14000 | H19: - | I19: 24000 | J19: - | K19: =AVERAGE(D19:J19) -> 19000
A20: 5 | B20: DAGING
B21: - Daging Sapi Grade Atas | C21: Kg | D21: 120000 | E21: 120000 | F21: 120000 | G21: 120000 | H21: 117000 | I21: 120000 | J21: 110000 | K21: =AVERAGE(D21:J21) -> 118142.86
B22: - Daging Sapi Grade Sedang | C22: Kg | D22: 110000 | E22: 110000 | F22: 150000 | G22: 110000 | H22: 114000 | I22: 110000 | J22: 100000 | K22: =AVERAGE(D22:J22) -> 114857.14
B23: - Daging Sapi Grade Bawah | C23: Kg | D23: 100000 | E23: 95000 | F23: 105000 | G23: 100000 | H23: 100000 | I23: 100000 | J23: - | K23: =AVERAGE(D23:J23) -> 100000
B24: - Daging Ayam Broiler | C24: Kg | D24: 30000 | E24: 29000 | F24: 32000 | G24: 30000 | H24: 32000 | I24: 30000 | J24: 32000 | K24: =AVERAGE(D24:J24) -> 30714.286
A25: 6 | B25: I K A N
B26: - Ikan Tongkol Segar (Uk. Sedang) | C26: Kg | D26: 48000 | E26: 44000 | F26: 35000 | G26: 40000 | H26: 30000 | I26: 38000 | J26: 35000 | K26: =AVERAGE(D26:J26) -> 38571.429
B27: - Ikan Mujair Segar (Uk. Sedang) | C27: Kg | D27: - | E27: 30000 | F27: 30000 | G27: 30000 | H27: 23000 | I27: 30000 | J27: 28000 | K27: =AVERAGE(D27:J27) -> 28500
B28: - Udang Segar (Uk. Sedang) | C28: Kg | D28: - | E28: 60000 | F28: 60000 | G28: 85000 | H28: 58000 | I28: 65000 | J28: 55000 | K28: =AVERAGE(D28:J28) -> 63833.333
B29: - Ikan Lele Segar (Ukuran Sedang) | C29: Kg | D29: - | E29: - | F29: - | G29: 25000 | H29: 23000 | I29: 24000 | J29: 26000 | K29: =AVERAGE(D29:J29) -> 24500
B30: - Ikan Bandeng Segar (Uk. Sedang) | C30: Kg | D30: 40000 | E30: 36000 | F30: 40000 | G30: 40000 | H30: 28000 | I30: 38000 | J30: 30000 | K30: =AVERAGE(D30:J30) -> 36000
B31: - Ikan Teri Asin (Bukan Teri Medan) | C31: Kg | D31: 80000 | E31: 100000 | F31: 100000 | G31: 60000 | H31: 80000 | I31: - | J31: - | K31: =AVERAGE(D31:J31) -> 84000
A32: 7 | B32: TELUR
B33: - Telur Ayam Broiler | C33: Kg | D33: 26000 | E33: 27000 | F33: 26000 | G33: 26000 | H33: 25000 | I33: 27000 | J33: 26500 | K33: =AVERAGE(D33:J33) -> 26214.286
B34: - Telur Ayam Kampung | C34: Butir | D34: 2500 | E34: 2000 | F34: 2000 | G34: 2400 | H34: 2000 | I34: 2500 | J34: 3000 | K34: =AVERAGE(D34:J34) -> 2342.8571
A35: 8 | B35: S U S U
B36: - Susu Kental Manis "INDOMILK" Putih | C36: 390 Gr/kaleng | D36: 12500 | E36: 12000 | F36: 10000 | G36: 12500 | H36: - | I36: 12000 | J36: 10000 | K36: =AVERAGE(D36:J36) -> 11500
B37: - Susu Bubuk "DANCOW" Full Cream | C37: 400 Gr/Dos | D37: - | E37: 37900 | F37: - | G37: 42500 | H37: - | I37: - | J37: - | K37: =AVERAGE(D37:J37) -> 40200
A38: 9 | B38: SABUN CUCI
B39: - Sabun Detergen Rinso (Anti Noda) | C39: 900 Gram | D39: 22000 | E39: - | F39: - | G39: 20500 | H39: 17500 | I39: 21000 | J39: 17500 | K39: =AVERAGE(D39:J39) -> 19700
B40: - Sabun Colek "Wing's Biru" | C40: 350 Gram | D40: 2000 | E40: - | F40: - | G40: 2000 | H40: 2000 | I40: 2000 | J40: 2000 | K40: =AVERAGE(D40:J40) -> 2000
A41: 10 | B41: JAGUNG
B42: - Jagung Pipilan Kering (Jenis Kecil) | C42: Kg | D42: 11000 | E42: 8000 | F42: 9000 | G42: 11000 | H42: 9000 | I42: 10000 | J42: 8000 | K42: =AVERAGE(D42:J42) -> 9428.5714
...

Sheet 4
A1: HARGA BAHAN-BAHAN POKOK
A2: DI PASAR TRADISIONAL KOTA SURABAYA
A3: HARI / TANGGAL : Sabtu / 04 Februari 2023
B4: NAMA BAHAN POKOK DAN PENTING LAINNYA | C4: SATUAN | D4: Pasar Tambahrejo | E4: Pasar Pucang Anom | F4: Pasar Wonokromo | G4: Pasar Genteng Baru | H4: Pasar Pabean | I4: Pasar Kembang | J4: Pasar Balongsari | K4: Rata-Rata
A7: 1 | B7: BERAS
