Workbook

Sheet REKAPITULASI
A1: BAGIAN PEREKONOMIAN DAN SUMBER DAYA ALAM
A2: LAPORAN HARGA BAHAN POKOK DI KOTA SURABAYA
A3: PERIODE MEI 2023
B4: NAMA BAHAN POKOK DAN PENTING LAINNYA | C4: SAT | AI4: HET/HAPK (Harga Eceran Tertinggi) | AJ4: FLUKTUASI
D5: 1 | E5: 2 | F5: 3 | G5: 4 | H5: 5 | I5: 6 | J5: 7 | K5: 8 | L5: 9 | M5: 10 | N5: 11 | O5: 12 | P5: 13 | Q5: 14 | R5: 15 | S5: 16 | T5: 17 | U5: 18 | V5: 19 | W5: 20 | X5: 21 | Y5: 22 | Z5: 23 | AA5: 24 | AB5: 25 | AC5: 26 | AD5: 27 | AE5: 28 | AF5: 29 | AG5: 30 | AH5: 31
A7: 1 | B7: BERAS
B8: - Beras Premium | C8: Kg | D8: ='1'!K8 -> 13328.571 | E8: ='2'!K8 -> 13328.571 | F8: ='3'!K8 -> 13328.571 | G8: ='4'!K8 -> 13328.571 | H8: ='5'!K8 -> 13328.571 | I8: ='6'!K8 -> 13328.571 | J8: ='7'!K8 -> 13328.571 | K8: ='8'!K8 -> 13257.143 | L8: ='9'!K8 -> 13328.571 | M8: ='10'!K8 -> 13328.571 | N8: ='11'!K8 -> 13328.571 | O8: ='12'!K8 -> 13042.857 | P8: ='13'!K8 -> 13042.857 | Q8: ='14'!K8 -> 13042.857 | R8: ='15'!K8 -> 13042.857 | S8: ='16'!K8 -> 13042.857 | T8: ='17'!K8 -> 13042.857 | U8: ='18'!K8 -> 13071.429 | V8: ='19'!K8 -> 13214.286 | W8: ='20'!K8 -> 13214.286 | X8: ='21'!K8 -> 13142.857 | Y8: ='22'!K8 -> 13214.286 | Z8: ='23'!K8 -> 13214.286 | AA8: ='24'!K8 -> 13214.286 | AB8: ='25'!K8 -> 13285.714 | AC8: ='26'!K8 -> 13285.714 | AD8: ='27'!K8 -> 13285.714 | AE8: ='28'!K8 -> 13285.714 | AF8: ='29'!K8 -> 13142.857 | AG8: ='30'!K8 -> 13500 | AH8: ='31'!K8 -> 13428.571 | AI8: 12800 | AJ8: =AH8-D8 -> 100 | AK8: =AVERAGE(D8:AH8) -> 13235.484
B9: - Beras Medium Bulog | C9: Kg | AG9: ='30'!K9 -> 10333.333 | AH9: ='31'!K9 -> 9566.6667 | AK9: =AVERAGE(D9:AH9) -> 9950
B10: - Beras Medium | C10: Kg | D10: ='1'!K9 -> 8971.4286 | E10: ='2'!K9 -> 8971.4286 | F10: ='3'!K9 -> 8971.4286 | G10: ='4'!K9 -> 8971.4286 | H10: ='5'!K9 -> 8971.4286 | I10: ='6'!K9 -> 8971.4286 | J10: ='7'!K9 -> 8971.4286 | K10: ='8'!K9 -> 8971.4286 | L10: ='9'!K9 -> 9400 | M10: ='10'!K9 -> 9400 | N10: ='11'!K9 -> 9400 | O10: ='12'!K9 -> 9400 | P10: ='13'!K9 -> 9400 | Q10: ='14'!K9 -> 9400 | R10: ='15'!K9 -> 9400 | S10: ='16'!K9 -> 9400 | T10: ='17'!K9 -> 9400 | U10: ='18'!K9 -> 9400 | V10: ='19'!K9 -> 8971.4286 | W10: ='20'!K9 -> 8971.4286 | X10: ='21'!K9 -> 8971.4286 | Y10: ='22'!K9 -> 8971.4286 | Z10: ='23'!K9 -> 8971.4286 | AA10: ='24'!K9 -> 8971.4286 | AB10: ='25'!K9 -> 9000 | AC10: ='26'!K9 -> 9000 | AD10: ='27'!K9 -> 9028.5714 | AE10: ='28'!K9 -> 9028.5714 | AF10: ='29'!K9 -> 9428.5714 | AG10: ='30'!K10 -> 11375 | AH10: ='31'!K10 -> 11166.667 | AI10: 9450 | AJ10: =AH10-D10 -> 2195.2381 | AK10: =AVERAGE(D10:AH10) -> 9278.3026
B11: - Beras Jagung | C11: Kg | D11: ='1'!K10 -> 9500 | E11: ='2'!K10 -> 9500 | F11: ='3'!K10 -> 9500 | G11: ='4'!K10 -> 9500 | H11: ='5'!K10 -> 9500 | I11: ='6'!K10 -> 9500 | J11: ='7'!K10 -> 9500 | K11: ='8'!K10 -> 9500 | L11: ='9'!K10 -> 10600 | M11: ='10'!K10 -> 10600 | N11: ='11'!K10 -> 10600 | O11: ='12'!K10 -> 10600 | P11: ='13'!K10 -> 10600 | Q11: ='14'!K10 -> 10600 | R11: ='15'!K10 -> 10600 | S11: ='16'!K10 -> 10600 | T11: ='17'!K10 -> 10600 | U11: ='18'!K10 -> 10600 | V11: ='19'!K10 -> 10600 | W11: ='20'!K10 -> 10600 | X11: ='21'!K10 -> 10600 | Y11: ='22'!K10 -> 10600 | Z11: ='23'!K10 -> 10600 | AA11: ='24'!K10 -> 10600 | AB11: ='25'!K10 -> 10600 | AC11: ='26'!K10 -> 10600 | AD11: ='27'!K10 -> 10600 | AE11: ='28'!K10 -> 10600 | AF11: ='29'!K10 -> 10600 | AG11: ='30'!K11 -> 10600 | AH11: ='31'!K11 -> 10600 | AJ11: =AH11-D11 -> 1100 | AK11: =AVERAGE(D11:AH11) -> 10316.129
B12: - Beras Ketan (Jenis Siyem) | C12: Kg | D12: ='1'!K11 -> 20000 | E12: ='2'!K11 -> 20000 | F12: ='3'!K11 -> 20000 | G12: ='4'!K11 -> 20000 | H12: ='5'!K11 -> 20000 | I12: ='6'!K11 -> 19333.333 | J12: ='7'!K11 -> 19333.333 | K12: ='8'!K11 -> 19333.333 | L12: ='9'!K11 -> 20200 | M12: ='10'!K11 -> 20200 | N12: ='11'!K11 -> 20200 | O12: ='12'!K11 -> 20200 | P12: ='13'!K11 -> 20200 | Q12: ='14'!K11 -> 20200 | R12: ='15'!K11 -> 20200 | S12: ='16'!K11 -> 20200 | T12: ='17'!K11 -> 20200 | U12: ='18'!K11 -> 20200 | V12: ='19'!K11 -> 20200 | W12: ='20'!K11 -> 20200 | X12: ='21'!K11 -> 20200 | Y12: ='22'!K11 -> 20200 | Z12: ='23'!K11 -> 20200 | AA12: ='24'!K11 -> 20200 | AB12: ='25'!K11 -> 20200 | AC12: ='26'!K11 -> 20200 | AD12: ='27'!K11 -> 20600 | AE12: ='28'!K11 -> 20600 | AF12: ='29'!K11 -> 20600 | AG12: ='30'!K12 -> 20200 | AH12: ='31'!K12 -> 21000 | AJ12: =AH12-D12 -> 1000 | AK12: =AVERAGE(D12:AH12) -> 20148.387
A13: 2 | B13: GULA | D13: ='1'!K12 | E13: ='2'!K12 | F13: ='3'!K12 | G13: ='4'!K12 | H13: ='5'!K12 | I13: ='6'!K12 | J13: ='7'!K12 | K13: ='8'!K12 | L13: ='9'!K12 | M13: ='10'!K12 | N13: ='11'!K12 | O13: ='12'!K12 | P13: ='13'!K12 | Q13: ='14'!K12 | R13: ='15'!K12 | S13: ='16'!K12 | T13: ='17'!K12 | U13: ='18'!K12 | V13: ='19'!K12 | W13: ='20'!K12 | X13: ='21'!K12 | Y13: ='22'!K12 | Z13: ='23'!K12 | AA13: ='24'!K12 | AB13: ='25'!K12 | AC13: ='26'!K12 | AD13: ='27'!K12 | AE13: ='28'!K12 | AF13: ='29'!K12 | AG13: ='30'!K13 | AH13: ='31'!K13 | AJ13: =AH13-D13 -> 0 | AK13: =AVERAGE(D13:AH13) -> #DIV/0!
B14: - Gula pasir lokal curah | C14: Kg | D14: ='1'!K13 -> 13000 | E14: ='2'!K13 -> 13000 | F14: ='3'!K13 -> 13000 | G14: ='4'!K13 -> 13000 | H14: ='5'!K13 -> 13000 | I14: ='6'!K13 -> 13000 | J14: ='7'!K13 -> 13000 | K14: ='8'!K13 -> 13000 | L14: ='9'!K13 -> 13000 | M14: ='10'!K13 -> 13000 | N14: ='11'!K13 -> 13000 | O14: ='12'!K13 -> 13000 | P14: ='13'!K13 -> 13000 | Q14: ='14'!K13 -> 13000 | R14: ='15'!K13 -> 13000 | S14: ='16'!K13 -> 13000 | T14: ='17'!K13 -> 13000 | U14: ='18'!K13 -> 13000 | V14: ='19'!K13 -> 13000 | W14: ='20'!K13 -> 13000 | X14: ='21'!K13 -> 13000 | Y14: ='22'!K13 -> 13000 | Z14: ='23'!K13 -> 13000 | AA14: ='24'!K13 -> 13071.429 | AB14: ='25'!K13 -> 13071.429 | AC14: ='26'!K13 -> 13071.429 | AD14: ='27'!K13 -> 13071.429 | AE14: ='28'!K13 -> 13071.429 | AF14: ='29'!K13 -> 13071.429 | AG14: ='30'!K14 -> 13071.429 | AH14: ='31'!K14 -> 13142.857 | AI14: 13500 | AJ14: =AH14-D14 -> 142.85714 | AK14: =AVERAGE(D14:AH14) -> 13020.737
B15: - Gula Jawa/Merah (Bahan Kelapa) | C15: Kg | D15: ='1'!K14 -> 16142.857 | E15: ='2'!K14 -> 16142.857 | F15: ='3'!K14 -> 16285.714 | G15: ='4'!K14 -> 16285.714 | H15: ='5'!K14 -> 16285.714 | I15: ='6'!K14 -> 16285.714 | J15: ='7'!K14 -> 16285.714 | K15: ='8'!K14 -> 16285.714 | L15: ='9'!K14 -> 15571.429 | M15: ='10'!K14 -> 15571.429 | N15: ='11'!K14 -> 15571.429 | O15: ='12'!K14 -> 15571.429 | P15: ='13'!K14 -> 15571.429 | Q15: ='14'!K14 -> 15571.429 | R15: ='15'!K14 -> 15571.429 | S15: ='16'!K14 -> 15571.429 | T15: ='17'!K14 -> 15714.286 | U15: ='18'!K14 -> 15714.286 | V15: ='19'!K14 -> 15714.286 | W15: ='20'!K14 -> 15714.286 | X15: ='21'!K14 -> 15714.286 | Y15: ='22'!K14 -> 15714.286 | Z15: ='23'!K14 -> 15714.286 | AA15: ='24'!K14 -> 15714.286 | AB15: ='25'!K14 -> 15714.286 | AC15: ='26'!K14 -> 15714.286 | AD15: ='27'!K14 -> 15714.286 | AE15: ='28'!K14 -> 15714.286 | AF15: ='29'!K14 -> 15714.286 | AG15: ='30'!K15 -> 16285.714 | AH15: ='31'!K15 -> 15714.286 | AJ15: =AH15-D15 -> -428.57143 | AK15: =AVERAGE(D15:AH15) -> 15834.101
A16: 3 | B16: MINYAK GORENG | D16: ='1'!K15 | E16: ='2'!K15 | F16: ='3'!K15 | G16: ='4'!K15 | H16: ='5'!K15 | I16: ='6'!K15 | J16: ='7'!K15 | K16: ='8'!K15 | L16: ='9'!K15 | M16: ='10'!K15 | N16: ='11'!K15 | O16: ='12'!K15 | P16: ='13'!K15 | Q16: ='14'!K15 | R16: ='15'!K15 | S16: ='16'!K15 | T16: ='17'!K15 | U16: ='18'!K15 | V16: ='19'!K15 | W16: ='20'!K15 | X16: ='21'!K15 | Y16: ='22'!K15 | Z16: ='23'!K15 | AA16: ='24'!K15 | AB16: ='25'!K15 | AC16: ='26'!K15 | AD16: ='27'!K15 | AE16: ='28'!K15 | AF16: ='29'!K15 | AG16: ='30'!K16 | AH16: ='31'!K16 | AJ16: =AH16-D16 -> 0 | AK16: =AVERAGE(D16:AH16) -> #DIV/0!
B17: - Minyak Goreng Curah (Bening) | C17: Kg | D17: ='1'!K16 -> 15428.571 | E17: ='2'!K16 -> 15428.571 | F17: ='3'!K16 -> 15428.571 | G17: ='4'!K16 -> 15428.571 | H17: ='5'!K16 -> 15285.714 | I17: ='6'!K16 -> 15285.714 | J17: ='7'!K16 -> 15571.429 | K17: ='8'!K16 -> 15714.286 | L17: ='9'!K16 -> 15833.333 | M17: ='10'!K16 -> 15833.333 | N17: ='11'!K16 -> 15833.333 | O17: ='12'!K16 -> 15833.333 | P17: ='13'!K16 -> 15833.333 | Q17: ='14'!K16 -> 16000 | R17: ='15'!K16 -> 16000 | S17: ='16'!K16 -> 16000 | T17: ='17'!K16 -> 15833.333 | U17: ='18'!K16 -> 15833.333 | V17: ='19'!K16 -> 15833.333 | W17: ='20'!K16 -> 15857.143 | X17: ='21'!K16 -> 15857.143 | Y17: ='22'!K16 -> 15833.333 | Z17: ='23'!K16 -> 15857.143 | AA17: ='24'!K16 -> 15857.143 | AB17: ='25'!K16 -> 15857.143 | AC17: ='26'!K16 -> 15857.143 | AD17: ='27'!K16 -> 15785.714 | AE17: ='28'!K16 -> 15785.714 | AF17: ='29'!K16 -> 15785.714 | AG17: ='30'!K17 -> 15357.143 | AH17: ='31'!K17 -> 15785.714 | AI17: 15500 | AJ17: =AH17-D17 -> 357.14286 | AK17: =AVERAGE(D17:AH17) -> 15732.719
B18: - Minyak Kita | C18: Liter | D18: ='1'!K17 -> 14000 | E18: ='2'!K17 -> 14000 | F18: ='3'!K17 -> 14000 | G18: ='4'!K17 -> 14000 | H18: ='5'!K17 -> 14000 | I18: ='6'!K17 -> 14000 | J18: ='7'!K17 -> 14000 | K18: ='8'!K17 -> 14000 | L18: ='9'!K17 -> 14333.333 | M18: ='10'!K17 -> 14333.333 | N18: ='11'!K17 -> 14333.333 | O18: ='12'!K17 -> 14333.333 | P18: ='13'!K17 -> 14333.333 | Q18: ='14'!K17 -> 14333.333 | R18: ='15'!K17 -> 14333.333 | S18: ='16'!K17 -> 14333.333 | T18: ='17'!K17 -> 14333.333 | U18: ='18'!K17 -> 14333.333 | V18: ='19'!K17 -> 14333.333 | W18: ='20'!K17 -> 14000 | X18: ='21'!K17 -> 14000 | Y18: ='22'!K17 -> 14333.333 | Z18: ='23'!K17 -> 14000 | AA18: ='24'!K17 -> 14000 | AB18: ='25'!K17 -> 14000 | AC18: ='26'!K17 -> 14000 | AD18: ='27'!K17 -> 14000 | AE18: ='28'!K17 -> 14000 | AF18: ='29'!K17 -> 14000 | AG18: ='30'!K18 -> 14000 | AH18: ='31'!K18 -> 14000 | AI18: 14000 | AJ18: =AH18-D18 -> 0 | AK18: =AVERAGE(D18:AH18) -> 14129.032
A19: 4 | B19: MENTEGA | D19: ='1'!K18 | E19: ='2'!K18 | F19: ='3'!K18 | G19: ='4'!K18 | H19: ='5'!K18 | I19: ='6'!K18 | J19: ='7'!K18 | K19: ='8'!K18 | L19: ='9'!K18 | M19: ='10'!K18 | N19: ='11'!K18 | O19: ='12'!K18 | P19: ='13'!K18 | Q19: ='14'!K18 | R19: ='15'!K18 | S19: ='16'!K18 | T19: ='17'!K18 | U19: ='18'!K18 | V19: ='19'!K18 | W19: ='20'!K18 | X19: ='21'!K18 | Y19: ='22'!K18 | Z19: ='23'!K18 | AA19: ='24'!K18 | AB19: ='25'!K18 | AC19: ='26'!K18 | AD19: ='27'!K18 | AE19: ='28'!K18 | AF19: ='29'!K18 | AG19: ='30'!K19 | AH19: ='31'!K19 | AJ19: =AH19-D19 -> 0 | AK19: =AVERAGE(D19:AH19) -> #DIV/0!
B20: - Mentega Curah (Amanda) | C20: Kg | D20: ='1'!K19 -> 19000 | E20: ='2'!K19 -> 19000 | F20: ='3'!K19 -> 19000 | G20: ='4'!K19 -> 19000 | H20: ='5'!K19 -> 19000 | I20: ='6'!K19 -> 19000 | J20: ='7'!K19 -> 19000 | K20: ='8'!K19 -> 19000 | L20: ='9'!K19 -> 21750 | M20: ='10'!K19 -> 21750 | N20: ='11'!K19 -> 21750 | O20: ='12'!K19 -> 21750 | P20: ='13'!K19 -> 21750 | Q20: ='14'!K19 -> 21250 | R20: ='15'!K19 -> 21250 | S20: ='16'!K19 -> 21250 | T20: ='17'!K19 -> 21250 | U20: ='18'!K19 -> 21250 | V20: ='19'!K19 -> 21250 | W20: ='20'!K19 -> 21250 | X20: ='21'!K19 -> 21250 | Y20: ='22'!K19 -> 21250 | Z20: ='23'!K19 -> 21250 | AA20: ='24'!K19 -> 21250 | AB20: ='25'!K19 -> 21250 | AC20: ='26'!K19 -> 21250 | AD20: ='27'!K19 -> 21250 | AE20: ='28'!K19 -> 21250 | AF20: ='29'!K19 -> 21250 | AG20: ='30'!K20 -> 22500 | AH20: ='31'!K20 -> 21250 | AJ20: =AH20-D20 -> 2250 | AK20: =AVERAGE(D20:AH20) -> 20790.323
A21: 5 | B21: DAGING | D21: ='1'!K20 | E21: ='2'!K20 | F21: ='3'!K20 | G21: ='4'!K20 | H21: ='5'!K20 | I21: ='6'!K20 | J21: ='7'!K20 | K21: ='8'!K20 | L21: ='9'!K20 | M21: ='10'!K20 | N21: ='11'!K20 | O21: ='12'!K20 | P21: ='13'!K20 | Q21: ='14'!K20 | R21: ='15'!K20 | S21: ='16'!K20 | T21: ='17'!K20 | U21: ='18'!K20 | V21: ='19'!K20 | W21: ='20'!K20 | X21: ='21'!K20 | Y21: ='22'!K20 | Z21: ='23'!K20 | AA21: ='24'!K20 | AB21: ='25'!K20 | AC21: ='26'!K20 | AD21: ='27'!K20 | AE21: ='28'!K20 | AF21: ='29'!K20 | AG21: ='30'!K21 | AH21: ='31'!K21 | AJ21: =AH21-D21 -> 0 | AK21: =AVERAGE(D21:AH21) -> #DIV/0!
B22: - Daging Sapi Grade Atas | C22: Kg | D22: ='1'!K21 -> 118142.86 | E22: ='2'!K21 -> 118142.86 | F22: ='3'!K21 -> 118142.86 | G22: ='4'!K21 -> 118142.86 | H22: ='5'!K21 -> 118142.86 | I22: ='6'!K21 -> 118142.86 | J22: ='7'!K21 -> 118142.86 | K22: ='8'!K21 -> 118142.86 | L22: ='9'!K21 -> 118142.86 | M22: ='10'!K21 -> 118142.86 | N22: ='11'!K21 -> 118142.86 | O22: ='12'!K21 -> 118142.86 | P22: ='13'!K21 -> 118142.86 | Q22: ='14'!K21 -> 118142.86 | R22: ='15'!K21 -> 118142.86 | S22: ='16'!K21 -> 118142.86 | T22: ='17'!K21 -> 118142.86 | U22: ='18'!K21 -> 118142.86 | V22: ='19'!K21 -> 118571.43 | W22: ='20'!K21 -> 118571.43 | X22: ='21'!K21 -> 118142.86 | Y22: ='22'!K21 -> 118142.86 | Z22: ='23'!K21 -> 118142.86 | AA22: ='24'!K21 -> 118142.86 | AB22: ='25'!K21 -> 118571.43 | AC22: ='26'!K21 -> 118571.43 | AD22: ='27'!K21 -> 118571.43 | AE22: ='28'!K21 -> 118571.43 | AF22: ='29'!K21 -> 118571.43 | AG22: ='30'!K22 -> 122857.14 | AH22: ='31'!K22 -> 118571.43 | AI22: 105000 | AJ22: =AH22-D22 -> 428.57143 | AK22: =AVERAGE(D22:AH22) -> 118405.53
B23: - Daging Sapi Grade Sedang | C23: Kg | D23: ='1'!K22 -> 109857.14 | E23: ='2'!K22 -> 109857.14 | F23: ='3'!K22 -> 109857.14 | G23: ='4'!K22 -> 109857.14 | H23: ='5'!K22 -> 109857.14 | I23: ='6'!K22 -> 109857.14 | J23: ='7'!K22 -> 109142.86 | K23: ='8'!K22 -> 109142.86 | L23: ='9'!K22 -> 109142.86 | M23: ='10'!K22 -> 109142.86 | N23: ='11'!K22 -> 109142.86 | O23: ='12'!K22 -> 109142.86 | P23: ='13'!K22 -> 109142.86 | Q23: ='14'!K22 -> 109142.86 | R23: ='15'!K22 -> 109142.86 | S23: ='16'!K22 -> 109142.86 | T23: ='17'!K22 -> 109142.86 | U23: ='18'!K22 -> 109142.86 | V23: ='19'!K22 -> 109142.86 | W23: ='20'!K22 -> 109142.86 | X23: ='21'!K22 -> 109142.86 | Y23: ='22'!K22 -> 109142.86 | Z23: ='23'!K22 -> 109142.86 | AA23: ='24'!K22 -> 109142.86 | AB23: ='25'!K22 -> 109142.86 | AC23: ='26'!K22 -> 109142.86 | AD23: ='27'!K22 -> 109142.86 | AE23: ='28'!K22 -> 109142.86 | AF23: ='29'!K22 -> 109142.86 | AG23: ='30'!K23 -> 114142.86 | AH23: ='31'!K23 -> 109142.86 | AI23: 80000 | AJ23: =AH23-D23 -> -714.28571 | AK23: =AVERAGE(D23:AH23) -> 109442.4
B24: - Daging Sapi Grade Bawah | C24: Kg | D24: ='1'!K23 -> 100000 | E24: ='2'!K23 -> 100000 | F24: ='3'!K23 -> 100000 | G24: ='4'!K23 -> 100000 | H24: ='5'!K23 -> 100000 | I24: ='6'!K23 -> 100000 | J24: ='7'!K23 -> 99166.667 | K24: ='8'!K23 -> 99166.667 | L24: ='9'!K23 -> 99166.667 | M24: ='10'!K23 -> 99166.667 | N24: ='11'!K23 -> 99166.667 | O24: ='12'!K23 -> 99166.667 | P24: ='13'!K23 -> 99166.667 | Q24: ='14'!K23 -> 99166.667 | R24: ='15'!K23 -> 99166.667 | S24: ='16'!K23 -> 99166.667 | T24: ='17'!K23 -> 99166.667 | U24: ='18'!K23 -> 99166.667 | V24: ='19'!K23 -> 99166.667 | W24: ='20'!K23 -> 99166.667 | X24: ='21'!K23 -> 99166.667 | Y24: ='22'!K23 -> 99166.667 | Z24: ='23'!K23 -> 99166.667 | AA24: ='24'!K23 -> 99166.667 | AB24: ='25'!K23 -> 99166.667 | AC24: ='26'!K23 -> 99166.667 | AD24: ='27'!K23 -> 99166.667 | AE24: ='28'!K23 -> 99166.667 | AF24: ='29'!K23 -> 99166.667 | AG24: ='30'!K24 -> 105000 | AH24: ='31'!K24 -> 99166.667 | AI24: 80000 | AJ24: =AH24-D24 -> -833.33333 | AK24: =AVERAGE(D24:AH24) -> 99516.129
B25: - Daging Ayam Broiler | C25: Kg | D25: ='1'!K24 -> 30857.143 | E25: ='2'!K24 -> 30857.143 | F25: ='3'!K24 -> 30571.429 | G25: ='4'!K24 -> 30571.429 | H25: ='5'!K24 -> 30857.143 | I25: ='6'!K24 -> 30285.714 | J25: ='7'!K24 -> 30000 | K25: ='8'!K24 -> 30285.714 | L25: ='9'!K24 -> 30857.143 | M25: ='10'!K24 -> 31000 | N25: ='11'!K24 -> 31285.714 | O25: ='12'!K24 -> 31571.429 | P25: ='13'!K24 -> 31571.429 | Q25: ='14'!K24 -> 31714.286 | R25: ='15'!K24 -> 32000 | S25: ='16'!K24 -> 32285.714 | T25: ='17'!K24 -> 33428.571 | U25: ='18'!K24 -> 33428.571 | V25: ='19'!K24 -> 33285.714 | W25: ='20'!K24 -> 33428.571 | X25: ='21'!K24 -> 33428.571 | Y25: ='22'!K24 -> 33571.429 | Z25: ='23'!K24 -> 33285.714 | AA25: ='24'!K24 -> 33000 | AB25: ='25'!K24 -> 32714.286 | AC25: ='26'!K24 -> 32714.286 | AD25: ='27'!K24 -> 32571.429 | AE25: ='28'!K24 -> 31571.429 | AF25: ='29'!K24 -> 31571.429 | AG25: ='30'!K25 -> 36571.429 | AH25: ='31'!K25 -> 30857.143 | AI25: 36750 | AJ25: =AH25-D25 -> 0 | AK25: =AVERAGE(D25:AH25) -> 32000
A26: 6 | B26: I K A N | D26: ='1'!K25 | E26: ='2'!K25 | F26: ='3'!K25 | G26: ='4'!K25 | H26: ='5'!K25 | I26: ='6'!K25 | J26: ='7'!K25 | K26: ='8'!K25 | L26: ='9'!K25 | M26: ='10'!K25 | N26: ='11'!K25 | O26: ='12'!K25 | P26: ='13'!K25 | Q26: ='14'!K25 | R26: ='15'!K25 | S26: ='16'!K25 | T26: ='17'!K25 | U26: ='18'!K25 | V26: ='19'!K25 | W26: ='20'!K25 | X26: ='21'!K25 | Y26: ='22'!K25 | Z26: ='23'!K25 | AA26: ='24'!K25 | AB26: ='25'!K25 | AC26: ='26'!K25 | AD26: ='27'!K25 | AE26: ='28'!K25 | AF26: ='29'!K25 | AG26: ='30'!K26 | AH26: ='31'!K26 | AJ26: =AH26-D26 -> 0 | AK26: =AVERAGE(D26:AH26) -> #DIV/0!
B27: - Ikan Tongkol Segar (Uk. Sedang) | C27: Kg | D27: ='1'!K26 -> 37500 | E27: ='2'!K26 -> 37500 | F27: ='3'!K26 -> 37500 | G27: ='4'!K26 -> 37500 | H27: ='5'!K26 -> 37500 | I27: ='6'!K26 -> 37500 | J27: ='7'!K26 -> 37166.667 | K27: ='8'!K26 -> 36666.667 | L27: ='9'!K26 -> 37500 | M27: ='10'!K26 -> 37500 | N27: ='11'!K26 -> 37500 | O27: ='12'!K26 -> 37500 | P27: ='13'!K26 -> 37500 | Q27: ='14'!K26 -> 37500 | R27: ='15'!K26 -> 37500 | S27: ='16'!K26 -> 38333.333 | T27: ='17'!K26 -> 37500 | U27: ='18'!K26 -> 37500 | V27: ='19'!K26 -> 37500 | W27: ='20'!K26 -> 37500 | X27: ='21'!K26 -> 36833.333 | Y27: ='22'!K26 -> 36833.333 | Z27: ='23'!K26 -> 36833.333 | AA27: ='24'!K26 -> 36833.333 | AB27: ='25'!K26 -> 37666.667 | AC27: ='26'!K26 -> 37666.667 | AD27: ='27'!K26 -> 37333.333 | AE27: ='28'!K26 -> 37333.333 | AF27: ='29'!K26 -> 37333.333 | AG27: ='30'!K27 -> 35714.286 | AH27: ='31'!K27 -> 37333.333 | AJ27: =AH27-D27 -> -166.66667 | AK27: =AVERAGE(D27:AH27) -> 37334.869
B28: - Ikan Mujair Segar (Uk. Sedang) | C28: Kg | D28: ='1'!K27 -> 28500 | E28: ='2'!K27 -> 28500 | F28: ='3'!K27 -> 28500 | G28: ='4'!K27 -> 28500 | H28: ='5'!K27 -> 28500 | I28: ='6'!K27 -> 28500 | J28: ='7'!K27 -> 28500 | K28: ='8'!K27 -> 28500 | L28: ='9'!K27 -> 29428.571 | M28: ='10'!K27 -> 29428.571 | N28: ='11'!K27 -> 29428.571 | O28: ='12'!K27 -> 29428.571 | P28: ='13'!K27 -> 29428.571 | Q28: ='14'!K27 -> 29142.857 | R28: ='15'!K27 -> 29142.857 | S28: ='16'!K27 -> 29142.857 | T28: ='17'!K27 -> 28857.143 | U28: ='18'!K27 -> 28857.143 | V28: ='19'!K27 -> 28857.143 | W28: ='20'!K27 -> 28857.143 | X28: ='21'!K27 -> 28857.143 | Y28: ='22'!K27 -> 28857.143 | Z28: ='23'!K27 -> 28857.143 | AA28: ='24'!K27 -> 29428.571 | AB28: ='25'!K27 -> 29714.286 | AC28: ='26'!K27 -> 29714.286 | AD28: ='27'!K27 -> 29428.571 | AE28: ='28'!K27 -> 29428.571 | AF28: ='29'!K27 -> 29428.571 | AG28: ='30'!K28 -> 31428.571 | AH28: ='31'!K28 -> 28857.143 | AJ28: =AH28-D28 -> 357.14286 | AK28: =AVERAGE(D28:AH28) -> 29096.774
B29: - Udang Segar (Uk. Sedang) | C29: Kg | D29: ='1'!K28 -> 67166.667 | E29: ='2'!K28 -> 67166.667 | F29: ='3'!K28 -> 67166.667 | G29: ='4'!K28 -> 67166.667 | H29: ='5'!K28 -> 66333.333 | I29: ='6'!K28 -> 66333.333 | J29: ='7'!K28 -> 67166.667 | K29: ='8'!K28 -> 66166.667 | L29: ='9'!K28 -> 65428.571 | M29: ='10'!K28 -> 65428.571 | N29: ='11'!K28 -> 65428.571 | O29: ='12'!K28 -> 65428.571 | P29: ='13'!K28 -> 65428.571 | Q29: ='14'!K28 -> 65428.571 | R29: ='15'!K28 -> 64000 | S29: ='16'!K28 -> 64000 | T29: ='17'!K28 -> 64000 | U29: ='18'!K28 -> 64000 | V29: ='19'!K28 -> 64000 | W29: ='20'!K28 -> 64000 | X29: ='21'!K28 -> 64000 | Y29: ='22'!K28 -> 64000 | Z29: ='23'!K28 -> 64000 | AA29: ='24'!K28 -> 63000 | AB29: ='25'!K28 -> 63000 | AC29: ='26'!K28 -> 63000 | AD29: ='27'!K28 -> 63285.714 | AE29: ='28'!K28 -> 63285.714 | AF29: ='29'!K28 -> 63285.714 | AG29: ='30'!K29 -> 67142.857 | AH29: ='31'!K29 -> 64000 | AJ29: =AH29-D29 -> -3166.6667 | AK29: =AVERAGE(D29:AH29) -> 64943.164
B30: - Ikan Lele Segar (Ukuran Sedang) | C30: Kg | D30: ='1'!K29 -> 24333.333 | E30: ='2'!K29 -> 24333.333 | F30: ='3'!K29 -> 24333.333 | G30: ='4'!K29 -> 24333.333 | H30: ='5'!K29 -> 24333.333 | I30: ='6'!K29 -> 24333.333 | J30: ='7'!K29 -> 24333.333 | K30: ='8'!K29 -> 24333.333 | L30: ='9'!K29 -> 24600 | M30: ='10'!K29 -> 24600 | N30: ='11'!K29 -> 24600 | O30: ='12'!K29 -> 24600 | P30: ='13'!K29 -> 24600 | Q30: ='14'!K29 -> 24600 | R30: ='15'!K29 -> 24600 | S30: ='16'!K29 -> 24600 | T30: ='17'!K29 -> 24600 | U30: ='18'!K29 -> 24600 | V30: ='19'!K29 -> 24600 | W30: ='20'!K29 -> 24600 | X30: ='21'!K29 -> 24600 | Y30: ='22'!K29 -> 24600 | Z30: ='23'!K29 -> 24600 | AA30: ='24'!K29 -> 24600 | AB30: ='25'!K29 -> 24600 | AC30: ='26'!K29 -> 24600 | AD30: ='27'!K29 -> 24600 | AE30: ='28'!K29 -> 24600 | AF30: ='29'!K29 -> 24600 | AG30: ='30'!K30 -> 24600 | AH30: ='31'!K30 -> 24600 | AJ30: =AH30-D30 -> 266.66667 | AK30: =AVERAGE(D30:AH30) -> 24531.183
B31: - Ikan Bandeng Segar (Uk. Sedang) | C31: Kg | D31: ='1'!K30 -> 37142.857 | E31: ='2'!K30 -> 37142.857 | F31: ='3'!K30 -> 37142.857 | G31: ='4'!K30 -> 37142.857 | H31: ='5'!K30 -> 37142.857 | I31: ='6'!K30 -> 37142.857 | J31: ='7'!K30 -> 37714.286 | K31: ='8'!K30 -> 37714.286 | L31: ='9'!K30 -> 38142.857 | M31: ='10'!K30 -> 38142.857 | N31: ='11'!K30 -> 38142.857 | O31: ='12'!K30 -> 38142.857 | P31: ='13'!K30 -> 38142.857 | Q31: ='14'!K30 -> 38142.857 | R31: ='15'!K30 -> 38714.286 | S31: ='16'!K30 -> 38714.286 | T31: ='17'!K30 -> 38857.143 | U31: ='18'!K30 -> 38857.143 | V31: ='19'!K30 -> 38857.143 | W31: ='20'!K30 -> 38857.143 | X31: ='21'!K30 -> 38857.143 | Y31: ='22'!K30 -> 38857.143 | Z31: ='23'!K30 -> 38857.143 | AA31: ='24'!K30 -> 37857.143 | AB31: ='25'!K30 -> 37857.143 | AC31: ='26'!K30 -> 37857.143 | AD31: ='27'!K30 -> 38714.286 | AE31: ='28'!K30 -> 38714.286 | AF31: ='29'!K30 -> 38714.286 | AG31: ='30'!K31 -> 38428.571 | AH31: ='31'!K31 -> 38857.143 | AJ31: =AH31-D31 -> 1714.2857 | AK31: =AVERAGE(D31:AH31) -> 38179.724
B32: - Ikan Teri Asin (Bukan Teri Medan) | C32: Kg | D32: ='1'!K31 -> 85000 | E32: ='2'!K31 -> 85000 | F32: ='3'!K31 -> 85000 | G32: ='4'!K31 -> 85000 | H32: ='5'!K31 -> 85000 | I32: ='6'!K31 -> 85000 | J32: ='7'!K31 -> 85000 | K32: ='8'!K31 -> 85000 | L32: ='9'!K31 -> 96666.667 | M32: ='10'!K31 -> 96666.667 | N32: ='11'!K31 -> 96666.667 | O32: ='12'!K31 -> 96666.667 | P32: ='13'!K31 -> 96666.667 | Q32: ='14'!K31 -> 96666.667 | R32: ='15'!K31 -> 96666.667 | S32: ='16'!K31 -> 96666.667 | T32: ='17'!K31 -> 96666.667 | U32: ='18'!K31 -> 96666.667 | V32: ='19'!K31 -> 96666.667 | W32: ='20'!K31 -> 96666.667 | X32: ='21'!K31 -> 96666.667 | Y32: ='22'!K31 -> 96666.667 | Z32: ='23'!K31 -> 96666.667 | AA32: ='24'!K31 -> 96666.667 | AB32: ='25'!K31 -> 96666.667 | AC32: ='26'!K31 -> 96666.667 | AD32: ='27'!K31 -> 96666.667 | AE32: ='28'!K31 -> 96666.667 | AF32: ='29'!K31 -> 96666.667 | AG32: ='30'!K32 -> 103333.33 | AH32: ='31'!K32 -> 96666.667 | AJ32: =AH32-D32 -> 11666.667 | AK32: =AVERAGE(D32:AH32) -> 93870.968
A33: 7 | B33: TELUR | D33: ='1'!K32 | E33: ='2'!K32 | F33: ='3'!K32 | G33: ='4'!K32 | H33: ='5'!K32 | I33: ='6'!K32 | J33: ='7'!K32 | K33: ='8'!K32 | L33: ='9'!K32 | M33: ='10'!K32 | N33: ='11'!K32 | O33: ='12'!K32 | P33: ='13'!K32 | Q33: ='14'!K32 | R33: ='15'!K32 | S33: ='16'!K32 | T33: ='17'!K32 | U33: ='18'!K32 | V33: ='19'!K32 | W33: ='20'!K32 | X33: ='21'!K32 | Y33: ='22'!K32 | Z33: ='23'!K32 | AA33: ='24'!K32 | AB33: ='25'!K32 | AC33: ='26'!K32 | AD33: ='27'!K32 | AE33: ='28'!K32 | AF33: ='29'!K32 | AG33: ='30'!K33 | AH33: ='31'!K33 | AJ33: =AH33-D33 -> 0 | AK33: =AVERAGE(D33:AH33) -> #DIV/0!
B34: - Telur Ayam Broiler | C34: Kg | D34: ='1'!K33 -> 25571.429 | E34: ='2'!K33 -> 25571.429 | F34: ='3'!K33 -> 25571.429 | G34: ='4'!K33 -> 25428.571 | H34: ='5'!K33 -> 25428.571 | I34: ='6'!K33 -> 25857.143 | J34: ='7'!K33 -> 26000 | K34: ='8'!K33 -> 26428.571 | L34: ='9'!K33 -> 27071.429 | M34: ='10'!K33 -> 27071.429 | N34: ='11'!K33 -> 27071.429 | O34: ='12'!K33 -> 27000 | P34: ='13'!K33 -> 27357.143 | Q34: ='14'!K33 -> 27571.429 | R34: ='15'!K33 -> 28142.857 | S34: ='16'!K33 -> 29000 | T34: ='17'!K33 -> 29142.857 | U34: ='18'!K33 -> 29285.714 | V34: ='19'!K33 -> 29428.571 | W34: ='20'!K33 -> 29428.571 | X34: ='21'!K33 -> 29428.571 | Y34: ='22'!K33 -> 29571.429 | Z34: ='23'!K33 -> 29571.429 | AA34: ='24'!K33 -> 29714.286 | AB34: ='25'!K33 -> 29571.429 | AC34: ='26'!K33 -> 29571.429 | AD34: ='27'!K33 -> 29357.143 | AE34: ='28'!K33 -> 29357.143 | AF34: ='29'!K33 -> 29357.143 | AG34: ='30'!K34 -> 27142.857 | AH34: ='31'!K34 -> 28785.714 | AI34: 27000 | AJ34: =AH34-D34 -> 3214.2857 | AK34: =AVERAGE(D34:AH34) -> 27898.618
B35: - Telur Ayam Kampung | C35: Butir | D35: ='1'!K34 -> 2357.1429 | E35: ='2'!K34 -> 2357.1429 | F35: ='3'!K34 -> 2357.1429 | G35: ='4'!K34 -> 2357.1429 | H35: ='5'!K34 -> 2357.1429 | I35: ='6'!K34 -> 2357.1429 | J35: ='7'!K34 -> 2357.1429 | K35: ='8'!K34 -> 2314.2857 | L35: ='9'!K34 -> 2385.7143 | M35: ='10'!K34 -> 2385.7143 | N35: ='11'!K34 -> 2385.7143 | O35: ='12'!K34 -> 2385.7143 | P35: ='13'!K34 -> 2385.7143 | Q35: ='14'!K34 -> 2385.7143 | R35: ='15'!K34 -> 2385.7143 | S35: ='16'!K34 -> 2385.7143 | T35: ='17'!K34 -> 2385.7143 | U35: ='18'!K34 -> 2385.7143 | V35: ='19'!K34 -> 2428.5714 | W35: ='20'!K34 -> 2428.5714 | X35: ='21'!K34 -> 2428.5714 | Y35: ='22'!K34 -> 2428.5714 | Z35: ='23'!K34 -> 2428.5714 | AA35: ='24'!K34 -> 2428.5714 | AB35: ='25'!K34 -> 2500 | AC35: ='26'!K34 -> 2500 | AD35: ='27'!K34 -> 2500 | AE35: ='28'!K34 -> 2500 | AF35: ='29'!K34 -> 2500 | AG35: ='30'!K35 -> 2385.7143 | AH35: ='31'!K35 -> 2500 | AJ35: =AH35-D35 -> 142.85714 | AK35: =AVERAGE(D35:AH35) -> 2407.3733
A36: 8 | B36: TAHU | I36: ='6'!K35 | J36: ='7'!K35 | K36: ='8'!K35 | L36: ='9'!K35 | M36: ='10'!K35 | N36: ='11'!K35 | O36: ='12'!K35 | P36: ='13'!K35 | Q36: ='14'!K35 | R36: ='15'!K35 | S36: ='16'!K35 | T36: ='17'!K35 | U36: ='18'!K35 | V36: ='19'!K35 | W36: ='20'!K35 | X36: ='21'!K35 | Y36: ='22'!K35 | Z36: ='23'!K35 | AA36: ='24'!K35 | AB36: ='25'!K35 | AC36: ='26'!K35 | AD36: ='27'!K35 | AE36: ='28'!K35 | AF36: ='29'!K35 | AG36: ='30'!K36 | AH36: ='31'!K36 | AK36: =AVERAGE(D36:AH36) -> #DIV/0!
B37: - Tahu biasa | C37: Kg | AF37: ='29'!K36 -> 11142.857 | AG37: ='30'!K37 -> 11142.857 | AH37: ='31'!K37 -> 11142.857 | AK37: =AVERAGE(D37:AH37) -> 11142.857
B38: - Tahu susu | C38: Kg | AF38: ='29'!K37 -> 12200 | AG38: ='30'!K38 -> 12400 | AH38: ='31'!K38 -> 12200 | AK38: =AVERAGE(D38:AH38) -> 12266.667
A39: 9 | B39: TEMPE | AF39: ='29'!K38 | AG39: ='30'!K39 | AH39: ='31'!K39 | AK39: =AVERAGE(D39:AH39) -> #DIV/0!
B40: - Tempe Kw I (campuran kedelai) | C40: Kg | AF40: ='29'!K39 -> 15600 | AG40: ='30'!K40 -> 15600 | AH40: ='31'!K40 -> 15600 | AK40: =AVERAGE(D40:AH40) -> 15600
B41: - Tempe Kw II (campuran jagung) | C41: Kg | AF41: ='29'!K40 -> 6833.3333 | AG41: ='30'!K41 -> 6833.3333 | AH41: ='31'!K41 -> 6833.3333 | AK41: =AVERAGE(D41:AH41) -> 6833.3333
...

Sheet 1
A1: HARGA BAHAN-BAHAN POKOK
A2: DI PASAR TRADISIONAL KOTA SURABAYA
A3: HARI / TANGGAL : Rabu / 01 Maret 2023
B4: NAMA BAHAN POKOK DAN PENTING LAINNYA | C4: SATUAN | D4: Pasar Tambahrejo | E4: Pasar Pucang Anom | F4: Pasar Wonokromo | G4: Pasar Genteng Baru | H4: Pasar Pabean | I4: Pasar Kembang | J4: Pasar Balongsari | K4: Rata-Rata
A7: 1 | B7: BERAS
B8: - Beras Premium | C8: Kg | D8: 13000 | E8: 12500 | F8: 14500 | G8: 12800 | H8: 14000 | I8: 13500 | J8: 13000 | K8: =AVERAGE(D8:J8) -> 13328.571
B9: - Beras Medium | C9: Kg | D9: 9000 | E9: 9000 | F9: 8800 | G9: 9000 | H9: 9000 | I9: 9000 | J9: 9000 | K9: =AVERAGE(D9:J9) -> 8971.4286
B10: - Beras Jagung | C10: Kg | D10: - | E10: - | F10: - | G10: - | H10: - | I10: 11000 | J10: 8000 | K10: =AVERAGE(D10:J10) -> 9500
B11: - Beras Ketan (Jenis Siyem) | C11: Kg | D11: - | E11: 23000 | F11: - | G11: - | H11: - | I11: 20000 | J11: 17000 | K11: =AVERAGE(D11:J11) -> 20000
A12: 2 | B12: GULA
B13: Gula Pasir Lokal Curah | C13: Kg | D13: 13000 | E13: 13000 | F13: 13000 | G13: 13000 | H13: 13000 | I13: 13000 | J13: 13000 | K13: =AVERAGE(D13:J13) -> 13000
B14: - Gula Jawa/Merah (Bahan Kelapa) | C14: Kg | D14: 15000 | E14: 16000 | F14: 16000 | G14: 19000 | H14: 15000 | I14: 16000 | J14: 16000 | K14: =AVERAGE(D14:J14) -> 16142.857
A15: 3 | B15: MINYAK GORENG
B16: - Minyak Goreng Curah (Bening) | C16: Kg | D16: 15000 | E16: 16000 | F16: 15000 | G16: 16000 | H16: 14000 | I16: 16000 | J16: 16000 | K16: =AVERAGE(D16:J16) -> 15428.571
B17: - Minyak Kita | C17: Liter | D17: 14000 | E17: 14000 | F17: 14000 | G17: 14000 | H17: - | I17: 14000 | J17: 14000 | K17: =AVERAGE(D17:J17) -> 14000
A18: 4 | B18: MENTEGA
B19: - Mentega Curah (Amanda) | C19: Kg | D19: - | E19: - | F19: - | G19: 14000 | H19: - | I19: 24000 | J19: - | K19: =AVERAGE(D19:J19) -> 19000
A20: 5 | B20: DAGING
B21: - Daging Sapi Grade Atas | C21: Kg | D21: 120000 | E21: 120000 | F21: 120000 | G21: 120000 | H21: 117000 | I21: 120000 | J21: 110000 | K21: =AVERAGE(D21:J21) -> 118142.86
B22: - Daging Sapi Grade Sedang | C22: Kg | D22: 110000 | E22: 110000 | F22: 115000 | G22: 110000 | H22: 114000 | I22: 110000 | J22: 100000 | K22: =AVERAGE(D22:J22) -> 109857.14
B23: - Daging Sapi Grade Bawah | C23: Kg | D23: 100000 | E23: 95000 | F23: 105000 | G23: 100000 | H23: 100000 | I23: 100000 | J23: - | K23: =AVERAGE(D23:J23) -> 100000
B24: - Daging Ayam Broiler | C24: Kg | D24: 30000 | E24: 30000 | F24: 32000 | G24: 30000 | H24: 32000 | I24: 30000 | J24: 32000 | K24: =AVERAGE(D24:J24) -> 30857.143
A25: 6 | B25: I K A N
B26: - Ikan Tongkol Segar (Uk. Sedang) | C26: Kg | D26: 35000 | E26: 40000 | F26: - | G26: 40000 | H26: 30000 | I26: 40000 | J26: 40000 | K26: =AVERAGE(D26:J26) -> 37500
B27: - Ikan Mujair Segar (Uk. Sedang) | C27: Kg | D27: - | E27: 30000 | F27: 30000 | G27: 30000 | H27: 23000 | I27: 30000 | J27: 28000 | K27: =AVERAGE(D27:J27) -> 28500
B28: - Udang Segar (Uk. Sedang) | C28: Kg | D28: - | E28: 70000 | F28: 60000 | G28: 75000 | H28: 58000 | I28: 80000 | J28: 60000 | K28: =AVERAGE(D28:J28) -> 67166.667
B29: - Ikan Lele Segar (Ukuran Sedang) | C29: Kg | D29: - | E29: - | F29: - | G29: - | H29: 23000 | I29: 24000 | J29: 26000 | K29: =AVERAGE(D29:J29) -> 24333.333
B30: - Ikan Bandeng Segar (Uk. Sedang) | C30: Kg | D30: 40000 | E30: 36000 | F30: 40000 | G30: 40000 | H30: 28000 | I30: 40000 | J30: 36000 | K30: =AVERAGE(D30:J30) -> 37142.857
B31: - Ikan Teri Asin (Bukan Teri Medan) | C31: Kg | D31: 80000 | E31: 100000 | F31: 80000 | G31: - | H31: 80000 | I31: - | J31: - | K31: =AVERAGE(D31:J31) -> 85000
A32: 7 | B32: TELUR
B33: - Telur Ayam Broiler | C33: Kg | D33: 26000 | E33: 26000 | F33: 26000 | G33: 26000 | H33: 24000 | I33: 26000 | J33: 25000 | K33: =AVERAGE(D33:J33) -> 25571.429
B34: - Telur Ayam Kampung | C34: Butir | D34: 2500 | E34: 2000 | F34: 2000 | G34: 2500 | H34: 2000 | I34: 2500 | J34: 3000 | K34: =AVERAGE(D34:J34) -> 2357.1429
A35: 8 | B35: TAHU DAN TEMPE
B36: - Tahu | C36: Biji | D36: 1000 | E36: 1000 | F36: 3500 | G36: 3000 | H36: 4000 | I36: 1200 | J36: 3000 | K36: =AVERAGE(D36:J36) -> 2385.7143
B37: - Tempe | C37: Biji | D37: 2500 | E37: 2500 | F37: 6000 | G37: 3000 | H37: 2500 | I37: 5000 | J37: 3500 | K37: =AVERAGE(D37:J37) -> 3571.4286
A38: 9 | B38: S U S U
B39: - Susu Kental Manis "INDOMILK" Putih | C39: 390 Gr/kaleng | D39: 12500 | E39: 12000 | F39: 10000 | G39: 12000 | H39: - | I39: 12000 | J39: 10000 | K39: =AVERAGE(D39:J39) -> 11416.667
B40: - Susu Bubuk "DANCOW" Full Cream | C40: 400 Gr/Dos | D40: - | E40: 37900 | F40: - | G40: 42500 | H40: - | I40: - | J40: - | K40: =AVERAGE(D40:J40) -> 40200
A41: 10 | B41: SABUN CUCI
B42: - Sabun Detergen Rinso (Anti Noda) | C42: 900 Gram | D42: - | E42: - | F42: - | G42: - | H42: 17500 | I42: 21000 | J42: 17500 | K42: =AVERAGE(D42:J42) -> 18666.667
...

Sheet 2
A1: HARGA BAHAN-BAHAN POKOK
A2: DI PASAR TRADISIONAL KOTA SURABAYA
A3: HARI / TANGGAL : Kamis / 02 Maret 2023
B4: NAMA BAHAN POKOK DAN PENTING LAINNYA | C4: SATUAN | D4: Pasar Tambahrejo | E4: Pasar Pucang Anom | F4: Pasar Wonokromo | G4: Pasar Genteng Baru | H4: Pasar Pabean | I4: Pasar Kembang | J4: Pasar Balongsari | K4: Rata-Rata
A7: 1 | B7: BERAS
B8: - Beras Premium | C8: Kg | D8: 13000 | E8: 12500 | F8: 14500 | G8: 12800 | H8: 14000 | I8: 13500 | J8: 13000 | K8: =AVERAGE(D8:J8) -> 13328.571
B9: - Beras Medium | C9: Kg | D9: 9000 | E9: 9000 | F9: 8800 | G9: 9000 | H9: 9000 | I9: 9000 | J9: 9000 | K9: =AVERAGE(D9:J9) -> 8971.4286
B10: - Beras Jagung | C10: Kg | D10: - | E10: - | F10: - | G10: - | H10: - | I10: 11000 | J10: 8000 | K10: =AVERAGE(D10:J10) -> 9500
B11: - Beras Ketan (Jenis Siyem) | C11: Kg | D11: - | E11: 23000 | F11: - | G11: - | H11: - | I11: 20000 | J11: 17000 | K11: =AVERAGE(D11:J11) -> 20000
A12: 2 | B12: GULA
B13: Gula Pasir Lokal Curah | C13: Kg | D13: 13000 | E13: 13000 | F13: 13000 | G13: 13000 | H13: 13000 | I13: 13000 | J13: 13000 | K13: =AVERAGE(D13:J13) -> 13000
B14: - Gula Jawa/Merah (Bahan Kelapa) | C14: Kg | D14: 15000 | E14: 16000 | F14: 16000 | G14: 19000 | H14: 15000 | I14: 16000 | J14: 16000 | K14: =AVERAGE(D14:J14) -> 16142.857
A15: 3 | B15: MINYAK GORENG
B16: - Minyak Goreng Curah (Bening) | C16: Kg | D16: 15000 | E16: 16000 | F16: 15000 | G16: 16000 | H16: 14000 | I16: 16000 | J16: 16000 | K16: =AVERAGE(D16:J16) -> 15428.571
B17: - Minyak Kita | C17: Liter | D17: 14000 | E17: 14000 | F17: 14000 | G17: 14000 | H17: - | I17: 14000 | J17: 14000 | K17: =AVERAGE(D17:J17) -> 14000
A18: 4 | B18: MENTEGA
B19: - Mentega Curah (Amanda) | C19: Kg | D19: - | E19: - | F19: - | G19: 14000 | H19: - | I19: 24000 | J19: - | K19: =AVERAGE(D19:J19) -> 19000
A20: 5 | B20: DAGING
B21: - Daging Sapi Grade Atas | C21: Kg | D21: 120000 | E21: 120000 | F21: 120000 | G21: 120000 | H21: 117000 | I21: 120000 | J21: 110000 | K21: =AVERAGE(D21:J21) -> 118142.86
B22: - Daging Sapi Grade Sedang | C22: Kg | D22: 110000 | E22: 110000 | F22: 115000 | G22: 110000 | H22: 114000 | I22: 110000 | J22: 100000 | K22: =AVERAGE(D22:J22) -> 109857.14
B23: - Daging Sapi Grade Bawah | C23: Kg | D23: 100000 | E23: 95000 | F23: 105000 | G23: 100000 | H23: 100000 | I23: 100000 | J23: - | K23: =AVERAGE(D23:J23) -> 100000
B24: - Daging Ayam Broiler | C24: Kg | D24: 30000 | E24: 30000 | F24: 32000 | G24: 30000 | H24: 32000 | I24: 30000 | J24: 32000 | K24: =AVERAGE(D24:J24) -> 30857.143
A25: 6 | B25: I K A N
B26: - Ikan Tongkol Segar (Uk. Sedang) | C26: Kg | D26: 35000 | E26: 40000 | F26: - | G26: 40000 | H26: 30000 | I26: 40000 | J26: 40000 | K26: =AVERAGE(D26:J26) -> 37500
B27: - Ikan Mujair Segar (Uk. Sedang) | C27: Kg | D27: - | E27: 30000 | F27: 30000 | G27: 30000 | H27: 23000 | I27: 30000 | J27: 28000 | K27: =AVERAGE(D27:J27) -> 28500
B28: - Udang Segar (Uk. Sedang) | C28: Kg | D28: - | E28: 70000 | F28: 60000 | G28: 75000 | H28: 58000 | I28: 80000 | J28: 60000 | K28: =AVERAGE(D28:J28) -> 67166.667
B29: - Ikan Lele Segar (Ukuran Sedang) | C29: Kg | D29: - | E29: - | F29: - | G29: - | H29: 23000 | I29: 24000 | J29: 26000 | K29: =AVERAGE(D29:J29) -> 24333.333
B30: - Ikan Bandeng Segar (Uk. Sedang) | C30: Kg | D30: 40000 | E30: 36000 | F30: 40000 | G30: 40000 | H30: 28000 | I30: 40000 | J30: 36000 | K30: =AVERAGE(D30:J30) -> 37142.857
B31: - Ikan Teri Asin (Bukan Teri Medan) | C31: Kg | D31: 80000 | E31: 100000 | F31: 80000 | G31: - | H31: 80000 | I31: - | J31: - | K31: =AVERAGE(D31:J31) -> 85000
A32: 7 | B32: TELUR
B33: - Telur Ayam Broiler | C33: Kg | D33: 26000 | E33: 26000 | F33: 26000 | G33: 26000 | H33: 24000 | I33: 26000 | J33: 25000 | K33: =AVERAGE(D33:J33) -> 25571.429
B34: - Telur Ayam Kampung | C34: Butir | D34: 2500 | E34: 2000 | F34: 2000 | G34: 2500 | H34: 2000 | I34: 2500 | J34: 3000 | K34: =AVERAGE(D34:J34) -> 2357.1429
A35: 8 | B35: TAHU DAN TEMPE
B36: - Tahu | C36: Biji | D36: 1000 | E36: 1000 | F36: 3500 | G36: 3000 | H36: 4000 | I36: 1200 | J36: 3000 | K36: =AVERAGE(D36:J36) -> 2385.7143
B37: - Tempe | C37: Biji | D37: 2500 | E37: 2500 | F37: 6000 | G37: 3000 | H37: 2500 | I37: 5000 | J37: 3500 | K37: =AVERAGE(D37:J37) -> 3571.4286
A38: 9 | B38: S U S U
B39: - Susu Kental Manis "INDOMILK" Putih | C39: 390 Gr/kaleng | D39: 12500 | E39: 12000 | F39: 10000 | G39: 12000 | H39: - | I39: 12000 | J39: 10000 | K39: =AVERAGE(D39:J39) -> 11416.667
B40: - Susu Bubuk "DANCOW" Full Cream | C40: 400 Gr/Dos | D40: - | E40: 37900 | F40: - | G40: 42500 | H40: - | I40: - | J40: - | K40: =AVERAGE(D40:J40) -> 40200
A41: 10 | B41: SABUN CUCI
B42: - Sabun Detergen Rinso (Anti Noda) | C42: 900 Gram | D42: - | E42: - | F42: - | G42: - | H42: 17500 | I42: 21000 | J42: 17500 | K42: =AVERAGE(D42:J42) -> 18666.667
...

Sheet 3
A1: HARGA BAHAN-BAHAN POKOK
A2: DI PASAR TRADISIONAL KOTA SURABAYA
A3: HARI / TANGGAL : Jumat / 03 Maret 2023
B4: NAMA BAHAN POKOK DAN PENTING LAINNYA | C4: SATUAN | D4: Pasar Tambahrejo | E4: Pasar Pucang Anom | F4: Pasar Wonokromo | G4: Pasar Genteng Baru | H4: Pasar Pabean | I4: Pasar Kembang | J4: Pasar Balongsari | K4: Rata-Rata
A7: 1 | B7: BERAS
B8: - Beras Premium | C8: Kg | D8: 13000 | E8: 12500 | F8: 14500 | G8: 12800 | H8: 14000 | I8: 13500 | J8: 13000 | K8: =AVERAGE(D8:J8) -> 13328.571
B9: - Beras Medium | C9: Kg | D9: 9000 | E9: 9000 | F9: 8800 | G9: 9000 | H9: 9000 | I9: 9000 | J9: 9000 | K9: =AVERAGE(D9:J9) -> 8971.4286
B10: - Beras Jagung | C10: Kg | D10: - | E10: - | F10: - | G10: - | H10: - | I10: 11000 | J10: 8000 | K10: =AVERAGE(D10:J10) -> 9500
B11: - Beras Ketan (Jenis Siyem) | C11: Kg | D11: - | E11: 23000 | F11: - | G11: - | H11: - | I11: 20000 | J11: 17000 | K11: =AVERAGE(D11:J11) -> 20000
A12: 2 | B12: GULA
B13: Gula Pasir Lokal Curah | C13: Kg | D13: 13000 | E13: 13000 | F13: 13000 | G13: 13000 | H13: 13000 | I13: 13000 | J13: 13000 | K13: =AVERAGE(D13:J13) -> 13000
B14: - Gula Jawa/Merah (Bahan Kelapa) | C14: Kg | D14: 15000 | E14: 16000 | F14: 16000 | G14: 19000 | H14: 15000 | I14: 17000 | J14: 16000 | K14: =AVERAGE(D14:J14) -> 16285.714
A15: 3 | B15: MINYAK GORENG
B16: - Minyak Goreng Curah (Bening) | C16: Kg | D16: 15000 | E16: 16000 | F16: 15000 | G16: 16000 | H16: 14000 | I16: 16000 | J16: 16000 | K16: =AVERAGE(D16:J16) -> 15428.571
B17: - Minyak Kita | C17: Liter | D17: 14000 | E17: 14000 | F17: 14000 | G17: 14000 | H17: - | I17: 14000 | J17: 14000 | K17: =AVERAGE(D17:J17) -> 14000
A18: 4 | B18: MENTEGA
B19: - Mentega Curah (Amanda) | C19: Kg | D19: - | E19: - | F19: - | G19: 14000 | H19: - | I19: 24000 | J19: - | K19: =AVERAGE(D19:J19) -> 19000
A20: 5 | B20: DAGING
B21: - Daging Sapi Grade Atas | C21: Kg | D21: 120000 | E21: 120000 | F21: 120000 | G21: 120000 | H21: 117000 | I21: 120000 | J21: 110000 | K21: =AVERAGE(D21:J21) -> 118142.86
B22: - Daging Sapi Grade Sedang | C22: Kg | D22: 110000 | E22: 110000 | F22: 115000 | G22: 110000 | H22: 114000 | I22: 110000 | J22: 100000 | K22: =AVERAGE(D22:J22) -> 109857.14
B23: - Daging Sapi Grade Bawah | C23: Kg | D23: 100000 | E23: 95000 | F23: 105000 | G23: 100000 | H23: 100000 | I23: 100000 | J23: - | K23: =AVERAGE(D23:J23) -> 100000
B24: - Daging Ayam Broiler | C24: Kg | D24: 30000 | E24: 28000 | F24: 32000 | G24: 30000 | H24: 32000 | I24: 30000 | J24: 32000 | K24: =AVERAGE(D24:J24) -> 30571.429
A25: 6 | B25: I K A N
B26: - Ikan Tongkol Segar (Uk. Sedang) | C26: Kg | D26: 35000 | E26: 40000 | F26: - | G26: 40000 | H26: 30000 | I26: 40000 | J26: 40000 | K26: =AVERAGE(D26:J26) -> 37500
B27: - Ikan Mujair Segar (Uk. Sedang) | C27: Kg | D27: - | E27: 30000 | F27: 30000 | G27: 30000 | H27: 23000 | I27: 30000 | J27: 28000 | K27: =AVERAGE(D27:J27) -> 28500
B28: - Udang Segar (Uk. Sedang) | C28: Kg | D28: - | E28: 70000 | F28: 60000 | G28: 75000 | H28: 58000 | I28: 80000 | J28: 60000 | K28: =AVERAGE(D28:J28) -> 67166.667
B29: - Ikan Lele Segar (Ukuran Sedang) | C29: Kg | D29: - | E29: - | F29: - | G29: - | H29: 23000 | I29: 24000 | J29: 26000 | K29: =AVERAGE(D29:J29) -> 24333.333
B30: - Ikan Bandeng Segar (Uk. Sedang) | C30: Kg | D30: 40000 | E30: 36000 | F30: 40000 | G30: 40000 | H30: 28000 | I30: 40000 | J30: 36000 | K30: =AVERAGE(D30:J30) -> 37142.857
B31: - Ikan Teri Asin (Bukan Teri Medan) | C31: Kg | D31: 80000 | E31: 100000 | F31: 80000 | G31: - | H31: 80000 | I31: - | J31: - | K31: =AVERAGE(D31:J31) -> 85000
A32: 7 | B32: TELUR
B33: - Telur Ayam Broiler | C33: Kg | D33: 26000 | E33: 26000 | F33: 26000 | G33: 26000 | H33: 24000 | I33: 26000 | J33: 25000 | K33: =AVERAGE(D33:J33) -> 25571.429
B34: - Telur Ayam Kampung | C34: Butir | D34: 2500 | E34: 2000 | F34: 2000 | G34: 2500 | H34: 2000 | I34: 2500 | J34: 3000 | K34: =AVERAGE(D34:J34) -> 2357.1429
A35: 8 | B35: TAHU DAN TEMPE
B36: - Tahu | C36: Biji | D36: 1000 | E36: 1000 | F36: 3500 | G36: 3000 | H36: 4000 | I36: 1200 | J36: 3000 | K36: =AVERAGE(D36:J36) -> 2385.7143
B37: - Tempe | C37: Biji | D37: 2500 | E37: 2500 | F37: 6000 | G37: 3000 | H37: 2500 | I37: 5000 | J37: 3500 | K37: =AVERAGE(D37:J37) -> 3571.4286
A38: 9 | B38: S U S U
B39: - Susu Kental Manis "INDOMILK" Putih | C39: 390 Gr/kaleng | D39: 12500 | E39: 12000 | F39: 10000 | G39: 12000 | H39: - | I39: 12000 | J39: 10000 | K39: =AVERAGE(D39:J39) -> 11416.667
B40: - Susu Bubuk "DANCOW" Full Cream | C40: 400 Gr/Dos | D40: - | E40: 37900 | F40: - | G40: 42500 | H40: - | I40: - | J40: - | K40: =AVERAGE(D40:J40) -> 40200
A41: 10 | B41: SABUN CUCI
B42: - Sabun Detergen Rinso (Anti Noda) | C42: 900 Gram | D42: - | E42: - | F42: - | G42: - | H42: 17500 | I42: 21000 | J42: 17500 | K42: =AVERAGE(D42:J42) -> 18666.667
...

Sheet 4
A1: HARGA BAHAN-BAHAN POKOK
A2: DI PASAR TRADISIONAL KOTA SURABAYA
A3: HARI / TANGGAL : Sabtu / 04 Maret 2023
B4: NAMA BAHAN POKOK DAN PENTING LAINNYA | C4: SATUAN | D4: Pasar Tambahrejo | E4: Pasar Pucang Anom | F4: Pasar Wonokromo | G4: Pasar Genteng Baru | H4: Pasar Pabean | I4: Pasar Kembang | J4: Pasar Balongsari | K4: Rata-Rata
A7: 1 | B7: BERAS
B8: - Beras Premium | C8: Kg | D8: 13000 | E8: 12500 | F8: 14500 | G8: 12800 | H8: 14000 | I8: 13500 | J8: 13000 | K8: =AVERAGE(D8:J8) -> 13328.571
B9: - Beras Medium | C9: Kg | D9: 9000 | E9: 9000 | F9: 8800 | G9: 9000 | H9: 9000 | I9: 9000 | J9: 9000 | K9: =AVERAGE(D9:J9) -> 8971.4286
B10: - Beras Jagung | C10: Kg | D10: - | E10: - | F10: - | G10: - | H10: - | I10: 11000 | J10: 8000 | K10: =AVERAGE(D10:J10) -> 9500
B11: - Beras Ketan (Jenis Siyem) | C11: Kg | D11: - | E11: 23000 | F11: - | G11: - | H11: - | I11: 20000 | J11: 17000 | K11: =AVERAGE(D11:J11) -> 20000
A12: 2 | B12: GULA
B13: Gula Pasir Lokal Curah | C13: Kg | D13: 13000 | E13: 13000 | F13: 13000 | G13: 13000 | H13: 13000 | I13: 13000 | J13: 13000 | K13: =AVERAGE(D13:J13) -> 13000
B14: - Gula Jawa/Merah (Bahan Kelapa) | C14: Kg | D14: 15000 | E14: 16000 | F14: 16000 | G14: 19000 | H14: 15000 | I14: 17000 | J14: 16000 | K14: =AVERAGE(D14:J14) -> 16285.714
A15: 3 | B15: MINYAK GORENG
B16: - Minyak Goreng Curah (Bening) | C16: Kg | D16: 15000 | E16: 16000 | F16: 15000 | G16: 16000 | H16: 14000 | I16: 16000 | J16: 16000 | K16: =AVERAGE(D16:J16) -> 15428.571
B17: - Minyak Kita | C17: Liter | D17: 14000 | E17: 14000 | F17: 14000 | G17: 14000 | H17: - | I17: 14000 | J17: 14000 | K17: =AVERAGE(D17:J17) -> 14000
A18: 4 | B18: MENTEGA
B19: - Mentega Curah (Amanda) | C19: Kg | D19: - | E19: - | F19: - | G19: 14000 | H19: - | I19: 24000 | J19: - | K19: =AVERAGE(D19:J19) -> 19000
A20: 5 | B20: DAGING
B21: - Daging Sapi Grade Atas | C21: Kg | D21: 120000 | E21: 120000 | F21: 120000 | G21: 120000 | H21: 117000 | I21: 120000 | J21: 110000 | K21: =AVERAGE(D21:J21) -> 118142.86
B22: - Daging Sapi Grade Sedang | C22: Kg | D22: 110000 | E22: 110000 | F22: 115000 | G22: 110000 | H22: 114000 | I22: 110000 | J22: 100000 | K22: =AVERAGE(D22:J22) -> 109857.14
B23: - Daging Sapi Grade Bawah | C23: Kg | D23: 100000 | E23: 95000 | F23: 105000 | G23: 100000 | H23: 100000 | I23: 100000 | J23: - | K23: =AVERAGE(D23:J23) -> 100000
B24: - Daging Ayam Broiler | C24: Kg | D24: 30000 | E24: 28000 | F24: 32000 | G24: 30000 | H24: 32000 | I24: 30000 | J24: 32000 | K24: =AVERAGE(D24:J24) -> 30571.429
A25: 6 | B25: I K A N
B26: - Ikan Tongkol Segar (Uk. Sedang) | C26: Kg | D26: 35000 | E26: 40000 | F26: - | G26: 40000 | H26: 30000 | I26: 40000 | J26: 40000 | K26: =AVERAGE(D26:J26) -> 37500
B27: - Ikan Mujair Segar (Uk. Sedang) | C27: Kg | D27: - | E27: 30000 | F27: 30000 | G27: 30000 | H27: 23000 | I27: 30000 | J27: 28000 | K27: =AVERAGE(D27:J27) -> 28500
B28: - Udang Segar (Uk. Sedang) | C28: Kg | D28: - | E28: 70000 | F28: 60000 | G28: 75000 | H28: 58000 | I28: 80000 | J28: 60000 | K28: =AVERAGE(D28:J28) -> 67166.667
B29: - Ikan Lele Segar (Ukuran Sedang) | C29: Kg | D29: - | E29: - | F29: - | G29: - | H29: 23000 | I29: 24000 | J29: 26000 | K29: =AVERAGE(D29:J29) -> 24333.333
B30: - Ikan Bandeng Segar (Uk. Sedang) | C30: Kg | D30: 40000 | E30: 36000 | F30: 40000 | G30: 40000 | H30: 28000 | I30: 40000 | J30: 36000 | K30: =AVERAGE(D30:J30) -> 37142.857
B31: - Ikan Teri Asin (Bukan Teri Medan) | C31: Kg | D31: 80000 | E31: 100000 | F31: 80000 | G31: - | H31: 80000 | I31: - | J31: - | K31: =AVERAGE(D31:J31) -> 85000
A32: 7 | B32: TELUR
B33: - Telur Ayam Broiler | C33: Kg | D33: 26000 | E33: 25000 | F33: 26000 | G33: 26000 | H33: 24000 | I33: 26000 | J33: 25000 | K33: =AVERAGE(D33:J33) -> 25428.571
B34: - Telur Ayam Kampung | C34: Butir | D34: 2500 | E34: 2000 | F34: 2000 | G34: 2500 | H34: 2000 | I34: 2500 | J34: 3000 | K34: =AVERAGE(D34:J34) -> 2357.1429
A35: 8 | B35: TAHU DAN TEMPE
B36: - Tahu | C36: Biji | D36: 1000 | E36: 1000 | F36: 3500 | G36: 3000 | H36: 4000 | I36: 1200 | J36: 3000 | K36: =AVERAGE(D36:J36) -> 2385.7143
B37: - Tempe | C37: Biji | D37: 2500 | E37: 2500 | F37: 6000 | G37: 3000 | H37: 2500 | I37: 5000 | J37: 3500 | K37: =AVERAGE(D37:J37) -> 3571.4286
A38: 9 | B38: S U S U
B39: - Susu Kental Manis "INDOMILK" Putih | C39: 390 Gr/kaleng | D39: 12500 | E39: 12000 | F39: 10000 | G39: 12000 | H39: - | I39: 12000 | J39: 10000 | K39: =AVERAGE(D39:J39) -> 11416.667
B40: - Susu Bubuk "DANCOW" Full Cream | C40: 400 Gr/Dos | D40: - | E40: 37900 | F40: - | G40: 42500 | H40: - | I40: - | J40: - | K40: =AVERAGE(D40:J40) -> 40200
A41: 10 | B41: SABUN CUCI
B42: - Sabun Detergen Rinso (Anti Noda) | C42: 900 Gram | D42: - | E42: - | F42: - | G42: - | H42: 17500 | I42: 21000 | J42: 17500 | K42: =AVERAGE(D42:J42) -> 18666.667
...

Sheet 5
A1: HARGA BAHAN-BAHAN POKOK
A2: DI PASAR TRADISIONAL KOTA SURABAYA
A3: HARI / TANGGAL : Minggu / 05 Maret 2023
B4: NAMA BAHAN POKOK DAN PENTING LAINNYA | C4: SATUAN | D4: Pasar Tambahrejo | E4: Pasar Pucang Anom | F4: Pasar Wonokromo | G4: Pasar Genteng Baru | H4: Pasar Pabean | I4: Pasar Kembang | J4: Pasar Balongsari | K4: Rata-Rata
A7: 1 | B7: BERAS
B8: - Beras Premium | C8: Kg | D8: 13000 | E8: 12500 | F8: 14500 | G8: 12800 | H8: 14000 | I8: 13500 | J8: 13000 | K8: =AVERAGE(D8:J8) -> 13328.571
B9: - Beras Medium | C9: Kg | D9: 9000 | E9: 9000 | F9: 8800 | G9: 9000 | H9: 9000 | I9: 9000 | J9: 9000 | K9: =AVERAGE(D9:J9) -> 8971.4286
B10: - Beras Jagung | C10: Kg | D10: - | E10: - | F10: - | G10: - | H10: - | I10: 11000 | J10: 8000 | K10: =AVERAGE(D10:J10) -> 9500
B11: - Beras Ketan (Jenis Siyem) | C11: Kg | D11: - | E11: 23000 | F11: - | G11: - | H11: - | I11: 20000 | J11: 17000 | K11: =AVERAGE(D11:J11) -> 20000
A12: 2 | B12: GULA
B13: Gula Pasir Lokal Curah | C13: Kg | D13: 13000 | E13: 13000 | F13: 13000 | G13: 13000 | H13: 13000 | I13: 13000 | J13: 13000 | K13: =AVERAGE(D13:J13) -> 13000
B14: - Gula Jawa/Merah (Bahan Kelapa) | C14: Kg | D14: 15000 | E14: 16000 | F14: 16000 | G14: 19000 | H14: 15000 | I14: 17000 | J14: 16000 | K14: =AVERAGE(D14:J14) -> 16285.714
A15: 3 | B15: MINYAK GORENG
B16: - Minyak Goreng Curah (Bening) | C16: Kg | D16: 15000 | E16: 16000 | F16: 14000 | G16: 16000 | H16: 14000 | I16: 16000 | J16: 16000 | K16: =AVERAGE(D16:J16) -> 15285.714
B17: - Minyak Kita | C17: Liter | D17: 14000 | E17: 14000 | F17: 14000 | G17: 14000 | H17: - | I17: 14000 | J17: 14000 | K17: =AVERAGE(D17:J17) -> 14000
A18: 4 | B18: MENTEGA
B19: - Mentega Curah (Amanda) | C19: Kg | D19: - | E19: - | F19: - | G19: 14000 | H19: - | I19: 24000 | J19: - | K19: =AVERAGE(D19:J19) -> 19000
A20: 5 | B20: DAGING
B21: - Daging Sapi Grade Atas | C21: Kg | D21: 120000 | E21: 120000 | F21: 120000 | G21: 120000 | H21: 117000 | I21: 120000 | J21: 110000 | K21: =AVERAGE(D21:J21) -> 118142.86
B22: - Daging Sapi Grade Sedang | C22: Kg | D22: 110000 | E22: 110000 | F22: 115000 | G22: 110000 | H22: 114000 | I22: 110000 | J22: 100000 | K22: =AVERAGE(D22:J22) -> 109857.14
B23: - Daging Sapi Grade Bawah | C23: Kg | D23: 100000 | E23: 95000 | F23: 105000 | G23: 100000 | H23: 100000 | I23: 100000 | J23: - | K23: =AVERAGE(D23:J23) -> 100000
B24: - Daging Ayam Broiler | C24: Kg | D24: 30000 | E24: 28000 | F24: 32000 | G24: 30000 | H24: 32000 | I24: 32000 | J24: 32000 | K24: =AVERAGE(D24:J24) -> 30857.143
A25: 6 | B25: I K A N
B26: - Ikan Tongkol Segar (Uk. Sedang) | C26: Kg | D26: 35000 | E26: 40000 | F26: - | G26: 40000 | H26: 30000 | I26: 40000 | J26: 40000 | K26: =AVERAGE(D26:J26) -> 37500
B27: - Ikan Mujair Segar (Uk. Sedang) | C27: Kg | D27: - | E27: 30000 | F27: 30000 | G27: 30000 | H27: 23000 | I27: 30000 | J27: 28000 | K27: =AVERAGE(D27:J27) -> 28500
B28: - Udang Segar (Uk. Sedang) | C28: Kg | D28: - | E28: 70000 | F28: 60000 | G28: 75000 | H28: 58000 | I28: 75000 | J28: 60000 | K28: =AVERAGE(D28:J28) -> 66333.333
B29: - Ikan Lele Segar (Ukuran Sedang) | C29: Kg | D29: - | E29: - | F29: - | G29: - | H29: 23000 | I29: 24000 | J29: 26000 | K29: =AVERAGE(D29:J29) -> 24333.333
B30: - Ikan Bandeng Segar (Uk. Sedang) | C30: Kg | D30: 40000 | E30: 36000 | F30: 40000 | G30: 40000 | H30: 28000 | I30: 40000 | J30: 36000 | K30: =AVERAGE(D30:J30) -> 37142.857
B31: - Ikan Teri Asin (Bukan Teri Medan) | C31: Kg | D31: 80000 | E31: 100000 | F31: 80000 | G31: - | H31: 80000 | I31: - | J31: - | K31: =AVERAGE(D31:J31) -> 85000
A32: 7 | B32: TELUR
B33: - Telur Ayam Broiler | C33: Kg | D33: 26000 | E33: 25000 | F33: 26000 | G33: 26000 | H33: 24000 | I33: 26000 | J33: 25000 | K33: =AVERAGE(D33:J33) -> 25428.571
B34: - Telur Ayam Kampung | C34: Butir | D34: 2500 | E34: 2000 | F34: 2000 | G34: 2500 | H34: 2000 | I34: 2500 | J34: 3000 | K34: =AVERAGE(D34:J34) -> 2357.1429
A35: 8 | B35: TAHU DAN TEMPE
B36: - Tahu | C36: Biji | D36: 1000 | E36: 1000 | F36: 3500 | G36: 3000 | H36: 4000 | I36: 1200 | J36: 3000 | K36: =AVERAGE(D36:J36) -> 2385.7143
B37: - Tempe | C37: Biji | D37: 2500 | E37: 2500 | F37: 6000 | G37: 3000 | H37: 2500 | I37: 5000 | J37: 3500 | K37: =AVERAGE(D37:J37) -> 3571.4286
A38: 9 | B38: S U S U
B39: - Susu Kental Manis "INDOMILK" Putih | C39: 390 Gr/kaleng | D39: 12500 | E39: 12000 | F39: 10000 | G39: 12000 | H39: - | I39: 12000 | J39: 10000 | K39: =AVERAGE(D39:J39) -> 11416.667
B40: - Susu Bubuk "DANCOW" Full Cream | C40: 400 Gr/Dos | D40: - | E40: 37900 | F40: - | G40: 42500 | H40: - | I40: - | J40: - | K40: =AVERAGE(D40:J40) -> 40200
A41: 10 | B41: SABUN CUCI
B42: - Sabun Detergen Rinso (Anti Noda) | C42: 900 Gram | D42: - | E42: - | F42: - | G42: - | H42: 17500 | I42: 21000 | J42: 17500 | K42: =AVERAGE(D42:J42) -> 18666.667
...

Sheet 6
A1: HARGA BAHAN-BAHAN POKOK
A2: DI PASAR TRADISIONAL KOTA SURABAYA
A3: HARI / TANGGAL : Senin / 06 Maret 2023
B4: NAMA BAHAN POKOK DAN PENTING LAINNYA | C4: SATUAN | D4: Pasar Tambahrejo | E4: Pasar Pucang Anom | F4: Pasar Wonokromo | G4: Pasar Genteng Baru | H4: Pasar Pabean | I4: Pasar Kembang | J4: Pasar Balongsari | K4: Rata-Rata
A7: 1 | B7: BERAS
B8: - Beras Premium | C8: Kg | D8: 13000 | E8: 12500 | F8: 14500 | G8: 12800 | H8: 14000 | I8: 13500 | J8: 13000 | K8: =AVERAGE(D8:J8) -> 13328.571
B9: - Beras Medium | C9: Kg | D9: 9000 | E9: 9000 | F9: 8800 | G9: 9000 | H9: 9000 | I9: 9000 | J9: 9000 | K9: =AVERAGE(D9:J9) -> 8971.4286
B10: - Beras Jagung | C10: Kg | D10: - | E10: - | F10: - | G10: - | H10: - | I10: 11000 | J10: 8000 | K10: =AVERAGE(D10:J10) -> 9500
B11: - Beras Ketan (Jenis Siyem) | C11: Kg | D11: - | E11: 21000 | F11: - | G11: - | H11: - | I11: 20000 | J11: 17000 | K11: =AVERAGE(D11:J11) -> 19333.333
A12: 2 | B12: GULA
B13: Gula Pasir Lokal Curah | C13: Kg | D13: 13000 | E13: 13000 | F13: 13000 | G13: 13000 | H13: 13000 | I13: 13000 | J13: 13000 | K13: =AVERAGE(D13:J13) -> 13000
B14: - Gula Jawa/Merah (Bahan Kelapa) | C14: Kg | D14: 15000 | E14: 16000 | F14: 16000 | G14: 19000 | H14: 15000 | I14: 17000 | J14: 16000 | K14: =AVERAGE(D14:J14) -> 16285.714
A15: 3 | B15: MINYAK GORENG
B16: - Minyak Goreng Curah (Bening) | C16: Kg | D16: 15000 | E16: 16000 | F16: 14000 | G16: 16000 | H16: 14000 | I16: 16000 | J16: 16000 | K16: =AVERAGE(D16:J16) -> 15285.714
B17: - Minyak Kita | C17: Liter | D17: 14000 | E17: 14000 | F17: 14000 | G17: 14000 | H17: - | I17: 14000 | J17: 14000 | K17: =AVERAGE(D17:J17) -> 14000
A18: 4 | B18: MENTEGA
B19: - Mentega Curah (Amanda) | C19: Kg | D19: - | E19: - | F19: - | G19: 14000 | H19: - | I19: 24000 | J19: - | K19: =AVERAGE(D19:J19) -> 19000
A20: 5 | B20: DAGING
B21: - Daging Sapi Grade Atas | C21: Kg | D21: 120000 | E21: 120000 | F21: 120000 | G21: 120000 | H21: 117000 | I21: 120000 | J21: 110000 | K21: =AVERAGE(D21:J21) -> 118142.86
B22: - Daging Sapi Grade Sedang | C22: Kg | D22: 110000 | E22: 110000 | F22: 115000 | G22: 110000 | H22: 114000 | I22: 110000 | J22: 100000 | K22: =AVERAGE(D22:J22) -> 109857.14
B23: - Daging Sapi Grade Bawah | C23: Kg | D23: 100000 | E23: 95000 | F23: 105000 | G23: 100000 | H23: 100000 | I23: 100000 | J23: - | K23: =AVERAGE(D23:J23) -> 100000
B24: - Daging Ayam Broiler | C24: Kg | D24: 30000 | E24: 28000 | F24: 30000 | G24: 30000 | H24: 32000 | I24: 32000 | J24: 30000 | K24: =AVERAGE(D24:J24) -> 30285.714
A25: 6 | B25: I K A N
B26: - Ikan Tongkol Segar (Uk. Sedang) | C26: Kg | D26: 35000 | E26: 40000 | F26: - | G26: 40000 | H26: 30000 | I26: 40000 | J26: 40000 | K26: =AVERAGE(D26:J26) -> 37500
B27: - Ikan Mujair Segar (Uk. Sedang) | C27: Kg | D27: - | E27: 30000 | F27: 30000 | G27: 30000 | H27: 23000 | I27: 30000 | J27: 28000 | K27: =AVERAGE(D27:J27) -> 28500
B28: - Udang Segar (Uk. Sedang) | C28: Kg | D28: - | E28: 70000 | F28: 60000 | G28: 75000 | H28: 58000 | I28: 75000 | J28: 60000 | K28: =AVERAGE(D28:J28) -> 66333.333
B29: - Ikan Lele Segar (Ukuran Sedang) | C29: Kg | D29: - | E29: - | F29: - | G29: - | H29: 23000 | I29: 24000 | J29: 26000 | K29: =AVERAGE(D29:J29) -> 24333.333
B30: - Ikan Bandeng Segar (Uk. Sedang) | C30: Kg | D30: 40000 | E30: 36000 | F30: 40000 | G30: 40000 | H30: 28000 | I30: 40000 | J30: 36000 | K30: =AVERAGE(D30:J30) -> 37142.857
B31: - Ikan Teri Asin (Bukan Teri Medan) | C31: Kg | D31: 80000 | E31: 100000 | F31: 80000 | G31: - | H31: 80000 | I31: - | J31: - | K31: =AVERAGE(D31:J31) -> 85000
A32: 7 | B32: TELUR
B33: - Telur Ayam Broiler | C33: Kg | D33: 26000 | E33: 25000 | F33: 27000 | G33: 26000 | H33: 25000 | I33: 26000 | J33: 26000 | K33: =AVERAGE(D33:J33) -> 25857.143
B34: - Telur Ayam Kampung | C34: Butir | D34: 2500 | E34: 2000 | F34: 2000 | G34: 2500 | H34: 2000 | I34: 2500 | J34: 3000 | K34: =AVERAGE(D34:J34) -> 2357.1429
A35: 8 | B35: TAHU DAN TEMPE
B36: - Tahu | C36: Biji | D36: 1000 | E36: 1000 | F36: 3500 | G36: 3000 | H36: 4000 | I36: 1200 | J36: 3000 | K36: =AVERAGE(D36:J36) -> 2385.7143
B37: - Tempe | C37: Biji | D37: 2500 | E37: 2500 | F37: 5000 | G37: 3000 | H37: 2500 | I37: 5000 | J37: 3500 | K37: =AVERAGE(D37:J37) -> 3428.5714
A38: 9 | B38: S U S U
B39: - Susu Kental Manis "INDOMILK" Putih | C39: 390 Gr/kaleng | D39: 12500 | E39: 12000 | F39: 10000 | G39: 12000 | H39: - | I39: 12000 | J39: 10000 | K39: =AVERAGE(D39:J39) -> 11416.667
B40: - Susu Bubuk "DANCOW" Full Cream | C40: 400 Gr/Dos | D40: - | E40: 37900 | F40: - | G40: 42500 | H40: - | I40: - | J40: - | K40: =AVERAGE(D40:J40) -> 40200
A41: 10 | B41: SABUN CUCI
B42: - Sabun Detergen Rinso (Anti Noda) | C42: 900 Gram | D42: - | E42: - | F42: - | G42: - | H42: 17500 | I42: 21000 | J42: 17500 | K42: =AVERAGE(D42:J42) -> 18666.667
...

Sheet 7
A1: HARGA BAHAN-BAHAN POKOK
A2: DI PASAR TRADISIONAL KOTA SURABAYA
A3: HARI / TANGGAL : Selasa / 07 Maret 2023
B4: NAMA BAHAN POKOK DAN PENTING LAINNYA | C4: SATUAN | D4: Pasar Tambahrejo | E4: Pasar Pucang Anom | F4: Pasar Wonokromo | G4: Pasar Genteng Baru | H4: Pasar Pabean | I4: Pasar Kembang | J4: Pasar Balongsari | K4: Rata-Rata
A7: 1 | B7: BERAS
B8: - Beras Premium | C8: Kg | D8: 13000 | E8: 12500 | F8: 14500 | G8: 12800 | H8: 14000 | I8: 13500 | J8: 13000 | K8: =AVERAGE(D8:J8) -> 13328.571
B9: - Beras Medium | C9: Kg | D9: 9000 | E9: 9000 | F9: 8800 | G9: 9000 | H9: 9000 | I9: 9000 | J9: 9000 | K9: =AVERAGE(D9:J9) -> 8971.4286
B10: - Beras Jagung | C10: Kg | D10: - | E10: - | F10: - | G10: - | H10: - | I10: 11000 | J10: 8000 | K10: =AVERAGE(D10:J10) -> 9500
B11: - Beras Ketan (Jenis Siyem) | C11: Kg | D11: - | E11: 21000 | F11: - | G11: - | H11: - | I11: 20000 | J11: 17000 | K11: =AVERAGE(D11:J11) -> 19333.333
A12: 2 | B12: GULA
B13: Gula Pasir Lokal Curah | C13: Kg | D13: 13000 | E13: 13000 | F13: 13000 | G13: 13000 | H13: 13000 | I13: 13000 | J13: 13000 | K13: =AVERAGE(D13:J13) -> 13000
B14: - Gula Jawa/Merah (Bahan Kelapa) | C14: Kg | D14: 15000 | E14: 16000 | F14: 16000 | G14: 19000 | H14: 15000 | I14: 17000 | J14: 16000 | K14: =AVERAGE(D14:J14) -> 16285.714
A15: 3 | B15: MINYAK GORENG
B16: - Minyak Goreng Curah (Bening) | C16: Kg | D16: 16000 | E16: 16000 | F16: 15000 | G16: 16000 | H16: 14000 | I16: 16000 | J16: 16000 | K16: =AVERAGE(D16:J16) -> 15571.429
B17: - Minyak Kita | C17: Liter | D17: 14000 | E17: 14000 | F17: - | G17: 14000 | H17: - | I17: 14000 | J17: 14000 | K17: =AVERAGE(D17:J17) -> 14000
A18: 4 | B18: MENTEGA
B19: - Mentega Curah (Amanda) | C19: Kg | D19: - | E19: - | F19: - | G19: 14000 | H19: - | I19: 24000 | J19: - | K19: =AVERAGE(D19:J19) -> 19000
A20: 5 | B20: DAGING
B21: - Daging Sapi Grade Atas | C21: Kg | D21: 120000 | E21: 120000 | F21: 120000 | G21: 120000 | H21: 117000 | I21: 120000 | J21: 110000 | K21: =AVERAGE(D21:J21) -> 118142.86
B22: - Daging Sapi Grade Sedang | C22: Kg | D22: 110000 | E22: 110000 | F22: 110000 | G22: 110000 | H22: 114000 | I22: 110000 | J22: 100000 | K22: =AVERAGE(D22:J22) -> 109142.86
B23: - Daging Sapi Grade Bawah | C23: Kg | D23: 100000 | E23: 95000 | F23: 100000 | G23: 100000 | H23: 100000 | I23: 100000 | J23: - | K23: =AVERAGE(D23:J23) -> 99166.667
B24: - Daging Ayam Broiler | C24: Kg | D24: 30000 | E24: 30000 | F24: 28000 | G24: 30000 | H24: 32000 | I24: 30000 | J24: 30000 | K24: =AVERAGE(D24:J24) -> 30000
A25: 6 | B25: I K A N
B26: - Ikan Tongkol Segar (Uk. Sedang) | C26: Kg | D26: 35000 | E26: 38000 | F26: - | G26: 40000 | H26: 30000 | I26: 40000 | J26: 40000 | K26: =AVERAGE(D26:J26) -> 37166.667
B27: - Ikan Mujair Segar (Uk. Sedang) | C27: Kg | D27: - | E27: 30000 | F27: 30000 | G27: 30000 | H27: 23000 | I27: 30000 | J27: 28000 | K27: =AVERAGE(D27:J27) -> 28500
B28: - Udang Segar (Uk. Sedang) | C28: Kg | D28: - | E28: 70000 | F28: 60000 | G28: 75000 | H28: 58000 | I28: 80000 | J28: 60000 | K28: =AVERAGE(D28:J28) -> 67166.667
B29: - Ikan Lele Segar (Ukuran Sedang) | C29: Kg | D29: - | E29: - | F29: - | G29: - | H29: 23000 | I29: 24000 | J29: 26000 | K29: =AVERAGE(D29:J29) -> 24333.333
B30: - Ikan Bandeng Segar (Uk. Sedang) | C30: Kg | D30: 40000 | E30: 36000 | F30: 40000 | G30: 40000 | H30: 28000 | I30: 44000 | J30: 36000 | K30: =AVERAGE(D30:J30) -> 37714.286
B31: - Ikan Teri Asin (Bukan Teri Medan) | C31: Kg | D31: 80000 | E31: 100000 | F31: 80000 | G31: - | H31: 80000 | I31: - | J31: - | K31: =AVERAGE(D31:J31) -> 85000
A32: 7 | B32: TELUR
B33: - Telur Ayam Broiler | C33: Kg | D33: 26000 | E33: 26000 | F33: 27000 | G33: 26000 | H33: 25000 | I33: 26000 | J33: 26000 | K33: =AVERAGE(D33:J33) -> 26000
B34: - Telur Ayam Kampung | C34: Butir | D34: 2500 | E34: 2000 | F34: 2000 | G34: 2500 | H34: 2000 | I34: 2500 | J34: 3000 | K34: =AVERAGE(D34:J34) -> 2357.1429
A35: 8 | B35: TAHU DAN TEMPE
B36: - Tahu | C36: Biji | D36: 1000 | E36: 1000 | F36: 3500 | G36: 3000 | H36: 4000 | I36: 1200 | J36: 3000 | K36: =AVERAGE(D36:J36) -> 2385.7143
B37: - Tempe | C37: Biji | D37: 2500 | E37: 2500 | F37: 5000 | G37: 3000 | H37: 2500 | I37: 5000 | J37: 3500 | K37: =AVERAGE(D37:J37) -> 3428.5714
A38: 9 | B38: S U S U
B39: - Susu Kental Manis "INDOMILK" Putih | C39: 390 Gr/kaleng | D39: 12500 | E39: 12000 | F39: 10000 | G39: 12000 | H39: - | I39: 12000 | J39: 10000 | K39: =AVERAGE(D39:J39) -> 11416.667
B40: - Susu Bubuk "DANCOW" Full Cream | C40: 400 Gr/Dos | D40: - | E40: 37900 | F40: - | G40: 42500 | H40: - | I40: - | J40: - | K40: =AVERAGE(D40:J40) -> 40200
A41: 10 | B41: SABUN CUCI
