Workbook

Sheet REKAPITULASI
A1: BAGIAN PEREKONOMIAN DAN SUMBER DAYA ALAM
A2: LAPORAN HARGA BAHAN POKOK DI KOTA SURABAYA
A3: PERIODE APRIL 2023
B4: NAMA BAHAN POKOK DAN PENTING LAINNYA | C4: SAT | AF4: HET/HAPK (Harga Eceran Tertinggi) | AG4: FLUKTUASI
D5: 1 | E5: 2 | F5: 3 | G5: 4 | H5: 5 | I5: 6 | J5: 7 | K5: 8 | L5: 9 | M5: 10 | N5: 11 | O5: 12 | P5: 13 | Q5: 14 | R5: 15 | S5: 16 | T5: 17 | U5: 18 | V5: 19 | W5: 20 | X5: 21 | Y5: 24 | Z5: 25 | AA5: 26 | AB5: 27 | AC5: 28 | AD5: 29 | AE5: 30
A7: 1 | B7: BERAS
B8: - Beras Premium | C8: Kg | D8: ='1'!K8 -> 13428.571 | E8: ='2'!K8 -> 13500 | F8: ='3'!K8 -> 13500 | G8: ='4'!K8 -> 13500 | H8: ='5'!K8 -> 13500 | I8: ='6'!K8 -> 13500 | J8: ='7'!K8 -> 13500 | K8: ='8'!K8 -> 13500 | L8: ='9'!K8 -> 13357.143 | M8: ='10'!K8 -> 13357.143 | N8: ='11'!K8 -> 13357.143 | O8: ='12'!K8 -> 13357.143 | P8: ='13'!K8 -> 13357.143 | Q8: ='14'!K8 -> 13357.143 | R8: ='15'!K8 -> 13357.143 | S8: ='16'!K8 -> 13357.143 | T8: ='17'!K8 -> 13357.143 | U8: ='18'!K8 -> 13357.143 | V8: ='19'!K8 -> 13357.143 | W8: ='20'!K8 -> 13357.143 | X8: ='21'!K8 -> 13357.143 | Y8: ='24'!K8 -> 13357.143 | Z8: ='25'!K8 -> 13642.857 | AA8: ='26'!K8 -> 13642.857 | AB8: ='27'!K8 -> 13642.857 | AC8: ='28'!K8 -> 13357.143 | AD8: ='29'!K8 -> 13500 | AE8: ='30'!K8 -> 13500 | AF8: 12800 | AG8: =AE8-D8 -> 71.428571 | AH8: =AVERAGE(D8:AE8) -> 13436.224
B9: - Beras Medium Bulog | C9: Kg | D9: ='1'!K9 -> 9566.6667 | E9: ='2'!K9 -> 9566.6667 | F9: ='3'!K9 -> 9566.6667 | G9: ='4'!K9 -> 9750 | H9: ='5'!K9 -> 9750 | I9: ='6'!K9 -> 9750 | J9: ='7'!K9 -> 9750 | K9: ='8'!K9 -> 9750 | L9: ='9'!K9 -> 9750 | M9: ='10'!K9 -> 9750 | N9: ='11'!K9 -> 9750 | O9: ='12'!K9 -> 9750 | P9: ='13'!K9 -> 9750 | Q9: ='14'!K9 -> 9750 | R9: ='15'!K9 -> 9750 | S9: ='16'!K9 -> 9750 | T9: ='17'!K9 -> 9750 | U9: ='18'!K9 -> 9750 | V9: ='19'!K9 -> 10000 | W9: ='20'!K9 -> 10000 | X9: ='21'!K9 -> 10000 | Y9: ='24'!K9 -> 10000 | Z9: ='25'!K9 -> 10666.667 | AA9: ='26'!K9 -> 10666.667 | AB9: ='27'!K9 -> 10666.667 | AC9: ='28'!K9 -> 10333.333 | AD9: ='29'!K9 -> 10333.333 | AE9: ='30'!K9 -> 10333.333 | AG9: =AE9-D9 -> 766.66667 | AH9: =AVERAGE(D9:AE9) -> 9926.7857
B10: - Beras Medium | C10: Kg | D10: ='1'!K10 -> 11166.667 | E10: ='2'!K10 -> 11166.667 | F10: ='3'!K10 -> 11333.333 | G10: ='4'!K10 -> 11333.333 | H10: ='5'!K10 -> 11333.333 | I10: ='6'!K10 -> 11333.333 | J10: ='7'!K10 -> 11333.333 | K10: ='8'!K10 -> 11333.333 | L10: ='9'!K10 -> 11333.333 | M10: ='10'!K10 -> 11333.333 | N10: ='11'!K10 -> 11333.333 | O10: ='12'!K10 -> 11333.333 | P10: ='13'!K10 -> 11333.333 | Q10: ='14'!K10 -> 11333.333 | R10: ='15'!K10 -> 11333.333 | S10: ='16'!K10 -> 11333.333 | T10: ='17'!K10 -> 11333.333 | U10: ='18'!K10 -> 11333.333 | V10: ='19'!K10 -> 11250 | W10: ='20'!K10 -> 11375 | X10: ='21'!K10 -> 11375 | Y10: ='24'!K10 -> 11375 | Z10: ='25'!K10 -> 11375 | AA10: ='26'!K10 -> 11375 | AB10: ='27'!K10 -> 11375 | AC10: ='28'!K10 -> 11375 | AD10: ='29'!K10 -> 11375 | AE10: ='30'!K10 -> 11375 | AF10: 9450 | AG10: =AE10-D10 -> 208.33333 | AH10: =AVERAGE(D10:AE10) -> 11331.845
B11: - Beras Jagung | C11: Kg | D11: ='1'!K11 -> 10600 | E11: ='2'!K11 -> 10600 | F11: ='3'!K11 -> 10600 | G11: ='4'!K11 -> 10600 | H11: ='5'!K11 -> 10600 | I11: ='6'!K11 -> 10600 | J11: ='7'!K11 -> 10600 | K11: ='8'!K11 -> 10600 | L11: ='9'!K11 -> 10600 | M11: ='10'!K11 -> 10600 | N11: ='11'!K11 -> 10600 | O11: ='12'!K11 -> 10600 | P11: ='13'!K11 -> 10600 | Q11: ='14'!K11 -> 10600 | R11: ='15'!K11 -> 10600 | S11: ='16'!K11 -> 10600 | T11: ='17'!K11 -> 10600 | U11: ='18'!K11 -> 10600 | V11: ='19'!K11 -> 10600 | W11: ='20'!K11 -> 10600 | X11: ='21'!K11 -> 10600 | Y11: ='24'!K11 -> 10600 | Z11: ='25'!K11 -> 10600 | AA11: ='26'!K11 -> 10600 | AB11: ='27'!K11 -> 10600 | AC11: ='28'!K11 -> 10600 | AD11: ='29'!K11 -> 10600 | AE11: ='30'!K11 -> 10600 | AG11: =AE11-D11 -> 0 | AH11: =AVERAGE(D11:AE11) -> 10600
B12: - Beras Ketan (Jenis Siyem) | C12: Kg | D12: ='1'!K12 -> 21000 | E12: ='2'!K12 -> 21000 | F12: ='3'!K12 -> 21000 | G12: ='4'!K12 -> 21000 | H12: ='5'!K12 -> 21000 | I12: ='6'!K12 -> 21000 | J12: ='7'!K12 -> 21000 | K12: ='8'!K12 -> 21000 | L12: ='9'!K12 -> 21000 | M12: ='10'!K12 -> 21000 | N12: ='11'!K12 -> 21000 | O12: ='12'!K12 -> 21000 | P12: ='13'!K12 -> 21000 | Q12: ='14'!K12 -> 21000 | R12: ='15'!K12 -> 21000 | S12: ='16'!K12 -> 21000 | T12: ='17'!K12 -> 21000 | U12: ='18'!K12 -> 21000 | V12: ='19'!K12 -> 21000 | W12: ='20'!K12 -> 21000 | X12: ='21'!K12 -> 21000 | Y12: ='24'!K12 -> 21000 | Z12: ='25'!K12 -> 20200 | AA12: ='26'!K12 -> 20600 | AB12: ='27'!K12 -> 21000 | AC12: ='28'!K12 -> 21000 | AD12: ='29'!K12 -> 20200 | AE12: ='30'!K12 -> 20200 | AG12: =AE12-D12 -> -800 | AH12: =AVERAGE(D12:AE12) -> 20900
A13: 2 | B13: GULA | D13: ='1'!K13 -> 0 | E13: ='2'!K13 -> 0 | F13: ='3'!K13 -> 0 | G13: ='4'!K13 -> 0 | H13: ='5'!K13 -> 0 | I13: ='6'!K13 -> 0 | J13: ='7'!K13 -> 0 | K13: ='8'!K13 -> 0 | L13: ='9'!K13 -> 0 | M13: ='10'!K13 -> 0 | N13: ='11'!K13 -> 0 | O13: ='12'!K13 -> 0 | P13: ='13'!K13 -> 0 | Q13: ='14'!K13 -> 0 | R13: ='15'!K13 -> 0 | S13: ='16'!K13 -> 0 | T13: ='17'!K13 -> 0 | U13: ='18'!K13 -> 0 | V13: ='19'!K13 -> 0 | W13: ='20'!K13 -> 0 | X13: ='21'!K13 -> 0 | Y13: ='24'!K13 -> 0 | Z13: ='25'!K13 -> 0 | AA13: ='26'!K13 -> 0 | AB13: ='27'!K13 -> 0 | AC13: ='28'!K13 -> 0 | AD13: ='29'!K13 -> 0 | AE13: ='30'!K13 -> 0 | AG13: =AE13-D13 -> 0 | AH13: =AVERAGE(D13:AE13) -> 0
B14: - Gula pasir lokal curah | C14: Kg | D14: ='1'!K14 -> 13142.857 | E14: ='2'!K14 -> 13142.857 | F14: ='3'!K14 -> 13142.857 | G14: ='4'!K14 -> 13142.857 | H14: ='5'!K14 -> 13142.857 | I14: ='6'!K14 -> 13142.857 | J14: ='7'!K14 -> 13142.857 | K14: ='8'!K14 -> 13142.857 | L14: ='9'!K14 -> 13142.857 | M14: ='10'!K14 -> 13142.857 | N14: ='11'!K14 -> 13142.857 | O14: ='12'!K14 -> 13142.857 | P14: ='13'!K14 -> 13142.857 | Q14: ='14'!K14 -> 13142.857 | R14: ='15'!K14 -> 13142.857 | S14: ='16'!K14 -> 13142.857 | T14: ='17'!K14 -> 13142.857 | U14: ='18'!K14 -> 13142.857 | V14: ='19'!K14 -> 13142.857 | W14: ='20'!K14 -> 13071.429 | X14: ='21'!K14 -> 13071.429 | Y14: ='24'!K14 -> 13071.429 | Z14: ='25'!K14 -> 13142.857 | AA14: ='26'!K14 -> 13071.429 | AB14: ='27'!K14 -> 13142.857 | AC14: ='28'!K14 -> 13142.857 | AD14: ='29'!K14 -> 13071.429 | AE14: ='30'!K14 -> 13071.429 | AF14: 13500 | AG14: =AE14-D14 -> -71.428571 | AH14: =AVERAGE(D14:AE14) -> 13127.551
B15: - Gula Jawa/Merah (Bahan Kelapa) | C15: Kg | D15: ='1'!K15 -> 15714.286 | E15: ='2'!K15 -> 15714.286 | F15: ='3'!K15 -> 15714.286 | G15: ='4'!K15 -> 15714.286 | H15: ='5'!K15 -> 15714.286 | I15: ='6'!K15 -> 15714.286 | J15: ='7'!K15 -> 15714.286 | K15: ='8'!K15 -> 15714.286 | L15: ='9'!K15 -> 15714.286 | M15: ='10'!K15 -> 15714.286 | N15: ='11'!K15 -> 15714.286 | O15: ='12'!K15 -> 15714.286 | P15: ='13'!K15 -> 15714.286 | Q15: ='14'!K15 -> 15714.286 | R15: ='15'!K15 -> 15714.286 | S15: ='16'!K15 -> 15714.286 | T15: ='17'!K15 -> 15714.286 | U15: ='18'!K15 -> 15714.286 | V15: ='19'!K15 -> 15714.286 | W15: ='20'!K15 -> 15571.429 | X15: ='21'!K15 -> 15714.286 | Y15: ='24'!K15 -> 15714.286 | Z15: ='25'!K15 -> 16285.714 | AA15: ='26'!K15 -> 16285.714 | AB15: ='27'!K15 -> 16142.857 | AC15: ='28'!K15 -> 15571.429 | AD15: ='29'!K15 -> 16285.714 | AE15: ='30'!K15 -> 16285.714 | AG15: =AE15-D15 -> 571.42857 | AH15: =AVERAGE(D15:AE15) -> 15801.02
A16: 3 | B16: MINYAK GORENG | D16: ='1'!K16 -> 0 | E16: ='2'!K16 -> 0 | F16: ='3'!K16 -> 0 | G16: ='4'!K16 -> 0 | H16: ='5'!K16 -> 0 | I16: ='6'!K16 -> 0 | J16: ='7'!K16 -> 0 | K16: ='8'!K16 -> 0 | L16: ='9'!K16 -> 0 | M16: ='10'!K16 -> 0 | N16: ='11'!K16 -> 0 | O16: ='12'!K16 -> 0 | P16: ='13'!K16 -> 0 | Q16: ='14'!K16 -> 0 | R16: ='15'!K16 -> 0 | S16: ='16'!K16 -> 0 | T16: ='17'!K16 -> 0 | U16: ='18'!K16 -> 0 | V16: ='19'!K16 -> 0 | W16: ='20'!K16 -> 0 | X16: ='21'!K16 -> 0 | Y16: ='24'!K16 -> 0 | Z16: ='25'!K16 -> 0 | AA16: ='26'!K16 -> 0 | AB16: ='27'!K16 -> 0 | AC16: ='28'!K16 -> 0 | AD16: ='29'!K16 -> 0 | AE16: ='30'!K16 -> 0 | AG16: =AE16-D16 -> 0 | AH16: =AVERAGE(D16:AE16) -> 0
B17: - Minyak Goreng Curah (Bening) | C17: Kg | D17: ='1'!K17 -> 15785.714 | E17: ='2'!K17 -> 15785.714 | F17: ='3'!K17 -> 15642.857 | G17: ='4'!K17 -> 15500 | H17: ='5'!K17 -> 15642.857 | I17: ='6'!K17 -> 15571.429 | J17: ='7'!K17 -> 15571.429 | K17: ='8'!K17 -> 15571.429 | L17: ='9'!K17 -> 15571.429 | M17: ='10'!K17 -> 15428.571 | N17: ='11'!K17 -> 15571.429 | O17: ='12'!K17 -> 15571.429 | P17: ='13'!K17 -> 15571.429 | Q17: ='14'!K17 -> 15500 | R17: ='15'!K17 -> 15500 | S17: ='16'!K17 -> 15500 | T17: ='17'!K17 -> 15500 | U17: ='18'!K17 -> 15500 | V17: ='19'!K17 -> 15500 | W17: ='20'!K17 -> 15500 | X17: ='21'!K17 -> 15357.143 | Y17: ='24'!K17 -> 15357.143 | Z17: ='25'!K17 -> 15500 | AA17: ='26'!K17 -> 15357.143 | AB17: ='27'!K17 -> 15357.143 | AC17: ='28'!K17 -> 15500 | AD17: ='29'!K17 -> 15357.143 | AE17: ='30'!K17 -> 15357.143 | AF17: 15500 | AG17: =AE17-D17 -> -428.57143 | AH17: =AVERAGE(D17:AE17) -> 15515.306
B18: - Minyak Kita | C18: Liter | D18: ='1'!K18 -> 14000 | E18: ='2'!K18 -> 14000 | F18: ='3'!K18 -> 14000 | G18: ='4'!K18 -> 14000 | H18: ='5'!K18 -> 14000 | I18: ='6'!K18 -> 14000 | J18: ='7'!K18 -> 14000 | K18: ='8'!K18 -> 14000 | L18: ='9'!K18 -> 14000 | M18: ='10'!K18 -> 14000 | N18: ='11'!K18 -> 14000 | O18: ='12'!K18 -> 14000 | P18: ='13'!K18 -> 14000 | Q18: ='14'!K18 -> 14000 | R18: ='15'!K18 -> 14000 | S18: ='16'!K18 -> 14000 | T18: ='17'!K18 -> 14000 | U18: ='18'!K18 -> 14000 | V18: ='19'!K18 -> 14000 | W18: ='20'!K18 -> 14000 | X18: ='21'!K18 -> 14000 | Y18: ='24'!K18 -> 14000 | Z18: ='25'!K18 -> 14000 | AA18: ='26'!K18 -> 14000 | AB18: ='27'!K18 -> 14000 | AC18: ='28'!K18 -> 14000 | AD18: ='29'!K18 -> 14000 | AE18: ='30'!K18 -> 14000 | AF18: 14000 | AG18: =AE18-D18 -> 0 | AH18: =AVERAGE(D18:AE18) -> 14000
A19: 4 | B19: MENTEGA | D19: ='1'!K19 -> 0 | E19: ='2'!K19 -> 0 | F19: ='3'!K19 -> 0 | G19: ='4'!K19 -> 0 | H19: ='5'!K19 -> 0 | I19: ='6'!K19 -> 0 | J19: ='7'!K19 -> 0 | K19: ='8'!K19 -> 0 | L19: ='9'!K19 -> 0 | M19: ='10'!K19 -> 0 | N19: ='11'!K19 -> 0 | O19: ='12'!K19 -> 0 | P19: ='13'!K19 -> 0 | Q19: ='14'!K19 -> 0 | R19: ='15'!K19 -> 0 | S19: ='16'!K19 -> 0 | T19: ='17'!K19 -> 0 | U19: ='18'!K19 -> 0 | V19: ='19'!K19 -> 0 | W19: ='20'!K19 -> 0 | X19: ='21'!K19 -> 0 | Y19: ='24'!K19 -> 0 | Z19: ='25'!K19 -> 0 | AA19: ='26'!K19 -> 0 | AB19: ='27'!K19 -> 0 | AC19: ='28'!K19 -> 0 | AD19: ='29'!K19 -> 0 | AE19: ='30'!K19 -> 0 | AG19: =AE19-D19 -> 0 | AH19: =AVERAGE(D19:AE19) -> 0
B20: - Mentega Curah (Amanda) | C20: Kg | D20: ='1'!K20 -> 21250 | E20: ='2'!K20 -> 21250 | F20: ='3'!K20 -> 21250 | G20: ='4'!K20 -> 21250 | H20: ='5'!K20 -> 21250 | I20: ='6'!K20 -> 21250 | J20: ='7'!K20 -> 21250 | K20: ='8'!K20 -> 21250 | L20: ='9'!K20 -> 21250 | M20: ='10'!K20 -> 21250 | N20: ='11'!K20 -> 21250 | O20: ='12'!K20 -> 21250 | P20: ='13'!K20 -> 21250 | Q20: ='14'!K20 -> 21250 | R20: ='15'!K20 -> 21250 | S20: ='16'!K20 -> 21250 | T20: ='17'!K20 -> 21250 | U20: ='18'!K20 -> 21250 | V20: ='19'!K20 -> 21250 | W20: ='20'!K20 -> 21250 | X20: ='21'!K20 -> 21250 | Y20: ='24'!K20 -> 21250 | Z20: ='25'!K20 -> 22500 | AA20: ='26'!K20 -> 22500 | AB20: ='27'!K20 -> 22500 | AC20: ='28'!K20 -> 21250 | AD20: ='29'!K20 -> 22500 | AE20: ='30'!K20 -> 22500 | AG20: =AE20-D20 -> 1250 | AH20: =AVERAGE(D20:AE20) -> 21473.214
A21: 5 | B21: DAGING | D21: ='1'!K21 -> 0 | E21: ='2'!K21 -> 0 | F21: ='3'!K21 -> 0 | G21: ='4'!K21 -> 0 | H21: ='5'!K21 -> 0 | I21: ='6'!K21 -> 0 | J21: ='7'!K21 -> 0 | K21: ='8'!K21 -> 0 | L21: ='9'!K21 -> 0 | M21: ='10'!K21 -> 0 | N21: ='11'!K21 -> 0 | O21: ='12'!K21 -> 0 | P21: ='13'!K21 -> 0 | Q21: ='14'!K21 -> 0 | R21: ='15'!K21 -> 0 | S21: ='16'!K21 -> 0 | T21: ='17'!K21 -> 0 | U21: ='18'!K21 -> 0 | V21: ='19'!K21 -> 0 | W21: ='20'!K21 -> 0 | X21: ='21'!K21 -> 0 | Y21: ='24'!K21 -> 0 | Z21: ='25'!K21 -> 0 | AA21: ='26'!K21 -> 0 | AB21: ='27'!K21 -> 0 | AC21: ='28'!K21 -> 0 | AD21: ='29'!K21 -> 0 | AE21: ='30'!K21 -> 0 | AG21: =AE21-D21 -> 0 | AH21: =AVERAGE(D21:AE21) -> 0
B22: - Daging Sapi Grade Atas | C22: Kg | D22: ='1'!K22 -> 118571.43 | E22: ='2'!K22 -> 118571.43 | F22: ='3'!K22 -> 118571.43 | G22: ='4'!K22 -> 118571.43 | H22: ='5'!K22 -> 118571.43 | I22: ='6'!K22 -> 118571.43 | J22: ='7'!K22 -> 118571.43 | K22: ='8'!K22 -> 118571.43 | L22: ='9'!K22 -> 118571.43 | M22: ='10'!K22 -> 118571.43 | N22: ='11'!K22 -> 118571.43 | O22: ='12'!K22 -> 118571.43 | P22: ='13'!K22 -> 118571.43 | Q22: ='14'!K22 -> 118571.43 | R22: ='15'!K22 -> 118571.43 | S22: ='16'!K22 -> 118571.43 | T22: ='17'!K22 -> 118571.43 | U22: ='18'!K22 -> 118571.43 | V22: ='19'!K22 -> 120000 | W22: ='20'!K22 -> 123571.43 | X22: ='21'!K22 -> 124285.71 | Y22: ='24'!K22 -> 124285.71 | Z22: ='25'!K22 -> 124285.71 | AA22: ='26'!K22 -> 122857.14 | AB22: ='27'!K22 -> 122857.14 | AC22: ='28'!K22 -> 121428.57 | AD22: ='29'!K22 -> 122857.14 | AE22: ='30'!K22 -> 122857.14 | AF22: 105000 | AG22: =AE22-D22 -> 4285.7143 | AH22: =AVERAGE(D22:AE22) -> 120127.55
B23: - Daging Sapi Grade Sedang | C23: Kg | D23: ='1'!K23 -> 109142.86 | E23: ='2'!K23 -> 109142.86 | F23: ='3'!K23 -> 109142.86 | G23: ='4'!K23 -> 109142.86 | H23: ='5'!K23 -> 109142.86 | I23: ='6'!K23 -> 109142.86 | J23: ='7'!K23 -> 109142.86 | K23: ='8'!K23 -> 109142.86 | L23: ='9'!K23 -> 109142.86 | M23: ='10'!K23 -> 109142.86 | N23: ='11'!K23 -> 109142.86 | O23: ='12'!K23 -> 109142.86 | P23: ='13'!K23 -> 109142.86 | Q23: ='14'!K23 -> 109142.86 | R23: ='15'!K23 -> 109142.86 | S23: ='16'!K23 -> 109142.86 | T23: ='17'!K23 -> 109142.86 | U23: ='18'!K23 -> 109142.86 | V23: ='19'!K23 -> 110571.43 | W23: ='20'!K23 -> 113428.57 | X23: ='21'!K23 -> 114142.86 | Y23: ='24'!K23 -> 114142.86 | Z23: ='25'!K23 -> 114142.86 | AA23: ='26'!K23 -> 113428.57 | AB23: ='27'!K23 -> 98714.286 | AC23: ='28'!K23 -> 113857.14 | AD23: ='29'!K23 -> 114142.86 | AE23: ='30'!K23 -> 114142.86 | AF23: 80000 | AG23: =AE23-D23 -> 5000 | AH23: =AVERAGE(D23:AE23) -> 110188.78
B24: - Daging Sapi Grade Bawah | C24: Kg | D24: ='1'!K24 -> 99166.667 | E24: ='2'!K24 -> 99166.667 | F24: ='3'!K24 -> 99166.667 | G24: ='4'!K24 -> 99166.667 | H24: ='5'!K24 -> 99166.667 | I24: ='6'!K24 -> 99166.667 | J24: ='7'!K24 -> 99166.667 | K24: ='8'!K24 -> 99166.667 | L24: ='9'!K24 -> 99166.667 | M24: ='10'!K24 -> 99166.667 | N24: ='11'!K24 -> 99166.667 | O24: ='12'!K24 -> 99166.667 | P24: ='13'!K24 -> 99166.667 | Q24: ='14'!K24 -> 99166.667 | R24: ='15'!K24 -> 99166.667 | S24: ='16'!K24 -> 99166.667 | T24: ='17'!K24 -> 99166.667 | U24: ='18'!K24 -> 99166.667 | V24: ='19'!K24 -> 100833.33 | W24: ='20'!K24 -> 103333.33 | X24: ='21'!K24 -> 104166.67 | Y24: ='24'!K24 -> 104166.67 | Z24: ='25'!K24 -> 104166.67 | AA24: ='26'!K24 -> 103333.33 | AB24: ='27'!K24 -> 104166.67 | AC24: ='28'!K24 -> 105000 | AD24: ='29'!K24 -> 105000 | AE24: ='30'!K24 -> 105000 | AF24: 80000 | AG24: =AE24-D24 -> 5833.3333 | AH24: =AVERAGE(D24:AE24) -> 100863.1
B25: - Daging Ayam Broiler | C25: Kg | D25: ='1'!K25 -> 30571.429 | E25: ='2'!K25 -> 30714.286 | F25: ='3'!K25 -> 31142.857 | G25: ='4'!K25 -> 31142.857 | H25: ='5'!K25 -> 31142.857 | I25: ='6'!K25 -> 30857.143 | J25: ='7'!K25 -> 30857.143 | K25: ='8'!K25 -> 30857.143 | L25: ='9'!K25 -> 30571.429 | M25: ='10'!K25 -> 31857.143 | N25: ='11'!K25 -> 32428.571 | O25: ='12'!K25 -> 32428.571 | P25: ='13'!K25 -> 32142.857 | Q25: ='14'!K25 -> 33000 | R25: ='15'!K25 -> 33000 | S25: ='16'!K25 -> 32857.143 | T25: ='17'!K25 -> 33428.571 | U25: ='18'!K25 -> 33857.143 | V25: ='19'!K25 -> 34428.571 | W25: ='20'!K25 -> 36571.429 | X25: ='21'!K25 -> 38833.333 | Y25: ='24'!K25 -> 38833.333 | Z25: ='25'!K25 -> 39833.333 | AA25: ='26'!K25 -> 40285.714 | AB25: ='27'!K25 -> 39285.714 | AC25: ='28'!K25 -> 36428.571 | AD25: ='29'!K25 -> 36571.429 | AE25: ='30'!K25 -> 36571.429 | AF25: 36750 | AG25: =AE25-D25 -> 6000 | AH25: =AVERAGE(D25:AE25) -> 33946.429
A26: 6 | B26: I K A N | D26: ='1'!K26 -> 0 | E26: ='2'!K26 -> 0 | F26: ='3'!K26 -> 0 | G26: ='4'!K26 -> 0 | H26: ='5'!K26 -> 0 | I26: ='6'!K26 -> 0 | J26: ='7'!K26 -> 0 | K26: ='8'!K26 -> 0 | L26: ='9'!K26 -> 0 | M26: ='10'!K26 -> 0 | N26: ='11'!K26 -> 0 | O26: ='12'!K26 -> 0 | P26: ='13'!K26 -> 0 | Q26: ='14'!K26 -> 0 | R26: ='15'!K26 -> 0 | S26: ='16'!K26 -> 0 | T26: ='17'!K26 -> 0 | U26: ='18'!K26 -> 0 | V26: ='19'!K26 -> 0 | W26: ='20'!K26 -> 0 | X26: ='21'!K26 -> 0 | Y26: ='24'!K26 -> 0 | Z26: ='25'!K26 -> 0 | AA26: ='26'!K26 -> 0 | AB26: ='27'!K26 -> 0 | AC26: ='28'!K26 -> 0 | AD26: ='29'!K26 -> 0 | AE26: ='30'!K26 -> 0 | AG26: =AE26-D26 -> 0 | AH26: =AVERAGE(D26:AE26) -> 0
B27: - Ikan Tongkol Segar (Uk. Sedang) | C27: Kg | D27: ='1'!K27 -> 37333.333 | E27: ='2'!K27 -> 37333.333 | F27: ='3'!K27 -> 36833.333 | G27: ='4'!K27 -> 36833.333 | H27: ='5'!K27 -> 36833.333 | I27: ='6'!K27 -> 36833.333 | J27: ='7'!K27 -> 36833.333 | K27: ='8'!K27 -> 37666.667 | L27: ='9'!K27 -> 37666.667 | M27: ='10'!K27 -> 37666.667 | N27: ='11'!K27 -> 37666.667 | O27: ='12'!K27 -> 37666.667 | P27: ='13'!K27 -> 38000 | Q27: ='14'!K27 -> 38000 | R27: ='15'!K27 -> 38000 | S27: ='16'!K27 -> 38333.333 | T27: ='17'!K27 -> 38333.333 | U27: ='18'!K27 -> 37666.667 | V27: ='19'!K27 -> 37666.667 | W27: ='20'!K27 -> 37666.667 | X27: ='21'!K27 -> 37600 | Y27: ='24'!K27 -> 37600 | Z27: ='25'!K27 -> 37600 | AA27: ='26'!K27 -> 39666.667 | AB27: ='27'!K27 -> 39666.667 | AC27: ='28'!K27 -> 39666.667 | AD27: ='29'!K27 -> 35714.286 | AE27: ='30'!K27 -> 35714.286 | AG27: =AE27-D27 -> -1619.0476 | AH27: =AVERAGE(D27:AE27) -> 37645.068
B28: - Ikan Mujair Segar (Uk. Sedang) | C28: Kg | D28: ='1'!K28 -> 28857.143 | E28: ='2'!K28 -> 29571.429 | F28: ='3'!K28 -> 29142.857 | G28: ='4'!K28 -> 29142.857 | H28: ='5'!K28 -> 29142.857 | I28: ='6'!K28 -> 29142.857 | J28: ='7'!K28 -> 29142.857 | K28: ='8'!K28 -> 29714.286 | L28: ='9'!K28 -> 29714.286 | M28: ='10'!K28 -> 29714.286 | N28: ='11'!K28 -> 29714.286 | O28: ='12'!K28 -> 29714.286 | P28: ='13'!K28 -> 29714.286 | Q28: ='14'!K28 -> 30000 | R28: ='15'!K28 -> 30000 | S28: ='16'!K28 -> 30000 | T28: ='17'!K28 -> 30000 | U28: ='18'!K28 -> 30285.714 | V28: ='19'!K28 -> 30285.714 | W28: ='20'!K28 -> 30285.714 | X28: ='21'!K28 -> 30000 | Y28: ='24'!K28 -> 30000 | Z28: ='25'!K28 -> 30000 | AA28: ='26'!K28 -> 31428.571 | AB28: ='27'!K28 -> 31000 | AC28: ='28'!K28 -> 31428.571 | AD28: ='29'!K28 -> 31428.571 | AE28: ='30'!K28 -> 31428.571 | AG28: =AE28-D28 -> 2571.4286 | AH28: =AVERAGE(D28:AE28) -> 30000
B29: - Udang Segar (Uk. Sedang) | C29: Kg | D29: ='1'!K29 -> 64000 | E29: ='2'!K29 -> 64000 | F29: ='3'!K29 -> 65428.571 | G29: ='4'!K29 -> 65428.571 | H29: ='5'!K29 -> 65142.857 | I29: ='6'!K29 -> 63714.286 | J29: ='7'!K29 -> 62285.714 | K29: ='8'!K29 -> 63714.286 | L29: ='9'!K29 -> 64285.714 | M29: ='10'!K29 -> 64285.714 | N29: ='11'!K29 -> 64285.714 | O29: ='12'!K29 -> 64285.714 | P29: ='13'!K29 -> 63285.714 | Q29: ='14'!K29 -> 63285.714 | R29: ='15'!K29 -> 63285.714 | S29: ='16'!K29 -> 63285.714 | T29: ='17'!K29 -> 63285.714 | U29: ='18'!K29 -> 63285.714 | V29: ='19'!K29 -> 63285.714 | W29: ='20'!K29 -> 64714.286 | X29: ='21'!K29 -> 64666.667 | Y29: ='24'!K29 -> 64666.667 | Z29: ='25'!K29 -> 64666.667 | AA29: ='26'!K29 -> 70000 | AB29: ='27'!K29 -> 67142.857 | AC29: ='28'!K29 -> 65714.286 | AD29: ='29'!K29 -> 67142.857 | AE29: ='30'!K29 -> 67142.857 | AG29: =AE29-D29 -> 3142.8571 | AH29: =AVERAGE(D29:AE29) -> 64632.653
B30: - Ikan Lele Segar (Ukuran Sedang) | C30: Kg | D30: ='1'!K30 -> 24600 | E30: ='2'!K30 -> 24600 | F30: ='3'!K30 -> 24600 | G30: ='4'!K30 -> 24600 | H30: ='5'!K30 -> 24600 | I30: ='6'!K30 -> 24600 | J30: ='7'!K30 -> 24600 | K30: ='8'!K30 -> 24600 | L30: ='9'!K30 -> 24600 | M30: ='10'!K30 -> 24600 | N30: ='11'!K30 -> 24600 | O30: ='12'!K30 -> 24600 | P30: ='13'!K30 -> 24600 | Q30: ='14'!K30 -> 24600 | R30: ='15'!K30 -> 24600 | S30: ='16'!K30 -> 24600 | T30: ='17'!K30 -> 24600 | U30: ='18'!K30 -> 24600 | V30: ='19'!K30 -> 24600 | W30: ='20'!K30 -> 24600 | X30: ='21'!K30 -> 24600 | Y30: ='24'!K30 -> 24600 | Z30: ='25'!K30 -> 24600 | AA30: ='26'!K30 -> 24600 | AB30: ='27'!K30 -> 24600 | AC30: ='28'!K30 -> 24600 | AD30: ='29'!K30 -> 24600 | AE30: ='30'!K30 -> 24600 | AG30: =AE30-D30 -> 0 | AH30: =AVERAGE(D30:AE30) -> 24600
B31: - Ikan Bandeng Segar (Uk. Sedang) | C31: Kg | D31: ='1'!K31 -> 38857.143 | E31: ='2'!K31 -> 38857.143 | F31: ='3'!K31 -> 38857.143 | G31: ='4'!K31 -> 38857.143 | H31: ='5'!K31 -> 38571.429 | I31: ='6'!K31 -> 38571.429 | J31: ='7'!K31 -> 38571.429 | K31: ='8'!K31 -> 37857.143 | L31: ='9'!K31 -> 37857.143 | M31: ='10'!K31 -> 38000 | N31: ='11'!K31 -> 38000 | O31: ='12'!K31 -> 38000 | P31: ='13'!K31 -> 38428.571 | Q31: ='14'!K31 -> 38428.571 | R31: ='15'!K31 -> 38428.571 | S31: ='16'!K31 -> 38428.571 | T31: ='17'!K31 -> 38428.571 | U31: ='18'!K31 -> 38142.857 | V31: ='19'!K31 -> 38142.857 | W31: ='20'!K31 -> 38428.571 | X31: ='21'!K31 -> 38500 | Y31: ='24'!K31 -> 38500 | Z31: ='25'!K31 -> 38500 | AA31: ='26'!K31 -> 38428.571 | AB31: ='27'!K31 -> 38428.571 | AC31: ='28'!K31 -> 38428.571 | AD31: ='29'!K31 -> 38428.571 | AE31: ='30'!K31 -> 38428.571 | AG31: =AE31-D31 -> -428.57143 | AH31: =AVERAGE(D31:AE31) -> 38405.612
B32: - Ikan Teri Asin (Bukan Teri Medan) | C32: Kg | D32: ='1'!K32 -> 96666.667 | E32: ='2'!K32 -> 96666.667 | F32: ='3'!K32 -> 96666.667 | G32: ='4'!K32 -> 96666.667 | H32: ='5'!K32 -> 96666.667 | I32: ='6'!K32 -> 96666.667 | J32: ='7'!K32 -> 96666.667 | K32: ='8'!K32 -> 96666.667 | L32: ='9'!K32 -> 96666.667 | M32: ='10'!K32 -> 96666.667 | N32: ='11'!K32 -> 96666.667 | O32: ='12'!K32 -> 96666.667 | P32: ='13'!K32 -> 96666.667 | Q32: ='14'!K32 -> 96666.667 | R32: ='15'!K32 -> 96666.667 | S32: ='16'!K32 -> 96666.667 | T32: ='17'!K32 -> 96666.667 | U32: ='18'!K32 -> 96666.667 | V32: ='19'!K32 -> 96666.667 | W32: ='20'!K32 -> 96666.667 | X32: ='21'!K32 -> 96666.667 | Y32: ='24'!K32 -> 96666.667 | Z32: ='25'!K32 -> 96666.667 | AA32: ='26'!K32 -> 91666.667 | AB32: ='27'!K32 -> 91666.667 | AC32: ='28'!K32 -> 96666.667 | AD32: ='29'!K32 -> 103333.33 | AE32: ='30'!K32 -> 103333.33 | AG32: =AE32-D32 -> 6666.6667 | AH32: =AVERAGE(D32:AE32) -> 96785.714
A33: 7 | B33: TELUR | D33: ='1'!K33 -> 0 | E33: ='2'!K33 -> 0 | F33: ='3'!K33 -> 0 | G33: ='4'!K33 -> 0 | H33: ='5'!K33 -> 0 | I33: ='6'!K33 -> 0 | J33: ='7'!K33 -> 0 | K33: ='8'!K33 -> 0 | L33: ='9'!K33 -> 0 | M33: ='10'!K33 -> 0 | N33: ='11'!K33 -> 0 | O33: ='12'!K33 -> 0 | P33: ='13'!K33 -> 0 | Q33: ='14'!K33 -> 0 | R33: ='15'!K33 -> 0 | S33: ='16'!K33 -> 0 | T33: ='17'!K33 -> 0 | U33: ='18'!K33 -> 0 | V33: ='19'!K33 -> 0 | W33: ='20'!K33 -> 0 | X33: ='21'!K33 -> 0 | Y33: ='24'!K33 -> 0 | Z33: ='25'!K33 -> 0 | AA33: ='26'!K33 -> 0 | AB33: ='27'!K33 -> 0 | AC33: ='28'!K33 -> 0 | AD33: ='29'!K33 -> 0 | AE33: ='30'!K33 -> 0 | AG33: =AE33-D33 -> 0 | AH33: =AVERAGE(D33:AE33) -> 0
B34: - Telur Ayam Broiler | C34: Kg | D34: ='1'!K34 -> 28642.857 | E34: ='2'!K34 -> 28500 | F34: ='3'!K34 -> 27428.571 | G34: ='4'!K34 -> 27142.857 | H34: ='5'!K34 -> 27142.857 | I34: ='6'!K34 -> 27142.857 | J34: ='7'!K34 -> 27142.857 | K34: ='8'!K34 -> 26928.571 | L34: ='9'!K34 -> 26785.714 | M34: ='10'!K34 -> 26928.571 | N34: ='11'!K34 -> 26642.857 | O34: ='12'!K34 -> 26642.857 | P34: ='13'!K34 -> 26642.857 | Q34: ='14'!K34 -> 26357.143 | R34: ='15'!K34 -> 26214.286 | S34: ='16'!K34 -> 26357.143 | T34: ='17'!K34 -> 26500 | U34: ='18'!K34 -> 26357.143 | V34: ='19'!K34 -> 26571.429 | W34: ='20'!K34 -> 26857.143 | X34: ='21'!K34 -> 27428.571 | Y34: ='24'!K34 -> 27428.571 | Z34: ='25'!K34 -> 27428.571 | AA34: ='26'!K34 -> 27285.714 | AB34: ='27'!K34 -> 27142.857 | AC34: ='28'!K34 -> 26857.143 | AD34: ='29'!K34 -> 27142.857 | AE34: ='30'!K34 -> 27142.857 | AF34: 27000 | AG34: =AE34-D34 -> -1500 | AH34: =AVERAGE(D34:AE34) -> 27028.061
B35: - Telur Ayam Kampung | C35: Butir | D35: ='1'!K35 -> 2500 | E35: ='2'!K35 -> 2500 | F35: ='3'!K35 -> 2500 | G35: ='4'!K35 -> 2528.5714 | H35: ='5'!K35 -> 2485.7143 | I35: ='6'!K35 -> 2485.7143 | J35: ='7'!K35 -> 2414.2857 | K35: ='8'!K35 -> 2414.2857 | L35: ='9'!K35 -> 2414.2857 | M35: ='10'!K35 -> 2414.2857 | N35: ='11'!K35 -> 2414.2857 | O35: ='12'!K35 -> 2385.7143 | P35: ='13'!K35 -> 2385.7143 | Q35: ='14'!K35 -> 2385.7143 | R35: ='15'!K35 -> 2385.7143 | S35: ='16'!K35 -> 2385.7143 | T35: ='17'!K35 -> 2414.2857 | U35: ='18'!K35 -> 2414.2857 | V35: ='19'!K35 -> 2485.7143 | W35: ='20'!K35 -> 2414.2857 | X35: ='21'!K35 -> 2414.2857 | Y35: ='24'!K35 -> 2414.2857 | Z35: ='25'!K35 -> 2414.2857 | AA35: ='26'!K35 -> 2414.2857 | AB35: ='27'!K35 -> 2385.7143 | AC35: ='28'!K35 -> 2385.7143 | AD35: ='29'!K35 -> 2385.7143 | AE35: ='30'!K35 -> 2385.7143 | AG35: =AE35-D35 -> -114.28571 | AH35: =AVERAGE(D35:AE35) -> 2426.0204
A36: 8 | B36: TAHU | D36: ='1'!K36 -> 0 | E36: ='2'!K36 -> 0 | F36: ='3'!K36 -> 0 | G36: ='4'!K36 -> 0 | H36: ='5'!K36 -> 0 | I36: ='6'!K36 -> 0 | J36: ='7'!K36 -> 0 | K36: ='8'!K36 -> 0 | L36: ='9'!K36 -> 0 | M36: ='10'!K36 -> 0 | N36: ='11'!K36 -> 0 | O36: ='12'!K36 -> 0 | P36: ='13'!K36 -> 0 | Q36: ='14'!K36 -> 0 | R36: ='15'!K36 -> 0 | S36: ='16'!K36 -> 0 | T36: ='17'!K36 -> 0 | U36: ='18'!K36 -> 0 | V36: ='19'!K36 -> 0 | W36: ='20'!K36 -> 0 | X36: ='21'!K36 -> 0 | Y36: ='24'!K36 -> 0 | Z36: ='25'!K36 -> 0 | AA36: ='26'!K36 -> 0 | AB36: ='27'!K36 -> 0 | AC36: ='28'!K36 -> 0 | AD36: ='29'!K36 -> 0 | AE36: ='30'!K36 -> 0 | AG36: =AE36-D36 -> 0 | AH36: =AVERAGE(D36:AE36) -> 0
B37: - Tahu biasa | C37: Kg | D37: ='1'!K37 -> 11142.857 | E37: ='2'!K37 -> 11142.857 | F37: ='3'!K37 -> 11142.857 | G37: ='4'!K37 -> 11142.857 | H37: ='5'!K37 -> 11142.857 | I37: ='6'!K37 -> 11142.857 | J37: ='7'!K37 -> 11142.857 | K37: ='8'!K37 -> 11142.857 | L37: ='9'!K37 -> 11142.857 | M37: ='10'!K37 -> 11142.857 | N37: ='11'!K37 -> 11142.857 | O37: ='12'!K37 -> 11142.857 | P37: ='13'!K37 -> 11142.857 | Q37: ='14'!K37 -> 11142.857 | R37: ='15'!K37 -> 11142.857 | S37: ='16'!K37 -> 11142.857 | T37: ='17'!K37 -> 11142.857 | U37: ='18'!K37 -> 11142.857 | V37: ='19'!K37 -> 11142.857 | W37: ='20'!K37 -> 11142.857 | X37: ='21'!K37 -> 11142.857 | Y37: ='24'!K37 -> 11142.857 | Z37: ='25'!K37 -> 11571.429 | AA37: ='26'!K37 -> 11357.143 | AB37: ='27'!K37 -> 11357.143 | AC37: ='28'!K37 -> 10714.286 | AD37: ='29'!K37 -> 11142.857 | AE37: ='30'!K37 -> 11142.857 | AG37: =AE37-D37 -> 0 | AH37: =AVERAGE(D37:AE37) -> 11158.163
B38: - Tahu susu | C38: Kg | D38: ='1'!K38 -> 12200 | E38: ='2'!K38 -> 12200 | F38: ='3'!K38 -> 12200 | G38: ='4'!K38 -> 12200 | H38: ='5'!K38 -> 12200 | I38: ='6'!K38 -> 12200 | J38: ='7'!K38 -> 12200 | K38: ='8'!K38 -> 12200 | L38: ='9'!K38 -> 12200 | M38: ='10'!K38 -> 12200 | N38: ='11'!K38 -> 12200 | O38: ='12'!K38 -> 12200 | P38: ='13'!K38 -> 12200 | Q38: ='14'!K38 -> 12200 | R38: ='15'!K38 -> 12200 | S38: ='16'!K38 -> 12200 | T38: ='17'!K38 -> 12200 | U38: ='18'!K38 -> 12200 | V38: ='19'!K38 -> 12200 | W38: ='20'!K38 -> 12200 | X38: ='21'!K38 -> 12200 | Y38: ='24'!K38 -> 12200 | Z38: ='25'!K38 -> 12400 | AA38: ='26'!K38 -> 12200 | AB38: ='27'!K38 -> 12200 | AC38: ='28'!K38 -> 12200 | AD38: ='29'!K38 -> 12400 | AE38: ='30'!K38 -> 12400 | AG38: =AE38-D38 -> 200 | AH38: =AVERAGE(D38:AE38) -> 12221.429
A39: 9 | B39: TEMPE | D39: ='1'!K39 -> 0 | E39: ='2'!K39 -> 0 | F39: ='3'!K39 -> 0 | G39: ='4'!K39 -> 0 | H39: ='5'!K39 -> 0 | I39: ='6'!K39 -> 0 | J39: ='7'!K39 -> 0 | K39: ='8'!K39 -> 0 | L39: ='9'!K39 -> 0 | M39: ='10'!K39 -> 0 | N39: ='11'!K39 -> 0 | O39: ='12'!K39 -> 0 | P39: ='13'!K39 -> 0 | Q39: ='14'!K39 -> 0 | R39: ='15'!K39 -> 0 | S39: ='16'!K39 -> 0 | T39: ='17'!K39 -> 0 | U39: ='18'!K39 -> 0 | V39: ='19'!K39 -> 0 | W39: ='20'!K39 -> 0 | X39: ='21'!K39 -> 0 | Y39: ='24'!K39 -> 0 | Z39: ='25'!K39 -> 0 | AA39: ='26'!K39 -> 0 | AB39: ='27'!K39 -> 0 | AC39: ='28'!K39 -> 0 | AD39: ='29'!K39 -> 0 | AE39: ='30'!K39 -> 0 | AG39: =AE39-D39 -> 0 | AH39: =AVERAGE(D39:AE39) -> 0
B40: - Tempe Kw I (campuran kedelai) | C40: Kg | D40: ='1'!K40 -> 15600 | E40: ='2'!K40 -> 15600 | F40: ='3'!K40 -> 15600 | G40: ='4'!K40 -> 15600 | H40: ='5'!K40 -> 15600 | I40: ='6'!K40 -> 15600 | J40: ='7'!K40 -> 15600 | K40: ='8'!K40 -> 15600 | L40: ='9'!K40 -> 15600 | M40: ='10'!K40 -> 15600 | N40: ='11'!K40 -> 15600 | O40: ='12'!K40 -> 15600 | P40: ='13'!K40 -> 15600 | Q40: ='14'!K40 -> 15600 | R40: ='15'!K40 -> 15600 | S40: ='16'!K40 -> 15600 | T40: ='17'!K40 -> 15600 | U40: ='18'!K40 -> 15600 | V40: ='19'!K40 -> 15600 | W40: ='20'!K40 -> 15600 | X40: ='21'!K40 -> 15600 | Y40: ='24'!K40 -> 15600 | Z40: ='25'!K40 -> 15600 | AA40: ='26'!K40 -> 15600 | AB40: ='27'!K40 -> 15600 | AC40: ='28'!K40 -> 15600 | AD40: ='29'!K40 -> 15600 | AE40: ='30'!K40 -> 15600 | AG40: =AE40-D40 -> 0 | AH40: =AVERAGE(D40:AE40) -> 15600
B41: - Tempe Kw II (campuran jagung) | C41: Kg | D41: ='1'!K41 -> 6833.3333 | E41: ='2'!K41 -> 6833.3333 | F41: ='3'!K41 -> 6833.3333 | G41: ='4'!K41 -> 6833.3333 | H41: ='5'!K41 -> 6833.3333 | I41: ='6'!K41 -> 6833.3333 | J41: ='7'!K41 -> 6833.3333 | K41: ='8'!K41 -> 6833.3333 | L41: ='9'!K41 -> 6833.3333 | M41: ='10'!K41 -> 6833.3333 | N41: ='11'!K41 -> 6833.3333 | O41: ='12'!K41 -> 6833.3333 | P41: ='13'!K41 -> 6833.3333 | Q41: ='14'!K41 -> 6833.3333 | R41: ='15'!K41 -> 6833.3333 | S41: ='16'!K41 -> 6833.3333 | T41: ='17'!K41 -> 6833.3333 | U41: ='18'!K41 -> 6833.3333 | V41: ='19'!K41 -> 6833.3333 | W41: ='20'!K41 -> 6833.3333 | X41: ='21'!K41 -> 6833.3333 | Y41: ='24'!K41 -> 6833.3333 | Z41: ='25'!K41 -> 6833.3333 | AA41: ='26'!K41 -> 6833.3333 | AB41: ='27'!K41 -> 6833.3333 | AC41: ='28'!K41 -> 6833.3333 | AD41: ='29'!K41 -> 6833.3333 | AE41: ='30'!K41 -> 6833.3333 | AG41: =AE41-D41 -> 0 | AH41: =AVERAGE(D41:AE41) -> 6833.3333
...

Sheet 1
A1: HARGA BAHAN-BAHAN POKOK
A2: DI PASAR TRADISIONAL KOTA SURABAYA
A3: HARI / TANGGAL : Sabtu / 01 April 2023
B4: NAMA BAHAN POKOK DAN PENTING LAINNYA | C4: SATUAN | D4: Pasar Tambahrejo | E4: Pasar Pucang Anom | F4: Pasar Wonokromo | G4: Pasar Genteng Baru | H4: Pasar Pabean | I4: Pasar Kembang | J4: Pasar Balongsari | K4: Rata-Rata
A7: 1 | B7: BERAS
B8: - Beras Premium | C8: Kg | D8: 13000 | E8: 13000 | F8: 14000 | G8: 13500 | H8: 13000 | I8: 14000 | J8: 13500 | K8: =AVERAGE(D8:J8) -> 13428.571
B9: - Beras Medium Bulog | C9: Kg | D9: - | E9: 9400 | F9: 12000 | G9: 9000 | H9: 9000 | I9: 9000 | J9: 9000 | K9: =AVERAGE(D9:J9) -> 9566.6667
B10: - Beras Medium | C10: Kg | D10: 11000 | E10: 11000 | F10: - | G10: 11500 | H10: - | I10: - | J10: - | K10: =AVERAGE(D10:J10) -> 11166.667
B11: - Beras Jagung | C11: Kg | D11: - | E11: 10000 | F11: 12000 | G11: 12000 | H11: - | I11: 11000 | J11: 8000 | K11: =AVERAGE(D11:J11) -> 10600
B12: - Beras Ketan (Jenis Siyem) | C12: Kg | D12: - | E12: 22000 | F12: 24000 | G12: 20000 | H12: - | I12: 22000 | J12: 17000 | K12: =AVERAGE(D12:J12) -> 21000
A13: 2 | B13: GULA
B14: - Gula pasir lokal curah | C14: Kg | D14: 13000 | E14: 13000 | F14: 13500 | G14: 13000 | H14: 13000 | I14: 13000 | J14: 13500 | K14: =AVERAGE(D14:J14) -> 13142.857
B15: - Gula Jawa/Merah (Bahan Kelapa) | C15: Kg | D15: 15000 | E15: 16000 | F15: 16000 | G15: 16000 | H15: 15000 | I15: 16000 | J15: 16000 | K15: =AVERAGE(D15:J15) -> 15714.286
A16: 3 | B16: MINYAK GORENG
B17: - Minyak Goreng Curah (Bening) | C17: Kg | D17: 16000 | E17: 16000 | F17: 17000 | G17: 16000 | H17: 14000 | I17: 16000 | J17: 15500 | K17: =AVERAGE(D17:J17) -> 15785.714
B18: - Minyak Kita | C18: Liter | D18: 14000 | E18: 14000 | F18: 14000 | G18: 14000 | H18: - | I18: 14000 | J18: 14000 | K18: =AVERAGE(D18:J18) -> 14000
A19: 4 | B19: MENTEGA
B20: - Mentega Curah (Amanda) | C20: Kg | D20: 20000 | E20: - | F20: 19000 | G20: 22000 | H20: - | I20: 24000 | J20: - | K20: =AVERAGE(D20:J20) -> 21250
A21: 5 | B21: DAGING
B22: - Daging Sapi Grade Atas | C22: Kg | D22: 120000 | E22: 120000 | F22: 120000 | G22: 120000 | H22: 120000 | I22: 120000 | J22: 110000 | K22: =AVERAGE(D22:J22) -> 118571.43
B23: - Daging Sapi Grade Sedang | C23: Kg | D23: 110000 | E23: 110000 | F23: 110000 | G23: 110000 | H23: 114000 | I23: 110000 | J23: 100000 | K23: =AVERAGE(D23:J23) -> 109142.86
B24: - Daging Sapi Grade Bawah | C24: Kg | D24: 100000 | E24: 95000 | F24: 100000 | G24: 100000 | H24: 100000 | I24: 100000 | J24: - | K24: =AVERAGE(D24:J24) -> 99166.667
B25: - Daging Ayam Broiler | C25: Kg | D25: 30000 | E25: 30000 | F25: 30000 | G25: 30000 | H25: 32000 | I25: 30000 | J25: 32000 | K25: =AVERAGE(D25:J25) -> 30571.429
A26: 6 | B26: I K A N
B27: - Ikan Tongkol Segar (Uk. Sedang) | C27: Kg | D27: 38000 | E27: 38000 | F27: - | G27: 45000 | H27: 30000 | I27: 38000 | J27: 35000 | K27: =AVERAGE(D27:J27) -> 37333.333
B28: - Ikan Mujair Segar (Uk. Sedang) | C28: Kg | D28: 28000 | E28: 30000 | F28: 30000 | G28: 35000 | H28: 23000 | I28: 30000 | J28: 26000 | K28: =AVERAGE(D28:J28) -> 28857.143
B29: - Udang Segar (Uk. Sedang) | C29: Kg | D29: 60000 | E29: 70000 | F29: 70000 | G29: 75000 | H29: 58000 | I29: 65000 | J29: 50000 | K29: =AVERAGE(D29:J29) -> 64000
B30: - Ikan Lele Segar (Ukuran Sedang) | C30: Kg | D30: 25000 | E30: - | F30: - | G30: 25000 | H30: 23000 | I30: 24000 | J30: 26000 | K30: =AVERAGE(D30:J30) -> 24600
B31: - Ikan Bandeng Segar (Uk. Sedang) | C31: Kg | D31: 45000 | E31: 36000 | F31: 40000 | G31: 45000 | H31: 28000 | I31: 38000 | J31: 40000 | K31: =AVERAGE(D31:J31) -> 38857.143
B32: - Ikan Teri Asin (Bukan Teri Medan) | C32: Kg | D32: - | E32: 100000 | F32: 110000 | G32: - | H32: 80000 | I32: - | J32: - | K32: =AVERAGE(D32:J32) -> 96666.667
A33: 7 | B33: TELUR
B34: - Telur Ayam Broiler | C34: Kg | D34: 29000 | E34: 28000 | F34: 29000 | G34: 29000 | H34: 28000 | I34: 29000 | J34: 28500 | K34: =AVERAGE(D34:J34) -> 28642.857
B35: - Telur Ayam Kampung | C35: Butir | D35: 3000 | E35: 2000 | F35: 2500 | G35: 2500 | H35: 2000 | I35: 2500 | J35: 3000 | K35: =AVERAGE(D35:J35) -> 2500
A36: 8 | B36: TAHU
B37: - Tahu biasa | C37: Kg | D37: 10000 | E37: 10000 | F37: 9000 | G37: 9000 | H37: 16000 | I37: 15000 | J37: 9000 | K37: =AVERAGE(D37:J37) -> 11142.857
B38: - Tahu susu | C38: Kg | D38: - | E38: 7000 | F38: 12000 | G38: 17000 | H38: - | I38: 13000 | J38: 12000 | K38: =AVERAGE(D38:J38) -> 12200
A39: 9 | B39: TEMPE
B40: - Tempe Kw I (campuran kedelai) | C40: Kg | D40: - | E40: 18000 | F40: - | G40: 16000 | H40: 14000 | I40: 15000 | J40: 15000 | K40: =AVERAGE(D40:J40) -> 15600
B41: - Tempe Kw II (campuran jagung) | C41: Kg | D41: 2500 | E41: 12000 | F41: 6000 | G41: - | H41: - | I41: - | J41: - | K41: =AVERAGE(D41:J41) -> 6833.3333
B42: - Tempe Kw III (campuran kulit) | C42: Kg | D42: - | E42: 2000 | F42: - | G42: - | H42: - | I42: - | J42: - | K42: =AVERAGE(D42:J42) -> 2000
...

Sheet 2
A1: HARGA BAHAN-BAHAN POKOK
A2: DI PASAR TRADISIONAL KOTA SURABAYA
A3: HARI / TANGGAL : Minggu / 02 April 2023
B4: NAMA BAHAN POKOK DAN PENTING LAINNYA | C4: SATUAN | D4: Pasar Tambahrejo | E4: Pasar Pucang Anom | F4: Pasar Wonokromo | G4: Pasar Genteng Baru | H4: Pasar Pabean | I4: Pasar Kembang | J4: Pasar Balongsari | K4: Rata-Rata
A7: 1 | B7: BERAS
B8: - Beras Premium | C8: Kg | D8: 13000 | E8: 13000 | F8: 14000 | G8: 13500 | H8: 13500 | I8: 14000 | J8: 13500 | K8: =AVERAGE(D8:J8) -> 13500
B9: - Beras Medium Bulog | C9: Kg | D9: - | E9: 9400 | F9: 12000 | G9: 9000 | H9: 9000 | I9: 9000 | J9: 9000 | K9: =AVERAGE(D9:J9) -> 9566.6667
B10: - Beras Medium | C10: Kg | D10: 11000 | E10: 11000 | F10: - | G10: 11500 | H10: - | I10: - | J10: - | K10: =AVERAGE(D10:J10) -> 11166.667
B11: - Beras Jagung | C11: Kg | D11: - | E11: 10000 | F11: 12000 | G11: 12000 | H11: - | I11: 11000 | J11: 8000 | K11: =AVERAGE(D11:J11) -> 10600
B12: - Beras Ketan (Jenis Siyem) | C12: Kg | D12: - | E12: 22000 | F12: 24000 | G12: 20000 | H12: - | I12: 22000 | J12: 17000 | K12: =AVERAGE(D12:J12) -> 21000
A13: 2 | B13: GULA
B14: - Gula pasir lokal curah | C14: Kg | D14: 13000 | E14: 13000 | F14: 13500 | G14: 13000 | H14: 13000 | I14: 13000 | J14: 13500 | K14: =AVERAGE(D14:J14) -> 13142.857
B15: - Gula Jawa/Merah (Bahan Kelapa) | C15: Kg | D15: 15000 | E15: 16000 | F15: 16000 | G15: 16000 | H15: 15000 | I15: 16000 | J15: 16000 | K15: =AVERAGE(D15:J15) -> 15714.286
A16: 3 | B16: MINYAK GORENG
B17: - Minyak Goreng Curah (Bening) | C17: Kg | D17: 16000 | E17: 16000 | F17: 17000 | G17: 16000 | H17: 14000 | I17: 16000 | J17: 15500 | K17: =AVERAGE(D17:J17) -> 15785.714
B18: - Minyak Kita | C18: Liter | D18: 14000 | E18: 14000 | F18: 14000 | G18: 14000 | H18: - | I18: 14000 | J18: 14000 | K18: =AVERAGE(D18:J18) -> 14000
A19: 4 | B19: MENTEGA
B20: - Mentega Curah (Amanda) | C20: Kg | D20: 20000 | E20: - | F20: 19000 | G20: 22000 | H20: - | I20: 24000 | J20: - | K20: =AVERAGE(D20:J20) -> 21250
A21: 5 | B21: DAGING
B22: - Daging Sapi Grade Atas | C22: Kg | D22: 120000 | E22: 120000 | F22: 120000 | G22: 120000 | H22: 120000 | I22: 120000 | J22: 110000 | K22: =AVERAGE(D22:J22) -> 118571.43
B23: - Daging Sapi Grade Sedang | C23: Kg | D23: 110000 | E23: 110000 | F23: 110000 | G23: 110000 | H23: 114000 | I23: 110000 | J23: 100000 | K23: =AVERAGE(D23:J23) -> 109142.86
B24: - Daging Sapi Grade Bawah | C24: Kg | D24: 100000 | E24: 95000 | F24: 100000 | G24: 100000 | H24: 100000 | I24: 100000 | J24: - | K24: =AVERAGE(D24:J24) -> 99166.667
B25: - Daging Ayam Broiler | C25: Kg | D25: 30000 | E25: 30000 | F25: 31000 | G25: 30000 | H25: 32000 | I25: 30000 | J25: 32000 | K25: =AVERAGE(D25:J25) -> 30714.286
A26: 6 | B26: I K A N
B27: - Ikan Tongkol Segar (Uk. Sedang) | C27: Kg | D27: 38000 | E27: 38000 | F27: - | G27: 45000 | H27: 30000 | I27: 38000 | J27: 35000 | K27: =AVERAGE(D27:J27) -> 37333.333
B28: - Ikan Mujair Segar (Uk. Sedang) | C28: Kg | D28: 28000 | E28: 30000 | F28: 35000 | G28: 35000 | H28: 23000 | I28: 30000 | J28: 26000 | K28: =AVERAGE(D28:J28) -> 29571.429
B29: - Udang Segar (Uk. Sedang) | C29: Kg | D29: 60000 | E29: 70000 | F29: 70000 | G29: 75000 | H29: 58000 | I29: 65000 | J29: 50000 | K29: =AVERAGE(D29:J29) -> 64000
B30: - Ikan Lele Segar (Ukuran Sedang) | C30: Kg | D30: 25000 | E30: - | F30: - | G30: 25000 | H30: 23000 | I30: 24000 | J30: 26000 | K30: =AVERAGE(D30:J30) -> 24600
B31: - Ikan Bandeng Segar (Uk. Sedang) | C31: Kg | D31: 45000 | E31: 36000 | F31: 40000 | G31: 45000 | H31: 28000 | I31: 38000 | J31: 40000 | K31: =AVERAGE(D31:J31) -> 38857.143
B32: - Ikan Teri Asin (Bukan Teri Medan) | C32: Kg | D32: - | E32: 100000 | F32: 110000 | G32: - | H32: 80000 | I32: - | J32: - | K32: =AVERAGE(D32:J32) -> 96666.667
A33: 7 | B33: TELUR
B34: - Telur Ayam Broiler | C34: Kg | D34: 29000 | E34: 28000 | F34: 28000 | G34: 29000 | H34: 28000 | I34: 29000 | J34: 28500 | K34: =AVERAGE(D34:J34) -> 28500
B35: - Telur Ayam Kampung | C35: Butir | D35: 3000 | E35: 2000 | F35: 2500 | G35: 2500 | H35: 2000 | I35: 2500 | J35: 3000 | K35: =AVERAGE(D35:J35) -> 2500
A36: 8 | B36: TAHU
B37: - Tahu biasa | C37: Kg | D37: 10000 | E37: 10000 | F37: 9000 | G37: 9000 | H37: 16000 | I37: 15000 | J37: 9000 | K37: =AVERAGE(D37:J37) -> 11142.857
B38: - Tahu susu | C38: Kg | D38: - | E38: 7000 | F38: 12000 | G38: 17000 | H38: - | I38: 13000 | J38: 12000 | K38: =AVERAGE(D38:J38) -> 12200
A39: 9 | B39: TEMPE
B40: - Tempe Kw I (campuran kedelai) | C40: Kg | D40: - | E40: 18000 | F40: - | G40: 16000 | H40: 14000 | I40: 15000 | J40: 15000 | K40: =AVERAGE(D40:J40) -> 15600
B41: - Tempe Kw II (campuran jagung) | C41: Kg | D41: 2500 | E41: 12000 | F41: 6000 | G41: - | H41: - | I41: - | J41: - | K41: =AVERAGE(D41:J41) -> 6833.3333
B42: - Tempe Kw III (campuran kulit) | C42: Kg | D42: - | E42: 2000 | F42: - | G42: - | H42: - | I42: - | J42: - | K42: =AVERAGE(D42:J42) -> 2000
...

Sheet 3
A1: HARGA BAHAN-BAHAN POKOK
A2: DI PASAR TRADISIONAL KOTA SURABAYA
A3: HARI / TANGGAL : Senin / 03 April 2023
B4: NAMA BAHAN POKOK DAN PENTING LAINNYA | C4: SATUAN | D4: Pasar Tambahrejo | E4: Pasar Pucang Anom | F4: Pasar Wonokromo | G4: Pasar Genteng Baru | H4: Pasar Pabean | I4: Pasar Kembang | J4: Pasar Balongsari | K4: Rata-Rata
A7: 1 | B7: BERAS
B8: - Beras Premium | C8: Kg | D8: 13000 | E8: 13500 | F8: 14000 | G8: 13500 | H8: 13000 | I8: 14000 | J8: 13500 | K8: =AVERAGE(D8:J8) -> 13500
B9: - Beras Medium Bulog | C9: Kg | D9: - | E9: 9400 | F9: 12000 | G9: 9000 | H9: 9000 | I9: 9000 | J9: 9000 | K9: =AVERAGE(D9:J9) -> 9566.6667
B10: - Beras Medium | C10: Kg | D10: 11000 | E10: 11500 | F10: - | G10: 11500 | H10: - | I10: - | J10: - | K10: =AVERAGE(D10:J10) -> 11333.333
B11: - Beras Jagung | C11: Kg | D11: - | E11: 10000 | F11: 12000 | G11: 12000 | H11: - | I11: 11000 | J11: 8000 | K11: =AVERAGE(D11:J11) -> 10600
B12: - Beras Ketan (Jenis Siyem) | C12: Kg | D12: - | E12: 22000 | F12: 24000 | G12: 20000 | H12: - | I12: 22000 | J12: 17000 | K12: =AVERAGE(D12:J12) -> 21000
A13: 2 | B13: GULA
B14: - Gula pasir lokal curah | C14: Kg | D14: 13000 | E14: 13000 | F14: 13500 | G14: 13000 | H14: 13000 | I14: 13000 | J14: 13500 | K14: =AVERAGE(D14:J14) -> 13142.857
B15: - Gula Jawa/Merah (Bahan Kelapa) | C15: Kg | D15: 15000 | E15: 16000 | F15: 16000 | G15: 16000 | H15: 15000 | I15: 16000 | J15: 16000 | K15: =AVERAGE(D15:J15) -> 15714.286
A16: 3 | B16: MINYAK GORENG
B17: - Minyak Goreng Curah (Bening) | C17: Kg | D17: 15000 | E17: 16000 | F17: 17000 | G17: 16000 | H17: 14000 | I17: 16000 | J17: 15500 | K17: =AVERAGE(D17:J17) -> 15642.857
B18: - Minyak Kita | C18: Liter | D18: 14000 | E18: 14000 | F18: 14000 | G18: 14000 | H18: - | I18: 14000 | J18: 14000 | K18: =AVERAGE(D18:J18) -> 14000
A19: 4 | B19: MENTEGA
B20: - Mentega Curah (Amanda) | C20: Kg | D20: 20000 | E20: - | F20: 19000 | G20: 22000 | H20: - | I20: 24000 | J20: - | K20: =AVERAGE(D20:J20) -> 21250
A21: 5 | B21: DAGING
B22: - Daging Sapi Grade Atas | C22: Kg | D22: 120000 | E22: 120000 | F22: 120000 | G22: 120000 | H22: 120000 | I22: 120000 | J22: 110000 | K22: =AVERAGE(D22:J22) -> 118571.43
B23: - Daging Sapi Grade Sedang | C23: Kg | D23: 110000 | E23: 110000 | F23: 110000 | G23: 110000 | H23: 114000 | I23: 110000 | J23: 100000 | K23: =AVERAGE(D23:J23) -> 109142.86
B24: - Daging Sapi Grade Bawah | C24: Kg | D24: 100000 | E24: 95000 | F24: 100000 | G24: 100000 | H24: 100000 | I24: 100000 | J24: - | K24: =AVERAGE(D24:J24) -> 99166.667
B25: - Daging Ayam Broiler | C25: Kg | D25: 32000 | E25: 30000 | F25: 32000 | G25: 30000 | H25: 32000 | I25: 30000 | J25: 32000 | K25: =AVERAGE(D25:J25) -> 31142.857
A26: 6 | B26: I K A N
B27: - Ikan Tongkol Segar (Uk. Sedang) | C27: Kg | D27: 35000 | E27: 38000 | F27: - | G27: 45000 | H27: 30000 | I27: 38000 | J27: 35000 | K27: =AVERAGE(D27:J27) -> 36833.333
B28: - Ikan Mujair Segar (Uk. Sedang) | C28: Kg | D28: 30000 | E28: 30000 | F28: 30000 | G28: 35000 | H28: 23000 | I28: 30000 | J28: 26000 | K28: =AVERAGE(D28:J28) -> 29142.857
B29: - Udang Segar (Uk. Sedang) | C29: Kg | D29: 65000 | E29: 70000 | F29: 70000 | G29: 75000 | H29: 58000 | I29: 70000 | J29: 50000 | K29: =AVERAGE(D29:J29) -> 65428.571
B30: - Ikan Lele Segar (Ukuran Sedang) | C30: Kg | D30: 25000 | E30: - | F30: - | G30: 25000 | H30: 23000 | I30: 24000 | J30: 26000 | K30: =AVERAGE(D30:J30) -> 24600
B31: - Ikan Bandeng Segar (Uk. Sedang) | C31: Kg | D31: 45000 | E31: 36000 | F31: 40000 | G31: 45000 | H31: 28000 | I31: 38000 | J31: 40000 | K31: =AVERAGE(D31:J31) -> 38857.143
B32: - Ikan Teri Asin (Bukan Teri Medan) | C32: Kg | D32: - | E32: 100000 | F32: 110000 | G32: - | H32: 80000 | I32: - | J32: - | K32: =AVERAGE(D32:J32) -> 96666.667
A33: 7 | B33: TELUR
B34: - Telur Ayam Broiler | C34: Kg | D34: 27000 | E34: 28000 | F34: 29000 | G34: 27000 | H34: 27000 | I34: 27000 | J34: 27000 | K34: =AVERAGE(D34:J34) -> 27428.571
B35: - Telur Ayam Kampung | C35: Butir | D35: 3000 | E35: 2000 | F35: 2500 | G35: 2500 | H35: 2000 | I35: 2500 | J35: 3000 | K35: =AVERAGE(D35:J35) -> 2500
A36: 8 | B36: TAHU
B37: - Tahu biasa | C37: Kg | D37: 10000 | E37: 10000 | F37: 9000 | G37: 9000 | H37: 16000 | I37: 15000 | J37: 9000 | K37: =AVERAGE(D37:J37) -> 11142.857
B38: - Tahu susu | C38: Kg | D38: - | E38: 7000 | F38: 12000 | G38: 17000 | H38: - | I38: 13000 | J38: 12000 | K38: =AVERAGE(D38:J38) -> 12200
A39: 9 | B39: TEMPE
B40: - Tempe Kw I (campuran kedelai) | C40: Kg | D40: - | E40: 18000 | F40: - | G40: 16000 | H40: 14000 | I40: 15000 | J40: 15000 | K40: =AVERAGE(D40:J40) -> 15600
B41: - Tempe Kw II (campuran jagung) | C41: Kg | D41: 2500 | E41: 12000 | F41: 6000 | G41: - | H41: - | I41: - | J41: - | K41: =AVERAGE(D41:J41) -> 6833.3333
B42: - Tempe Kw III (campuran kulit) | C42: Kg | D42: - | E42: 2000 | F42: - | G42: - | H42: - | I42: - | J42: - | K42: =AVERAGE(D42:J42) -> 2000
...

Sheet 4
A1: HARGA BAHAN-BAHAN POKOK
A2: DI PASAR TRADISIONAL KOTA SURABAYA
A3: HARI / TANGGAL : Selasa / 04 April 2023
B4: NAMA BAHAN POKOK DAN PENTING LAINNYA | C4: SATUAN | D4: Pasar Tambahrejo | E4: Pasar Pucang Anom | F4: Pasar Wonokromo | G4: Pasar Genteng Baru | H4: Pasar Pabean | I4: Pasar Kembang | J4: Pasar Balongsari | K4: Rata-Rata
A7: 1 | B7: BERAS
B8: - Beras Premium | C8: Kg | D8: 13000 | E8: 13500 | F8: 14000 | G8: 13500 | H8: 13000 | I8: 14000 | J8: 13500 | K8: =AVERAGE(D8:J8) -> 13500
B9: - Beras Medium Bulog | C9: Kg | D9: - | E9: - | F9: 12000 | G9: - | H9: 9000 | I9: 9000 | J9: 9000 | K9: =AVERAGE(D9:J9) -> 9750
B10: - Beras Medium | C10: Kg | D10: 11000 | E10: 11500 | F10: - | G10: 11500 | H10: - | I10: - | J10: - | K10: =AVERAGE(D10:J10) -> 11333.333
B11: - Beras Jagung | C11: Kg | D11: - | E11: 10000 | F11: 12000 | G11: 12000 | H11: - | I11: 11000 | J11: 8000 | K11: =AVERAGE(D11:J11) -> 10600
B12: - Beras Ketan (Jenis Siyem) | C12: Kg | D12: - | E12: 22000 | F12: 24000 | G12: 20000 | H12: - | I12: 22000 | J12: 17000 | K12: =AVERAGE(D12:J12) -> 21000
A13: 2 | B13: GULA
B14: - Gula pasir lokal curah | C14: Kg | D14: 13000 | E14: 13000 | F14: 13500 | G14: 13000 | H14: 13000 | I14: 13000 | J14: 13500 | K14: =AVERAGE(D14:J14) -> 13142.857
B15: - Gula Jawa/Merah (Bahan Kelapa) | C15: Kg | D15: 15000 | E15: 16000 | F15: 16000 | G15: 16000 | H15: 15000 | I15: 16000 | J15: 16000 | K15: =AVERAGE(D15:J15) -> 15714.286
A16: 3 | B16: MINYAK GORENG
B17: - Minyak Goreng Curah (Bening) | C17: Kg | D17: 15000 | E17: 16000 | F17: 16000 | G17: 16000 | H17: 14000 | I17: 16000 | J17: 15500 | K17: =AVERAGE(D17:J17) -> 15500
B18: - Minyak Kita | C18: Liter | D18: 14000 | E18: 14000 | F18: 14000 | G18: 14000 | H18: - | I18: 14000 | J18: 14000 | K18: =AVERAGE(D18:J18) -> 14000
A19: 4 | B19: MENTEGA
B20: - Mentega Curah (Amanda) | C20: Kg | D20: 20000 | E20: - | F20: 19000 | G20: 22000 | H20: - | I20: 24000 | J20: - | K20: =AVERAGE(D20:J20) -> 21250
A21: 5 | B21: DAGING
B22: - Daging Sapi Grade Atas | C22: Kg | D22: 120000 | E22: 120000 | F22: 120000 | G22: 120000 | H22: 120000 | I22: 120000 | J22: 110000 | K22: =AVERAGE(D22:J22) -> 118571.43
B23: - Daging Sapi Grade Sedang | C23: Kg | D23: 110000 | E23: 110000 | F23: 110000 | G23: 110000 | H23: 114000 | I23: 110000 | J23: 100000 | K23: =AVERAGE(D23:J23) -> 109142.86
B24: - Daging Sapi Grade Bawah | C24: Kg | D24: 100000 | E24: 95000 | F24: 100000 | G24: 100000 | H24: 100000 | I24: 100000 | J24: - | K24: =AVERAGE(D24:J24) -> 99166.667
B25: - Daging Ayam Broiler | C25: Kg | D25: 32000 | E25: 30000 | F25: 32000 | G25: 30000 | H25: 32000 | I25: 30000 | J25: 32000 | K25: =AVERAGE(D25:J25) -> 31142.857
A26: 6 | B26: I K A N
B27: - Ikan Tongkol Segar (Uk. Sedang) | C27: Kg | D27: 35000 | E27: 38000 | F27: - | G27: 45000 | H27: 30000 | I27: 38000 | J27: 35000 | K27: =AVERAGE(D27:J27) -> 36833.333
B28: - Ikan Mujair Segar (Uk. Sedang) | C28: Kg | D28: 30000 | E28: 30000 | F28: 30000 | G28: 35000 | H28: 23000 | I28: 30000 | J28: 26000 | K28: =AVERAGE(D28:J28) -> 29142.857
B29: - Udang Segar (Uk. Sedang) | C29: Kg | D29: 65000 | E29: 70000 | F29: 70000 | G29: 75000 | H29: 58000 | I29: 70000 | J29: 50000 | K29: =AVERAGE(D29:J29) -> 65428.571
B30: - Ikan Lele Segar (Ukuran Sedang) | C30: Kg | D30: 25000 | E30: - | F30: - | G30: 25000 | H30: 23000 | I30: 24000 | J30: 26000 | K30: =AVERAGE(D30:J30) -> 24600
B31: - Ikan Bandeng Segar (Uk. Sedang) | C31: Kg | D31: 45000 | E31: 36000 | F31: 40000 | G31: 45000 | H31: 28000 | I31: 38000 | J31: 40000 | K31: =AVERAGE(D31:J31) -> 38857.143
B32: - Ikan Teri Asin (Bukan Teri Medan) | C32: Kg | D32: - | E32: 100000 | F32: 110000 | G32: - | H32: 80000 | I32: - | J32: - | K32: =AVERAGE(D32:J32) -> 96666.667
A33: 7 | B33: TELUR
B34: - Telur Ayam Broiler | C34: Kg | D34: 27000 | E34: 28000 | F34: 28000 | G34: 27000 | H34: 26000 | I34: 27000 | J34: 27000 | K34: =AVERAGE(D34:J34) -> 27142.857
B35: - Telur Ayam Kampung | C35: Butir | D35: 3000 | E35: 2200 | F35: 2500 | G35: 2500 | H35: 2000 | I35: 2500 | J35: 3000 | K35: =AVERAGE(D35:J35) -> 2528.5714
A36: 8 | B36: TAHU
B37: - Tahu biasa | C37: Kg | D37: 10000 | E37: 10000 | F37: 9000 | G37: 9000 | H37: 16000 | I37: 15000 | J37: 9000 | K37: =AVERAGE(D37:J37) -> 11142.857
B38: - Tahu susu | C38: Kg | D38: - | E38: 7000 | F38: 12000 | G38: 17000 | H38: - | I38: 13000 | J38: 12000 | K38: =AVERAGE(D38:J38) -> 12200
A39: 9 | B39: TEMPE
B40: - Tempe Kw I (campuran kedelai) | C40: Kg | D40: - | E40: 18000 | F40: - | G40: 16000 | H40: 14000 | I40: 15000 | J40: 15000 | K40: =AVERAGE(D40:J40) -> 15600
B41: - Tempe Kw II (campuran jagung) | C41: Kg | D41: 2500 | E41: 12000 | F41: 6000 | G41: - | H41: - | I41: - | J41: - | K41: =AVERAGE(D41:J41) -> 6833.3333
B42: - Tempe Kw III (campuran kulit) | C42: Kg | D42: - | E42: 2000 | F42: - | G42: - | H42: - | I42: - | J42: - | K42: =AVERAGE(D42:J42) -> 2000
...

Sheet 5
A1: HARGA BAHAN-BAHAN POKOK
A2: DI PASAR TRADISIONAL KOTA SURABAYA
A3: HARI / TANGGAL : Rabu / 05 April 2023
B4: NAMA BAHAN POKOK DAN PENTING LAINNYA | C4: SATUAN | D4: Pasar Tambahrejo | E4: Pasar Pucang Anom | F4: Pasar Wonokromo | G4: Pasar Genteng Baru | H4: Pasar Pabean | I4: Pasar Kembang | J4: Pasar Balongsari | K4: Rata-Rata
A7: 1 | B7: BERAS
B8: - Beras Premium | C8: Kg | D8: 13000 | E8: 13500 | F8: 14000 | G8: 13500 | H8: 13000 | I8: 14000 | J8: 13500 | K8: =AVERAGE(D8:J8) -> 13500
B9: - Beras Medium Bulog | C9: Kg | D9: - | E9: - | F9: 12000 | G9: - | H9: 9000 | I9: 9000 | J9: 9000 | K9: =AVERAGE(D9:J9) -> 9750
B10: - Beras Medium | C10: Kg | D10: 11000 | E10: 11500 | F10: - | G10: 11500 | H10: - | I10: - | J10: - | K10: =AVERAGE(D10:J10) -> 11333.333
B11: - Beras Jagung | C11: Kg | D11: - | E11: 10000 | F11: 12000 | G11: 12000 | H11: - | I11: 11000 | J11: 8000 | K11: =AVERAGE(D11:J11) -> 10600
B12: - Beras Ketan (Jenis Siyem) | C12: Kg | D12: - | E12: 22000 | F12: 24000 | G12: 20000 | H12: - | I12: 22000 | J12: 17000 | K12: =AVERAGE(D12:J12) -> 21000
A13: 2 | B13: GULA
B14: - Gula pasir lokal curah | C14: Kg | D14: 13000 | E14: 13000 | F14: 13500 | G14: 13000 | H14: 13000 | I14: 13000 | J14: 13500 | K14: =AVERAGE(D14:J14) -> 13142.857
B15: - Gula Jawa/Merah (Bahan Kelapa) | C15: Kg | D15: 15000 | E15: 16000 | F15: 16000 | G15: 16000 | H15: 15000 | I15: 16000 | J15: 16000 | K15: =AVERAGE(D15:J15) -> 15714.286
A16: 3 | B16: MINYAK GORENG
B17: - Minyak Goreng Curah (Bening) | C17: Kg | D17: 15000 | E17: 16000 | F17: 17000 | G17: 16000 | H17: 14000 | I17: 16000 | J17: 15500 | K17: =AVERAGE(D17:J17) -> 15642.857
B18: - Minyak Kita | C18: Liter | D18: 14000 | E18: 14000 | F18: 14000 | G18: 14000 | H18: - | I18: 14000 | J18: 14000 | K18: =AVERAGE(D18:J18) -> 14000
A19: 4 | B19: MENTEGA
B20: - Mentega Curah (Amanda) | C20: Kg | D20: 20000 | E20: - | F20: 19000 | G20: 22000 | H20: - | I20: 24000 | J20: - | K20: =AVERAGE(D20:J20) -> 21250
A21: 5 | B21: DAGING
B22: - Daging Sapi Grade Atas | C22: Kg | D22: 120000 | E22: 120000 | F22: 120000 | G22: 120000 | H22: 120000 | I22: 120000 | J22: 110000 | K22: =AVERAGE(D22:J22) -> 118571.43
B23: - Daging Sapi Grade Sedang | C23: Kg | D23: 110000 | E23: 110000 | F23: 110000 | G23: 110000 | H23: 114000 | I23: 110000 | J23: 100000 | K23: =AVERAGE(D23:J23) -> 109142.86
B24: - Daging Sapi Grade Bawah | C24: Kg | D24: 100000 | E24: 95000 | F24: 100000 | G24: 100000 | H24: 100000 | I24: 100000 | J24: - | K24: =AVERAGE(D24:J24) -> 99166.667
B25: - Daging Ayam Broiler | C25: Kg | D25: 32000 | E25: 30000 | F25: 32000 | G25: 30000 | H25: 32000 | I25: 30000 | J25: 32000 | K25: =AVERAGE(D25:J25) -> 31142.857
A26: 6 | B26: I K A N
B27: - Ikan Tongkol Segar (Uk. Sedang) | C27: Kg | D27: 35000 | E27: 38000 | F27: - | G27: 45000 | H27: 30000 | I27: 38000 | J27: 35000 | K27: =AVERAGE(D27:J27) -> 36833.333
B28: - Ikan Mujair Segar (Uk. Sedang) | C28: Kg | D28: 30000 | E28: 30000 | F28: 30000 | G28: 35000 | H28: 23000 | I28: 30000 | J28: 26000 | K28: =AVERAGE(D28:J28) -> 29142.857
B29: - Udang Segar (Uk. Sedang) | C29: Kg | D29: 65000 | E29: 70000 | F29: 70000 | G29: 75000 | H29: 58000 | I29: 68000 | J29: 50000 | K29: =AVERAGE(D29:J29) -> 65142.857
B30: - Ikan Lele Segar (Ukuran Sedang) | C30: Kg | D30: 25000 | E30: - | F30: - | G30: 25000 | H30: 23000 | I30: 24000 | J30: 26000 | K30: =AVERAGE(D30:J30) -> 24600
B31: - Ikan Bandeng Segar (Uk. Sedang) | C31: Kg | D31: 45000 | E31: 36000 | F31: 40000 | G31: 45000 | H31: 28000 | I31: 36000 | J31: 40000 | K31: =AVERAGE(D31:J31) -> 38571.429
B32: - Ikan Teri Asin (Bukan Teri Medan) | C32: Kg | D32: - | E32: 100000 | F32: 110000 | G32: - | H32: 80000 | I32: - | J32: - | K32: =AVERAGE(D32:J32) -> 96666.667
A33: 7 | B33: TELUR
B34: - Telur Ayam Broiler | C34: Kg | D34: 27000 | E34: 28000 | F34: 28000 | G34: 27000 | H34: 26000 | I34: 27000 | J34: 27000 | K34: =AVERAGE(D34:J34) -> 27142.857
B35: - Telur Ayam Kampung | C35: Butir | D35: 3000 | E35: 2200 | F35: 2500 | G35: 2200 | H35: 2000 | I35: 2500 | J35: 3000 | K35: =AVERAGE(D35:J35) -> 2485.7143
A36: 8 | B36: TAHU
B37: - Tahu biasa | C37: Kg | D37: 10000 | E37: 10000 | F37: 9000 | G37: 9000 | H37: 16000 | I37: 15000 | J37: 9000 | K37: =AVERAGE(D37:J37) -> 11142.857
B38: - Tahu susu | C38: Kg | D38: - | E38: 7000 | F38: 12000 | G38: 17000 | H38: - | I38: 13000 | J38: 12000 | K38: =AVERAGE(D38:J38) -> 12200
A39: 9 | B39: TEMPE
B40: - Tempe Kw I (campuran kedelai) | C40: Kg | D40: - | E40: 18000 | F40: - | G40: 16000 | H40: 14000 | I40: 15000 | J40: 15000 | K40: =AVERAGE(D40:J40) -> 15600
B41: - Tempe Kw II (campuran jagung) | C41: Kg | D41: 2500 | E41: 12000 | F41: 6000 | G41: - | H41: - | I41: - | J41: - | K41: =AVERAGE(D41:J41) -> 6833.3333
B42: - Tempe Kw III (campuran kulit) | C42: Kg | D42: - | E42: 2000 | F42: - | G42: - | H42: - | I42: - | J42: - | K42: =AVERAGE(D42:J42) -> 2000
...

Sheet 6
A1: HARGA BAHAN-BAHAN POKOK
A2: DI PASAR TRADISIONAL KOTA SURABAYA
A3: HARI / TANGGAL : Kamis / 06 April 2023
B4: NAMA BAHAN POKOK DAN PENTING LAINNYA | C4: SATUAN | D4: Pasar Tambahrejo | E4: Pasar Pucang Anom | F4: Pasar Wonokromo | G4: Pasar Genteng Baru | H4: Pasar Pabean | I4: Pasar Kembang | J4: Pasar Balongsari | K4: Rata-Rata
A7: 1 | B7: BERAS
B8: - Beras Premium | C8: Kg | D8: 13000 | E8: 13500 | F8: 14000 | G8: 13500 | H8: 13000 | I8: 14000 | J8: 13500 | K8: =AVERAGE(D8:J8) -> 13500
B9: - Beras Medium Bulog | C9: Kg | D9: - | E9: - | F9: 12000 | G9: - | H9: 9000 | I9: 9000 | J9: 9000 | K9: =AVERAGE(D9:J9) -> 9750
B10: - Beras Medium | C10: Kg | D10: 11000 | E10: 11500 | F10: - | G10: 11500 | H10: - | I10: - | J10: - | K10: =AVERAGE(D10:J10) -> 11333.333
B11: - Beras Jagung | C11: Kg | D11: - | E11: 10000 | F11: 12000 | G11: 12000 | H11: - | I11: 11000 | J11: 8000 | K11: =AVERAGE(D11:J11) -> 10600
B12: - Beras Ketan (Jenis Siyem) | C12: Kg | D12: - | E12: 22000 | F12: 24000 | G12: 20000 | H12: - | I12: 22000 | J12: 17000 | K12: =AVERAGE(D12:J12) -> 21000
A13: 2 | B13: GULA
B14: - Gula pasir lokal curah | C14: Kg | D14: 13000 | E14: 13000 | F14: 13500 | G14: 13000 | H14: 13000 | I14: 13000 | J14: 13500 | K14: =AVERAGE(D14:J14) -> 13142.857
B15: - Gula Jawa/Merah (Bahan Kelapa) | C15: Kg | D15: 15000 | E15: 16000 | F15: 16000 | G15: 16000 | H15: 15000 | I15: 16000 | J15: 16000 | K15: =AVERAGE(D15:J15) -> 15714.286
A16: 3 | B16: MINYAK GORENG
B17: - Minyak Goreng Curah (Bening) | C17: Kg | D17: 15000 | E17: 16000 | F17: 17000 | G17: 16000 | H17: 14000 | I17: 16000 | J17: 15000 | K17: =AVERAGE(D17:J17) -> 15571.429
B18: - Minyak Kita | C18: Liter | D18: 14000 | E18: 14000 | F18: 14000 | G18: 14000 | H18: - | I18: 14000 | J18: 14000 | K18: =AVERAGE(D18:J18) -> 14000
A19: 4 | B19: MENTEGA
B20: - Mentega Curah (Amanda) | C20: Kg | D20: 20000 | E20: - | F20: 19000 | G20: 22000 | H20: - | I20: 24000 | J20: - | K20: =AVERAGE(D20:J20) -> 21250
A21: 5 | B21: DAGING
B22: - Daging Sapi Grade Atas | C22: Kg | D22: 120000 | E22: 120000 | F22: 120000 | G22: 120000 | H22: 120000 | I22: 120000 | J22: 110000 | K22: =AVERAGE(D22:J22) -> 118571.43
B23: - Daging Sapi Grade Sedang | C23: Kg | D23: 110000 | E23: 110000 | F23: 110000 | G23: 110000 | H23: 114000 | I23: 110000 | J23: 100000 | K23: =AVERAGE(D23:J23) -> 109142.86
B24: - Daging Sapi Grade Bawah | C24: Kg | D24: 100000 | E24: 95000 | F24: 100000 | G24: 100000 | H24: 100000 | I24: 100000 | J24: - | K24: =AVERAGE(D24:J24) -> 99166.667
B25: - Daging Ayam Broiler | C25: Kg | D25: 32000 | E25: 30000 | F25: 30000 | G25: 30000 | H25: 32000 | I25: 30000 | J25: 32000 | K25: =AVERAGE(D25:J25) -> 30857.143
A26: 6 | B26: I K A N
B27: - Ikan Tongkol Segar (Uk. Sedang) | C27: Kg | D27: 35000 | E27: 38000 | F27: - | G27: 45000 | H27: 30000 | I27: 38000 | J27: 35000 | K27: =AVERAGE(D27:J27) -> 36833.333
B28: - Ikan Mujair Segar (Uk. Sedang) | C28: Kg | D28: 30000 | E28: 30000 | F28: 30000 | G28: 35000 | H28: 23000 | I28: 30000 | J28: 26000 | K28: =AVERAGE(D28:J28) -> 29142.857
B29: - Udang Segar (Uk. Sedang) | C29: Kg | D29: 65000 | E29: 60000 | F29: 70000 | G29: 75000 | H29: 58000 | I29: 68000 | J29: 50000 | K29: =AVERAGE(D29:J29) -> 63714.286
B30: - Ikan Lele Segar (Ukuran Sedang) | C30: Kg | D30: 25000 | E30: - | F30: - | G30: 25000 | H30: 23000 | I30: 24000 | J30: 26000 | K30: =AVERAGE(D30:J30) -> 24600
B31: - Ikan Bandeng Segar (Uk. Sedang) | C31: Kg | D31: 45000 | E31: 36000 | F31: 40000 | G31: 45000 | H31: 28000 | I31: 36000 | J31: 40000 | K31: =AVERAGE(D31:J31) -> 38571.429
B32: - Ikan Teri Asin (Bukan Teri Medan) | C32: Kg | D32: - | E32: 100000 | F32: 110000 | G32: - | H32: 80000 | I32: - | J32: - | K32: =AVERAGE(D32:J32) -> 96666.667
A33: 7 | B33: TELUR
B34: - Telur Ayam Broiler | C34: Kg | D34: 27000 | E34: 28000 | F34: 27000 | G34: 27000 | H34: 27000 | I34: 27000 | J34: 27000 | K34: =AVERAGE(D34:J34) -> 27142.857
B35: - Telur Ayam Kampung | C35: Butir | D35: 3000 | E35: 2200 | F35: 2500 | G35: 2200 | H35: 2000 | I35: 2500 | J35: 3000 | K35: =AVERAGE(D35:J35) -> 2485.7143
A36: 8 | B36: TAHU
B37: - Tahu biasa | C37: Kg | D37: 10000 | E37: 10000 | F37: 9000 | G37: 9000 | H37: 16000 | I37: 15000 | J37: 9000 | K37: =AVERAGE(D37:J37) -> 11142.857
B38: - Tahu susu | C38: Kg | D38: - | E38: 7000 | F38: 12000 | G38: 17000 | H38: - | I38: 13000 | J38: 12000 | K38: =AVERAGE(D38:J38) -> 12200
A39: 9 | B39: TEMPE
B40: - Tempe Kw I (campuran kedelai) | C40: Kg | D40: - | E40: 18000 | F40: - | G40: 16000 | H40: 14000 | I40: 15000 | J40: 15000 | K40: =AVERAGE(D40:J40) -> 15600
B41: - Tempe Kw II (campuran jagung) | C41: Kg | D41: 2500 | E41: 12000 | F41: 6000 | G41: - | H41: - | I41: - | J41: - | K41: =AVERAGE(D41:J41) -> 6833.3333
B42: - Tempe Kw III (campuran kulit) | C42: Kg | D42: - | E42: 2000 | F42: - | G42: - | H42: - | I42: - | J42: - | K42: =AVERAGE(D42:J42) -> 2000
...

Sheet 7
A1: HARGA BAHAN-BAHAN POKOK
A2: DI PASAR TRADISIONAL KOTA SURABAYA
A3: HARI / TANGGAL : Jumat / 07 April 2023
B4: NAMA BAHAN POKOK DAN PENTING LAINNYA | C4: SATUAN | D4: Pasar Tambahrejo | E4: Pasar Pucang Anom | F4: Pasar Wonokromo | G4: Pasar Genteng Baru | H4: Pasar Pabean | I4: Pasar Kembang | J4: Pasar Balongsari | K4: Rata-Rata
A7: 1 | B7: BERAS
B8: - Beras Premium | C8: Kg | D8: 13000 | E8: 13500 | F8: 14000 | G8: 13500 | H8: 13000 | I8: 14000 | J8: 13500 | K8: =AVERAGE(D8:J8) -> 13500
B9: - Beras Medium Bulog | C9: Kg | D9: - | E9: - | F9: 12000 | G9: - | H9: 9000 | I9: 9000 | J9: 9000 | K9: =AVERAGE(D9:J9) -> 9750
B10: - Beras Medium | C10: Kg | D10: 11000 | E10: 11500 | F10: - | G10: 11500 | H10: - | I10: - | J10: - | K10: =AVERAGE(D10:J10) -> 11333.333
B11: - Beras Jagung | C11: Kg | D11: - | E11: 10000 | F11: 12000 | G11: 12000 | H11: - | I11: 11000 | J11: 8000 | K11: =AVERAGE(D11:J11) -> 10600
B12: - Beras Ketan (Jenis Siyem) | C12: Kg | D12: - | E12: 22000 | F12: 24000 | G12: 20000 | H12: - | I12: 22000 | J12: 17000 | K12: =AVERAGE(D12:J12) -> 21000
A13: 2 | B13: GULA
