Workbook

Sheet REKAPITULASI
A1: BAGIAN PEREKONOMIAN DAN SUMBER DAYA ALAM
A2: LAPORAN HARGA BAHAN POKOK DI KOTA SURABAYA
A3: PERIODE MEI 2023
B4: NAMA BAHAN POKOK DAN PENTING LAINNYA | C4: SAT | AI4: HET/HAPK (Harga Eceran Tertinggi) | AJ4: FLUKTUASI
D5: 1 | E5: 2 | F5: 3 | G5: 4 | H5: 5 | I5: 6 | J5: 7 | K5: 8 | L5: 9 | M5: 10 | N5: 11 | O5: 12 | P5: 13 | Q5: 14 | R5: 15 | S5: 16 | T5: 17 | U5: 18 | V5: 19 | W5: 20 | X5: 21 | Y5: 22 | Z5: 23 | AA5: 24 | AB5: 25 | AC5: 26 | AD5: 27 | AE5: 28 | AF5: 29 | AG5: 30 | AH5: 31
A7: 1 | B7: BERAS
B8: - Beras Premium | C8: Kg | D8: ='1'!K8 -> 13500 | E8: ='2'!K8 -> 13500 | F8: ='3'!K8 -> 13642.857 | G8: ='4'!K8 -> 13285.714 | H8: ='5'!K8 -> 13357.143 | I8: ='6'!K8 -> 13642.857 | J8: ='7'!K8 -> 13642.857 | K8: ='8'!K8 -> 13357.143 | L8: ='9'!K8 -> 13357.143 | M8: ='10'!K8 -> 13357.143 | N8: ='11'!K8 -> 13357.143 | O8: ='12'!K8 -> 13357.143 | P8: ='13'!K8 -> 13357.143 | Q8: ='14'!K8 -> 13357.143 | R8: ='15'!K8 -> 13357.143 | S8: ='16'!K8 -> 13357.143 | T8: ='17'!K8 -> 13357.143 | U8: ='18'!K8 -> 13357.143 | V8: ='19'!K8 -> 13357.143 | W8: ='20'!K8 -> 13357.143 | X8: ='21'!K8 -> 13357.143 | Y8: ='22'!K8 -> 13357.143 | Z8: ='23'!K8 -> 13357.143 | AA8: ='24'!K8 -> 13357.143 | AB8: ='25'!K8 -> 13357.143 | AC8: ='26'!K8 -> 13357.143 | AD8: ='27'!K8 -> 13357.143 | AE8: ='28'!K8 -> 13357.143 | AF8: ='29'!K8 -> 13357.143 | AG8: ='30'!K8 -> 13357.143 | AH8: ='31'!K8 -> 13357.143 | AI8: 12800 | AJ8: =AH8-D8 -> -142.85714 | AK8: =AVERAGE(D8:AH8) -> 13391.705
B9: - Beras Medium Bulog | C9: Kg | D9: ='1'!K9 -> 10333.333 | E9: ='2'!K9 -> 10333.333 | F9: ='3'!K9 -> 10000 | G9: ='4'!K9 -> 9666.6667 | H9: ='5'!K9 -> 10000 | I9: ='6'!K9 -> 10000 | J9: ='7'!K9 -> 10000 | K9: ='8'!K9 -> 8933.3333 | L9: ='9'!K9 -> 9000 | M9: ='10'!K9 -> 9000 | N9: ='11'!K9 -> 9000 | O9: ='12'!K9 -> 9000 | P9: ='13'!K9 -> 9000 | Q9: ='14'!K9 -> 9000 | R9: ='15'!K9 -> 9000 | S9: ='16'!K9 -> 9166.6667 | T9: ='17'!K9 -> 9166.6667 | U9: ='18'!K9 -> 9166.6667 | V9: ='19'!K9 -> 9166.6667 | W9: ='20'!K9 -> 9166.6667 | X9: ='21'!K9 -> 9333.3333 | Y9: ='22'!K9 -> 9333.3333 | Z9: ='23'!K9 -> 9333.3333 | AA9: ='24'!K9 -> 9333.3333 | AB9: ='25'!K9 -> 9666.6667 | AC9: ='26'!K9 -> 9666.6667 | AD9: ='27'!K9 -> 9666.6667 | AE9: ='28'!K9 -> 9666.6667 | AF9: ='29'!K9 -> 10000 | AG9: ='30'!K9 -> 9000 | AH9: ='31'!K9 -> 9000 | AJ9: =AH9-D9 -> -1333.3333 | AK9: =AVERAGE(D9:AH9) -> 9422.5806
B10: - Beras Medium | C10: Kg | D10: ='1'!K10 -> 11375 | E10: ='2'!K10 -> 11375 | F10: ='3'!K10 -> 11375 | G10: ='4'!K10 -> 11375 | H10: ='5'!K10 -> 11375 | I10: ='6'!K10 -> 11375 | J10: ='7'!K10 -> 11375 | K10: ='8'!K10 -> 11375 | L10: ='9'!K10 -> 11700 | M10: ='10'!K10 -> 11900 | N10: ='11'!K10 -> 11700 | O10: ='12'!K10 -> 11700 | P10: ='13'!K10 -> 11700 | Q10: ='14'!K10 -> 11700 | R10: ='15'!K10 -> 11700 | S10: ='16'!K10 -> 11700 | T10: ='17'!K10 -> 11700 | U10: ='18'!K10 -> 11700 | V10: ='19'!K10 -> 11700 | W10: ='20'!K10 -> 11500 | X10: ='21'!K10 -> 11500 | Y10: ='22'!K10 -> 11500 | Z10: ='23'!K10 -> 11500 | AA10: ='24'!K10 -> 11500 | AB10: ='25'!K10 -> 11700 | AC10: ='26'!K10 -> 11700 | AD10: ='27'!K10 -> 11900 | AE10: ='28'!K10 -> 11916.667 | AF10: ='29'!K10 -> 12000 | AG10: ='30'!K10 -> 12000 | AH10: ='31'!K10 -> 12000 | AI10: 9450 | AJ10: =AH10-D10 -> 625 | AK10: =AVERAGE(D10:AH10) -> 11632.796
B11: - Beras Jagung | C11: Kg | D11: ='1'!K11 -> 10600 | E11: ='2'!K11 -> 10600 | F11: ='3'!K11 -> 10600 | G11: ='4'!K11 -> 10600 | H11: ='5'!K11 -> 10600 | I11: ='6'!K11 -> 10600 | J11: ='7'!K11 -> 10600 | K11: ='8'!K11 -> 10600 | L11: ='9'!K11 -> 10600 | M11: ='10'!K11 -> 10600 | N11: ='11'!K11 -> 10600 | O11: ='12'!K11 -> 10600 | P11: ='13'!K11 -> 10600 | Q11: ='14'!K11 -> 10600 | R11: ='15'!K11 -> 10600 | S11: ='16'!K11 -> 10600 | T11: ='17'!K11 -> 10600 | U11: ='18'!K11 -> 10600 | V11: ='19'!K11 -> 10600 | W11: ='20'!K11 -> 10600 | X11: ='21'!K11 -> 10600 | Y11: ='22'!K11 -> 10600 | Z11: ='23'!K11 -> 10600 | AA11: ='24'!K11 -> 10600 | AB11: ='25'!K11 -> 10600 | AC11: ='26'!K11 -> 10600 | AD11: ='27'!K11 -> 10600 | AE11: ='28'!K11 -> 10600 | AF11: ='29'!K11 -> 10600 | AG11: ='30'!K11 -> 10600 | AH11: ='31'!K11 -> 10600 | AJ11: =AH11-D11 -> 0 | AK11: =AVERAGE(D11:AH11) -> 10600
B12: - Beras Ketan (Jenis Siyem) | C12: Kg | D12: ='1'!K12 -> 20600 | E12: ='2'!K12 -> 21000 | F12: ='3'!K12 -> 20200 | G12: ='4'!K12 -> 20200 | H12: ='5'!K12 -> 21000 | I12: ='6'!K12 -> 20200 | J12: ='7'!K12 -> 19800 | K12: ='8'!K12 -> 20600 | L12: ='9'!K12 -> 20600 | M12: ='10'!K12 -> 19800 | N12: ='11'!K12 -> 20600 | O12: ='12'!K12 -> 20600 | P12: ='13'!K12 -> 19800 | Q12: ='14'!K12 -> 19800 | R12: ='15'!K12 -> 20600 | S12: ='16'!K12 -> 19800 | T12: ='17'!K12 -> 19800 | U12: ='18'!K12 -> 19800 | V12: ='19'!K12 -> 20200 | W12: ='20'!K12 -> 19400 | X12: ='21'!K12 -> 19800 | Y12: ='22'!K12 -> 20200 | Z12: ='23'!K12 -> 20200 | AA12: ='24'!K12 -> 20200 | AB12: ='25'!K12 -> 20200 | AC12: ='26'!K12 -> 20200 | AD12: ='27'!K12 -> 19800 | AE12: ='28'!K12 -> 19800 | AF12: ='29'!K12 -> 20200 | AG12: ='30'!K12 -> 20200 | AH12: ='31'!K12 -> 20200 | AJ12: =AH12-D12 -> -400 | AK12: =AVERAGE(D12:AH12) -> 20174.194
A13: 2 | B13: GULA | D13: ='1'!K13 -> 0 | E13: ='2'!K13 -> 0 | F13: ='3'!K13 -> 0 | G13: ='4'!K13 -> 0 | H13: ='5'!K13 -> 0 | I13: ='6'!K13 -> 0 | J13: ='7'!K13 -> 0 | K13: ='8'!K13 -> 0 | L13: ='9'!K13 -> 0 | M13: ='10'!K13 -> 0 | N13: ='11'!K13 -> 0 | O13: ='12'!K13 -> 0 | P13: ='13'!K13 -> 0 | Q13: ='14'!K13 -> 0 | R13: ='15'!K13 -> 0 | S13: ='16'!K13 -> 0 | T13: ='17'!K13 -> 0 | U13: ='18'!K13 -> 0 | V13: ='19'!K13 -> 0 | W13: ='20'!K13 -> 0 | X13: ='21'!K13 -> 0 | Y13: ='22'!K13 -> 0 | Z13: ='23'!K13 -> 0 | AA13: ='24'!K13 -> 0 | AB13: ='25'!K13 -> 0 | AC13: ='26'!K13 -> 0 | AD13: ='27'!K13 -> 0 | AE13: ='28'!K13 -> 0 | AF13: ='29'!K13 -> 0 | AG13: ='30'!K13 -> 0 | AH13: ='31'!K13 -> 0 | AJ13: =AH13-D13 -> 0 | AK13: =AVERAGE(D13:AH13) -> 0
B14: - Gula pasir lokal curah | C14: Kg | D14: ='1'!K14 -> 13071.429 | E14: ='2'!K14 -> 13214.286 | F14: ='3'!K14 -> 13142.857 | G14: ='4'!K14 -> 13214.286 | H14: ='5'!K14 -> 13214.286 | I14: ='6'!K14 -> 13285.714 | J14: ='7'!K14 -> 13357.143 | K14: ='8'!K14 -> 13285.714 | L14: ='9'!K14 -> 13357.143 | M14: ='10'!K14 -> 13357.143 | N14: ='11'!K14 -> 13357.143 | O14: ='12'!K14 -> 13357.143 | P14: ='13'!K14 -> 13357.143 | Q14: ='14'!K14 -> 13357.143 | R14: ='15'!K14 -> 13357.143 | S14: ='16'!K14 -> 13357.143 | T14: ='17'!K14 -> 13357.143 | U14: ='18'!K14 -> 13357.143 | V14: ='19'!K14 -> 13500 | W14: ='20'!K14 -> 13428.571 | X14: ='21'!K14 -> 13428.571 | Y14: ='22'!K14 -> 13571.429 | Z14: ='23'!K14 -> 13571.429 | AA14: ='24'!K14 -> 13571.429 | AB14: ='25'!K14 -> 13571.429 | AC14: ='26'!K14 -> 13571.429 | AD14: ='27'!K14 -> 13500 | AE14: ='28'!K14 -> 13500 | AF14: ='29'!K14 -> 13571.429 | AG14: ='30'!K14 -> 13571.429 | AH14: ='31'!K14 -> 13571.429 | AI14: 13500 | AJ14: =AH14-D14 -> 500 | AK14: =AVERAGE(D14:AH14) -> 13396.313
B15: - Gula Jawa/Merah (Bahan Kelapa) | C15: Kg | D15: ='1'!K15 -> 16285.714 | E15: ='2'!K15 -> 15571.429 | F15: ='3'!K15 -> 15857.143 | G15: ='4'!K15 -> 16000 | H15: ='5'!K15 -> 15571.429 | I15: ='6'!K15 -> 16000 | J15: ='7'!K15 -> 16000 | K15: ='8'!K15 -> 15571.429 | L15: ='9'!K15 -> 15571.429 | M15: ='10'!K15 -> 15714.286 | N15: ='11'!K15 -> 15571.429 | O15: ='12'!K15 -> 15571.429 | P15: ='13'!K15 -> 16000 | Q15: ='14'!K15 -> 16000 | R15: ='15'!K15 -> 15571.429 | S15: ='16'!K15 -> 16285.714 | T15: ='17'!K15 -> 16571.429 | U15: ='18'!K15 -> 16571.429 | V15: ='19'!K15 -> 15857.143 | W15: ='20'!K15 -> 16142.857 | X15: ='21'!K15 -> 16857.143 | Y15: ='22'!K15 -> 15857.143 | Z15: ='23'!K15 -> 15857.143 | AA15: ='24'!K15 -> 15857.143 | AB15: ='25'!K15 -> 15857.143 | AC15: ='26'!K15 -> 15857.143 | AD15: ='27'!K15 -> 16571.429 | AE15: ='28'!K15 -> 16571.429 | AF15: ='29'!K15 -> 15857.143 | AG15: ='30'!K15 -> 15857.143 | AH15: ='31'!K15 -> 15857.143 | AJ15: =AH15-D15 -> -428.57143 | AK15: =AVERAGE(D15:AH15) -> 15972.35
A16: 3 | B16: MINYAK GORENG | D16: ='1'!K16 -> 0 | E16: ='2'!K16 -> 0 | F16: ='3'!K16 -> 0 | G16: ='4'!K16 -> 0 | H16: ='5'!K16 -> 0 | I16: ='6'!K16 -> 0 | J16: ='7'!K16 -> 0 | K16: ='8'!K16 -> 0 | L16: ='9'!K16 -> 0 | M16: ='10'!K16 -> 0 | N16: ='11'!K16 -> 0 | O16: ='12'!K16 -> 0 | P16: ='13'!K16 -> 0 | Q16: ='14'!K16 -> 0 | R16: ='15'!K16 -> 0 | S16: ='16'!K16 -> 0 | T16: ='17'!K16 -> 0 | U16: ='18'!K16 -> 0 | V16: ='19'!K16 -> 0 | W16: ='20'!K16 -> 0 | X16: ='21'!K16 -> 0 | Y16: ='22'!K16 -> 0 | Z16: ='23'!K16 -> 0 | AA16: ='24'!K16 -> 0 | AB16: ='25'!K16 -> 0 | AC16: ='26'!K16 -> 0 | AD16: ='27'!K16 -> 0 | AE16: ='28'!K16 -> 0 | AF16: ='29'!K16 -> 0 | AG16: ='30'!K16 -> 0 | AH16: ='31'!K16 -> 0 | AJ16: =AH16-D16 -> 0 | AK16: =AVERAGE(D16:AH16) -> 0
B17: - Minyak Goreng Curah (Bening) | C17: Kg | D17: ='1'!K17 -> 15357.143 | E17: ='2'!K17 -> 15500 | F17: ='3'!K17 -> 15357.143 | G17: ='4'!K17 -> 15357.143 | H17: ='5'!K17 -> 15500 | I17: ='6'!K17 -> 15500 | J17: ='7'!K17 -> 15500 | K17: ='8'!K17 -> 15500 | L17: ='9'!K17 -> 15642.857 | M17: ='10'!K17 -> 15642.857 | N17: ='11'!K17 -> 15642.857 | O17: ='12'!K17 -> 15642.857 | P17: ='13'!K17 -> 15642.857 | Q17: ='14'!K17 -> 15642.857 | R17: ='15'!K17 -> 15642.857 | S17: ='16'!K17 -> 15642.857 | T17: ='17'!K17 -> 15642.857 | U17: ='18'!K17 -> 15642.857 | V17: ='19'!K17 -> 15642.857 | W17: ='20'!K17 -> 15500 | X17: ='21'!K17 -> 15500 | Y17: ='22'!K17 -> 15571.429 | Z17: ='23'!K17 -> 15571.429 | AA17: ='24'!K17 -> 15571.429 | AB17: ='25'!K17 -> 15571.429 | AC17: ='26'!K17 -> 15571.429 | AD17: ='27'!K17 -> 15571.429 | AE17: ='28'!K17 -> 15571.429 | AF17: ='29'!K17 -> 15571.429 | AG17: ='30'!K17 -> 15571.429 | AH17: ='31'!K17 -> 15571.429 | AI17: 15500 | AJ17: =AH17-D17 -> 214.28571 | AK17: =AVERAGE(D17:AH17) -> 15559.908
B18: - Minyak Kita | C18: Liter | D18: ='1'!K18 -> 14000 | E18: ='2'!K18 -> 14000 | F18: ='3'!K18 -> 14000 | G18: ='4'!K18 -> 14000 | H18: ='5'!K18 -> 14000 | I18: ='6'!K18 -> 14000 | J18: ='7'!K18 -> 14000 | K18: ='8'!K18 -> 14000 | L18: ='9'!K18 -> 14000 | M18: ='10'!K18 -> 14000 | N18: ='11'!K18 -> 14000 | O18: ='12'!K18 -> 14000 | P18: ='13'!K18 -> 14000 | Q18: ='14'!K18 -> 14000 | R18: ='15'!K18 -> 14000 | S18: ='16'!K18 -> 14000 | T18: ='17'!K18 -> 14000 | U18: ='18'!K18 -> 14000 | V18: ='19'!K18 -> 14000 | W18: ='20'!K18 -> 14000 | X18: ='21'!K18 -> 14000 | Y18: ='22'!K18 -> 14000 | Z18: ='23'!K18 -> 14000 | AA18: ='24'!K18 -> 14000 | AB18: ='25'!K18 -> 14000 | AC18: ='26'!K18 -> 14000 | AD18: ='27'!K18 -> 14000 | AE18: ='28'!K18 -> 14000 | AF18: ='29'!K18 -> 14000 | AG18: ='30'!K18 -> 14000 | AH18: ='31'!K18 -> 14000 | AI18: 14000 | AJ18: =AH18-D18 -> 0 | AK18: =AVERAGE(D18:AH18) -> 14000
A19: 4 | B19: MENTEGA | D19: ='1'!K19 -> 0 | E19: ='2'!K19 -> 0 | F19: ='3'!K19 -> 0 | G19: ='4'!K19 -> 0 | H19: ='5'!K19 -> 0 | I19: ='6'!K19 -> 0 | J19: ='7'!K19 -> 0 | K19: ='8'!K19 -> 0 | L19: ='9'!K19 -> 0 | M19: ='10'!K19 -> 0 | N19: ='11'!K19 -> 0 | O19: ='12'!K19 -> 0 | P19: ='13'!K19 -> 0 | Q19: ='14'!K19 -> 0 | R19: ='15'!K19 -> 0 | S19: ='16'!K19 -> 0 | T19: ='17'!K19 -> 0 | U19: ='18'!K19 -> 0 | V19: ='19'!K19 -> 0 | W19: ='20'!K19 -> 0 | X19: ='21'!K19 -> 0 | Y19: ='22'!K19 -> 0 | Z19: ='23'!K19 -> 0 | AA19: ='24'!K19 -> 0 | AB19: ='25'!K19 -> 0 | AC19: ='26'!K19 -> 0 | AD19: ='27'!K19 -> 0 | AE19: ='28'!K19 -> 0 | AF19: ='29'!K19 -> 0 | AG19: ='30'!K19 -> 0 | AH19: ='31'!K19 -> 0 | AJ19: =AH19-D19 -> 0 | AK19: =AVERAGE(D19:AH19) -> 0
B20: - Mentega Curah (Amanda) | C20: Kg | D20: ='1'!K20 -> 22500 | E20: ='2'!K20 -> 21250 | F20: ='3'!K20 -> 22500 | G20: ='4'!K20 -> 22500 | H20: ='5'!K20 -> 21250 | I20: ='6'!K20 -> 22500 | J20: ='7'!K20 -> 22500 | K20: ='8'!K20 -> 21250 | L20: ='9'!K20 -> 21250 | M20: ='10'!K20 -> 21250 | N20: ='11'!K20 -> 21250 | O20: ='12'!K20 -> 21250 | P20: ='13'!K20 -> 21250 | Q20: ='14'!K20 -> 21250 | R20: ='15'!K20 -> 21250 | S20: ='16'!K20 -> 21250 | T20: ='17'!K20 -> 21500 | U20: ='18'!K20 -> 21500 | V20: ='19'!K20 -> 21250 | W20: ='20'!K20 -> 21250 | X20: ='21'!K20 -> 21250 | Y20: ='22'!K20 -> 21250 | Z20: ='23'!K20 -> 21250 | AA20: ='24'!K20 -> 21250 | AB20: ='25'!K20 -> 21250 | AC20: ='26'!K20 -> 21250 | AD20: ='27'!K20 -> 21500 | AE20: ='28'!K20 -> 21500 | AF20: ='29'!K20 -> 21250 | AG20: ='30'!K20 -> 21250 | AH20: ='31'!K20 -> 21250 | AJ20: =AH20-D20 -> -1250 | AK20: =AVERAGE(D20:AH20) -> 21483.871
A21: 5 | B21: DAGING | D21: ='1'!K21 -> 0 | E21: ='2'!K21 -> 0 | F21: ='3'!K21 -> 0 | G21: ='4'!K21 -> 0 | H21: ='5'!K21 -> 0 | I21: ='6'!K21 -> 0 | J21: ='7'!K21 -> 0 | K21: ='8'!K21 -> 0 | L21: ='9'!K21 -> 0 | M21: ='10'!K21 -> 0 | N21: ='11'!K21 -> 0 | O21: ='12'!K21 -> 0 | P21: ='13'!K21 -> 0 | Q21: ='14'!K21 -> 0 | R21: ='15'!K21 -> 0 | S21: ='16'!K21 -> 0 | T21: ='17'!K21 -> 0 | U21: ='18'!K21 -> 0 | V21: ='19'!K21 -> 0 | W21: ='20'!K21 -> 0 | X21: ='21'!K21 -> 0 | Y21: ='22'!K21 -> 0 | Z21: ='23'!K21 -> 0 | AA21: ='24'!K21 -> 0 | AB21: ='25'!K21 -> 0 | AC21: ='26'!K21 -> 0 | AD21: ='27'!K21 -> 0 | AE21: ='28'!K21 -> 0 | AF21: ='29'!K21 -> 0 | AG21: ='30'!K21 -> 0 | AH21: ='31'!K21 -> 0 | AJ21: =AH21-D21 -> 0 | AK21: =AVERAGE(D21:AH21) -> 0
B22: - Daging Sapi Grade Atas | C22: Kg | D22: ='1'!K22 -> 122500 | E22: ='2'!K22 -> 120833.33 | F22: ='3'!K22 -> 122500 | G22: ='4'!K22 -> 120833.33 | H22: ='5'!K22 -> 120833.33 | I22: ='6'!K22 -> 120833.33 | J22: ='7'!K22 -> 120833.33 | K22: ='8'!K22 -> 120833.33 | L22: ='9'!K22 -> 120000 | M22: ='10'!K22 -> 120000 | N22: ='11'!K22 -> 120000 | O22: ='12'!K22 -> 120000 | P22: ='13'!K22 -> 120000 | Q22: ='14'!K22 -> 120000 | R22: ='15'!K22 -> 120000 | S22: ='16'!K22 -> 120000 | T22: ='17'!K22 -> 120000 | U22: ='18'!K22 -> 120000 | V22: ='19'!K22 -> 120000 | W22: ='20'!K22 -> 120000 | X22: ='21'!K22 -> 120000 | Y22: ='22'!K22 -> 120000 | Z22: ='23'!K22 -> 120000 | AA22: ='24'!K22 -> 120000 | AB22: ='25'!K22 -> 120000 | AC22: ='26'!K22 -> 120000 | AD22: ='27'!K22 -> 120000 | AE22: ='28'!K22 -> 120000 | AF22: ='29'!K22 -> 120000 | AG22: ='30'!K22 -> 120000 | AH22: ='31'!K22 -> 120000 | AI22: 105000 | AJ22: =AH22-D22 -> -2500 | AK22: =AVERAGE(D22:AH22) -> 120322.58
B23: - Daging Sapi Grade Sedang | C23: Kg | D23: ='1'!K23 -> 114857.14 | E23: ='2'!K23 -> 112714.29 | F23: ='3'!K23 -> 114142.86 | G23: ='4'!K23 -> 112714.29 | H23: ='5'!K23 -> 112714.29 | I23: ='6'!K23 -> 112714.29 | J23: ='7'!K23 -> 112714.29 | K23: ='8'!K23 -> 112714.29 | L23: ='9'!K23 -> 112714.29 | M23: ='10'!K23 -> 112714.29 | N23: ='11'!K23 -> 112714.29 | O23: ='12'!K23 -> 112714.29 | P23: ='13'!K23 -> 112714.29 | Q23: ='14'!K23 -> 112000 | R23: ='15'!K23 -> 112000 | S23: ='16'!K23 -> 112000 | T23: ='17'!K23 -> 112000 | U23: ='18'!K23 -> 112000 | V23: ='19'!K23 -> 112000 | W23: ='20'!K23 -> 112000 | X23: ='21'!K23 -> 112000 | Y23: ='22'!K23 -> 112000 | Z23: ='23'!K23 -> 112000 | AA23: ='24'!K23 -> 112000 | AB23: ='25'!K23 -> 112000 | AC23: ='26'!K23 -> 112000 | AD23: ='27'!K23 -> 112000 | AE23: ='28'!K23 -> 112000 | AF23: ='29'!K23 -> 112000 | AG23: ='30'!K23 -> 112000 | AH23: ='31'!K23 -> 112000 | AI23: 80000 | AJ23: =AH23-D23 -> -2857.1429 | AK23: =AVERAGE(D23:AH23) -> 112414.75
B24: - Daging Sapi Grade Bawah | C24: Kg | D24: ='1'!K24 -> 105000 | E24: ='2'!K24 -> 102857.14 | F24: ='3'!K24 -> 103571.43 | G24: ='4'!K24 -> 102857.14 | H24: ='5'!K24 -> 102857.14 | I24: ='6'!K24 -> 102857.14 | J24: ='7'!K24 -> 102857.14 | K24: ='8'!K24 -> 102857.14 | L24: ='9'!K24 -> 102857.14 | M24: ='10'!K24 -> 102142.86 | N24: ='11'!K24 -> 102857.14 | O24: ='12'!K24 -> 102857.14 | P24: ='13'!K24 -> 102857.14 | Q24: ='14'!K24 -> 102857.14 | R24: ='15'!K24 -> 102857.14 | S24: ='16'!K24 -> 102857.14 | T24: ='17'!K24 -> 102857.14 | U24: ='18'!K24 -> 102857.14 | V24: ='19'!K24 -> 102857.14 | W24: ='20'!K24 -> 102857.14 | X24: ='21'!K24 -> 102857.14 | Y24: ='22'!K24 -> 102857.14 | Z24: ='23'!K24 -> 102857.14 | AA24: ='24'!K24 -> 102857.14 | AB24: ='25'!K24 -> 102857.14 | AC24: ='26'!K24 -> 102857.14 | AD24: ='27'!K24 -> 102857.14 | AE24: ='28'!K24 -> 102857.14 | AF24: ='29'!K24 -> 102857.14 | AG24: ='30'!K24 -> 102857.14 | AH24: ='31'!K24 -> 102857.14 | AI24: 80000 | AJ24: =AH24-D24 -> -2142.8571 | AK24: =AVERAGE(D24:AH24) -> 102926.27
B25: - Daging Ayam Broiler | C25: Kg | D25: ='1'!K25 -> 36000 | E25: ='2'!K25 -> 34000 | F25: ='3'!K25 -> 33571.429 | G25: ='4'!K25 -> 33571.429 | H25: ='5'!K25 -> 33000 | I25: ='6'!K25 -> 33000 | J25: ='7'!K25 -> 33000 | K25: ='8'!K25 -> 32857.143 | L25: ='9'!K25 -> 32857.143 | M25: ='10'!K25 -> 33428.571 | N25: ='11'!K25 -> 33857.143 | O25: ='12'!K25 -> 34000 | P25: ='13'!K25 -> 34000 | Q25: ='14'!K25 -> 34000 | R25: ='15'!K25 -> 34571.429 | S25: ='16'!K25 -> 34142.857 | T25: ='17'!K25 -> 34428.571 | U25: ='18'!K25 -> 34571.429 | V25: ='19'!K25 -> 34571.429 | W25: ='20'!K25 -> 34714.286 | X25: ='21'!K25 -> 34857.143 | Y25: ='22'!K25 -> 35285.714 | Z25: ='23'!K25 -> 35571.429 | AA25: ='24'!K25 -> 35857.143 | AB25: ='25'!K25 -> 36571.429 | AC25: ='26'!K25 -> 36428.571 | AD25: ='27'!K25 -> 36285.714 | AE25: ='28'!K25 -> 36428.571 | AF25: ='29'!K25 -> 35857.143 | AG25: ='30'!K25 -> 35714.286 | AH25: ='31'!K25 -> 35857.143 | AI25: 36750 | AJ25: =AH25-D25 -> -142.85714 | AK25: =AVERAGE(D25:AH25) -> 34608.295
A26: 6 | B26: I K A N | D26: ='1'!K26 -> 0 | E26: ='2'!K26 -> 0 | F26: ='3'!K26 -> 0 | G26: ='4'!K26 -> 0 | H26: ='5'!K26 -> 0 | I26: ='6'!K26 -> 0 | J26: ='7'!K26 -> 0 | K26: ='8'!K26 -> 0 | L26: ='9'!K26 -> 0 | M26: ='10'!K26 -> 0 | N26: ='11'!K26 -> 0 | O26: ='12'!K26 -> 0 | P26: ='13'!K26 -> 0 | Q26: ='14'!K26 -> 0 | R26: ='15'!K26 -> 0 | S26: ='16'!K26 -> 0 | T26: ='17'!K26 -> 0 | U26: ='18'!K26 -> 0 | V26: ='19'!K26 -> 0 | W26: ='20'!K26 -> 0 | X26: ='21'!K26 -> 0 | Y26: ='22'!K26 -> 0 | Z26: ='23'!K26 -> 0 | AA26: ='24'!K26 -> 0 | AB26: ='25'!K26 -> 0 | AC26: ='26'!K26 -> 0 | AD26: ='27'!K26 -> 0 | AE26: ='28'!K26 -> 0 | AF26: ='29'!K26 -> 0 | AG26: ='30'!K26 -> 0 | AH26: ='31'!K26 -> 0 | AJ26: =AH26-D26 -> 0 | AK26: =AVERAGE(D26:AH26) -> 0
B27: - Ikan Tongkol Segar (Uk. Sedang) | C27: Kg | D27: ='1'!K27 -> 35714.286 | E27: ='2'!K27 -> 35714.286 | F27: ='3'!K27 -> 35714.286 | G27: ='4'!K27 -> 35714.286 | H27: ='5'!K27 -> 35714.286 | I27: ='6'!K27 -> 35714.286 | J27: ='7'!K27 -> 35714.286 | K27: ='8'!K27 -> 39666.667 | L27: ='9'!K27 -> 38833.333 | M27: ='10'!K27 -> 38285.714 | N27: ='11'!K27 -> 38833.333 | O27: ='12'!K27 -> 38833.333 | P27: ='13'!K27 -> 38833.333 | Q27: ='14'!K27 -> 38833.333 | R27: ='15'!K27 -> 38833.333 | S27: ='16'!K27 -> 38833.333 | T27: ='17'!K27 -> 38833.333 | U27: ='18'!K27 -> 38833.333 | V27: ='19'!K27 -> 39166.667 | W27: ='20'!K27 -> 39166.667 | X27: ='21'!K27 -> 39166.667 | Y27: ='22'!K27 -> 39166.667 | Z27: ='23'!K27 -> 39166.667 | AA27: ='24'!K27 -> 39166.667 | AB27: ='25'!K27 -> 39166.667 | AC27: ='26'!K27 -> 39166.667 | AD27: ='27'!K27 -> 39166.667 | AE27: ='28'!K27 -> 39166.667 | AF27: ='29'!K27 -> 39166.667 | AG27: ='30'!K27 -> 39166.667 | AH27: ='31'!K27 -> 36666.667 | AJ27: =AH27-D27 -> 952.38095 | AK27: =AVERAGE(D27:AH27) -> 38197.389
B28: - Ikan Mujair Segar (Uk. Sedang) | C28: Kg | D28: ='1'!K28 -> 31428.571 | E28: ='2'!K28 -> 31142.857 | F28: ='3'!K28 -> 31142.857 | G28: ='4'!K28 -> 30571.429 | H28: ='5'!K28 -> 29571.429 | I28: ='6'!K28 -> 30571.429 | J28: ='7'!K28 -> 30571.429 | K28: ='8'!K28 -> 29571.429 | L28: ='9'!K28 -> 29000 | M28: ='10'!K28 -> 29000 | N28: ='11'!K28 -> 29000 | O28: ='12'!K28 -> 29714.286 | P28: ='13'!K28 -> 29714.286 | Q28: ='14'!K28 -> 29714.286 | R28: ='15'!K28 -> 29714.286 | S28: ='16'!K28 -> 29714.286 | T28: ='17'!K28 -> 29714.286 | U28: ='18'!K28 -> 29714.286 | V28: ='19'!K28 -> 29142.857 | W28: ='20'!K28 -> 29142.857 | X28: ='21'!K28 -> 29142.857 | Y28: ='22'!K28 -> 29142.857 | Z28: ='23'!K28 -> 29142.857 | AA28: ='24'!K28 -> 29142.857 | AB28: ='25'!K28 -> 29142.857 | AC28: ='26'!K28 -> 29428.571 | AD28: ='27'!K28 -> 29714.286 | AE28: ='28'!K28 -> 29714.286 | AF28: ='29'!K28 -> 29428.571 | AG28: ='30'!K28 -> 29428.571 | AH28: ='31'!K28 -> 27714.286 | AJ28: =AH28-D28 -> -3714.2857 | AK28: =AVERAGE(D28:AH28) -> 29645.161
B29: - Udang Segar (Uk. Sedang) | C29: Kg | D29: ='1'!K29 -> 67142.857 | E29: ='2'!K29 -> 66142.857 | F29: ='3'!K29 -> 67571.429 | G29: ='4'!K29 -> 67285.714 | H29: ='5'!K29 -> 65857.143 | I29: ='6'!K29 -> 67285.714 | J29: ='7'!K29 -> 67285.714 | K29: ='8'!K29 -> 65857.143 | L29: ='9'!K29 -> 65857.143 | M29: ='10'!K29 -> 65857.143 | N29: ='11'!K29 -> 65857.143 | O29: ='12'!K29 -> 65857.143 | P29: ='13'!K29 -> 65857.143 | Q29: ='14'!K29 -> 65857.143 | R29: ='15'!K29 -> 65857.143 | S29: ='16'!K29 -> 64714.286 | T29: ='17'!K29 -> 64714.286 | U29: ='18'!K29 -> 64714.286 | V29: ='19'!K29 -> 64714.286 | W29: ='20'!K29 -> 64714.286 | X29: ='21'!K29 -> 64714.286 | Y29: ='22'!K29 -> 64714.286 | Z29: ='23'!K29 -> 64714.286 | AA29: ='24'!K29 -> 64714.286 | AB29: ='25'!K29 -> 64714.286 | AC29: ='26'!K29 -> 64714.286 | AD29: ='27'!K29 -> 64714.286 | AE29: ='28'!K29 -> 64714.286 | AF29: ='29'!K29 -> 64714.286 | AG29: ='30'!K29 -> 64714.286 | AH29: ='31'!K29 -> 64714.286 | AJ29: =AH29-D29 -> -2428.5714 | AK29: =AVERAGE(D29:AH29) -> 65511.521
B30: - Ikan Lele Segar (Ukuran Sedang) | C30: Kg | D30: ='1'!K30 -> 24600 | E30: ='2'!K30 -> 24600 | F30: ='3'!K30 -> 24600 | G30: ='4'!K30 -> 24600 | H30: ='5'!K30 -> 24600 | I30: ='6'!K30 -> 24600 | J30: ='7'!K30 -> 24600 | K30: ='8'!K30 -> 24600 | L30: ='9'!K30 -> 24600 | M30: ='10'!K30 -> 24600 | N30: ='11'!K30 -> 24600 | O30: ='12'!K30 -> 24600 | P30: ='13'!K30 -> 24600 | Q30: ='14'!K30 -> 24600 | R30: ='15'!K30 -> 24600 | S30: ='16'!K30 -> 24600 | T30: ='17'!K30 -> 24600 | U30: ='18'!K30 -> 24600 | V30: ='19'!K30 -> 24600 | W30: ='20'!K30 -> 24600 | X30: ='21'!K30 -> 24600 | Y30: ='22'!K30 -> 24600 | Z30: ='23'!K30 -> 24600 | AA30: ='24'!K30 -> 24600 | AB30: ='25'!K30 -> 24600 | AC30: ='26'!K30 -> 24600 | AD30: ='27'!K30 -> 24600 | AE30: ='28'!K30 -> 24600 | AF30: ='29'!K30 -> 24600 | AG30: ='30'!K30 -> 24600 | AH30: ='31'!K30 -> 24600 | AJ30: =AH30-D30 -> 0 | AK30: =AVERAGE(D30:AH30) -> 24600
B31: - Ikan Bandeng Segar (Uk. Sedang) | C31: Kg | D31: ='1'!K31 -> 38428.571 | E31: ='2'!K31 -> 38428.571 | F31: ='3'!K31 -> 38428.571 | G31: ='4'!K31 -> 38428.571 | H31: ='5'!K31 -> 38428.571 | I31: ='6'!K31 -> 38428.571 | J31: ='7'!K31 -> 38428.571 | K31: ='8'!K31 -> 38428.571 | L31: ='9'!K31 -> 39142.857 | M31: ='10'!K31 -> 38428.571 | N31: ='11'!K31 -> 39142.857 | O31: ='12'!K31 -> 39142.857 | P31: ='13'!K31 -> 39142.857 | Q31: ='14'!K31 -> 39142.857 | R31: ='15'!K31 -> 39142.857 | S31: ='16'!K31 -> 39428.571 | T31: ='17'!K31 -> 39428.571 | U31: ='18'!K31 -> 39428.571 | V31: ='19'!K31 -> 39285.714 | W31: ='20'!K31 -> 39285.714 | X31: ='21'!K31 -> 39285.714 | Y31: ='22'!K31 -> 39285.714 | Z31: ='23'!K31 -> 39285.714 | AA31: ='24'!K31 -> 39285.714 | AB31: ='25'!K31 -> 39285.714 | AC31: ='26'!K31 -> 39000 | AD31: ='27'!K31 -> 39000 | AE31: ='28'!K31 -> 39000 | AF31: ='29'!K31 -> 39000 | AG31: ='30'!K31 -> 39000 | AH31: ='31'!K31 -> 37000 | AJ31: =AH31-D31 -> -1428.5714 | AK31: =AVERAGE(D31:AH31) -> 38903.226
B32: - Ikan Teri Asin (Bukan Teri Medan) | C32: Kg | D32: ='1'!K32 -> 103333.33 | E32: ='2'!K32 -> 96666.667 | F32: ='3'!K32 -> 103333.33 | G32: ='4'!K32 -> 91666.667 | H32: ='5'!K32 -> 96666.667 | I32: ='6'!K32 -> 91666.667 | J32: ='7'!K32 -> 91666.667 | K32: ='8'!K32 -> 96666.667 | L32: ='9'!K32 -> 96666.667 | M32: ='10'!K32 -> 96666.667 | N32: ='11'!K32 -> 96666.667 | O32: ='12'!K32 -> 96666.667 | P32: ='13'!K32 -> 91000 | Q32: ='14'!K32 -> 91000 | R32: ='15'!K32 -> 96666.667 | S32: ='16'!K32 -> 96666.667 | T32: ='17'!K32 -> 96666.667 | U32: ='18'!K32 -> 96666.667 | V32: ='19'!K32 -> 96666.667 | W32: ='20'!K32 -> 96666.667 | X32: ='21'!K32 -> 96666.667 | Y32: ='22'!K32 -> 96666.667 | Z32: ='23'!K32 -> 96666.667 | AA32: ='24'!K32 -> 96666.667 | AB32: ='25'!K32 -> 96666.667 | AC32: ='26'!K32 -> 96666.667 | AD32: ='27'!K32 -> 96666.667 | AE32: ='28'!K32 -> 96666.667 | AF32: ='29'!K32 -> 96666.667 | AG32: ='30'!K32 -> 96666.667 | AH32: ='31'!K32 -> 96666.667 | AJ32: =AH32-D32 -> -6666.6667 | AK32: =AVERAGE(D32:AH32) -> 96247.312
A33: 7 | B33: TELUR | D33: ='1'!K33 -> 0 | E33: ='2'!K33 -> 0 | F33: ='3'!K33 -> 0 | G33: ='4'!K33 -> 0 | H33: ='5'!K33 -> 0 | I33: ='6'!K33 -> 0 | J33: ='7'!K33 -> 0 | K33: ='8'!K33 -> 0 | L33: ='9'!K33 -> 0 | M33: ='10'!K33 -> 0 | N33: ='11'!K33 -> 0 | O33: ='12'!K33 -> 0 | P33: ='13'!K33 -> 0 | Q33: ='14'!K33 -> 0 | R33: ='15'!K33 -> 0 | S33: ='16'!K33 -> 0 | T33: ='17'!K33 -> 0 | U33: ='18'!K33 -> 0 | V33: ='19'!K33 -> 0 | W33: ='20'!K33 -> 0 | X33: ='21'!K33 -> 0 | Y33: ='22'!K33 -> 0 | Z33: ='23'!K33 -> 0 | AA33: ='24'!K33 -> 0 | AB33: ='25'!K33 -> 0 | AC33: ='26'!K33 -> 0 | AD33: ='27'!K33 -> 0 | AE33: ='28'!K33 -> 0 | AF33: ='29'!K33 -> 0 | AG33: ='30'!K33 -> 0 | AH33: ='31'!K33 -> 0 | AJ33: =AH33-D33 -> 0 | AK33: =AVERAGE(D33:AH33) -> 0
B34: - Telur Ayam Broiler | C34: Kg | D34: ='1'!K34 -> 27142.857 | E34: ='2'!K34 -> 26714.286 | F34: ='3'!K34 -> 27000 | G34: ='4'!K34 -> 27285.714 | H34: ='5'!K34 -> 27785.714 | I34: ='6'!K34 -> 28214.286 | J34: ='7'!K34 -> 28214.286 | K34: ='8'!K34 -> 28142.857 | L34: ='9'!K34 -> 28714.286 | M34: ='10'!K34 -> 29000 | N34: ='11'!K34 -> 29142.857 | O34: ='12'!K34 -> 29428.571 | P34: ='13'!K34 -> 30142.857 | Q34: ='14'!K34 -> 30428.571 | R34: ='15'!K34 -> 30714.286 | S34: ='16'!K34 -> 31428.571 | T34: ='17'!K34 -> 31142.857 | U34: ='18'!K34 -> 30857.143 | V34: ='19'!K34 -> 31285.714 | W34: ='20'!K34 -> 31571.429 | X34: ='21'!K34 -> 31714.286 | Y34: ='22'!K34 -> 31357.143 | Z34: ='23'!K34 -> 31214.286 | AA34: ='24'!K34 -> 30642.857 | AB34: ='25'!K34 -> 30571.429 | AC34: ='26'!K34 -> 30428.571 | AD34: ='27'!K34 -> 30428.571 | AE34: ='28'!K34 -> 30571.429 | AF34: ='29'!K34 -> 30214.286 | AG34: ='30'!K34 -> 30214.286 | AH34: ='31'!K34 -> 29928.571 | AI34: 27000 | AJ34: =AH34-D34 -> 2785.7143 | AK34: =AVERAGE(D34:AH34) -> 29730.415
B35: - Telur Ayam Kampung | C35: Butir | D35: ='1'!K35 -> 2457.1429 | E35: ='2'!K35 -> 2385.7143 | F35: ='3'!K35 -> 2457.1429 | G35: ='4'!K35 -> 2385.7143 | H35: ='5'!K35 -> 2385.7143 | I35: ='6'!K35 -> 2385.7143 | J35: ='7'!K35 -> 2385.7143 | K35: ='8'!K35 -> 2385.7143 | L35: ='9'!K35 -> 2385.7143 | M35: ='10'!K35 -> 2485.7143 | N35: ='11'!K35 -> 2414.2857 | O35: ='12'!K35 -> 2414.2857 | P35: ='13'!K35 -> 2414.2857 | Q35: ='14'!K35 -> 2414.2857 | R35: ='15'!K35 -> 2414.2857 | S35: ='16'!K35 -> 2414.2857 | T35: ='17'!K35 -> 2414.2857 | U35: ='18'!K35 -> 2414.2857 | V35: ='19'!K35 -> 2414.2857 | W35: ='20'!K35 -> 2414.2857 | X35: ='21'!K35 -> 2414.2857 | Y35: ='22'!K35 -> 2414.2857 | Z35: ='23'!K35 -> 2414.2857 | AA35: ='24'!K35 -> 2414.2857 | AB35: ='25'!K35 -> 2414.2857 | AC35: ='26'!K35 -> 2414.2857 | AD35: ='27'!K35 -> 2414.2857 | AE35: ='28'!K35 -> 2414.2857 | AF35: ='29'!K35 -> 2414.2857 | AG35: ='30'!K35 -> 2414.2857 | AH35: ='31'!K35 -> 2414.2857 | AJ35: =AH35-D35 -> -42.857143 | AK35: =AVERAGE(D35:AH35) -> 2412.9032
A36: 8 | B36: TAHU | D36: ='1'!K36 -> 0 | E36: ='2'!K36 -> 0 | F36: ='3'!K36 -> 0 | G36: ='4'!K36 -> 0 | H36: ='5'!K36 -> 0 | I36: ='6'!K36 -> 0 | J36: ='7'!K36 -> 0 | K36: ='8'!K36 -> 0 | L36: ='9'!K36 -> 0 | M36: ='10'!K36 -> 0 | N36: ='11'!K36 -> 0 | O36: ='12'!K36 -> 0 | P36: ='13'!K36 -> 0 | Q36: ='14'!K36 -> 0 | R36: ='15'!K36 -> 0 | S36: ='16'!K36 -> 0 | T36: ='17'!K36 -> 0 | U36: ='18'!K36 -> 0 | V36: ='19'!K36 -> 0 | W36: ='20'!K36 -> 0 | X36: ='21'!K36 -> 0 | Y36: ='22'!K36 -> 0 | Z36: ='23'!K36 -> 0 | AA36: ='24'!K36 -> 0 | AB36: ='25'!K36 -> 0 | AC36: ='26'!K36 -> 0 | AD36: ='27'!K36 -> 0 | AE36: ='28'!K36 -> 0 | AF36: ='29'!K36 -> 0 | AG36: ='30'!K36 -> 0 | AH36: ='31'!K36 -> 0 | AJ36: =AH36-D36 -> 0 | AK36: =AVERAGE(D36:AH36) -> 0
B37: - Tahu biasa | C37: Kg | D37: ='1'!K37 -> 11142.857 | E37: ='2'!K37 -> 11142.857 | F37: ='3'!K37 -> 11142.857 | G37: ='4'!K37 -> 11142.857 | H37: ='5'!K37 -> 11142.857 | I37: ='6'!K37 -> 10714.286 | J37: ='7'!K37 -> 9857.1429 | K37: ='8'!K37 -> 10714.286 | L37: ='9'!K37 -> 10714.286 | M37: ='10'!K37 -> 10714.286 | N37: ='11'!K37 -> 10714.286 | O37: ='12'!K37 -> 10714.286 | P37: ='13'!K37 -> 10714.286 | Q37: ='14'!K37 -> 10285.714 | R37: ='15'!K37 -> 10714.286 | S37: ='16'!K37 -> 10714.286 | T37: ='17'!K37 -> 10714.286 | U37: ='18'!K37 -> 10714.286 | V37: ='19'!K37 -> 10714.286 | W37: ='20'!K37 -> 10714.286 | X37: ='21'!K37 -> 10714.286 | Y37: ='22'!K37 -> 10714.286 | Z37: ='23'!K37 -> 10714.286 | AA37: ='24'!K37 -> 10714.286 | AB37: ='25'!K37 -> 10714.286 | AC37: ='26'!K37 -> 10714.286 | AD37: ='27'!K37 -> 9857.1429 | AE37: ='28'!K37 -> 9857.1429 | AF37: ='29'!K37 -> 9857.1429 | AG37: ='30'!K37 -> 9857.1429 | AH37: ='31'!K37 -> 9857.1429 | AJ37: =AH37-D37 -> -1285.7143 | AK37: =AVERAGE(D37:AH37) -> 10603.687
B38: - Tahu susu | C38: Kg | D38: ='1'!K38 -> 12400 | E38: ='2'!K38 -> 12600 | F38: ='3'!K38 -> 12800 | G38: ='4'!K38 -> 12600 | H38: ='5'!K38 -> 12600 | I38: ='6'!K38 -> 12600 | J38: ='7'!K38 -> 12600 | K38: ='8'!K38 -> 12600 | L38: ='9'!K38 -> 12600 | M38: ='10'!K38 -> 12600 | N38: ='11'!K38 -> 12600 | O38: ='12'!K38 -> 12600 | P38: ='13'!K38 -> 12600 | Q38: ='14'!K38 -> 12600 | R38: ='15'!K38 -> 12600 | S38: ='16'!K38 -> 12600 | T38: ='17'!K38 -> 12600 | U38: ='18'!K38 -> 12600 | V38: ='19'!K38 -> 12600 | W38: ='20'!K38 -> 12600 | X38: ='21'!K38 -> 12600 | Y38: ='22'!K38 -> 12600 | Z38: ='23'!K38 -> 12600 | AA38: ='24'!K38 -> 12600 | AB38: ='25'!K38 -> 12600 | AC38: ='26'!K38 -> 12600 | AD38: ='27'!K38 -> 12600 | AE38: ='28'!K38 -> 12600 | AF38: ='29'!K38 -> 12600 | AG38: ='30'!K38 -> 12600 | AH38: ='31'!K38 -> 12600 | AJ38: =AH38-D38 -> 200 | AK38: =AVERAGE(D38:AH38) -> 12600
A39: 9 | B39: TEMPE | D39: ='1'!K39 -> 0 | E39: ='2'!K39 -> 0 | F39: ='3'!K39 -> 0 | G39: ='4'!K39 -> 0 | H39: ='5'!K39 -> 0 | I39: ='6'!K39 -> 0 | J39: ='7'!K39 -> 0 | K39: ='8'!K39 -> 0 | L39: ='9'!K39 -> 0 | M39: ='10'!K39 -> 0 | N39: ='11'!K39 -> 0 | O39: ='12'!K39 -> 0 | P39: ='13'!K39 -> 0 | Q39: ='14'!K39 -> 0 | R39: ='15'!K39 -> 0 | S39: ='16'!K39 -> 0 | T39: ='17'!K39 -> 0 | U39: ='18'!K39 -> 0 | V39: ='19'!K39 -> 0 | W39: ='20'!K39 -> 0 | X39: ='21'!K39 -> 0 | Y39: ='22'!K39 -> 0 | Z39: ='23'!K39 -> 0 | AA39: ='24'!K39 -> 0 | AB39: ='25'!K39 -> 0 | AC39: ='26'!K39 -> 0 | AD39: ='27'!K39 -> 0 | AE39: ='28'!K39 -> 0 | AF39: ='29'!K39 -> 0 | AG39: ='30'!K39 -> 0 | AH39: ='31'!K39 -> 0 | AJ39: =AH39-D39 -> 0 | AK39: =AVERAGE(D39:AH39) -> 0
B40: - Tempe Kw I (campuran kedelai) | C40: Kg | D40: ='1'!K40 -> 15600 | E40: ='2'!K40 -> 15600 | F40: ='3'!K40 -> 15600 | G40: ='4'!K40 -> 15600 | H40: ='5'!K40 -> 15600 | I40: ='6'!K40 -> 15600 | J40: ='7'!K40 -> 15600 | K40: ='8'!K40 -> 15600 | L40: ='9'!K40 -> 15600 | M40: ='10'!K40 -> 15600 | N40: ='11'!K40 -> 15600 | O40: ='12'!K40 -> 15600 | P40: ='13'!K40 -> 15600 | Q40: ='14'!K40 -> 15600 | R40: ='15'!K40 -> 15600 | S40: ='16'!K40 -> 15600 | T40: ='17'!K40 -> 15600 | U40: ='18'!K40 -> 15600 | V40: ='19'!K40 -> 15600 | W40: ='20'!K40 -> 15600 | X40: ='21'!K40 -> 15600 | Y40: ='22'!K40 -> 15600 | Z40: ='23'!K40 -> 15600 | AA40: ='24'!K40 -> 15600 | AB40: ='25'!K40 -> 15600 | AC40: ='26'!K40 -> 15600 | AD40: ='27'!K40 -> 15600 | AE40: ='28'!K40 -> 15600 | AF40: ='29'!K40 -> 15600 | AG40: ='30'!K40 -> 15600 | AH40: ='31'!K40 -> 15600 | AJ40: =AH40-D40 -> 0 | AK40: =AVERAGE(D40:AH40) -> 15600
B41: - Tempe Kw II (campuran jagung) | C41: Kg | D41: ='1'!K41 -> 6833.3333 | E41: ='2'!K41 -> 6833.3333 | F41: ='3'!K41 -> 6833.3333 | G41: ='4'!K41 -> 6833.3333 | H41: ='5'!K41 -> 6833.3333 | I41: ='6'!K41 -> 6833.3333 | J41: ='7'!K41 -> 6833.3333 | K41: ='8'!K41 -> 6833.3333 | L41: ='9'!K41 -> 6833.3333 | M41: ='10'!K41 -> 6833.3333 | N41: ='11'!K41 -> 6833.3333 | O41: ='12'!K41 -> 6833.3333 | P41: ='13'!K41 -> 6833.3333 | Q41: ='14'!K41 -> 6833.3333 | R41: ='15'!K41 -> 6833.3333 | S41: ='16'!K41 -> 6833.3333 | T41: ='17'!K41 -> 6833.3333 | U41: ='18'!K41 -> 6833.3333 | V41: ='19'!K41 -> 6833.3333 | W41: ='20'!K41 -> 6833.3333 | X41: ='21'!K41 -> 6833.3333 | Y41: ='22'!K41 -> 6833.3333 | Z41: ='23'!K41 -> 6833.3333 | AA41: ='24'!K41 -> 6833.3333 | AB41: ='25'!K41 -> 6833.3333 | AC41: ='26'!K41 -> 6833.3333 | AD41: ='27'!K41 -> 6833.3333 | AE41: ='28'!K41 -> 6833.3333 | AF41: ='29'!K41 -> 6833.3333 | AG41: ='30'!K41 -> 6833.3333 | AH41: ='31'!K41 -> 6833.3333 | AJ41: =AH41-D41 -> 0 | AK41: =AVERAGE(D41:AH41) -> 6833.3333
...

Sheet GRAFIK
A1: BAGIAN PEREKONOMIAN DAN SUMBER DAYA ALAM
A2: GRAFIK LAPORAN HARGA BAHAN POKOK DI KOTA SURABAYA
A3: PERIODE MEI 2023
C4: 1 | D4: 2 | E4: 3 | F4: 4 | G4: 5 | H4: 6 | I4: 7 | J4: 8 | K4: 9 | L4: 10 | M4: 11 | N4: 12 | O4: 13 | P4: 14 | Q4: 15 | R4: 16 | S4: 17 | T4: 18 | U4: 19 | V4: 20 | W4: 21 | X4: 22 | Y4: 23 | Z4: 24 | AA4: 25 | AB4: 26 | AC4: 27 | AD4: 28 | AE4: 29 | AF4: 30 | AG4: 31
A5: - Gula pasir lokal curah | B5: Kg | C5: ='1'!K14 -> 13071.429 | D5: ='2'!K14 -> 13214.286 | E5: ='3'!K14 -> 13142.857 | F5: ='4'!K14 -> 13214.286 | G5: ='5'!K14 -> 13214.286 | H5: ='6'!K14 -> 13285.714 | I5: ='7'!K14 -> 13357.143 | J5: ='8'!K14 -> 13285.714 | K5: ='9'!K14 -> 13357.143 | L5: ='10'!K14 -> 13357.143 | M5: ='11'!K14 -> 13357.143 | N5: ='12'!K14 -> 13357.143 | O5: ='13'!K14 -> 13357.143 | P5: ='14'!K14 -> 13357.143 | Q5: ='15'!K14 -> 13357.143 | R5: ='16'!K14 -> 13357.143 | S5: ='17'!K14 -> 13357.143 | T5: ='18'!K14 -> 13357.143 | U5: ='19'!K14 -> 13500 | V5: ='20'!K14 -> 13428.571 | W5: ='21'!K14 -> 13428.571 | X5: ='22'!K14 -> 13571.429 | Y5: ='23'!K14 -> 13571.429 | Z5: ='24'!K14 -> 13571.429 | AA5: ='25'!K14 -> 13571.429 | AB5: ='26'!K14 -> 13571.429 | AC5: ='27'!K14 -> 13500 | AD5: ='28'!K14 -> 13500 | AE5: ='29'!K14 -> 13571.429 | AF5: ='30'!K14 -> 13571.429 | AG5: ='31'!K14 -> 13571.429
C24: 1 | D24: 2 | E24: 3 | F24: 4 | G24: 5 | H24: 6 | I24: 7 | J24: 8 | K24: 9 | L24: 10 | M24: 11 | N24: 12 | O24: 13 | P24: 14 | Q24: 15 | R24: 16 | S24: 17 | T24: 18 | U24: 19 | V24: 20 | W24: 21 | X24: 22 | Y24: 23 | Z24: 24 | AA24: 25 | AB24: 26 | AC24: 27 | AD24: 28 | AE24: 29 | AF24: 30 | AG24: 31
A25: - Daging Ayam Broiler | B25: Kg | C25: ='1'!K25 -> 36000 | D25: ='2'!K25 -> 34000 | E25: ='3'!K25 -> 33571.429 | F25: ='4'!K25 -> 33571.429 | G25: ='5'!K25 -> 33000 | H25: ='6'!K25 -> 33000 | I25: ='7'!K25 -> 33000 | J25: ='8'!K25 -> 32857.143 | K25: ='9'!K25 -> 32857.143 | L25: ='10'!K25 -> 33428.571 | M25: ='11'!K25 -> 33857.143 | N25: ='12'!K25 -> 34000 | O25: ='13'!K25 -> 34000 | P25: ='14'!K25 -> 34000 | Q25: ='15'!K25 -> 34571.429 | R25: ='16'!K25 -> 34142.857 | S25: ='17'!K25 -> 34428.571 | T25: ='18'!K25 -> 34571.429 | U25: ='19'!K25 -> 34571.429 | V25: ='20'!K25 -> 34714.286 | W25: ='21'!K25 -> 34857.143 | X25: ='22'!K25 -> 35285.714 | Y25: ='23'!K25 -> 35571.429 | Z25: ='24'!K25 -> 35857.143 | AA25: ='25'!K25 -> 36571.429 | AB25: ='26'!K25 -> 36428.571 | AC25: ='27'!K25 -> 36285.714 | AD25: ='28'!K25 -> 36428.571 | AE25: ='29'!K25 -> 35857.143 | AF25: ='30'!K25 -> 35714.286 | AG25: ='31'!K25 -> 35857.143
C44: 1 | D44: 2 | E44: 3 | F44: 4 | G44: 5 | H44: 6 | I44: 7 | J44: 8 | K44: 9 | L44: 10 | M44: 11 | N44: 12 | O44: 13 | P44: 14 | Q44: 15 | R44: 16 | S44: 17 | T44: 18 | U44: 19 | V44: 20 | W44: 21 | X44: 22 | Y44: 23 | Z44: 24 | AA44: 25 | AB44: 26 | AC44: 27 | AD44: 28 | AE44: 29 | AF44: 30 | AG44: 31
A45: - Telur Ayam Broiler | B45: Kg | C45: ='1'!K34 -> 27142.857 | D45: ='2'!K34 -> 26714.286 | E45: ='3'!K34 -> 27000 | F45: ='4'!K34 -> 27285.714 | G45: ='5'!K34 -> 27785.714 | H45: ='6'!K34 -> 28214.286 | I45: ='7'!K34 -> 28214.286 | J45: ='8'!K34 -> 28142.857 | K45: ='9'!K34 -> 28714.286 | L45: ='10'!K34 -> 29000 | M45: ='11'!K34 -> 29142.857 | N45: ='12'!K34 -> 29428.571 | O45: ='13'!K34 -> 30142.857 | P45: ='14'!K34 -> 30428.571 | Q45: ='15'!K34 -> 30714.286 | R45: ='16'!K34 -> 31428.571 | S45: ='17'!K34 -> 31142.857 | T45: ='18'!K34 -> 30857.143 | U45: ='19'!K34 -> 31285.714 | V45: ='20'!K34 -> 31571.429 | W45: ='21'!K34 -> 31714.286 | X45: ='22'!K34 -> 31357.143 | Y45: ='23'!K34 -> 31214.286 | Z45: ='24'!K34 -> 30642.857 | AA45: ='25'!K34 -> 30571.429 | AB45: ='26'!K34 -> 30428.571 | AC45: ='27'!K34 -> 30428.571 | AD45: ='28'!K34 -> 30571.429 | AE45: ='29'!K34 -> 30214.286 | AF45: ='30'!K34 -> 30214.286 | AG45: ='31'!K34 -> 29928.571
C68: 1 | D68: 2 | E68: 3 | F68: 4 | G68: 5 | H68: 6 | I68: 7 | J68: 8 | K68: 9 | L68: 10 | M68: 11 | N68: 12 | O68: 13 | P68: 14 | Q68: 15 | R68: 16 | S68: 17 | T68: 18 | U68: 19 | V68: 20 | W68: 21 | X68: 22 | Y68: 23 | Z68: 24 | AA68: 25 | AB68: 26 | AC68: 27 | AD68: 28 | AE68: 29 | AF68: 30 | AG68: 31
A69: - Cabe Merah Besar | B69: Kg | C69: ='1'!K64 -> 28857.143 | D69: ='2'!K64 -> 29857.143 | E69: ='3'!K64 -> 29571.429 | F69: ='4'!K64 -> 29714.286 | G69: ='5'!K64 -> 29285.714 | H69: ='6'!K64 -> 30714.286 | I69: ='7'!K64 -> 30000 | J69: ='8'!K64 -> 28714.286 | K69: ='9'!K64 -> 31571.429 | L69: ='10'!K64 -> 31857.143 | M69: ='11'!K64 -> 31857.143 | N69: ='12'!K64 -> 32571.429 | O69: ='13'!K64 -> 32857.143 | P69: ='14'!K64 -> 32857.143 | Q69: ='15'!K64 -> 33285.714 | R69: ='16'!K64 -> 34000 | S69: ='17'!K64 -> 34285.714 | T69: ='18'!K64 -> 34285.714 | U69: ='19'!K64 -> 32142.857 | V69: ='20'!K64 -> 32857.143 | W69: ='21'!K64 -> 33142.857 | X69: ='22'!K64 -> 32428.571 | Y69: ='23'!K64 -> 32571.429 | Z69: ='24'!K64 -> 31285.714 | AA69: ='25'!K64 -> 30142.857 | AB69: ='26'!K64 -> 30857.143 | AC69: ='27'!K64 -> 32142.857 | AD69: ='28'!K64 -> 30714.286 | AE69: ='29'!K64 -> 30714.286 | AF69: ='30'!K64 -> 31428.571 | AG69: ='31'!K64 -> 31428.571
A70: - Cabe Merah Kriting | B70: Kg | C70: ='1'!K65 -> 36250 | D70: ='2'!K65 -> 30750 | E70: ='3'!K65 -> 31250 | F70: ='4'!K65 -> 31250 | G70: ='5'!K65 -> 31250 | H70: ='6'!K65 -> 31250 | I70: ='7'!K65 -> 33000 | J70: ='8'!K65 -> 31000 | K70: ='9'!K65 -> 34000 | L70: ='10'!K65 -> 31000 | M70: ='11'!K65 -> 31000 | N70: ='12'!K65 -> 31000 | O70: ='13'!K65 -> 30000 | P70: ='14'!K65 -> 30000 | Q70: ='15'!K65 -> 30000 | R70: ='16'!K65 -> 30000 | S70: ='17'!K65 -> 30000 | T70: ='18'!K65 -> 30000 | U70: ='19'!K65 -> 28000 | V70: ='20'!K65 -> 30000 | W70: ='21'!K65 -> 29000 | X70: ='22'!K65 -> 29000 | Y70: ='23'!K65 -> 29000 | Z70: ='24'!K65 -> 29000 | AA70: ='25'!K65 -> 29000 | AB70: ='26'!K65 -> 28800 | AC70: ='27'!K65 -> 30000 | AD70: ='28'!K65 -> 27000 | AE70: ='29'!K65 -> 27600 | AF70: ='30'!K65 -> 26600 | AG70: ='31'!K65 -> 26000
A71: - Cabe Merah Kecil-Rawit | B71: Kg | C71: ='1'!K66 -> 26285.714 | D71: ='2'!K66 -> 27857.143 | E71: ='3'!K66 -> 26428.571 | F71: ='4'!K66 -> 26857.143 | G71: ='5'!K66 -> 27142.857 | H71: ='6'!K66 -> 27857.143 | I71: ='7'!K66 -> 26428.571 | J71: ='8'!K66 -> 26428.571 | K71: ='9'!K66 -> 27142.857 | L71: ='10'!K66 -> 28571.429 | M71: ='11'!K66 -> 29571.429 | N71: ='12'!K66 -> 31142.857 | O71: ='13'!K66 -> 31142.857 | P71: ='14'!K66 -> 31857.143 | Q71: ='15'!K66 -> 31857.143 | R71: ='16'!K66 -> 32571.429 | S71: ='17'!K66 -> 32714.286 | T71: ='18'!K66 -> 32428.571 | U71: ='19'!K66 -> 34285.714 | V71: ='20'!K66 -> 34428.571 | W71: ='21'!K66 -> 35714.286 | X71: ='22'!K66 -> 35428.571 | Y71: ='23'!K66 -> 35428.571 | Z71: ='24'!K66 -> 35428.571 | AA71: ='25'!K66 -> 36428.571 | AB71: ='26'!K66 -> 37857.143 | AC71: ='27'!K66 -> 35714.286 | AD71: ='28'!K66 -> 35714.286 | AE71: ='29'!K66 -> 36857.143 | AF71: ='30'!K66 -> 37428.571 | AG71: ='31'!K66 -> 37857.143
C89: 1 | D89: 2 | E89: 3 | F89: 4 | G89: 5 | H89: 6 | I89: 7 | J89: 8 | K89: 9 | L89: 10 | M89: 11 | N89: 12 | O89: 13 | P89: 14 | Q89: 15 | R89: 16 | S89: 17 | T89: 18 | U89: 19 | V89: 20 | W89: 21 | X89: 22 | Y89: 23 | Z89: 24 | AA89: 25 | AB89: 26 | AC89: 27 | AD89: 28 | AE89: 29 | AF89: 30 | AG89: 31
A90: - Bawang Putih (Jenis Kating) | B90: Kg | C90: ='1'!K70 -> 34857.143 | D90: ='2'!K70 -> 35000 | E90: ='3'!K70 -> 35428.571 | F90: ='4'!K70 -> 34571.429 | G90: ='5'!K70 -> 34428.571 | H90: ='6'!K70 -> 35428.571 | I90: ='7'!K70 -> 35428.571 | J90: ='8'!K70 -> 35857.143 | K90: ='9'!K70 -> 36000 | L90: ='10'!K70 -> 35857.143 | M90: ='11'!K70 -> 36000 | N90: ='12'!K70 -> 35714.286 | O90: ='13'!K70 -> 36000 | P90: ='14'!K70 -> 36000 | Q90: ='15'!K70 -> 36428.571 | R90: ='16'!K70 -> 35714.286 | S90: ='17'!K70 -> 35857.143 | T90: ='18'!K70 -> 35857.143 | U90: ='19'!K70 -> 36142.857 | V90: ='20'!K70 -> 36000 | W90: ='21'!K70 -> 36142.857 | X90: ='22'!K70 -> 36714.286 | Y90: ='23'!K70 -> 37000 | Z90: ='24'!K70 -> 36142.857 | AA90: ='25'!K70 -> 35857.143 | AB90: ='26'!K70 -> 36285.714 | AC90: ='27'!K70 -> 36142.857 | AD90: ='28'!K70 -> 36142.857 | AE90: ='29'!K70 -> 36142.857 | AF90: ='30'!K70 -> 36428.571 | AG90: ='31'!K70 -> 36428.571
A91: - Bawang Putih (Jenis Sinco) | B91: Kg | C91: ='1'!K71 -> 30571.429 | D91: ='2'!K71 -> 30142.857 | E91: ='3'!K71 -> 31142.857 | F91: ='4'!K71 -> 30857.143 | G91: ='5'!K71 -> 31142.857 | H91: ='6'!K71 -> 31714.286 | I91: ='7'!K71 -> 31714.286 | J91: ='8'!K71 -> 31428.571 | K91: ='9'!K71 -> 31714.286 | L91: ='10'!K71 -> 32428.571 | M91: ='11'!K71 -> 32714.286 | N91: ='12'!K71 -> 33000 | O91: ='13'!K71 -> 32714.286 | P91: ='14'!K71 -> 32714.286 | Q91: ='15'!K71 -> 33142.857 | R91: ='16'!K71 -> 32285.714 | S91: ='17'!K71 -> 32142.857 | T91: ='18'!K71 -> 32142.857 | U91: ='19'!K71 -> 32571.429 | V91: ='20'!K71 -> 32571.429 | W91: ='21'!K71 -> 32714.286 | X91: ='22'!K71 -> 32714.286 | Y91: ='23'!K71 -> 33285.714 | Z91: ='24'!K71 -> 32714.286 | AA91: ='25'!K71 -> 32714.286 | AB91: ='26'!K71 -> 32714.286 | AC91: ='27'!K71 -> 32714.286 | AD91: ='28'!K71 -> 32714.286 | AE91: ='29'!K71 -> 33428.571 | AF91: ='30'!K71 -> 34000 | AG91: ='31'!K71 -> 33714.286
A92: - Bawang Merah (Kualitas Lokal) | B92: Kg | C92: ='1'!K72 -> 42285.714 | D92: ='2'!K72 -> 41428.571 | E92: ='3'!K72 -> 40857.143 | F92: ='4'!K72 -> 40428.571 | G92: ='5'!K72 -> 40714.286 | H92: ='6'!K72 -> 40857.143 | I92: ='7'!K72 -> 40857.143 | J92: ='8'!K72 -> 40000 | K92: ='9'!K72 -> 39857.143 | L92: ='10'!K72 -> 39428.571 | M92: ='11'!K72 -> 39000 | N92: ='12'!K72 -> 38142.857 | O92: ='13'!K72 -> 37428.571 | P92: ='14'!K72 -> 37428.571 | Q92: ='15'!K72 -> 36714.286 | R92: ='16'!K72 -> 36714.286 | S92: ='17'!K72 -> 37714.286 | T92: ='18'!K72 -> 37714.286 | U92: ='19'!K72 -> 37142.857 | V92: ='20'!K72 -> 37142.857 | W92: ='21'!K72 -> 37000 | X92: ='22'!K72 -> 37142.857 | Y92: ='23'!K72 -> 37142.857 | Z92: ='24'!K72 -> 37571.429 | AA92: ='25'!K72 -> 37285.714 | AB92: ='26'!K72 -> 36714.286 | AC92: ='27'!K72 -> 37857.143 | AD92: ='28'!K72 -> 35714.286 | AE92: ='29'!K72 -> 35000 | AF92: ='30'!K72 -> 35428.571 | AG92: ='31'!K72 -> 35000
A93: - Bawang Bombay | B93: Kg | C93: ='1'!K73 -> 39571.429 | D93: ='2'!K73 -> 40285.714 | E93: ='3'!K73 -> 41000 | F93: ='4'!K73 -> 41428.571 | G93: ='5'!K73 -> 40714.286 | H93: ='6'!K73 -> 41428.571 | I93: ='7'!K73 -> 41428.571 | J93: ='8'!K73 -> 40285.714 | K93: ='9'!K73 -> 40285.714 | L93: ='10'!K73 -> 40285.714 | M93: ='11'!K73 -> 40285.714 | N93: ='12'!K73 -> 40285.714 | O93: ='13'!K73 -> 40285.714 | P93: ='14'!K73 -> 40285.714 | Q93: ='15'!K73 -> 41714.286 | R93: ='16'!K73 -> 41000 | S93: ='17'!K73 -> 41000 | T93: ='18'!K73 -> 41000 | U93: ='19'!K73 -> 41000 | V93: ='20'!K73 -> 40285.714 | W93: ='21'!K73 -> 41000 | X93: ='22'!K73 -> 42142.857 | Y93: ='23'!K73 -> 42142.857 | Z93: ='24'!K73 -> 42142.857 | AA93: ='25'!K73 -> 42142.857 | AB93: ='26'!K73 -> 42142.857 | AC93: ='27'!K73 -> 42142.857 | AD93: ='28'!K73 -> 41428.571 | AE93: ='29'!K73 -> 42142.857 | AF93: ='30'!K73 -> 42000 | AG93: ='31'!K73 -> 42000

Sheet 1
A1: HARGA BAHAN-BAHAN POKOK
A2: DI PASAR TRADISIONAL KOTA SURABAYA
A3: HARI / TANGGAL : Senin / 01 Mei 2023
B4: NAMA BAHAN POKOK DAN PENTING LAINNYA | C4: SATUAN | D4: Pasar Tambahrejo | E4: Pasar Pucang Anom | F4: Pasar Wonokromo | G4: Pasar Genteng Baru | H4: Pasar Pabean | I4: Pasar Kembang | J4: Pasar Balongsari | K4: Rata-Rata
A7: 1 | B7: BERAS
B8: - Beras Premium | C8: Kg | D8: 13000 | E8: 13500 | F8: 15000 | G8: 13500 | H8: 12000 | I8: 14000 | J8: 13500 | K8: =AVERAGE(D8:J8) -> 13500
B9: - Beras Medium Bulog | C9: Kg | D9: - | E9: - | F9: 13000 | G9: - | H9: 9000 | I9: - | J9: 9000 | K9: =AVERAGE(D9:J9) -> 10333.333
B10: - Beras Medium | C10: Kg | D10: 11000 | E10: 11500 | F10: - | G10: 11500 | H10: - | I10: 11500 | J10: - | K10: =AVERAGE(D10:J10) -> 11375
B11: - Beras Jagung | C11: Kg | D11: - | E11: 10000 | F11: 12000 | G11: 12000 | H11: - | I11: 11000 | J11: 8000 | K11: =AVERAGE(D11:J11) -> 10600
B12: - Beras Ketan (Jenis Siyem) | C12: Kg | D12: - | E12: 22000 | F12: 22000 | G12: 20000 | H12: - | I12: 22000 | J12: 17000 | K12: =AVERAGE(D12:J12) -> 20600
A13: 2 | B13: GULA
B14: - Gula pasir lokal curah | C14: Kg | D14: 13000 | E14: 13000 | F14: 13000 | G14: 13000 | H14: 13000 | I14: 13000 | J14: 13500 | K14: =AVERAGE(D14:J14) -> 13071.429
B15: - Gula Jawa/Merah (Bahan Kelapa) | C15: Kg | D15: 15000 | E15: 16000 | F15: 20000 | G15: 16000 | H15: 15000 | I15: 16000 | J15: 16000 | K15: =AVERAGE(D15:J15) -> 16285.714
A16: 3 | B16: MINYAK GORENG
B17: - Minyak Goreng Curah (Bening) | C17: Kg | D17: 14500 | E17: 16000 | F17: 16000 | G17: 16000 | H17: 14000 | I17: 16000 | J17: 15000 | K17: =AVERAGE(D17:J17) -> 15357.143
B18: - Minyak Kita | C18: Liter | D18: 14000 | E18: 14000 | F18: 14000 | G18: 14000 | H18: - | I18: 14000 | J18: 14000 | K18: =AVERAGE(D18:J18) -> 14000
A19: 4 | B19: MENTEGA
B20: - Mentega Curah (Amanda) | C20: Kg | D20: 20000 | E20: - | F20: 24000 | G20: 22000 | H20: - | I20: 24000 | J20: - | K20: =AVERAGE(D20:J20) -> 22500
A21: 5 | B21: DAGING
B22: - Daging Sapi Grade Atas | C22: Kg | D22: 120000 | E22: 120000 | F22: 130000 | G22: 125000 | H22: 120000 | I22: 120000 | J22: - | K22: =AVERAGE(D22:J22) -> 122500
B23: - Daging Sapi Grade Sedang | C23: Kg | D23: 110000 | E23: 110000 | F23: 120000 | G23: 120000 | H23: 114000 | I23: 115000 | J23: 115000 | K23: =AVERAGE(D23:J23) -> 114857.14
B24: - Daging Sapi Grade Bawah | C24: Kg | D24: 100000 | E24: 95000 | F24: 110000 | G24: 115000 | H24: 100000 | I24: 110000 | J24: 105000 | K24: =AVERAGE(D24:J24) -> 105000
B25: - Daging Ayam Broiler | C25: Kg | D25: 36000 | E25: 33000 | F25: 35000 | G25: 37000 | H25: 36000 | I25: 35000 | J25: 40000 | K25: =AVERAGE(D25:J25) -> 36000
A26: 6 | B26: I K A N
B27: - Ikan Tongkol Segar (Uk. Sedang) | C27: Kg | D27: 45000 | E27: 38000 | F27: 12000 | G27: 45000 | H27: 30000 | I27: 40000 | J27: 40000 | K27: =AVERAGE(D27:J27) -> 35714.286
B28: - Ikan Mujair Segar (Uk. Sedang) | C28: Kg | D28: 35000 | E28: 30000 | F28: 35000 | G28: 35000 | H28: 23000 | I28: 32000 | J28: 30000 | K28: =AVERAGE(D28:J28) -> 31428.571
B29: - Udang Segar (Uk. Sedang) | C29: Kg | D29: 80000 | E29: 60000 | F29: 70000 | G29: 75000 | H29: 58000 | I29: 67000 | J29: 60000 | K29: =AVERAGE(D29:J29) -> 67142.857
B30: - Ikan Lele Segar (Ukuran Sedang) | C30: Kg | D30: 25000 | E30: - | F30: - | G30: 25000 | H30: 23000 | I30: 24000 | J30: 26000 | K30: =AVERAGE(D30:J30) -> 24600
B31: - Ikan Bandeng Segar (Uk. Sedang) | C31: Kg | D31: 45000 | E31: 36000 | F31: 40000 | G31: 45000 | H31: 28000 | I31: 40000 | J31: 35000 | K31: =AVERAGE(D31:J31) -> 38428.571
B32: - Ikan Teri Asin (Bukan Teri Medan) | C32: Kg | D32: - | E32: 100000 | F32: 130000 | G32: - | H32: 80000 | I32: - | J32: - | K32: =AVERAGE(D32:J32) -> 103333.33
A33: 7 | B33: TELUR
B34: - Telur Ayam Broiler | C34: Kg | D34: 27000 | E34: 27000 | F34: 28000 | G34: 27000 | H34: 27000 | I34: 27000 | J34: 27000 | K34: =AVERAGE(D34:J34) -> 27142.857
B35: - Telur Ayam Kampung | C35: Butir | D35: 3000 | E35: 2200 | F35: 2500 | G35: 2000 | H35: 2000 | I35: 2500 | J35: 3000 | K35: =AVERAGE(D35:J35) -> 2457.1429
A36: 8 | B36: TAHU
B37: - Tahu biasa | C37: Kg | D37: 10000 | E37: 10000 | F37: 12000 | G37: 9000 | H37: 16000 | I37: 12000 | J37: 9000 | K37: =AVERAGE(D37:J37) -> 11142.857
B38: - Tahu susu | C38: Kg | D38: - | E38: 7000 | F38: 13000 | G38: 17000 | H38: - | I38: 13000 | J38: 12000 | K38: =AVERAGE(D38:J38) -> 12400
A39: 9 | B39: TEMPE
B40: - Tempe Kw I (campuran kedelai) | C40: Kg | D40: - | E40: 18000 | F40: - | G40: 16000 | H40: 14000 | I40: 15000 | J40: 15000 | K40: =AVERAGE(D40:J40) -> 15600
B41: - Tempe Kw II (campuran jagung) | C41: Kg | D41: 2500 | E41: 12000 | F41: 6000 | G41: - | H41: - | I41: - | J41: - | K41: =AVERAGE(D41:J41) -> 6833.3333
B42: - Tempe Kw III (campuran kulit) | C42: Kg | D42: - | E42: 2000 | F42: - | G42: - | H42: - | I42: - | J42: - | K42: =AVERAGE(D42:J42) -> 2000
...

Sheet 2
A1: HARGA BAHAN-BAHAN POKOK
A2: DI PASAR TRADISIONAL KOTA SURABAYA
A3: HARI / TANGGAL : Selasa / 02 Mei 2023
B4: NAMA BAHAN POKOK DAN PENTING LAINNYA | C4: SATUAN | D4: Pasar Tambahrejo | E4: Pasar Pucang Anom | F4: Pasar Wonokromo | G4: Pasar Genteng Baru | H4: Pasar Pabean | I4: Pasar Kembang | J4: Pasar Balongsari | K4: Rata-Rata
A7: 1 | B7: BERAS
B8: - Beras Premium | C8: Kg | D8: 13000 | E8: 13500 | F8: 15000 | G8: 13500 | H8: 12000 | I8: 14000 | J8: 13500 | K8: =AVERAGE(D8:J8) -> 13500
B9: - Beras Medium Bulog | C9: Kg | D9: - | E9: - | F9: 13000 | G9: - | H9: 9000 | I9: - | J9: 9000 | K9: =AVERAGE(D9:J9) -> 10333.333
B10: - Beras Medium | C10: Kg | D10: 11000 | E10: 11500 | F10: - | G10: 11500 | H10: - | I10: 11500 | J10: - | K10: =AVERAGE(D10:J10) -> 11375
B11: - Beras Jagung | C11: Kg | D11: - | E11: 10000 | F11: 12000 | G11: 12000 | H11: - | I11: 11000 | J11: 8000 | K11: =AVERAGE(D11:J11) -> 10600
B12: - Beras Ketan (Jenis Siyem) | C12: Kg | D12: - | E12: 22000 | F12: 24000 | G12: 20000 | H12: - | I12: 22000 | J12: 17000 | K12: =AVERAGE(D12:J12) -> 21000
A13: 2 | B13: GULA
B14: - Gula pasir lokal curah | C14: Kg | D14: 13000 | E14: 13500 | F14: 13500 | G14: 13000 | H14: 13000 | I14: 13000 | J14: 13500 | K14: =AVERAGE(D14:J14) -> 13214.286
B15: - Gula Jawa/Merah (Bahan Kelapa) | C15: Kg | D15: 15000 | E15: 16000 | F15: 15000 | G15: 16000 | H15: 15000 | I15: 16000 | J15: 16000 | K15: =AVERAGE(D15:J15) -> 15571.429
A16: 3 | B16: MINYAK GORENG
B17: - Minyak Goreng Curah (Bening) | C17: Kg | D17: 14500 | E17: 16000 | F17: 17000 | G17: 16000 | H17: 14000 | I17: 16000 | J17: 15000 | K17: =AVERAGE(D17:J17) -> 15500
B18: - Minyak Kita | C18: Liter | D18: 14000 | E18: 14000 | F18: 14000 | G18: 14000 | H18: - | I18: 14000 | J18: 14000 | K18: =AVERAGE(D18:J18) -> 14000
A19: 4 | B19: MENTEGA
B20: - Mentega Curah (Amanda) | C20: Kg | D20: 20000 | E20: - | F20: 19000 | G20: 22000 | H20: - | I20: 24000 | J20: - | K20: =AVERAGE(D20:J20) -> 21250
A21: 5 | B21: DAGING
B22: - Daging Sapi Grade Atas | C22: Kg | D22: 120000 | E22: 120000 | F22: 120000 | G22: 125000 | H22: 120000 | I22: 120000 | J22: - | K22: =AVERAGE(D22:J22) -> 120833.33
B23: - Daging Sapi Grade Sedang | C23: Kg | D23: 110000 | E23: 110000 | F23: 110000 | G23: 115000 | H23: 114000 | I23: 115000 | J23: 115000 | K23: =AVERAGE(D23:J23) -> 112714.29
B24: - Daging Sapi Grade Bawah | C24: Kg | D24: 100000 | E24: 95000 | F24: 105000 | G24: 105000 | H24: 100000 | I24: 110000 | J24: 105000 | K24: =AVERAGE(D24:J24) -> 102857.14
B25: - Daging Ayam Broiler | C25: Kg | D25: 33000 | E25: 33000 | F25: 32000 | G25: 33000 | H25: 38000 | I25: 34000 | J25: 35000 | K25: =AVERAGE(D25:J25) -> 34000
A26: 6 | B26: I K A N
B27: - Ikan Tongkol Segar (Uk. Sedang) | C27: Kg | D27: 45000 | E27: 38000 | F27: 12000 | G27: 45000 | H27: 30000 | I27: 40000 | J27: 40000 | K27: =AVERAGE(D27:J27) -> 35714.286
B28: - Ikan Mujair Segar (Uk. Sedang) | C28: Kg | D28: 35000 | E28: 30000 | F28: 35000 | G28: 35000 | H28: 23000 | I28: 30000 | J28: 30000 | K28: =AVERAGE(D28:J28) -> 31142.857
B29: - Udang Segar (Uk. Sedang) | C29: Kg | D29: 80000 | E29: 60000 | F29: 60000 | G29: 75000 | H29: 58000 | I29: 70000 | J29: 60000 | K29: =AVERAGE(D29:J29) -> 66142.857
B30: - Ikan Lele Segar (Ukuran Sedang) | C30: Kg | D30: 25000 | E30: - | F30: - | G30: 25000 | H30: 23000 | I30: 24000 | J30: 26000 | K30: =AVERAGE(D30:J30) -> 24600
B31: - Ikan Bandeng Segar (Uk. Sedang) | C31: Kg | D31: 45000 | E31: 36000 | F31: 40000 | G31: 45000 | H31: 28000 | I31: 40000 | J31: 35000 | K31: =AVERAGE(D31:J31) -> 38428.571
B32: - Ikan Teri Asin (Bukan Teri Medan) | C32: Kg | D32: - | E32: 100000 | F32: 110000 | G32: - | H32: 80000 | I32: - | J32: - | K32: =AVERAGE(D32:J32) -> 96666.667
A33: 7 | B33: TELUR
B34: - Telur Ayam Broiler | C34: Kg | D34: 27000 | E34: 27000 | F34: 26000 | G34: 27000 | H34: 26000 | I34: 27000 | J34: 27000 | K34: =AVERAGE(D34:J34) -> 26714.286
B35: - Telur Ayam Kampung | C35: Butir | D35: 3000 | E35: 2200 | F35: 2000 | G35: 2000 | H35: 2000 | I35: 2500 | J35: 3000 | K35: =AVERAGE(D35:J35) -> 2385.7143
A36: 8 | B36: TAHU
B37: - Tahu biasa | C37: Kg | D37: 10000 | E37: 10000 | F37: 12000 | G37: 9000 | H37: 16000 | I37: 12000 | J37: 9000 | K37: =AVERAGE(D37:J37) -> 11142.857
B38: - Tahu susu | C38: Kg | D38: - | E38: 7000 | F38: 12000 | G38: 17000 | H38: - | I38: 15000 | J38: 12000 | K38: =AVERAGE(D38:J38) -> 12600
A39: 9 | B39: TEMPE
B40: - Tempe Kw I (campuran kedelai) | C40: Kg | D40: - | E40: 18000 | F40: - | G40: 16000 | H40: 14000 | I40: 15000 | J40: 15000 | K40: =AVERAGE(D40:J40) -> 15600
B41: - Tempe Kw II (campuran jagung) | C41: Kg | D41: 2500 | E41: 12000 | F41: 6000 | G41: - | H41: - | I41: - | J41: - | K41: =AVERAGE(D41:J41) -> 6833.3333
B42: - Tempe Kw III (campuran kulit) | C42: Kg | D42: - | E42: 2000 | F42: - | G42: - | H42: - | I42: - | J42: - | K42: =AVERAGE(D42:J42) -> 2000
...

Sheet 3
A1: HARGA BAHAN-BAHAN POKOK
A2: DI PASAR TRADISIONAL KOTA SURABAYA
A3: HARI / TANGGAL : Rabu / 03 Mei 2023
B4: NAMA BAHAN POKOK DAN PENTING LAINNYA | C4: SATUAN | D4: Pasar Tambahrejo | E4: Pasar Pucang Anom | F4: Pasar Wonokromo | G4: Pasar Genteng Baru | H4: Pasar Pabean | I4: Pasar Kembang | J4: Pasar Balongsari | K4: Rata-Rata
A7: 1 | B7: BERAS
B8: - Beras Premium | C8: Kg | D8: 13000 | E8: 13500 | F8: 16000 | G8: 13500 | H8: 12000 | I8: 14000 | J8: 13500 | K8: =AVERAGE(D8:J8) -> 13642.857
B9: - Beras Medium Bulog | C9: Kg | D9: - | E9: - | F9: 12000 | G9: - | H9: 9000 | I9: - | J9: 9000 | K9: =AVERAGE(D9:J9) -> 10000
B10: - Beras Medium | C10: Kg | D10: 11000 | E10: 11500 | F10: - | G10: 11500 | H10: - | I10: 11500 | J10: - | K10: =AVERAGE(D10:J10) -> 11375
B11: - Beras Jagung | C11: Kg | D11: - | E11: 10000 | F11: 12000 | G11: 12000 | H11: - | I11: 11000 | J11: 8000 | K11: =AVERAGE(D11:J11) -> 10600
B12: - Beras Ketan (Jenis Siyem) | C12: Kg | D12: - | E12: 22000 | F12: 20000 | G12: 20000 | H12: - | I12: 22000 | J12: 17000 | K12: =AVERAGE(D12:J12) -> 20200
A13: 2 | B13: GULA
B14: - Gula pasir lokal curah | C14: Kg | D14: 13000 | E14: 13500 | F14: 13000 | G14: 13000 | H14: 13000 | I14: 13000 | J14: 13500 | K14: =AVERAGE(D14:J14) -> 13142.857
B15: - Gula Jawa/Merah (Bahan Kelapa) | C15: Kg | D15: 15000 | E15: 16000 | F15: 17000 | G15: 16000 | H15: 15000 | I15: 16000 | J15: 16000 | K15: =AVERAGE(D15:J15) -> 15857.143
A16: 3 | B16: MINYAK GORENG
B17: - Minyak Goreng Curah (Bening) | C17: Kg | D17: 14500 | E17: 16000 | F17: 16000 | G17: 16000 | H17: 14000 | I17: 16000 | J17: 15000 | K17: =AVERAGE(D17:J17) -> 15357.143
B18: - Minyak Kita | C18: Liter | D18: 14000 | E18: 14000 | F18: 14000 | G18: 14000 | H18: - | I18: 14000 | J18: 14000 | K18: =AVERAGE(D18:J18) -> 14000
A19: 4 | B19: MENTEGA
B20: - Mentega Curah (Amanda) | C20: Kg | D20: 20000 | E20: - | F20: 24000 | G20: 22000 | H20: - | I20: 24000 | J20: - | K20: =AVERAGE(D20:J20) -> 22500
A21: 5 | B21: DAGING
B22: - Daging Sapi Grade Atas | C22: Kg | D22: 120000 | E22: 120000 | F22: 130000 | G22: 125000 | H22: 120000 | I22: 120000 | J22: - | K22: =AVERAGE(D22:J22) -> 122500
B23: - Daging Sapi Grade Sedang | C23: Kg | D23: 110000 | E23: 110000 | F23: 120000 | G23: 115000 | H23: 114000 | I23: 115000 | J23: 115000 | K23: =AVERAGE(D23:J23) -> 114142.86
B24: - Daging Sapi Grade Bawah | C24: Kg | D24: 100000 | E24: 95000 | F24: 110000 | G24: 105000 | H24: 100000 | I24: 110000 | J24: 105000 | K24: =AVERAGE(D24:J24) -> 103571.43
B25: - Daging Ayam Broiler | C25: Kg | D25: 33000 | E25: 33000 | F25: 34000 | G25: 32000 | H25: 35000 | I25: 33000 | J25: 35000 | K25: =AVERAGE(D25:J25) -> 33571.429
A26: 6 | B26: I K A N
B27: - Ikan Tongkol Segar (Uk. Sedang) | C27: Kg | D27: 45000 | E27: 38000 | F27: 12000 | G27: 45000 | H27: 30000 | I27: 40000 | J27: 40000 | K27: =AVERAGE(D27:J27) -> 35714.286
B28: - Ikan Mujair Segar (Uk. Sedang) | C28: Kg | D28: 35000 | E28: 30000 | F28: 35000 | G28: 35000 | H28: 23000 | I28: 30000 | J28: 30000 | K28: =AVERAGE(D28:J28) -> 31142.857
B29: - Udang Segar (Uk. Sedang) | C29: Kg | D29: 80000 | E29: 60000 | F29: 70000 | G29: 75000 | H29: 58000 | I29: 70000 | J29: 60000 | K29: =AVERAGE(D29:J29) -> 67571.429
B30: - Ikan Lele Segar (Ukuran Sedang) | C30: Kg | D30: 25000 | E30: - | F30: - | G30: 25000 | H30: 23000 | I30: 24000 | J30: 26000 | K30: =AVERAGE(D30:J30) -> 24600
B31: - Ikan Bandeng Segar (Uk. Sedang) | C31: Kg | D31: 45000 | E31: 36000 | F31: 40000 | G31: 45000 | H31: 28000 | I31: 40000 | J31: 35000 | K31: =AVERAGE(D31:J31) -> 38428.571
B32: - Ikan Teri Asin (Bukan Teri Medan) | C32: Kg | D32: - | E32: 100000 | F32: 130000 | G32: - | H32: 80000 | I32: - | J32: - | K32: =AVERAGE(D32:J32) -> 103333.33
A33: 7 | B33: TELUR
B34: - Telur Ayam Broiler | C34: Kg | D34: 27000 | E34: 27000 | F34: 28000 | G34: 27000 | H34: 26000 | I34: 27000 | J34: 27000 | K34: =AVERAGE(D34:J34) -> 27000
B35: - Telur Ayam Kampung | C35: Butir | D35: 3000 | E35: 2200 | F35: 2500 | G35: 2000 | H35: 2000 | I35: 2500 | J35: 3000 | K35: =AVERAGE(D35:J35) -> 2457.1429
A36: 8 | B36: TAHU
B37: - Tahu biasa | C37: Kg | D37: 10000 | E37: 10000 | F37: 12000 | G37: 9000 | H37: 16000 | I37: 12000 | J37: 9000 | K37: =AVERAGE(D37:J37) -> 11142.857
B38: - Tahu susu | C38: Kg | D38: - | E38: 7000 | F38: 13000 | G38: 17000 | H38: - | I38: 15000 | J38: 12000 | K38: =AVERAGE(D38:J38) -> 12800
A39: 9 | B39: TEMPE
B40: - Tempe Kw I (campuran kedelai) | C40: Kg | D40: - | E40: 18000 | F40: - | G40: 16000 | H40: 14000 | I40: 15000 | J40: 15000 | K40: =AVERAGE(D40:J40) -> 15600
B41: - Tempe Kw II (campuran jagung) | C41: Kg | D41: 2500 | E41: 12000 | F41: 6000 | G41: - | H41: - | I41: - | J41: - | K41: =AVERAGE(D41:J41) -> 6833.3333
B42: - Tempe Kw III (campuran kulit) | C42: Kg | D42: - | E42: 2000 | F42: - | G42: - | H42: - | I42: - | J42: - | K42: =AVERAGE(D42:J42) -> 2000
...

Sheet 4
A1: HARGA BAHAN-BAHAN POKOK
A2: DI PASAR TRADISIONAL KOTA SURABAYA
A3: HARI / TANGGAL : Kamis / 04 Mei 2023
B4: NAMA BAHAN POKOK DAN PENTING LAINNYA | C4: SATUAN | D4: Pasar Tambahrejo | E4: Pasar Pucang Anom | F4: Pasar Wonokromo | G4: Pasar Genteng Baru | H4: Pasar Pabean | I4: Pasar Kembang | J4: Pasar Balongsari | K4: Rata-Rata
A7: 1 | B7: BERAS
B8: - Beras Premium | C8: Kg | D8: 13000 | E8: 13500 | F8: 13500 | G8: 13500 | H8: 12000 | I8: 14000 | J8: 13500 | K8: =AVERAGE(D8:J8) -> 13285.714
B9: - Beras Medium Bulog | C9: Kg | D9: - | E9: - | F9: 11000 | G9: - | H9: 9000 | I9: - | J9: 9000 | K9: =AVERAGE(D9:J9) -> 9666.6667
B10: - Beras Medium | C10: Kg | D10: 11000 | E10: 11500 | F10: - | G10: 11500 | H10: - | I10: 11500 | J10: - | K10: =AVERAGE(D10:J10) -> 11375
B11: - Beras Jagung | C11: Kg | D11: - | E11: 10000 | F11: 12000 | G11: 12000 | H11: - | I11: 11000 | J11: 8000 | K11: =AVERAGE(D11:J11) -> 10600
B12: - Beras Ketan (Jenis Siyem) | C12: Kg | D12: - | E12: 22000 | F12: 20000 | G12: 20000 | H12: - | I12: 22000 | J12: 17000 | K12: =AVERAGE(D12:J12) -> 20200
A13: 2 | B13: GULA
B14: - Gula pasir lokal curah | C14: Kg | D14: 13000 | E14: 13500 | F14: 13500 | G14: 13000 | H14: 13000 | I14: 13000 | J14: 13500 | K14: =AVERAGE(D14:J14) -> 13214.286
B15: - Gula Jawa/Merah (Bahan Kelapa) | C15: Kg | D15: 15000 | E15: 16000 | F15: 18000 | G15: 16000 | H15: 15000 | I15: 16000 | J15: 16000 | K15: =AVERAGE(D15:J15) -> 16000
A16: 3 | B16: MINYAK GORENG
B17: - Minyak Goreng Curah (Bening) | C17: Kg | D17: 14500 | E17: 16000 | F17: 16000 | G17: 16000 | H17: 14000 | I17: 16000 | J17: 15000 | K17: =AVERAGE(D17:J17) -> 15357.143
B18: - Minyak Kita | C18: Liter | D18: 14000 | E18: 14000 | F18: 14000 | G18: 14000 | H18: - | I18: 14000 | J18: 14000 | K18: =AVERAGE(D18:J18) -> 14000
A19: 4 | B19: MENTEGA
B20: - Mentega Curah (Amanda) | C20: Kg | D20: 20000 | E20: - | F20: 24000 | G20: 22000 | H20: - | I20: 24000 | J20: - | K20: =AVERAGE(D20:J20) -> 22500
A21: 5 | B21: DAGING
