Workbook

Sheet REKAPITULASI
A1: BAGIAN PEREKONOMIAN DAN SUMBER DAYA ALAM
A2: LAPORAN HARGA BAHAN POKOK DI KOTA SURABAYA
A3: PERIODE JUNI 2023
B4: NAMA BAHAN POKOK DAN PENTING LAINNYA | C4: SAT | AG4: HET/HAPK (Harga Eceran Tertinggi) | AH4: FLUKTUASI
D5: 1 | E5: 2 | F5: 3 | G5: 4 | H5: 5 | I5: 6 | J5: 7 | K5: 8 | L5: 9 | M5: 10 | N5: 11 | O5: 12 | P5: 13 | Q5: 14 | R5: 15 | S5: 16 | T5: 17 | U5: 18 | V5: 19 | W5: 20 | X5: 21 | Y5: 22 | Z5: 23 | AA5: 24 | AB5: 25 | AC5: 26 | AD5: 27 | AE5: 28 | AF5: 30
A7: 1 | B7: BERAS
B8: - Beras Premium | C8: Kg | D8: ='1'!K8 -> 13357.143 | E8: ='2'!K8 -> 13357.143 | F8: ='3'!K8 -> 13357.143 | G8: ='4'!K8 -> 13357.143 | H8: ='5'!K8 -> 13357.143 | I8: ='6'!K8 -> 13357.143 | J8: ='7'!K8 -> 13357.143 | K8: ='8'!K8 -> 13357.143 | L8: ='9'!K8 -> 13357.143 | M8: ='10'!K8 -> 13214.286 | N8: ='11'!K8 -> 13071.429 | O8: ='12'!K8 -> 13000 | P8: ='13'!K8 -> 13071.429 | Q8: ='14'!K8 -> 13000 | R8: ='15'!K8 -> 13000 | S8: ='14'!K8 -> 13000 | T8: ='17'!K8 -> 13071.429 | U8: ='18'!K8 -> 13142.857 | V8: ='19'!K8 -> 13071.429 | W8: ='20'!K8 -> 13071.429 | X8: ='21'!K8 -> 13214.286 | Y8: ='22'!K8 -> 13214.286 | Z8: ='23'!K8 -> 13214.286 | AA8: ='24'!K8 -> 13214.286 | AB8: ='25'!K8 -> 13214.286 | AC8: ='26'!K8 -> 13214.286 | AD8: ='27'!K8 -> 13214.286 | AE8: ='28'!K8 -> 13214.286 | AF8: ='30'!K8 -> 13214.286 | AG8: 12800 | AH8: =AF8-D8 -> -142.85714 | AI8: =AVERAGE(D8:AF8) -> 13201.97
B9: - Beras IR.64 Medium Bulog | C9: KG | D9: ='1'!K9 -> 9000 | E9: ='2'!K9 -> 9000 | F9: ='3'!K9 -> 9000 | G9: ='4'!K9 -> 9000 | H9: ='5'!K9 -> 9000 | I9: ='6'!K9 -> 9000 | J9: ='7'!K9 -> 9000 | K9: ='8'!K9 -> 9000 | L9: ='9'!K9 -> 9000 | M9: ='10'!K9 -> 9000 | N9: ='11'!K9 -> 9000 | O9: ='12'!K9 -> 9000 | P9: ='13'!K9 -> 9000 | Q9: ='14'!K9 -> 9000 | R9: ='15'!K9 -> 9000 | S9: ='14'!K9 -> 9000 | T9: ='17'!K9 -> 9250 | U9: ='18'!K9 -> 9250 | V9: ='19'!K9 -> 9000 | W9: ='20'!K9 -> 9000 | X9: ='21'!K9 -> 9000 | Y9: ='22'!K9 -> 9000 | Z9: ='23'!K9 -> 9000 | AA9: ='24'!K9 -> 9000 | AB9: ='25'!K9 -> 9250 | AC9: ='26'!K9 -> 9000 | AD9: ='27'!K9 -> 9000 | AE9: ='28'!K9 -> 9125 | AF9: ='30'!K9 -> 9375 | AH9: =AF9-D9 -> 375 | AI9: =AVERAGE(D9:AF9) -> 9043.1034
B10: - Beras IR.64 Medium | C10: Kg | D10: ='1'!K10 -> 11833.333 | E10: ='2'!K10 -> 11833.333 | F10: ='3'!K10 -> 12000 | G10: ='4'!K10 -> 12000 | H10: ='5'!K10 -> 12000 | I10: ='6'!K10 -> 12000 | J10: ='7'!K10 -> 12000 | K10: ='8'!K10 -> 12000 | L10: ='9'!K10 -> 12166.667 | M10: ='10'!K10 -> 11833.333 | N10: ='11'!K10 -> 11166.667 | O10: ='12'!K10 -> 11500 | P10: ='13'!K10 -> 11083.333 | Q10: ='14'!K10 -> 10966.667 | R10: ='15'!K10 -> 11133.333 | S10: ='14'!K10 -> 10966.667 | T10: ='17'!K10 -> 10860 | U10: ='18'!K10 -> 10860 | V10: ='19'!K10 -> 11000 | W10: ='20'!K10 -> 10980 | X10: ='21'!K10 -> 10760 | Y10: ='22'!K10 -> 10450 | Z10: ='23'!K10 -> 10560 | AA10: ='24'!K10 -> 10560 | AB10: ='25'!K10 -> 10560 | AC10: ='26'!K10 -> 10360 | AD10: ='27'!K10 -> 10360 | AE10: ='28'!K10 -> 10450 | AF10: ='30'!K10 -> 10450 | AG10: 9450 | AH10: =AF10-D10 -> -1383.3333 | AI10: =AVERAGE(D10:AF10) -> 11196.322
B11: - Beras Jagung | C11: Kg | D11: ='1'!K11 -> 10600 | E11: ='2'!K11 -> 10600 | F11: ='3'!K11 -> 10600 | G11: ='4'!K11 -> 10600 | H11: ='5'!K11 -> 10600 | I11: ='6'!K11 -> 10600 | J11: ='7'!K11 -> 10600 | K11: ='8'!K11 -> 10600 | L11: ='9'!K11 -> 10600 | M11: ='10'!K11 -> 10600 | N11: ='11'!K11 -> 10600 | O11: ='12'!K11 -> 10600 | P11: ='13'!K11 -> 10600 | Q11: ='14'!K11 -> 10600 | R11: ='15'!K11 -> 10600 | S11: ='14'!K11 -> 10600 | T11: ='17'!K11 -> 10600 | U11: ='18'!K11 -> 10600 | V11: ='19'!K11 -> 10200 | W11: ='20'!K11 -> 10200 | X11: ='21'!K11 -> 10200 | Y11: ='22'!K11 -> 10200 | Z11: ='23'!K11 -> 10200 | AA11: ='24'!K11 -> 10200 | AB11: ='25'!K11 -> 10200 | AC11: ='26'!K11 -> 10200 | AD11: ='27'!K11 -> 10200 | AE11: ='28'!K11 -> 10200 | AF11: ='30'!K11 -> 10200 | AH11: =AF11-D11 -> -400 | AI11: =AVERAGE(D11:AF11) -> 10448.276
B12: - Beras Ketan (Jenis Siyem) | C12: Kg | D12: ='1'!K12 -> 20200 | E12: ='2'!K12 -> 19000 | F12: ='3'!K12 -> 19000 | G12: ='4'!K12 -> 19000 | H12: ='5'!K12 -> 20200 | I12: ='6'!K12 -> 20200 | J12: ='7'!K12 -> 20200 | K12: ='8'!K12 -> 20200 | L12: ='9'!K12 -> 20200 | M12: ='10'!K12 -> 19000 | N12: ='11'!K12 -> 19000 | O12: ='12'!K12 -> 19000 | P12: ='13'!K12 -> 20200 | Q12: ='14'!K12 -> 20200 | R12: ='15'!K12 -> 20200 | S12: ='14'!K12 -> 20200 | T12: ='17'!K12 -> 20200 | U12: ='18'!K12 -> 20200 | V12: ='19'!K12 -> 20200 | W12: ='20'!K12 -> 20200 | X12: ='21'!K12 -> 20200 | Y12: ='22'!K12 -> 19400 | Z12: ='23'!K12 -> 20200 | AA12: ='24'!K12 -> 20200 | AB12: ='25'!K12 -> 18800 | AC12: ='26'!K12 -> 18800 | AD12: ='27'!K12 -> 18800 | AE12: ='28'!K12 -> 18800 | AF12: ='30'!K12 -> 18800 | AH12: =AF12-D12 -> -1400 | AI12: =AVERAGE(D12:AF12) -> 19682.759
A13: 2 | B13: GULA | D13: ='1'!K13 | E13: ='2'!K13 | F13: ='3'!K13 | G13: ='4'!K13 | H13: ='5'!K13 | I13: ='6'!K13 | J13: ='7'!K13 | K13: ='8'!K13 | L13: ='9'!K13 | M13: ='10'!K13 | N13: ='11'!K13 | O13: ='12'!K13 | P13: ='13'!K13 | Q13: ='14'!K13 | R13: ='15'!K13 | S13: ='14'!K13 | T13: ='17'!K13 | U13: ='18'!K13 | V13: ='19'!K13 | W13: ='20'!K13 | X13: ='21'!K13 | Y13: ='22'!K13 | Z13: ='23'!K13 | AA13: ='24'!K13 | AB13: ='25'!K13 | AC13: ='26'!K13 | AD13: ='27'!K13 | AE13: ='28'!K13 | AF13: ='30'!K13 | AH13: =AF13-D13 -> 0 | AI13: =AVERAGE(D13:AF13) -> #DIV/0!
B14: Gula Pasir Lokal Curah | C14: Kg | D14: ='1'!K14 -> 13571.429 | E14: ='2'!K14 -> 13500 | F14: ='3'!K14 -> 13500 | G14: ='4'!K14 -> 13428.571 | H14: ='5'!K14 -> 13500 | I14: ='6'!K14 -> 13500 | J14: ='7'!K14 -> 13500 | K14: ='8'!K14 -> 13500 | L14: ='9'!K14 -> 13500 | M14: ='10'!K14 -> 13428.571 | N14: ='11'!K14 -> 13428.571 | O14: ='12'!K14 -> 13428.571 | P14: ='13'!K14 -> 13357.143 | Q14: ='14'!K14 -> 13357.143 | R14: ='15'!K14 -> 13357.143 | S14: ='14'!K14 -> 13357.143 | T14: ='17'!K14 -> 13285.714 | U14: ='18'!K14 -> 13285.714 | V14: ='19'!K14 -> 13214.286 | W14: ='20'!K14 -> 13214.286 | X14: ='21'!K14 -> 13214.286 | Y14: ='22'!K14 -> 13214.286 | Z14: ='23'!K14 -> 13214.286 | AA14: ='24'!K14 -> 13214.286 | AB14: ='25'!K14 -> 13285.714 | AC14: ='26'!K14 -> 13285.714 | AD14: ='27'!K14 -> 13285.714 | AE14: ='28'!K14 -> 13285.714 | AF14: ='30'!K14 -> 13285.714 | AG14: 13500 | AH14: =AF14-D14 -> -285.71429 | AI14: =AVERAGE(D14:AF14) -> 13362.069
B15: - Gula Jawa/Merah (Bahan Kelapa) | C15: Kg | D15: ='1'!K15 -> 15857.143 | E15: ='2'!K15 -> 17142.857 | F15: ='3'!K15 -> 17142.857 | G15: ='4'!K15 -> 16571.429 | H15: ='5'!K15 -> 15857.143 | I15: ='6'!K15 -> 15857.143 | J15: ='7'!K15 -> 15857.143 | K15: ='8'!K15 -> 15857.143 | L15: ='9'!K15 -> 15857.143 | M15: ='10'!K15 -> 15857.143 | N15: ='11'!K15 -> 15857.143 | O15: ='12'!K15 -> 15571.429 | P15: ='13'!K15 -> 15571.429 | Q15: ='14'!K15 -> 15571.429 | R15: ='15'!K15 -> 15571.429 | S15: ='14'!K15 -> 15571.429 | T15: ='17'!K15 -> 15714.286 | U15: ='18'!K15 -> 16285.714 | V15: ='19'!K15 -> 15571.429 | W15: ='20'!K15 -> 15285.714 | X15: ='21'!K15 -> 15285.714 | Y15: ='22'!K15 -> 15285.714 | Z15: ='23'!K15 -> 15285.714 | AA15: ='24'!K15 -> 15285.714 | AB15: ='25'!K15 -> 15428.571 | AC15: ='26'!K15 -> 15428.571 | AD15: ='27'!K15 -> 15428.571 | AE15: ='28'!K15 -> 15428.571 | AF15: ='30'!K15 -> 15428.571 | AH15: =AF15-D15 -> -428.57143 | AI15: =AVERAGE(D15:AF15) -> 15748.768
B16: MINYAK GORENG | D16: ='1'!K16 | E16: ='2'!K16 | F16: ='3'!K16 | G16: ='4'!K16 | H16: ='5'!K16 | I16: ='6'!K16 | J16: ='7'!K16 | K16: ='8'!K16 | L16: ='9'!K16 | M16: ='10'!K16 | N16: ='11'!K16 | O16: ='12'!K16 | P16: ='13'!K16 | Q16: ='14'!K16 | R16: ='15'!K16 | S16: ='14'!K16 | T16: ='17'!K16 | U16: ='18'!K16 | V16: ='19'!K16 | W16: ='20'!K16 | X16: ='21'!K16 | Y16: ='22'!K16 | Z16: ='23'!K16 | AA16: ='24'!K16 | AB16: ='25'!K16 | AC16: ='26'!K16 | AD16: ='27'!K16 | AE16: ='28'!K16 | AF16: ='30'!K16 | AH16: =AF16-D16 -> 0 | AI16: =AVERAGE(D16:AF16) -> #DIV/0!
B17: - Minyak Goreng Curah (Bening) | C17: Kg | D17: ='1'!K17 -> 15571.429 | E17: ='2'!K17 -> 15571.429 | F17: ='3'!K17 -> 15571.429 | G17: ='4'!K17 -> 15571.429 | H17: ='5'!K17 -> 15571.429 | I17: ='6'!K17 -> 15571.429 | J17: ='7'!K17 -> 15571.429 | K17: ='8'!K17 -> 15571.429 | L17: ='9'!K17 -> 15500 | M17: ='10'!K17 -> 15285.714 | N17: ='11'!K17 -> 15071.429 | O17: ='12'!K17 -> 15214.286 | P17: ='13'!K17 -> 15214.286 | Q17: ='14'!K17 -> 15000 | R17: ='15'!K17 -> 15000 | S17: ='14'!K17 -> 15000 | T17: ='17'!K17 -> 15000 | U17: ='18'!K17 -> 15142.857 | V17: ='19'!K17 -> 15000 | W17: ='20'!K17 -> 15000 | X17: ='21'!K17 -> 15142.857 | Y17: ='22'!K17 -> 15142.857 | Z17: ='23'!K17 -> 15142.857 | AA17: ='24'!K17 -> 15142.857 | AB17: ='25'!K17 -> 15142.857 | AC17: ='26'!K17 -> 15142.857 | AD17: ='27'!K17 -> 15142.857 | AE17: ='28'!K17 -> 15142.857 | AF17: ='30'!K17 -> 15142.857 | AG17: 15500 | AH17: =AF17-D17 -> -428.57143 | AI17: =AVERAGE(D17:AF17) -> 15251.232
B18: - Minyak KITA | C18: Kg | D18: ='1'!K18 -> 14000 | E18: ='2'!K18 -> 14000 | F18: ='3'!K18 -> 14000 | G18: ='4'!K18 -> 14000 | H18: ='5'!K18 -> 14000 | I18: ='6'!K18 -> 14000 | J18: ='7'!K18 -> 14000 | K18: ='8'!K18 -> 14000 | L18: ='9'!K18 -> 14000 | M18: ='10'!K18 -> 14000 | N18: ='11'!K18 -> 14000 | O18: ='12'!K18 -> 14000 | P18: ='13'!K18 -> 14000 | Q18: ='14'!K18 -> 14000 | R18: ='15'!K18 -> 14000 | S18: ='14'!K18 -> 14000 | T18: ='17'!K18 -> 14000 | U18: ='18'!K18 -> 14000 | V18: ='19'!K18 -> 14000 | W18: ='20'!K18 -> 14000 | X18: ='21'!K18 -> 14000 | Y18: ='22'!K18 -> 14000 | Z18: ='23'!K18 -> 14000 | AA18: ='24'!K18 -> 14000 | AB18: ='25'!K18 -> 14000 | AC18: ='26'!K18 -> 14000 | AD18: ='27'!K18 -> 14000 | AE18: ='28'!K18 -> 14000 | AF18: ='30'!K18 -> 14000 | AG18: 14000 | AH18: =AF18-D18 -> 0 | AI18: =AVERAGE(D18:AF18) -> 14000
A19: 4 | B19: MENTEGA | D19: ='1'!K19 | E19: ='2'!K19 | F19: ='3'!K19 | G19: ='4'!K19 | H19: ='5'!K19 | I19: ='6'!K19 | J19: ='7'!K19 | K19: ='8'!K19 | L19: ='9'!K19 | M19: ='10'!K19 | N19: ='11'!K19 | O19: ='12'!K19 | P19: ='13'!K19 | Q19: ='14'!K19 | R19: ='15'!K19 | S19: ='14'!K19 | T19: ='17'!K19 | U19: ='18'!K19 | V19: ='19'!K19 | W19: ='20'!K19 | X19: ='21'!K19 | Y19: ='22'!K19 | Z19: ='23'!K19 | AA19: ='24'!K19 | AB19: ='25'!K19 | AC19: ='26'!K19 | AD19: ='27'!K19 | AE19: ='28'!K19 | AF19: ='30'!K19 | AH19: =AF19-D19 -> 0 | AI19: =AVERAGE(D19:AF19) -> #DIV/0!
B20: - Mentega Curah (Amanda) | C20: Kg | D20: ='1'!K20 -> 21250 | E20: ='2'!K20 -> 21250 | F20: ='3'!K20 -> 21250 | G20: ='4'!K20 -> 21250 | H20: ='5'!K20 -> 21250 | I20: ='6'!K20 -> 21250 | J20: ='7'!K20 -> 21250 | K20: ='8'!K20 -> 21250 | L20: ='9'!K20 -> 21250 | M20: ='10'!K20 -> 21250 | N20: ='11'!K20 -> 21250 | O20: ='12'!K20 -> 21250 | P20: ='13'!K20 -> 21250 | Q20: ='14'!K20 -> 21250 | R20: ='15'!K20 -> 21250 | S20: ='14'!K20 -> 21250 | T20: ='17'!K20 -> 21250 | U20: ='18'!K20 -> 21250 | V20: ='19'!K20 -> 21250 | W20: ='20'!K20 -> 21250 | X20: ='21'!K20 -> 21250 | Y20: ='22'!K20 -> 21250 | Z20: ='23'!K20 -> 21250 | AA20: ='24'!K20 -> 21250 | AB20: ='25'!K20 -> 21500 | AC20: ='26'!K20 -> 21500 | AD20: ='27'!K20 -> 21500 | AE20: ='28'!K20 -> 21500 | AF20: ='30'!K20 -> 21500 | AH20: =AF20-D20 -> 250 | AI20: =AVERAGE(D20:AF20) -> 21293.103
A21: 5 | B21: DAGING | D21: ='1'!K21 | E21: ='2'!K21 | F21: ='3'!K21 | G21: ='4'!K21 | H21: ='5'!K21 | I21: ='6'!K21 | J21: ='7'!K21 | K21: ='8'!K21 | L21: ='9'!K21 | M21: ='10'!K21 | N21: ='11'!K21 | O21: ='12'!K21 | P21: ='13'!K21 | Q21: ='14'!K21 | R21: ='15'!K21 | S21: ='14'!K21 | T21: ='17'!K21 | U21: ='18'!K21 | V21: ='19'!K21 | W21: ='20'!K21 | X21: ='21'!K21 | Y21: ='22'!K21 | Z21: ='23'!K21 | AA21: ='24'!K21 | AB21: ='25'!K21 | AC21: ='26'!K21 | AD21: ='27'!K21 | AE21: ='28'!K21 | AF21: ='30'!K21 | AH21: =AF21-D21 -> 0 | AI21: =AVERAGE(D21:AF21) -> #DIV/0!
B22: - Daging Sapi Grade Atas | C22: Kg | D22: ='1'!K22 -> 120000 | E22: ='2'!K22 -> 120000 | F22: ='3'!K22 -> 120000 | G22: ='4'!K22 -> 120000 | H22: ='5'!K22 -> 120000 | I22: ='6'!K22 -> 120000 | J22: ='7'!K22 -> 120000 | K22: ='8'!K22 -> 120000 | L22: ='9'!K22 -> 120000 | M22: ='10'!K22 -> 120000 | N22: ='11'!K22 -> 120000 | O22: ='12'!K22 -> 120000 | P22: ='13'!K22 -> 120000 | Q22: ='14'!K22 -> 120000 | R22: ='15'!K22 -> 120000 | S22: ='14'!K22 -> 120000 | T22: ='17'!K22 -> 120000 | U22: ='18'!K22 -> 120000 | V22: ='19'!K22 -> 120000 | W22: ='20'!K22 -> 120000 | X22: ='21'!K22 -> 120000 | Y22: ='22'!K22 -> 120000 | Z22: ='23'!K22 -> 120000 | AA22: ='24'!K22 -> 120000 | AB22: ='25'!K22 -> 120000 | AC22: ='26'!K22 -> 120000 | AD22: ='27'!K22 -> 120000 | AE22: ='28'!K22 -> 120000 | AF22: ='30'!K22 -> 120000 | AG22: 105000 | AH22: =AF22-D22 -> 0 | AI22: =AVERAGE(D22:AF22) -> 120000
B23: - Daging Sapi Grade Sedang | C23: Kg | D23: ='1'!K23 -> 112000 | E23: ='2'!K23 -> 112000 | F23: ='3'!K23 -> 112000 | G23: ='4'!K23 -> 112000 | H23: ='5'!K23 -> 112000 | I23: ='6'!K23 -> 112000 | J23: ='7'!K23 -> 112000 | K23: ='8'!K23 -> 112000 | L23: ='9'!K23 -> 112000 | M23: ='10'!K23 -> 112000 | N23: ='11'!K23 -> 112000 | O23: ='12'!K23 -> 112000 | P23: ='13'!K23 -> 112000 | Q23: ='14'!K23 -> 112000 | R23: ='15'!K23 -> 112000 | S23: ='14'!K23 -> 112000 | T23: ='17'!K23 -> 112000 | U23: ='18'!K23 -> 112000 | V23: ='19'!K23 -> 112000 | W23: ='20'!K23 -> 112000 | X23: ='21'!K23 -> 112000 | Y23: ='22'!K23 -> 112000 | Z23: ='23'!K23 -> 112000 | AA23: ='24'!K23 -> 111428.57 | AB23: ='25'!K23 -> 111428.57 | AC23: ='26'!K23 -> 111428.57 | AD23: ='27'!K23 -> 111428.57 | AE23: ='28'!K23 -> 111428.57 | AF23: ='30'!K23 -> 111428.57 | AG23: 80000 | AH23: =AF23-D23 -> -571.42857 | AI23: =AVERAGE(D23:AF23) -> 111881.77
B24: - Daging Sapi Grade Bawah | C24: Kg | D24: ='1'!K24 -> 102857.14 | E24: ='2'!K24 -> 102857.14 | F24: ='3'!K24 -> 102857.14 | G24: ='4'!K24 -> 102857.14 | H24: ='5'!K24 -> 102857.14 | I24: ='6'!K24 -> 102857.14 | J24: ='7'!K24 -> 102857.14 | K24: ='8'!K24 -> 102857.14 | L24: ='9'!K24 -> 102857.14 | M24: ='10'!K24 -> 102857.14 | N24: ='11'!K24 -> 102857.14 | O24: ='12'!K24 -> 102857.14 | P24: ='13'!K24 -> 102857.14 | Q24: ='14'!K24 -> 102857.14 | R24: ='15'!K24 -> 102857.14 | S24: ='14'!K24 -> 102857.14 | T24: ='17'!K24 -> 102857.14 | U24: ='18'!K24 -> 102857.14 | V24: ='19'!K24 -> 102857.14 | W24: ='20'!K24 -> 102857.14 | X24: ='21'!K24 -> 102857.14 | Y24: ='22'!K24 -> 102857.14 | Z24: ='23'!K24 -> 102857.14 | AA24: ='24'!K24 -> 102857.14 | AB24: ='25'!K24 -> 102857.14 | AC24: ='26'!K24 -> 102857.14 | AD24: ='27'!K24 -> 102857.14 | AE24: ='28'!K24 -> 102857.14 | AF24: ='30'!K24 -> 102857.14 | AG24: 80000 | AH24: =AF24-D24 -> 0 | AI24: =AVERAGE(D24:AF24) -> 102857.14
B25: - Daging Ayam Broiler | C25: Kg | D25: ='1'!K25 -> 35857.143 | E25: ='2'!K25 -> 36142.857 | F25: ='3'!K25 -> 36714.286 | G25: ='4'!K25 -> 36714.286 | H25: ='5'!K25 -> 37000 | I25: ='6'!K25 -> 37714.286 | J25: ='7'!K25 -> 37571.429 | K25: ='8'!K25 -> 37571.429 | L25: ='9'!K25 -> 37571.429 | M25: ='10'!K25 -> 37571.429 | N25: ='11'!K25 -> 37142.857 | O25: ='12'!K25 -> 36428.571 | P25: ='13'!K25 -> 36142.857 | Q25: ='14'!K25 -> 36285.714 | R25: ='15'!K25 -> 36571.429 | S25: ='14'!K25 -> 36285.714 | T25: ='17'!K25 -> 37285.714 | U25: ='18'!K25 -> 37285.714 | V25: ='19'!K25 -> 37714.286 | W25: ='20'!K25 -> 37714.286 | X25: ='21'!K25 -> 37714.286 | Y25: ='22'!K25 -> 37857.143 | Z25: ='23'!K25 -> 38142.857 | AA25: ='24'!K25 -> 38142.857 | AB25: ='25'!K25 -> 37857.143 | AC25: ='26'!K25 -> 38142.857 | AD25: ='27'!K25 -> 38571.429 | AE25: ='28'!K25 -> 38571.429 | AF25: ='30'!K25 -> 39285.714 | AG25: 36750 | AH25: =AF25-D25 -> 3428.5714 | AI25: =AVERAGE(D25:AF25) -> 37364.532
A26: 6 | B26: I K A N | D26: ='1'!K26 | E26: ='2'!K26 | F26: ='3'!K26 | G26: ='4'!K26 | H26: ='5'!K26 | I26: ='6'!K26 | J26: ='7'!K26 | K26: ='8'!K26 | L26: ='9'!K26 | M26: ='10'!K26 | N26: ='11'!K26 | O26: ='12'!K26 | P26: ='13'!K26 | Q26: ='14'!K26 | R26: ='15'!K26 | S26: ='14'!K26 | T26: ='17'!K26 | U26: ='18'!K26 | V26: ='19'!K26 | W26: ='20'!K26 | X26: ='21'!K26 | Y26: ='22'!K26 | Z26: ='23'!K26 | AA26: ='24'!K26 | AB26: ='25'!K26 | AC26: ='26'!K26 | AD26: ='27'!K26 | AE26: ='28'!K26 | AF26: ='30'!K26 | AH26: =AF26-D26 -> 0 | AI26: =AVERAGE(D26:AF26) -> #DIV/0!
B27: - Ikan Tongkol Segar (Uk. Sedang) | C27: Kg | D27: ='1'!K27 -> 36666.667 | E27: ='2'!K27 -> 36666.667 | F27: ='3'!K27 -> 36666.667 | G27: ='4'!K27 -> 36666.667 | H27: ='5'!K27 -> 37500 | I27: ='6'!K27 -> 37500 | J27: ='7'!K27 -> 37500 | K27: ='8'!K27 -> 37500 | L27: ='9'!K27 -> 37500 | M27: ='10'!K27 -> 37500 | N27: ='11'!K27 -> 36666.667 | O27: ='12'!K27 -> 36666.667 | P27: ='13'!K27 -> 36666.667 | Q27: ='14'!K27 -> 35833.333 | R27: ='15'!K27 -> 35833.333 | S27: ='14'!K27 -> 35833.333 | T27: ='17'!K27 -> 35833.333 | U27: ='18'!K27 -> 35833.333 | V27: ='19'!K27 -> 38333.333 | W27: ='20'!K27 -> 38333.333 | X27: ='21'!K27 -> 38333.333 | Y27: ='22'!K27 -> 37500 | Z27: ='23'!K27 -> 37000 | AA27: ='24'!K27 -> 35833.333 | AB27: ='25'!K27 -> 35857.143 | AC27: ='26'!K27 -> 35857.143 | AD27: ='27'!K27 -> 35857.143 | AE27: ='28'!K27 -> 35857.143 | AF27: ='30'!K27 -> 35833.333 | AH27: =AF27-D27 -> -833.33333 | AI27: =AVERAGE(D27:AF27) -> 36738.916
B28: - Ikan Mujair Segar (Uk. Sedang) | C28: Kg | D28: ='1'!K28 -> 27714.286 | E28: ='2'!K28 -> 27428.571 | F28: ='3'!K28 -> 27714.286 | G28: ='4'!K28 -> 27714.286 | H28: ='5'!K28 -> 27428.571 | I28: ='6'!K28 -> 27428.571 | J28: ='7'!K28 -> 27428.571 | K28: ='8'!K28 -> 27428.571 | L28: ='9'!K28 -> 27714.286 | M28: ='10'!K28 -> 27714.286 | N28: ='11'!K28 -> 27571.429 | O28: ='12'!K28 -> 26000 | P28: ='13'!K28 -> 26571.429 | Q28: ='14'!K28 -> 26571.429 | R28: ='15'!K28 -> 26285.714 | S28: ='14'!K28 -> 26571.429 | T28: ='17'!K28 -> 26285.714 | U28: ='18'!K28 -> 26285.714 | V28: ='19'!K28 -> 26428.571 | W28: ='20'!K28 -> 26428.571 | X28: ='21'!K28 -> 26428.571 | Y28: ='22'!K28 -> 26428.571 | Z28: ='23'!K28 -> 26428.571 | AA28: ='24'!K28 -> 26428.571 | AB28: ='25'!K28 -> 26142.857 | AC28: ='26'!K28 -> 26285.714 | AD28: ='27'!K28 -> 26285.714 | AE28: ='28'!K28 -> 26285.714 | AF28: ='30'!K28 -> 26285.714 | AH28: =AF28-D28 -> -1428.5714 | AI28: =AVERAGE(D28:AF28) -> 26817.734
B29: - Udang Segar (Uk. Sedang) | C29: Kg | D29: ='1'!K29 -> 64714.286 | E29: ='2'!K29 -> 64000 | F29: ='3'!K29 -> 64000 | G29: ='4'!K29 -> 64000 | H29: ='5'!K29 -> 64000 | I29: ='6'!K29 -> 64000 | J29: ='7'!K29 -> 64000 | K29: ='8'!K29 -> 64000 | L29: ='9'!K29 -> 65428.571 | M29: ='10'!K29 -> 65428.571 | N29: ='11'!K29 -> 65428.571 | O29: ='12'!K29 -> 62571.429 | P29: ='13'!K29 -> 61142.857 | Q29: ='14'!K29 -> 61142.857 | R29: ='15'!K29 -> 61142.857 | S29: ='14'!K29 -> 61142.857 | T29: ='17'!K29 -> 61142.857 | U29: ='18'!K29 -> 61142.857 | V29: ='19'!K29 -> 61857.143 | W29: ='20'!K29 -> 61142.857 | X29: ='21'!K29 -> 61142.857 | Y29: ='22'!K29 -> 61142.857 | Z29: ='23'!K29 -> 61142.857 | AA29: ='24'!K29 -> 61142.857 | AB29: ='25'!K29 -> 61142.857 | AC29: ='26'!K29 -> 61142.857 | AD29: ='27'!K29 -> 61142.857 | AE29: ='28'!K29 -> 61142.857 | AF29: ='30'!K29 -> 61142.857 | AH29: =AF29-D29 -> -3571.4286 | AI29: =AVERAGE(D29:AF29) -> 62472.906
B30: - Ikan Lele Segar (Ukuran Sedang) | C30: Kg | D30: ='1'!K30 -> 24600 | E30: ='2'!K30 -> 24600 | F30: ='3'!K30 -> 24600 | G30: ='4'!K30 -> 24600 | H30: ='5'!K30 -> 24600 | I30: ='6'!K30 -> 24600 | J30: ='7'!K30 -> 24600 | K30: ='8'!K30 -> 24600 | L30: ='9'!K30 -> 24600 | M30: ='10'!K30 -> 24600 | N30: ='11'!K30 -> 24600 | O30: ='12'!K30 -> 24600 | P30: ='13'!K30 -> 24600 | Q30: ='14'!K30 -> 24600 | R30: ='15'!K30 -> 24600 | S30: ='14'!K30 -> 24600 | T30: ='17'!K30 -> 24600 | U30: ='18'!K30 -> 24600 | V30: ='19'!K30 -> 24600 | W30: ='20'!K30 -> 24600 | X30: ='21'!K30 -> 24600 | Y30: ='22'!K30 -> 24600 | Z30: ='23'!K30 -> 24600 | AA30: ='24'!K30 -> 24600 | AB30: ='25'!K30 -> 24600 | AC30: ='26'!K30 -> 24600 | AD30: ='27'!K30 -> 24600 | AE30: ='28'!K30 -> 24600 | AF30: ='30'!K30 -> 24600 | AH30: =AF30-D30 -> 0 | AI30: =AVERAGE(D30:AF30) -> 24600
B31: - Ikan Bandeng Segar (Uk. Sedang) | C31: Kg | D31: ='1'!K31 -> 37000 | E31: ='2'!K31 -> 36714.286 | F31: ='3'!K31 -> 37000 | G31: ='4'!K31 -> 37000 | H31: ='5'!K31 -> 36714.286 | I31: ='6'!K31 -> 36714.286 | J31: ='7'!K31 -> 36714.286 | K31: ='8'!K31 -> 36142.857 | L31: ='9'!K31 -> 36285.714 | M31: ='10'!K31 -> 36285.714 | N31: ='11'!K31 -> 34857.143 | O31: ='12'!K31 -> 35428.571 | P31: ='13'!K31 -> 36428.571 | Q31: ='14'!K31 -> 36428.571 | R31: ='15'!K31 -> 36142.857 | S31: ='14'!K31 -> 36428.571 | T31: ='17'!K31 -> 36142.857 | U31: ='18'!K31 -> 36142.857 | V31: ='19'!K31 -> 36714.286 | W31: ='20'!K31 -> 36714.286 | X31: ='21'!K31 -> 36714.286 | Y31: ='22'!K31 -> 36714.286 | Z31: ='23'!K31 -> 36714.286 | AA31: ='24'!K31 -> 36857.143 | AB31: ='25'!K31 -> 36857.143 | AC31: ='26'!K31 -> 36857.143 | AD31: ='27'!K31 -> 36857.143 | AE31: ='28'!K31 -> 36857.143 | AF31: ='30'!K31 -> 36714.286 | AH31: =AF31-D31 -> -285.71429 | AI31: =AVERAGE(D31:AF31) -> 36522.167
B32: - Ikan Teri Asin (Bukan Teri Medan) | C32: Kg | D32: ='1'!K32 -> 96666.667 | E32: ='2'!K32 -> 96666.667 | F32: ='3'!K32 -> 96666.667 | G32: ='4'!K32 -> 96666.667 | H32: ='5'!K32 -> 96666.667 | I32: ='6'!K32 -> 96666.667 | J32: ='7'!K32 -> 96666.667 | K32: ='8'!K32 -> 96666.667 | L32: ='9'!K32 -> 96666.667 | M32: ='10'!K32 -> 91666.667 | N32: ='11'!K32 -> 91666.667 | O32: ='12'!K32 -> 91666.667 | P32: ='13'!K32 -> 96666.667 | Q32: ='14'!K32 -> 96666.667 | R32: ='15'!K32 -> 96666.667 | S32: ='14'!K32 -> 96666.667 | T32: ='17'!K32 -> 96666.667 | U32: ='18'!K32 -> 96666.667 | V32: ='19'!K32 -> 96666.667 | W32: ='20'!K32 -> 96666.667 | X32: ='21'!K32 -> 96666.667 | Y32: ='22'!K32 -> 96666.667 | Z32: ='23'!K32 -> 96666.667 | AA32: ='24'!K32 -> 96666.667 | AB32: ='25'!K32 -> 86666.667 | AC32: ='26'!K32 -> 86666.667 | AD32: ='27'!K32 -> 86666.667 | AE32: ='28'!K32 -> 103333.33 | AF32: ='30'!K32 -> 93333.333 | AH32: =AF32-D32 -> -3333.3333 | AI32: =AVERAGE(D32:AF32) -> 95229.885
A33: 7 | B33: TELUR | D33: ='1'!K33 | E33: ='2'!K33 | F33: ='3'!K33 | G33: ='4'!K33 | H33: ='5'!K33 | I33: ='6'!K33 | J33: ='7'!K33 | K33: ='8'!K33 | L33: ='9'!K33 | M33: ='10'!K33 | N33: ='11'!K33 | O33: ='12'!K33 | P33: ='13'!K33 | Q33: ='14'!K33 | R33: ='15'!K33 | S33: ='14'!K33 | T33: ='17'!K33 | U33: ='18'!K33 | V33: ='19'!K33 | W33: ='20'!K33 | X33: ='21'!K33 | Y33: ='22'!K33 | Z33: ='23'!K33 | AA33: ='24'!K33 | AB33: ='25'!K33 | AC33: ='26'!K33 | AD33: ='27'!K33 | AE33: ='28'!K33 | AF33: ='30'!K33 | AH33: =AF33-D33 -> 0 | AI33: =AVERAGE(D33:AF33) -> #DIV/0!
B34: - Telur Ayam Horn | C34: Kg | D34: ='1'!K34 -> 29785.714 | E34: ='2'!K34 -> 29571.429 | F34: ='3'!K34 -> 29142.857 | G34: ='4'!K34 -> 29142.857 | H34: ='5'!K34 -> 28928.571 | I34: ='6'!K34 -> 28785.714 | J34: ='7'!K34 -> 29571.429 | K34: ='8'!K34 -> 29642.857 | L34: ='9'!K34 -> 29857.143 | M34: ='10'!K34 -> 30142.857 | N34: ='11'!K34 -> 29857.143 | O34: ='12'!K34 -> 29857.143 | P34: ='13'!K34 -> 29857.143 | Q34: ='14'!K34 -> 29714.286 | R34: ='15'!K34 -> 29714.286 | S34: ='14'!K34 -> 29714.286 | T34: ='17'!K34 -> 29714.286 | U34: ='18'!K34 -> 29428.571 | V34: ='19'!K34 -> 28928.571 | W34: ='20'!K34 -> 28857.143 | X34: ='21'!K34 -> 29142.857 | Y34: ='22'!K34 -> 29000 | Z34: ='23'!K34 -> 29357.143 | AA34: ='24'!K34 -> 29214.286 | AB34: ='25'!K34 -> 29357.143 | AC34: ='26'!K34 -> 29857.143 | AD34: ='27'!K34 -> 29714.286 | AE34: ='28'!K34 -> 29428.571 | AF34: ='30'!K34 -> 29714.286 | AG34: 27000 | AH34: =AF34-D34 -> -71.428571 | AI34: =AVERAGE(D34:AF34) -> 29482.759
B35: - Telur Ayam Kampung | C35: Butir | D35: ='1'!K35 -> 2414.2857 | E35: ='2'!K35 -> 2414.2857 | F35: ='3'!K35 -> 2414.2857 | G35: ='4'!K35 -> 2414.2857 | H35: ='5'!K35 -> 2414.2857 | I35: ='6'!K35 -> 2414.2857 | J35: ='7'!K35 -> 2457.1429 | K35: ='8'!K35 -> 2457.1429 | L35: ='9'!K35 -> 2457.1429 | M35: ='10'!K35 -> 2528.5714 | N35: ='11'!K35 -> 2528.5714 | O35: ='12'!K35 -> 2528.5714 | P35: ='13'!K35 -> 2457.1429 | Q35: ='14'!K35 -> 2528.5714 | R35: ='15'!K35 -> 2528.5714 | S35: ='14'!K35 -> 2528.5714 | T35: ='17'!K35 -> 2671.4286 | U35: ='18'!K35 -> 2671.4286 | V35: ='19'!K35 -> 2671.4286 | W35: ='20'!K35 -> 2671.4286 | X35: ='21'!K35 -> 2671.4286 | Y35: ='22'!K35 -> 2671.4286 | Z35: ='23'!K35 -> 2671.4286 | AA35: ='24'!K35 -> 2671.4286 | AB35: ='25'!K35 -> 2700 | AC35: ='26'!K35 -> 2700 | AD35: ='27'!K35 -> 2700 | AE35: ='28'!K35 -> 2671.4286 | AF35: ='30'!K35 -> 2671.4286 | AH35: =AF35-D35 -> 257.14286 | AI35: =AVERAGE(D35:AF35) -> 2562.069
A36: 8 | B36: TAHU | D36: ='1'!K36 | E36: ='2'!K36 | F36: ='3'!K36 | G36: ='4'!K36 | H36: ='5'!K36 | I36: ='6'!K36 | J36: ='7'!K36 | K36: ='8'!K36 | L36: ='9'!K36 | M36: ='10'!K36 | N36: ='11'!K36 | O36: ='12'!K36 | P36: ='13'!K36 | Q36: ='14'!K36 | R36: ='15'!K36 | S36: ='14'!K36 | T36: ='17'!K36 | U36: ='18'!K36 | V36: ='19'!K36 | W36: ='20'!K36 | X36: ='21'!K36 | Y36: ='22'!K36 | Z36: ='23'!K36 | AA36: ='24'!K36 | AB36: ='25'!K36 | AC36: ='26'!K36 | AD36: ='27'!K36 | AE36: ='28'!K36 | AF36: ='30'!K36 | AH36: =AF36-D36 -> 0 | AI36: =AVERAGE(D36:AF36) -> #DIV/0!
B37: - Tahu biasa | C37: Kg | D37: ='1'!K37 -> 10714.286 | E37: ='2'!K37 -> 10714.286 | F37: ='3'!K37 -> 10714.286 | G37: ='4'!K37 -> 10714.286 | H37: ='5'!K37 -> 10714.286 | I37: ='6'!K37 -> 10714.286 | J37: ='7'!K37 -> 10714.286 | K37: ='8'!K37 -> 10714.286 | L37: ='9'!K37 -> 10714.286 | M37: ='10'!K37 -> 10714.286 | N37: ='11'!K37 -> 10714.286 | O37: ='12'!K37 -> 10000 | P37: ='13'!K37 -> 10000 | Q37: ='14'!K37 -> 10000 | R37: ='15'!K37 -> 10000 | S37: ='14'!K37 -> 10000 | T37: ='17'!K37 -> 10000 | U37: ='18'!K37 -> 10000 | V37: ='19'!K37 -> 10000 | W37: ='20'!K37 -> 10000 | X37: ='21'!K37 -> 10000 | Y37: ='22'!K37 -> 10000 | Z37: ='23'!K37 -> 10000 | AA37: ='24'!K37 -> 10000 | AB37: ='25'!K37 -> 10000 | AC37: ='26'!K37 -> 10000 | AD37: ='27'!K37 -> 10000 | AE37: ='28'!K37 -> 10000 | AF37: ='30'!K37 -> 10000 | AH37: =AF37-D37 -> -714.28571 | AI37: =AVERAGE(D37:AF37) -> 10270.936
B38: - Tahu susu | C38: Kg | D38: ='1'!K38 -> 12600 | E38: ='2'!K38 -> 12600 | F38: ='3'!K38 -> 12600 | G38: ='4'!K38 -> 12600 | H38: ='5'!K38 -> 12600 | I38: ='6'!K38 -> 12600 | J38: ='7'!K38 -> 12600 | K38: ='8'!K38 -> 12600 | L38: ='9'!K38 -> 12600 | M38: ='10'!K38 -> 12600 | N38: ='11'!K38 -> 12600 | O38: ='12'!K38 -> 12600 | P38: ='13'!K38 -> 12600 | Q38: ='14'!K38 -> 12600 | R38: ='15'!K38 -> 12600 | S38: ='14'!K38 -> 12600 | T38: ='17'!K38 -> 12600 | U38: ='18'!K38 -> 12600 | V38: ='19'!K38 -> 12600 | W38: ='20'!K38 -> 12600 | X38: ='21'!K38 -> 12600 | Y38: ='22'!K38 -> 12600 | Z38: ='23'!K38 -> 12600 | AA38: ='24'!K38 -> 12600 | AB38: ='25'!K38 -> 12600 | AC38: ='26'!K38 -> 12600 | AD38: ='27'!K38 -> 12600 | AE38: ='28'!K38 -> 12600 | AF38: ='30'!K38 -> 12600 | AH38: =AF38-D38 -> 0 | AI38: =AVERAGE(D38:AF38) -> 12600
A39: 9 | B39: TEMPE | D39: ='1'!K39 | E39: ='2'!K39 | F39: ='3'!K39 | G39: ='4'!K39 | H39: ='5'!K39 | I39: ='6'!K39 | J39: ='7'!K39 | K39: ='8'!K39 | L39: ='9'!K39 | M39: ='10'!K39 | N39: ='11'!K39 | O39: ='12'!K39 | P39: ='13'!K39 | Q39: ='14'!K39 | R39: ='15'!K39 | S39: ='14'!K39 | T39: ='17'!K39 | U39: ='18'!K39 | V39: ='19'!K39 | W39: ='20'!K39 | X39: ='21'!K39 | Y39: ='22'!K39 | Z39: ='23'!K39 | AA39: ='24'!K39 | AB39: ='25'!K39 | AC39: ='26'!K39 | AD39: ='27'!K39 | AE39: ='28'!K39 | AF39: ='30'!K39 | AH39: =AF39-D39 -> 0 | AI39: =AVERAGE(D39:AF39) -> #DIV/0!
B40: - Tempe Kw I (campuran kedelai) | C40: Kg | D40: ='1'!K40 -> 15600 | E40: ='2'!K40 -> 15600 | F40: ='3'!K40 -> 15600 | G40: ='4'!K40 -> 15600 | H40: ='5'!K40 -> 15600 | I40: ='6'!K40 -> 15600 | J40: ='7'!K40 -> 15600 | K40: ='8'!K40 -> 15600 | L40: ='9'!K40 -> 15600 | M40: ='10'!K40 -> 15600 | N40: ='11'!K40 -> 15600 | O40: ='12'!K40 -> 14000 | P40: ='13'!K40 -> 14000 | Q40: ='14'!K40 -> 14000 | R40: ='15'!K40 -> 14000 | S40: ='14'!K40 -> 14000 | T40: ='17'!K40 -> 14000 | U40: ='18'!K40 -> 14000 | V40: ='19'!K40 -> 14000 | W40: ='20'!K40 -> 14000 | X40: ='21'!K40 -> 14000 | Y40: ='22'!K40 -> 14000 | Z40: ='23'!K40 -> 14000 | AA40: ='24'!K40 -> 14000 | AB40: ='25'!K40 -> 14000 | AC40: ='26'!K40 -> 14000 | AD40: ='27'!K40 -> 14000 | AE40: ='28'!K40 -> 14000 | AF40: ='30'!K40 -> 14000 | AH40: =AF40-D40 -> -1600 | AI40: =AVERAGE(D40:AF40) -> 14606.897
B41: - Tempe Kw II (campuran jagung) | C41: Kg | D41: ='1'!K41 -> 6833.3333 | E41: ='2'!K41 -> 6833.3333 | F41: ='3'!K41 -> 6833.3333 | G41: ='4'!K41 -> 6833.3333 | H41: ='5'!K41 -> 6833.3333 | I41: ='6'!K41 -> 6833.3333 | J41: ='7'!K41 -> 6833.3333 | K41: ='8'!K41 -> 6833.3333 | L41: ='9'!K41 -> 6833.3333 | M41: ='10'!K41 -> 6833.3333 | N41: ='11'!K41 -> 6833.3333 | O41: ='12'!K41 -> 6833.3333 | P41: ='13'!K41 -> 6833.3333 | Q41: ='14'!K41 -> 6833.3333 | R41: ='15'!K41 -> 6833.3333 | S41: ='14'!K41 -> 6833.3333 | T41: ='17'!K41 -> 6833.3333 | U41: ='18'!K41 -> 6833.3333 | V41: ='19'!K41 -> 6833.3333 | W41: ='20'!K41 -> 6833.3333 | X41: ='21'!K41 -> 6833.3333 | Y41: ='22'!K41 -> 6833.3333 | Z41: ='23'!K41 -> 6833.3333 | AA41: ='24'!K41 -> 6833.3333 | AB41: ='25'!K41 -> 6833.3333 | AC41: ='26'!K41 -> 6833.3333 | AD41: ='27'!K41 -> 6833.3333 | AE41: ='28'!K41 -> 6833.3333 | AF41: ='30'!K41 -> 6833.3333 | AH41: =AF41-D41 -> 0 | AI41: =AVERAGE(D41:AF41) -> 6833.3333
...

Sheet 1
A1: HARGA BAHAN-BAHAN POKOK
A2: DI PASAR TRADISIONAL KOTA SURABAYA
A3: HARI / TANGGAL : Kamis / 01 Juni 2023
B4: NAMA BAHAN POKOK DAN PENTING LAINNYA | C4: SATUAN | D4: Pasar Tambahrejo | E4: Pasar Pucang Anom | F4: Pasar Wonokromo | G4: Pasar Genteng Baru | H4: Pasar Pabean | I4: Pasar Kembang | J4: Pasar Balongsari | K4: Rata-Rata
A7: 1 | B7: BERAS
B8: - Beras Premium | C8: Kg | D8: 13000 | E8: 13500 | F8: 14000 | G8: 13500 | H8: 12000 | I8: 14000 | J8: 13500 | K8: =AVERAGE(D8:J8) -> 13357.143
B9: - Beras Medium Bulog | C9: Kg | D9: 9000 | E9: 9000 | F9: 9000 | G9: 9000 | H9: - | I9: - | J9: - | K9: =AVERAGE(D9:J9) -> 9000
B10: - Beras Medium | C10: Kg | D10: 11000 | E10: 11500 | F10: 12000 | G10: 11500 | H10: - | I10: 12500 | J10: 12500 | K10: =AVERAGE(D10:J10) -> 11833.333
B11: - Beras Jagung | C11: Kg | D11: - | E11: 10000 | F11: 12000 | G11: 12000 | H11: - | I11: 11000 | J11: 8000 | K11: =AVERAGE(D11:J11) -> 10600
B12: - Beras Ketan (Jenis Siyem) | C12: Kg | D12: - | E12: 22000 | F12: 24000 | G12: 20000 | H12: - | I12: 18000 | J12: 17000 | K12: =AVERAGE(D12:J12) -> 20200
A13: 2 | B13: GULA
B14: - Gula pasir lokal curah | C14: Kg | D14: 13000 | E14: 13500 | F14: 14000 | G14: 13500 | H14: 13500 | I14: 13500 | J14: 14000 | K14: =AVERAGE(D14:J14) -> 13571.429
B15: - Gula Jawa/Merah (Bahan Kelapa) | C15: Kg | D15: 15000 | E15: 16000 | F15: 15000 | G15: 16000 | H15: 15000 | I15: 18000 | J15: 16000 | K15: =AVERAGE(D15:J15) -> 15857.143
A16: 3 | B16: MINYAK GORENG
B17: - Minyak Goreng Curah (Bening) | C17: Kg | D17: 14500 | E17: 16000 | F17: 17000 | G17: 16000 | H17: 14000 | I17: 16000 | J17: 15500 | K17: =AVERAGE(D17:J17) -> 15571.429
B18: - Minyak Kita | C18: Liter | D18: 14000 | E18: 14000 | F18: 14000 | G18: 14000 | H18: - | I18: 14000 | J18: 14000 | K18: =AVERAGE(D18:J18) -> 14000
A19: 4 | B19: MENTEGA
B20: - Mentega Curah (Amanda) | C20: Kg | D20: 20000 | E20: - | F20: 19000 | G20: 22000 | H20: - | I20: 24000 | J20: - | K20: =AVERAGE(D20:J20) -> 21250
A21: 5 | B21: DAGING
B22: - Daging Sapi Grade Atas | C22: Kg | D22: 120000 | E22: 120000 | F22: 120000 | G22: 120000 | H22: 120000 | I22: 120000 | J22: - | K22: =AVERAGE(D22:J22) -> 120000
B23: - Daging Sapi Grade Sedang | C23: Kg | D23: 110000 | E23: 110000 | F23: 110000 | G23: 110000 | H23: 114000 | I23: 115000 | J23: 115000 | K23: =AVERAGE(D23:J23) -> 112000
B24: - Daging Sapi Grade Bawah | C24: Kg | D24: 100000 | E24: 95000 | F24: 105000 | G24: 105000 | H24: 100000 | I24: 110000 | J24: 105000 | K24: =AVERAGE(D24:J24) -> 102857.14
B25: - Daging Ayam Broiler | C25: Kg | D25: 36000 | E25: 36000 | F25: 35000 | G25: 35000 | H25: 36000 | I25: 35000 | J25: 38000 | K25: =AVERAGE(D25:J25) -> 35857.143
A26: 6 | B26: I K A N
B27: - Ikan Tongkol Segar (Uk. Sedang) | C27: Kg | D27: 30000 | E27: 40000 | F27: - | G27: 45000 | H27: 30000 | I27: 40000 | J27: 35000 | K27: =AVERAGE(D27:J27) -> 36666.667
B28: - Ikan Mujair Segar (Uk. Sedang) | C28: Kg | D28: 25000 | E28: 28000 | F28: 28000 | G28: 35000 | H28: 23000 | I28: 29000 | J28: 26000 | K28: =AVERAGE(D28:J28) -> 27714.286
B29: - Udang Segar (Uk. Sedang) | C29: Kg | D29: 80000 | E29: 60000 | F29: 60000 | G29: 75000 | H29: 58000 | I29: 60000 | J29: 60000 | K29: =AVERAGE(D29:J29) -> 64714.286
B30: - Ikan Lele Segar (Ukuran Sedang) | C30: Kg | D30: 25000 | E30: - | F30: - | G30: 25000 | H30: 23000 | I30: 24000 | J30: 26000 | K30: =AVERAGE(D30:J30) -> 24600
B31: - Ikan Bandeng Segar (Uk. Sedang) | C31: Kg | D31: 35000 | E31: 35000 | F31: 36000 | G31: 45000 | H31: 28000 | I31: 40000 | J31: 40000 | K31: =AVERAGE(D31:J31) -> 37000
B32: - Ikan Teri Asin (Bukan Teri Medan) | C32: Kg | D32: - | E32: 100000 | F32: 110000 | G32: - | H32: 80000 | I32: - | J32: - | K32: =AVERAGE(D32:J32) -> 96666.667
A33: 7 | B33: TELUR
B34: - Telur Ayam Broiler | C34: Kg | D34: 29000 | E34: 30000 | F34: 30000 | G34: 31000 | H34: 29000 | I34: 29000 | J34: 30500 | K34: =AVERAGE(D34:J34) -> 29785.714
B35: - Telur Ayam Kampung | C35: Butir | D35: 3000 | E35: 2200 | F35: 2000 | G35: 2200 | H35: 2000 | I35: 2500 | J35: 3000 | K35: =AVERAGE(D35:J35) -> 2414.2857
A36: 8 | B36: TAHU
B37: - Tahu biasa | C37: Kg | D37: 10000 | E37: 10000 | F37: 9000 | G37: 9000 | H37: 16000 | I37: 12000 | J37: 9000 | K37: =AVERAGE(D37:J37) -> 10714.286
B38: - Tahu susu | C38: Kg | D38: - | E38: 7000 | F38: 12000 | G38: 17000 | H38: - | I38: 15000 | J38: 12000 | K38: =AVERAGE(D38:J38) -> 12600
A39: 9 | B39: TEMPE
B40: - Tempe Kw I (campuran kedelai) | C40: Kg | D40: - | E40: 18000 | F40: - | G40: 16000 | H40: 14000 | I40: 15000 | J40: 15000 | K40: =AVERAGE(D40:J40) -> 15600
B41: - Tempe Kw II (campuran jagung) | C41: Kg | D41: 2500 | E41: 12000 | F41: 6000 | G41: - | H41: - | I41: - | J41: - | K41: =AVERAGE(D41:J41) -> 6833.3333
B42: - Tempe Kw III (campuran kulit) | C42: Kg | D42: - | E42: 2000 | F42: - | G42: - | H42: - | I42: - | J42: - | K42: =AVERAGE(D42:J42) -> 2000
...

Sheet 2
A1: HARGA BAHAN-BAHAN POKOK
A2: DI PASAR TRADISIONAL KOTA SURABAYA
A3: HARI / TANGGAL : Jumat / 02 Juni 2023
B4: NAMA BAHAN POKOK DAN PENTING LAINNYA | C4: SATUAN | D4: Pasar Tambahrejo | E4: Pasar Pucang Anom | F4: Pasar Wonokromo | G4: Pasar Genteng Baru | H4: Pasar Pabean | I4: Pasar Kembang | J4: Pasar Balongsari | K4: Rata-Rata
A7: 1 | B7: BERAS
B8: - Beras Premium | C8: Kg | D8: 13000 | E8: 13500 | F8: 14000 | G8: 13500 | H8: 12000 | I8: 14000 | J8: 13500 | K8: =AVERAGE(D8:J8) -> 13357.143
B9: - Beras Medium Bulog | C9: Kg | D9: 9000 | E9: 9000 | F9: 9000 | G9: 9000 | H9: - | I9: - | J9: - | K9: =AVERAGE(D9:J9) -> 9000
B10: - Beras Medium | C10: Kg | D10: 11000 | E10: 11500 | F10: 12000 | G10: 11500 | H10: - | I10: 12500 | J10: 12500 | K10: =AVERAGE(D10:J10) -> 11833.333
B11: - Beras Jagung | C11: Kg | D11: - | E11: 10000 | F11: 12000 | G11: 12000 | H11: - | I11: 11000 | J11: 8000 | K11: =AVERAGE(D11:J11) -> 10600
B12: - Beras Ketan (Jenis Siyem) | C12: Kg | D12: - | E12: 22000 | F12: 18000 | G12: 20000 | H12: - | I12: 18000 | J12: 17000 | K12: =AVERAGE(D12:J12) -> 19000
A13: 2 | B13: GULA
B14: - Gula pasir lokal curah | C14: Kg | D14: 13000 | E14: 13500 | F14: 14000 | G14: 13500 | H14: 13500 | I14: 13500 | J14: 13500 | K14: =AVERAGE(D14:J14) -> 13500
B15: - Gula Jawa/Merah (Bahan Kelapa) | C15: Kg | D15: 15000 | E15: 16000 | F15: 24000 | G15: 16000 | H15: 15000 | I15: 18000 | J15: 16000 | K15: =AVERAGE(D15:J15) -> 17142.857
A16: 3 | B16: MINYAK GORENG
B17: - Minyak Goreng Curah (Bening) | C17: Kg | D17: 14500 | E17: 16000 | F17: 17000 | G17: 16000 | H17: 14000 | I17: 16000 | J17: 15500 | K17: =AVERAGE(D17:J17) -> 15571.429
B18: - Minyak Kita | C18: Liter | D18: 14000 | E18: 14000 | F18: 14000 | G18: 14000 | H18: - | I18: 14000 | J18: 14000 | K18: =AVERAGE(D18:J18) -> 14000
A19: 4 | B19: MENTEGA
B20: - Mentega Curah (Amanda) | C20: Kg | D20: 20000 | E20: - | F20: 19000 | G20: 22000 | H20: - | I20: 24000 | J20: - | K20: =AVERAGE(D20:J20) -> 21250
A21: 5 | B21: DAGING
B22: - Daging Sapi Grade Atas | C22: Kg | D22: 120000 | E22: 120000 | F22: 120000 | G22: 120000 | H22: 120000 | I22: 120000 | J22: - | K22: =AVERAGE(D22:J22) -> 120000
B23: - Daging Sapi Grade Sedang | C23: Kg | D23: 110000 | E23: 110000 | F23: 110000 | G23: 110000 | H23: 114000 | I23: 115000 | J23: 115000 | K23: =AVERAGE(D23:J23) -> 112000
B24: - Daging Sapi Grade Bawah | C24: Kg | D24: 100000 | E24: 95000 | F24: 105000 | G24: 105000 | H24: 100000 | I24: 110000 | J24: 105000 | K24: =AVERAGE(D24:J24) -> 102857.14
B25: - Daging Ayam Broiler | C25: Kg | D25: 36000 | E25: 36000 | F25: 35000 | G25: 35000 | H25: 36000 | I25: 35000 | J25: 40000 | K25: =AVERAGE(D25:J25) -> 36142.857
A26: 6 | B26: I K A N
B27: - Ikan Tongkol Segar (Uk. Sedang) | C27: Kg | D27: 30000 | E27: 40000 | F27: - | G27: 45000 | H27: 30000 | I27: 40000 | J27: 35000 | K27: =AVERAGE(D27:J27) -> 36666.667
B28: - Ikan Mujair Segar (Uk. Sedang) | C28: Kg | D28: 25000 | E28: 28000 | F28: 28000 | G28: 35000 | H28: 23000 | I28: 29000 | J28: 24000 | K28: =AVERAGE(D28:J28) -> 27428.571
B29: - Udang Segar (Uk. Sedang) | C29: Kg | D29: 80000 | E29: 60000 | F29: 60000 | G29: 75000 | H29: 58000 | I29: 60000 | J29: 55000 | K29: =AVERAGE(D29:J29) -> 64000
B30: - Ikan Lele Segar (Ukuran Sedang) | C30: Kg | D30: 25000 | E30: - | F30: - | G30: 25000 | H30: 23000 | I30: 24000 | J30: 26000 | K30: =AVERAGE(D30:J30) -> 24600
B31: - Ikan Bandeng Segar (Uk. Sedang) | C31: Kg | D31: 35000 | E31: 35000 | F31: 36000 | G31: 45000 | H31: 28000 | I31: 40000 | J31: 38000 | K31: =AVERAGE(D31:J31) -> 36714.286
B32: - Ikan Teri Asin (Bukan Teri Medan) | C32: Kg | D32: - | E32: 100000 | F32: 110000 | G32: - | H32: 80000 | I32: - | J32: - | K32: =AVERAGE(D32:J32) -> 96666.667
A33: 7 | B33: TELUR
B34: - Telur Ayam Broiler | C34: Kg | D34: 29000 | E34: 30000 | F34: 30000 | G34: 30000 | H34: 29000 | I34: 29000 | J34: 30000 | K34: =AVERAGE(D34:J34) -> 29571.429
B35: - Telur Ayam Kampung | C35: Butir | D35: 3000 | E35: 2200 | F35: 2000 | G35: 2200 | H35: 2000 | I35: 2500 | J35: 3000 | K35: =AVERAGE(D35:J35) -> 2414.2857
A36: 8 | B36: TAHU
B37: - Tahu biasa | C37: Kg | D37: 10000 | E37: 10000 | F37: 9000 | G37: 9000 | H37: 16000 | I37: 12000 | J37: 9000 | K37: =AVERAGE(D37:J37) -> 10714.286
B38: - Tahu susu | C38: Kg | D38: - | E38: 7000 | F38: 12000 | G38: 17000 | H38: - | I38: 15000 | J38: 12000 | K38: =AVERAGE(D38:J38) -> 12600
A39: 9 | B39: TEMPE
B40: - Tempe Kw I (campuran kedelai) | C40: Kg | D40: - | E40: 18000 | F40: - | G40: 16000 | H40: 14000 | I40: 15000 | J40: 15000 | K40: =AVERAGE(D40:J40) -> 15600
B41: - Tempe Kw II (campuran jagung) | C41: Kg | D41: 2500 | E41: 12000 | F41: 6000 | G41: - | H41: - | I41: - | J41: - | K41: =AVERAGE(D41:J41) -> 6833.3333
B42: - Tempe Kw III (campuran kulit) | C42: Kg | D42: - | E42: 2000 | F42: - | G42: - | H42: - | I42: - | J42: - | K42: =AVERAGE(D42:J42) -> 2000
...

Sheet 3
A1: HARGA BAHAN-BAHAN POKOK
A2: DI PASAR TRADISIONAL KOTA SURABAYA
A3: HARI / TANGGAL : Sabtu / 03 Juni 2023
B4: NAMA BAHAN POKOK DAN PENTING LAINNYA | C4: SATUAN | D4: Pasar Tambahrejo | E4: Pasar Pucang Anom | F4: Pasar Wonokromo | G4: Pasar Genteng Baru | H4: Pasar Pabean | I4: Pasar Kembang | J4: Pasar Balongsari | K4: Rata-Rata
A7: 1 | B7: BERAS
B8: - Beras Premium | C8: Kg | D8: 13000 | E8: 13500 | F8: 14000 | G8: 13500 | H8: 12000 | I8: 14000 | J8: 13500 | K8: =AVERAGE(D8:J8) -> 13357.143
B9: - Beras Medium Bulog | C9: Kg | D9: 9000 | E9: 9000 | F9: 9000 | G9: 9000 | H9: - | I9: - | J9: - | K9: =AVERAGE(D9:J9) -> 9000
B10: - Beras Medium | C10: Kg | D10: 11000 | E10: 11500 | F10: 13000 | G10: 11500 | H10: - | I10: 12500 | J10: 12500 | K10: =AVERAGE(D10:J10) -> 12000
B11: - Beras Jagung | C11: Kg | D11: - | E11: 10000 | F11: 12000 | G11: 12000 | H11: - | I11: 11000 | J11: 8000 | K11: =AVERAGE(D11:J11) -> 10600
B12: - Beras Ketan (Jenis Siyem) | C12: Kg | D12: - | E12: 22000 | F12: 18000 | G12: 20000 | H12: - | I12: 18000 | J12: 17000 | K12: =AVERAGE(D12:J12) -> 19000
A13: 2 | B13: GULA
B14: - Gula pasir lokal curah | C14: Kg | D14: 13000 | E14: 13500 | F14: 14000 | G14: 13500 | H14: 13500 | I14: 13500 | J14: 13500 | K14: =AVERAGE(D14:J14) -> 13500
B15: - Gula Jawa/Merah (Bahan Kelapa) | C15: Kg | D15: 15000 | E15: 16000 | F15: 24000 | G15: 16000 | H15: 15000 | I15: 18000 | J15: 16000 | K15: =AVERAGE(D15:J15) -> 17142.857
A16: 3 | B16: MINYAK GORENG
B17: - Minyak Goreng Curah (Bening) | C17: Kg | D17: 14500 | E17: 16000 | F17: 17000 | G17: 16000 | H17: 14000 | I17: 16000 | J17: 15500 | K17: =AVERAGE(D17:J17) -> 15571.429
B18: - Minyak Kita | C18: Liter | D18: 14000 | E18: 14000 | F18: 14000 | G18: 14000 | H18: - | I18: 14000 | J18: 14000 | K18: =AVERAGE(D18:J18) -> 14000
A19: 4 | B19: MENTEGA
B20: - Mentega Curah (Amanda) | C20: Kg | D20: 20000 | E20: - | F20: 19000 | G20: 22000 | H20: - | I20: 24000 | J20: - | K20: =AVERAGE(D20:J20) -> 21250
A21: 5 | B21: DAGING
B22: - Daging Sapi Grade Atas | C22: Kg | D22: 120000 | E22: 120000 | F22: 120000 | G22: 120000 | H22: 120000 | I22: 120000 | J22: - | K22: =AVERAGE(D22:J22) -> 120000
B23: - Daging Sapi Grade Sedang | C23: Kg | D23: 110000 | E23: 110000 | F23: 110000 | G23: 110000 | H23: 114000 | I23: 115000 | J23: 115000 | K23: =AVERAGE(D23:J23) -> 112000
B24: - Daging Sapi Grade Bawah | C24: Kg | D24: 100000 | E24: 95000 | F24: 105000 | G24: 105000 | H24: 100000 | I24: 110000 | J24: 105000 | K24: =AVERAGE(D24:J24) -> 102857.14
B25: - Daging Ayam Broiler | C25: Kg | D25: 36000 | E25: 36000 | F25: 35000 | G25: 35000 | H25: 40000 | I25: 35000 | J25: 40000 | K25: =AVERAGE(D25:J25) -> 36714.286
A26: 6 | B26: I K A N
B27: - Ikan Tongkol Segar (Uk. Sedang) | C27: Kg | D27: 30000 | E27: 40000 | F27: - | G27: 45000 | H27: 30000 | I27: 40000 | J27: 35000 | K27: =AVERAGE(D27:J27) -> 36666.667
B28: - Ikan Mujair Segar (Uk. Sedang) | C28: Kg | D28: 25000 | E28: 28000 | F28: 30000 | G28: 35000 | H28: 23000 | I28: 29000 | J28: 24000 | K28: =AVERAGE(D28:J28) -> 27714.286
B29: - Udang Segar (Uk. Sedang) | C29: Kg | D29: 80000 | E29: 60000 | F29: 60000 | G29: 75000 | H29: 58000 | I29: 60000 | J29: 55000 | K29: =AVERAGE(D29:J29) -> 64000
B30: - Ikan Lele Segar (Ukuran Sedang) | C30: Kg | D30: 25000 | E30: - | F30: - | G30: 25000 | H30: 23000 | I30: 24000 | J30: 26000 | K30: =AVERAGE(D30:J30) -> 24600
B31: - Ikan Bandeng Segar (Uk. Sedang) | C31: Kg | D31: 35000 | E31: 35000 | F31: 38000 | G31: 45000 | H31: 28000 | I31: 40000 | J31: 38000 | K31: =AVERAGE(D31:J31) -> 37000
B32: - Ikan Teri Asin (Bukan Teri Medan) | C32: Kg | D32: - | E32: 100000 | F32: 110000 | G32: - | H32: 80000 | I32: - | J32: - | K32: =AVERAGE(D32:J32) -> 96666.667
A33: 7 | B33: TELUR
B34: - Telur Ayam Broiler | C34: Kg | D34: 29000 | E34: 30000 | F34: 30000 | G34: 30000 | H34: 28000 | I34: 27000 | J34: 30000 | K34: =AVERAGE(D34:J34) -> 29142.857
B35: - Telur Ayam Kampung | C35: Butir | D35: 3000 | E35: 2200 | F35: 2000 | G35: 2200 | H35: 2000 | I35: 2500 | J35: 3000 | K35: =AVERAGE(D35:J35) -> 2414.2857
A36: 8 | B36: TAHU
B37: - Tahu biasa | C37: Kg | D37: 10000 | E37: 10000 | F37: 9000 | G37: 9000 | H37: 16000 | I37: 12000 | J37: 9000 | K37: =AVERAGE(D37:J37) -> 10714.286
B38: - Tahu susu | C38: Kg | D38: - | E38: 7000 | F38: 12000 | G38: 17000 | H38: - | I38: 15000 | J38: 12000 | K38: =AVERAGE(D38:J38) -> 12600
A39: 9 | B39: TEMPE
B40: - Tempe Kw I (campuran kedelai) | C40: Kg | D40: - | E40: 18000 | F40: - | G40: 16000 | H40: 14000 | I40: 15000 | J40: 15000 | K40: =AVERAGE(D40:J40) -> 15600
B41: - Tempe Kw II (campuran jagung) | C41: Kg | D41: 2500 | E41: 12000 | F41: 6000 | G41: - | H41: - | I41: - | J41: - | K41: =AVERAGE(D41:J41) -> 6833.3333
B42: - Tempe Kw III (campuran kulit) | C42: Kg | D42: - | E42: 2000 | F42: - | G42: - | H42: - | I42: - | J42: - | K42: =AVERAGE(D42:J42) -> 2000
...

Sheet 4
A1: HARGA BAHAN-BAHAN POKOK
A2: DI PASAR TRADISIONAL KOTA SURABAYA
A3: HARI / TANGGAL : Minggu / 04 Juni 2023
B4: NAMA BAHAN POKOK DAN PENTING LAINNYA | C4: SATUAN | D4: Pasar Tambahrejo | E4: Pasar Pucang Anom | F4: Pasar Wonokromo | G4: Pasar Genteng Baru | H4: Pasar Pabean | I4: Pasar Kembang | J4: Pasar Balongsari | K4: Rata-Rata
A7: 1 | B7: BERAS
B8: - Beras Premium | C8: Kg | D8: 13000 | E8: 13500 | F8: 14000 | G8: 13500 | H8: 12000 | I8: 14000 | J8: 13500 | K8: =AVERAGE(D8:J8) -> 13357.143
B9: - Beras Medium Bulog | C9: Kg | D9: 9000 | E9: 9000 | F9: 9000 | G9: 9000 | H9: - | I9: - | J9: - | K9: =AVERAGE(D9:J9) -> 9000
B10: - Beras Medium | C10: Kg | D10: 11000 | E10: 11500 | F10: 13000 | G10: 11500 | H10: - | I10: 12500 | J10: 12500 | K10: =AVERAGE(D10:J10) -> 12000
B11: - Beras Jagung | C11: Kg | D11: - | E11: 10000 | F11: 12000 | G11: 12000 | H11: - | I11: 11000 | J11: 8000 | K11: =AVERAGE(D11:J11) -> 10600
B12: - Beras Ketan (Jenis Siyem) | C12: Kg | D12: - | E12: 22000 | F12: 18000 | G12: 20000 | H12: - | I12: 18000 | J12: 17000 | K12: =AVERAGE(D12:J12) -> 19000
A13: 2 | B13: GULA
B14: - Gula pasir lokal curah | C14: Kg | D14: 13000 | E14: 13500 | F14: 13500 | G14: 13500 | H14: 13500 | I14: 13500 | J14: 13500 | K14: =AVERAGE(D14:J14) -> 13428.571
B15: - Gula Jawa/Merah (Bahan Kelapa) | C15: Kg | D15: 15000 | E15: 16000 | F15: 20000 | G15: 16000 | H15: 15000 | I15: 18000 | J15: 16000 | K15: =AVERAGE(D15:J15) -> 16571.429
A16: 3 | B16: MINYAK GORENG
B17: - Minyak Goreng Curah (Bening) | C17: Kg | D17: 14500 | E17: 16000 | F17: 17000 | G17: 16000 | H17: 14000 | I17: 16000 | J17: 15500 | K17: =AVERAGE(D17:J17) -> 15571.429
B18: - Minyak Kita | C18: Liter | D18: 14000 | E18: 14000 | F18: 14000 | G18: 14000 | H18: - | I18: 14000 | J18: 14000 | K18: =AVERAGE(D18:J18) -> 14000
A19: 4 | B19: MENTEGA
B20: - Mentega Curah (Amanda) | C20: Kg | D20: 20000 | E20: - | F20: 19000 | G20: 22000 | H20: - | I20: 24000 | J20: - | K20: =AVERAGE(D20:J20) -> 21250
A21: 5 | B21: DAGING
B22: - Daging Sapi Grade Atas | C22: Kg | D22: 120000 | E22: 120000 | F22: 120000 | G22: 120000 | H22: 120000 | I22: 120000 | J22: - | K22: =AVERAGE(D22:J22) -> 120000
B23: - Daging Sapi Grade Sedang | C23: Kg | D23: 110000 | E23: 110000 | F23: 110000 | G23: 110000 | H23: 114000 | I23: 115000 | J23: 115000 | K23: =AVERAGE(D23:J23) -> 112000
B24: - Daging Sapi Grade Bawah | C24: Kg | D24: 100000 | E24: 95000 | F24: 105000 | G24: 105000 | H24: 100000 | I24: 110000 | J24: 105000 | K24: =AVERAGE(D24:J24) -> 102857.14
B25: - Daging Ayam Broiler | C25: Kg | D25: 36000 | E25: 36000 | F25: 35000 | G25: 35000 | H25: 40000 | I25: 35000 | J25: 40000 | K25: =AVERAGE(D25:J25) -> 36714.286
A26: 6 | B26: I K A N
B27: - Ikan Tongkol Segar (Uk. Sedang) | C27: Kg | D27: 30000 | E27: 40000 | F27: - | G27: 45000 | H27: 30000 | I27: 40000 | J27: 35000 | K27: =AVERAGE(D27:J27) -> 36666.667
B28: - Ikan Mujair Segar (Uk. Sedang) | C28: Kg | D28: 25000 | E28: 28000 | F28: 30000 | G28: 35000 | H28: 23000 | I28: 29000 | J28: 24000 | K28: =AVERAGE(D28:J28) -> 27714.286
B29: - Udang Segar (Uk. Sedang) | C29: Kg | D29: 80000 | E29: 60000 | F29: 60000 | G29: 75000 | H29: 58000 | I29: 60000 | J29: 55000 | K29: =AVERAGE(D29:J29) -> 64000
B30: - Ikan Lele Segar (Ukuran Sedang) | C30: Kg | D30: 25000 | E30: - | F30: - | G30: 25000 | H30: 23000 | I30: 24000 | J30: 26000 | K30: =AVERAGE(D30:J30) -> 24600
B31: - Ikan Bandeng Segar (Uk. Sedang) | C31: Kg | D31: 35000 | E31: 35000 | F31: 38000 | G31: 45000 | H31: 28000 | I31: 40000 | J31: 38000 | K31: =AVERAGE(D31:J31) -> 37000
B32: - Ikan Teri Asin (Bukan Teri Medan) | C32: Kg | D32: - | E32: 100000 | F32: 110000 | G32: - | H32: 80000 | I32: - | J32: - | K32: =AVERAGE(D32:J32) -> 96666.667
A33: 7 | B33: TELUR
B34: - Telur Ayam Broiler | C34: Kg | D34: 29000 | E34: 30000 | F34: 30000 | G34: 30000 | H34: 28000 | I34: 27000 | J34: 30000 | K34: =AVERAGE(D34:J34) -> 29142.857
B35: - Telur Ayam Kampung | C35: Butir | D35: 3000 | E35: 2200 | F35: 2000 | G35: 2200 | H35: 2000 | I35: 2500 | J35: 3000 | K35: =AVERAGE(D35:J35) -> 2414.2857
A36: 8 | B36: TAHU
B37: - Tahu biasa | C37: Kg | D37: 10000 | E37: 10000 | F37: 9000 | G37: 9000 | H37: 16000 | I37: 12000 | J37: 9000 | K37: =AVERAGE(D37:J37) -> 10714.286
B38: - Tahu susu | C38: Kg | D38: - | E38: 7000 | F38: 12000 | G38: 17000 | H38: - | I38: 15000 | J38: 12000 | K38: =AVERAGE(D38:J38) -> 12600
A39: 9 | B39: TEMPE
B40: - Tempe Kw I (campuran kedelai) | C40: Kg | D40: - | E40: 18000 | F40: - | G40: 16000 | H40: 14000 | I40: 15000 | J40: 15000 | K40: =AVERAGE(D40:J40) -> 15600
B41: - Tempe Kw II (campuran jagung) | C41: Kg | D41: 2500 | E41: 12000 | F41: 6000 | G41: - | H41: - | I41: - | J41: - | K41: =AVERAGE(D41:J41) -> 6833.3333
B42: - Tempe Kw III (campuran kulit) | C42: Kg | D42: - | E42: 2000 | F42: - | G42: - | H42: - | I42: - | J42: - | K42: =AVERAGE(D42:J42) -> 2000
...

Sheet 5
A1: HARGA BAHAN-BAHAN POKOK
A2: DI PASAR TRADISIONAL KOTA SURABAYA
A3: HARI / TANGGAL : Senin / 05 Juni 2023
B4: NAMA BAHAN POKOK DAN PENTING LAINNYA | C4: SATUAN | D4: Pasar Tambahrejo | E4: Pasar Pucang Anom | F4: Pasar Wonokromo | G4: Pasar Genteng Baru | H4: Pasar Pabean | I4: Pasar Kembang | J4: Pasar Balongsari | K4: Rata-Rata
A7: 1 | B7: BERAS
B8: - Beras Premium | C8: Kg | D8: 13000 | E8: 13500 | F8: 14000 | G8: 13500 | H8: 12000 | I8: 14000 | J8: 13500 | K8: =AVERAGE(D8:J8) -> 13357.143
B9: - Beras Medium Bulog | C9: Kg | D9: 9000 | E9: 9000 | F9: 9000 | G9: 9000 | H9: - | I9: - | J9: - | K9: =AVERAGE(D9:J9) -> 9000
B10: - Beras Medium | C10: Kg | D10: 11000 | E10: 11500 | F10: 13000 | G10: 11500 | H10: - | I10: 12500 | J10: 12500 | K10: =AVERAGE(D10:J10) -> 12000
B11: - Beras Jagung | C11: Kg | D11: - | E11: 10000 | F11: 12000 | G11: 12000 | H11: - | I11: 11000 | J11: 8000 | K11: =AVERAGE(D11:J11) -> 10600
B12: - Beras Ketan (Jenis Siyem) | C12: Kg | D12: - | E12: 22000 | F12: 24000 | G12: 20000 | H12: - | I12: 18000 | J12: 17000 | K12: =AVERAGE(D12:J12) -> 20200
A13: 2 | B13: GULA
B14: - Gula pasir lokal curah | C14: Kg | D14: 13000 | E14: 13500 | F14: 14000 | G14: 13500 | H14: 13500 | I14: 13500 | J14: 13500 | K14: =AVERAGE(D14:J14) -> 13500
B15: - Gula Jawa/Merah (Bahan Kelapa) | C15: Kg | D15: 15000 | E15: 16000 | F15: 15000 | G15: 16000 | H15: 15000 | I15: 18000 | J15: 16000 | K15: =AVERAGE(D15:J15) -> 15857.143
A16: 3 | B16: MINYAK GORENG
B17: - Minyak Goreng Curah (Bening) | C17: Kg | D17: 14500 | E17: 16000 | F17: 17000 | G17: 16000 | H17: 14000 | I17: 16000 | J17: 15500 | K17: =AVERAGE(D17:J17) -> 15571.429
B18: - Minyak Kita | C18: Liter | D18: 14000 | E18: 14000 | F18: 14000 | G18: 14000 | H18: - | I18: 14000 | J18: 14000 | K18: =AVERAGE(D18:J18) -> 14000
A19: 4 | B19: MENTEGA
B20: - Mentega Curah (Amanda) | C20: Kg | D20: 20000 | E20: - | F20: 19000 | G20: 22000 | H20: - | I20: 24000 | J20: - | K20: =AVERAGE(D20:J20) -> 21250
A21: 5 | B21: DAGING
B22: - Daging Sapi Grade Atas | C22: Kg | D22: 120000 | E22: 120000 | F22: 120000 | G22: 120000 | H22: 120000 | I22: 120000 | J22: - | K22: =AVERAGE(D22:J22) -> 120000
B23: - Daging Sapi Grade Sedang | C23: Kg | D23: 110000 | E23: 110000 | F23: 110000 | G23: 110000 | H23: 114000 | I23: 115000 | J23: 115000 | K23: =AVERAGE(D23:J23) -> 112000
B24: - Daging Sapi Grade Bawah | C24: Kg | D24: 100000 | E24: 95000 | F24: 105000 | G24: 105000 | H24: 100000 | I24: 110000 | J24: 105000 | K24: =AVERAGE(D24:J24) -> 102857.14
B25: - Daging Ayam Broiler | C25: Kg | D25: 36000 | E25: 36000 | F25: 36000 | G25: 36000 | H25: 40000 | I25: 35000 | J25: 40000 | K25: =AVERAGE(D25:J25) -> 37000
A26: 6 | B26: I K A N
B27: - Ikan Tongkol Segar (Uk. Sedang) | C27: Kg | D27: 35000 | E27: 40000 | F27: - | G27: 45000 | H27: 30000 | I27: 40000 | J27: 35000 | K27: =AVERAGE(D27:J27) -> 37500
B28: - Ikan Mujair Segar (Uk. Sedang) | C28: Kg | D28: 25000 | E28: 28000 | F28: 28000 | G28: 35000 | H28: 23000 | I28: 29000 | J28: 24000 | K28: =AVERAGE(D28:J28) -> 27428.571
B29: - Udang Segar (Uk. Sedang) | C29: Kg | D29: 80000 | E29: 60000 | F29: 60000 | G29: 75000 | H29: 58000 | I29: 60000 | J29: 55000 | K29: =AVERAGE(D29:J29) -> 64000
B30: - Ikan Lele Segar (Ukuran Sedang) | C30: Kg | D30: 25000 | E30: - | F30: - | G30: 25000 | H30: 23000 | I30: 24000 | J30: 26000 | K30: =AVERAGE(D30:J30) -> 24600
B31: - Ikan Bandeng Segar (Uk. Sedang) | C31: Kg | D31: 35000 | E31: 35000 | F31: 36000 | G31: 45000 | H31: 28000 | I31: 40000 | J31: 38000 | K31: =AVERAGE(D31:J31) -> 36714.286
B32: - Ikan Teri Asin (Bukan Teri Medan) | C32: Kg | D32: - | E32: 100000 | F32: 110000 | G32: - | H32: 80000 | I32: - | J32: - | K32: =AVERAGE(D32:J32) -> 96666.667
A33: 7 | B33: TELUR
B34: - Telur Ayam Broiler | C34: Kg | D34: 29000 | E34: 30000 | F34: 30000 | G34: 30000 | H34: 28000 | I34: 27000 | J34: 28500 | K34: =AVERAGE(D34:J34) -> 28928.571
B35: - Telur Ayam Kampung | C35: Butir | D35: 3000 | E35: 2200 | F35: 2000 | G35: 2200 | H35: 2000 | I35: 2500 | J35: 3000 | K35: =AVERAGE(D35:J35) -> 2414.2857
A36: 8 | B36: TAHU
B37: - Tahu biasa | C37: Kg | D37: 10000 | E37: 10000 | F37: 9000 | G37: 9000 | H37: 16000 | I37: 12000 | J37: 9000 | K37: =AVERAGE(D37:J37) -> 10714.286
B38: - Tahu susu | C38: Kg | D38: - | E38: 7000 | F38: 12000 | G38: 17000 | H38: - | I38: 15000 | J38: 12000 | K38: =AVERAGE(D38:J38) -> 12600
A39: 9 | B39: TEMPE
B40: - Tempe Kw I (campuran kedelai) | C40: Kg | D40: - | E40: 18000 | F40: - | G40: 16000 | H40: 14000 | I40: 15000 | J40: 15000 | K40: =AVERAGE(D40:J40) -> 15600
B41: - Tempe Kw II (campuran jagung) | C41: Kg | D41: 2500 | E41: 12000 | F41: 6000 | G41: - | H41: - | I41: - | J41: - | K41: =AVERAGE(D41:J41) -> 6833.3333
B42: - Tempe Kw III (campuran kulit) | C42: Kg | D42: - | E42: 2000 | F42: - | G42: - | H42: - | I42: - | J42: - | K42: =AVERAGE(D42:J42) -> 2000
...

Sheet 6
A1: HARGA BAHAN-BAHAN POKOK
A2: DI PASAR TRADISIONAL KOTA SURABAYA
A3: HARI / TANGGAL : Selasa / 06 Juni 2023
B4: NAMA BAHAN POKOK DAN PENTING LAINNYA | C4: SATUAN | D4: Pasar Tambahrejo | E4: Pasar Pucang Anom | F4: Pasar Wonokromo | G4: Pasar Genteng Baru | H4: Pasar Pabean | I4: Pasar Kembang | J4: Pasar Balongsari | K4: Rata-Rata
A7: 1 | B7: BERAS
B8: - Beras Premium | C8: Kg | D8: 13000 | E8: 13500 | F8: 14000 | G8: 13500 | H8: 12000 | I8: 14000 | J8: 13500 | K8: =AVERAGE(D8:J8) -> 13357.143
B9: - Beras Medium Bulog | C9: Kg | D9: 9000 | E9: 9000 | F9: 9000 | G9: 9000 | H9: - | I9: - | J9: - | K9: =AVERAGE(D9:J9) -> 9000
B10: - Beras Medium | C10: Kg | D10: 11000 | E10: 11500 | F10: 13000 | G10: 11500 | H10: - | I10: 12500 | J10: 12500 | K10: =AVERAGE(D10:J10) -> 12000
B11: - Beras Jagung | C11: Kg | D11: - | E11: 10000 | F11: 12000 | G11: 12000 | H11: - | I11: 11000 | J11: 8000 | K11: =AVERAGE(D11:J11) -> 10600
B12: - Beras Ketan (Jenis Siyem) | C12: Kg | D12: - | E12: 22000 | F12: 24000 | G12: 20000 | H12: - | I12: 18000 | J12: 17000 | K12: =AVERAGE(D12:J12) -> 20200
A13: 2 | B13: GULA
B14: - Gula pasir lokal curah | C14: Kg | D14: 13000 | E14: 13500 | F14: 14000 | G14: 13500 | H14: 13500 | I14: 13500 | J14: 13500 | K14: =AVERAGE(D14:J14) -> 13500
B15: - Gula Jawa/Merah (Bahan Kelapa) | C15: Kg | D15: 15000 | E15: 16000 | F15: 15000 | G15: 16000 | H15: 15000 | I15: 18000 | J15: 16000 | K15: =AVERAGE(D15:J15) -> 15857.143
A16: 3 | B16: MINYAK GORENG
B17: - Minyak Goreng Curah (Bening) | C17: Kg | D17: 14500 | E17: 16000 | F17: 17000 | G17: 16000 | H17: 14000 | I17: 16000 | J17: 15500 | K17: =AVERAGE(D17:J17) -> 15571.429
B18: - Minyak Kita | C18: Liter | D18: 14000 | E18: 14000 | F18: 14000 | G18: 14000 | H18: - | I18: 14000 | J18: 14000 | K18: =AVERAGE(D18:J18) -> 14000
A19: 4 | B19: MENTEGA
B20: - Mentega Curah (Amanda) | C20: Kg | D20: 20000 | E20: - | F20: 19000 | G20: 22000 | H20: - | I20: 24000 | J20: - | K20: =AVERAGE(D20:J20) -> 21250
A21: 5 | B21: DAGING
B22: - Daging Sapi Grade Atas | C22: Kg | D22: 120000 | E22: 120000 | F22: 120000 | G22: 120000 | H22: 120000 | I22: 120000 | J22: - | K22: =AVERAGE(D22:J22) -> 120000
B23: - Daging Sapi Grade Sedang | C23: Kg | D23: 110000 | E23: 110000 | F23: 110000 | G23: 110000 | H23: 114000 | I23: 115000 | J23: 115000 | K23: =AVERAGE(D23:J23) -> 112000
B24: - Daging Sapi Grade Bawah | C24: Kg | D24: 100000 | E24: 95000 | F24: 105000 | G24: 105000 | H24: 100000 | I24: 110000 | J24: 105000 | K24: =AVERAGE(D24:J24) -> 102857.14
B25: - Daging Ayam Broiler | C25: Kg | D25: 36000 | E25: 36000 | F25: 37000 | G25: 37000 | H25: 40000 | I25: 38000 | J25: 40000 | K25: =AVERAGE(D25:J25) -> 37714.286
A26: 6 | B26: I K A N
B27: - Ikan Tongkol Segar (Uk. Sedang) | C27: Kg | D27: 35000 | E27: 40000 | F27: - | G27: 45000 | H27: 30000 | I27: 40000 | J27: 35000 | K27: =AVERAGE(D27:J27) -> 37500
B28: - Ikan Mujair Segar (Uk. Sedang) | C28: Kg | D28: 25000 | E28: 28000 | F28: 28000 | G28: 35000 | H28: 23000 | I28: 29000 | J28: 24000 | K28: =AVERAGE(D28:J28) -> 27428.571
B29: - Udang Segar (Uk. Sedang) | C29: Kg | D29: 80000 | E29: 60000 | F29: 60000 | G29: 75000 | H29: 58000 | I29: 60000 | J29: 55000 | K29: =AVERAGE(D29:J29) -> 64000
B30: - Ikan Lele Segar (Ukuran Sedang) | C30: Kg | D30: 25000 | E30: - | F30: - | G30: 25000 | H30: 23000 | I30: 24000 | J30: 26000 | K30: =AVERAGE(D30:J30) -> 24600
B31: - Ikan Bandeng Segar (Uk. Sedang) | C31: Kg | D31: 35000 | E31: 35000 | F31: 36000 | G31: 45000 | H31: 28000 | I31: 40000 | J31: 38000 | K31: =AVERAGE(D31:J31) -> 36714.286
B32: - Ikan Teri Asin (Bukan Teri Medan) | C32: Kg | D32: - | E32: 100000 | F32: 110000 | G32: - | H32: 80000 | I32: - | J32: - | K32: =AVERAGE(D32:J32) -> 96666.667
A33: 7 | B33: TELUR
B34: - Telur Ayam Broiler | C34: Kg | D34: 29000 | E34: 30000 | F34: 29000 | G34: 30000 | H34: 28000 | I34: 27000 | J34: 28500 | K34: =AVERAGE(D34:J34) -> 28785.714
B35: - Telur Ayam Kampung | C35: Butir | D35: 3000 | E35: 2200 | F35: 2000 | G35: 2200 | H35: 2000 | I35: 2500 | J35: 3000 | K35: =AVERAGE(D35:J35) -> 2414.2857
A36: 8 | B36: TAHU
B37: - Tahu biasa | C37: Kg | D37: 10000 | E37: 10000 | F37: 9000 | G37: 9000 | H37: 16000 | I37: 12000 | J37: 9000 | K37: =AVERAGE(D37:J37) -> 10714.286
B38: - Tahu susu | C38: Kg | D38: - | E38: 7000 | F38: 12000 | G38: 17000 | H38: - | I38: 15000 | J38: 12000 | K38: =AVERAGE(D38:J38) -> 12600
A39: 9 | B39: TEMPE
B40: - Tempe Kw I (campuran kedelai) | C40: Kg | D40: - | E40: 18000 | F40: - | G40: 16000 | H40: 14000 | I40: 15000 | J40: 15000 | K40: =AVERAGE(D40:J40) -> 15600
B41: - Tempe Kw II (campuran jagung) | C41: Kg | D41: 2500 | E41: 12000 | F41: 6000 | G41: - | H41: - | I41: - | J41: - | K41: =AVERAGE(D41:J41) -> 6833.3333
B42: - Tempe Kw III (campuran kulit) | C42: Kg | D42: - | E42: 2000 | F42: - | G42: - | H42: - | I42: - | J42: - | K42: =AVERAGE(D42:J42) -> 2000
...

Sheet 7
A1: HARGA BAHAN-BAHAN POKOK
A2: DI PASAR TRADISIONAL KOTA SURABAYA
A3: HARI / TANGGAL : Rabu / 07 Juni 2023
B4: NAMA BAHAN POKOK DAN PENTING LAINNYA | C4: SATUAN | D4: Pasar Tambahrejo | E4: Pasar Pucang Anom | F4: Pasar Wonokromo | G4: Pasar Genteng Baru | H4: Pasar Pabean | I4: Pasar Kembang | J4: Pasar Balongsari | K4: Rata-Rata
A7: 1 | B7: BERAS
B8: - Beras Premium | C8: Kg | D8: 13000 | E8: 13500 | F8: 14000 | G8: 13500 | H8: 12000 | I8: 14000 | J8: 13500 | K8: =AVERAGE(D8:J8) -> 13357.143
B9: - Beras Medium Bulog | C9: Kg | D9: 9000 | E9: 9000 | F9: - | G9: 9000 | H9: - | I9: - | J9: - | K9: =AVERAGE(D9:J9) -> 9000
B10: - Beras Medium | C10: Kg | D10: 11000 | E10: 11500 | F10: 13000 | G10: 11500 | H10: - | I10: 12500 | J10: 12500 | K10: =AVERAGE(D10:J10) -> 12000
B11: - Beras Jagung | C11: Kg | D11: - | E11: 10000 | F11: 12000 | G11: 12000 | H11: - | I11: 11000 | J11: 8000 | K11: =AVERAGE(D11:J11) -> 10600
B12: - Beras Ketan (Jenis Siyem) | C12: Kg | D12: - | E12: 22000 | F12: 24000 | G12: 20000 | H12: - | I12: 18000 | J12: 17000 | K12: =AVERAGE(D12:J12) -> 20200
A13: 2 | B13: GULA
B14: - Gula pasir lokal curah | C14: Kg | D14: 13000 | E14: 13500 | F14: 14000 | G14: 13500 | H14: 13500 | I14: 13500 | J14: 13500 | K14: =AVERAGE(D14:J14) -> 13500
B15: - Gula Jawa/Merah (Bahan Kelapa) | C15: Kg | D15: 15000 | E15: 16000 | F15: 15000 | G15: 16000 | H15: 15000 | I15: 18000 | J15: 16000 | K15: =AVERAGE(D15:J15) -> 15857.143
A16: 3 | B16: MINYAK GORENG
