Workbook

Sheet REKAPITULASI
A1: BAGIAN PEREKONOMIAN DAN SUMBER DAYA ALAM
A2: LAPORAN HARGA BAHAN POKOK DI KOTA SURABAYA
A3: PERIODE 25 JULI 2023 - 31 JULI 2023
B4: NAMA BAHAN POKOK DAN PENTING LAINNYA | AH4: HET/HAPK (Harga Eceran Tertinggi) | AI4: FLUKTUASI
C5: 1 | D5: 2 | E5: 3 | F5: 4 | G5: 5 | H5: 6 | I5: 7 | J5: 8 | K5: 9 | L5: 10 | M5: 11 | N5: 12 | O5: 13 | P5: 14 | Q5: 15 | R5: 16 | S5: 17 | T5: 18 | U5: 19 | V5: 20 | W5: 21 | X5: 22 | Y5: 23 | Z5: 24 | AA5: 25 | AB5: 26 | AC5: 27 | AD5: 28 | AE5: 29 | AF5: 30 | AG5: 31
A7: 1 | B7: BERAS
B8: - Beras Premium | C8: ='01'!K8 -> 13214.286 | D8: ='02'!K8 -> 13214.286 | E8: ='03'!K8 -> 13214.286 | F8: ='04'!K8 -> 13214.286 | G8: ='05'!K8 -> 13214.286 | H8: ='06'!K8 -> 13142.857 | I8: ='07'!K8 -> 13142.857 | J8: ='08'!K8 -> 13142.857 | K8: ='09'!K8 -> 13142.857 | L8: ='10'!K8 -> 13142.857 | M8: ='11'!K8 -> 13142.857 | N8: ='12'!K8 -> 13071.429 | O8: ='13'!K8 -> 13071.429 | P8: ='14'!K8 -> 13071.429 | Q8: ='15'!K8 -> 13000 | R8: ='16'!K8 -> 13000 | S8: ='17'!K8 -> 13000 | T8: ='18'!K8 -> 13000 | U8: ='19'!K8 -> 13000 | V8: ='20'!K8 -> 13000 | W8: ='21'!K8 -> 13000 | X8: ='22'!K8 -> 13000 | Y8: ='23'!K8 -> 13071.429 | Z8: ='24'!K8 -> 13000 | AA8: ='25'!K8 -> 13000 | AB8: ='26'!K8 -> 13000 | AC8: ='27'!K8 -> 13000 | AD8: ='28'!K8 -> 13000 | AE8: ='29'!K8 -> 13000 | AF8: ='30'!K8 -> 13071.429 | AG8: ='31'!K8 -> 12714.286 | AH8: 12800 | AI8: =AG8-AA8 -> -285.71429
B9: - Beras IR.64 Medium Bulog | C9: ='01'!K9 -> 9000 | D9: ='02'!K9 -> 9000 | E9: ='03'!K9 -> 9000 | F9: ='04'!K9 -> 9000 | G9: ='05'!K9 -> 9000 | H9: ='06'!K9 -> 9000 | I9: ='07'!K9 -> 9000 | J9: ='08'!K9 -> 9000 | K9: ='09'!K9 -> 9000 | L9: ='10'!K9 -> 9000 | M9: ='11'!K9 -> 9000 | N9: ='12'!K9 -> 9250 | O9: ='13'!K9 -> 9250 | P9: ='14'!K9 -> 9250 | Q9: ='15'!K9 -> 9000 | R9: ='16'!K9 -> 9000 | S9: ='17'!K9 -> 9000 | T9: ='18'!K9 -> 9000 | U9: ='19'!K9 -> 9250 | V9: ='20'!K9 -> 9375 | W9: ='21'!K9 -> 9000 | X9: ='22'!K9 -> 9000 | Y9: ='23'!K9 -> 9000 | Z9: ='24'!K9 -> 9000 | AA9: ='25'!K9 -> 9000 | AB9: ='26'!K9 -> 9000 | AC9: ='27'!K9 -> 9000 | AD9: ='28'!K9 -> 9000 | AE9: ='29'!K9 -> 9000 | AF9: ='30'!K9 -> 9000 | AG9: ='31'!K9 -> 9000 | AI9: =AG9-AA9 -> 0
B10: - Beras IR.64 Medium | C10: ='01'!K10 -> 10660 | D10: ='02'!K10 -> 10325 | E10: ='03'!K10 -> 10940 | F10: ='04'!K10 -> 10940 | G10: ='05'!K10 -> 10940 | H10: ='06'!K10 -> 10940 | I10: ='07'!K10 -> 10940 | J10: ='08'!K10 -> 10940 | K10: ='09'!K10 -> 10940 | L10: ='10'!K10 -> 10940 | M10: ='11'!K10 -> 10940 | N10: ='12'!K10 -> 10940 | O10: ='13'!K10 -> 10940 | P10: ='14'!K10 -> 10940 | Q10: ='15'!K10 -> 10950 | R10: ='16'!K10 -> 10950 | S10: ='17'!K10 -> 10950 | T10: ='18'!K10 -> 10950 | U10: ='19'!K10 -> 10950 | V10: ='20'!K10 -> 10950 | W10: ='21'!K10 -> 10950 | X10: ='22'!K10 -> 10760 | Y10: ='23'!K10 -> 10760 | Z10: ='24'!K10 -> 10860 | AA10: ='25'!K10 -> 11300 | AB10: ='26'!K10 -> 11300 | AC10: ='27'!K10 -> 11380 | AD10: ='28'!K10 -> 11380 | AE10: ='29'!K10 -> 11380 | AF10: ='30'!K10 -> 10980 | AG10: ='31'!K10 -> 10640 | AH10: 9450 | AI10: =AG10-AA10 -> -660
B11: - Beras Jagung | C11: ='01'!K11 -> 10200 | D11: ='02'!K11 -> 10200 | E11: ='03'!K11 -> 10200 | F11: ='04'!K11 -> 10200 | G11: ='05'!K11 -> 10200 | H11: ='06'!K11 -> 10200 | I11: ='07'!K11 -> 10200 | J11: ='08'!K11 -> 10000 | K11: ='09'!K11 -> 10000 | L11: ='10'!K11 -> 10200 | M11: ='11'!K11 -> 10200 | N11: ='12'!K11 -> 10200 | O11: ='13'!K11 -> 10200 | P11: ='14'!K11 -> 10200 | Q11: ='15'!K11 -> 10200 | R11: ='16'!K11 -> 10200 | S11: ='17'!K11 -> 10200 | T11: ='18'!K11 -> 10200 | U11: ='19'!K11 -> 10200 | V11: ='20'!K11 -> 10200 | W11: ='21'!K11 -> 10200 | X11: ='22'!K11 -> 10200 | Y11: ='23'!K11 -> 10200 | Z11: ='24'!K11 -> 10200 | AA11: ='25'!K11 -> 10200 | AB11: ='26'!K11 -> 10200 | AC11: ='27'!K11 -> 10200 | AD11: ='28'!K11 -> 10200 | AE11: ='29'!K11 -> 10200 | AF11: ='30'!K11 -> 10200 | AG11: ='31'!K11 -> 10200 | AI11: =AG11-AA11 -> 0
B12: - Beras Ketan (Jenis Siyem) | C12: ='01'!K12 -> 19400 | D12: ='02'!K12 -> 19400 | E12: ='03'!K12 -> 18800 | F12: ='04'!K12 -> 18600 | G12: ='05'!K12 -> 18600 | H12: ='06'!K12 -> 18600 | I12: ='07'!K12 -> 18600 | J12: ='08'!K12 -> 18800 | K12: ='09'!K12 -> 18800 | L12: ='10'!K12 -> 18600 | M12: ='11'!K12 -> 18600 | N12: ='12'!K12 -> 18600 | O12: ='13'!K12 -> 18600 | P12: ='14'!K12 -> 18600 | Q12: ='15'!K12 -> 18600 | R12: ='16'!K12 -> 18600 | S12: ='17'!K12 -> 18600 | T12: ='18'!K12 -> 18600 | U12: ='19'!K12 -> 18600 | V12: ='20'!K12 -> 18600 | W12: ='21'!K12 -> 18600 | X12: ='22'!K12 -> 20000 | Y12: ='23'!K12 -> 20000 | Z12: ='24'!K12 -> 18600 | AA12: ='25'!K12 -> 18600 | AB12: ='26'!K12 -> 18600 | AC12: ='27'!K12 -> 18600 | AD12: ='28'!K12 -> 18600 | AE12: ='29'!K12 -> 18600 | AF12: ='30'!K12 -> 20000 | AG12: ='31'!K12 -> 18600 | AI12: =AG12-AA12 -> 0
A13: 2 | B13: GULA | C13: ='01'!K13 -> 0 | D13: ='02'!K13 -> 0 | E13: ='03'!K13 -> 0 | F13: ='04'!K13 -> 0 | G13: ='05'!K13 -> 0 | H13: ='06'!K13 -> 0 | I13: ='07'!K13 -> 0 | J13: ='08'!K13 -> 0 | K13: ='09'!K13 -> 0 | L13: ='10'!K13 -> 0 | M13: ='11'!K13 -> 0 | N13: ='12'!K13 -> 0 | O13: ='13'!K13 -> 0 | P13: ='14'!K13 -> 0 | Q13: ='15'!K13 -> 0 | R13: ='16'!K13 -> 0 | S13: ='17'!K13 -> 0 | T13: ='18'!K13 -> 0 | U13: ='19'!K13 -> 0 | V13: ='20'!K13 -> 0 | W13: ='21'!K13 -> 0 | X13: ='22'!K13 -> 0 | Y13: ='23'!K13 -> 0 | Z13: ='24'!K13 -> 0 | AA13: ='25'!K13 -> 0 | AB13: ='26'!K13 -> 0 | AC13: ='27'!K13 -> 0 | AD13: ='28'!K13 -> 0 | AE13: ='29'!K13 -> 0 | AF13: ='30'!K13 -> 0 | AG13: ='31'!K13 -> 0 | AI13: =AG13-AA13 -> 0
B14: Gula Pasir Lokal Curah | C14: ='01'!K14 -> 13285.714 | D14: ='02'!K14 -> 13285.714 | E14: ='03'!K14 -> 13285.714 | F14: ='04'!K14 -> 13285.714 | G14: ='05'!K14 -> 13285.714 | H14: ='06'!K14 -> 13285.714 | I14: ='07'!K14 -> 13285.714 | J14: ='08'!K14 -> 13285.714 | K14: ='09'!K14 -> 13285.714 | L14: ='10'!K14 -> 13285.714 | M14: ='11'!K14 -> 13285.714 | N14: ='12'!K14 -> 13285.714 | O14: ='13'!K14 -> 13285.714 | P14: ='14'!K14 -> 13285.714 | Q14: ='15'!K14 -> 13214.286 | R14: ='16'!K14 -> 13357.143 | S14: ='17'!K14 -> 13285.714 | T14: ='18'!K14 -> 13285.714 | U14: ='19'!K14 -> 13285.714 | V14: ='20'!K14 -> 13285.714 | W14: ='21'!K14 -> 13357.143 | X14: ='22'!K14 -> 13357.143 | Y14: ='23'!K14 -> 13357.143 | Z14: ='24'!K14 -> 13357.143 | AA14: ='25'!K14 -> 13357.143 | AB14: ='26'!K14 -> 13357.143 | AC14: ='27'!K14 -> 13357.143 | AD14: ='28'!K14 -> 13357.143 | AE14: ='29'!K14 -> 13357.143 | AF14: ='30'!K14 -> 13357.143 | AG14: ='31'!K14 -> 13357.143 | AH14: 13500 | AI14: =AG14-AA14 -> 0
B15: - Gula Jawa/Merah (Bahan Kelapa) | C15: ='01'!K15 -> 15714.286 | D15: ='02'!K15 -> 15571.429 | E15: ='03'!K15 -> 15428.571 | F15: ='04'!K15 -> 15428.571 | G15: ='05'!K15 -> 15428.571 | H15: ='06'!K15 -> 15428.571 | I15: ='07'!K15 -> 15428.571 | J15: ='08'!K15 -> 15428.571 | K15: ='09'!K15 -> 15714.286 | L15: ='10'!K15 -> 15428.571 | M15: ='11'!K15 -> 15428.571 | N15: ='12'!K15 -> 15285.714 | O15: ='13'!K15 -> 15285.714 | P15: ='14'!K15 -> 15285.714 | Q15: ='15'!K15 -> 15285.714 | R15: ='16'!K15 -> 15285.714 | S15: ='17'!K15 -> 15285.714 | T15: ='18'!K15 -> 15285.714 | U15: ='19'!K15 -> 15285.714 | V15: ='20'!K15 -> 15285.714 | W15: ='21'!K15 -> 15285.714 | X15: ='22'!K15 -> 15571.429 | Y15: ='23'!K15 -> 15571.429 | Z15: ='24'!K15 -> 15285.714 | AA15: ='25'!K15 -> 15285.714 | AB15: ='26'!K15 -> 15285.714 | AC15: ='27'!K15 -> 15285.714 | AD15: ='28'!K15 -> 15285.714 | AE15: ='29'!K15 -> 15285.714 | AF15: ='30'!K15 -> 15571.429 | AG15: ='31'!K15 -> 15285.714 | AI15: =AG15-AA15 -> 0
B16: MINYAK GORENG | C16: ='01'!K16 -> 0 | D16: ='02'!K16 -> 0 | E16: ='03'!K16 -> 0 | F16: ='04'!K16 -> 0 | G16: ='05'!K16 -> 0 | H16: ='06'!K16 -> 0 | I16: ='07'!K16 -> 0 | J16: ='08'!K16 -> 0 | K16: ='09'!K16 -> 0 | L16: ='10'!K16 -> 0 | M16: ='11'!K16 -> 0 | N16: ='12'!K16 -> 0 | O16: ='13'!K16 -> 0 | P16: ='14'!K16 -> 0 | Q16: ='15'!K16 -> 0 | R16: ='16'!K16 -> 0 | S16: ='17'!K16 -> 0 | T16: ='18'!K16 -> 0 | U16: ='19'!K16 -> 0 | V16: ='20'!K16 -> 0 | W16: ='21'!K16 -> 0 | X16: ='22'!K16 -> 0 | Y16: ='23'!K16 -> 0 | Z16: ='24'!K16 -> 0 | AA16: ='25'!K16 -> 0 | AB16: ='26'!K16 -> 0 | AC16: ='27'!K16 -> 0 | AD16: ='28'!K16 -> 0 | AE16: ='29'!K16 -> 0 | AF16: ='30'!K16 -> 0 | AG16: ='31'!K16 -> 0 | AI16: =AG16-AA16 -> 0
B17: - Minyak Goreng Curah (Bening) | C17: ='01'!K17 -> 15142.857 | D17: ='02'!K17 -> 15142.857 | E17: ='03'!K17 -> 15142.857 | F17: ='04'!K17 -> 15142.857 | G17: ='05'!K17 -> 15142.857 | H17: ='06'!K17 -> 15142.857 | I17: ='07'!K17 -> 15142.857 | J17: ='08'!K17 -> 15285.714 | K17: ='09'!K17 -> 15142.857 | L17: ='10'!K17 -> 15214.286 | M17: ='11'!K17 -> 15357.143 | N17: ='12'!K17 -> 15000 | O17: ='13'!K17 -> 15000 | P17: ='14'!K17 -> 15000 | Q17: ='15'!K17 -> 14928.571 | R17: ='16'!K17 -> 14928.571 | S17: ='17'!K17 -> 14928.571 | T17: ='18'!K17 -> 14928.571 | U17: ='19'!K17 -> 14928.571 | V17: ='20'!K17 -> 14928.571 | W17: ='21'!K17 -> 15000 | X17: ='22'!K17 -> 13000 | Y17: ='23'!K17 -> 15142.857 | Z17: ='24'!K17 -> 15000 | AA17: ='25'!K17 -> 15000 | AB17: ='26'!K17 -> 15000 | AC17: ='27'!K17 -> 15000 | AD17: ='28'!K17 -> 15000 | AE17: ='29'!K17 -> 15000 | AF17: ='30'!K17 -> 15142.857 | AG17: ='31'!K17 -> 15000 | AH17: 15500 | AI17: =AG17-AA17 -> 0
B18: - Minyak KITA | C18: ='01'!K18 -> 14000 | D18: ='02'!K18 -> 14000 | E18: ='03'!K18 -> 14000 | F18: ='04'!K18 -> 14000 | G18: ='05'!K18 -> 14000 | H18: ='06'!K18 -> 14000 | I18: ='07'!K18 -> 14000 | J18: ='08'!K18 -> 14000 | K18: ='09'!K18 -> 14000 | L18: ='10'!K18 -> 14000 | M18: ='11'!K18 -> 14000 | N18: ='12'!K18 -> 14000 | O18: ='13'!K18 -> 14000 | P18: ='14'!K18 -> 14000 | Q18: ='15'!K18 -> 14000 | R18: ='16'!K18 -> 14000 | S18: ='17'!K18 -> 14000 | T18: ='18'!K18 -> 14000 | U18: ='19'!K18 -> 14000 | V18: ='20'!K18 -> 14000 | W18: ='21'!K18 -> 14000 | X18: ='22'!K18 -> 14000 | Y18: ='23'!K18 -> 14000 | Z18: ='24'!K18 -> 14000 | AA18: ='25'!K18 -> 14000 | AB18: ='26'!K18 -> 14000 | AC18: ='27'!K18 -> 14000 | AD18: ='28'!K18 -> 14000 | AE18: ='29'!K18 -> 14000 | AF18: ='30'!K18 -> 14000 | AG18: ='31'!K18 -> 14000 | AH18: 14000 | AI18: =AG18-AA18 -> 0
A19: 4 | B19: MENTEGA | C19: ='01'!K19 -> 0 | D19: ='02'!K19 -> 0 | E19: ='03'!K19 -> 0 | F19: ='04'!K19 -> 0 | G19: ='05'!K19 -> 0 | H19: ='06'!K19 -> 0 | I19: ='07'!K19 -> 0 | J19: ='08'!K19 -> 0 | K19: ='09'!K19 -> 0 | L19: ='10'!K19 -> 0 | M19: ='11'!K19 -> 0 | N19: ='12'!K19 -> 0 | O19: ='13'!K19 -> 0 | P19: ='14'!K19 -> 0 | Q19: ='15'!K19 -> 0 | R19: ='16'!K19 -> 0 | S19: ='17'!K19 -> 0 | T19: ='18'!K19 -> 0 | U19: ='19'!K19 -> 0 | V19: ='20'!K19 -> 0 | W19: ='21'!K19 -> 0 | X19: ='22'!K19 -> 0 | Y19: ='23'!K19 -> 0 | Z19: ='24'!K19 -> 0 | AA19: ='25'!K19 -> 0 | AB19: ='26'!K19 -> 0 | AC19: ='27'!K19 -> 0 | AD19: ='28'!K19 -> 0 | AE19: ='29'!K19 -> 0 | AF19: ='30'!K19 -> 0 | AG19: ='31'!K19 -> 0 | AI19: =AG19-AA19 -> 0
B20: - Mentega Curah (Amanda) | C20: ='01'!K20 -> 21500 | D20: ='02'!K20 -> 21500 | E20: ='03'!K20 -> 21500 | F20: ='04'!K20 -> 21500 | G20: ='05'!K20 -> 21500 | H20: ='06'!K20 -> 21500 | I20: ='07'!K20 -> 21500 | J20: ='08'!K20 -> 21250 | K20: ='09'!K20 -> 21250 | L20: ='10'!K20 -> 21500 | M20: ='11'!K20 -> 21500 | N20: ='12'!K20 -> 21500 | O20: ='13'!K20 -> 21500 | P20: ='14'!K20 -> 21500 | Q20: ='15'!K20 -> 21500 | R20: ='16'!K20 -> 21250 | S20: ='17'!K20 -> 21500 | T20: ='18'!K20 -> 21500 | U20: ='19'!K20 -> 21500 | V20: ='20'!K20 -> 21500 | W20: ='21'!K20 -> 21500 | X20: ='22'!K20 -> 21500 | Y20: ='23'!K20 -> 21500 | Z20: ='24'!K20 -> 21500 | AA20: ='25'!K20 -> 21500 | AB20: ='26'!K20 -> 21500 | AC20: ='27'!K20 -> 21500 | AD20: ='28'!K20 -> 21500 | AE20: ='29'!K20 -> 21500 | AF20: ='30'!K20 -> 21500 | AG20: ='31'!K20 -> 21500 | AI20: =AG20-AA20 -> 0
A21: 5 | B21: DAGING | C21: ='01'!K21 -> 0 | D21: ='02'!K21 -> 0 | E21: ='03'!K21 -> 0 | F21: ='04'!K21 -> 0 | G21: ='05'!K21 -> 0 | H21: ='06'!K21 -> 0 | I21: ='07'!K21 -> 0 | J21: ='08'!K21 -> 0 | K21: ='09'!K21 -> 0 | L21: ='10'!K21 -> 0 | M21: ='11'!K21 -> 0 | N21: ='12'!K21 -> 0 | O21: ='13'!K21 -> 0 | P21: ='14'!K21 -> 0 | Q21: ='15'!K21 -> 0 | R21: ='16'!K21 -> 0 | S21: ='17'!K21 -> 0 | T21: ='18'!K21 -> 0 | U21: ='19'!K21 -> 0 | V21: ='20'!K21 -> 0 | W21: ='21'!K21 -> 0 | X21: ='22'!K21 -> 0 | Y21: ='23'!K21 -> 0 | Z21: ='24'!K21 -> 0 | AA21: ='25'!K21 -> 0 | AB21: ='26'!K21 -> 0 | AC21: ='27'!K21 -> 0 | AD21: ='28'!K21 -> 0 | AE21: ='29'!K21 -> 0 | AF21: ='30'!K21 -> 0 | AG21: ='31'!K21 -> 0 | AI21: =AG21-AA21 -> 0
B22: - Daging Sapi Grade Atas | C22: ='01'!K22 -> 120000 | D22: ='02'!K22 -> 120000 | E22: ='03'!K22 -> 120000 | F22: ='04'!K22 -> 120000 | G22: ='05'!K22 -> 120000 | H22: ='06'!K22 -> 120000 | I22: ='07'!K22 -> 120000 | J22: ='08'!K22 -> 120000 | K22: ='09'!K22 -> 120000 | L22: ='10'!K22 -> 120000 | M22: ='11'!K22 -> 120000 | N22: ='12'!K22 -> 120000 | O22: ='13'!K22 -> 120000 | P22: ='14'!K22 -> 120000 | Q22: ='15'!K22 -> 120000 | R22: ='16'!K22 -> 119166.67 | S22: ='17'!K22 -> 120000 | T22: ='18'!K22 -> 120000 | U22: ='19'!K22 -> 120000 | V22: ='20'!K22 -> 120000 | W22: ='21'!K22 -> 120000 | X22: ='22'!K22 -> 120000 | Y22: ='23'!K22 -> 120000 | Z22: ='24'!K22 -> 120000 | AA22: ='25'!K22 -> 120000 | AB22: ='26'!K22 -> 120000 | AC22: ='27'!K22 -> 120000 | AD22: ='28'!K22 -> 120000 | AE22: ='29'!K22 -> 120000 | AF22: ='30'!K22 -> 120000 | AG22: ='31'!K22 -> 120000 | AH22: 105000 | AI22: =AG22-AA22 -> 0
B23: - Daging Sapi Grade Sedang | C23: ='01'!K23 -> 111428.57 | D23: ='02'!K23 -> 111428.57 | E23: ='03'!K23 -> 111428.57 | F23: ='04'!K23 -> 111428.57 | G23: ='05'!K23 -> 111428.57 | H23: ='06'!K23 -> 111428.57 | I23: ='07'!K23 -> 111428.57 | J23: ='08'!K23 -> 111428.57 | K23: ='09'!K23 -> 111428.57 | L23: ='10'!K23 -> 111428.57 | M23: ='11'!K23 -> 111428.57 | N23: ='12'!K23 -> 111428.57 | O23: ='13'!K23 -> 111428.57 | P23: ='14'!K23 -> 111428.57 | Q23: ='15'!K23 -> 111428.57 | R23: ='16'!K23 -> 110714.29 | S23: ='17'!K23 -> 111428.57 | T23: ='18'!K23 -> 111428.57 | U23: ='19'!K23 -> 111428.57 | V23: ='20'!K23 -> 111428.57 | W23: ='21'!K23 -> 111428.57 | X23: ='22'!K23 -> 111428.57 | Y23: ='23'!K23 -> 111428.57 | Z23: ='24'!K23 -> 111428.57 | AA23: ='25'!K23 -> 111428.57 | AB23: ='26'!K23 -> 111428.57 | AC23: ='27'!K23 -> 111428.57 | AD23: ='28'!K23 -> 111428.57 | AE23: ='29'!K23 -> 111428.57 | AF23: ='30'!K23 -> 111428.57 | AG23: ='31'!K23 -> 111428.57 | AH23: 80000 | AI23: =AG23-AA23 -> 0
B24: - Daging Sapi Grade Bawah | C24: ='01'!K24 -> 102857.14 | D24: ='02'!K24 -> 102857.14 | E24: ='03'!K24 -> 102857.14 | F24: ='04'!K24 -> 102857.14 | G24: ='05'!K24 -> 102857.14 | H24: ='06'!K24 -> 102857.14 | I24: ='07'!K24 -> 102857.14 | J24: ='08'!K24 -> 102857.14 | K24: ='09'!K24 -> 102857.14 | L24: ='10'!K24 -> 102857.14 | M24: ='11'!K24 -> 102857.14 | N24: ='12'!K24 -> 102857.14 | O24: ='13'!K24 -> 102857.14 | P24: ='14'!K24 -> 102857.14 | Q24: ='15'!K24 -> 102857.14 | R24: ='16'!K24 -> 101428.57 | S24: ='17'!K24 -> 101428.57 | T24: ='18'!K24 -> 101428.57 | U24: ='19'!K24 -> 101428.57 | V24: ='20'!K24 -> 101428.57 | W24: ='21'!K24 -> 101428.57 | X24: ='22'!K24 -> 101428.57 | Y24: ='23'!K24 -> 101428.57 | Z24: ='24'!K24 -> 101428.57 | AA24: ='25'!K24 -> 101428.57 | AB24: ='26'!K24 -> 101428.57 | AC24: ='27'!K24 -> 101428.57 | AD24: ='28'!K24 -> 101428.57 | AE24: ='29'!K24 -> 101428.57 | AF24: ='30'!K24 -> 101428.57 | AG24: ='31'!K24 -> 101428.57 | AH24: 80000 | AI24: =AG24-AA24 -> 0
B25: - Daging Ayam Broiler | C25: ='01'!K25 -> 39285.714 | D25: ='02'!K25 -> 39285.714 | E25: ='03'!K25 -> 38857.143 | F25: ='04'!K25 -> 38714.286 | G25: ='05'!K25 -> 38714.286 | H25: ='06'!K25 -> 38428.571 | I25: ='07'!K25 -> 38428.571 | J25: ='08'!K25 -> 38571.429 | K25: ='09'!K25 -> 38428.571 | L25: ='10'!K25 -> 38000 | M25: ='11'!K25 -> 38285.714 | N25: ='12'!K25 -> 37571.429 | O25: ='13'!K25 -> 38000 | P25: ='14'!K25 -> 37857.143 | Q25: ='15'!K25 -> 37857.143 | R25: ='16'!K25 -> 38285.714 | S25: ='17'!K25 -> 38000 | T25: ='18'!K25 -> 37714.286 | U25: ='19'!K25 -> 37857.143 | V25: ='20'!K25 -> 37857.143 | W25: ='21'!K25 -> 37857.143 | X25: ='22'!K25 -> 37428.571 | Y25: ='23'!K25 -> 37285.714 | Z25: ='24'!K25 -> 36571.429 | AA25: ='25'!K25 -> 36428.571 | AB25: ='26'!K25 -> 36142.857 | AC25: ='27'!K25 -> 36142.857 | AD25: ='28'!K25 -> 35428.571 | AE25: ='29'!K25 -> 35571.429 | AF25: ='30'!K25 -> 35285.714 | AG25: ='31'!K25 -> 34714.286 | AH25: 36750 | AI25: =AG25-AA25 -> -1714.2857
A26: 6 | B26: I K A N | C26: ='01'!K26 -> 0 | D26: ='02'!K26 -> 0 | E26: ='03'!K26 -> 0 | F26: ='04'!K26 -> 0 | G26: ='05'!K26 -> 0 | H26: ='06'!K26 -> 0 | I26: ='07'!K26 -> 0 | J26: ='08'!K26 -> 0 | K26: ='09'!K26 -> 0 | L26: ='10'!K26 -> 0 | M26: ='11'!K26 -> 0 | N26: ='12'!K26 -> 0 | O26: ='13'!K26 -> 0 | P26: ='14'!K26 -> 0 | Q26: ='15'!K26 -> 0 | R26: ='16'!K26 -> 0 | S26: ='17'!K26 -> 0 | T26: ='18'!K26 -> 0 | U26: ='19'!K26 -> 0 | V26: ='20'!K26 -> 0 | W26: ='21'!K26 -> 0 | X26: ='22'!K26 -> 0 | Y26: ='23'!K26 -> 0 | Z26: ='24'!K26 -> 0 | AA26: ='25'!K26 -> 0 | AB26: ='26'!K26 -> 0 | AC26: ='27'!K26 -> 0 | AD26: ='28'!K26 -> 0 | AE26: ='29'!K26 -> 0 | AF26: ='30'!K26 -> 0 | AG26: ='31'!K26 -> 0 | AI26: =AG26-AA26 -> 0
B27: - Ikan Tongkol Segar (Uk. Sedang) | C27: ='01'!K27 -> 35166.667 | D27: ='02'!K27 -> 35166.667 | E27: ='03'!K27 -> 35833.333 | F27: ='04'!K27 -> 35833.333 | G27: ='05'!K27 -> 35833.333 | H27: ='06'!K27 -> 35833.333 | I27: ='07'!K27 -> 35833.333 | J27: ='08'!K27 -> 36666.667 | K27: ='09'!K27 -> 36666.667 | L27: ='10'!K27 -> 36666.667 | M27: ='11'!K27 -> 36666.667 | N27: ='12'!K27 -> 36666.667 | O27: ='13'!K27 -> 36666.667 | P27: ='14'!K27 -> 35833.333 | Q27: ='15'!K27 -> 35833.333 | R27: ='16'!K27 -> 35833.333 | S27: ='17'!K27 -> 35833.333 | T27: ='18'!K27 -> 35000 | U27: ='19'!K27 -> 35000 | V27: ='20'!K27 -> 35166.667 | W27: ='21'!K27 -> 35166.667 | X27: ='22'!K27 -> 35166.667 | Y27: ='23'!K27 -> 37285.714 | Z27: ='24'!K27 -> 35166.667 | AA27: ='25'!K27 -> 36833.333 | AB27: ='26'!K27 -> 36833.333 | AC27: ='27'!K27 -> 36833.333 | AD27: ='28'!K27 -> 36833.333 | AE27: ='29'!K27 -> 36000 | AF27: ='30'!K27 -> 38000 | AG27: ='31'!K27 -> 36000 | AI27: =AG27-AA27 -> -833.33333
B28: - Ikan Mujair Segar (Uk. Sedang) | C28: ='01'!K28 -> 26285.714 | D28: ='02'!K28 -> 26857.143 | E28: ='03'!K28 -> 26285.714 | F28: ='04'!K28 -> 26285.714 | G28: ='05'!K28 -> 26285.714 | H28: ='06'!K28 -> 26285.714 | I28: ='07'!K28 -> 27428.571 | J28: ='08'!K28 -> 26571.429 | K28: ='09'!K28 -> 26571.429 | L28: ='10'!K28 -> 26571.429 | M28: ='11'!K28 -> 26571.429 | N28: ='12'!K28 -> 26571.429 | O28: ='13'!K28 -> 26571.429 | P28: ='14'!K28 -> 26571.429 | Q28: ='15'!K28 -> 26571.429 | R28: ='16'!K28 -> 26857.143 | S28: ='17'!K28 -> 26857.143 | T28: ='18'!K28 -> 26857.143 | U28: ='19'!K28 -> 26857.143 | V28: ='20'!K28 -> 27142.857 | W28: ='21'!K28 -> 27142.857 | X28: ='22'!K28 -> 27142.857 | Y28: ='23'!K28 -> 27142.857 | Z28: ='24'!K28 -> 27142.857 | AA28: ='25'!K28 -> 27142.857 | AB28: ='26'!K28 -> 27142.857 | AC28: ='27'!K28 -> 27142.857 | AD28: ='28'!K28 -> 26857.143 | AE28: ='29'!K28 -> 26714.286 | AF28: ='30'!K28 -> 27000 | AG28: ='31'!K28 -> 26714.286 | AI28: =AG28-AA28 -> -428.57143
B29: - Udang Segar (Uk. Sedang) | C29: ='01'!K29 -> 61142.857 | D29: ='02'!K29 -> 62571.429 | E29: ='03'!K29 -> 61142.857 | F29: ='04'!K29 -> 61142.857 | G29: ='05'!K29 -> 61142.857 | H29: ='06'!K29 -> 61142.857 | I29: ='07'!K29 -> 61142.857 | J29: ='08'!K29 -> 61142.857 | K29: ='09'!K29 -> 61142.857 | L29: ='10'!K29 -> 61142.857 | M29: ='11'!K29 -> 61857.143 | N29: ='12'!K29 -> 61142.857 | O29: ='13'!K29 -> 61142.857 | P29: ='14'!K29 -> 61142.857 | Q29: ='15'!K29 -> 61857.143 | R29: ='16'!K29 -> 62571.429 | S29: ='17'!K29 -> 61857.143 | T29: ='18'!K29 -> 63285.714 | U29: ='19'!K29 -> 62571.429 | V29: ='20'!K29 -> 62571.429 | W29: ='21'!K29 -> 62571.429 | X29: ='22'!K29 -> 63285.714 | Y29: ='23'!K29 -> 63285.714 | Z29: ='24'!K29 -> 62571.429 | AA29: ='25'!K29 -> 64714.286 | AB29: ='26'!K29 -> 63285.714 | AC29: ='27'!K29 -> 63285.714 | AD29: ='28'!K29 -> 62571.429 | AE29: ='29'!K29 -> 62571.429 | AF29: ='30'!K29 -> 64000 | AG29: ='31'!K29 -> 62571.429 | AI29: =AG29-AA29 -> -2142.8571
B30: - Ikan Lele Segar (Ukuran Sedang) | C30: ='01'!K30 -> 24600 | D30: ='02'!K30 -> 24600 | E30: ='03'!K30 -> 25000 | F30: ='04'!K30 -> 25000 | G30: ='05'!K30 -> 25000 | H30: ='06'!K30 -> 25000 | I30: ='07'!K30 -> 25000 | J30: ='08'!K30 -> 25000 | K30: ='09'!K30 -> 25000 | L30: ='10'!K30 -> 25000 | M30: ='11'!K30 -> 25000 | N30: ='12'!K30 -> 25000 | O30: ='13'!K30 -> 25000 | P30: ='14'!K30 -> 25000 | Q30: ='15'!K30 -> 25000 | R30: ='16'!K30 -> 25000 | S30: ='17'!K30 -> 24600 | T30: ='18'!K30 -> 24600 | U30: ='19'!K30 -> 24600 | V30: ='20'!K30 -> 24600 | W30: ='21'!K30 -> 24000 | X30: ='22'!K30 -> 24000 | Y30: ='23'!K30 -> 24000 | Z30: ='24'!K30 -> 24000 | AA30: ='25'!K30 -> 24600 | AB30: ='26'!K30 -> 24600 | AC30: ='27'!K30 -> 24600 | AD30: ='28'!K30 -> 24600 | AE30: ='29'!K30 -> 24000 | AF30: ='30'!K30 -> 24000 | AG30: ='31'!K30 -> 24000 | AI30: =AG30-AA30 -> -600
B31: - Ikan Bandeng Segar (Uk. Sedang) | C31: ='01'!K31 -> 36000 | D31: ='02'!K31 -> 36000 | E31: ='03'!K31 -> 36428.571 | F31: ='04'!K31 -> 36428.571 | G31: ='05'!K31 -> 36428.571 | H31: ='06'!K31 -> 36428.571 | I31: ='07'!K31 -> 35857.143 | J31: ='08'!K31 -> 35857.143 | K31: ='09'!K31 -> 35857.143 | L31: ='10'!K31 -> 35571.429 | M31: ='11'!K31 -> 36142.857 | N31: ='12'!K31 -> 35571.429 | O31: ='13'!K31 -> 35714.286 | P31: ='14'!K31 -> 35000 | Q31: ='15'!K31 -> 35571.429 | R31: ='16'!K31 -> 35857.143 | S31: ='17'!K31 -> 35142.857 | T31: ='18'!K31 -> 35142.857 | U31: ='19'!K31 -> 35142.857 | V31: ='20'!K31 -> 35142.857 | W31: ='21'!K31 -> 35142.857 | X31: ='22'!K31 -> 35142.857 | Y31: ='23'!K31 -> 35142.857 | Z31: ='24'!K31 -> 35142.857 | AA31: ='25'!K31 -> 35428.571 | AB31: ='26'!K31 -> 34714.286 | AC31: ='27'!K31 -> 34714.286 | AD31: ='28'!K31 -> 34428.571 | AE31: ='29'!K31 -> 34428.571 | AF31: ='30'!K31 -> 33857.143 | AG31: ='31'!K31 -> 33714.286 | AI31: =AG31-AA31 -> -1714.2857
B32: - Ikan Teri Asin (Bukan Teri Medan) | C32: ='01'!K32 -> 93333.333 | D32: ='02'!K32 -> 86250 | E32: ='03'!K32 -> 87500 | F32: ='04'!K32 -> 87500 | G32: ='05'!K32 -> 87500 | H32: ='06'!K32 -> 87500 | I32: ='07'!K32 -> 87500 | J32: ='08'!K32 -> 87500 | K32: ='09'!K32 -> 86250 | L32: ='10'!K32 -> 87500 | M32: ='11'!K32 -> 87500 | N32: ='12'!K32 -> 87500 | O32: ='13'!K32 -> 87500 | P32: ='14'!K32 -> 87500 | Q32: ='15'!K32 -> 87500 | R32: ='16'!K32 -> 87500 | S32: ='17'!K32 -> 87500 | T32: ='18'!K32 -> 87500 | U32: ='19'!K32 -> 87500 | V32: ='20'!K32 -> 87500 | W32: ='21'!K32 -> 87500 | X32: ='22'!K32 -> 82500 | Y32: ='23'!K32 -> 82500 | Z32: ='24'!K32 -> 82500 | AA32: ='25'!K32 -> 87500 | AB32: ='26'!K32 -> 87500 | AC32: ='27'!K32 -> 87500 | AD32: ='28'!K32 -> 87500 | AE32: ='29'!K32 -> 87500 | AF32: ='30'!K32 -> 82500 | AG32: ='31'!K32 -> 82500 | AI32: =AG32-AA32 -> -5000
A33: 7 | B33: TELUR | C33: ='01'!K33 -> 0 | D33: ='02'!K33 -> 0 | E33: ='03'!K33 -> 0 | F33: ='04'!K33 -> 0 | G33: ='05'!K33 -> 0 | H33: ='06'!K33 -> 0 | I33: ='07'!K33 -> 0 | J33: ='08'!K33 -> 0 | K33: ='09'!K33 -> 0 | L33: ='10'!K33 -> 0 | M33: ='11'!K33 -> 0 | N33: ='12'!K33 -> 0 | O33: ='13'!K33 -> 0 | P33: ='14'!K33 -> 0 | Q33: ='15'!K33 -> 0 | R33: ='16'!K33 -> 0 | S33: ='17'!K33 -> 0 | T33: ='18'!K33 -> 0 | U33: ='19'!K33 -> 0 | V33: ='20'!K33 -> 0 | W33: ='21'!K33 -> 0 | X33: ='22'!K33 -> 0 | Y33: ='23'!K33 -> 0 | Z33: ='24'!K33 -> 0 | AA33: ='25'!K33 -> 0 | AB33: ='26'!K33 -> 0 | AC33: ='27'!K33 -> 0 | AD33: ='28'!K33 -> 0 | AE33: ='29'!K33 -> 0 | AF33: ='30'!K33 -> 0 | AG33: ='31'!K33 -> 0 | AI33: =AG33-AA33 -> 0
B34: - Telur Ayam Horn | C34: ='01'!K34 -> 29571.429 | D34: ='02'!K34 -> 29857.143 | E34: ='03'!K34 -> 29857.143 | F34: ='04'!K34 -> 29857.143 | G34: ='05'!K34 -> 29857.143 | H34: ='06'!K34 -> 30000 | I34: ='07'!K34 -> 29857.143 | J34: ='08'!K34 -> 30142.857 | K34: ='09'!K34 -> 30142.857 | L34: ='10'!K34 -> 30142.857 | M34: ='11'!K34 -> 30142.857 | N34: ='12'!K34 -> 29714.286 | O34: ='13'!K34 -> 29571.429 | P34: ='14'!K34 -> 29285.714 | Q34: ='15'!K34 -> 29285.714 | R34: ='16'!K34 -> 29857.143 | S34: ='17'!K34 -> 29428.571 | T34: ='18'!K34 -> 29428.571 | U34: ='19'!K34 -> 29428.571 | V34: ='20'!K34 -> 29428.571 | W34: ='21'!K34 -> 29571.429 | X34: ='22'!K34 -> 30000 | Y34: ='23'!K34 -> 30000 | Z34: ='24'!K34 -> 29714.286 | AA34: ='25'!K34 -> 29857.143 | AB34: ='26'!K34 -> 29714.286 | AC34: ='27'!K34 -> 29857.143 | AD34: ='28'!K34 -> 29857.143 | AE34: ='29'!K34 -> 29857.143 | AF34: ='30'!K34 -> 30142.857 | AG34: ='31'!K34 -> 29428.571 | AH34: 27000 | AI34: =AG34-AA34 -> -428.57143
B35: - Telur Ayam Kampung | C35: ='01'!K35 -> 2785.7143 | D35: ='02'!K35 -> 2928.5714 | E35: ='03'!K35 -> 2785.7143 | F35: ='04'!K35 -> 2785.7143 | G35: ='05'!K35 -> 2785.7143 | H35: ='06'!K35 -> 2785.7143 | I35: ='07'!K35 -> 2785.7143 | J35: ='08'!K35 -> 2785.7143 | K35: ='09'!K35 -> 2785.7143 | L35: ='10'!K35 -> 2785.7143 | M35: ='11'!K35 -> 2857.1429 | N35: ='12'!K35 -> 2785.7143 | O35: ='13'!K35 -> 2785.7143 | P35: ='14'!K35 -> 2785.7143 | Q35: ='15'!K35 -> 2785.7143 | R35: ='16'!K35 -> 2785.7143 | S35: ='17'!K35 -> 2785.7143 | T35: ='18'!K35 -> 2785.7143 | U35: ='19'!K35 -> 2785.7143 | V35: ='20'!K35 -> 2785.7143 | W35: ='21'!K35 -> 2785.7143 | X35: ='22'!K35 -> 2814.2857 | Y35: ='23'!K35 -> 2814.2857 | Z35: ='24'!K35 -> 2785.7143 | AA35: ='25'!K35 -> 2785.7143 | AB35: ='26'!K35 -> 2785.7143 | AC35: ='27'!K35 -> 2785.7143 | AD35: ='28'!K35 -> 2785.7143 | AE35: ='29'!K35 -> 2785.7143 | AF35: ='30'!K35 -> 2814.2857 | AG35: ='31'!K35 -> 2785.7143 | AI35: =AG35-AA35 -> 0
A36: 8 | B36: TAHU | C36: ='01'!K36 -> 0 | D36: ='02'!K36 -> 0 | E36: ='03'!K36 -> 0 | F36: ='04'!K36 -> 0 | G36: ='05'!K36 -> 0 | H36: ='06'!K36 -> 0 | I36: ='07'!K36 -> 0 | J36: ='08'!K36 -> 0 | K36: ='09'!K36 -> 0 | L36: ='10'!K36 -> 0 | M36: ='11'!K36 -> 0 | N36: ='12'!K36 -> 0 | O36: ='13'!K36 -> 0 | P36: ='14'!K36 -> 0 | Q36: ='15'!K36 -> 0 | R36: ='16'!K36 -> 0 | S36: ='17'!K36 -> 0 | T36: ='18'!K36 -> 0 | U36: ='19'!K36 -> 0 | V36: ='20'!K36 -> 0 | W36: ='21'!K36 -> 0 | X36: ='22'!K36 -> 0 | Y36: ='23'!K36 -> 0 | Z36: ='24'!K36 -> 0 | AA36: ='25'!K36 -> 0 | AB36: ='26'!K36 -> 0 | AC36: ='27'!K36 -> 0 | AD36: ='28'!K36 -> 0 | AE36: ='29'!K36 -> 0 | AF36: ='30'!K36 -> 0 | AG36: ='31'!K36 -> 0 | AI36: =AG36-AA36 -> 0
B37: - Tahu biasa | C37: ='01'!K37 -> 10000 | D37: ='02'!K37 -> 10000 | E37: ='03'!K37 -> 10000 | F37: ='04'!K37 -> 10000 | G37: ='05'!K37 -> 10000 | H37: ='06'!K37 -> 10000 | I37: ='07'!K37 -> 10000 | J37: ='08'!K37 -> 10000 | K37: ='09'!K37 -> 10000 | L37: ='10'!K37 -> 10000 | M37: ='11'!K37 -> 10000 | N37: ='12'!K37 -> 10000 | O37: ='13'!K37 -> 10000 | P37: ='14'!K37 -> 10000 | Q37: ='15'!K37 -> 10000 | R37: ='16'!K37 -> 10000 | S37: ='17'!K37 -> 10000 | T37: ='18'!K37 -> 10000 | U37: ='19'!K37 -> 10000 | V37: ='20'!K37 -> 10000 | W37: ='21'!K37 -> 10000 | X37: ='22'!K37 -> 10000 | Y37: ='23'!K37 -> 10000 | Z37: ='24'!K37 -> 10000 | AA37: ='25'!K37 -> 10000 | AB37: ='26'!K37 -> 10000 | AC37: ='27'!K37 -> 10000 | AD37: ='28'!K37 -> 10000 | AE37: ='29'!K37 -> 10000 | AF37: ='30'!K37 -> 10000 | AG37: ='31'!K37 -> 10000 | AI37: =AG37-AA37 -> 0
B38: - Tahu susu | C38: ='01'!K38 -> 12600 | D38: ='02'!K38 -> 12600 | E38: ='03'!K38 -> 12600 | F38: ='04'!K38 -> 12600 | G38: ='05'!K38 -> 12600 | H38: ='06'!K38 -> 12600 | I38: ='07'!K38 -> 12000 | J38: ='08'!K38 -> 12000 | K38: ='09'!K38 -> 12000 | L38: ='10'!K38 -> 12000 | M38: ='11'!K38 -> 12000 | N38: ='12'!K38 -> 12000 | O38: ='13'!K38 -> 12000 | P38: ='14'!K38 -> 12000 | Q38: ='15'!K38 -> 12000 | R38: ='16'!K38 -> 12100 | S38: ='17'!K38 -> 12000 | T38: ='18'!K38 -> 12000 | U38: ='19'!K38 -> 12000 | V38: ='20'!K38 -> 12000 | W38: ='21'!K38 -> 12000 | X38: ='22'!K38 -> 12000 | Y38: ='23'!K38 -> 12000 | Z38: ='24'!K38 -> 12000 | AA38: ='25'!K38 -> 12000 | AB38: ='26'!K38 -> 12000 | AC38: ='27'!K38 -> 12000 | AD38: ='28'!K38 -> 12600 | AE38: ='29'!K38 -> 12600 | AF38: ='30'!K38 -> 12600 | AG38: ='31'!K38 -> 12600 | AI38: =AG38-AA38 -> 600
A39: 9 | B39: TEMPE | C39: ='01'!K39 -> 0 | D39: ='02'!K39 -> 0 | E39: ='03'!K39 -> 0 | F39: ='04'!K39 -> 0 | G39: ='05'!K39 -> 0 | H39: ='06'!K39 -> 0 | I39: ='07'!K39 -> 0 | J39: ='08'!K39 -> 0 | K39: ='09'!K39 -> 0 | L39: ='10'!K39 -> 0 | M39: ='11'!K39 -> 0 | N39: ='12'!K39 -> 0 | O39: ='13'!K39 -> 0 | P39: ='14'!K39 -> 0 | Q39: ='15'!K39 -> 0 | R39: ='16'!K39 -> 0 | S39: ='17'!K39 -> 0 | T39: ='18'!K39 -> 0 | U39: ='19'!K39 -> 0 | V39: ='20'!K39 -> 0 | W39: ='21'!K39 -> 0 | X39: ='22'!K39 -> 0 | Y39: ='23'!K39 -> 0 | Z39: ='24'!K39 -> 0 | AA39: ='25'!K39 -> 0 | AB39: ='26'!K39 -> 0 | AC39: ='27'!K39 -> 0 | AD39: ='28'!K39 -> 0 | AE39: ='29'!K39 -> 0 | AF39: ='30'!K39 -> 0 | AG39: ='31'!K39 -> 0 | AI39: =AG39-AA39 -> 0
B40: - Tempe Kw I (campuran kedelai) | C40: ='01'!K40 -> 14000 | D40: ='02'!K40 -> 14000 | E40: ='03'!K40 -> 14000 | F40: ='04'!K40 -> 14000 | G40: ='05'!K40 -> 14000 | H40: ='06'!K40 -> 14000 | I40: ='07'!K40 -> 14000 | J40: ='08'!K40 -> 14000 | K40: ='09'!K40 -> 14000 | L40: ='10'!K40 -> 14000 | M40: ='11'!K40 -> 14000 | N40: ='12'!K40 -> 14000 | O40: ='13'!K40 -> 14000 | P40: ='14'!K40 -> 14000 | Q40: ='15'!K40 -> 14000 | R40: ='16'!K40 -> 14000 | S40: ='17'!K40 -> 14000 | T40: ='18'!K40 -> 14000 | U40: ='19'!K40 -> 14000 | V40: ='20'!K40 -> 14000 | W40: ='21'!K40 -> 14000 | X40: ='22'!K40 -> 14000 | Y40: ='23'!K40 -> 14000 | Z40: ='24'!K40 -> 14000 | AA40: ='25'!K40 -> 14000 | AB40: ='26'!K40 -> 14000 | AC40: ='27'!K40 -> 14000 | AD40: ='28'!K40 -> 13000 | AE40: ='29'!K40 -> 13000 | AF40: ='30'!K40 -> 13000 | AG40: ='31'!K40 -> 13000 | AI40: =AG40-AA40 -> -1000
B41: - Tempe Kw II (campuran jagung) | C41: ='01'!K41 -> 6833.3333 | D41: ='02'!K41 -> 6833.3333 | E41: ='03'!K41 -> 6833.3333 | F41: ='04'!K41 -> 6833.3333 | G41: ='05'!K41 -> 6833.3333 | H41: ='06'!K41 -> 6833.3333 | I41: ='07'!K41 -> 6833.3333 | J41: ='08'!K41 -> 6833.3333 | K41: ='09'!K41 -> 6833.3333 | L41: ='10'!K41 -> 6833.3333 | M41: ='11'!K41 -> 6833.3333 | N41: ='12'!K41 -> 6833.3333 | O41: ='13'!K41 -> 6833.3333 | P41: ='14'!K41 -> 6833.3333 | Q41: ='15'!K41 -> 6833.3333 | R41: ='16'!K41 -> 6833.3333 | S41: ='17'!K41 -> 6833.3333 | T41: ='18'!K41 -> 6833.3333 | U41: ='19'!K41 -> 6833.3333 | V41: ='20'!K41 -> 6833.3333 | W41: ='21'!K41 -> 6833.3333 | X41: ='22'!K41 -> 6833.3333 | Y41: ='23'!K41 -> 6833.3333 | Z41: ='24'!K41 -> 6833.3333 | AA41: ='25'!K41 -> 6833.3333 | AB41: ='26'!K41 -> 6833.3333 | AC41: ='27'!K41 -> 6833.3333 | AD41: ='28'!K41 -> 4250 | AE41: ='29'!K41 -> 4250 | AF41: ='30'!K41 -> 4250 | AG41: ='31'!K41 -> 4250 | AI41: =AG41-AA41 -> -2583.3333
...

Sheet GRAFIK
A1: BAGIAN PEREKONOMIAN DAN SUMBER DAYA ALAM
A2: LAPORAN HARGA BAHAN POKOK DI KOTA SURABAYA
A3: PERIODE JULI 2023
