Workbook

Sheet REKAPITULASI
A1: BAGIAN PEREKONOMIAN DAN SUMBER DAYA ALAM
A2: LAPORAN HARGA BAHAN POKOK DI KOTA SURABAYA
A3: PERIODE AGUSTUS 2023
B4: NAMA BAHAN POKOK DAN PENTING LAINNYA | AH4: HET/HAPK (Harga Eceran Tertinggi) | AI4: FLUKTUASI
C5: 1 | D5: 2 | E5: 3 | F5: 4 | G5: 5 | H5: 6 | I5: 7 | J5: 8 | K5: 9 | L5: 10 | M5: 11 | N5: 12 | O5: 13 | P5: 14 | Q5: 15 | R5: 16 | S5: 17 | T5: 18 | U5: 19 | V5: 20 | W5: 21 | X5: 22 | Y5: 23 | Z5: 24 | AA5: 25 | AB5: 26 | AC5: 27 | AD5: 28 | AE5: 29 | AF5: 30 | AG5: 31
A7: 1 | B7: BERAS
B8: - Beras Premium | C8: ='01'!K8 -> 13000 | D8: ='02'!K8 -> 13000 | E8: ='03'!K8 -> 13000 | F8: ='04'!K8 -> 13000 | G8: ='05'!K8 -> 13142.857 | H8: ='06'!K8 -> 13142.857 | I8: ='07'!K8 -> 13142.857 | J8: ='08'!K8 -> 13000 | K8: ='09'!K8 -> 13000 | L8: ='10'!K8 -> 13000 | M8: ='11'!K8 -> 13000 | N8: ='12'!K8 -> 13000 | O8: ='13'!K8 -> 13000 | P8: ='14'!K8 -> 13071.429 | Q8: ='15'!K8 -> 13071.429 | R8: ='16'!K8 -> 13071.429 | S8: ='17'!K8 -> 13000 | T8: ='18'!K8 -> 13071.429 | U8: ='19'!K8 -> 13071.429 | V8: ='20'!K8 -> 13071.429 | W8: ='21'!K8 -> 13071.429 | X8: ='22'!K8 -> 13071.429 | Y8: ='23'!K8 -> 13071.429 | Z8: ='24'!K8 -> 13071.429 | AA8: ='25'!K8 -> 13142.857 | AB8: ='26'!K8 -> 13142.857 | AC8: ='27'!K8 -> 13214.286 | AD8: ='28'!K8 -> 13142.857 | AE8: ='29'!K8 -> 13171.429 | AF8: ='30'!K8 -> 13142.857 | AG8: ='31'!K8 -> 13142.857 | AH8: 12800 | AI8: =AG8-C8 -> 142.85714 | AJ8: =AVERAGE(C8:AG8) -> 13072.35
B9: - Beras IR.64 Medium Bulog | C9: ='01'!K9 -> 9000 | D9: ='02'!K9 -> 9000 | E9: ='03'!K9 -> 9000 | F9: ='04'!K9 -> 9000 | G9: ='05'!K9 -> 9200 | H9: ='06'!K9 -> 9200 | I9: ='07'!K9 -> 9200 | J9: ='08'!K9 -> 9200 | K9: ='09'!K9 -> 9200 | L9: ='10'!K9 -> 9200 | M9: ='11'!K9 -> 9200 | N9: ='12'!K9 -> 9200 | O9: ='13'!K9 -> 9250 | P9: ='14'!K9 -> 9200 | Q9: ='15'!K9 -> 9200 | R9: ='16'!K9 -> 9200 | S9: ='17'!K9 -> 9200 | T9: ='18'!K9 -> 9200 | U9: ='19'!K9 -> 9200 | V9: ='20'!K9 -> 9200 | W9: ='21'!K9 -> 9200 | X9: ='22'!K9 -> 9200 | Y9: ='23'!K9 -> 9200 | Z9: ='24'!K9 -> 9200 | AA9: ='25'!K9 -> 9200 | AB9: ='26'!K9 -> 9000 | AC9: ='27'!K9 -> 9100 | AD9: ='28'!K9 -> 9200 | AE9: ='29'!K9 -> 9300 | AF9: ='30'!K9 -> 9300 | AG9: ='31'!K9 -> 9300 | AI9: =AG9-C9 -> 300 | AJ9: =AVERAGE(C9:AG9) -> 9175.8065
B10: - Beras IR.64 Medium | C10: ='01'!K10 -> 10860 | D10: ='02'!K10 -> 11300 | E10: ='03'!K10 -> 10860 | F10: ='04'!K10 -> 11160 | G10: ='05'!K10 -> 11460 | H10: ='06'!K10 -> 10960 | I10: ='07'!K10 -> 11160 | J10: ='08'!K10 -> 11160 | K10: ='09'!K10 -> 11160 | L10: ='10'!K10 -> 11160 | M10: ='11'!K10 -> 11160 | N10: ='12'!K10 -> 11160 | O10: ='13'!K10 -> 11160 | P10: ='14'!K10 -> 11660 | Q10: ='15'!K10 -> 11660 | R10: ='16'!K10 -> 11660 | S10: ='17'!K10 -> 11160 | T10: ='18'!K10 -> 11660 | U10: ='19'!K10 -> 11660 | V10: ='20'!K10 -> 11660 | W10: ='21'!K10 -> 11660 | X10: ='22'!K10 -> 11660 | Y10: ='23'!K10 -> 11660 | Z10: ='24'!K10 -> 11660 | AA10: ='25'!K10 -> 11660 | AB10: ='26'!K10 -> 11660 | AC10: ='27'!K10 -> 12160 | AD10: ='28'!K10 -> 11660 | AE10: ='29'!K10 -> 11850 | AF10: ='30'!K10 -> 11880 | AG10: ='31'!K10 -> 11880 | AH10: 9450 | AI10: =AG10-C10 -> 1020 | AJ10: =AVERAGE(C10:AG10) -> 11459.032
B11: - Beras Jagung | C11: ='01'!K11 -> 10200 | D11: ='02'!K11 -> 10750 | E11: ='03'!K11 -> 10200 | F11: ='04'!K11 -> 10200 | G11: ='05'!K11 -> 10200 | H11: ='06'!K11 -> 10200 | I11: ='07'!K11 -> 10200 | J11: ='08'!K11 -> 10200 | K11: ='09'!K11 -> 10200 | L11: ='10'!K11 -> 10200 | M11: ='11'!K11 -> 10200 | N11: ='12'!K11 -> 10200 | O11: ='13'!K11 -> 10200 | P11: ='14'!K11 -> 10000 | Q11: ='15'!K11 -> 10000 | R11: ='16'!K11 -> 10000 | S11: ='17'!K11 -> 10200 | T11: ='18'!K11 -> 10000 | U11: ='19'!K11 -> 10000 | V11: ='20'!K11 -> 10000 | W11: ='21'!K11 -> 10000 | X11: ='22'!K11 -> 10000 | Y11: ='23'!K11 -> 10000 | Z11: ='24'!K11 -> 10000 | AA11: ='25'!K11 -> 10000 | AB11: ='26'!K11 -> 10000 | AC11: ='27'!K11 -> 9800 | AD11: ='28'!K11 -> 10000 | AE11: ='29'!K11 -> 10000 | AF11: ='30'!K11 -> 10000 | AG11: ='31'!K11 -> 10000 | AI11: =AG11-C11 -> -200 | AJ11: =AVERAGE(C11:AG11) -> 10101.613
B12: - Beras Ketan (Jenis Siyem) | C12: ='01'!K12 -> 18600 | D12: ='02'!K12 -> 19000 | E12: ='03'!K12 -> 18600 | F12: ='04'!K12 -> 18600 | G12: ='05'!K12 -> 18800 | H12: ='06'!K12 -> 18800 | I12: ='07'!K12 -> 18600 | J12: ='08'!K12 -> 18600 | K12: ='09'!K12 -> 18600 | L12: ='10'!K12 -> 18600 | M12: ='11'!K12 -> 18600 | N12: ='12'!K12 -> 18600 | O12: ='13'!K12 -> 18600 | P12: ='14'!K12 -> 18600 | Q12: ='15'!K12 -> 18600 | R12: ='16'!K12 -> 18600 | S12: ='17'!K12 -> 18600 | T12: ='18'!K12 -> 18600 | U12: ='19'!K12 -> 18600 | V12: ='20'!K12 -> 20000 | W12: ='21'!K12 -> 18600 | X12: ='22'!K12 -> 18600 | Y12: ='23'!K12 -> 18600 | Z12: ='24'!K12 -> 18600 | AA12: ='25'!K12 -> 18600 | AB12: ='26'!K12 -> 18600 | AC12: ='27'!K12 -> 18600 | AD12: ='28'!K12 -> 18600 | AE12: ='29'!K12 -> 18600 | AF12: ='30'!K12 -> 18600 | AG12: ='31'!K12 -> 18600 | AI12: =AG12-C12 -> 0 | AJ12: =AVERAGE(C12:AG12) -> 18670.968
A13: 2 | B13: GULA | C13: ='01'!K13 -> 0 | D13: ='02'!K13 -> 0 | E13: ='03'!K13 -> 0 | F13: ='04'!K13 -> 0 | G13: ='05'!K13 -> 0 | H13: ='06'!K13 -> 0 | I13: ='07'!K13 -> 0 | J13: ='08'!K13 -> 0 | K13: ='09'!K13 -> 0 | L13: ='10'!K13 -> 0 | M13: ='11'!K13 -> 0 | N13: ='12'!K13 -> 0 | O13: ='13'!K13 -> 0 | P13: ='14'!K13 -> 0 | Q13: ='15'!K13 -> 0 | R13: ='16'!K13 -> 0 | S13: ='17'!K13 -> 0 | T13: ='18'!K13 -> 0 | U13: ='19'!K13 -> 0 | V13: ='20'!K13 -> 0 | W13: ='21'!K13 -> 0 | X13: ='22'!K13 -> 0 | Y13: ='23'!K13 -> 0 | Z13: ='24'!K13 -> 0 | AA13: ='25'!K13 -> 0 | AB13: ='26'!K13 -> 0 | AC13: ='27'!K13 -> 0 | AD13: ='28'!K13 -> 0 | AE13: ='29'!K13 -> 0 | AF13: ='30'!K13 -> 0 | AG13: ='31'!K13 -> 0 | AI13: =AG13-C13 -> 0 | AJ13: =AVERAGE(C13:AG13) -> 0
B14: Gula Pasir Lokal Curah | C14: ='01'!K14 -> 13357.143 | D14: ='02'!K14 -> 13357.143 | E14: ='03'!K14 -> 13357.143 | F14: ='04'!K14 -> 13357.143 | G14: ='05'!K14 -> 13357.143 | H14: ='06'!K14 -> 13357.143 | I14: ='07'!K14 -> 13357.143 | J14: ='08'!K14 -> 13285.714 | K14: ='09'!K14 -> 13285.714 | L14: ='10'!K14 -> 13357.143 | M14: ='11'!K14 -> 13357.143 | N14: ='12'!K14 -> 13428.571 | O14: ='13'!K14 -> 13428.571 | P14: ='14'!K14 -> 13357.143 | Q14: ='15'!K14 -> 13357.143 | R14: ='16'!K14 -> 13357.143 | S14: ='17'!K14 -> 13357.143 | T14: ='18'!K14 -> 13357.143 | U14: ='19'!K14 -> 13285.714 | V14: ='20'!K14 -> 13214.286 | W14: ='21'!K14 -> 13285.714 | X14: ='22'!K14 -> 13285.714 | Y14: ='23'!K14 -> 13285.714 | Z14: ='24'!K14 -> 13285.714 | AA14: ='25'!K14 -> 13285.714 | AB14: ='26'!K14 -> 13285.714 | AC14: ='27'!K14 -> 13285.714 | AD14: ='28'!K14 -> 13285.714 | AE14: ='29'!K14 -> 13285.714 | AF14: ='30'!K14 -> 13285.714 | AG14: ='31'!K14 -> 13285.714 | AH14: 13500 | AI14: =AG14-C14 -> -71.428571 | AJ14: =AVERAGE(C14:AG14) -> 13324.885
B15: - Gula Jawa/Merah (Bahan Kelapa) | C15: ='01'!K15 -> 15285.714 | D15: ='02'!K15 -> 15142.857 | E15: ='03'!K15 -> 15285.714 | F15: ='04'!K15 -> 15285.714 | G15: ='05'!K15 -> 15714.286 | H15: ='06'!K15 -> 15714.286 | I15: ='07'!K15 -> 15285.714 | J15: ='08'!K15 -> 15285.714 | K15: ='09'!K15 -> 15285.714 | L15: ='10'!K15 -> 15285.714 | M15: ='11'!K15 -> 15285.714 | N15: ='12'!K15 -> 15285.714 | O15: ='13'!K15 -> 15285.714 | P15: ='14'!K15 -> 15142.857 | Q15: ='15'!K15 -> 15142.857 | R15: ='16'!K15 -> 15142.857 | S15: ='17'!K15 -> 15285.714 | T15: ='18'!K15 -> 15142.857 | U15: ='19'!K15 -> 15142.857 | V15: ='20'!K15 -> 15142.857 | W15: ='21'!K15 -> 15142.857 | X15: ='22'!K15 -> 15142.857 | Y15: ='23'!K15 -> 15142.857 | Z15: ='24'!K15 -> 15142.857 | AA15: ='25'!K15 -> 15142.857 | AB15: ='26'!K15 -> 15142.857 | AC15: ='27'!K15 -> 15428.571 | AD15: ='28'!K15 -> 15142.857 | AE15: ='29'!K15 -> 15142.857 | AF15: ='30'!K15 -> 15142.857 | AG15: ='31'!K15 -> 15142.857 | AI15: =AG15-C15 -> -142.85714 | AJ15: =AVERAGE(C15:AG15) -> 15239.631
B16: MINYAK GORENG | C16: ='01'!K16 -> 0 | D16: ='02'!K16 -> 0 | E16: ='03'!K16 -> 0 | F16: ='04'!K16 -> 0 | G16: ='05'!K16 -> 0 | H16: ='06'!K16 -> 0 | I16: ='07'!K16 -> 0 | J16: ='08'!K16 -> 0 | K16: ='09'!K16 -> 0 | L16: ='10'!K16 -> 0 | M16: ='11'!K16 -> 0 | N16: ='12'!K16 -> 0 | O16: ='13'!K16 -> 0 | P16: ='14'!K16 -> 0 | Q16: ='15'!K16 -> 0 | R16: ='16'!K16 -> 0 | S16: ='17'!K16 -> 0 | T16: ='18'!K16 -> 0 | U16: ='19'!K16 -> 0 | V16: ='20'!K16 -> 0 | W16: ='21'!K16 -> 0 | X16: ='22'!K16 -> 0 | Y16: ='23'!K16 -> 0 | Z16: ='24'!K16 -> 0 | AA16: ='25'!K16 -> 0 | AB16: ='26'!K16 -> 0 | AC16: ='27'!K16 -> 0 | AD16: ='28'!K16 -> 0 | AE16: ='29'!K16 -> 0 | AF16: ='30'!K16 -> 0 | AG16: ='31'!K16 -> 0 | AI16: =AG16-C16 -> 0 | AJ16: =AVERAGE(C16:AG16) -> 0
B17: - Minyak Goreng Curah (Bening) | C17: ='01'!K17 -> 15000 | D17: ='02'!K17 -> 15000 | E17: ='03'!K17 -> 15000 | F17: ='04'!K17 -> 15000 | G17: ='05'!K17 -> 15285.714 | H17: ='06'!K17 -> 15285.714 | I17: ='07'!K17 -> 15000 | J17: ='08'!K17 -> 15000 | K17: ='09'!K17 -> 15000 | L17: ='10'!K17 -> 15000 | M17: ='11'!K17 -> 15000 | N17: ='12'!K17 -> 15000 | O17: ='13'!K17 -> 15000 | P17: ='14'!K17 -> 15000 | Q17: ='15'!K17 -> 15000 | R17: ='16'!K17 -> 15000 | S17: ='17'!K17 -> 15000 | T17: ='18'!K17 -> 15000 | U17: ='19'!K17 -> 15000 | V17: ='20'!K17 -> 15000 | W17: ='21'!K17 -> 15000 | X17: ='22'!K17 -> 15000 | Y17: ='23'!K17 -> 15000 | Z17: ='24'!K17 -> 15000 | AA17: ='25'!K17 -> 15000 | AB17: ='26'!K17 -> 15000 | AC17: ='27'!K17 -> 15142.857 | AD17: ='28'!K17 -> 15000 | AE17: ='29'!K17 -> 15000 | AF17: ='30'!K17 -> 15000 | AG17: ='31'!K17 -> 15000 | AH17: 15500 | AI17: =AG17-C17 -> 0 | AJ17: =AVERAGE(C17:AG17) -> 15023.041
B18: - Minyak KITA | C18: ='01'!K18 -> 14000 | D18: ='02'!K18 -> 14000 | E18: ='03'!K18 -> 14000 | F18: ='04'!K18 -> 14000 | G18: ='05'!K18 -> 14000 | H18: ='06'!K18 -> 14000 | I18: ='07'!K18 -> 14000 | J18: ='08'!K18 -> 14000 | K18: ='09'!K18 -> 14000 | L18: ='10'!K18 -> 14000 | M18: ='11'!K18 -> 14000 | N18: ='12'!K18 -> 14000 | O18: ='13'!K18 -> 14000 | P18: ='14'!K18 -> 14000 | Q18: ='15'!K18 -> 14000 | R18: ='16'!K18 -> 14000 | S18: ='17'!K18 -> 14000 | T18: ='18'!K18 -> 14000 | U18: ='19'!K18 -> 14000 | V18: ='20'!K18 -> 14000 | W18: ='21'!K18 -> 14000 | X18: ='22'!K18 -> 14000 | Y18: ='23'!K18 -> 14000 | Z18: ='24'!K18 -> 14000 | AA18: ='25'!K18 -> 14000 | AB18: ='26'!K18 -> 14000 | AC18: ='27'!K18 -> 14000 | AD18: ='28'!K18 -> 14000 | AE18: ='29'!K18 -> 14000 | AF18: ='30'!K18 -> 14000 | AG18: ='31'!K18 -> 14000 | AH18: 14000 | AI18: =AG18-C18 -> 0 | AJ18: =AVERAGE(C18:AG18) -> 14000
A19: 4 | B19: MENTEGA | C19: ='01'!K19 -> 0 | D19: ='02'!K19 -> 0 | E19: ='03'!K19 -> 0 | F19: ='04'!K19 -> 0 | G19: ='05'!K19 -> 0 | H19: ='06'!K19 -> 0 | I19: ='07'!K19 -> 0 | J19: ='08'!K19 -> 0 | K19: ='09'!K19 -> 0 | L19: ='10'!K19 -> 0 | M19: ='11'!K19 -> 0 | N19: ='12'!K19 -> 0 | O19: ='13'!K19 -> 0 | P19: ='14'!K19 -> 0 | Q19: ='15'!K19 -> 0 | R19: ='16'!K19 -> 0 | S19: ='17'!K19 -> 0 | T19: ='18'!K19 -> 0 | U19: ='19'!K19 -> 0 | V19: ='20'!K19 -> 0 | W19: ='21'!K19 -> 0 | X19: ='22'!K19 -> 0 | Y19: ='23'!K19 -> 0 | Z19: ='24'!K19 -> 0 | AA19: ='25'!K19 -> 0 | AB19: ='26'!K19 -> 0 | AC19: ='27'!K19 -> 0 | AD19: ='28'!K19 -> 0 | AE19: ='29'!K19 -> 0 | AF19: ='30'!K19 -> 0 | AG19: ='31'!K19 -> 0 | AI19: =AG19-C19 -> 0 | AJ19: =AVERAGE(C19:AG19) -> 0
B20: - Mentega Curah (Amanda) | C20: ='01'!K20 -> 21500 | D20: ='02'!K20 -> 21500 | E20: ='03'!K20 -> 21500 | F20: ='04'!K20 -> 21500 | G20: ='05'!K20 -> 21500 | H20: ='06'!K20 -> 21500 | I20: ='07'!K20 -> 21500 | J20: ='08'!K20 -> 21500 | K20: ='09'!K20 -> 21500 | L20: ='10'!K20 -> 21500 | M20: ='11'!K20 -> 21500 | N20: ='12'!K20 -> 21500 | O20: ='13'!K20 -> 21750 | P20: ='14'!K20 -> 21375 | Q20: ='15'!K20 -> 21375 | R20: ='16'!K20 -> 21375 | S20: ='17'!K20 -> 21500 | T20: ='18'!K20 -> 21375 | U20: ='19'!K20 -> 21375 | V20: ='20'!K20 -> 21125 | W20: ='21'!K20 -> 21375 | X20: ='22'!K20 -> 21375 | Y20: ='23'!K20 -> 21375 | Z20: ='24'!K20 -> 21375 | AA20: ='25'!K20 -> 21375 | AB20: ='26'!K20 -> 21375 | AC20: ='27'!K20 -> 21375 | AD20: ='28'!K20 -> 21375 | AE20: ='29'!K20 -> 21375 | AF20: ='30'!K20 -> 21375 | AG20: ='31'!K20 -> 21375 | AI20: =AG20-C20 -> -125 | AJ20: =AVERAGE(C20:AG20) -> 21431.452
A21: 5 | B21: DAGING | C21: ='01'!K21 -> 0 | D21: ='02'!K21 -> 0 | E21: ='03'!K21 -> 0 | F21: ='04'!K21 -> 0 | G21: ='05'!K21 -> 0 | H21: ='06'!K21 -> 0 | I21: ='07'!K21 -> 0 | J21: ='08'!K21 -> 0 | K21: ='09'!K21 -> 0 | L21: ='10'!K21 -> 0 | M21: ='11'!K21 -> 0 | N21: ='12'!K21 -> 0 | O21: ='13'!K21 -> 0 | P21: ='14'!K21 -> 0 | Q21: ='15'!K21 -> 0 | R21: ='16'!K21 -> 0 | S21: ='17'!K21 -> 0 | T21: ='18'!K21 -> 0 | U21: ='19'!K21 -> 0 | V21: ='20'!K21 -> 0 | W21: ='21'!K21 -> 0 | X21: ='22'!K21 -> 0 | Y21: ='23'!K21 -> 0 | Z21: ='24'!K21 -> 0 | AA21: ='25'!K21 -> 0 | AB21: ='26'!K21 -> 0 | AC21: ='27'!K21 -> 0 | AD21: ='28'!K21 -> 0 | AE21: ='29'!K21 -> 0 | AF21: ='30'!K21 -> 0 | AG21: ='31'!K21 -> 0 | AI21: =AG21-C21 -> 0 | AJ21: =AVERAGE(C21:AG21) -> 0
B22: - Daging Sapi Grade Atas | C22: ='01'!K22 -> 120000 | D22: ='02'!K22 -> 120000 | E22: ='03'!K22 -> 120000 | F22: ='04'!K22 -> 120000 | G22: ='05'!K22 -> 119166.67 | H22: ='06'!K22 -> 119166.67 | I22: ='07'!K22 -> 120000 | J22: ='08'!K22 -> 120000 | K22: ='09'!K22 -> 120000 | L22: ='10'!K22 -> 120000 | M22: ='11'!K22 -> 120000 | N22: ='12'!K22 -> 120000 | O22: ='13'!K22 -> 120000 | P22: ='14'!K22 -> 120000 | Q22: ='15'!K22 -> 120000 | R22: ='16'!K22 -> 120000 | S22: ='17'!K22 -> 120000 | T22: ='18'!K22 -> 120000 | U22: ='19'!K22 -> 120000 | V22: ='20'!K22 -> 120000 | W22: ='21'!K22 -> 120000 | X22: ='22'!K22 -> 120000 | Y22: ='23'!K22 -> 120000 | Z22: ='24'!K22 -> 120000 | AA22: ='25'!K22 -> 120000 | AB22: ='26'!K22 -> 120000 | AC22: ='27'!K22 -> 120000 | AD22: ='28'!K22 -> 120000 | AE22: ='29'!K22 -> 120000 | AF22: ='30'!K22 -> 120000 | AG22: ='31'!K22 -> 120000 | AH22: 105000 | AI22: =AG22-C22 -> 0 | AJ22: =AVERAGE(C22:AG22) -> 119946.24
B23: - Daging Sapi Grade Sedang | C23: ='01'!K23 -> 111428.57 | D23: ='02'!K23 -> 110714.29 | E23: ='03'!K23 -> 110714.29 | F23: ='04'!K23 -> 110714.29 | G23: ='05'!K23 -> 110714.29 | H23: ='06'!K23 -> 110714.29 | I23: ='07'!K23 -> 110714.29 | J23: ='08'!K23 -> 110714.29 | K23: ='09'!K23 -> 110714.29 | L23: ='10'!K23 -> 110714.29 | M23: ='11'!K23 -> 110714.29 | N23: ='12'!K23 -> 110714.29 | O23: ='13'!K23 -> 110714.29 | P23: ='14'!K23 -> 110714.29 | Q23: ='15'!K23 -> 110714.29 | R23: ='16'!K23 -> 110714.29 | S23: ='17'!K23 -> 110714.29 | T23: ='18'!K23 -> 110714.29 | U23: ='19'!K23 -> 110714.29 | V23: ='20'!K23 -> 110714.29 | W23: ='21'!K23 -> 110714.29 | X23: ='22'!K23 -> 110714.29 | Y23: ='23'!K23 -> 110714.29 | Z23: ='24'!K23 -> 110714.29 | AA23: ='25'!K23 -> 110714.29 | AB23: ='26'!K23 -> 110714.29 | AC23: ='27'!K23 -> 110714.29 | AD23: ='28'!K23 -> 110714.29 | AE23: ='29'!K23 -> 110714.29 | AF23: ='30'!K23 -> 110714.29 | AG23: ='31'!K23 -> 110714.29 | AH23: 80000 | AI23: =AG23-C23 -> -714.28571 | AJ23: =AVERAGE(C23:AG23) -> 110737.33
B24: - Daging Sapi Grade Bawah | C24: ='01'!K24 -> 100000 | D24: ='02'!K24 -> 99285.714 | E24: ='03'!K24 -> 99285.714 | F24: ='04'!K24 -> 99285.714 | G24: ='05'!K24 -> 98571.429 | H24: ='06'!K24 -> 98571.429 | I24: ='07'!K24 -> 99285.714 | J24: ='08'!K24 -> 99285.714 | K24: ='09'!K24 -> 99285.714 | L24: ='10'!K24 -> 99285.714 | M24: ='11'!K24 -> 99285.714 | N24: ='12'!K24 -> 99285.714 | O24: ='13'!K24 -> 99285.714 | P24: ='14'!K24 -> 99285.714 | Q24: ='15'!K24 -> 99285.714 | R24: ='16'!K24 -> 99285.714 | S24: ='17'!K24 -> 99285.714 | T24: ='18'!K24 -> 99285.714 | U24: ='19'!K24 -> 98571.429 | V24: ='20'!K24 -> 98571.429 | W24: ='21'!K24 -> 98571.429 | X24: ='22'!K24 -> 98571.429 | Y24: ='23'!K24 -> 98571.429 | Z24: ='24'!K24 -> 98571.429 | AA24: ='25'!K24 -> 98571.429 | AB24: ='26'!K24 -> 98571.429 | AC24: ='27'!K24 -> 98571.429 | AD24: ='28'!K24 -> 98571.429 | AE24: ='29'!K24 -> 98571.429 | AF24: ='30'!K24 -> 98571.429 | AG24: ='31'!K24 -> 98571.429 | AH24: 80000 | AI24: =AG24-C24 -> -1428.5714 | AJ24: =AVERAGE(C24:AG24) -> 98963.134
B25: - Daging Ayam Broiler | C25: ='01'!K25 -> 34571.429 | D25: ='02'!K25 -> 34571.429 | E25: ='03'!K25 -> 33857.143 | F25: ='04'!K25 -> 33714.286 | G25: ='05'!K25 -> 33714.286 | H25: ='06'!K25 -> 33714.286 | I25: ='07'!K25 -> 34000 | J25: ='08'!K25 -> 33714.286 | K25: ='09'!K25 -> 34857.143 | L25: ='10'!K25 -> 35142.857 | M25: ='11'!K25 -> 35428.571 | N25: ='12'!K25 -> 35714.286 | O25: ='13'!K25 -> 35571.429 | P25: ='14'!K25 -> 35714.286 | Q25: ='15'!K25 -> 35571.429 | R25: ='16'!K25 -> 35571.429 | S25: ='17'!K25 -> 35714.286 | T25: ='18'!K25 -> 35857.143 | U25: ='19'!K25 -> 35714.286 | V25: ='20'!K25 -> 35285.714 | W25: ='21'!K25 -> 35285.714 | X25: ='22'!K25 -> 35142.857 | Y25: ='23'!K25 -> 35142.857 | Z25: ='24'!K25 -> 35285.714 | AA25: ='25'!K25 -> 35285.714 | AB25: ='26'!K25 -> 35285.714 | AC25: ='27'!K25 -> 35571.429 | AD25: ='28'!K25 -> 35428.571 | AE25: ='29'!K25 -> 35428.571 | AF25: ='30'!K25 -> 35285.714 | AG25: ='31'!K25 -> 35285.714 | AH25: 36750 | AI25: =AG25-C25 -> 714.28571 | AJ25: =AVERAGE(C25:AG25) -> 35046.083
A26: 6 | B26: I K A N | C26: ='01'!K26 -> 0 | D26: ='02'!K26 -> 0 | E26: ='03'!K26 -> 0 | F26: ='04'!K26 -> 0 | G26: ='05'!K26 -> 0 | H26: ='06'!K26 -> 0 | I26: ='07'!K26 -> 0 | J26: ='08'!K26 -> 0 | K26: ='09'!K26 -> 0 | L26: ='10'!K26 -> 0 | M26: ='11'!K26 -> 0 | N26: ='12'!K26 -> 0 | O26: ='13'!K26 -> 0 | P26: ='14'!K26 -> 0 | Q26: ='15'!K26 -> 0 | R26: ='16'!K26 -> 0 | S26: ='17'!K26 -> 0 | T26: ='18'!K26 -> 0 | U26: ='19'!K26 -> 0 | V26: ='20'!K26 -> 0 | W26: ='21'!K26 -> 0 | X26: ='22'!K26 -> 0 | Y26: ='23'!K26 -> 0 | Z26: ='24'!K26 -> 0 | AA26: ='25'!K26 -> 0 | AB26: ='26'!K26 -> 0 | AC26: ='27'!K26 -> 0 | AD26: ='28'!K26 -> 0 | AE26: ='29'!K26 -> 0 | AF26: ='30'!K26 -> 0 | AG26: ='31'!K26 -> 0 | AI26: =AG26-C26 -> 0 | AJ26: =AVERAGE(C26:AG26) -> 0
B27: - Ikan Tongkol Segar (Uk. Sedang) | C27: ='01'!K27 -> 36000 | D27: ='02'!K27 -> 35166.667 | E27: ='03'!K27 -> 36000 | F27: ='04'!K27 -> 36000 | G27: ='05'!K27 -> 36000 | H27: ='06'!K27 -> 36000 | I27: ='07'!K27 -> 36000 | J27: ='08'!K27 -> 36000 | K27: ='09'!K27 -> 36000 | L27: ='10'!K27 -> 36000 | M27: ='11'!K27 -> 36000 | N27: ='12'!K27 -> 36000 | O27: ='13'!K27 -> 36000 | P27: ='14'!K27 -> 36500 | Q27: ='15'!K27 -> 36500 | R27: ='16'!K27 -> 36500 | S27: ='17'!K27 -> 36000 | T27: ='18'!K27 -> 36500 | U27: ='19'!K27 -> 36500 | V27: ='20'!K27 -> 35666.667 | W27: ='21'!K27 -> 35666.667 | X27: ='22'!K27 -> 35666.667 | Y27: ='23'!K27 -> 35666.667 | Z27: ='24'!K27 -> 35666.667 | AA27: ='25'!K27 -> 35666.667 | AB27: ='26'!K27 -> 35666.667 | AC27: ='27'!K27 -> 35666.667 | AD27: ='28'!K27 -> 35666.667 | AE27: ='29'!K27 -> 35666.667 | AF27: ='30'!K27 -> 36500 | AG27: ='31'!K27 -> 36500 | AI27: =AG27-C27 -> 500 | AJ27: =AVERAGE(C27:AG27) -> 35978.495
B28: - Ikan Mujair Segar (Uk. Sedang) | C28: ='01'!K28 -> 26714.286 | D28: ='02'!K28 -> 26428.571 | E28: ='03'!K28 -> 26714.286 | F28: ='04'!K28 -> 27000 | G28: ='05'!K28 -> 27000 | H28: ='06'!K28 -> 27000 | I28: ='07'!K28 -> 27000 | J28: ='08'!K28 -> 27000 | K28: ='09'!K28 -> 27000 | L28: ='10'!K28 -> 26714.286 | M28: ='11'!K28 -> 26714.286 | N28: ='12'!K28 -> 26714.286 | O28: ='13'!K28 -> 26714.286 | P28: ='14'!K28 -> 27142.857 | Q28: ='15'!K28 -> 27142.857 | R28: ='16'!K28 -> 27142.857 | S28: ='17'!K28 -> 26714.286 | T28: ='18'!K28 -> 27142.857 | U28: ='19'!K28 -> 27142.857 | V28: ='20'!K28 -> 27142.857 | W28: ='21'!K28 -> 27142.857 | X28: ='22'!K28 -> 27142.857 | Y28: ='23'!K28 -> 27142.857 | Z28: ='24'!K28 -> 27142.857 | AA28: ='25'!K28 -> 27142.857 | AB28: ='26'!K28 -> 27142.857 | AC28: ='27'!K28 -> 27142.857 | AD28: ='28'!K28 -> 27142.857 | AE28: ='29'!K28 -> 27142.857 | AF28: ='30'!K28 -> 27142.857 | AG28: ='31'!K28 -> 27142.857 | AI28: =AG28-C28 -> 428.57143 | AJ28: =AVERAGE(C28:AG28) -> 26995.392
B29: - Udang Segar (Uk. Sedang) | C29: ='01'!K29 -> 63285.714 | D29: ='02'!K29 -> 63714.286 | E29: ='03'!K29 -> 63285.714 | F29: ='04'!K29 -> 64714.286 | G29: ='05'!K29 -> 64714.286 | H29: ='06'!K29 -> 64714.286 | I29: ='07'!K29 -> 64714.286 | J29: ='08'!K29 -> 63285.714 | K29: ='09'!K29 -> 64714.286 | L29: ='10'!K29 -> 64714.286 | M29: ='11'!K29 -> 64714.286 | N29: ='12'!K29 -> 64714.286 | O29: ='13'!K29 -> 64714.286 | P29: ='14'!K29 -> 64714.286 | Q29: ='15'!K29 -> 64714.286 | R29: ='16'!K29 -> 64714.286 | S29: ='17'!K29 -> 64714.286 | T29: ='18'!K29 -> 64000 | U29: ='19'!K29 -> 64000 | V29: ='20'!K29 -> 64714.286 | W29: ='21'!K29 -> 64000 | X29: ='22'!K29 -> 64000 | Y29: ='23'!K29 -> 64000 | Z29: ='24'!K29 -> 64000 | AA29: ='25'!K29 -> 64000 | AB29: ='26'!K29 -> 64000 | AC29: ='27'!K29 -> 64000 | AD29: ='28'!K29 -> 64000 | AE29: ='29'!K29 -> 64000 | AF29: ='30'!K29 -> 64000 | AG29: ='31'!K29 -> 64000 | AI29: =AG29-C29 -> 714.28571 | AJ29: =AVERAGE(C29:AG29) -> 64244.24
B30: - Ikan Lele Segar (Ukuran Sedang) | C30: ='01'!K30 -> 24000 | D30: ='02'!K30 -> 23400 | E30: ='03'!K30 -> 24000 | F30: ='04'!K30 -> 24000 | G30: ='05'!K30 -> 24000 | H30: ='06'!K30 -> 24000 | I30: ='07'!K30 -> 24000 | J30: ='08'!K30 -> 24000 | K30: ='09'!K30 -> 24000 | L30: ='10'!K30 -> 24000 | M30: ='11'!K30 -> 24000 | N30: ='12'!K30 -> 24000 | O30: ='13'!K30 -> 24000 | P30: ='14'!K30 -> 24000 | Q30: ='15'!K30 -> 24000 | R30: ='16'!K30 -> 24000 | S30: ='17'!K30 -> 24000 | T30: ='18'!K30 -> 24000 | U30: ='19'!K30 -> 24000 | V30: ='20'!K30 -> 24000 | W30: ='21'!K30 -> 24000 | X30: ='22'!K30 -> 24000 | Y30: ='23'!K30 -> 24000 | Z30: ='24'!K30 -> 24000 | AA30: ='25'!K30 -> 24000 | AB30: ='26'!K30 -> 24000 | AC30: ='27'!K30 -> 24000 | AD30: ='28'!K30 -> 24000 | AE30: ='29'!K30 -> 24000 | AF30: ='30'!K30 -> 24000 | AG30: ='31'!K30 -> 24000 | AI30: =AG30-C30 -> 0 | AJ30: =AVERAGE(C30:AG30) -> 23980.645
B31: - Ikan Bandeng Segar (Uk. Sedang) | C31: ='01'!K31 -> 34000 | D31: ='02'!K31 -> 33714.286 | E31: ='03'!K31 -> 34000 | F31: ='04'!K31 -> 34428.571 | G31: ='05'!K31 -> 34428.571 | H31: ='06'!K31 -> 34428.571 | I31: ='07'!K31 -> 34428.571 | J31: ='08'!K31 -> 34428.571 | K31: ='09'!K31 -> 34428.571 | L31: ='10'!K31 -> 34428.571 | M31: ='11'!K31 -> 34428.571 | N31: ='12'!K31 -> 34428.571 | O31: ='13'!K31 -> 34428.571 | P31: ='14'!K31 -> 35285.714 | Q31: ='15'!K31 -> 35285.714 | R31: ='16'!K31 -> 35285.714 | S31: ='17'!K31 -> 35142.857 | T31: ='18'!K31 -> 34571.429 | U31: ='19'!K31 -> 35285.714 | V31: ='20'!K31 -> 35285.714 | W31: ='21'!K31 -> 34571.429 | X31: ='22'!K31 -> 34571.429 | Y31: ='23'!K31 -> 34571.429 | Z31: ='24'!K31 -> 34571.429 | AA31: ='25'!K31 -> 34571.429 | AB31: ='26'!K31 -> 34571.429 | AC31: ='27'!K31 -> 35000 | AD31: ='28'!K31 -> 34571.429 | AE31: ='29'!K31 -> 34571.429 | AF31: ='30'!K31 -> 34571.429 | AG31: ='31'!K31 -> 34571.429 | AI31: =AG31-C31 -> 571.42857 | AJ31: =AVERAGE(C31:AG31) -> 34608.295
B32: - Ikan Teri Asin (Bukan Teri Medan) | C32: ='01'!K32 -> 82500 | D32: ='02'!K32 -> 85000 | E32: ='03'!K32 -> 82500 | F32: ='04'!K32 -> 82500 | G32: ='05'!K32 -> 82500 | H32: ='06'!K32 -> 92500 | I32: ='07'!K32 -> 87500 | J32: ='08'!K32 -> 87500 | K32: ='09'!K32 -> 87500 | L32: ='10'!K32 -> 87500 | M32: ='11'!K32 -> 87500 | N32: ='12'!K32 -> 87500 | O32: ='13'!K32 -> 87500 | P32: ='14'!K32 -> 87500 | Q32: ='15'!K32 -> 87500 | R32: ='16'!K32 -> 87500 | S32: ='17'!K32 -> 87500 | T32: ='18'!K32 -> 87500 | U32: ='19'!K32 -> 87500 | V32: ='20'!K32 -> 87500 | W32: ='21'!K32 -> 87500 | X32: ='22'!K32 -> 87500 | Y32: ='23'!K32 -> 87500 | Z32: ='24'!K32 -> 87500 | AA32: ='25'!K32 -> 87500 | AB32: ='26'!K32 -> 87500 | AC32: ='27'!K32 -> 97500 | AD32: ='28'!K32 -> 87500 | AE32: ='29'!K32 -> 87500 | AF32: ='30'!K32 -> 87500 | AG32: ='31'!K32 -> 87500 | AI32: =AG32-C32 -> 5000 | AJ32: =AVERAGE(C32:AG32) -> 87258.065
A33: 7 | B33: TELUR | C33: ='01'!K33 -> 0 | D33: ='02'!K33 -> 0 | E33: ='03'!K33 -> 0 | F33: ='04'!K33 -> 0 | G33: ='05'!K33 -> 0 | H33: ='06'!K33 -> 0 | I33: ='07'!K33 -> 0 | J33: ='08'!K33 -> 0 | K33: ='09'!K33 -> 0 | L33: ='10'!K33 -> 0 | M33: ='11'!K33 -> 0 | N33: ='12'!K33 -> 0 | O33: ='13'!K33 -> 0 | P33: ='14'!K33 -> 0 | Q33: ='15'!K33 -> 0 | R33: ='16'!K33 -> 0 | S33: ='17'!K33 -> 0 | T33: ='18'!K33 -> 0 | U33: ='19'!K33 -> 0 | V33: ='20'!K33 -> 0 | W33: ='21'!K33 -> 0 | X33: ='22'!K33 -> 0 | Y33: ='23'!K33 -> 0 | Z33: ='24'!K33 -> 0 | AA33: ='25'!K33 -> 0 | AB33: ='26'!K33 -> 0 | AC33: ='27'!K33 -> 0 | AD33: ='28'!K33 -> 0 | AE33: ='29'!K33 -> 0 | AF33: ='30'!K33 -> 0 | AG33: ='31'!K33 -> 0 | AI33: =AG33-C33 -> 0 | AJ33: =AVERAGE(C33:AG33) -> 0
B34: - Telur Ayam Horn | C34: ='01'!K34 -> 29428.571 | D34: ='02'!K34 -> 29857.143 | E34: ='03'!K34 -> 29857.143 | F34: ='04'!K34 -> 29857.143 | G34: ='05'!K34 -> 30000 | H34: ='06'!K34 -> 30000 | I34: ='07'!K34 -> 29571.429 | J34: ='08'!K34 -> 29428.571 | K34: ='09'!K34 -> 29571.429 | L34: ='10'!K34 -> 29571.429 | M34: ='11'!K34 -> 29285.714 | N34: ='12'!K34 -> 29571.429 | O34: ='13'!K34 -> 29857.143 | P34: ='14'!K34 -> 29571.429 | Q34: ='15'!K34 -> 29428.571 | R34: ='16'!K34 -> 29142.857 | S34: ='17'!K34 -> 29142.857 | T34: ='18'!K34 -> 28785.714 | U34: ='19'!K34 -> 28214.286 | V34: ='20'!K34 -> 27857.143 | W34: ='21'!K34 -> 27285.714 | X34: ='22'!K34 -> 27285.714 | Y34: ='23'!K34 -> 27000 | Z34: ='24'!K34 -> 27000 | AA34: ='25'!K34 -> 26857.143 | AB34: ='26'!K34 -> 26857.143 | AC34: ='27'!K34 -> 26857.143 | AD34: ='28'!K34 -> 26571.429 | AE34: ='29'!K34 -> 26285.714 | AF34: ='30'!K34 -> 25857.143 | AG34: ='31'!K34 -> 25428.571 | AH34: 27000 | AI34: =AG34-C34 -> -4000 | AJ34: =AVERAGE(C34:AG34) -> 28428.571
B35: - Telur Ayam Kampung | C35: ='01'!K35 -> 2785.7143 | D35: ='02'!K35 -> 2714.2857 | E35: ='03'!K35 -> 2785.7143 | F35: ='04'!K35 -> 2785.7143 | G35: ='05'!K35 -> 2785.7143 | H35: ='06'!K35 -> 2785.7143 | I35: ='07'!K35 -> 2714.2857 | J35: ='08'!K35 -> 2714.2857 | K35: ='09'!K35 -> 2714.2857 | L35: ='10'!K35 -> 2714.2857 | M35: ='11'!K35 -> 2714.2857 | N35: ='12'!K35 -> 2714.2857 | O35: ='13'!K35 -> 2714.2857 | P35: ='14'!K35 -> 2714.2857 | Q35: ='15'!K35 -> 2714.2857 | R35: ='16'!K35 -> 2714.2857 | S35: ='17'!K35 -> 2714.2857 | T35: ='18'!K35 -> 2714.2857 | U35: ='19'!K35 -> 2714.2857 | V35: ='20'!K35 -> 2714.2857 | W35: ='21'!K35 -> 2714.2857 | X35: ='22'!K35 -> 2714.2857 | Y35: ='23'!K35 -> 2714.2857 | Z35: ='24'!K35 -> 2714.2857 | AA35: ='25'!K35 -> 2714.2857 | AB35: ='26'!K35 -> 2714.2857 | AC35: ='27'!K35 -> 2714.2857 | AD35: ='28'!K35 -> 2714.2857 | AE35: ='29'!K35 -> 2714.2857 | AF35: ='30'!K35 -> 2714.2857 | AG35: ='31'!K35 -> 2714.2857 | AI35: =AG35-C35 -> -71.428571 | AJ35: =AVERAGE(C35:AG35) -> 2725.8065
A36: 8 | B36: TAHU | C36: ='01'!K36 -> 0 | D36: ='02'!K36 -> 0 | E36: ='03'!K36 -> 0 | F36: ='04'!K36 -> 0 | G36: ='05'!K36 -> 0 | H36: ='06'!K36 -> 0 | I36: ='07'!K36 -> 0 | J36: ='08'!K36 -> 0 | K36: ='09'!K36 -> 0 | L36: ='10'!K36 -> 0 | M36: ='11'!K36 -> 0 | N36: ='12'!K36 -> 0 | O36: ='13'!K36 -> 0 | P36: ='14'!K36 -> 0 | Q36: ='15'!K36 -> 0 | R36: ='16'!K36 -> 0 | S36: ='17'!K36 -> 0 | T36: ='18'!K36 -> 0 | U36: ='19'!K36 -> 0 | V36: ='20'!K36 -> 0 | W36: ='21'!K36 -> 0 | X36: ='22'!K36 -> 0 | Y36: ='23'!K36 -> 0 | Z36: ='24'!K36 -> 0 | AA36: ='25'!K36 -> 0 | AB36: ='26'!K36 -> 0 | AC36: ='27'!K36 -> 0 | AD36: ='28'!K36 -> 0 | AE36: ='29'!K36 -> 0 | AF36: ='30'!K36 -> 0 | AG36: ='31'!K36 -> 0 | AI36: =AG36-C36 -> 0 | AJ36: =AVERAGE(C36:AG36) -> 0
B37: - Tahu biasa | C37: ='01'!K37 -> 10000 | D37: ='02'!K37 -> 10000 | E37: ='03'!K37 -> 10000 | F37: ='04'!K37 -> 10000 | G37: ='05'!K37 -> 10000 | H37: ='06'!K37 -> 10000 | I37: ='07'!K37 -> 10000 | J37: ='08'!K37 -> 10000 | K37: ='09'!K37 -> 10000 | L37: ='10'!K37 -> 10000 | M37: ='11'!K37 -> 9857.1429 | N37: ='12'!K37 -> 9857.1429 | O37: ='13'!K37 -> 9857.1429 | P37: ='14'!K37 -> 9857.1429 | Q37: ='15'!K37 -> 9857.1429 | R37: ='16'!K37 -> 9857.1429 | S37: ='17'!K37 -> 9857.1429 | T37: ='18'!K37 -> 9857.1429 | U37: ='19'!K37 -> 9857.1429 | V37: ='20'!K37 -> 9857.1429 | W37: ='21'!K37 -> 9857.1429 | X37: ='22'!K37 -> 9857.1429 | Y37: ='23'!K37 -> 9857.1429 | Z37: ='24'!K37 -> 9857.1429 | AA37: ='25'!K37 -> 9857.1429 | AB37: ='26'!K37 -> 9857.1429 | AC37: ='27'!K37 -> 9857.1429 | AD37: ='28'!K37 -> 9857.1429 | AE37: ='29'!K37 -> 9857.1429 | AF37: ='30'!K37 -> 9857.1429 | AG37: ='31'!K37 -> 9857.1429 | AI37: =AG37-C37 -> -142.85714 | AJ37: =AVERAGE(C37:AG37) -> 9903.2258
B38: - Tahu susu | C38: ='01'!K38 -> 12600 | D38: ='02'!K38 -> 13400 | E38: ='03'!K38 -> 12600 | F38: ='04'!K38 -> 12600 | G38: ='05'!K38 -> 12600 | H38: ='06'!K38 -> 12600 | I38: ='07'!K38 -> 12600 | J38: ='08'!K38 -> 12600 | K38: ='09'!K38 -> 12600 | L38: ='10'!K38 -> 12600 | M38: ='11'!K38 -> 13000 | N38: ='12'!K38 -> 12600 | O38: ='13'!K38 -> 12600 | P38: ='14'!K38 -> 12600 | Q38: ='15'!K38 -> 12600 | R38: ='16'!K38 -> 12600 | S38: ='17'!K38 -> 12600 | T38: ='18'!K38 -> 12600 | U38: ='19'!K38 -> 12600 | V38: ='20'!K38 -> 12600 | W38: ='21'!K38 -> 12600 | X38: ='22'!K38 -> 12600 | Y38: ='23'!K38 -> 12600 | Z38: ='24'!K38 -> 12600 | AA38: ='25'!K38 -> 12600 | AB38: ='26'!K38 -> 12600 | AC38: ='27'!K38 -> 12600 | AD38: ='28'!K38 -> 12600 | AE38: ='29'!K38 -> 12600 | AF38: ='30'!K38 -> 12600 | AG38: ='31'!K38 -> 12600 | AI38: =AG38-C38 -> 0 | AJ38: =AVERAGE(C38:AG38) -> 12638.71
A39: 9 | B39: TEMPE | C39: ='01'!K39 -> 0 | D39: ='02'!K39 -> 0 | E39: ='03'!K39 -> 0 | F39: ='04'!K39 -> 0 | G39: ='05'!K39 -> 0 | H39: ='06'!K39 -> 0 | I39: ='07'!K39 -> 0 | J39: ='08'!K39 -> 0 | K39: ='09'!K39 -> 0 | L39: ='10'!K39 -> 0 | M39: ='11'!K39 -> 0 | N39: ='12'!K39 -> 0 | O39: ='13'!K39 -> 0 | P39: ='14'!K39 -> 0 | Q39: ='15'!K39 -> 0 | R39: ='16'!K39 -> 0 | S39: ='17'!K39 -> 0 | T39: ='18'!K39 -> 0 | U39: ='19'!K39 -> 0 | V39: ='20'!K39 -> 0 | W39: ='21'!K39 -> 0 | X39: ='22'!K39 -> 0 | Y39: ='23'!K39 -> 0 | Z39: ='24'!K39 -> 0 | AA39: ='25'!K39 -> 0 | AB39: ='26'!K39 -> 0 | AC39: ='27'!K39 -> 0 | AD39: ='28'!K39 -> 0 | AE39: ='29'!K39 -> 0 | AF39: ='30'!K39 -> 0 | AG39: ='31'!K39 -> 0 | AI39: =AG39-C39 -> 0 | AJ39: =AVERAGE(C39:AG39) -> 0
B40: - Tempe Kw I (campuran kedelai) | C40: ='01'!K40 -> 13000 | D40: ='02'!K40 -> 12750 | E40: ='03'!K40 -> 13000 | F40: ='04'!K40 -> 13000 | G40: ='05'!K40 -> 13000 | H40: ='06'!K40 -> 13000 | I40: ='07'!K40 -> 13000 | J40: ='08'!K40 -> 13000 | K40: ='09'!K40 -> 13000 | L40: ='10'!K40 -> 13000 | M40: ='11'!K40 -> 13000 | N40: ='12'!K40 -> 13000 | O40: ='13'!K40 -> 13000 | P40: ='14'!K40 -> 13000 | Q40: ='15'!K40 -> 13000 | R40: ='16'!K40 -> 13000 | S40: ='17'!K40 -> 13000 | T40: ='18'!K40 -> 13000 | U40: ='19'!K40 -> 13000 | V40: ='20'!K40 -> 13000 | W40: ='21'!K40 -> 13000 | X40: ='22'!K40 -> 13000 | Y40: ='23'!K40 -> 13000 | Z40: ='24'!K40 -> 13000 | AA40: ='25'!K40 -> 13000 | AB40: ='26'!K40 -> 13000 | AC40: ='27'!K40 -> 13000 | AD40: ='28'!K40 -> 13000 | AE40: ='29'!K40 -> 13000 | AF40: ='30'!K40 -> 13000 | AG40: ='31'!K40 -> 13000 | AI40: =AG40-C40 -> 0 | AJ40: =AVERAGE(C40:AG40) -> 12991.935
B41: - Tempe Kw II (campuran jagung) | C41: ='01'!K41 -> 4250 | D41: ='02'!K41 -> 4250 | E41: ='03'!K41 -> 4250 | F41: ='04'!K41 -> 4250 | G41: ='05'!K41 -> 4250 | H41: ='06'!K41 -> 4250 | I41: ='07'!K41 -> 4250 | J41: ='08'!K41 -> 4250 | K41: ='09'!K41 -> 4250 | L41: ='10'!K41 -> 4250 | M41: ='11'!K41 -> 4250 | N41: ='12'!K41 -> 4250 | O41: ='13'!K41 -> 4250 | P41: ='14'!K41 -> 4250 | Q41: ='15'!K41 -> 4250 | R41: ='16'!K41 -> 4250 | S41: ='17'!K41 -> 4250 | T41: ='18'!K41 -> 4250 | U41: ='19'!K41 -> 4250 | V41: ='20'!K41 -> 4250 | W41: ='21'!K41 -> 4250 | X41: ='22'!K41 -> 4250 | Y41: ='23'!K41 -> 4250 | Z41: ='24'!K41 -> 4250 | AA41: ='25'!K41 -> 4250 | AB41: ='26'!K41 -> 4250 | AC41: ='27'!K41 -> 4250 | AD41: ='28'!K41 -> 4250 | AE41: ='29'!K41 -> 4250 | AF41: ='30'!K41 -> 4250 | AG41: ='31'!K41 -> 4250 | AI41: =AG41-C41 -> 0 | AJ41: =AVERAGE(C41:AG41) -> 4250
...

Sheet 01
A1: HARGA BAHAN-BAHAN POKOK
A2: DI PASAR TRADISIONAL KOTA SURABAYA
A3: Hari / Tanggal : Selasa , 01 Agustus 2023
B4: NAMA BAHAN POKOK DAN PENTING LAINNYA | C4: SATUAN | D4: Pasar Tambahrejo | E4: Pasar Pucang Anom | F4: Pasar Wonokromo | G4: Pasar Genteng Baru | H4: Pasar Pabean | I4: Pasar Kembang | J4: Pasar Balongsari | K4: Rata-Rata
A7: 1 | B7: BERAS
B8: - Beras Premium | C8: Kg | D8: 13000 | E8: 13000 | F8: 13000 | G8: 13000 | H8: 13000 | I8: 13000 | J8: 13000 | K8: =AVERAGE(D8:J8) -> 13000
B9: - Beras Medium Bulog | C9: Kg | D9: 9000 | E9: 9000 | F9: 9000 | G9: - | H9: - | I9: - | J9: - | K9: =AVERAGE(D9:J9) -> 9000
B10: - Beras Medium | C10: Kg | D10: - | E10: 10900 | F10: 10500 | G10: 10900 | H10: 12000 | I10: 10000 | J10: - | K10: =AVERAGE(D10:J10) -> 10860
B11: - Beras Jagung | C11: Kg | D11: - | E11: 10000 | F11: 12000 | G11: 10000 | H11: - | I11: 11000 | J11: 8000 | K11: =AVERAGE(D11:J11) -> 10200
B12: - Beras Ketan (Jenis Siyem) | C12: Kg | D12: - | E12: 21000 | F12: 17000 | G12: 20000 | H12: - | I12: 18000 | J12: 17000 | K12: =AVERAGE(D12:J12) -> 18600
A13: 2 | B13: GULA
B14: - Gula pasir lokal curah | C14: Kg | D14: 13500 | E14: 13000 | F14: 13500 | G14: 13000 | H14: 13500 | I14: 13500 | J14: 13500 | K14: =AVERAGE(D14:J14) -> 13357.143
B15: - Gula Jawa/Merah (Bahan Kelapa) | C15: Kg | D15: 15000 | E15: 16000 | F15: 15000 | G15: 14000 | H15: 15000 | I15: 16000 | J15: 16000 | K15: =AVERAGE(D15:J15) -> 15285.714
A16: 3 | B16: MINYAK GORENG
B17: - Minyak Goreng Curah (Bening) | C17: Kg | D17: 15000 | E17: 15000 | F17: 15000 | G17: 15000 | H17: 15000 | I17: 15000 | J17: 15000 | K17: =AVERAGE(D17:J17) -> 15000
B18: - Minyak Kita | C18: Liter | D18: 14000 | E18: 14000 | F18: 14000 | G18: 14000 | H18: - | I18: 14000 | J18: 14000 | K18: =AVERAGE(D18:J18) -> 14000
A19: 4 | B19: MENTEGA
B20: - Mentega Curah (Amanda) | C20: Kg | D20: 20000 | E20: - | F20: 20000 | G20: 22000 | H20: - | I20: 24000 | J20: - | K20: =AVERAGE(D20:J20) -> 21500
A21: 5 | B21: DAGING
B22: - Daging Sapi Grade Atas | C22: Kg | D22: 120000 | E22: 120000 | F22: 120000 | G22: 120000 | H22: 120000 | I22: 120000 | J22: - | K22: =AVERAGE(D22:J22) -> 120000
B23: - Daging Sapi Grade Sedang | C23: Kg | D23: 110000 | E23: 110000 | F23: 110000 | G23: 110000 | H23: 110000 | I23: 115000 | J23: 115000 | K23: =AVERAGE(D23:J23) -> 111428.57
B24: - Daging Sapi Grade Bawah | C24: Kg | D24: 90000 | E24: 95000 | F24: 105000 | G24: 105000 | H24: 100000 | I24: 100000 | J24: 105000 | K24: =AVERAGE(D24:J24) -> 100000
B25: - Daging Ayam Broiler | C25: Kg | D25: 35000 | E25: 33000 | F25: 35000 | G25: 34000 | H25: 35000 | I25: 35000 | J25: 35000 | K25: =AVERAGE(D25:J25) -> 34571.429
A26: 6 | B26: I K A N
B27: - Ikan Tongkol Segar (Uk. Sedang) | C27: Kg | D27: 35000 | E27: 36000 | F27: - | G27: 35000 | H27: 35000 | I27: 35000 | J27: 40000 | K27: =AVERAGE(D27:J27) -> 36000
B28: - Ikan Mujair Segar (Uk. Sedang) | C28: Kg | D28: 26000 | E28: 30000 | F28: 28000 | G28: 30000 | H28: 23000 | I28: 25000 | J28: 25000 | K28: =AVERAGE(D28:J28) -> 26714.286
B29: - Udang Segar (Uk. Sedang) | C29: Kg | D29: 60000 | E29: 60000 | F29: 60000 | G29: 70000 | H29: 68000 | I29: 60000 | J29: 65000 | K29: =AVERAGE(D29:J29) -> 63285.714
B30: - Ikan Lele Segar (Ukuran Sedang) | C30: Kg | D30: 25000 | E30: - | F30: - | G30: 25000 | H30: 23000 | I30: 21000 | J30: 26000 | K30: =AVERAGE(D30:J30) -> 24000
B31: - Ikan Bandeng Segar (Uk. Sedang) | C31: Kg | D31: 37000 | E31: 35000 | F31: 38000 | G31: 35000 | H31: 28000 | I31: 35000 | J31: 30000 | K31: =AVERAGE(D31:J31) -> 34000
B32: - Ikan Teri Asin (Bukan Teri Medan) | C32: Kg | D32: - | E32: 100000 | F32: 80000 | G32: - | H32: 80000 | I32: - | J32: 70000 | K32: =AVERAGE(D32:J32) -> 82500
A33: 7 | B33: TELUR
B34: - Telur Ayam Broiler | C34: Kg | D34: 30000 | E34: 30000 | F34: 27000 | G34: 30000 | H34: 30000 | I34: 29000 | J34: 30000 | K34: =AVERAGE(D34:J34) -> 29428.571
B35: - Telur Ayam Kampung | C35: Butir | D35: 3000 | E35: 3000 | F35: 2500 | G35: 2500 | H35: 2500 | I35: 3000 | J35: 3000 | K35: =AVERAGE(D35:J35) -> 2785.7143
A36: 8 | B36: TAHU
B37: - Tahu biasa | C37: Kg | D37: 10000 | E37: 10000 | F37: 9000 | G37: 9000 | H37: 16000 | I37: 7000 | J37: 9000 | K37: =AVERAGE(D37:J37) -> 10000
B38: - Tahu susu | C38: Kg | D38: - | E38: 10000 | F38: 12000 | G38: 14000 | H38: - | I38: 15000 | J38: 12000 | K38: =AVERAGE(D38:J38) -> 12600
A39: 9 | B39: TEMPE
B40: - Tempe Kw I (campuran kedelai) | C40: Kg | D40: - | E40: - | F40: - | G40: 16000 | H40: 14000 | I40: 7000 | J40: 15000 | K40: =AVERAGE(D40:J40) -> 13000
B41: - Tempe Kw II (campuran jagung) | C41: Kg | D41: 2500 | E41: - | F41: 6000 | G41: - | H41: - | I41: - | J41: - | K41: =AVERAGE(D41:J41) -> 4250
B42: - Tempe Kw III (campuran kulit) | C42: Kg | D42: - | E42: 2500 | F42: - | G42: - | H42: - | I42: - | J42: - | K42: =AVERAGE(D42:J42) -> 2500
...

Sheet 02
A1: HARGA BAHAN-BAHAN POKOK
A2: DI PASAR TRADISIONAL KOTA SURABAYA
A3: Hari / Tanggal : Rabu , 02 Agustus 2023
B4: NAMA BAHAN POKOK DAN PENTING LAINNYA | C4: SATUAN | D4: Pasar Tambahrejo | E4: Pasar Pucang Anom | F4: Pasar Wonokromo | G4: Pasar Genteng Baru | H4: Pasar Pabean | I4: Pasar Kembang | J4: Pasar Balongsari | K4: Rata-Rata
A7: 1 | B7: BERAS
B8: - Beras Premium | C8: Kg | D8: 13000 | E8: 13000 | F8: 13000 | G8: 13000 | H8: 13000 | I8: 13000 | J8: 13000 | K8: =AVERAGE(D8:J8) -> 13000
B9: - Beras Medium Bulog | C9: Kg | D9: 9000 | E9: 9000 | F9: 9000 | G9: - | H9: - | I9: - | J9: - | K9: =AVERAGE(D9:J9) -> 9000
B10: - Beras Medium | C10: Kg | D10: - | E10: 10900 | F10: 12000 | G10: 10900 | H10: 12000 | I10: 10000 | J10: 12000 | K10: =AVERAGE(D10:J10) -> 11300
B11: - Beras Jagung | C11: Kg | D11: - | E11: 10000 | F11: 12000 | G11: 10000 | H11: - | I11: 11000 | J11: - | K11: =AVERAGE(D11:J11) -> 10750
B12: - Beras Ketan (Jenis Siyem) | C12: Kg | D12: - | E12: 21000 | F12: 17000 | G12: 20000 | H12: - | I12: 18000 | J12: - | K12: =AVERAGE(D12:J12) -> 19000
A13: 2 | B13: GULA
B14: - Gula pasir lokal curah | C14: Kg | D14: 13500 | E14: 13000 | F14: 13500 | G14: 13000 | H14: 13500 | I14: 13500 | J14: 13500 | K14: =AVERAGE(D14:J14) -> 13357.143
B15: - Gula Jawa/Merah (Bahan Kelapa) | C15: Kg | D15: 15000 | E15: 16000 | F15: 15000 | G15: 14000 | H15: 15000 | I15: 16000 | J15: 15000 | K15: =AVERAGE(D15:J15) -> 15142.857
A16: 3 | B16: MINYAK GORENG
B17: - Minyak Goreng Curah (Bening) | C17: Kg | D17: 15000 | E17: 15000 | F17: 15000 | G17: 15000 | H17: 15000 | I17: 15000 | J17: 15000 | K17: =AVERAGE(D17:J17) -> 15000
B18: - Minyak Kita | C18: Liter | D18: 14000 | E18: 14000 | F18: 14000 | G18: 14000 | H18: - | I18: 14000 | J18: - | K18: =AVERAGE(D18:J18) -> 14000
A19: 4 | B19: MENTEGA
B20: - Mentega Curah (Amanda) | C20: Kg | D20: 20000 | E20: - | F20: 20000 | G20: 22000 | H20: - | I20: 24000 | J20: - | K20: =AVERAGE(D20:J20) -> 21500
A21: 5 | B21: DAGING
B22: - Daging Sapi Grade Atas | C22: Kg | D22: 120000 | E22: 120000 | F22: 120000 | G22: 120000 | H22: 120000 | I22: 120000 | J22: - | K22: =AVERAGE(D22:J22) -> 120000
B23: - Daging Sapi Grade Sedang | C23: Kg | D23: 110000 | E23: 110000 | F23: 110000 | G23: 110000 | H23: 110000 | I23: 115000 | J23: 110000 | K23: =AVERAGE(D23:J23) -> 110714.29
B24: - Daging Sapi Grade Bawah | C24: Kg | D24: 90000 | E24: 95000 | F24: 105000 | G24: 105000 | H24: 100000 | I24: 100000 | J24: 100000 | K24: =AVERAGE(D24:J24) -> 99285.714
B25: - Daging Ayam Broiler | C25: Kg | D25: 35000 | E25: 33000 | F25: 35000 | G25: 34000 | H25: 35000 | I25: 35000 | J25: 35000 | K25: =AVERAGE(D25:J25) -> 34571.429
A26: 6 | B26: I K A N
B27: - Ikan Tongkol Segar (Uk. Sedang) | C27: Kg | D27: 35000 | E27: 36000 | F27: - | G27: 35000 | H27: 35000 | I27: 35000 | J27: 35000 | K27: =AVERAGE(D27:J27) -> 35166.667
B28: - Ikan Mujair Segar (Uk. Sedang) | C28: Kg | D28: 26000 | E28: 30000 | F28: 28000 | G28: 30000 | H28: 23000 | I28: 25000 | J28: 23000 | K28: =AVERAGE(D28:J28) -> 26428.571
B29: - Udang Segar (Uk. Sedang) | C29: Kg | D29: 60000 | E29: 60000 | F29: 60000 | G29: 70000 | H29: 68000 | I29: 60000 | J29: 68000 | K29: =AVERAGE(D29:J29) -> 63714.286
B30: - Ikan Lele Segar (Ukuran Sedang) | C30: Kg | D30: 25000 | E30: - | F30: - | G30: 25000 | H30: 23000 | I30: 21000 | J30: 23000 | K30: =AVERAGE(D30:J30) -> 23400
B31: - Ikan Bandeng Segar (Uk. Sedang) | C31: Kg | D31: 37000 | E31: 35000 | F31: 38000 | G31: 35000 | H31: 28000 | I31: 35000 | J31: 28000 | K31: =AVERAGE(D31:J31) -> 33714.286
B32: - Ikan Teri Asin (Bukan Teri Medan) | C32: Kg | D32: - | E32: 100000 | F32: 80000 | G32: - | H32: 80000 | I32: - | J32: 80000 | K32: =AVERAGE(D32:J32) -> 85000
A33: 7 | B33: TELUR
B34: - Telur Ayam Broiler | C34: Kg | D34: 30000 | E34: 30000 | F34: 30000 | G34: 30000 | H34: 30000 | I34: 29000 | J34: 30000 | K34: =AVERAGE(D34:J34) -> 29857.143
B35: - Telur Ayam Kampung | C35: Butir | D35: 3000 | E35: 3000 | F35: 2500 | G35: 2500 | H35: 2500 | I35: 3000 | J35: 2500 | K35: =AVERAGE(D35:J35) -> 2714.2857
A36: 8 | B36: TAHU
B37: - Tahu biasa | C37: Kg | D37: 10000 | E37: 10000 | F37: 9000 | G37: 9000 | H37: 16000 | I37: 7000 | J37: 9000 | K37: =AVERAGE(D37:J37) -> 10000
B38: - Tahu susu | C38: Kg | D38: - | E38: 10000 | F38: 12000 | G38: 14000 | H38: - | I38: 15000 | J38: 16000 | K38: =AVERAGE(D38:J38) -> 13400
A39: 9 | B39: TEMPE
B40: - Tempe Kw I (campuran kedelai) | C40: Kg | D40: - | E40: - | F40: - | G40: 16000 | H40: 14000 | I40: 7000 | J40: 14000 | K40: =AVERAGE(D40:J40) -> 12750
B41: - Tempe Kw II (campuran jagung) | C41: Kg | D41: 2500 | E41: - | F41: 6000 | G41: - | H41: - | I41: - | J41: - | K41: =AVERAGE(D41:J41) -> 4250
B42: - Tempe Kw III (campuran kulit) | C42: Kg | D42: - | E42: 2500 | F42: - | G42: - | H42: - | I42: - | J42: - | K42: =AVERAGE(D42:J42) -> 2500
...

Sheet 03
A1: HARGA BAHAN-BAHAN POKOK
A2: DI PASAR TRADISIONAL KOTA SURABAYA
A3: Hari / Tanggal : Kamis , 03 Agustus 2023
B4: NAMA BAHAN POKOK DAN PENTING LAINNYA | C4: SATUAN | D4: Pasar Tambahrejo | E4: Pasar Pucang Anom | F4: Pasar Wonokromo | G4: Pasar Genteng Baru | H4: Pasar Pabean | I4: Pasar Kembang | J4: Pasar Balongsari | K4: Rata-Rata
A7: 1 | B7: BERAS
B8: - Beras Premium | C8: Kg | D8: 13000 | E8: 13000 | F8: 13000 | G8: 13000 | H8: 13000 | I8: 13000 | J8: 13000 | K8: =AVERAGE(D8:J8) -> 13000
B9: - Beras Medium Bulog | C9: Kg | D9: 9000 | E9: - | F9: 9000 | G9: - | H9: - | I9: - | J9: - | K9: =AVERAGE(D9:J9) -> 9000
B10: - Beras Medium | C10: Kg | D10: - | E10: 10900 | F10: 10500 | G10: 10900 | H10: 12000 | I10: 10000 | J10: - | K10: =AVERAGE(D10:J10) -> 10860
B11: - Beras Jagung | C11: Kg | D11: - | E11: 10000 | F11: 12000 | G11: 10000 | H11: - | I11: 11000 | J11: 8000 | K11: =AVERAGE(D11:J11) -> 10200
B12: - Beras Ketan (Jenis Siyem) | C12: Kg | D12: - | E12: 21000 | F12: 17000 | G12: 20000 | H12: - | I12: 18000 | J12: 17000 | K12: =AVERAGE(D12:J12) -> 18600
A13: 2 | B13: GULA
B14: - Gula pasir lokal curah | C14: Kg | D14: 13500 | E14: 13000 | F14: 13500 | G14: 13000 | H14: 13500 | I14: 13500 | J14: 13500 | K14: =AVERAGE(D14:J14) -> 13357.143
B15: - Gula Jawa/Merah (Bahan Kelapa) | C15: Kg | D15: 15000 | E15: 16000 | F15: 15000 | G15: 14000 | H15: 15000 | I15: 16000 | J15: 16000 | K15: =AVERAGE(D15:J15) -> 15285.714
A16: 3 | B16: MINYAK GORENG
B17: - Minyak Goreng Curah (Bening) | C17: Kg | D17: 15000 | E17: 15000 | F17: 15000 | G17: 15000 | H17: 15000 | I17: 15000 | J17: 15000 | K17: =AVERAGE(D17:J17) -> 15000
B18: - Minyak Kita | C18: Liter | D18: 14000 | E18: 14000 | F18: 14000 | G18: 14000 | H18: - | I18: 14000 | J18: 14000 | K18: =AVERAGE(D18:J18) -> 14000
A19: 4 | B19: MENTEGA
B20: - Mentega Curah (Amanda) | C20: Kg | D20: 20000 | E20: - | F20: 20000 | G20: 22000 | H20: - | I20: 24000 | J20: - | K20: =AVERAGE(D20:J20) -> 21500
A21: 5 | B21: DAGING
B22: - Daging Sapi Grade Atas | C22: Kg | D22: 120000 | E22: 120000 | F22: 120000 | G22: 120000 | H22: 120000 | I22: 120000 | J22: - | K22: =AVERAGE(D22:J22) -> 120000
B23: - Daging Sapi Grade Sedang | C23: Kg | D23: 110000 | E23: 110000 | F23: 110000 | G23: 110000 | H23: 110000 | I23: 115000 | J23: 110000 | K23: =AVERAGE(D23:J23) -> 110714.29
B24: - Daging Sapi Grade Bawah | C24: Kg | D24: 90000 | E24: 95000 | F24: 105000 | G24: 105000 | H24: 100000 | I24: 100000 | J24: 100000 | K24: =AVERAGE(D24:J24) -> 99285.714
B25: - Daging Ayam Broiler | C25: Kg | D25: 31000 | E25: 33000 | F25: 35000 | G25: 34000 | H25: 35000 | I25: 34000 | J25: 35000 | K25: =AVERAGE(D25:J25) -> 33857.143
A26: 6 | B26: I K A N
B27: - Ikan Tongkol Segar (Uk. Sedang) | C27: Kg | D27: 35000 | E27: 36000 | F27: - | G27: 35000 | H27: 35000 | I27: 35000 | J27: 40000 | K27: =AVERAGE(D27:J27) -> 36000
B28: - Ikan Mujair Segar (Uk. Sedang) | C28: Kg | D28: 26000 | E28: 30000 | F28: 28000 | G28: 30000 | H28: 23000 | I28: 25000 | J28: 25000 | K28: =AVERAGE(D28:J28) -> 26714.286
B29: - Udang Segar (Uk. Sedang) | C29: Kg | D29: 60000 | E29: 60000 | F29: 60000 | G29: 70000 | H29: 68000 | I29: 60000 | J29: 65000 | K29: =AVERAGE(D29:J29) -> 63285.714
B30: - Ikan Lele Segar (Ukuran Sedang) | C30: Kg | D30: 25000 | E30: - | F30: - | G30: 25000 | H30: 23000 | I30: 21000 | J30: 26000 | K30: =AVERAGE(D30:J30) -> 24000
B31: - Ikan Bandeng Segar (Uk. Sedang) | C31: Kg | D31: 37000 | E31: 35000 | F31: 38000 | G31: 35000 | H31: 28000 | I31: 35000 | J31: 30000 | K31: =AVERAGE(D31:J31) -> 34000
B32: - Ikan Teri Asin (Bukan Teri Medan) | C32: Kg | D32: - | E32: 100000 | F32: 80000 | G32: - | H32: 80000 | I32: - | J32: 70000 | K32: =AVERAGE(D32:J32) -> 82500
A33: 7 | B33: TELUR
B34: - Telur Ayam Broiler | C34: Kg | D34: 30000 | E34: 30000 | F34: 30000 | G34: 30000 | H34: 30000 | I34: 29000 | J34: 30000 | K34: =AVERAGE(D34:J34) -> 29857.143
B35: - Telur Ayam Kampung | C35: Butir | D35: 3000 | E35: 3000 | F35: 2500 | G35: 2500 | H35: 2500 | I35: 3000 | J35: 3000 | K35: =AVERAGE(D35:J35) -> 2785.7143
A36: 8 | B36: TAHU
B37: - Tahu biasa | C37: Kg | D37: 10000 | E37: 10000 | F37: 9000 | G37: 9000 | H37: 16000 | I37: 7000 | J37: 9000 | K37: =AVERAGE(D37:J37) -> 10000
B38: - Tahu susu | C38: Kg | D38: - | E38: 10000 | F38: 12000 | G38: 14000 | H38: - | I38: 15000 | J38: 12000 | K38: =AVERAGE(D38:J38) -> 12600
A39: 9 | B39: TEMPE
B40: - Tempe Kw I (campuran kedelai) | C40: Kg | D40: - | E40: - | F40: - | G40: 16000 | H40: 14000 | I40: 7000 | J40: 15000 | K40: =AVERAGE(D40:J40) -> 13000
B41: - Tempe Kw II (campuran jagung) | C41: Kg | D41: 2500 | E41: - | F41: 6000 | G41: - | H41: - | I41: - | J41: - | K41: =AVERAGE(D41:J41) -> 4250
B42: - Tempe Kw III (campuran kulit) | C42: Kg | D42: - | E42: 2500 | F42: - | G42: - | H42: - | I42: - | J42: - | K42: =AVERAGE(D42:J42) -> 2500
...

Sheet 04
A1: HARGA BAHAN-BAHAN POKOK
A2: DI PASAR TRADISIONAL KOTA SURABAYA
A3: Hari / Tanggal : Jumat, 04 Agustus 2023
B4: NAMA BAHAN POKOK DAN PENTING LAINNYA | C4: SATUAN | D4: Pasar Tambahrejo | E4: Pasar Pucang Anom | F4: Pasar Wonokromo | G4: Pasar Genteng Baru | H4: Pasar Pabean | I4: Pasar Kembang | J4: Pasar Balongsari | K4: Rata-Rata
A7: 1 | B7: BERAS
B8: - Beras Premium | C8: Kg | D8: 13000 | E8: 13000 | F8: 13000 | G8: 13000 | H8: 13000 | I8: 13000 | J8: 13000 | K8: =AVERAGE(D8:J8) -> 13000
B9: - Beras Medium Bulog | C9: Kg | D9: 9000 | E9: - | F9: 9000 | G9: - | H9: - | I9: - | J9: - | K9: =AVERAGE(D9:J9) -> 9000
B10: - Beras Medium | C10: Kg | D10: - | E10: 10900 | F10: 12000 | G10: 10900 | H10: 12000 | I10: 10000 | J10: - | K10: =AVERAGE(D10:J10) -> 11160
B11: - Beras Jagung | C11: Kg | D11: - | E11: 10000 | F11: 12000 | G11: 10000 | H11: - | I11: 11000 | J11: 8000 | K11: =AVERAGE(D11:J11) -> 10200
B12: - Beras Ketan (Jenis Siyem) | C12: Kg | D12: - | E12: 21000 | F12: 17000 | G12: 20000 | H12: - | I12: 18000 | J12: 17000 | K12: =AVERAGE(D12:J12) -> 18600
A13: 2 | B13: GULA
B14: - Gula pasir lokal curah | C14: Kg | D14: 13500 | E14: 13000 | F14: 13500 | G14: 13000 | H14: 13500 | I14: 13500 | J14: 13500 | K14: =AVERAGE(D14:J14) -> 13357.143
B15: - Gula Jawa/Merah (Bahan Kelapa) | C15: Kg | D15: 15000 | E15: 16000 | F15: 15000 | G15: 14000 | H15: 15000 | I15: 16000 | J15: 16000 | K15: =AVERAGE(D15:J15) -> 15285.714
A16: 3 | B16: MINYAK GORENG
B17: - Minyak Goreng Curah (Bening) | C17: Kg | D17: 15000 | E17: 15000 | F17: 15000 | G17: 15000 | H17: 15000 | I17: 15000 | J17: 15000 | K17: =AVERAGE(D17:J17) -> 15000
B18: - Minyak Kita | C18: Liter | D18: 14000 | E18: 14000 | F18: 14000 | G18: 14000 | H18: - | I18: 14000 | J18: 14000 | K18: =AVERAGE(D18:J18) -> 14000
A19: 4 | B19: MENTEGA
B20: - Mentega Curah (Amanda) | C20: Kg | D20: 20000 | E20: - | F20: 20000 | G20: 22000 | H20: - | I20: 24000 | J20: - | K20: =AVERAGE(D20:J20) -> 21500
A21: 5 | B21: DAGING
B22: - Daging Sapi Grade Atas | C22: Kg | D22: 120000 | E22: 120000 | F22: 120000 | G22: 120000 | H22: 120000 | I22: 120000 | J22: - | K22: =AVERAGE(D22:J22) -> 120000
B23: - Daging Sapi Grade Sedang | C23: Kg | D23: 110000 | E23: 110000 | F23: 110000 | G23: 110000 | H23: 110000 | I23: 115000 | J23: 110000 | K23: =AVERAGE(D23:J23) -> 110714.29
B24: - Daging Sapi Grade Bawah | C24: Kg | D24: 90000 | E24: 95000 | F24: 105000 | G24: 105000 | H24: 100000 | I24: 100000 | J24: 100000 | K24: =AVERAGE(D24:J24) -> 99285.714
B25: - Daging Ayam Broiler | C25: Kg | D25: 31000 | E25: 33000 | F25: 34000 | G25: 34000 | H25: 35000 | I25: 34000 | J25: 35000 | K25: =AVERAGE(D25:J25) -> 33714.286
A26: 6 | B26: I K A N
B27: - Ikan Tongkol Segar (Uk. Sedang) | C27: Kg | D27: 35000 | E27: 36000 | F27: - | G27: 35000 | H27: 35000 | I27: 35000 | J27: 40000 | K27: =AVERAGE(D27:J27) -> 36000
B28: - Ikan Mujair Segar (Uk. Sedang) | C28: Kg | D28: 26000 | E28: 30000 | F28: 30000 | G28: 30000 | H28: 23000 | I28: 25000 | J28: 25000 | K28: =AVERAGE(D28:J28) -> 27000
B29: - Udang Segar (Uk. Sedang) | C29: Kg | D29: 60000 | E29: 60000 | F29: 70000 | G29: 70000 | H29: 68000 | I29: 60000 | J29: 65000 | K29: =AVERAGE(D29:J29) -> 64714.286
B30: - Ikan Lele Segar (Ukuran Sedang) | C30: Kg | D30: 25000 | E30: - | F30: - | G30: 25000 | H30: 23000 | I30: 21000 | J30: 26000 | K30: =AVERAGE(D30:J30) -> 24000
B31: - Ikan Bandeng Segar (Uk. Sedang) | C31: Kg | D31: 37000 | E31: 36000 | F31: 40000 | G31: 35000 | H31: 28000 | I31: 35000 | J31: 30000 | K31: =AVERAGE(D31:J31) -> 34428.571
B32: - Ikan Teri Asin (Bukan Teri Medan) | C32: Kg | D32: - | E32: 100000 | F32: 80000 | G32: - | H32: 80000 | I32: - | J32: 70000 | K32: =AVERAGE(D32:J32) -> 82500
A33: 7 | B33: TELUR
B34: - Telur Ayam Broiler | C34: Kg | D34: 30000 | E34: 30000 | F34: 30000 | G34: 30000 | H34: 30000 | I34: 29000 | J34: 30000 | K34: =AVERAGE(D34:J34) -> 29857.143
B35: - Telur Ayam Kampung | C35: Butir | D35: 3000 | E35: 3000 | F35: 2500 | G35: 2500 | H35: 2500 | I35: 3000 | J35: 3000 | K35: =AVERAGE(D35:J35) -> 2785.7143
A36: 8 | B36: TAHU
B37: - Tahu biasa | C37: Kg | D37: 10000 | E37: 10000 | F37: 9000 | G37: 9000 | H37: 16000 | I37: 7000 | J37: 9000 | K37: =AVERAGE(D37:J37) -> 10000
B38: - Tahu susu | C38: Kg | D38: - | E38: 10000 | F38: 12000 | G38: 14000 | H38: - | I38: 15000 | J38: 12000 | K38: =AVERAGE(D38:J38) -> 12600
A39: 9 | B39: TEMPE
B40: - Tempe Kw I (campuran kedelai) | C40: Kg | D40: - | E40: - | F40: - | G40: 16000 | H40: 14000 | I40: 7000 | J40: 15000 | K40: =AVERAGE(D40:J40) -> 13000
B41: - Tempe Kw II (campuran jagung) | C41: Kg | D41: 2500 | E41: - | F41: 6000 | G41: - | H41: - | I41: - | J41: - | K41: =AVERAGE(D41:J41) -> 4250
B42: - Tempe Kw III (campuran kulit) | C42: Kg | D42: - | E42: 2500 | F42: - | G42: - | H42: - | I42: - | J42: - | K42: =AVERAGE(D42:J42) -> 2500
...

Sheet 05
A1: HARGA BAHAN-BAHAN POKOK
A2: DI PASAR TRADISIONAL KOTA SURABAYA
A3: Hari / Tanggal : Sabtu, 05 Agustus 2023
B4: NAMA BAHAN POKOK DAN PENTING LAINNYA | C4: SATUAN | D4: Pasar Tambahrejo | E4: Pasar Pucang Anom | F4: Pasar Wonokromo | G4: Pasar Genteng Baru | H4: Pasar Pabean | I4: Pasar Kembang | J4: Pasar Balongsari | K4: Rata-Rata
A7: 1 | B7: BERAS
B8: - Beras Premium | C8: Kg | D8: 13000 | E8: 13000 | F8: 14000 | G8: 13000 | H8: 13000 | I8: 13000 | J8: 13000 | K8: =AVERAGE(D8:J8) -> 13142.857
B9: - Beras Medium Bulog | C9: Kg | D9: 9000 | E9: - | F9: 9400 | G9: - | H9: - | I9: - | J9: - | K9: =AVERAGE(D9:J9) -> 9200
B10: - Beras Medium | C10: Kg | D10: - | E10: 10900 | F10: 13500 | G10: 10900 | H10: 12000 | I10: 10000 | J10: - | K10: =AVERAGE(D10:J10) -> 11460
B11: - Beras Jagung | C11: Kg | D11: - | E11: 10000 | F11: 12000 | G11: 10000 | H11: - | I11: 11000 | J11: 8000 | K11: =AVERAGE(D11:J11) -> 10200
B12: - Beras Ketan (Jenis Siyem) | C12: Kg | D12: - | E12: 21000 | F12: 18000 | G12: 20000 | H12: - | I12: 18000 | J12: 17000 | K12: =AVERAGE(D12:J12) -> 18800
A13: 2 | B13: GULA
B14: - Gula pasir lokal curah | C14: Kg | D14: 13500 | E14: 13000 | F14: 13500 | G14: 13000 | H14: 13500 | I14: 13500 | J14: 13500 | K14: =AVERAGE(D14:J14) -> 13357.143
B15: - Gula Jawa/Merah (Bahan Kelapa) | C15: Kg | D15: 15000 | E15: 16000 | F15: 18000 | G15: 14000 | H15: 15000 | I15: 16000 | J15: 16000 | K15: =AVERAGE(D15:J15) -> 15714.286
A16: 3 | B16: MINYAK GORENG
B17: - Minyak Goreng Curah (Bening) | C17: Kg | D17: 15000 | E17: 15000 | F17: 17000 | G17: 15000 | H17: 15000 | I17: 15000 | J17: 15000 | K17: =AVERAGE(D17:J17) -> 15285.714
B18: - Minyak Kita | C18: Liter | D18: 14000 | E18: 14000 | F18: 14000 | G18: 14000 | H18: - | I18: 14000 | J18: 14000 | K18: =AVERAGE(D18:J18) -> 14000
A19: 4 | B19: MENTEGA
B20: - Mentega Curah (Amanda) | C20: Kg | D20: 20000 | E20: - | F20: 20000 | G20: 22000 | H20: - | I20: 24000 | J20: - | K20: =AVERAGE(D20:J20) -> 21500
A21: 5 | B21: DAGING
B22: - Daging Sapi Grade Atas | C22: Kg | D22: 120000 | E22: 120000 | F22: 115000 | G22: 120000 | H22: 120000 | I22: 120000 | J22: - | K22: =AVERAGE(D22:J22) -> 119166.67
B23: - Daging Sapi Grade Sedang | C23: Kg | D23: 110000 | E23: 110000 | F23: 110000 | G23: 110000 | H23: 110000 | I23: 115000 | J23: 110000 | K23: =AVERAGE(D23:J23) -> 110714.29
B24: - Daging Sapi Grade Bawah | C24: Kg | D24: 90000 | E24: 95000 | F24: 100000 | G24: 105000 | H24: 100000 | I24: 100000 | J24: 100000 | K24: =AVERAGE(D24:J24) -> 98571.429
B25: - Daging Ayam Broiler | C25: Kg | D25: 31000 | E25: 33000 | F25: 34000 | G25: 33000 | H25: 35000 | I25: 35000 | J25: 35000 | K25: =AVERAGE(D25:J25) -> 33714.286
A26: 6 | B26: I K A N
B27: - Ikan Tongkol Segar (Uk. Sedang) | C27: Kg | D27: 35000 | E27: 36000 | F27: - | G27: 35000 | H27: 35000 | I27: 35000 | J27: 40000 | K27: =AVERAGE(D27:J27) -> 36000
B28: - Ikan Mujair Segar (Uk. Sedang) | C28: Kg | D28: 26000 | E28: 30000 | F28: 30000 | G28: 30000 | H28: 23000 | I28: 25000 | J28: 25000 | K28: =AVERAGE(D28:J28) -> 27000
B29: - Udang Segar (Uk. Sedang) | C29: Kg | D29: 60000 | E29: 60000 | F29: 70000 | G29: 70000 | H29: 68000 | I29: 60000 | J29: 65000 | K29: =AVERAGE(D29:J29) -> 64714.286
B30: - Ikan Lele Segar (Ukuran Sedang) | C30: Kg | D30: 25000 | E30: - | F30: - | G30: 25000 | H30: 23000 | I30: 21000 | J30: 26000 | K30: =AVERAGE(D30:J30) -> 24000
B31: - Ikan Bandeng Segar (Uk. Sedang) | C31: Kg | D31: 37000 | E31: 36000 | F31: 40000 | G31: 35000 | H31: 28000 | I31: 35000 | J31: 30000 | K31: =AVERAGE(D31:J31) -> 34428.571
B32: - Ikan Teri Asin (Bukan Teri Medan) | C32: Kg | D32: - | E32: 100000 | F32: 80000 | G32: - | H32: 80000 | I32: - | J32: 70000 | K32: =AVERAGE(D32:J32) -> 82500
A33: 7 | B33: TELUR
B34: - Telur Ayam Broiler | C34: Kg | D34: 30000 | E34: 30000 | F34: 31000 | G34: 30000 | H34: 30000 | I34: 29000 | J34: 30000 | K34: =AVERAGE(D34:J34) -> 30000
B35: - Telur Ayam Kampung | C35: Butir | D35: 3000 | E35: 3000 | F35: 2500 | G35: 2500 | H35: 2500 | I35: 3000 | J35: 3000 | K35: =AVERAGE(D35:J35) -> 2785.7143
A36: 8 | B36: TAHU
B37: - Tahu biasa | C37: Kg | D37: 10000 | E37: 10000 | F37: 9000 | G37: 9000 | H37: 16000 | I37: 7000 | J37: 9000 | K37: =AVERAGE(D37:J37) -> 10000
B38: - Tahu susu | C38: Kg | D38: - | E38: 10000 | F38: 12000 | G38: 14000 | H38: - | I38: 15000 | J38: 12000 | K38: =AVERAGE(D38:J38) -> 12600
A39: 9 | B39: TEMPE
B40: - Tempe Kw I (campuran kedelai) | C40: Kg | D40: - | E40: - | F40: - | G40: 16000 | H40: 14000 | I40: 7000 | J40: 15000 | K40: =AVERAGE(D40:J40) -> 13000
B41: - Tempe Kw II (campuran jagung) | C41: Kg | D41: 2500 | E41: - | F41: 6000 | G41: - | H41: - | I41: - | J41: - | K41: =AVERAGE(D41:J41) -> 4250
B42: - Tempe Kw III (campuran kulit) | C42: Kg | D42: - | E42: 2500 | F42: - | G42: - | H42: - | I42: - | J42: - | K42: =AVERAGE(D42:J42) -> 2500
...

Sheet 06
A1: HARGA BAHAN-BAHAN POKOK
A2: DI PASAR TRADISIONAL KOTA SURABAYA
A3: Hari / Tanggal : Minggu , 06 Agustus 2023
B4: NAMA BAHAN POKOK DAN PENTING LAINNYA | C4: SATUAN | D4: Pasar Tambahrejo | E4: Pasar Pucang Anom | F4: Pasar Wonokromo | G4: Pasar Genteng Baru | H4: Pasar Pabean | I4: Pasar Kembang | J4: Pasar Balongsari | K4: Rata-Rata
A7: 1 | B7: BERAS
B8: - Beras Premium | C8: Kg | D8: 13000 | E8: 13000 | F8: 14000 | G8: 13000 | H8: 13000 | I8: 13000 | J8: 13000 | K8: =AVERAGE(D8:J8) -> 13142.857
B9: - Beras Medium Bulog | C9: Kg | D9: 9000 | E9: - | F9: 9400 | G9: - | H9: - | I9: - | J9: - | K9: =AVERAGE(D9:J9) -> 9200
B10: - Beras Medium | C10: Kg | D10: - | E10: 10900 | F10: 11000 | G10: 10900 | H10: 12000 | I10: 10000 | J10: - | K10: =AVERAGE(D10:J10) -> 10960
B11: - Beras Jagung | C11: Kg | D11: - | E11: 10000 | F11: 12000 | G11: 10000 | H11: - | I11: 11000 | J11: 8000 | K11: =AVERAGE(D11:J11) -> 10200
B12: - Beras Ketan (Jenis Siyem) | C12: Kg | D12: - | E12: 21000 | F12: 18000 | G12: 20000 | H12: - | I12: 18000 | J12: 17000 | K12: =AVERAGE(D12:J12) -> 18800
A13: 2 | B13: GULA
B14: - Gula pasir lokal curah | C14: Kg | D14: 13500 | E14: 13000 | F14: 13500 | G14: 13000 | H14: 13500 | I14: 13500 | J14: 13500 | K14: =AVERAGE(D14:J14) -> 13357.143
B15: - Gula Jawa/Merah (Bahan Kelapa) | C15: Kg | D15: 15000 | E15: 16000 | F15: 18000 | G15: 14000 | H15: 15000 | I15: 16000 | J15: 16000 | K15: =AVERAGE(D15:J15) -> 15714.286
A16: 3 | B16: MINYAK GORENG
B17: - Minyak Goreng Curah (Bening) | C17: Kg | D17: 15000 | E17: 15000 | F17: 17000 | G17: 15000 | H17: 15000 | I17: 15000 | J17: 15000 | K17: =AVERAGE(D17:J17) -> 15285.714
B18: - Minyak Kita | C18: Liter | D18: 14000 | E18: 14000 | F18: 14000 | G18: 14000 | H18: - | I18: 14000 | J18: 14000 | K18: =AVERAGE(D18:J18) -> 14000
A19: 4 | B19: MENTEGA
B20: - Mentega Curah (Amanda) | C20: Kg | D20: 20000 | E20: - | F20: 20000 | G20: 22000 | H20: - | I20: 24000 | J20: - | K20: =AVERAGE(D20:J20) -> 21500
A21: 5 | B21: DAGING
B22: - Daging Sapi Grade Atas | C22: Kg | D22: 120000 | E22: 120000 | F22: 115000 | G22: 120000 | H22: 120000 | I22: 120000 | J22: - | K22: =AVERAGE(D22:J22) -> 119166.67
B23: - Daging Sapi Grade Sedang | C23: Kg | D23: 110000 | E23: 110000 | F23: 110000 | G23: 110000 | H23: 110000 | I23: 115000 | J23: 110000 | K23: =AVERAGE(D23:J23) -> 110714.29
B24: - Daging Sapi Grade Bawah | C24: Kg | D24: 90000 | E24: 95000 | F24: 100000 | G24: 105000 | H24: 100000 | I24: 100000 | J24: 100000 | K24: =AVERAGE(D24:J24) -> 98571.429
B25: - Daging Ayam Broiler | C25: Kg | D25: 31000 | E25: 33000 | F25: 34000 | G25: 33000 | H25: 35000 | I25: 35000 | J25: 35000 | K25: =AVERAGE(D25:J25) -> 33714.286
A26: 6 | B26: I K A N
B27: - Ikan Tongkol Segar (Uk. Sedang) | C27: Kg | D27: 35000 | E27: 36000 | F27: - | G27: 35000 | H27: 35000 | I27: 35000 | J27: 40000 | K27: =AVERAGE(D27:J27) -> 36000
B28: - Ikan Mujair Segar (Uk. Sedang) | C28: Kg | D28: 26000 | E28: 30000 | F28: 30000 | G28: 30000 | H28: 23000 | I28: 25000 | J28: 25000 | K28: =AVERAGE(D28:J28) -> 27000
B29: - Udang Segar (Uk. Sedang) | C29: Kg | D29: 60000 | E29: 60000 | F29: 70000 | G29: 70000 | H29: 68000 | I29: 60000 | J29: 65000 | K29: =AVERAGE(D29:J29) -> 64714.286
B30: - Ikan Lele Segar (Ukuran Sedang) | C30: Kg | D30: 25000 | E30: - | F30: - | G30: 25000 | H30: 23000 | I30: 21000 | J30: 26000 | K30: =AVERAGE(D30:J30) -> 24000
B31: - Ikan Bandeng Segar (Uk. Sedang) | C31: Kg | D31: 37000 | E31: 36000 | F31: 40000 | G31: 35000 | H31: 28000 | I31: 35000 | J31: 30000 | K31: =AVERAGE(D31:J31) -> 34428.571
B32: - Ikan Teri Asin (Bukan Teri Medan) | C32: Kg | D32: - | E32: 100000 | F32: 120000 | G32: - | H32: 80000 | I32: - | J32: 70000 | K32: =AVERAGE(D32:J32) -> 92500
A33: 7 | B33: TELUR
B34: - Telur Ayam Broiler | C34: Kg | D34: 30000 | E34: 30000 | F34: 31000 | G34: 30000 | H34: 30000 | I34: 29000 | J34: 30000 | K34: =AVERAGE(D34:J34) -> 30000
