Workbook

Sheet REKAPITULASI
A1: BAGIAN PEREKONOMIAN DAN SUMBER DAYA ALAM
A2: LAPORAN HARGA BAHAN POKOK DI KOTA SURABAYA
A3: PERIODE NOVEMBER 2023
B4: NAMA BAHAN POKOK DAN PENTING LAINNYA | C4: SAT | AH4: HET/HAPK (Harga Eceran Tertinggi) | AI4: FLUKTUASI
D5: 1 | E5: 2 | F5: 3 | G5: 4 | H5: 5 | I5: 6 | J5: 7 | K5: 8 | L5: 9 | M5: 10 | N5: 11 | O5: 12 | P5: 13 | Q5: 14 | R5: 15 | S5: 16 | T5: 17 | U5: 18 | V5: 19 | W5: 20 | X5: 21 | Y5: 22 | Z5: 23 | AA5: 24 | AB5: 25 | AC5: 26 | AD5: 27 | AE5: 28 | AF5: 29 | AG5: 30
A7: 1 | B7: BERAS
B8: - Beras Premium | C8: Kg | D8: ='1'!K8 -> 13714.286 | E8: ='2'!K8 -> 13714.286 | F8: ='3'!K8 -> 14142.857 | G8: ='4'!K8 -> 14142.857 | H8: ='5'!K8 -> 14142.857 | I8: ='6'!K8 -> 14142.857 | J8: ='7'!K8 -> 14142.857 | K8: ='8'!K8 -> 14142.857 | L8: ='9'!K8 -> 14100 | M8: ='10'!K8 -> 14114.286 | N8: ='11'!K8 -> 13971.429 | O8: ='12'!K8 -> 13971.429 | P8: ='13'!K8 -> 13971.429 | Q8: ='14'!K8 -> 13971.429 | R8: ='15'!K8 -> 13985.714 | S8: ='14'!K8 -> 13971.429 | T8: ='17'!K8 -> 13985.714 | U8: ='18'!K8 -> 13985.714 | V8: ='19'!K8 -> 13985.714 | W8: ='20'!K8 -> 13985.714 | X8: ='21'!K8 -> 13985.714 | Y8: ='22'!K8 -> 13985.714 | Z8: ='23'!K8 -> 13985.714 | AA8: ='24'!K8 -> 13985.714 | AB8: ='25'!K8 -> 13985.714 | AC8: ='26'!K8 -> 13985.714 | AD8: ='27'!K8 -> 13985.714 | AE8: ='28'!K8 -> 13985.714 | AF8: ='29'!K8 -> 14128.571 | AG8: ='30'!K8 -> 14128.571 | AH8: 12800 | AI8: =AG8-D8 -> 414.28571 | AJ8: =AVERAGE(D8:AG8) -> 14014.286
B9: - Beras IR.64 Medium Bulog | C9: KG | D9: ='1'!K9 -> 10916.667 | E9: ='2'!K9 -> 10916.667 | F9: ='3'!K9 -> 10916.667 | G9: ='4'!K9 -> 10916.667 | H9: ='5'!K9 -> 10916.667 | I9: ='6'!K9 -> 10916.667 | J9: ='7'!K9 -> 10916.667 | K9: ='8'!K9 -> 10916.667 | L9: ='9'!K9 -> 10916.667 | M9: ='10'!K9 -> 10900 | N9: ='11'!K9 -> 10900 | O9: ='12'!K9 -> 10900 | P9: ='13'!K9 -> 10900 | Q9: ='14'!K9 -> 10900 | R9: ='15'!K9 -> 10900 | S9: ='14'!K9 -> 10900 | T9: ='17'!K9 -> 10900 | U9: ='18'!K9 -> 10900 | V9: ='19'!K9 -> 10900 | W9: ='20'!K9 -> 10900 | X9: ='21'!K9 -> 10900 | Y9: ='22'!K9 -> 10900 | Z9: ='23'!K9 -> 10900 | AA9: ='24'!K9 -> 10900 | AB9: ='25'!K9 -> 10900 | AC9: ='26'!K9 -> 10900 | AD9: ='27'!K9 -> 10900 | AE9: ='28'!K9 -> 10900 | AF9: ='29'!K9 -> 10900 | AG9: ='30'!K9 -> 10900 | AI9: =AG9-D9 -> -16.666667 | AJ9: =AVERAGE(D9:AG9) -> 10905
B10: - Beras IR.64 Medium | C10: Kg | D10: ='1'!K10 -> 0 | E10: ='2'!K10 -> 0 | F10: ='3'!K10 -> 0 | G10: ='4'!K10 -> 0 | H10: ='5'!K10 -> 0 | I10: ='6'!K10 -> 0 | J10: ='7'!K10 -> 0 | K10: ='8'!K10 -> 0 | L10: ='9'!K10 -> 0 | M10: ='10'!K10 -> 0 | N10: ='11'!K10 -> 0 | O10: ='12'!K10 -> 0 | P10: ='13'!K10 -> 0 | Q10: ='14'!K10 -> 0 | R10: ='15'!K10 -> 0 | S10: ='14'!K10 -> 0 | T10: ='17'!K10 -> 0 | U10: ='18'!K10 -> 0 | V10: ='19'!K10 -> 0 | W10: ='20'!K10 -> 0 | X10: ='21'!K10 -> 0 | Y10: ='22'!K10 -> 0 | Z10: ='23'!K10 -> 0 | AA10: ='24'!K10 -> 0 | AB10: ='25'!K10 -> 0 | AC10: ='26'!K10 -> 0 | AD10: ='27'!K10 -> 0 | AE10: ='28'!K10 -> 0 | AF10: ='29'!K10 -> 0 | AG10: ='30'!K10 -> 0 | AH10: 9450 | AI10: =AG10-D10 -> 0 | AJ10: =AVERAGE(D10:AG10) -> 0
B11: - Beras Jagung | C11: Kg | D11: ='1'!K11 -> 10400 | E11: ='2'!K11 -> 10400 | F11: ='3'!K11 -> 10400 | G11: ='4'!K11 -> 10400 | H11: ='5'!K11 -> 10400 | I11: ='6'!K11 -> 10400 | J11: ='7'!K11 -> 10400 | K11: ='8'!K11 -> 10400 | L11: ='9'!K11 -> 10400 | M11: ='10'!K11 -> 10400 | N11: ='11'!K11 -> 10400 | O11: ='12'!K11 -> 10400 | P11: ='13'!K11 -> 10400 | Q11: ='14'!K11 -> 10000 | R11: ='15'!K11 -> 10000 | S11: ='14'!K11 -> 10000 | T11: ='17'!K11 -> 10000 | U11: ='18'!K11 -> 10000 | V11: ='19'!K11 -> 10400 | W11: ='20'!K11 -> 10400 | X11: ='21'!K11 -> 10400 | Y11: ='22'!K11 -> 10400 | Z11: ='23'!K11 -> 10400 | AA11: ='24'!K11 -> 10400 | AB11: ='25'!K11 -> 10400 | AC11: ='26'!K11 -> 10400 | AD11: ='27'!K11 -> 10400 | AE11: ='28'!K11 -> 10400 | AF11: ='29'!K11 -> 10400 | AG11: ='30'!K11 -> 10400 | AI11: =AG11-D11 -> 0 | AJ11: =AVERAGE(D11:AG11) -> 10333.333
B12: - Beras Ketan (Jenis Siyem) | C12: Kg | D12: ='1'!K12 -> 18400 | E12: ='2'!K12 -> 18400 | F12: ='3'!K12 -> 18400 | G12: ='4'!K12 -> 18400 | H12: ='5'!K12 -> 18400 | I12: ='6'!K12 -> 18400 | J12: ='7'!K12 -> 17400 | K12: ='8'!K12 -> 17750 | L12: ='9'!K12 -> 17750 | M12: ='10'!K12 -> 17750 | N12: ='11'!K12 -> 17750 | O12: ='12'!K12 -> 17750 | P12: ='13'!K12 -> 17750 | Q12: ='14'!K12 -> 18000 | R12: ='15'!K12 -> 18750 | S12: ='14'!K12 -> 18000 | T12: ='17'!K12 -> 19000 | U12: ='18'!K12 -> 19000 | V12: ='19'!K12 -> 18400 | W12: ='20'!K12 -> 18400 | X12: ='21'!K12 -> 18400 | Y12: ='22'!K12 -> 18400 | Z12: ='23'!K12 -> 18400 | AA12: ='24'!K12 -> 18400 | AB12: ='25'!K12 -> 18400 | AC12: ='26'!K12 -> 18400 | AD12: ='27'!K12 -> 18400 | AE12: ='28'!K12 -> 18400 | AF12: ='29'!K12 -> 18400 | AG12: ='30'!K12 -> 18400 | AI12: =AG12-D12 -> 0 | AJ12: =AVERAGE(D12:AG12) -> 18261.667
A13: 2 | B13: GULA | D13: ='1'!K13 -> 0 | E13: ='2'!K13 -> 0 | F13: ='3'!K13 -> 0 | G13: ='4'!K13 -> 0 | H13: ='5'!K13 -> 0 | I13: ='6'!K13 -> 0 | J13: ='7'!K13 -> 0 | K13: ='8'!K13 -> 0 | L13: ='9'!K13 -> 0 | M13: ='10'!K13 -> 0 | N13: ='11'!K13 -> 0 | O13: ='12'!K13 -> 0 | P13: ='13'!K13 -> 0 | Q13: ='14'!K13 -> 0 | R13: ='15'!K13 -> 0 | S13: ='14'!K13 -> 0 | T13: ='17'!K13 -> 0 | U13: ='18'!K13 -> 0 | V13: ='19'!K13 -> 0 | W13: ='20'!K13 -> 0 | X13: ='21'!K13 -> 0 | Y13: ='22'!K13 -> 0 | Z13: ='23'!K13 -> 0 | AA13: ='24'!K13 -> 0 | AB13: ='25'!K13 -> 0 | AC13: ='26'!K13 -> 0 | AD13: ='27'!K13 -> 0 | AE13: ='28'!K13 -> 0 | AF13: ='29'!K13 -> 0 | AG13: ='30'!K13 -> 0 | AI13: =AG13-D13 -> 0 | AJ13: =AVERAGE(D13:AG13) -> 0
B14: Gula Pasir Lokal Curah | C14: Kg | D14: ='1'!K14 -> 14642.857 | E14: ='2'!K14 -> 14642.857 | F14: ='3'!K14 -> 15071.429 | G14: ='4'!K14 -> 15285.714 | H14: ='5'!K14 -> 15142.857 | I14: ='6'!K14 -> 15285.714 | J14: ='7'!K14 -> 15214.286 | K14: ='8'!K14 -> 15214.286 | L14: ='9'!K14 -> 15214.286 | M14: ='10'!K14 -> 15142.857 | N14: ='11'!K14 -> 15214.286 | O14: ='12'!K14 -> 15214.286 | P14: ='13'!K14 -> 15428.571 | Q14: ='14'!K14 -> 15285.714 | R14: ='15'!K14 -> 15428.571 | S14: ='14'!K14 -> 15285.714 | T14: ='17'!K14 -> 15500 | U14: ='18'!K14 -> 15500 | V14: ='19'!K14 -> 15357.143 | W14: ='20'!K14 -> 15500 | X14: ='21'!K14 -> 15642.857 | Y14: ='22'!K14 -> 15642.857 | Z14: ='23'!K14 -> 15714.286 | AA14: ='24'!K14 -> 15857.143 | AB14: ='25'!K14 -> 15857.143 | AC14: ='26'!K14 -> 15857.143 | AD14: ='27'!K14 -> 16000 | AE14: ='28'!K14 -> 16000 | AF14: ='29'!K14 -> 16214.286 | AG14: ='30'!K14 -> 16285.714 | AH14: 13500 | AI14: =AG14-D14 -> 1642.8571 | AJ14: =AVERAGE(D14:AG14) -> 15454.762
B15: - Gula Jawa/Merah (Bahan Kelapa) | C15: Kg | D15: ='1'!K15 -> 15142.857 | E15: ='2'!K15 -> 15142.857 | F15: ='3'!K15 -> 15285.714 | G15: ='4'!K15 -> 15285.714 | H15: ='5'!K15 -> 15285.714 | I15: ='6'!K15 -> 15285.714 | J15: ='7'!K15 -> 15285.714 | K15: ='8'!K15 -> 15285.714 | L15: ='9'!K15 -> 15285.714 | M15: ='10'!K15 -> 15285.714 | N15: ='11'!K15 -> 15285.714 | O15: ='12'!K15 -> 15285.714 | P15: ='13'!K15 -> 15285.714 | Q15: ='14'!K15 -> 15285.714 | R15: ='15'!K15 -> 15285.714 | S15: ='14'!K15 -> 15285.714 | T15: ='17'!K15 -> 15500 | U15: ='18'!K15 -> 15500 | V15: ='19'!K15 -> 15500 | W15: ='20'!K15 -> 15500 | X15: ='21'!K15 -> 15500 | Y15: ='22'!K15 -> 15500 | Z15: ='23'!K15 -> 15642.857 | AA15: ='24'!K15 -> 15642.857 | AB15: ='25'!K15 -> 15642.857 | AC15: ='26'!K15 -> 15642.857 | AD15: ='27'!K15 -> 15785.714 | AE15: ='28'!K15 -> 15785.714 | AF15: ='29'!K15 -> 15785.714 | AG15: ='30'!K15 -> 15785.714 | AI15: =AG15-D15 -> 642.85714 | AJ15: =AVERAGE(D15:AG15) -> 15433.333
B16: MINYAK GORENG | D16: ='1'!K16 -> 0 | E16: ='2'!K16 -> 0 | F16: ='3'!K16 -> 0 | G16: ='4'!K16 -> 0 | H16: ='5'!K16 -> 0 | I16: ='6'!K16 -> 0 | J16: ='7'!K16 -> 0 | K16: ='8'!K16 -> 0 | L16: ='9'!K16 -> 0 | M16: ='10'!K16 -> 0 | N16: ='11'!K16 -> 0 | O16: ='12'!K16 -> 0 | P16: ='13'!K16 -> 0 | Q16: ='14'!K16 -> 0 | R16: ='15'!K16 -> 0 | S16: ='14'!K16 -> 0 | T16: ='17'!K16 -> 0 | U16: ='18'!K16 -> 0 | V16: ='19'!K16 -> 0 | W16: ='20'!K16 -> 0 | X16: ='21'!K16 -> 0 | Y16: ='22'!K16 -> 0 | Z16: ='23'!K16 -> 0 | AA16: ='24'!K16 -> 0 | AB16: ='25'!K16 -> 0 | AC16: ='26'!K16 -> 0 | AD16: ='27'!K16 -> 0 | AE16: ='28'!K16 -> 0 | AF16: ='29'!K16 -> 0 | AG16: ='30'!K16 -> 0 | AI16: =AG16-D16 -> 0 | AJ16: =AVERAGE(D16:AG16) -> 0
B17: - Minyak Goreng Curah (Bening) | C17: Kg | D17: ='1'!K17 -> 15142.857 | E17: ='2'!K17 -> 15142.857 | F17: ='3'!K17 -> 15142.857 | G17: ='4'!K17 -> 15142.857 | H17: ='5'!K17 -> 15142.857 | I17: ='6'!K17 -> 15142.857 | J17: ='7'!K17 -> 15142.857 | K17: ='8'!K17 -> 15142.857 | L17: ='9'!K17 -> 15000 | M17: ='10'!K17 -> 15142.857 | N17: ='11'!K17 -> 15142.857 | O17: ='12'!K17 -> 15142.857 | P17: ='13'!K17 -> 15142.857 | Q17: ='14'!K17 -> 15142.857 | R17: ='15'!K17 -> 15142.857 | S17: ='14'!K17 -> 15142.857 | T17: ='17'!K17 -> 15142.857 | U17: ='18'!K17 -> 15142.857 | V17: ='19'!K17 -> 15142.857 | W17: ='20'!K17 -> 15142.857 | X17: ='21'!K17 -> 15142.857 | Y17: ='22'!K17 -> 15142.857 | Z17: ='23'!K17 -> 15142.857 | AA17: ='24'!K17 -> 15142.857 | AB17: ='25'!K17 -> 15142.857 | AC17: ='26'!K17 -> 15142.857 | AD17: ='27'!K17 -> 15142.857 | AE17: ='28'!K17 -> 15142.857 | AF17: ='29'!K17 -> 15285.714 | AG17: ='30'!K17 -> 15142.857 | AH17: 15500 | AI17: =AG17-D17 -> 0 | AJ17: =AVERAGE(D17:AG17) -> 15142.857
B18: - Minyak KITA | C18: Kg | D18: ='1'!K18 -> 14000 | E18: ='2'!K18 -> 14000 | F18: ='3'!K18 -> 14000 | G18: ='4'!K18 -> 14000 | H18: ='5'!K18 -> 14000 | I18: ='6'!K18 -> 14000 | J18: ='7'!K18 -> 14000 | K18: ='8'!K18 -> 14000 | L18: ='9'!K18 -> 14000 | M18: ='10'!K18 -> 14000 | N18: ='11'!K18 -> 14000 | O18: ='12'!K18 -> 14000 | P18: ='13'!K18 -> 14000 | Q18: ='14'!K18 -> 14000 | R18: ='15'!K18 -> 14000 | S18: ='14'!K18 -> 14000 | T18: ='17'!K18 -> 14000 | U18: ='18'!K18 -> 14000 | V18: ='19'!K18 -> 14000 | W18: ='20'!K18 -> 14000 | X18: ='21'!K18 -> 14000 | Y18: ='22'!K18 -> 14000 | Z18: ='23'!K18 -> 14000 | AA18: ='24'!K18 -> 14000 | AB18: ='25'!K18 -> 14000 | AC18: ='26'!K18 -> 14000 | AD18: ='27'!K18 -> 14000 | AE18: ='28'!K18 -> 14000 | AF18: ='29'!K18 -> 14000 | AG18: ='30'!K18 -> 14000 | AH18: 14000 | AI18: =AG18-D18 -> 0 | AJ18: =AVERAGE(D18:AG18) -> 14000
A19: 4 | B19: MENTEGA | D19: ='1'!K19 -> 0 | E19: ='2'!K19 -> 0 | F19: ='3'!K19 -> 0 | G19: ='4'!K19 -> 0 | H19: ='5'!K19 -> 0 | I19: ='6'!K19 -> 0 | J19: ='7'!K19 -> 0 | K19: ='8'!K19 -> 0 | L19: ='9'!K19 -> 0 | M19: ='10'!K19 -> 0 | N19: ='11'!K19 -> 0 | O19: ='12'!K19 -> 0 | P19: ='13'!K19 -> 0 | Q19: ='14'!K19 -> 0 | R19: ='15'!K19 -> 0 | S19: ='14'!K19 -> 0 | T19: ='17'!K19 -> 0 | U19: ='18'!K19 -> 0 | V19: ='19'!K19 -> 0 | W19: ='20'!K19 -> 0 | X19: ='21'!K19 -> 0 | Y19: ='22'!K19 -> 0 | Z19: ='23'!K19 -> 0 | AA19: ='24'!K19 -> 0 | AB19: ='25'!K19 -> 0 | AC19: ='26'!K19 -> 0 | AD19: ='27'!K19 -> 0 | AE19: ='28'!K19 -> 0 | AF19: ='29'!K19 -> 0 | AG19: ='30'!K19 -> 0 | AI19: =AG19-D19 -> 0 | AJ19: =AVERAGE(D19:AG19) -> 0
B20: - Mentega Curah (Amanda) | C20: Kg | D20: ='1'!K20 -> 20400 | E20: ='2'!K20 -> 20400 | F20: ='3'!K20 -> 20400 | G20: ='4'!K20 -> 20400 | H20: ='5'!K20 -> 20400 | I20: ='6'!K20 -> 20400 | J20: ='7'!K20 -> 20400 | K20: ='8'!K20 -> 20400 | L20: ='9'!K20 -> 20400 | M20: ='10'!K20 -> 20400 | N20: ='11'!K20 -> 20400 | O20: ='12'!K20 -> 20400 | P20: ='13'!K20 -> 20400 | Q20: ='14'!K20 -> 20400 | R20: ='15'!K20 -> 20400 | S20: ='14'!K20 -> 20400 | T20: ='17'!K20 -> 20400 | U20: ='18'!K20 -> 20400 | V20: ='19'!K20 -> 20400 | W20: ='20'!K20 -> 20400 | X20: ='21'!K20 -> 20400 | Y20: ='22'!K20 -> 20400 | Z20: ='23'!K20 -> 20400 | AA20: ='24'!K20 -> 20400 | AB20: ='25'!K20 -> 20400 | AC20: ='26'!K20 -> 20400 | AD20: ='27'!K20 -> 20400 | AE20: ='28'!K20 -> 20400 | AF20: ='29'!K20 -> 20400 | AG20: ='30'!K20 -> 20400 | AI20: =AG20-D20 -> 0 | AJ20: =AVERAGE(D20:AG20) -> 20400
A21: 5 | B21: DAGING | D21: ='1'!K21 -> 0 | E21: ='2'!K21 -> 0 | F21: ='3'!K21 -> 0 | G21: ='4'!K21 -> 0 | H21: ='5'!K21 -> 0 | I21: ='6'!K21 -> 0 | J21: ='7'!K21 -> 0 | K21: ='8'!K21 -> 0 | L21: ='9'!K21 -> 0 | M21: ='10'!K21 -> 0 | N21: ='11'!K21 -> 0 | O21: ='12'!K21 -> 0 | P21: ='13'!K21 -> 0 | Q21: ='14'!K21 -> 0 | R21: ='15'!K21 -> 0 | S21: ='14'!K21 -> 0 | T21: ='17'!K21 -> 0 | U21: ='18'!K21 -> 0 | V21: ='19'!K21 -> 0 | W21: ='20'!K21 -> 0 | X21: ='21'!K21 -> 0 | Y21: ='22'!K21 -> 0 | Z21: ='23'!K21 -> 0 | AA21: ='24'!K21 -> 0 | AB21: ='25'!K21 -> 0 | AC21: ='26'!K21 -> 0 | AD21: ='27'!K21 -> 0 | AE21: ='28'!K21 -> 0 | AF21: ='29'!K21 -> 0 | AG21: ='30'!K21 -> 0 | AI21: =AG21-D21 -> 0 | AJ21: =AVERAGE(D21:AG21) -> 0
B22: - Daging Sapi Grade Atas | C22: Kg | D22: ='1'!K22 -> 120000 | E22: ='2'!K22 -> 120000 | F22: ='3'!K22 -> 120000 | G22: ='4'!K22 -> 120000 | H22: ='5'!K22 -> 120000 | I22: ='6'!K22 -> 120000 | J22: ='7'!K22 -> 120000 | K22: ='8'!K22 -> 120000 | L22: ='9'!K22 -> 120000 | M22: ='10'!K22 -> 120000 | N22: ='11'!K22 -> 120000 | O22: ='12'!K22 -> 120000 | P22: ='13'!K22 -> 120000 | Q22: ='14'!K22 -> 120000 | R22: ='15'!K22 -> 120000 | S22: ='14'!K22 -> 120000 | T22: ='17'!K22 -> 120000 | U22: ='18'!K22 -> 120000 | V22: ='19'!K22 -> 120000 | W22: ='20'!K22 -> 120000 | X22: ='21'!K22 -> 120000 | Y22: ='22'!K22 -> 120000 | Z22: ='23'!K22 -> 120000 | AA22: ='24'!K22 -> 120000 | AB22: ='25'!K22 -> 120000 | AC22: ='26'!K22 -> 120000 | AD22: ='27'!K22 -> 120000 | AE22: ='28'!K22 -> 120000 | AF22: ='29'!K22 -> 120000 | AG22: ='30'!K22 -> 120000 | AH22: 105000 | AI22: =AG22-D22 -> 0 | AJ22: =AVERAGE(D22:AG22) -> 120000
B23: - Daging Sapi Grade Sedang | C23: Kg | D23: ='1'!K23 -> 111428.57 | E23: ='2'!K23 -> 111428.57 | F23: ='3'!K23 -> 111428.57 | G23: ='4'!K23 -> 111428.57 | H23: ='5'!K23 -> 111428.57 | I23: ='6'!K23 -> 111428.57 | J23: ='7'!K23 -> 111428.57 | K23: ='8'!K23 -> 111428.57 | L23: ='9'!K23 -> 111428.57 | M23: ='10'!K23 -> 110714.29 | N23: ='11'!K23 -> 110714.29 | O23: ='12'!K23 -> 110714.29 | P23: ='13'!K23 -> 110714.29 | Q23: ='14'!K23 -> 110714.29 | R23: ='15'!K23 -> 110714.29 | S23: ='14'!K23 -> 110714.29 | T23: ='17'!K23 -> 110714.29 | U23: ='18'!K23 -> 110714.29 | V23: ='19'!K23 -> 110714.29 | W23: ='20'!K23 -> 110714.29 | X23: ='21'!K23 -> 110714.29 | Y23: ='22'!K23 -> 110714.29 | Z23: ='23'!K23 -> 110714.29 | AA23: ='24'!K23 -> 110714.29 | AB23: ='25'!K23 -> 110714.29 | AC23: ='26'!K23 -> 110714.29 | AD23: ='27'!K23 -> 110714.29 | AE23: ='28'!K23 -> 110714.29 | AF23: ='29'!K23 -> 110714.29 | AG23: ='30'!K23 -> 110714.29 | AH23: 80000 | AI23: =AG23-D23 -> -714.28571 | AJ23: =AVERAGE(D23:AG23) -> 110928.57
B24: - Daging Sapi Grade Bawah | C24: Kg | D24: ='1'!K24 -> 100714.29 | E24: ='2'!K24 -> 100714.29 | F24: ='3'!K24 -> 100714.29 | G24: ='4'!K24 -> 100714.29 | H24: ='5'!K24 -> 100714.29 | I24: ='6'!K24 -> 100714.29 | J24: ='7'!K24 -> 100714.29 | K24: ='8'!K24 -> 100714.29 | L24: ='9'!K24 -> 100714.29 | M24: ='10'!K24 -> 100714.29 | N24: ='11'!K24 -> 100714.29 | O24: ='12'!K24 -> 100714.29 | P24: ='13'!K24 -> 100714.29 | Q24: ='14'!K24 -> 99285.714 | R24: ='15'!K24 -> 99285.714 | S24: ='14'!K24 -> 99285.714 | T24: ='17'!K24 -> 99285.714 | U24: ='18'!K24 -> 100714.29 | V24: ='19'!K24 -> 100714.29 | W24: ='20'!K24 -> 100714.29 | X24: ='21'!K24 -> 100714.29 | Y24: ='22'!K24 -> 100714.29 | Z24: ='23'!K24 -> 100714.29 | AA24: ='24'!K24 -> 100714.29 | AB24: ='25'!K24 -> 100714.29 | AC24: ='26'!K24 -> 100714.29 | AD24: ='27'!K24 -> 100714.29 | AE24: ='28'!K24 -> 100714.29 | AF24: ='29'!K24 -> 100714.29 | AG24: ='30'!K24 -> 100714.29 | AH24: 80000 | AI24: =AG24-D24 -> 0 | AJ24: =AVERAGE(D24:AG24) -> 100523.81
B25: - Daging Ayam Broiler | C25: Kg | D25: ='1'!K25 -> 33714.286 | E25: ='2'!K25 -> 33571.429 | F25: ='3'!K25 -> 33642.857 | G25: ='4'!K25 -> 33642.857 | H25: ='5'!K25 -> 33642.857 | I25: ='6'!K25 -> 33500 | J25: ='7'!K25 -> 33857.143 | K25: ='8'!K25 -> 34000 | L25: ='9'!K25 -> 34000 | M25: ='10'!K25 -> 34142.857 | N25: ='11'!K25 -> 34142.857 | O25: ='12'!K25 -> 34142.857 | P25: ='13'!K25 -> 34142.857 | Q25: ='14'!K25 -> 34142.857 | R25: ='15'!K25 -> 33857.143 | S25: ='14'!K25 -> 34142.857 | T25: ='17'!K25 -> 33285.714 | U25: ='18'!K25 -> 33571.429 | V25: ='19'!K25 -> 33714.286 | W25: ='20'!K25 -> 33428.571 | X25: ='21'!K25 -> 33142.857 | Y25: ='22'!K25 -> 33142.857 | Z25: ='23'!K25 -> 32428.571 | AA25: ='24'!K25 -> 31714.286 | AB25: ='25'!K25 -> 31571.429 | AC25: ='26'!K25 -> 31714.286 | AD25: ='27'!K25 -> 31714.286 | AE25: ='28'!K25 -> 31142.857 | AF25: ='29'!K25 -> 31000 | AG25: ='30'!K25 -> 31142.857 | AH25: 36750 | AI25: =AG25-D25 -> -2571.4286 | AJ25: =AVERAGE(D25:AG25) -> 33166.667
A26: 6 | B26: I K A N | D26: ='1'!K26 -> 0 | E26: ='2'!K26 -> 0 | F26: ='3'!K26 -> 0 | G26: ='4'!K26 -> 0 | H26: ='5'!K26 -> 0 | I26: ='6'!K26 -> 0 | J26: ='7'!K26 -> 0 | K26: ='8'!K26 -> 0 | L26: ='9'!K26 -> 0 | M26: ='10'!K26 -> 0 | N26: ='11'!K26 -> 0 | O26: ='12'!K26 -> 0 | P26: ='13'!K26 -> 0 | Q26: ='14'!K26 -> 0 | R26: ='15'!K26 -> 0 | S26: ='14'!K26 -> 0 | T26: ='17'!K26 -> 0 | U26: ='18'!K26 -> 0 | V26: ='19'!K26 -> 0 | W26: ='20'!K26 -> 0 | X26: ='21'!K26 -> 0 | Y26: ='22'!K26 -> 0 | Z26: ='23'!K26 -> 0 | AA26: ='24'!K26 -> 0 | AB26: ='25'!K26 -> 0 | AC26: ='26'!K26 -> 0 | AD26: ='27'!K26 -> 0 | AE26: ='28'!K26 -> 0 | AF26: ='29'!K26 -> 0 | AG26: ='30'!K26 -> 0 | AI26: =AG26-D26 -> 0 | AJ26: =AVERAGE(D26:AG26) -> 0
B27: - Ikan Tongkol Segar (Uk. Sedang) | C27: Kg | D27: ='1'!K27 -> 35166.667 | E27: ='2'!K27 -> 35166.667 | F27: ='3'!K27 -> 35166.667 | G27: ='4'!K27 -> 35166.667 | H27: ='5'!K27 -> 35166.667 | I27: ='6'!K27 -> 35666.667 | J27: ='7'!K27 -> 35666.667 | K27: ='8'!K27 -> 35666.667 | L27: ='9'!K27 -> 35666.667 | M27: ='10'!K27 -> 35800 | N27: ='11'!K27 -> 35800 | O27: ='12'!K27 -> 35800 | P27: ='13'!K27 -> 35800 | Q27: ='14'!K27 -> 35666.667 | R27: ='15'!K27 -> 35666.667 | S27: ='14'!K27 -> 35666.667 | T27: ='17'!K27 -> 35666.667 | U27: ='18'!K27 -> 35666.667 | V27: ='19'!K27 -> 35800 | W27: ='20'!K27 -> 35800 | X27: ='21'!K27 -> 35800 | Y27: ='22'!K27 -> 35800 | Z27: ='23'!K27 -> 35800 | AA27: ='24'!K27 -> 35800 | AB27: ='25'!K27 -> 35800 | AC27: ='26'!K27 -> 35800 | AD27: ='27'!K27 -> 35800 | AE27: ='28'!K27 -> 35600 | AF27: ='29'!K27 -> 35600 | AG27: ='30'!K27 -> 35600 | AI27: =AG27-D27 -> 433.33333 | AJ27: =AVERAGE(D27:AG27) -> 35634.444
B28: - Ikan Mujair Segar (Uk. Sedang) | C28: Kg | D28: ='1'!K28 -> 27285.714 | E28: ='2'!K28 -> 27285.714 | F28: ='3'!K28 -> 27285.714 | G28: ='4'!K28 -> 27285.714 | H28: ='5'!K28 -> 27285.714 | I28: ='6'!K28 -> 28000 | J28: ='7'!K28 -> 28285.714 | K28: ='8'!K28 -> 28285.714 | L28: ='9'!K28 -> 28285.714 | M28: ='10'!K28 -> 28571.429 | N28: ='11'!K28 -> 28571.429 | O28: ='12'!K28 -> 28571.429 | P28: ='13'!K28 -> 28571.429 | Q28: ='14'!K28 -> 28285.714 | R28: ='15'!K28 -> 28285.714 | S28: ='14'!K28 -> 28285.714 | T28: ='17'!K28 -> 28285.714 | U28: ='18'!K28 -> 28571.429 | V28: ='19'!K28 -> 28571.429 | W28: ='20'!K28 -> 28571.429 | X28: ='21'!K28 -> 28571.429 | Y28: ='22'!K28 -> 28571.429 | Z28: ='23'!K28 -> 28571.429 | AA28: ='24'!K28 -> 28571.429 | AB28: ='25'!K28 -> 28571.429 | AC28: ='26'!K28 -> 28571.429 | AD28: ='27'!K28 -> 27857.143 | AE28: ='28'!K28 -> 27857.143 | AF28: ='29'!K28 -> 27857.143 | AG28: ='30'!K28 -> 27857.143 | AI28: =AG28-D28 -> 571.42857 | AJ28: =AVERAGE(D28:AG28) -> 28176.19
B29: - Udang Segar (Uk. Sedang) | C29: Kg | D29: ='1'!K29 -> 66571.429 | E29: ='2'!K29 -> 66571.429 | F29: ='3'!K29 -> 66571.429 | G29: ='4'!K29 -> 66571.429 | H29: ='5'!K29 -> 66571.429 | I29: ='6'!K29 -> 67285.714 | J29: ='7'!K29 -> 65857.143 | K29: ='8'!K29 -> 65857.143 | L29: ='9'!K29 -> 65857.143 | M29: ='10'!K29 -> 65428.571 | N29: ='11'!K29 -> 65428.571 | O29: ='12'!K29 -> 65428.571 | P29: ='13'!K29 -> 65428.571 | Q29: ='14'!K29 -> 64714.286 | R29: ='15'!K29 -> 64714.286 | S29: ='14'!K29 -> 64714.286 | T29: ='17'!K29 -> 64714.286 | U29: ='18'!K29 -> 65428.571 | V29: ='19'!K29 -> 65428.571 | W29: ='20'!K29 -> 65428.571 | X29: ='21'!K29 -> 65428.571 | Y29: ='22'!K29 -> 65428.571 | Z29: ='23'!K29 -> 64714.286 | AA29: ='24'!K29 -> 64714.286 | AB29: ='25'!K29 -> 63285.714 | AC29: ='26'!K29 -> 63285.714 | AD29: ='27'!K29 -> 63285.714 | AE29: ='28'!K29 -> 63285.714 | AF29: ='29'!K29 -> 63285.714 | AG29: ='30'!K29 -> 63285.714 | AI29: =AG29-D29 -> -3285.7143 | AJ29: =AVERAGE(D29:AG29) -> 65152.381
B30: - Ikan Lele Segar (Ukuran Sedang) | C30: Kg | D30: ='1'!K30 -> 24600 | E30: ='2'!K30 -> 24600 | F30: ='3'!K30 -> 24600 | G30: ='4'!K30 -> 24600 | H30: ='5'!K30 -> 24600 | I30: ='6'!K30 -> 24600 | J30: ='7'!K30 -> 24600 | K30: ='8'!K30 -> 24600 | L30: ='9'!K30 -> 24600 | M30: ='10'!K30 -> 24750 | N30: ='11'!K30 -> 24750 | O30: ='12'!K30 -> 24750 | P30: ='13'!K30 -> 24750 | Q30: ='14'!K30 -> 24750 | R30: ='15'!K30 -> 24750 | S30: ='14'!K30 -> 24750 | T30: ='17'!K30 -> 24750 | U30: ='18'!K30 -> 24750 | V30: ='19'!K30 -> 24750 | W30: ='20'!K30 -> 24750 | X30: ='21'!K30 -> 24750 | Y30: ='22'!K30 -> 24750 | Z30: ='23'!K30 -> 24750 | AA30: ='24'!K30 -> 24750 | AB30: ='25'!K30 -> 24750 | AC30: ='26'!K30 -> 24750 | AD30: ='27'!K30 -> 24750 | AE30: ='28'!K30 -> 24750 | AF30: ='29'!K30 -> 24750 | AG30: ='30'!K30 -> 24750 | AI30: =AG30-D30 -> 150 | AJ30: =AVERAGE(D30:AG30) -> 24705
B31: - Ikan Bandeng Segar (Uk. Sedang) | C31: Kg | D31: ='1'!K31 -> 36000 | E31: ='2'!K31 -> 36000 | F31: ='3'!K31 -> 36000 | G31: ='4'!K31 -> 36000 | H31: ='5'!K31 -> 36000 | I31: ='6'!K31 -> 36714.286 | J31: ='7'!K31 -> 37000 | K31: ='8'!K31 -> 37000 | L31: ='9'!K31 -> 37000 | M31: ='10'!K31 -> 37571.429 | N31: ='11'!K31 -> 37857.143 | O31: ='12'!K31 -> 37571.429 | P31: ='13'!K31 -> 37571.429 | Q31: ='14'!K31 -> 37285.714 | R31: ='15'!K31 -> 37285.714 | S31: ='14'!K31 -> 37285.714 | T31: ='17'!K31 -> 37857.143 | U31: ='18'!K31 -> 38142.857 | V31: ='19'!K31 -> 38142.857 | W31: ='20'!K31 -> 37571.429 | X31: ='21'!K31 -> 37571.429 | Y31: ='22'!K31 -> 37571.429 | Z31: ='23'!K31 -> 37285.714 | AA31: ='24'!K31 -> 37714.286 | AB31: ='25'!K31 -> 37714.286 | AC31: ='26'!K31 -> 37714.286 | AD31: ='27'!K31 -> 37000 | AE31: ='28'!K31 -> 37000 | AF31: ='29'!K31 -> 37000 | AG31: ='30'!K31 -> 37000 | AI31: =AG31-D31 -> 1000 | AJ31: =AVERAGE(D31:AG31) -> 37180.952
B32: - Ikan Teri Asin (Bukan Teri Medan) | C32: Kg | D32: ='1'!K32 -> 87500 | E32: ='2'!K32 -> 87500 | F32: ='3'!K32 -> 87500 | G32: ='4'!K32 -> 87500 | H32: ='5'!K32 -> 87500 | I32: ='6'!K32 -> 87500 | J32: ='7'!K32 -> 87500 | K32: ='8'!K32 -> 87500 | L32: ='9'!K32 -> 87500 | M32: ='10'!K32 -> 87500 | N32: ='11'!K32 -> 87500 | O32: ='12'!K32 -> 87500 | P32: ='13'!K32 -> 87500 | Q32: ='14'!K32 -> 83333.333 | R32: ='15'!K32 -> 83333.333 | S32: ='14'!K32 -> 83333.333 | T32: ='17'!K32 -> 83333.333 | U32: ='18'!K32 -> 87500 | V32: ='19'!K32 -> 87500 | W32: ='20'!K32 -> 87500 | X32: ='21'!K32 -> 87500 | Y32: ='22'!K32 -> 87500 | Z32: ='23'!K32 -> 87500 | AA32: ='24'!K32 -> 87500 | AB32: ='25'!K32 -> 87500 | AC32: ='26'!K32 -> 87500 | AD32: ='27'!K32 -> 87500 | AE32: ='28'!K32 -> 87500 | AF32: ='29'!K32 -> 87500 | AG32: ='30'!K32 -> 87500 | AI32: =AG32-D32 -> 0 | AJ32: =AVERAGE(D32:AG32) -> 86944.444
A33: 7 | B33: TELUR | D33: ='1'!K33 -> 0 | E33: ='2'!K33 -> 0 | F33: ='3'!K33 -> 0 | G33: ='4'!K33 -> 0 | H33: ='5'!K33 -> 0 | I33: ='6'!K33 -> 0 | J33: ='7'!K33 -> 0 | K33: ='8'!K33 -> 0 | L33: ='9'!K33 -> 0 | M33: ='10'!K33 -> 0 | N33: ='11'!K33 -> 0 | O33: ='12'!K33 -> 0 | P33: ='13'!K33 -> 0 | Q33: ='14'!K33 -> 0 | R33: ='15'!K33 -> 0 | S33: ='14'!K33 -> 0 | T33: ='17'!K33 -> 0 | U33: ='18'!K33 -> 0 | V33: ='19'!K33 -> 0 | W33: ='20'!K33 -> 0 | X33: ='21'!K33 -> 0 | Y33: ='22'!K33 -> 0 | Z33: ='23'!K33 -> 0 | AA33: ='24'!K33 -> 0 | AB33: ='25'!K33 -> 0 | AC33: ='26'!K33 -> 0 | AD33: ='27'!K33 -> 0 | AE33: ='28'!K33 -> 0 | AF33: ='29'!K33 -> 0 | AG33: ='30'!K33 -> 0 | AI33: =AG33-D33 -> 0 | AJ33: =AVERAGE(D33:AG33) -> 0
B34: - Telur Ayam Horn | C34: Kg | D34: ='1'!K34 -> 24428.571 | E34: ='2'!K34 -> 24428.571 | F34: ='3'!K34 -> 24571.429 | G34: ='4'!K34 -> 24571.429 | H34: ='5'!K34 -> 24571.429 | I34: ='6'!K34 -> 25571.429 | J34: ='7'!K34 -> 25428.571 | K34: ='8'!K34 -> 25571.429 | L34: ='9'!K34 -> 25571.429 | M34: ='10'!K34 -> 26000 | N34: ='11'!K34 -> 25857.143 | O34: ='12'!K34 -> 26142.857 | P34: ='13'!K34 -> 26071.429 | Q34: ='14'!K34 -> 25857.143 | R34: ='15'!K34 -> 26000 | S34: ='14'!K34 -> 25857.143 | T34: ='17'!K34 -> 26428.571 | U34: ='18'!K34 -> 26142.857 | V34: ='19'!K34 -> 26285.714 | W34: ='20'!K34 -> 26214.286 | X34: ='21'!K34 -> 26214.286 | Y34: ='22'!K34 -> 26428.571 | Z34: ='23'!K34 -> 26142.857 | AA34: ='24'!K34 -> 26285.714 | AB34: ='25'!K34 -> 26142.857 | AC34: ='26'!K34 -> 26142.857 | AD34: ='27'!K34 -> 26357.143 | AE34: ='28'!K34 -> 26500 | AF34: ='29'!K34 -> 26642.857 | AG34: ='30'!K34 -> 26642.857 | AH34: 27000 | AI34: =AG34-D34 -> 2214.2857 | AJ34: =AVERAGE(D34:AG34) -> 25835.714
B35: - Telur Ayam Kampung | C35: Butir | D35: ='1'!K35 -> 2728.5714 | E35: ='2'!K35 -> 2728.5714 | F35: ='3'!K35 -> 2728.5714 | G35: ='4'!K35 -> 2728.5714 | H35: ='5'!K35 -> 2728.5714 | I35: ='6'!K35 -> 2728.5714 | J35: ='7'!K35 -> 2728.5714 | K35: ='8'!K35 -> 2728.5714 | L35: ='9'!K35 -> 2728.5714 | M35: ='10'!K35 -> 2657.1429 | N35: ='11'!K35 -> 2657.1429 | O35: ='12'!K35 -> 2657.1429 | P35: ='13'!K35 -> 2657.1429 | Q35: ='14'!K35 -> 2728.5714 | R35: ='15'!K35 -> 2728.5714 | S35: ='14'!K35 -> 2728.5714 | T35: ='17'!K35 -> 2728.5714 | U35: ='18'!K35 -> 2657.1429 | V35: ='19'!K35 -> 2657.1429 | W35: ='20'!K35 -> 2657.1429 | X35: ='21'!K35 -> 2657.1429 | Y35: ='22'!K35 -> 2728.5714 | Z35: ='23'!K35 -> 2800 | AA35: ='24'!K35 -> 2800 | AB35: ='25'!K35 -> 2800 | AC35: ='26'!K35 -> 2800 | AD35: ='27'!K35 -> 2800 | AE35: ='28'!K35 -> 2800 | AF35: ='29'!K35 -> 2800 | AG35: ='30'!K35 -> 2800 | AI35: =AG35-D35 -> 71.428571 | AJ35: =AVERAGE(D35:AG35) -> 2728.5714
A36: 8 | B36: TAHU | D36: ='1'!K36 -> 0 | E36: ='2'!K36 -> 0 | F36: ='3'!K36 -> 0 | G36: ='4'!K36 -> 0 | H36: ='5'!K36 -> 0 | I36: ='6'!K36 -> 0 | J36: ='7'!K36 -> 0 | K36: ='8'!K36 -> 0 | L36: ='9'!K36 -> 0 | M36: ='10'!K36 -> 0 | N36: ='11'!K36 -> 0 | O36: ='12'!K36 -> 0 | P36: ='13'!K36 -> 0 | Q36: ='14'!K36 -> 0 | R36: ='15'!K36 -> 0 | S36: ='14'!K36 -> 0 | T36: ='17'!K36 -> 0 | U36: ='18'!K36 -> 0 | V36: ='19'!K36 -> 0 | W36: ='20'!K36 -> 0 | X36: ='21'!K36 -> 0 | Y36: ='22'!K36 -> 0 | Z36: ='23'!K36 -> 0 | AA36: ='24'!K36 -> 0 | AB36: ='25'!K36 -> 0 | AC36: ='26'!K36 -> 0 | AD36: ='27'!K36 -> 0 | AE36: ='28'!K36 -> 0 | AF36: ='29'!K36 -> 0 | AG36: ='30'!K36 -> 0 | AI36: =AG36-D36 -> 0 | AJ36: =AVERAGE(D36:AG36) -> 0
B37: - Tahu biasa | C37: Kg | D37: ='1'!K37 -> 8750 | E37: ='2'!K37 -> 8750 | F37: ='3'!K37 -> 8750 | G37: ='4'!K37 -> 8750 | H37: ='5'!K37 -> 8750 | I37: ='6'!K37 -> 8750 | J37: ='7'!K37 -> 8750 | K37: ='8'!K37 -> 8750 | L37: ='9'!K37 -> 8750 | M37: ='10'!K37 -> 9035.7143 | N37: ='11'!K37 -> 9035.7143 | O37: ='12'!K37 -> 9035.7143 | P37: ='13'!K37 -> 9035.7143 | Q37: ='14'!K37 -> 9035.7143 | R37: ='15'!K37 -> 7892.8571 | S37: ='14'!K37 -> 9035.7143 | T37: ='17'!K37 -> 7892.8571 | U37: ='18'!K37 -> 9035.7143 | V37: ='19'!K37 -> 9035.7143 | W37: ='20'!K37 -> 9035.7143 | X37: ='21'!K37 -> 9035.7143 | Y37: ='22'!K37 -> 9035.7143 | Z37: ='23'!K37 -> 9035.7143 | AA37: ='24'!K37 -> 9035.7143 | AB37: ='25'!K37 -> 9035.7143 | AC37: ='26'!K37 -> 9035.7143 | AD37: ='27'!K37 -> 9035.7143 | AE37: ='28'!K37 -> 9035.7143 | AF37: ='29'!K37 -> 9035.7143 | AG37: ='30'!K37 -> 9035.7143 | AI37: =AG37-D37 -> 285.71429 | AJ37: =AVERAGE(D37:AG37) -> 8873.8095
B38: - Tahu susu | C38: Kg | D38: ='1'!K38 -> 12600 | E38: ='2'!K38 -> 12600 | F38: ='3'!K38 -> 12600 | G38: ='4'!K38 -> 12600 | H38: ='5'!K38 -> 12600 | I38: ='6'!K38 -> 12600 | J38: ='7'!K38 -> 12600 | K38: ='8'!K38 -> 12600 | L38: ='9'!K38 -> 12600 | M38: ='10'!K38 -> 12000 | N38: ='11'!K38 -> 12000 | O38: ='12'!K38 -> 12000 | P38: ='13'!K38 -> 12000 | Q38: ='14'!K38 -> 12000 | R38: ='15'!K38 -> 12000 | S38: ='14'!K38 -> 12000 | T38: ='17'!K38 -> 12000 | U38: ='18'!K38 -> 12000 | V38: ='19'!K38 -> 12000 | W38: ='20'!K38 -> 12000 | X38: ='21'!K38 -> 12000 | Y38: ='22'!K38 -> 12000 | Z38: ='23'!K38 -> 12000 | AA38: ='24'!K38 -> 12000 | AB38: ='25'!K38 -> 12000 | AC38: ='26'!K38 -> 12000 | AD38: ='27'!K38 -> 12000 | AE38: ='28'!K38 -> 12000 | AF38: ='29'!K38 -> 12000 | AG38: ='30'!K38 -> 12000 | AI38: =AG38-D38 -> -600 | AJ38: =AVERAGE(D38:AG38) -> 12180
A39: 9 | B39: TEMPE | D39: ='1'!K39 -> 0 | E39: ='2'!K39 -> 0 | F39: ='3'!K39 -> 0 | G39: ='4'!K39 -> 0 | H39: ='5'!K39 -> 0 | I39: ='6'!K39 -> 0 | J39: ='7'!K39 -> 0 | K39: ='8'!K39 -> 0 | L39: ='9'!K39 -> 0 | M39: ='10'!K39 -> 0 | N39: ='11'!K39 -> 0 | O39: ='12'!K39 -> 0 | P39: ='13'!K39 -> 0 | Q39: ='14'!K39 -> 0 | R39: ='15'!K39 -> 0 | S39: ='14'!K39 -> 0 | T39: ='17'!K39 -> 0 | U39: ='18'!K39 -> 0 | V39: ='19'!K39 -> 0 | W39: ='20'!K39 -> 0 | X39: ='21'!K39 -> 0 | Y39: ='22'!K39 -> 0 | Z39: ='23'!K39 -> 0 | AA39: ='24'!K39 -> 0 | AB39: ='25'!K39 -> 0 | AC39: ='26'!K39 -> 0 | AD39: ='27'!K39 -> 0 | AE39: ='28'!K39 -> 0 | AF39: ='29'!K39 -> 0 | AG39: ='30'!K39 -> 0 | AI39: =AG39-D39 -> 0 | AJ39: =AVERAGE(D39:AG39) -> 0
B40: - Tempe Kw I (campuran kedelai) | C40: Kg | D40: ='1'!K40 -> 13000 | E40: ='2'!K40 -> 13000 | F40: ='3'!K40 -> 13000 | G40: ='4'!K40 -> 13000 | H40: ='5'!K40 -> 13000 | I40: ='6'!K40 -> 13000 | J40: ='7'!K40 -> 13000 | K40: ='8'!K40 -> 13000 | L40: ='9'!K40 -> 13000 | M40: ='10'!K40 -> 12750 | N40: ='11'!K40 -> 15000 | O40: ='12'!K40 -> 15000 | P40: ='13'!K40 -> 15000 | Q40: ='14'!K40 -> 15000 | R40: ='15'!K40 -> 15000 | S40: ='14'!K40 -> 15000 | T40: ='17'!K40 -> 15000 | U40: ='18'!K40 -> 15000 | V40: ='19'!K40 -> 15000 | W40: ='20'!K40 -> 15000 | X40: ='21'!K40 -> 15000 | Y40: ='22'!K40 -> 15000 | Z40: ='23'!K40 -> 15000 | AA40: ='24'!K40 -> 15000 | AB40: ='25'!K40 -> 15000 | AC40: ='26'!K40 -> 15000 | AD40: ='27'!K40 -> 15000 | AE40: ='28'!K40 -> 15000 | AF40: ='29'!K40 -> 15000 | AG40: ='30'!K40 -> 15000 | AI40: =AG40-D40 -> 2000 | AJ40: =AVERAGE(D40:AG40) -> 14325
B41: - Tempe Kw II (campuran jagung) | C41: Kg | D41: ='1'!K41 -> 6000 | E41: ='2'!K41 -> 6000 | F41: ='3'!K41 -> 6000 | G41: ='4'!K41 -> 6000 | H41: ='5'!K41 -> 6000 | I41: ='6'!K41 -> 6000 | J41: ='7'!K41 -> 6000 | K41: ='8'!K41 -> 6000 | L41: ='9'!K41 -> 6000 | M41: ='10'!K41 -> 6000 | N41: ='11'!K41 -> 6000 | O41: ='12'!K41 -> 6000 | P41: ='13'!K41 -> 6000 | Q41: ='14'!K41 -> 6000 | R41: ='15'!K41 -> 6000 | S41: ='14'!K41 -> 6000 | T41: ='17'!K41 -> 6000 | U41: ='18'!K41 -> 6000 | V41: ='19'!K41 -> 6000 | W41: ='20'!K41 -> 6000 | X41: ='21'!K41 -> 6000 | Y41: ='22'!K41 -> 6000 | Z41: ='23'!K41 -> 6000 | AA41: ='24'!K41 -> 6000 | AB41: ='25'!K41 -> 6000 | AC41: ='26'!K41 -> 6000 | AD41: ='27'!K41 -> 6000 | AE41: ='28'!K41 -> 6000 | AF41: ='29'!K41 -> 6000 | AG41: ='30'!K41 -> 6000 | AI41: =AG41-D41 -> 0 | AJ41: =AVERAGE(D41:AG41) -> 6000
...

Sheet 1
A1: HARGA BAHAN-BAHAN POKOK
A2: DI PASAR TRADISIONAL KOTA SURABAYA
A3: Hari / Tanggal : Rabu , 01 November 2023
B4: NAMA BAHAN POKOK DAN PENTING LAINNYA | C4: SATUAN | D4: Pasar Tambahrejo | E4: Pasar Pucang Anom | F4: Pasar Wonokromo | G4: Pasar Genteng Baru | H4: Pasar Pabean | I4: Pasar Kembang | J4: Pasar Balongsari | K4: Rata-Rata
A7: 1 | B7: BERAS
B8: - Beras Premium | C8: Kg | D8: 13000 | E8: 13500 | F8: 14000 | G8: 13500 | H8: 14000 | I8: 14000 | J8: 14000 | K8: =AVERAGE(D8:J8) -> 13714.286
B9: - Beras Medium Bulog | C9: Kg | D9: 10900 | E9: 10900 | F9: 10900 | G9: 10900 | H9: 10900 | I9: 11000 | J9: - | K9: =AVERAGE(D9:J9) -> 10916.667
B10: - Beras Medium | C10: Kg | D10: - | E10: - | F10: - | G10: - | H10: - | I10: - | J10: - | K10: 0
B11: - Beras Jagung | C11: Kg | D11: - | E11: 10000 | F11: 12000 | G11: 10000 | H11: - | I11: 12000 | J11: 8000 | K11: =AVERAGE(D11:J11) -> 10400
B12: - Beras Ketan (Jenis Siyem) | C12: Kg | D12: - | E12: 21000 | F12: 17000 | G12: 20000 | H12: - | I12: 17000 | J12: 17000 | K12: =AVERAGE(D12:J12) -> 18400
A13: 2 | B13: GULA
B14: - Gula pasir lokal curah | C14: Kg | D14: 16000 | E14: 14000 | F14: 14500 | G14: 13500 | H14: 15000 | I14: 13500 | J14: 16000 | K14: =AVERAGE(D14:J14) -> 14642.857
B15: - Gula Jawa/Merah (Bahan Kelapa) | C15: Kg | D15: 15000 | E15: 16000 | F15: 15000 | G15: 14000 | H15: 15000 | I15: 15000 | J15: 16000 | K15: =AVERAGE(D15:J15) -> 15142.857
A16: 3 | B16: MINYAK GORENG
B17: - Minyak Goreng Curah (Bening) | C17: Kg | D17: 15000 | E17: 15000 | F17: 16000 | G17: 15000 | H17: 15000 | I17: 15000 | J17: 15000 | K17: =AVERAGE(D17:J17) -> 15142.857
B18: - Minyak Kita | C18: Liter | D18: 14000 | E18: 14000 | F18: 14000 | G18: 14000 | H18: - | I18: 14000 | J18: 14000 | K18: =AVERAGE(D18:J18) -> 14000
A19: 4 | B19: MENTEGA
B20: - Mentega Curah (Amanda) | C20: Kg | D20: 20000 | E20: 20000 | F20: 20000 | G20: 22000 | H20: - | I20: 20000 | J20: - | K20: =AVERAGE(D20:J20) -> 20400
A21: 5 | B21: DAGING
B22: - Daging Sapi Grade Atas | C22: Kg | D22: 120000 | E22: 120000 | F22: 120000 | G22: 120000 | H22: 120000 | I22: 120000 | J22: - | K22: =AVERAGE(D22:J22) -> 120000
B23: - Daging Sapi Grade Sedang | C23: Kg | D23: 110000 | E23: 110000 | F23: 110000 | G23: 110000 | H23: 115000 | I23: 115000 | J23: 110000 | K23: =AVERAGE(D23:J23) -> 111428.57
B24: - Daging Sapi Grade Bawah | C24: Kg | D24: 90000 | E24: 95000 | F24: 100000 | G24: 105000 | H24: 110000 | I24: 100000 | J24: 105000 | K24: =AVERAGE(D24:J24) -> 100714.29
B25: - Daging Ayam Broiler | C25: Kg | D25: 34000 | E25: 33000 | F25: 33000 | G25: 33000 | H25: 35000 | I25: 34000 | J25: 34000 | K25: =AVERAGE(D25:J25) -> 33714.286
A26: 6 | B26: I K A N
B27: - Ikan Tongkol Segar (Uk. Sedang) | C27: Kg | D27: 35000 | E27: 36000 | F27: - | G27: 35000 | H27: 35000 | I27: 35000 | J27: 35000 | K27: =AVERAGE(D27:J27) -> 35166.667
B28: - Ikan Mujair Segar (Uk. Sedang) | C28: Kg | D28: 25000 | E28: 28000 | F28: 30000 | G28: 30000 | H28: 23000 | I28: 30000 | J28: 25000 | K28: =AVERAGE(D28:J28) -> 27285.714
B29: - Udang Segar (Uk. Sedang) | C29: Kg | D29: 60000 | E29: 60000 | F29: 75000 | G29: 70000 | H29: 68000 | I29: 68000 | J29: 65000 | K29: =AVERAGE(D29:J29) -> 66571.429
B30: - Ikan Lele Segar (Ukuran Sedang) | C30: Kg | D30: 25000 | E30: - | F30: - | G30: 25000 | H30: 23000 | I30: 24000 | J30: 26000 | K30: =AVERAGE(D30:J30) -> 24600
B31: - Ikan Bandeng Segar (Uk. Sedang) | C31: Kg | D31: 35000 | E31: 36000 | F31: 40000 | G31: 35000 | H31: 28000 | I31: 38000 | J31: 40000 | K31: =AVERAGE(D31:J31) -> 36000
B32: - Ikan Teri Asin (Bukan Teri Medan) | C32: Kg | D32: - | E32: 100000 | F32: 100000 | G32: - | H32: 80000 | I32: - | J32: 70000 | K32: =AVERAGE(D32:J32) -> 87500
A33: 7 | B33: TELUR
B34: - Telur Ayam Broiler | C34: Kg | D34: 24000 | E34: 24000 | F34: 25000 | G34: 24000 | H34: 24000 | I34: 25000 | J34: 25000 | K34: =AVERAGE(D34:J34) -> 24428.571
B35: - Telur Ayam Kampung | C35: Butir | D35: 3000 | E35: 2500 | F35: 2500 | G35: 2600 | H35: 2500 | I35: 3000 | J35: 3000 | K35: =AVERAGE(D35:J35) -> 2728.5714
A36: 8 | B36: TAHU
B37: - Tahu biasa | C37: Kg | D37: 10000 | E37: 1250 | F37: 9000 | G37: 9000 | H37: 16000 | I37: 7000 | J37: 9000 | K37: =AVERAGE(D37:J37) -> 8750
B38: - Tahu susu | C38: Kg | D38: - | E38: 10000 | F38: 12000 | G38: 14000 | H38: - | I38: 15000 | J38: 12000 | K38: =AVERAGE(D38:J38) -> 12600
A39: 9 | B39: TEMPE
B40: - Tempe Kw I (campuran kedelai) | C40: Kg | D40: - | E40: - | F40: - | G40: 16000 | H40: 14000 | I40: 7000 | J40: 15000 | K40: =AVERAGE(D40:J40) -> 13000
B41: - Tempe Kw II (campuran jagung) | C41: Kg | D41: - | E41: - | F41: 6000 | G41: - | H41: - | I41: - | J41: - | K41: =AVERAGE(D41:J41) -> 6000
B42: - Tempe Kw III (campuran kulit) | C42: Kg | D42: - | E42: 2500 | F42: - | G42: - | H42: - | I42: - | J42: - | K42: =AVERAGE(D42:J42) -> 2500
...

Sheet 2
A1: HARGA BAHAN-BAHAN POKOK
A2: DI PASAR TRADISIONAL KOTA SURABAYA
A3: Hari / Tanggal : Kamis , 02 November 2023
B4: NAMA BAHAN POKOK DAN PENTING LAINNYA | C4: SATUAN | D4: Pasar Tambahrejo | E4: Pasar Pucang Anom | F4: Pasar Wonokromo | G4: Pasar Genteng Baru | H4: Pasar Pabean | I4: Pasar Kembang | J4: Pasar Balongsari | K4: Rata-Rata
A7: 1 | B7: BERAS
B8: - Beras Premium | C8: Kg | D8: 13000 | E8: 13500 | F8: 14000 | G8: 13500 | H8: 14000 | I8: 14000 | J8: 14000 | K8: =AVERAGE(D8:J8) -> 13714.286
B9: - Beras Medium Bulog | C9: Kg | D9: 10900 | E9: 10900 | F9: 10900 | G9: 10900 | H9: 10900 | I9: 11000 | J9: - | K9: =AVERAGE(D9:J9) -> 10916.667
B10: - Beras Medium | C10: Kg | D10: - | E10: - | F10: - | G10: - | H10: - | I10: - | J10: - | K10: 0
B11: - Beras Jagung | C11: Kg | D11: - | E11: 10000 | F11: 12000 | G11: 10000 | H11: - | I11: 12000 | J11: 8000 | K11: =AVERAGE(D11:J11) -> 10400
B12: - Beras Ketan (Jenis Siyem) | C12: Kg | D12: - | E12: 21000 | F12: 17000 | G12: 20000 | H12: - | I12: 17000 | J12: 17000 | K12: =AVERAGE(D12:J12) -> 18400
A13: 2 | B13: GULA
B14: - Gula pasir lokal curah | C14: Kg | D14: 16000 | E14: 14000 | F14: 14500 | G14: 13500 | H14: 15000 | I14: 13500 | J14: 16000 | K14: =AVERAGE(D14:J14) -> 14642.857
B15: - Gula Jawa/Merah (Bahan Kelapa) | C15: Kg | D15: 15000 | E15: 16000 | F15: 15000 | G15: 14000 | H15: 15000 | I15: 15000 | J15: 16000 | K15: =AVERAGE(D15:J15) -> 15142.857
A16: 3 | B16: MINYAK GORENG
B17: - Minyak Goreng Curah (Bening) | C17: Kg | D17: 15000 | E17: 15000 | F17: 16000 | G17: 15000 | H17: 15000 | I17: 15000 | J17: 15000 | K17: =AVERAGE(D17:J17) -> 15142.857
B18: - Minyak Kita | C18: Liter | D18: 14000 | E18: 14000 | F18: 14000 | G18: 14000 | H18: - | I18: 14000 | J18: 14000 | K18: =AVERAGE(D18:J18) -> 14000
A19: 4 | B19: MENTEGA
B20: - Mentega Curah (Amanda) | C20: Kg | D20: 20000 | E20: 20000 | F20: 20000 | G20: 22000 | H20: - | I20: 20000 | J20: - | K20: =AVERAGE(D20:J20) -> 20400
A21: 5 | B21: DAGING
B22: - Daging Sapi Grade Atas | C22: Kg | D22: 120000 | E22: 120000 | F22: 120000 | G22: 120000 | H22: 120000 | I22: 120000 | J22: - | K22: =AVERAGE(D22:J22) -> 120000
B23: - Daging Sapi Grade Sedang | C23: Kg | D23: 110000 | E23: 110000 | F23: 110000 | G23: 110000 | H23: 115000 | I23: 115000 | J23: 110000 | K23: =AVERAGE(D23:J23) -> 111428.57
B24: - Daging Sapi Grade Bawah | C24: Kg | D24: 90000 | E24: 95000 | F24: 100000 | G24: 105000 | H24: 110000 | I24: 100000 | J24: 105000 | K24: =AVERAGE(D24:J24) -> 100714.29
B25: - Daging Ayam Broiler | C25: Kg | D25: 34000 | E25: 33000 | F25: 33000 | G25: 33000 | H25: 34000 | I25: 34000 | J25: 34000 | K25: =AVERAGE(D25:J25) -> 33571.429
A26: 6 | B26: I K A N
B27: - Ikan Tongkol Segar (Uk. Sedang) | C27: Kg | D27: 35000 | E27: 36000 | F27: - | G27: 35000 | H27: 35000 | I27: 35000 | J27: 35000 | K27: =AVERAGE(D27:J27) -> 35166.667
B28: - Ikan Mujair Segar (Uk. Sedang) | C28: Kg | D28: 25000 | E28: 28000 | F28: 30000 | G28: 30000 | H28: 23000 | I28: 30000 | J28: 25000 | K28: =AVERAGE(D28:J28) -> 27285.714
B29: - Udang Segar (Uk. Sedang) | C29: Kg | D29: 60000 | E29: 60000 | F29: 75000 | G29: 70000 | H29: 68000 | I29: 68000 | J29: 65000 | K29: =AVERAGE(D29:J29) -> 66571.429
B30: - Ikan Lele Segar (Ukuran Sedang) | C30: Kg | D30: 25000 | E30: - | F30: - | G30: 25000 | H30: 23000 | I30: 24000 | J30: 26000 | K30: =AVERAGE(D30:J30) -> 24600
B31: - Ikan Bandeng Segar (Uk. Sedang) | C31: Kg | D31: 35000 | E31: 36000 | F31: 40000 | G31: 35000 | H31: 28000 | I31: 38000 | J31: 40000 | K31: =AVERAGE(D31:J31) -> 36000
B32: - Ikan Teri Asin (Bukan Teri Medan) | C32: Kg | D32: - | E32: 100000 | F32: 100000 | G32: - | H32: 80000 | I32: - | J32: 70000 | K32: =AVERAGE(D32:J32) -> 87500
A33: 7 | B33: TELUR
B34: - Telur Ayam Broiler | C34: Kg | D34: 24000 | E34: 24000 | F34: 25000 | G34: 24000 | H34: 24000 | I34: 25000 | J34: 25000 | K34: =AVERAGE(D34:J34) -> 24428.571
B35: - Telur Ayam Kampung | C35: Butir | D35: 3000 | E35: 2500 | F35: 2500 | G35: 2600 | H35: 2500 | I35: 3000 | J35: 3000 | K35: =AVERAGE(D35:J35) -> 2728.5714
A36: 8 | B36: TAHU
B37: - Tahu biasa | C37: Kg | D37: 10000 | E37: 1250 | F37: 9000 | G37: 9000 | H37: 16000 | I37: 7000 | J37: 9000 | K37: =AVERAGE(D37:J37) -> 8750
B38: - Tahu susu | C38: Kg | D38: - | E38: 10000 | F38: 12000 | G38: 14000 | H38: - | I38: 15000 | J38: 12000 | K38: =AVERAGE(D38:J38) -> 12600
A39: 9 | B39: TEMPE
B40: - Tempe Kw I (campuran kedelai) | C40: Kg | D40: - | E40: - | F40: - | G40: 16000 | H40: 14000 | I40: 7000 | J40: 15000 | K40: =AVERAGE(D40:J40) -> 13000
B41: - Tempe Kw II (campuran jagung) | C41: Kg | D41: - | E41: - | F41: 6000 | G41: - | H41: - | I41: - | J41: - | K41: =AVERAGE(D41:J41) -> 6000
B42: - Tempe Kw III (campuran kulit) | C42: Kg | D42: - | E42: 2500 | F42: - | G42: - | H42: - | I42: - | J42: - | K42: =AVERAGE(D42:J42) -> 2500
...

Sheet 3
A1: HARGA BAHAN-BAHAN POKOK
A2: DI PASAR TRADISIONAL KOTA SURABAYA
A3: Hari / Tanggal : Jumat , 03 November 2023
B4: NAMA BAHAN POKOK DAN PENTING LAINNYA | C4: SATUAN | D4: Pasar Tambahrejo | E4: Pasar Pucang Anom | F4: Pasar Wonokromo | G4: Pasar Genteng Baru | H4: Pasar Pabean | I4: Pasar Kembang | J4: Pasar Balongsari | K4: Rata-Rata
A7: 1 | B7: BERAS
B8: - Beras Premium | C8: Kg | D8: 15000 | E8: 14000 | F8: 14000 | G8: 14000 | H8: 14000 | I8: 14000 | J8: 14000 | K8: =AVERAGE(D8:J8) -> 14142.857
B9: - Beras Medium Bulog | C9: Kg | D9: 10900 | E9: 10900 | F9: 10900 | G9: 10900 | H9: 10900 | I9: 11000 | J9: - | K9: =AVERAGE(D9:J9) -> 10916.667
B10: - Beras Medium | C10: Kg | D10: - | E10: - | F10: - | G10: - | H10: - | I10: - | J10: - | K10: 0
B11: - Beras Jagung | C11: Kg | D11: - | E11: 10000 | F11: 12000 | G11: 10000 | H11: - | I11: 12000 | J11: 8000 | K11: =AVERAGE(D11:J11) -> 10400
B12: - Beras Ketan (Jenis Siyem) | C12: Kg | D12: - | E12: 21000 | F12: 17000 | G12: 20000 | H12: - | I12: 17000 | J12: 17000 | K12: =AVERAGE(D12:J12) -> 18400
A13: 2 | B13: GULA
B14: - Gula pasir lokal curah | C14: Kg | D14: 16000 | E14: 14500 | F14: 14500 | G14: 16000 | H14: 15000 | I14: 13500 | J14: 16000 | K14: =AVERAGE(D14:J14) -> 15071.429
B15: - Gula Jawa/Merah (Bahan Kelapa) | C15: Kg | D15: 15000 | E15: 16000 | F15: 15000 | G15: 15000 | H15: 15000 | I15: 15000 | J15: 16000 | K15: =AVERAGE(D15:J15) -> 15285.714
A16: 3 | B16: MINYAK GORENG
B17: - Minyak Goreng Curah (Bening) | C17: Kg | D17: 15000 | E17: 15000 | F17: 16000 | G17: 15000 | H17: 15000 | I17: 15000 | J17: 15000 | K17: =AVERAGE(D17:J17) -> 15142.857
B18: - Minyak Kita | C18: Liter | D18: 14000 | E18: 14000 | F18: 14000 | G18: 14000 | H18: - | I18: 14000 | J18: 14000 | K18: =AVERAGE(D18:J18) -> 14000
A19: 4 | B19: MENTEGA
B20: - Mentega Curah (Amanda) | C20: Kg | D20: 20000 | E20: 20000 | F20: 20000 | G20: 22000 | H20: - | I20: 20000 | J20: - | K20: =AVERAGE(D20:J20) -> 20400
A21: 5 | B21: DAGING
B22: - Daging Sapi Grade Atas | C22: Kg | D22: 120000 | E22: 120000 | F22: 120000 | G22: 120000 | H22: 120000 | I22: 120000 | J22: - | K22: =AVERAGE(D22:J22) -> 120000
B23: - Daging Sapi Grade Sedang | C23: Kg | D23: 110000 | E23: 110000 | F23: 110000 | G23: 110000 | H23: 115000 | I23: 115000 | J23: 110000 | K23: =AVERAGE(D23:J23) -> 111428.57
B24: - Daging Sapi Grade Bawah | C24: Kg | D24: 90000 | E24: 95000 | F24: 100000 | G24: 105000 | H24: 110000 | I24: 100000 | J24: 105000 | K24: =AVERAGE(D24:J24) -> 100714.29
B25: - Daging Ayam Broiler | C25: Kg | D25: 34000 | E25: 33000 | F25: 33000 | G25: 33000 | H25: 34500 | I25: 34000 | J25: 34000 | K25: =AVERAGE(D25:J25) -> 33642.857
A26: 6 | B26: I K A N
B27: - Ikan Tongkol Segar (Uk. Sedang) | C27: Kg | D27: 35000 | E27: 36000 | F27: - | G27: 35000 | H27: 35000 | I27: 35000 | J27: 35000 | K27: =AVERAGE(D27:J27) -> 35166.667
B28: - Ikan Mujair Segar (Uk. Sedang) | C28: Kg | D28: 25000 | E28: 28000 | F28: 30000 | G28: 30000 | H28: 23000 | I28: 30000 | J28: 25000 | K28: =AVERAGE(D28:J28) -> 27285.714
B29: - Udang Segar (Uk. Sedang) | C29: Kg | D29: 60000 | E29: 60000 | F29: 75000 | G29: 70000 | H29: 68000 | I29: 68000 | J29: 65000 | K29: =AVERAGE(D29:J29) -> 66571.429
B30: - Ikan Lele Segar (Ukuran Sedang) | C30: Kg | D30: 25000 | E30: - | F30: - | G30: 25000 | H30: 23000 | I30: 24000 | J30: 26000 | K30: =AVERAGE(D30:J30) -> 24600
B31: - Ikan Bandeng Segar (Uk. Sedang) | C31: Kg | D31: 35000 | E31: 36000 | F31: 40000 | G31: 35000 | H31: 28000 | I31: 38000 | J31: 40000 | K31: =AVERAGE(D31:J31) -> 36000
B32: - Ikan Teri Asin (Bukan Teri Medan) | C32: Kg | D32: - | E32: 100000 | F32: 100000 | G32: - | H32: 80000 | I32: - | J32: 70000 | K32: =AVERAGE(D32:J32) -> 87500
A33: 7 | B33: TELUR
B34: - Telur Ayam Broiler | C34: Kg | D34: 25000 | E34: 24000 | F34: 25000 | G34: 24000 | H34: 24000 | I34: 25000 | J34: 25000 | K34: =AVERAGE(D34:J34) -> 24571.429
B35: - Telur Ayam Kampung | C35: Butir | D35: 3000 | E35: 2500 | F35: 2500 | G35: 2600 | H35: 2500 | I35: 3000 | J35: 3000 | K35: =AVERAGE(D35:J35) -> 2728.5714
A36: 8 | B36: TAHU
B37: - Tahu biasa | C37: Kg | D37: 10000 | E37: 1250 | F37: 9000 | G37: 9000 | H37: 16000 | I37: 7000 | J37: 9000 | K37: =AVERAGE(D37:J37) -> 8750
B38: - Tahu susu | C38: Kg | D38: - | E38: 10000 | F38: 12000 | G38: 14000 | H38: - | I38: 15000 | J38: 12000 | K38: =AVERAGE(D38:J38) -> 12600
A39: 9 | B39: TEMPE
B40: - Tempe Kw I (campuran kedelai) | C40: Kg | D40: - | E40: - | F40: - | G40: 16000 | H40: 14000 | I40: 7000 | J40: 15000 | K40: =AVERAGE(D40:J40) -> 13000
B41: - Tempe Kw II (campuran jagung) | C41: Kg | D41: - | E41: - | F41: 6000 | G41: - | H41: - | I41: - | J41: - | K41: =AVERAGE(D41:J41) -> 6000
B42: - Tempe Kw III (campuran kulit) | C42: Kg | D42: - | E42: 2500 | F42: - | G42: - | H42: - | I42: - | J42: - | K42: =AVERAGE(D42:J42) -> 2500
...

Sheet 4
A1: HARGA BAHAN-BAHAN POKOK
A2: DI PASAR TRADISIONAL KOTA SURABAYA
A3: Hari / Tanggal : Sabtu , 04 November 2023
B4: NAMA BAHAN POKOK DAN PENTING LAINNYA | C4: SATUAN | D4: Pasar Tambahrejo | E4: Pasar Pucang Anom | F4: Pasar Wonokromo | G4: Pasar Genteng Baru | H4: Pasar Pabean | I4: Pasar Kembang | J4: Pasar Balongsari | K4: Rata-Rata
A7: 1 | B7: BERAS
B8: - Beras Premium | C8: Kg | D8: 15000 | E8: 14000 | F8: 14000 | G8: 14000 | H8: 14000 | I8: 14000 | J8: 14000 | K8: =AVERAGE(D8:J8) -> 14142.857
B9: - Beras Medium Bulog | C9: Kg | D9: 10900 | E9: 10900 | F9: 10900 | G9: 10900 | H9: 10900 | I9: 11000 | J9: - | K9: =AVERAGE(D9:J9) -> 10916.667
B10: - Beras Medium | C10: Kg | D10: - | E10: - | F10: - | G10: - | H10: - | I10: - | J10: - | K10: 0
B11: - Beras Jagung | C11: Kg | D11: - | E11: 10000 | F11: 12000 | G11: 10000 | H11: - | I11: 12000 | J11: 8000 | K11: =AVERAGE(D11:J11) -> 10400
B12: - Beras Ketan (Jenis Siyem) | C12: Kg | D12: - | E12: 21000 | F12: 17000 | G12: 20000 | H12: - | I12: 17000 | J12: 17000 | K12: =AVERAGE(D12:J12) -> 18400
A13: 2 | B13: GULA
B14: - Gula pasir lokal curah | C14: Kg | D14: 16000 | E14: 14500 | F14: 14500 | G14: 16000 | H14: 15000 | I14: 15000 | J14: 16000 | K14: =AVERAGE(D14:J14) -> 15285.714
B15: - Gula Jawa/Merah (Bahan Kelapa) | C15: Kg | D15: 15000 | E15: 16000 | F15: 15000 | G15: 15000 | H15: 15000 | I15: 15000 | J15: 16000 | K15: =AVERAGE(D15:J15) -> 15285.714
A16: 3 | B16: MINYAK GORENG
B17: - Minyak Goreng Curah (Bening) | C17: Kg | D17: 15000 | E17: 15000 | F17: 16000 | G17: 15000 | H17: 15000 | I17: 15000 | J17: 15000 | K17: =AVERAGE(D17:J17) -> 15142.857
B18: - Minyak Kita | C18: Liter | D18: 14000 | E18: 14000 | F18: 14000 | G18: 14000 | H18: - | I18: 14000 | J18: 14000 | K18: =AVERAGE(D18:J18) -> 14000
A19: 4 | B19: MENTEGA
B20: - Mentega Curah (Amanda) | C20: Kg | D20: 20000 | E20: 20000 | F20: 20000 | G20: 22000 | H20: - | I20: 20000 | J20: - | K20: =AVERAGE(D20:J20) -> 20400
A21: 5 | B21: DAGING
B22: - Daging Sapi Grade Atas | C22: Kg | D22: 120000 | E22: 120000 | F22: 120000 | G22: 120000 | H22: 120000 | I22: 120000 | J22: - | K22: =AVERAGE(D22:J22) -> 120000
B23: - Daging Sapi Grade Sedang | C23: Kg | D23: 110000 | E23: 110000 | F23: 110000 | G23: 110000 | H23: 115000 | I23: 115000 | J23: 110000 | K23: =AVERAGE(D23:J23) -> 111428.57
B24: - Daging Sapi Grade Bawah | C24: Kg | D24: 90000 | E24: 95000 | F24: 100000 | G24: 105000 | H24: 110000 | I24: 100000 | J24: 105000 | K24: =AVERAGE(D24:J24) -> 100714.29
B25: - Daging Ayam Broiler | C25: Kg | D25: 34000 | E25: 33000 | F25: 33000 | G25: 33000 | H25: 34500 | I25: 34000 | J25: 34000 | K25: =AVERAGE(D25:J25) -> 33642.857
A26: 6 | B26: I K A N
B27: - Ikan Tongkol Segar (Uk. Sedang) | C27: Kg | D27: 35000 | E27: 36000 | F27: - | G27: 35000 | H27: 35000 | I27: 35000 | J27: 35000 | K27: =AVERAGE(D27:J27) -> 35166.667
B28: - Ikan Mujair Segar (Uk. Sedang) | C28: Kg | D28: 25000 | E28: 28000 | F28: 30000 | G28: 30000 | H28: 23000 | I28: 30000 | J28: 25000 | K28: =AVERAGE(D28:J28) -> 27285.714
B29: - Udang Segar (Uk. Sedang) | C29: Kg | D29: 60000 | E29: 60000 | F29: 75000 | G29: 70000 | H29: 68000 | I29: 68000 | J29: 65000 | K29: =AVERAGE(D29:J29) -> 66571.429
B30: - Ikan Lele Segar (Ukuran Sedang) | C30: Kg | D30: 25000 | E30: - | F30: - | G30: 25000 | H30: 23000 | I30: 24000 | J30: 26000 | K30: =AVERAGE(D30:J30) -> 24600
B31: - Ikan Bandeng Segar (Uk. Sedang) | C31: Kg | D31: 35000 | E31: 36000 | F31: 40000 | G31: 35000 | H31: 28000 | I31: 38000 | J31: 40000 | K31: =AVERAGE(D31:J31) -> 36000
B32: - Ikan Teri Asin (Bukan Teri Medan) | C32: Kg | D32: - | E32: 100000 | F32: 100000 | G32: - | H32: 80000 | I32: - | J32: 70000 | K32: =AVERAGE(D32:J32) -> 87500
A33: 7 | B33: TELUR
B34: - Telur Ayam Broiler | C34: Kg | D34: 25000 | E34: 24000 | F34: 25000 | G34: 24000 | H34: 24000 | I34: 25000 | J34: 25000 | K34: =AVERAGE(D34:J34) -> 24571.429
B35: - Telur Ayam Kampung | C35: Butir | D35: 3000 | E35: 2500 | F35: 2500 | G35: 2600 | H35: 2500 | I35: 3000 | J35: 3000 | K35: =AVERAGE(D35:J35) -> 2728.5714
A36: 8 | B36: TAHU
B37: - Tahu biasa | C37: Kg | D37: 10000 | E37: 1250 | F37: 9000 | G37: 9000 | H37: 16000 | I37: 7000 | J37: 9000 | K37: =AVERAGE(D37:J37) -> 8750
B38: - Tahu susu | C38: Kg | D38: - | E38: 10000 | F38: 12000 | G38: 14000 | H38: - | I38: 15000 | J38: 12000 | K38: =AVERAGE(D38:J38) -> 12600
A39: 9 | B39: TEMPE
B40: - Tempe Kw I (campuran kedelai) | C40: Kg | D40: - | E40: - | F40: - | G40: 16000 | H40: 14000 | I40: 7000 | J40: 15000 | K40: =AVERAGE(D40:J40) -> 13000
B41: - Tempe Kw II (campuran jagung) | C41: Kg | D41: - | E41: - | F41: 6000 | G41: - | H41: - | I41: - | J41: - | K41: =AVERAGE(D41:J41) -> 6000
B42: - Tempe Kw III (campuran kulit) | C42: Kg | D42: - | E42: 2500 | F42: - | G42: - | H42: - | I42: - | J42: - | K42: =AVERAGE(D42:J42) -> 2500
...

Sheet 5
A1: HARGA BAHAN-BAHAN POKOK
A2: DI PASAR TRADISIONAL KOTA SURABAYA
A3: Hari / Tanggal : Minggu , 05 November 2023
B4: NAMA BAHAN POKOK DAN PENTING LAINNYA | C4: SATUAN | D4: Pasar Tambahrejo | E4: Pasar Pucang Anom | F4: Pasar Wonokromo | G4: Pasar Genteng Baru | H4: Pasar Pabean | I4: Pasar Kembang | J4: Pasar Balongsari | K4: Rata-Rata
A7: 1 | B7: BERAS
B8: - Beras Premium | C8: Kg | D8: 15000 | E8: 14000 | F8: 14000 | G8: 14000 | H8: 14000 | I8: 14000 | J8: 14000 | K8: =AVERAGE(D8:J8) -> 14142.857
B9: - Beras Medium Bulog | C9: Kg | D9: 10900 | E9: 10900 | F9: 10900 | G9: 10900 | H9: 10900 | I9: 11000 | J9: - | K9: =AVERAGE(D9:J9) -> 10916.667
B10: - Beras Medium | C10: Kg | D10: - | E10: - | F10: - | G10: - | H10: - | I10: - | J10: - | K10: 0
B11: - Beras Jagung | C11: Kg | D11: - | E11: 10000 | F11: 12000 | G11: 10000 | H11: - | I11: 12000 | J11: 8000 | K11: =AVERAGE(D11:J11) -> 10400
B12: - Beras Ketan (Jenis Siyem) | C12: Kg | D12: - | E12: 21000 | F12: 17000 | G12: 20000 | H12: - | I12: 17000 | J12: 17000 | K12: =AVERAGE(D12:J12) -> 18400
A13: 2 | B13: GULA
B14: - Gula pasir lokal curah | C14: Kg | D14: 16000 | E14: 14500 | F14: 14500 | G14: 15000 | H14: 15000 | I14: 15000 | J14: 16000 | K14: =AVERAGE(D14:J14) -> 15142.857
B15: - Gula Jawa/Merah (Bahan Kelapa) | C15: Kg | D15: 15000 | E15: 16000 | F15: 15000 | G15: 15000 | H15: 15000 | I15: 15000 | J15: 16000 | K15: =AVERAGE(D15:J15) -> 15285.714
A16: 3 | B16: MINYAK GORENG
B17: - Minyak Goreng Curah (Bening) | C17: Kg | D17: 15000 | E17: 15000 | F17: 16000 | G17: 15000 | H17: 15000 | I17: 15000 | J17: 15000 | K17: =AVERAGE(D17:J17) -> 15142.857
B18: - Minyak Kita | C18: Liter | D18: 14000 | E18: 14000 | F18: 14000 | G18: 14000 | H18: - | I18: 14000 | J18: 14000 | K18: =AVERAGE(D18:J18) -> 14000
A19: 4 | B19: MENTEGA
B20: - Mentega Curah (Amanda) | C20: Kg | D20: 20000 | E20: 20000 | F20: 20000 | G20: 22000 | H20: - | I20: 20000 | J20: - | K20: =AVERAGE(D20:J20) -> 20400
A21: 5 | B21: DAGING
B22: - Daging Sapi Grade Atas | C22: Kg | D22: 120000 | E22: 120000 | F22: 120000 | G22: 120000 | H22: 120000 | I22: 120000 | J22: - | K22: =AVERAGE(D22:J22) -> 120000
B23: - Daging Sapi Grade Sedang | C23: Kg | D23: 110000 | E23: 110000 | F23: 110000 | G23: 110000 | H23: 115000 | I23: 115000 | J23: 110000 | K23: =AVERAGE(D23:J23) -> 111428.57
B24: - Daging Sapi Grade Bawah | C24: Kg | D24: 90000 | E24: 95000 | F24: 100000 | G24: 105000 | H24: 110000 | I24: 100000 | J24: 105000 | K24: =AVERAGE(D24:J24) -> 100714.29
B25: - Daging Ayam Broiler | C25: Kg | D25: 34000 | E25: 33000 | F25: 33000 | G25: 33000 | H25: 34500 | I25: 34000 | J25: 34000 | K25: =AVERAGE(D25:J25) -> 33642.857
A26: 6 | B26: I K A N
B27: - Ikan Tongkol Segar (Uk. Sedang) | C27: Kg | D27: 35000 | E27: 36000 | F27: - | G27: 35000 | H27: 35000 | I27: 35000 | J27: 35000 | K27: =AVERAGE(D27:J27) -> 35166.667
B28: - Ikan Mujair Segar (Uk. Sedang) | C28: Kg | D28: 25000 | E28: 28000 | F28: 30000 | G28: 30000 | H28: 23000 | I28: 30000 | J28: 25000 | K28: =AVERAGE(D28:J28) -> 27285.714
B29: - Udang Segar (Uk. Sedang) | C29: Kg | D29: 60000 | E29: 60000 | F29: 75000 | G29: 70000 | H29: 68000 | I29: 68000 | J29: 65000 | K29: =AVERAGE(D29:J29) -> 66571.429
B30: - Ikan Lele Segar (Ukuran Sedang) | C30: Kg | D30: 25000 | E30: - | F30: - | G30: 25000 | H30: 23000 | I30: 24000 | J30: 26000 | K30: =AVERAGE(D30:J30) -> 24600
B31: - Ikan Bandeng Segar (Uk. Sedang) | C31: Kg | D31: 35000 | E31: 36000 | F31: 40000 | G31: 35000 | H31: 28000 | I31: 38000 | J31: 40000 | K31: =AVERAGE(D31:J31) -> 36000
B32: - Ikan Teri Asin (Bukan Teri Medan) | C32: Kg | D32: - | E32: 100000 | F32: 100000 | G32: - | H32: 80000 | I32: - | J32: 70000 | K32: =AVERAGE(D32:J32) -> 87500
A33: 7 | B33: TELUR
B34: - Telur Ayam Broiler | C34: Kg | D34: 25000 | E34: 24000 | F34: 25000 | G34: 24000 | H34: 24000 | I34: 25000 | J34: 25000 | K34: =AVERAGE(D34:J34) -> 24571.429
B35: - Telur Ayam Kampung | C35: Butir | D35: 3000 | E35: 2500 | F35: 2500 | G35: 2600 | H35: 2500 | I35: 3000 | J35: 3000 | K35: =AVERAGE(D35:J35) -> 2728.5714
A36: 8 | B36: TAHU
B37: - Tahu biasa | C37: Kg | D37: 10000 | E37: 1250 | F37: 9000 | G37: 9000 | H37: 16000 | I37: 7000 | J37: 9000 | K37: =AVERAGE(D37:J37) -> 8750
B38: - Tahu susu | C38: Kg | D38: - | E38: 10000 | F38: 12000 | G38: 14000 | H38: - | I38: 15000 | J38: 12000 | K38: =AVERAGE(D38:J38) -> 12600
A39: 9 | B39: TEMPE
B40: - Tempe Kw I (campuran kedelai) | C40: Kg | D40: - | E40: - | F40: - | G40: 16000 | H40: 14000 | I40: 7000 | J40: 15000 | K40: =AVERAGE(D40:J40) -> 13000
B41: - Tempe Kw II (campuran jagung) | C41: Kg | D41: - | E41: - | F41: 6000 | G41: - | H41: - | I41: - | J41: - | K41: =AVERAGE(D41:J41) -> 6000
B42: - Tempe Kw III (campuran kulit) | C42: Kg | D42: - | E42: 2500 | F42: - | G42: - | H42: - | I42: - | J42: - | K42: =AVERAGE(D42:J42) -> 2500
...

Sheet 6
A1: HARGA BAHAN-BAHAN POKOK
A2: DI PASAR TRADISIONAL KOTA SURABAYA
A3: Hari / Tanggal : Senin , 06 November 2023
B4: NAMA BAHAN POKOK DAN PENTING LAINNYA | C4: SATUAN | D4: Pasar Tambahrejo | E4: Pasar Pucang Anom | F4: Pasar Wonokromo | G4: Pasar Genteng Baru | H4: Pasar Pabean | I4: Pasar Kembang | J4: Pasar Balongsari | K4: Rata-Rata
A7: 1 | B7: BERAS
B8: - Beras Premium | C8: Kg | D8: 15000 | E8: 14000 | F8: 14000 | G8: 14000 | H8: 14000 | I8: 14000 | J8: 14000 | K8: =AVERAGE(D8:J8) -> 14142.857
B9: - Beras Medium Bulog | C9: Kg | D9: 10900 | E9: 10900 | F9: 10900 | G9: 10900 | H9: 10900 | I9: 11000 | J9: - | K9: =AVERAGE(D9:J9) -> 10916.667
B10: - Beras Medium | C10: Kg | D10: - | E10: - | F10: - | G10: - | H10: - | I10: - | J10: - | K10: 0
B11: - Beras Jagung | C11: Kg | D11: - | E11: 10000 | F11: 12000 | G11: 10000 | H11: - | I11: 12000 | J11: 8000 | K11: =AVERAGE(D11:J11) -> 10400
B12: - Beras Ketan (Jenis Siyem) | C12: Kg | D12: - | E12: 21000 | F12: 17000 | G12: 20000 | H12: - | I12: 17000 | J12: 17000 | K12: =AVERAGE(D12:J12) -> 18400
A13: 2 | B13: GULA
B14: - Gula pasir lokal curah | C14: Kg | D14: 16000 | E14: 15000 | F14: 15000 | G14: 15000 | H14: 15000 | I14: 15000 | J14: 16000 | K14: =AVERAGE(D14:J14) -> 15285.714
B15: - Gula Jawa/Merah (Bahan Kelapa) | C15: Kg | D15: 15000 | E15: 16000 | F15: 15000 | G15: 15000 | H15: 15000 | I15: 15000 | J15: 16000 | K15: =AVERAGE(D15:J15) -> 15285.714
A16: 3 | B16: MINYAK GORENG
B17: - Minyak Goreng Curah (Bening) | C17: Kg | D17: 15000 | E17: 15000 | F17: 16000 | G17: 15000 | H17: 15000 | I17: 15000 | J17: 15000 | K17: =AVERAGE(D17:J17) -> 15142.857
B18: - Minyak Kita | C18: Liter | D18: 14000 | E18: 14000 | F18: 14000 | G18: 14000 | H18: - | I18: 14000 | J18: 14000 | K18: =AVERAGE(D18:J18) -> 14000
A19: 4 | B19: MENTEGA
B20: - Mentega Curah (Amanda) | C20: Kg | D20: 20000 | E20: 20000 | F20: 20000 | G20: 22000 | H20: - | I20: 20000 | J20: - | K20: =AVERAGE(D20:J20) -> 20400
A21: 5 | B21: DAGING
B22: - Daging Sapi Grade Atas | C22: Kg | D22: 120000 | E22: 120000 | F22: 120000 | G22: 120000 | H22: 120000 | I22: 120000 | J22: - | K22: =AVERAGE(D22:J22) -> 120000
B23: - Daging Sapi Grade Sedang | C23: Kg | D23: 110000 | E23: 110000 | F23: 110000 | G23: 110000 | H23: 115000 | I23: 115000 | J23: 110000 | K23: =AVERAGE(D23:J23) -> 111428.57
B24: - Daging Sapi Grade Bawah | C24: Kg | D24: 90000 | E24: 95000 | F24: 100000 | G24: 105000 | H24: 110000 | I24: 100000 | J24: 105000 | K24: =AVERAGE(D24:J24) -> 100714.29
B25: - Daging Ayam Broiler | C25: Kg | D25: 34000 | E25: 32000 | F25: 33000 | G25: 33000 | H25: 34500 | I25: 34000 | J25: 34000 | K25: =AVERAGE(D25:J25) -> 33500
A26: 6 | B26: I K A N
B27: - Ikan Tongkol Segar (Uk. Sedang) | C27: Kg | D27: 35000 | E27: 36000 | F27: - | G27: 35000 | H27: 35000 | I27: 35000 | J27: 38000 | K27: =AVERAGE(D27:J27) -> 35666.667
B28: - Ikan Mujair Segar (Uk. Sedang) | C28: Kg | D28: 30000 | E28: 28000 | F28: 30000 | G28: 30000 | H28: 23000 | I28: 30000 | J28: 25000 | K28: =AVERAGE(D28:J28) -> 28000
B29: - Udang Segar (Uk. Sedang) | C29: Kg | D29: 60000 | E29: 60000 | F29: 75000 | G29: 70000 | H29: 68000 | I29: 68000 | J29: 70000 | K29: =AVERAGE(D29:J29) -> 67285.714
B30: - Ikan Lele Segar (Ukuran Sedang) | C30: Kg | D30: 25000 | E30: - | F30: - | G30: 25000 | H30: 23000 | I30: 24000 | J30: 26000 | K30: =AVERAGE(D30:J30) -> 24600
B31: - Ikan Bandeng Segar (Uk. Sedang) | C31: Kg | D31: 40000 | E31: 36000 | F31: 40000 | G31: 35000 | H31: 28000 | I31: 38000 | J31: 40000 | K31: =AVERAGE(D31:J31) -> 36714.286
B32: - Ikan Teri Asin (Bukan Teri Medan) | C32: Kg | D32: - | E32: 100000 | F32: 100000 | G32: - | H32: 80000 | I32: - | J32: 70000 | K32: =AVERAGE(D32:J32) -> 87500
A33: 7 | B33: TELUR
B34: - Telur Ayam Broiler | C34: Kg | D34: 25000 | E34: 25000 | F34: 26000 | G34: 25000 | H34: 26000 | I34: 25000 | J34: 27000 | K34: =AVERAGE(D34:J34) -> 25571.429
B35: - Telur Ayam Kampung | C35: Butir | D35: 3000 | E35: 2500 | F35: 2500 | G35: 2600 | H35: 2500 | I35: 3000 | J35: 3000 | K35: =AVERAGE(D35:J35) -> 2728.5714
A36: 8 | B36: TAHU
B37: - Tahu biasa | C37: Kg | D37: 10000 | E37: 1250 | F37: 9000 | G37: 9000 | H37: 16000 | I37: 7000 | J37: 9000 | K37: =AVERAGE(D37:J37) -> 8750
B38: - Tahu susu | C38: Kg | D38: - | E38: 10000 | F38: 12000 | G38: 14000 | H38: - | I38: 15000 | J38: 12000 | K38: =AVERAGE(D38:J38) -> 12600
A39: 9 | B39: TEMPE
B40: - Tempe Kw I (campuran kedelai) | C40: Kg | D40: - | E40: - | F40: - | G40: 16000 | H40: 14000 | I40: 7000 | J40: 15000 | K40: =AVERAGE(D40:J40) -> 13000
B41: - Tempe Kw II (campuran jagung) | C41: Kg | D41: - | E41: - | F41: 6000 | G41: - | H41: - | I41: - | J41: - | K41: =AVERAGE(D41:J41) -> 6000
B42: - Tempe Kw III (campuran kulit) | C42: Kg | D42: - | E42: 2500 | F42: - | G42: - | H42: - | I42: - | J42: - | K42: =AVERAGE(D42:J42) -> 2500
...

Sheet 7
A1: HARGA BAHAN-BAHAN POKOK
A2: DI PASAR TRADISIONAL KOTA SURABAYA
